Workbook

Sheet Clinker
B1: AUG | C1: Iron Ore | G1: Raw Meal | K1: Tan Coal | Q1: EDENVILLEY coal | W1: RUVUMA coal | AB1: GODMWANGA coal | AF1: STAMICO coal | AK1: Coal Ash | AO1: Ariim Coal | AT1: Market insight coal | AY1: Jitegemee coal | BD1: MAX coal | BI1: SINO coal | BN1: IBRICO coal | BS1: MEGA CJ coal | BX1: Mabenga coal | CC1: TENKO | CH1: SCOLASTICA | CM1: Connect | CR1: Yongda | CW1: KINDAINI COAL | DB1: Montreal | DG1: LUGEWA COAL | DL1: mchekane | DQ1: Lik & Lambert coal | DV1: SIAAS | EA1: kiln coal | EE1: cpp coal | EI1: clinker
B2: Date | C2: Opening Stock | D2: Production | E2: Consumption | F2: Closing Stock | G2: Opening Stock | H2: Production | I2: total Consumption | J2: Closing Stock | K2: Opening Stock | L2: Production | M2: CPP | N2: KILN | O2: Consumption | P2: Closing Stock | Q2: Opening Stock | R2: Production | S2: Consumption CPP | T2: Consump Kiln | U2: Total Consumption | V2: Closing Stock | W2: Opening Stock | X2: Production | Y2: Consumption CPP | Z2: Consumption | AA2: Closing Stock | AB2: Opening Stock | AC2: Production | AD2: Consumption | AE2: Closing Stock | AF2: Opening Stock | AG2: Production | AH2: kiln cons | AI2: Consumption | AJ2: Closing Stock | AK2: Opening Stock | AL2: Production | AM2: Consumption | AN2: Closing Stock | AO2: Opening Stock | AP2: Production | AQ2: Consumption | AR2: CPP CONS | AS2: Closing Stock | AT2: Opening Stock | AU2: Production | AV2: Consumption | AW2: CPP CONS | AX2: Closing Stock | AY2: Opening Stock | AZ2: Production | BA2: Consumption | BB2: CPP CONS | BC2: Closing Stock | BD2: Opening Stock | BE2: Production | BF2: Consumption | BG2: CPP CONS | BH2: Closing Stock | BI2: Opening Stock | BJ2: Production | BK2: Consumption | BL2: CPP CONS | BM2: Closing Stock | BN2: Opening Stock | BO2: Production | BP2: Consumption | BQ2: CPP CONS | BR2: Closing Stock | BS2: Opening Stock | BT2: Production | BU2: Consumption | BV2: CPP CONS | BW2: Closing Stock | BX2: Opening Stock | BY2: Production | BZ2: Consumption | CA2: CPP CONS | CB2: Closing Stock | CC2: Opening Stock | CD2: Production | CE2: Consumption | CF2: CPP CONS | CG2: Closing Stock | CH2: Opening Stock | CI2: Production | CJ2: Consumption | CK2: CPP CONS | CL2: Closing Stock | CM2: Opening Stock | CN2: Production | CO2: Consumption | CP2: CPP CONS | CQ2: Closing Stock | CR2: Opening Stock | CS2: Production | CT2: Consumption | CU2: CPP CONS | CV2: Closing Stock | CW2: Opening Stock | CX2: Production | CY2: Consumption | CZ2: CPP CONS | DA2: Closing Stock | DB2: Opening Stock | DC2: Production | DD2: Consumption | DE2: CPP CONS | DF2: Closing Stock | DG2: Opening Stock | DH2: Production | DI2: Consumption | DJ2: CPP CONS | DK2: Closing Stock | DL2: Opening Stock | DM2: Production | DN2: Consumption | DO2: CPP CONS | DP2: Closing Stock | DQ2: Opening Stock | DR2: Production | DS2: Consumption | DT2: CPP CONS | DU2: Closing Stock | DV2: Opening Stock | DW2: Production | DX2: Consumption | DY2: CPP CONS | DZ2: Closing Stock | EA2: Opening Stock | EB2: Production | EC2: Consumption | ED2: Closing Stock | EE2: Opening Stock | EF2: Production | EG2: Consumption | EH2: Closing Stock | EI2: Opening Stock | EJ2: Production | EK2: Consumption | EL2: Closing Stock | EM2: own clinker | EN2: spg clinker
B3: 1 | C3: 2647.92 | D3: 0 | E3: 52 | F3: =C3+D3-E3 -> 2595.92 | G3: 1907.0496 | H3: 0 | I3: 0 | J3: =G3+H3-I3-[1]Cement!U3 -> 1907.0496 | K3: 0 | L3: 0 | M3: =CPP!D3 -> 0 | N3: 0 | O3: =M3+N3 -> 0 | P3: =K3+L3-O3 -> 0 | Q3: 0 | R3: 0 | S3: =CPP!E3 -> 0 | T3: 0 | U3: =S3+T3 -> 0 | V3: =Q3+R3-U3 -> 0 | W3: 1063.04 | X3: 0 | Y3: =CPP!H3 -> 0 | Z3: 0 | AA3: =W3+X3-Z3-Y3 -> 1063.04 | AB3: 0 | AC3: 0 | AD3: =CPP!F3 -> 0 | AE3: =AB3+AC3-AD3 -> 0 | AF3: 4048.67 | AG3: 272.05 | AH3: 0 | AI3: =CPP!G3 -> 156 | AJ3: =AF3+AG3-AI3 -> 4164.72 | AK3: 0 | AL3: 0 | AM3: 0 | AN3: =AK3+AL3-AM3 -> 0 | AO3: 0 | AP3: 0 | AQ3: 0 | AR3: =CPP!I3 -> 0 | AS3: =AO3+AP3-AQ3-AR3 -> 0 | AT3: 2933.9 | AU3: 0 | AV3: 306.23 | AW3: =CPP!X3 -> 0 | AX3: =AT3+AU3-AV3-AW3 -> 2627.67 | AY3: 412.027 | AZ3: 121.76 | BA3: 0 | BB3: =CPP!M3 -> 0 | BC3: =AY3+AZ3-BA3-BB3 -> 533.787 | BD3: 0 | BE3: 0 | BF3: 0 | BG3: =CPP!K3 -> 0 | BH3: =BD3+BE3-BF3-BG3 -> 0 | BI3: 0 | BJ3: 0 | BK3: 0 | BL3: =CPP!L3 -> 0 | BM3: =BI3+BJ3-BK3-BL3 -> 0 | BN3: 0 | BO3: 0 | BP3: 0 | BQ3: =CPP!N3 -> 0 | BR3: =BN3+BO3-BP3-BQ3 -> 0 | BS3: 0 | BT3: 0 | BU3: 0 | BV3: =CPP!O3 -> 0 | BW3: =BS3+BT3-BU3-BV3 -> 0 | BX3: 0 | BY3: 0 | BZ3: 0 | CB3: 0 | CC3: 0 | CD3: 0 | CE3: 0 | CF3: =CPP!P3 -> 0 | CG3: =CC3+CD3-CE3-CF3 -> 0 | CH3: 0 | CI3: 0 | CJ3: 0 | CK3: =CPP!Q3 -> 0 | CL3: =CH3+CI3-CJ3-CK3 -> 0 | CM3: 0.05 | CN3: 0 | CO3: 0 | CP3: =CPP!R3 -> 0 | CQ3: =CM3+CN3-CP3 -> 0.05 | CR3: 0 | CS3: 0 | CT3: 0 | CU3: =CPP!S3 -> 0 | CV3: =CR3+CS3-CT3-CU3 -> 0 | CW3: 0 | CX3: 0 | CY3: 0 | CZ3: =CPP!T3 -> 0 | DA3: =CW3+CX3-CY3-CZ3 -> 0 | DB3: 7.11 | DC3: 0 | DD3: 7.1 | DE3: =CPP!U3 -> 0 | DF3: =DB3+DC3-DD3-DE3 -> 0.01 | DG3: 0 | DH3: 0 | DI3: 0 | DJ3: =CPP!V3 -> 0 | DK3: =DG3+DH3-DI3-DJ3 -> 0 | DL3: 212 | DM3: 30 | DN3: 0 | DO3: =CPP!W3 -> 0 | DP3: =DL3+DM3-DN3-DO3 -> 242 | DQ3: 0 | DR3: 0 | DS3: 0 | DT3: =CPP!J3 -> 0 | DU3: =DQ3+DR3-DS3-DT3 -> 0 | DV3: 0 | DW3: 0 | DX3: 0 | DY3: 0 | DZ3: =DV3+DW3-DX3-DY3 -> 0 | EA3: 2159.814 | EB3: 0 | EC3: 0 | ED3: 6228.9 | EE3: 12495.05 | EF3: =R3+AC3+AG3 -> 272.05 | EG3: =CPP!D3+CPP!E3+CPP!F3+CPP!G3+CPP!H3+CPP!I3+CPP!J3+CPP!M3+BG3 -> 156 | EH3: =EE3+EF3-EG3 -> 12611.1 | EI3: 31251.902 | EJ3: =EM3+EN3 -> 1970 | EK3: ='DAILY CEM1'!AG4+'DAILY CEM2'!AF4 -> 1611.34 | EL3: =EI3+EJ3-EK3 -> 31610.562 | EM3: 1970 | EN3: 0 | EO3: 0
B4: 2 | C4: =F3 -> 2595.92 | D4: 0 | E4: 49 | F4: =C4+D4-E4 -> 2546.92 | G4: =J3 -> 1907.0496 | H4: 0 | I4: 0 | J4: =G4+H4-I4-[1]Cement!U4 -> 1907.0496 | K4: =P3 -> 0 | L4: 0 | M4: =CPP!D4 -> 0 | N4: 0 | O4: =M4+N4 -> 0 | P4: =K4+L4-O4 -> 0 | Q4: =V3 -> 0 | R4: 0 | S4: =CPP!E4 -> 0 | T4: 0 | U4: =S4+T4 -> 0 | V4: =Q4+R4-U4 -> 0 | W4: =AA3 -> 1063.04 | X4: 0 | Y4: =CPP!H4 -> 0 | Z4: 0 | AA4: =W4+X4-Z4-Y4 -> 1063.04 | AB4: =AE3 -> 0 | AC4: 0 | AD4: =CPP!F4 -> 0 | AE4: =AB4+AC4-AD4 -> 0 | AF4: =AJ3 -> 4164.72 | AG4: 150.1 | AH4: 0 | AI4: =CPP!G4 -> 130 | AJ4: =AF4+AG4-AI4 -> 4184.82 | AK4: =AN3 -> 0 | AL4: 0 | AM4: 0 | AN4: =AK4+AL4-AM4 -> 0 | AO4: =AS3 -> 0 | AP4: 0 | AQ4: 0 | AR4: =CPP!I4 -> 0 | AS4: =AO4+AP4-AQ4-AR4 -> 0 | AT4: =AX3 -> 2627.67 | AU4: 0 | AV4: 277.78 | AW4: =CPP!X4 -> 0 | AX4: =AT4+AU4-AV4-AW4 -> 2349.89 | AY4: =BC3 -> 533.787 | AZ4: 156.98 | BA4: 0 | BB4: =CPP!M4 -> 0 | BC4: =AY4+AZ4-BA4-BB4 -> 690.767 | BD4: =BH3 -> 0 | BE4: 0 | BF4: 0 | BG4: =CPP!K4 -> 0 | BH4: =BD4+BE4-BF4-BG4 -> 0 | BI4: =BM3 -> 0 | BJ4: 0 | BK4: 0 | BL4: =CPP!L4 -> 0 | BM4: =BI4+BJ4-BK4-BL4 -> 0 | BN4: =BR3 -> 0 | BO4: 0 | BP4: 0 | BQ4: =CPP!N4 -> 0 | BR4: =BN4+BO4-BP4-BQ4 -> 0 | BS4: =BW3 -> 0 | BT4: 0 | BU4: 0 | BV4: =CPP!O4 -> 0 | BW4: =BS4+BT4-BU4-BV4 -> 0 | BX4: =CB3 -> 0 | BY4: 0 | BZ4: 0 | CB4: =BX4+BY4-BZ4-CA4 -> 0 | CC4: =CG3 -> 0 | CD4: 0 | CE4: 0 | CF4: =CPP!P4 -> 0 | CG4: =CC4+CD4-CE4-CF4 -> 0 | CH4: =CL3 -> 0 | CI4: 0 | CJ4: 0 | CK4: =CPP!Q4 -> 0 | CL4: =CH4+CI4-CJ4-CK4 -> 0 | CM4: =CQ3 -> 0.05 | CN4: 0 | CO4: 0 | CP4: =CPP!R4 -> 0 | CQ4: =CM4+CN4-CP4 -> 0.05 | CR4: =CV3 -> 0 | CS4: 0 | CT4: 0 | CU4: =CPP!S4 -> 0 | CV4: =CR4+CS4-CT4-CU4 -> 0 | CW4: =DA3 -> 0 | CX4: 0 | CY4: 0 | CZ4: =CPP!T4 -> 0 | DA4: =CW4+CX4-CY4-CZ4 -> 0 | DB4: =DF3 -> 0.01 | DC4: 0 | DD4: 0 | DE4: =CPP!U4 -> 0 | DF4: =DB4+DC4-DD4-DE4 -> 0.01 | DG4: =DK3 -> 0 | DH4: 0 | DI4: 0 | DJ4: =CPP!V4 -> 0 | DK4: =DG4+DH4-DI4-DJ4 -> 0 | DL4: =DP3 -> 242 | DM4: 30 | DN4: 0 | DO4: =CPP!W4 -> 0 | DP4: =DL4+DM4-DN4-DO4 -> 272 | DQ4: =DU3 -> 0 | DR4: 0 | DS4: 0 | DT4: =CPP!J4 -> 0 | DU4: =DQ4+DR4-DS4-DT4 -> 0 | DV4: =DZ3 -> 0 | DW4: 0 | DX4: 0 | DY4: 0 | DZ4: =DV4+DW4-DX4-DY4 -> 0 | EA4: =K4+W4+AK4+AO4+AT4+AY4 -> 4224.497 | EB4: 0 | EC4: 0 | ED4: =EA4+EB4-EC4 -> 4224.497 | EE4: =Q4+AB4+AF4 -> 4164.72 | EF4: =R4+AC4+AG4 -> 150.1 | EG4: =CPP!D4+CPP!E4+CPP!F4+CPP!G4+CPP!H4+CPP!I4+CPP!J4+CPP!M4+BG4 -> 130 | EH4: =EE4+EF4-EG4 -> 4184.82 | EI4: =EL3 -> 31610.562 | EJ4: =EM4+EN4 -> 1615 | EK4: ='DAILY CEM1'!AG5+'DAILY CEM2'!AF5 -> 1783.008 | EL4: =EI4+EJ4-EK4 -> 31442.554 | EM4: 1615 | EN4: 0 | EO4: 0
B5: 3 | C5: =F4 -> 2546.92 | D5: 0 | E5: 67 | F5: =C5+D5-E5 -> 2479.92 | G5: =J4 -> 1907.0496 | H5: 0 | I5: 0 | J5: =G5+H5-I5-[1]Cement!U5 -> 1907.0496 | K5: =P4 -> 0 | L5: 0 | M5: =CPP!D5 -> 0 | N5: 0 | O5: =M5+N5 -> 0 | P5: =K5+L5-O5 -> 0 | Q5: =V4 -> 0 | R5: 0 | S5: =CPP!E5 -> 0 | T5: 0 | U5: =S5+T5 -> 0 | V5: =Q5+R5-U5 -> 0 | W5: =AA4 -> 1063.04 | X5: 0 | Y5: =CPP!H5 -> 0 | Z5: 0 | AA5: =W5+X5-Z5-Y5 -> 1063.04 | AB5: =AE4 -> 0 | AC5: 0 | AD5: =CPP!F5 -> 0 | AE5: =AB5+AC5-AD5 -> 0 | AF5: =AJ4 -> 4184.82 | AG5: 397.15 | AH5: 0 | AI5: =CPP!G5 -> 138 | AJ5: =AF5+AG5-AI5 -> 4443.97 | AK5: =AN4 -> 0 | AL5: 0 | AM5: 0 | AN5: =AK5+AL5-AM5 -> 0 | AO5: =AS4 -> 0 | AP5: 0 | AQ5: 0 | AR5: =CPP!I5 -> 0 | AS5: =AO5+AP5-AQ5-AR5 -> 0 | AT5: =AX4 -> 2349.89 | AU5: 0 | AV5: 239 | AW5: =CPP!X5 -> 0 | AX5: =AT5+AU5-AV5-AW5 -> 2110.89 | AY5: =BC4 -> 690.767 | AZ5: 221.94 | BA5: 0 | BB5: =CPP!M5 -> 0 | BC5: =AY5+AZ5-BA5-BB5 -> 912.707 | BD5: =BH4 -> 0 | BE5: 0 | BF5: 0 | BG5: =CPP!K5 -> 0 | BH5: =BD5+BE5-BF5-BG5 -> 0 | BI5: =BM4 -> 0 | BJ5: 0 | BK5: 0 | BL5: =CPP!L5 -> 0 | BM5: =BI5+BJ5-BK5-BL5 -> 0 | BN5: =BR4 -> 0 | BO5: 0 | BP5: 0 | BQ5: =CPP!N5 -> 0 | BR5: =BN5+BO5-BP5-BQ5 -> 0 | BS5: =BW4 -> 0 | BT5: 0 | BU5: 0 | BV5: =CPP!O5 -> 0 | BW5: =BS5+BT5-BU5-BV5 -> 0 | BX5: =CB4 -> 0 | BY5: 0 | BZ5: 0 | CB5: =BX5+BY5-BZ5-CA5 -> 0 | CC5: =CG4 -> 0 | CD5: 0 | CE5: 0 | CF5: =CPP!P5 -> 0 | CG5: =CC5+CD5-CE5-CF5 -> 0 | CH5: =CL4 -> 0 | CI5: 0 | CJ5: 0 | CK5: =CPP!Q5 -> 0 | CL5: =CH5+CI5-CJ5-CK5 -> 0 | CM5: =CQ4 -> 0.05 | CN5: 0 | CO5: 0 | CP5: =CPP!R5 -> 0 | CQ5: =CM5+CN5-CP5 -> 0.05 | CR5: =CV4 -> 0 | CS5: 0 | CT5: 0 | CU5: =CPP!S5 -> 0 | CV5: =CR5+CS5-CT5-CU5 -> 0 | CW5: =DA4 -> 0 | CX5: 0 | CY5: 0 | CZ5: =CPP!T5 -> 0 | DA5: =CW5+CX5-CY5-CZ5 -> 0 | DB5: =DF4 -> 0.01 | DC5: 0 | DD5: 0 | DE5: =CPP!U5 -> 0 | DF5: =DB5+DC5-DD5-DE5 -> 0.01 | DG5: =DK4 -> 0 | DH5: 0 | DI5: 0 | DJ5: =CPP!V5 -> 0 | DK5: =DG5+DH5-DI5-DJ5 -> 0 | DL5: =DP4 -> 272 | DM5: 0 | DN5: 0 | DO5: =CPP!W5 -> 0 | DP5: =DL5+DM5-DN5-DO5 -> 272 | DQ5: =DU4 -> 0 | DR5: 0 | DS5: 0 | DT5: =CPP!J5 -> 0 | DU5: =DQ5+DR5-DS5-DT5 -> 0 | DV5: =DZ4 -> 0 | DW5: 0 | DX5: 0 | DY5: 0 | DZ5: =DV5+DW5-DX5-DY5 -> 0 | EA5: =K5+W5+AK5+AO5+AT5+AY5 -> 4103.697 | EB5: 0 | EC5: 0 | ED5: =EA5+EB5-EC5 -> 4103.697 | EE5: =Q5+AB5+AF5 -> 4184.82 | EF5: =R5+AC5+AG5 -> 397.15 | EG5: =CPP!D5+CPP!E5+CPP!F5+CPP!G5+CPP!H5+CPP!I5+CPP!J5+CPP!M5+BG5 -> 138 | EH5: =EE5+EF5-EG5 -> 4443.97 | EI5: =EL4 -> 31442.554 | EJ5: =EM5+EN5 -> 1408 | EK5: ='DAILY CEM1'!AG6+'DAILY CEM2'!AF6 -> 2274.24 | EL5: =EI5+EJ5-EK5 -> 30576.314 | EM5: 1408 | EN5: 0 | EO5: 0
B6: 4 | C6: =F5 -> 2479.92 | D6: 0 | E6: 82 | F6: =C6+D6-E6 -> 2397.92 | G6: =J5 -> 1907.0496 | H6: 0 | I6: 0 | J6: =G6+H6-I6-[1]Cement!U6 -> 1907.0496 | K6: =P5 -> 0 | L6: 0 | M6: =CPP!D6 -> 0 | N6: 0 | O6: =M6+N6 -> 0 | P6: =K6+L6-O6 -> 0 | Q6: =V5 -> 0 | R6: 0 | S6: =CPP!E6 -> 0 | T6: 0 | U6: =S6+T6 -> 0 | V6: =Q6+R6-U6 -> 0 | W6: =AA5 -> 1063.04 | X6: 0 | Y6: =CPP!H6 -> 0 | Z6: 0 | AA6: =W6+X6-Z6-Y6 -> 1063.04 | AB6: =AE5 -> 0 | AC6: 0 | AD6: =CPP!F6 -> 0 | AE6: =AB6+AC6-AD6 -> 0 | AF6: =AJ5 -> 4443.97 | AG6: 120.2 | AH6: 0 | AI6: =CPP!G6 -> 158 | AJ6: =AF6+AG6-AI6 -> 4406.17 | AK6: =AN5 -> 0 | AL6: 0 | AM6: 0 | AN6: =AK6+AL6-AM6 -> 0 | AO6: =AS5 -> 0 | AP6: 0 | AQ6: 0 | AR6: =CPP!I6 -> 0 | AS6: =AO6+AP6-AQ6-AR6 -> 0 | AT6: =AX5 -> 2110.89 | AU6: 0 | AV6: 316.67 | AW6: =CPP!X6 -> 0 | AX6: =AT6+AU6-AV6-AW6 -> 1794.22 | AY6: =BC5 -> 912.707 | AZ6: 92.16 | BA6: 0 | BB6: =CPP!M6 -> 0 | BC6: =AY6+AZ6-BA6-BB6 -> 1004.867 | BD6: =BH5 -> 0 | BE6: 0 | BF6: 0 | BG6: =CPP!K6 -> 0 | BH6: =BD6+BE6-BF6-BG6 -> 0 | BI6: =BM5 -> 0 | BJ6: 0 | BK6: 0 | BL6: =CPP!L6 -> 0 | BM6: =BI6+BJ6-BK6-BL6 -> 0 | BN6: =BR5 -> 0 | BO6: 0 | BP6: 0 | BQ6: =CPP!N6 -> 0 | BR6: =BN6+BO6-BP6-BQ6 -> 0 | BS6: =BW5 -> 0 | BT6: 0 | BU6: 0 | BV6: =CPP!O6 -> 0 | BW6: =BS6+BT6-BU6-BV6 -> 0 | BX6: =CB5 -> 0 | BY6: 0 | BZ6: 0 | CB6: =BX6+BY6-BZ6-CA6 -> 0 | CC6: =CG5 -> 0 | CD6: 0 | CE6: 0 | CF6: =CPP!P6 -> 0 | CG6: =CC6+CD6-CE6-CF6 -> 0 | CH6: =CL5 -> 0 | CI6: 0 | CJ6: 0 | CK6: =CPP!Q6 -> 0 | CL6: =CH6+CI6-CJ6-CK6 -> 0 | CM6: =CQ5 -> 0.05 | CN6: 0 | CO6: 0 | CP6: =CPP!R6 -> 0 | CQ6: =CM6+CN6-CP6 -> 0.05 | CR6: =CV5 -> 0 | CS6: 0 | CT6: 0 | CU6: =CPP!S6 -> 0 | CV6: =CR6+CS6-CT6-CU6 -> 0 | CW6: =DA5 -> 0 | CX6: 0 | CY6: 0 | CZ6: =CPP!T6 -> 0 | DA6: =CW6+CX6-CY6-CZ6 -> 0 | DB6: =DF5 -> 0.01 | DC6: 0 | DD6: 0 | DE6: =CPP!U6 -> 0 | DF6: =DB6+DC6-DD6-DE6 -> 0.01 | DG6: =DK5 -> 0 | DH6: 0 | DI6: 0 | DJ6: =CPP!V6 -> 0 | DK6: =DG6+DH6-DI6-DJ6 -> 0 | DL6: =DP5 -> 272 | DM6: 32 | DN6: 0 | DO6: =CPP!W6 -> 0 | DP6: =DL6+DM6-DN6-DO6 -> 304 | DQ6: =DU5 -> 0 | DR6: 0 | DS6: 0 | DT6: =CPP!J6 -> 0 | DU6: =DQ6+DR6-DS6-DT6 -> 0 | DV6: =DZ5 -> 0 | DW6: 0 | DX6: 0 | DY6: 0 | DZ6: =DV6+DW6-DX6-DY6 -> 0 | EA6: =K6+W6+AK6+AO6+AT6+AY6 -> 4086.637 | EB6: 0 | EC6: 0 | ED6: =EA6+EB6-EC6 -> 4086.637 | EE6: =Q6+AB6+AF6 -> 4443.97 | EF6: =R6+AC6+AG6 -> 120.2 | EG6: =CPP!D6+CPP!E6+CPP!F6+CPP!G6+CPP!H6+CPP!I6+CPP!J6+CPP!M6+BG6 -> 158 | EH6: =EE6+EF6-EG6 -> 4406.17 | EI6: =EL5 -> 30576.314 | EJ6: =EM6+EN6 -> 1790 | EK6: ='DAILY CEM1'!AG7+'DAILY CEM2'!AF7 -> 2000.12 | EL6: =EI6+EJ6-EK6 -> 30366.194 | EM6: 1790 | EN6: 0 | EO6: 281.82
B7: 5 | C7: =F6 -> 2397.92 | D7: 0 | E7: 73 | F7: =C7+D7-E7 -> 2324.92 | G7: =J6 -> 1907.0496 | H7: 0 | I7: 0 | J7: =G7+H7-I7-[1]Cement!U7 -> 1907.0496 | K7: =P6 -> 0 | L7: 0 | M7: =CPP!D7 -> 0 | N7: 0 | O7: =M7+N7 -> 0 | P7: =K7+L7-O7 -> 0 | Q7: =V6 -> 0 | R7: 0 | S7: =CPP!E7 -> 0 | T7: 0 | U7: =S7+T7 -> 0 | V7: =Q7+R7-U7 -> 0 | W7: =AA6 -> 1063.04 | X7: 0 | Y7: =CPP!H7 -> 0 | Z7: 0 | AA7: =W7+X7-Z7-Y7 -> 1063.04 | AB7: =AE6 -> 0 | AC7: 0 | AD7: =CPP!F7 -> 0 | AE7: =AB7+AC7-AD7 -> 0 | AF7: =AJ6 -> 4406.17 | AG7: 30 | AH7: 0 | AI7: =CPP!G7 -> 140 | AJ7: =AF7+AG7-AI7 -> 4296.17 | AK7: =AN6 -> 0 | AL7: 0 | AM7: 0 | AN7: =AK7+AL7-AM7 -> 0 | AO7: =AS6 -> 0 | AP7: 0 | AQ7: 0 | AR7: =CPP!I7 -> 0 | AS7: =AO7+AP7-AQ7-AR7 -> 0 | AT7: =AX6 -> 1794.22 | AU7: 0 | AV7: 292.22 | AW7: =CPP!X7 -> 0 | AX7: =AT7+AU7-AV7-AW7 -> 1502 | AY7: =BC6 -> 1004.867 | AZ7: 0 | BA7: 0 | BB7: =CPP!M7 -> 0 | BC7: =AY7+AZ7-BA7-BB7 -> 1004.867 | BD7: =BH6 -> 0 | BE7: 0 | BF7: 0 | BG7: =CPP!K7 -> 0 | BH7: =BD7+BE7-BF7-BG7 -> 0 | BI7: =BM6 -> 0 | BJ7: 0 | BK7: 0 | BL7: =CPP!L7 -> 0 | BM7: =BI7+BJ7-BK7-BL7 -> 0 | BN7: =BR6 -> 0 | BO7: 0 | BP7: 0 | BQ7: =CPP!N7 -> 0 | BR7: =BN7+BO7-BP7-BQ7 -> 0 | BS7: =BW6 -> 0 | BT7: 0 | BU7: 0 | BV7: =CPP!O7 -> 0 | BW7: =BS7+BT7-BU7-BV7 -> 0 | BX7: =CB6 -> 0 | BY7: 0 | BZ7: 0 | CB7: =BX7+BY7-BZ7-CA7 -> 0 | CC7: =CG6 -> 0 | CD7: 0 | CE7: 0 | CF7: =CPP!P7 -> 0 | CG7: =CC7+CD7-CE7-CF7 -> 0 | CH7: =CL6 -> 0 | CI7: 0 | CJ7: 0 | CK7: =CPP!Q7 -> 0 | CL7: =CH7+CI7-CJ7-CK7 -> 0 | CM7: =CQ6 -> 0.05 | CN7: 0 | CO7: 0 | CP7: =CPP!R7 -> 0 | CQ7: =CM7+CN7-CP7 -> 0.05 | CR7: =CV6 -> 0 | CS7: 0 | CT7: 0 | CU7: =CPP!S7 -> 0 | CV7: =CR7+CS7-CT7-CU7 -> 0 | CW7: =DA6 -> 0 | CX7: 0 | CY7: 0 | CZ7: =CPP!T7 -> 0 | DA7: =CW7+CX7-CY7-CZ7 -> 0 | DB7: =DF6 -> 0.01 | DC7: 0 | DD7: 0 | DE7: =CPP!U7 -> 0 | DF7: =DB7+DC7-DD7-DE7 -> 0.01 | DG7: =DK6 -> 0 | DH7: 0 | DI7: 0 | DJ7: =CPP!V7 -> 0 | DK7: =DG7+DH7-DI7-DJ7 -> 0 | DL7: =DP6 -> 304 | DM7: 0 | DN7: 0 | DO7: =CPP!W7 -> 0 | DP7: =DL7+DM7-DN7-DO7 -> 304 | DQ7: =DU6 -> 0 | DR7: 0 | DS7: 0 | DT7: =CPP!J7 -> 0 | DU7: =DQ7+DR7-DS7-DT7 -> 0 | DV7: =DZ6 -> 0 | DW7: 0 | DX7: 0 | DY7: 0 | DZ7: =DV7+DW7-DX7-DY7 -> 0 | EA7: =K7+W7+AK7+AO7+AT7+AY7 -> 3862.127 | EB7: 0 | EC7: 0 | ED7: =EA7+EB7-EC7 -> 3862.127 | EE7: =Q7+AB7+AF7 -> 4406.17 | EF7: =R7+AC7+AG7 -> 30 | EG7: =CPP!D7+CPP!E7+CPP!F7+CPP!G7+CPP!H7+CPP!I7+CPP!J7+CPP!M7+BG7 -> 140 | EH7: =EE7+EF7-EG7 -> 4296.17 | EI7: =EL6 -> 30366.194 | EJ7: =EM7+EN7 -> 1690 | EK7: ='DAILY CEM1'!AG8+'DAILY CEM2'!AF8 -> 1825.615 | EL7: =EI7+EJ7-EK7 -> 30230.579 | EM7: 1690 | EN7: 0 | EO7: 1348.5
B8: 6 | C8: =F7 -> 2324.92 | D8: 0 | E8: 62 | F8: =C8+D8-E8 -> 2262.92 | G8: =J7 -> 1907.0496 | H8: 0 | I8: 0 | J8: =G8+H8-I8-[1]Cement!U8 -> 1907.0496 | K8: =P7 -> 0 | L8: 0 | M8: =CPP!D8 -> 0 | N8: 0 | O8: =M8+N8 -> 0 | P8: =K8+L8-O8 -> 0 | Q8: =V7 -> 0 | R8: 0 | S8: =CPP!E8 -> 0 | T8: 0 | U8: =S8+T8 -> 0 | V8: =Q8+R8-U8 -> 0 | W8: =AA7 -> 1063.04 | X8: 0 | Y8: =CPP!H8 -> 0 | Z8: 0 | AA8: =W8+X8-Z8-Y8 -> 1063.04 | AB8: =AE7 -> 0 | AC8: 0 | AD8: =CPP!F8 -> 0 | AE8: =AB8+AC8-AD8 -> 0 | AF8: =AJ7 -> 4296.17 | AG8: 0 | AH8: 0 | AI8: =CPP!G8 -> 140 | AJ8: =AF8+AG8-AI8 -> 4156.17 | AK8: =AN7 -> 0 | AL8: 0 | AM8: 0 | AN8: =AK8+AL8-AM8 -> 0 | AO8: =AS7 -> 0 | AP8: 0 | AQ8: 0 | AR8: =CPP!I8 -> 0 | AS8: =AO8+AP8-AQ8-AR8 -> 0 | AT8: =AX7 -> 1502 | AU8: 0 | AV8: 265.56 | AW8: =CPP!X8 -> 0 | AX8: =AT8+AU8-AV8-AW8 -> 1236.44 | AY8: =BC7 -> 1004.867 | AZ8: 0 | BA8: 0 | BB8: =CPP!M8 -> 0 | BC8: =AY8+AZ8-BA8-BB8 -> 1004.867 | BD8: =BH7 -> 0 | BE8: 0 | BF8: 0 | BG8: =CPP!K8 -> 0 | BH8: =BD8+BE8-BF8-BG8 -> 0 | BI8: =BM7 -> 0 | BJ8: 0 | BK8: 0 | BL8: =CPP!L8 -> 0 | BM8: =BI8+BJ8-BK8-BL8 -> 0 | BN8: =BR7 -> 0 | BO8: 0 | BP8: 0 | BQ8: =CPP!N8 -> 0 | BR8: =BN8+BO8-BP8-BQ8 -> 0 | BS8: =BW7 -> 0 | BT8: 0 | BU8: 0 | BV8: =CPP!O8 -> 0 | BW8: =BS8+BT8-BU8-BV8 -> 0 | BX8: =CB7 -> 0 | BY8: 0 | BZ8: 0 | CB8: =BX8+BY8-BZ8-CA8 -> 0 | CC8: =CG7 -> 0 | CD8: 0 | CE8: 0 | CF8: =CPP!P8 -> 0 | CG8: =CC8+CD8-CE8-CF8 -> 0 | CH8: =CL7 -> 0 | CI8: 0 | CJ8: 0 | CK8: =CPP!Q8 -> 0 | CL8: =CH8+CI8-CJ8-CK8 -> 0 | CM8: =CQ7 -> 0.05 | CN8: 0 | CO8: 0 | CP8: =CPP!R8 -> 0 | CQ8: =CM8+CN8-CP8 -> 0.05 | CR8: =CV7 -> 0 | CS8: 0 | CT8: 0 | CU8: =CPP!S8 -> 0 | CV8: =CR8+CS8-CT8-CU8 -> 0 | CW8: =DA7 -> 0 | CX8: 0 | CY8: 0 | CZ8: =CPP!T8 -> 0 | DA8: =CW8+CX8-CY8-CZ8 -> 0 | DB8: =DF7 -> 0.01 | DC8: 0 | DD8: 0 | DE8: =CPP!U8 -> 0 | DF8: =DB8+DC8-DD8-DE8 -> 0.01 | DG8: =DK7 -> 0 | DH8: 0 | DI8: 0 | DJ8: =CPP!V8 -> 0 | DK8: =DG8+DH8-DI8-DJ8 -> 0 | DL8: =DP7 -> 304 | DM8: 0 | DN8: 0 | DO8: =CPP!W8 -> 0 | DP8: =DL8+DM8-DN8-DO8 -> 304 | DQ8: =DU7 -> 0 | DR8: 0 | DS8: 0 | DT8: =CPP!J8 -> 0 | DU8: =DQ8+DR8-DS8-DT8 -> 0 | DV8: =DZ7 -> 0 | DW8: 0 | DX8: 0 | DY8: 0 | DZ8: =DV8+DW8-DX8-DY8 -> 0 | EA8: =K8+W8+AK8+AO8+AT8+AY8 -> 3569.907 | EB8: 0 | EC8: 0 | ED8: =EA8+EB8-EC8 -> 3569.907 | EE8: =Q8+AB8+AF8 -> 4296.17 | EF8: =R8+AC8+AG8 -> 0 | EG8: =CPP!D8+CPP!E8+CPP!F8+CPP!G8+CPP!H8+CPP!I8+CPP!J8+CPP!M8+BG8 -> 140 | EH8: =EE8+EF8-EG8 -> 4156.17 | EI8: =EL7 -> 30230.579 | EJ8: =EM8+EN8 -> 1505 | EK8: ='DAILY CEM1'!AG9+'DAILY CEM2'!AF9 -> 1714.594 | EL8: =EI8+EJ8-EK8 -> 30020.985 | EM8: 1505 | EN8: 0 | EO8: 1147.3
B9: 7 | C9: =F8 -> 2262.92 | D9: 0 | E9: 77 | F9: =C9+D9-E9 -> 2185.92 | G9: =J8 -> 1907.0496 | H9: 0 | I9: 0 | J9: =G9+H9-I9-[1]Cement!U9 -> 1907.0496 | K9: =P8 -> 0 | L9: 0 | M9: =CPP!D9 -> 0 | N9: 0 | O9: =M9+N9 -> 0 | P9: =K9+L9-O9 -> 0 | Q9: =V8 -> 0 | R9: 0 | S9: =CPP!E9 -> 0 | T9: 0 | U9: =S9+T9 -> 0 | V9: =Q9+R9-U9 -> 0 | W9: =AA8 -> 1063.04 | X9: 0 | Y9: =CPP!H9 -> 0 | Z9: 0 | AA9: =W9+X9-Z9-Y9 -> 1063.04 | AB9: =AE8 -> 0 | AC9: 0 | AD9: =CPP!F9 -> 0 | AE9: =AB9+AC9-AD9 -> 0 | AF9: =AJ8 -> 4156.17 | AG9: 0 | AH9: 0 | AI9: =CPP!G9 -> 138 | AJ9: =AF9+AG9-AI9 -> 4018.17 | AK9: =AN8 -> 0 | AL9: 0 | AM9: 0 | AN9: =AK9+AL9-AM9 -> 0 | AO9: =AS8 -> 0 | AP9: 0 | AQ9: 0 | AR9: =CPP!I9 -> 0 | AS9: =AO9+AP9-AQ9-AR9 -> 0 | AT9: =AX8 -> 1236.44 | AU9: 0 | AV9: 250 | AW9: =CPP!X9 -> 0 | AX9: =AT9+AU9-AV9-AW9 -> 986.44 | AY9: =BC8 -> 1004.867 | AZ9: 0 | BA9: 0 | BB9: =CPP!M9 -> 0 | BC9: =AY9+AZ9-BA9-BB9 -> 1004.867 | BD9: =BH8 -> 0 | BE9: 0 | BF9: 0 | BG9: =CPP!K9 -> 0 | BH9: =BD9+BE9-BF9-BG9 -> 0 | BI9: =BM8 -> 0 | BJ9: 0 | BK9: 0 | BL9: =CPP!L9 -> 0 | BM9: =BI9+BJ9-BK9-BL9 -> 0 | BN9: =BR8 -> 0 | BO9: 0 | BP9: 0 | BQ9: =CPP!N9 -> 0 | BR9: =BN9+BO9-BP9-BQ9 -> 0 | BS9: =BW8 -> 0 | BT9: 0 | BU9: 0 | BV9: =CPP!O9 -> 0 | BW9: =BS9+BT9-BU9-BV9 -> 0 | BX9: =CB8 -> 0 | BY9: 0 | BZ9: 0 | CB9: =BX9+BY9-BZ9-CA9 -> 0 | CC9: =CG8 -> 0 | CD9: 0 | CE9: 0 | CF9: =CPP!P9 -> 0 | CG9: =CC9+CD9-CE9-CF9 -> 0 | CH9: =CL8 -> 0 | CI9: 0 | CJ9: 0 | CK9: =CPP!Q9 -> 0 | CL9: =CH9+CI9-CJ9-CK9 -> 0 | CM9: =CQ8 -> 0.05 | CN9: 0 | CO9: 0 | CP9: =CPP!R9 -> 0 | CQ9: =CM9+CN9-CP9 -> 0.05 | CR9: =CV8 -> 0 | CS9: 0 | CT9: 0 | CU9: =CPP!S9 -> 0 | CV9: =CR9+CS9-CT9-CU9 -> 0 | CW9: =DA8 -> 0 | CX9: 0 | CY9: 0 | CZ9: =CPP!T9 -> 0 | DA9: =CW9+CX9-CY9-CZ9 -> 0 | DB9: =DF8 -> 0.01 | DC9: 0 | DD9: 0 | DE9: =CPP!U9 -> 0 | DF9: =DB9+DC9-DD9-DE9 -> 0.01 | DG9: =DK8 -> 0 | DH9: 0 | DI9: 0 | DJ9: =CPP!V9 -> 0 | DK9: =DG9+DH9-DI9-DJ9 -> 0 | DL9: =DP8 -> 304 | DM9: 0 | DN9: 0 | DO9: =CPP!W9 -> 0 | DP9: =DL9+DM9-DN9-DO9 -> 304 | DQ9: =DU8 -> 0 | DR9: 0 | DS9: 0 | DT9: =CPP!J9 -> 0 | DU9: =DQ9+DR9-DS9-DT9 -> 0 | DV9: =DZ8 -> 0 | DW9: 0 | DX9: 0 | DY9: 0 | DZ9: =DV9+DW9-DX9-DY9 -> 0 | EA9: =K9+W9+AK9+AO9+AT9+AY9 -> 3304.347 | EB9: 0 | EC9: 0 | ED9: =EA9+EB9-EC9 -> 3304.347 | EE9: =Q9+AB9+AF9 -> 4156.17 | EF9: =R9+AC9+AG9 -> 0 | EG9: =CPP!D9+CPP!E9+CPP!F9+CPP!G9+CPP!H9+CPP!I9+CPP!J9+CPP!M9+BG9 -> 138 | EH9: =EE9+EF9-EG9 -> 4018.17 | EI9: =EL8 -> 30020.985 | EJ9: =EM9+EN9 -> 1480 | EK9: ='DAILY CEM1'!AG10+'DAILY CEM2'!AF10 -> 1090.804 | EL9: =EI9+EJ9-EK9 -> 30410.181 | EM9: 1480 | EN9: 0 | EO9: 1790.43
B10: 8 | C10: =F9 -> 2185.92 | D10: 0 | E10: 64 | F10: =C10+D10-E10 -> 2121.92 | G10: =J9 -> 1907.0496 | H10: 0 | I10: 0 | J10: =G10+H10-I10-[1]Cement!U10 -> 1907.0496 | K10: =P9 -> 0 | L10: 0 | M10: =CPP!D10 -> 0 | N10: 0 | O10: =M10+N10 -> 0 | P10: =K10+L10-O10 -> 0 | Q10: =V9 -> 0 | R10: 0 | S10: =CPP!E10 -> 0 | T10: 0 | U10: =S10+T10 -> 0 | V10: =Q10+R10-U10 -> 0 | W10: =AA9 -> 1063.04 | X10: 0 | Y10: =CPP!H10 -> 0 | Z10: 0 | AA10: =W10+X10-Z10-Y10 -> 1063.04 | AB10: =AE9 -> 0 | AC10: 0 | AD10: =CPP!F10 -> 0 | AE10: =AB10+AC10-AD10 -> 0 | AF10: =AJ9 -> 4018.17 | AG10: 0 | AH10: 0 | AI10: =CPP!G10 -> 137 | AJ10: =AF10+AG10-AI10 -> 3881.17 | AK10: =AN9 -> 0 | AL10: 0 | AM10: 0 | AN10: =AK10+AL10-AM10 -> 0 | AO10: =AS9 -> 0 | AP10: 0 | AQ10: 0 | AR10: =CPP!I10 -> 0 | AS10: =AO10+AP10-AQ10-AR10 -> 0 | AT10: =AX9 -> 986.44 | AU10: 0 | AV10: 233.33 | AW10: =CPP!X10 -> 0 | AX10: =AT10+AU10-AV10-AW10 -> 753.11 | AY10: =BC9 -> 1004.867 | AZ10: 0 | BA10: 0 | BB10: =CPP!M10 -> 0 | BC10: =AY10+AZ10-BA10-BB10 -> 1004.867 | BD10: =BH9 -> 0 | BE10: 0 | BF10: 0 | BG10: =CPP!K10 -> 0 | BH10: =BD10+BE10-BF10-BG10 -> 0 | BI10: =BM9 -> 0 | BJ10: 0 | BK10: 0 | BL10: =CPP!L10 -> 0 | BM10: =BI10+BJ10-BK10-BL10 -> 0 | BN10: =BR9 -> 0 | BO10: 0 | BP10: 0 | BQ10: =CPP!N10 -> 0 | BR10: =BN10+BO10-BP10-BQ10 -> 0 | BS10: =BW9 -> 0 | BT10: 0 | BU10: 0 | BV10: =CPP!O10 -> 0 | BW10: =BS10+BT10-BU10-BV10 -> 0 | BX10: =CB9 -> 0 | BY10: 0 | BZ10: 0 | CB10: =BX10+BY10-BZ10-CA10 -> 0 | CC10: =CG9 -> 0 | CD10: 0 | CE10: 0 | CF10: =CPP!P10 -> 0 | CG10: =CC10+CD10-CE10-CF10 -> 0 | CH10: =CL9 -> 0 | CI10: 0 | CJ10: 0 | CK10: =CPP!Q10 -> 0 | CL10: =CH10+CI10-CJ10-CK10 -> 0 | CM10: =CQ9 -> 0.05 | CN10: 0 | CO10: 0 | CP10: =CPP!R10 -> 0 | CQ10: =CM10+CN10-CP10 -> 0.05 | CR10: =CV9 -> 0 | CS10: 0 | CT10: 0 | CU10: =CPP!S10 -> 0 | CV10: =CR10+CS10-CT10-CU10 -> 0 | CW10: =DA9 -> 0 | CX10: 0 | CY10: 0 | CZ10: =CPP!T10 -> 0 | DA10: =CW10+CX10-CY10-CZ10 -> 0 | DB10: =DF9 -> 0.01 | DC10: 0 | DD10: 0 | DE10: =CPP!U10 -> 0 | DF10: =DB10+DC10-DD10-DE10 -> 0.01 | DG10: =DK9 -> 0 | DH10: 0 | DI10: 0 | DJ10: =CPP!V10 -> 0 | DK10: =DG10+DH10-DI10-DJ10 -> 0 | DL10: =DP9 -> 304 | DM10: 0 | DN10: 0 | DO10: =CPP!W10 -> 0 | DP10: =DL10+DM10-DN10-DO10 -> 304 | DQ10: =DU9 -> 0 | DR10: 0 | DS10: 0 | DT10: =CPP!J10 -> 0 | DU10: =DQ10+DR10-DS10-DT10 -> 0 | DV10: =DZ9 -> 0 | DW10: 0 | DX10: 0 | DY10: 0 | DZ10: =DV10+DW10-DX10-DY10 -> 0 | EA10: =K10+W10+AK10+AO10+AT10+AY10 -> 3054.347 | EB10: 0 | EC10: 0 | ED10: =EA10+EB10-EC10 -> 3054.347 | EE10: =Q10+AB10+AF10 -> 4018.17 | EF10: =R10+AC10+AG10 -> 0 | EG10: =CPP!D10+CPP!E10+CPP!F10+CPP!G10+CPP!H10+CPP!I10+CPP!J10+CPP!M10+BG10 -> 137 | EH10: =EE10+EF10-EG10 -> 3881.17 | EI10: =EL9 -> 30410.181 | EJ10: =EM10+EN10 -> 1390 | EK10: ='DAILY CEM1'!AG11+'DAILY CEM2'!AF11 -> 1204.1415 | EL10: =EI10+EJ10-EK10 -> 30596.04 | EM10: 1390 | EN10: 0 | EO10: 2512.06
B11: 9 | C11: =F10 -> 2121.92 | D11: 0 | E11: 73 | F11: =C11+D11-E11 -> 2048.92 | G11: =J10 -> 1907.0496 | H11: 0 | I11: 0 | J11: =G11+H11-I11-[1]Cement!U11 -> 1882.0496 | K11: =P10 -> 0 | L11: 0 | M11: =CPP!D11 -> 0 | N11: 0 | O11: =M11+N11 -> 0 | P11: =K11+L11-O11 -> 0 | Q11: =V10 -> 0 | R11: 0 | S11: =CPP!E11 -> 0 | T11: 0 | U11: =S11+T11 -> 0 | V11: =Q11+R11-U11 -> 0 | W11: =AA10 -> 1063.04 | X11: 0 | Y11: =CPP!H11 -> 0 | Z11: 0 | AA11: =W11+X11-Z11-Y11 -> 1063.04 | AB11: =AE10 -> 0 | AC11: 0 | AD11: =CPP!F11 -> 0 | AE11: =AB11+AC11-AD11 -> 0 | AF11: =AJ10 -> 3881.17 | AG11: 344.15 | AH11: 0 | AI11: =CPP!G11 -> 130 | AJ11: =AF11+AG11-AI11 -> 4095.32 | AK11: =AN10 -> 0 | AL11: 0 | AM11: 0 | AN11: =AK11+AL11-AM11 -> 0 | AO11: =AS10 -> 0 | AP11: 0 | AQ11: 0 | AR11: =CPP!I11 -> 0 | AS11: =AO11+AP11-AQ11-AR11 -> 0 | AT11: =AX10 -> 753.11 | AU11: 0 | AV11: 250 | AW11: =CPP!X11 -> 0 | AX11: =AT11+AU11-AV11-AW11 -> 503.11 | AY11: =BC10 -> 1004.867 | AZ11: 942.44 | BA11: 0 | BB11: =CPP!M11 -> 0 | BC11: =AY11+AZ11-BA11-BB11 -> 1947.307 | BD11: =BH10 -> 0 | BE11: 0 | BF11: 0 | BG11: =CPP!K11 -> 0 | BH11: =BD11+BE11-BF11-BG11 -> 0 | BI11: =BM10 -> 0 | BJ11: 0 | BK11: 0 | BL11: =CPP!L11 -> 0 | BM11: =BI11+BJ11-BK11-BL11 -> 0 | BN11: =BR10 -> 0 | BO11: 0 | BP11: 0 | BQ11: =CPP!N11 -> 0 | BR11: =BN11+BO11-BP11-BQ11 -> 0 | BS11: =BW10 -> 0 | BT11: 0 | BU11: 0 | BV11: =CPP!O11 -> 0 | BW11: =BS11+BT11-BU11-BV11 -> 0 | BX11: =CB10 -> 0 | BY11: 0 | BZ11: 0 | CB11: =BX11+BY11-BZ11-CA11 -> 0 | CC11: =CG10 -> 0 | CD11: 0 | CE11: 0 | CF11: =CPP!P11 -> 0 | CG11: =CC11+CD11-CE11-CF11 -> 0 | CH11: =CL10 -> 0 | CI11: 0 | CJ11: 0 | CK11: =CPP!Q11 -> 0 | CL11: =CH11+CI11-CJ11-CK11 -> 0 | CM11: =CQ10 -> 0.05 | CN11: 0 | CO11: 0 | CP11: =CPP!R11 -> 0 | CQ11: =CM11+CN11-CP11 -> 0.05 | CR11: =CV10 -> 0 | CS11: 0 | CT11: 0 | CU11: =CPP!S11 -> 0 | CV11: =CR11+CS11-CT11-CU11 -> 0 | CW11: =DA10 -> 0 | CX11: 0 | CY11: 0 | CZ11: =CPP!T11 -> 0 | DA11: =CW11+CX11-CY11-CZ11 -> 0 | DB11: =DF10 -> 0.01 | DC11: 0 | DD11: 0 | DE11: =CPP!U11 -> 0 | DF11: =DB11+DC11-DD11-DE11 -> 0.01 | DG11: =DK10 -> 0 | DH11: 0 | DI11: 0 | DJ11: =CPP!V11 -> 0 | DK11: =DG11+DH11-DI11-DJ11 -> 0 | DL11: =DP10 -> 304 | DM11: 0 | DN11: 0 | DO11: =CPP!W11 -> 0 | DP11: =DL11+DM11-DN11-DO11 -> 304 | DQ11: =DU10 -> 0 | DR11: 0 | DS11: 0 | DT11: =CPP!J11 -> 0 | DU11: =DQ11+DR11-DS11-DT11 -> 0 | DV11: =DZ10 -> 0 | DW11: 0 | DX11: 0 | DY11: 0 | DZ11: =DV11+DW11-DX11-DY11 -> 0 | EA11: =K11+W11+AK11+AO11+AT11+AY11 -> 2821.017 | EB11: 0 | EC11: 0 | ED11: =EA11+EB11-EC11 -> 2821.017 | EE11: =Q11+AB11+AF11 -> 3881.17 | EF11: =R11+AC11+AG11 -> 344.15 | EG11: =CPP!D11+CPP!E11+CPP!F11+CPP!G11+CPP!H11+CPP!I11+CPP!J11+CPP!M11+BG11 -> 130 | EH11: =EE11+EF11-EG11 -> 4095.32 | EI11: =EL10 -> 30596.04 | EJ11: =EM11+EN11 -> 1430 | EK11: ='DAILY CEM1'!AG12+'DAILY CEM2'!AF12 -> 1365.683 | EL11: =EI11+EJ11-EK11 -> 30660.357 | EM11: 1430 | EN11: 0 | EO11: 2398.87
B12: 10 | C12: =F11 -> 2048.92 | D12: 0 | E12: 95 | F12: =C12+D12-E12 -> 1953.92 | G12: =J11 -> 1882.0496 | H12: 0 | I12: 0 | J12: =G12+H12-I12-[1]Cement!U12 -> 1843.0496 | K12: =P11 -> 0 | L12: 0 | M12: =CPP!D12 -> 0 | N12: 0 | O12: =M12+N12 -> 0 | P12: =K12+L12-O12 -> 0 | Q12: =V11 -> 0 | R12: 0 | S12: =CPP!E12 -> 0 | T12: 0 | U12: =S12+T12 -> 0 | V12: =Q12+R12-U12 -> 0 | W12: =AA11 -> 1063.04 | X12: 0 | Y12: =CPP!H12 -> 0 | Z12: 0 | AA12: =W12+X12-Z12-Y12 -> 1063.04 | AB12: =AE11 -> 0 | AC12: 0 | AD12: =CPP!F12 -> 0 | AE12: =AB12+AC12-AD12 -> 0 | AF12: =AJ11 -> 4095.32 | AG12: 251.7 | AH12: 0 | AI12: =CPP!G12 -> 131 | AJ12: =AF12+AG12-AI12 -> 4216.02 | AK12: =AN11 -> 0 | AL12: 0 | AM12: 0 | AN12: =AK12+AL12-AM12 -> 0 | AO12: =AS11 -> 0 | AP12: 0 | AQ12: 0 | AR12: =CPP!I12 -> 0 | AS12: =AO12+AP12-AQ12-AR12 -> 0 | AT12: =AX11 -> 503.11 | AU12: 0 | AV12: 260 | AW12: =CPP!X12 -> 0 | AX12: =AT12+AU12-AV12-AW12 -> 243.11 | AY12: =BC11 -> 1947.307 | AZ12: 191.78 | BA12: 0 | BB12: =CPP!M12 -> 0 | BC12: =AY12+AZ12-BA12-BB12 -> 2139.087 | BD12: =BH11 -> 0 | BE12: 0 | BF12: 0 | BG12: =CPP!K12 -> 0 | BH12: =BD12+BE12-BF12-BG12 -> 0 | BI12: =BM11 -> 0 | BJ12: 0 | BK12: 0 | BL12: =CPP!L12 -> 0 | BM12: =BI12+BJ12-BK12-BL12 -> 0 | BN12: =BR11 -> 0 | BO12: 0 | BP12: 0 | BQ12: =CPP!N12 -> 0 | BR12: =BN12+BO12-BP12-BQ12 -> 0 | BS12: =BW11 -> 0 | BT12: 0 | BU12: 0 | BV12: =CPP!O12 -> 0 | BW12: =BS12+BT12-BU12-BV12 -> 0 | BX12: =CB11 -> 0 | BY12: 0 | BZ12: 0 | CB12: =BX12+BY12-BZ12-CA12 -> 0 | CC12: =CG11 -> 0 | CD12: 0 | CE12: 0 | CF12: =CPP!P12 -> 0 | CG12: =CC12+CD12-CE12-CF12 -> 0 | CH12: =CL11 -> 0 | CI12: 0 | CJ12: 0 | CK12: =CPP!Q12 -> 0 | CL12: =CH12+CI12-CJ12-CK12 -> 0 | CM12: =CQ11 -> 0.05 | CN12: 0 | CO12: 0 | CP12: =CPP!R12 -> 0 | CQ12: =CM12+CN12-CP12 -> 0.05 | CR12: =CV11 -> 0 | CS12: 0 | CT12: 0 | CU12: =CPP!S12 -> 0 | CV12: =CR12+CS12-CT12-CU12 -> 0 | CW12: =DA11 -> 0 | CX12: 0 | CY12: 0 | CZ12: =CPP!T12 -> 0 | DA12: =CW12+CX12-CY12-CZ12 -> 0 | DB12: =DF11 -> 0.01 | DC12: 0 | DD12: 0 | DE12: =CPP!U12 -> 0 | DF12: =DB12+DC12-DD12-DE12 -> 0.01 | DG12: =DK11 -> 0 | DH12: 0 | DI12: 0 | DJ12: =CPP!V12 -> 0 | DK12: =DG12+DH12-DI12-DJ12 -> 0 | DL12: =DP11 -> 304 | DM12: 0 | DN12: 0 | DO12: =CPP!W12 -> 0 | DP12: =DL12+DM12-DN12-DO12 -> 304 | DQ12: =DU11 -> 0 | DR12: 0 | DS12: 0 | DT12: =CPP!J12 -> 0 | DU12: =DQ12+DR12-DS12-DT12 -> 0 | DV12: =DZ11 -> 0 | DW12: 0 | DX12: 0 | DY12: 0 | DZ12: =DV12+DW12-DX12-DY12 -> 0 | EA12: =K12+W12+AK12+AO12+AT12+AY12 -> 3513.457 | EB12: 0 | EC12: 0 | ED12: =EA12+EB12-EC12 -> 3513.457 | EE12: =Q12+AB12+AF12 -> 4095.32 | EF12: =R12+AC12+AG12 -> 251.7 | EG12: =CPP!D12+CPP!E12+CPP!F12+CPP!G12+CPP!H12+CPP!I12+CPP!J12+CPP!M12+BG12 -> 131 | EH12: =EE12+EF12-EG12 -> 4216.02 | EI12: =EL11 -> 30660.357 | EJ12: =EM12+EN12 -> 1510 | EK12: ='DAILY CEM1'!AG13+'DAILY CEM2'!AF13 -> 2075.32 | EL12: =EI12+EJ12-EK12 -> 30095.037 | EM12: 1510 | EN12: 0 | EO12: 2254.04
B13: 11 | C13: =F12 -> 1953.92 | D13: 0 | E13: 47 | F13: =C13+D13-E13 -> 1906.92 | G13: =J12 -> 1843.0496 | H13: 0 | I13: 0 | J13: =G13+H13-I13-[1]Cement!U13 -> 1806.0496 | K13: =P12 -> 0 | L13: 0 | M13: =CPP!D13 -> 0 | N13: 0 | O13: =M13+N13 -> 0 | P13: =K13+L13-O13 -> 0 | Q13: =V12 -> 0 | R13: 0 | S13: =CPP!E13 -> 0 | T13: 0 | U13: =S13+T13 -> 0 | V13: =Q13+R13-U13 -> 0 | W13: =AA12 -> 1063.04 | X13: 0 | Y13: =CPP!H13 -> 0 | Z13: 0 | AA13: =W13+X13-Z13-Y13 -> 1063.04 | AB13: =AE12 -> 0 | AC13: 0 | AD13: =CPP!F13 -> 0 | AE13: =AB13+AC13-AD13 -> 0 | AF13: =AJ12 -> 4216.02 | AG13: 0 | AH13: 0 | AI13: =CPP!G13 -> 137 | AJ13: =AF13+AG13-AI13 -> 4079.02 | AK13: =AN12 -> 0 | AL13: 0 | AM13: 0 | AN13: =AK13+AL13-AM13 -> 0 | AO13: =AS12 -> 0 | AP13: 0 | AQ13: 0 | AR13: =CPP!I13 -> 0 | AS13: =AO13+AP13-AQ13-AR13 -> 0 | AT13: =AX12 -> 243.11 | AU13: 0 | AV13: 215 | AW13: =CPP!X13 -> 0 | AX13: =AT13+AU13-AV13-AW13 -> 28.11 | AY13: =BC12 -> 2139.087 | AZ13: 157.12 | BA13: 0 | BB13: =CPP!M13 -> 0 | BC13: =AY13+AZ13-BA13-BB13 -> 2296.207 | BD13: =BH12 -> 0 | BE13: 0 | BF13: 0 | BG13: =CPP!K13 -> 0 | BH13: =BD13+BE13-BF13-BG13 -> 0 | BI13: =BM12 -> 0 | BJ13: 0 | BK13: 0 | BL13: =CPP!L13 -> 0 | BM13: =BI13+BJ13-BK13-BL13 -> 0 | BN13: =BR12 -> 0 | BO13: 0 | BP13: 0 | BQ13: =CPP!N13 -> 0 | BR13: =BN13+BO13-BP13-BQ13 -> 0 | BS13: =BW12 -> 0 | BT13: 0 | BU13: 0 | BV13: =CPP!O13 -> 0 | BW13: =BS13+BT13-BU13-BV13 -> 0 | BX13: =CB12 -> 0 | BY13: 0 | BZ13: 0 | CB13: =BX13+BY13-BZ13-CA13 -> 0 | CC13: =CG12 -> 0 | CD13: 0 | CE13: 0 | CF13: =CPP!P13 -> 0 | CG13: =CC13+CD13-CE13-CF13 -> 0 | CH13: =CL12 -> 0 | CI13: 0 | CJ13: 0 | CK13: =CPP!Q13 -> 0 | CL13: =CH13+CI13-CJ13-CK13 -> 0 | CM13: =CQ12 -> 0.05 | CN13: 0 | CO13: 0 | CP13: =CPP!R13 -> 0 | CQ13: =CM13+CN13-CP13 -> 0.05 | CR13: =CV12 -> 0 | CS13: 0 | CT13: 0 | CU13: =CPP!S13 -> 0 | CV13: =CR13+CS13-CT13-CU13 -> 0 | CW13: =DA12 -> 0 | CX13: 0 | CY13: 0 | CZ13: =CPP!T13 -> 0 | DA13: =CW13+CX13-CY13-CZ13 -> 0 | DB13: =DF12 -> 0.01 | DC13: 0 | DD13: 0 | DE13: =CPP!U13 -> 0 | DF13: =DB13+DC13-DD13-DE13 -> 0.01 | DG13: =DK12 -> 0 | DH13: 0 | DI13: 0 | DJ13: =CPP!V13 -> 0 | DK13: =DG13+DH13-DI13-DJ13 -> 0 | DL13: =DP12 -> 304 | DM13: 0 | DN13: 0 | DO13: =CPP!W13 -> 0 | DP13: =DL13+DM13-DN13-DO13 -> 304 | DQ13: =DU12 -> 0 | DR13: 0 | DS13: 0 | DT13: =CPP!J13 -> 0 | DU13: =DQ13+DR13-DS13-DT13 -> 0 | DV13: =DZ12 -> 0 | DW13: 0 | DX13: 0 | DY13: 0 | DZ13: =DV13+DW13-DX13-DY13 -> 0 | EA13: =K13+W13+AK13+AO13+AT13+AY13 -> 3445.237 | EB13: 0 | EC13: 0 | ED13: =EA13+EB13-EC13 -> 3445.237 | EE13: =Q13+AB13+AF13 -> 4216.02 | EF13: =R13+AC13+AG13 -> 0 | EG13: =CPP!D13+CPP!E13+CPP!F13+CPP!G13+CPP!H13+CPP!I13+CPP!J13+CPP!M13+BG13 -> 137 | EH13: =EE13+EF13-EG13 -> 4079.02 | EI13: =EL12 -> 30095.037 | EJ13: =EM13+EN13 -> 1290 | EK13: ='DAILY CEM1'!AG14+'DAILY CEM2'!AF14 -> 2304 | EL13: =EI13+EJ13-EK13 -> 29081.037 | EM13: 1290 | EN13: 0 | EO13: 1778.35
B14: 12 | C14: =F13 -> 1906.92 | D14: 0 | E14: 59 | F14: =C14+D14-E14 -> 1847.92 | G14: =J13 -> 1806.0496 | H14: 0 | I14: 0 | J14: =G14+H14-I14-[1]Cement!U14 -> 1761.0496 | K14: =P13 -> 0 | L14: 0 | M14: =CPP!D14 -> 0 | N14: 0 | O14: =M14+N14 -> 0 | P14: =K14+L14-O14 -> 0 | Q14: =V13 -> 0 | R14: 0 | S14: =CPP!E14 -> 0 | T14: 0 | U14: =S14+T14 -> 0 | V14: =Q14+R14-U14 -> 0 | W14: =AA13 -> 1063.04 | X14: 0 | Y14: =CPP!H14 -> 0 | Z14: 286.67 | AA14: =W14+X14-Z14-Y14 -> 776.37 | AB14: =AE13 -> 0 | AC14: 0 | AD14: =CPP!F14 -> 0 | AE14: =AB14+AC14-AD14 -> 0 | AF14: =AJ13 -> 4079.02 | AG14: 95 | AH14: 0 | AI14: =CPP!G14 -> 137 | AJ14: =AF14+AG14-AI14 -> 4037.02 | AK14: =AN13 -> 0 | AL14: 0 | AM14: 0 | AN14: =AK14+AL14-AM14 -> 0 | AO14: =AS13 -> 0 | AP14: 0 | AQ14: 0 | AR14: =CPP!I14 -> 0 | AS14: =AO14+AP14-AQ14-AR14 -> 0 | AT14: =AX13 -> 28.11 | AU14: 0 | AV14: 0 | AW14: =CPP!X14 -> 0 | AX14: =AT14+AU14-AV14-AW14 -> 28.11 | AY14: =BC13 -> 2296.207 | AZ14: 186.68 | BA14: 0 | BB14: =CPP!M14 -> 0 | BC14: =AY14+AZ14-BA14-BB14 -> 2482.887 | BD14: =BH13 -> 0 | BE14: 0 | BF14: 0 | BG14: =CPP!K14 -> 0 | BH14: =BD14+BE14-BF14-BG14 -> 0 | BI14: =BM13 -> 0 | BJ14: 0 | BK14: 0 | BL14: =CPP!L14 -> 0 | BM14: =BI14+BJ14-BK14-BL14 -> 0 | BN14: =BR13 -> 0 | BO14: 0 | BP14: 0 | BQ14: =CPP!N14 -> 0 | BR14: =BN14+BO14-BP14-BQ14 -> 0 | BS14: =BW13 -> 0 | BT14: 0 | BU14: 0 | BV14: =CPP!O14 -> 0 | BW14: =BS14+BT14-BU14-BV14 -> 0 | BX14: =CB13 -> 0 | BY14: 0 | BZ14: 0 | CB14: =BX14+BY14-BZ14-CA14 -> 0 | CC14: =CG13 -> 0 | CD14: 0 | CE14: 0 | CF14: =CPP!P14 -> 0 | CG14: =CC14+CD14-CE14-CF14 -> 0 | CH14: =CL13 -> 0 | CI14: 0 | CJ14: 0 | CK14: =CPP!Q14 -> 0 | CL14: =CH14+CI14-CJ14-CK14 -> 0 | CM14: =CQ13 -> 0.05 | CN14: 0 | CO14: 0 | CP14: =CPP!R14 -> 0 | CQ14: =CM14+CN14-CP14 -> 0.05 | CR14: =CV13 -> 0 | CS14: 0 | CT14: 0 | CU14: =CPP!S14 -> 0 | CV14: =CR14+CS14-CT14-CU14 -> 0 | CW14: =DA13 -> 0 | CX14: 0 | CY14: 0 | CZ14: =CPP!T14 -> 0 | DA14: =CW14+CX14-CY14-CZ14 -> 0 | DB14: =DF13 -> 0.01 | DC14: 0 | DD14: 0 | DE14: =CPP!U14 -> 0 | DF14: =DB14+DC14-DD14-DE14 -> 0.01 | DG14: =DK13 -> 0 | DH14: 0 | DI14: 0 | DJ14: =CPP!V14 -> 0 | DK14: =DG14+DH14-DI14-DJ14 -> 0 | DL14: =DP13 -> 304 | DM14: 0 | DN14: 0 | DO14: =CPP!W14 -> 0 | DP14: =DL14+DM14-DN14-DO14 -> 304 | DQ14: =DU13 -> 0 | DR14: 0 | DS14: 0 | DT14: =CPP!J14 -> 0 | DU14: =DQ14+DR14-DS14-DT14 -> 0 | DV14: =DZ13 -> 0 | DW14: 0 | DX14: 0 | DY14: 0 | DZ14: =DV14+DW14-DX14-DY14 -> 0 | EA14: =K14+W14+AK14+AO14+AT14+AY14 -> 3387.357 | EB14: 0 | EC14: 0 | ED14: =EA14+EB14-EC14 -> 3387.357 | EE14: =Q14+AB14+AF14 -> 4079.02 | EF14: =R14+AC14+AG14 -> 95 | EG14: =CPP!D14+CPP!E14+CPP!F14+CPP!G14+CPP!H14+CPP!I14+CPP!J14+CPP!M14+BG14 -> 137 | EH14: =EE14+EF14-EG14 -> 4037.02 | EI14: =EL13 -> 29081.037 | EJ14: =EM14+EN14 -> 1710 | EK14: ='DAILY CEM1'!AG15+'DAILY CEM2'!AF15 -> 2081.504 | EL14: =EI14+EJ14-EK14 -> 28709.533 | EM14: 1710 | EN14: 0 | EO14: 1958.66
B15: 13 | C15: =F14 -> 1847.92 | D15: 0 | E15: 46 | F15: =C15+D15-E15 -> 1801.92 | G15: =J14 -> 1761.0496 | H15: 0 | I15: 0 | J15: =G15+H15-I15-[1]Cement!U15 -> 1695.0496 | K15: =P14 -> 0 | L15: 0 | M15: =CPP!D15 -> 0 | N15: 0 | O15: =M15+N15 -> 0 | P15: =K15+L15-O15 -> 0 | Q15: =V14 -> 0 | R15: 0 | S15: =CPP!E15 -> 0 | T15: 0 | U15: =S15+T15 -> 0 | V15: =Q15+R15-U15 -> 0 | W15: =AA14 -> 776.37 | X15: 0 | Y15: =CPP!H15 -> 0 | Z15: 242.22 | AA15: =W15+X15-Z15-Y15 -> 534.15 | AB15: =AE14 -> 0 | AC15: 0 | AD15: =CPP!F15 -> 0 | AE15: =AB15+AC15-AD15 -> 0 | AF15: =AJ14 -> 4037.02 | AG15: 0 | AH15: 0 | AI15: =CPP!G15 -> 126 | AJ15: =AF15+AG15-AH15-AI15 -> 3911.02 | AK15: =AN14 -> 0 | AL15: 0 | AM15: 0 | AN15: =AK15+AL15-AM15 -> 0 | AO15: =AS14 -> 0 | AP15: 0 | AQ15: 0 | AR15: =CPP!I15 -> 0 | AS15: =AO15+AP15-AQ15-AR15 -> 0 | AT15: =AX14 -> 28.11 | AU15: 0 | AV15: 0 | AW15: =CPP!X15 -> 0 | AX15: =AT15+AU15-AV15-AW15 -> 28.11 | AY15: =BC14 -> 2482.887 | AZ15: 0 | BA15: 0 | BB15: =CPP!M15 -> 0 | BC15: =AY15+AZ15-BA15-BB15 -> 2482.887 | BD15: =BH14 -> 0 | BE15: 0 | BF15: 0 | BG15: =CPP!K15 -> 0 | BH15: =BD15+BE15-BF15-BG15 -> 0 | BI15: =BM14 -> 0 | BJ15: 0 | BK15: 0 | BL15: =CPP!L15 -> 0 | BM15: =BI15+BJ15-BK15-BL15 -> 0 | BN15: =BR14 -> 0 | BO15: 0 | BP15: 0 | BQ15: =CPP!N15 -> 0 | BR15: =BN15+BO15-BP15-BQ15 -> 0 | BS15: =BW14 -> 0 | BT15: 0 | BU15: 0 | BV15: =CPP!O15 -> 0 | BW15: =BS15+BT15-BU15-BV15 -> 0 | BX15: =CB14 -> 0 | BY15: 0 | BZ15: 0 | CB15: =BX15+BY15-BZ15-CA15 -> 0 | CC15: =CG14 -> 0 | CD15: 0 | CE15: 0 | CF15: =CPP!P15 -> 0 | CG15: =CC15+CD15-CE15-CF15 -> 0 | CH15: =CL14 -> 0 | CI15: 0 | CJ15: 0 | CK15: =CPP!Q15 -> 0 | CL15: =CH15+CI15-CJ15-CK15 -> 0 | CM15: =CQ14 -> 0.05 | CN15: 0 | CO15: 0 | CP15: =CPP!R15 -> 0 | CQ15: =CM15+CN15-CP15 -> 0.05 | CR15: =CV14 -> 0 | CS15: 0 | CT15: 0 | CU15: =CPP!S15 -> 0 | CV15: =CR15+CS15-CT15-CU15 -> 0 | CW15: =DA14 -> 0 | CX15: 0 | CY15: 0 | CZ15: =CPP!T15 -> 0 | DA15: =CW15+CX15-CY15-CZ15 -> 0 | DB15: =DF14 -> 0.01 | DC15: 0 | DD15: 0 | DE15: =CPP!U15 -> 0 | DF15: =DB15+DC15-DD15-DE15 -> 0.01 | DG15: =DK14 -> 0 | DH15: 0 | DI15: 0 | DJ15: =CPP!V15 -> 0 | DK15: =DG15+DH15-DI15-DJ15 -> 0 | DL15: =DP14 -> 304 | DM15: 0 | DN15: 0 | DO15: =CPP!W15 -> 0 | DP15: =DL15+DM15-DN15-DO15 -> 304 | DQ15: =DU14 -> 0 | DR15: 0 | DS15: 0 | DT15: =CPP!J15 -> 0 | DU15: =DQ15+DR15-DS15-DT15 -> 0 | DV15: =DZ14 -> 0 | DW15: 0 | DX15: 0 | DY15: 0 | DZ15: =DV15+DW15-DX15-DY15 -> 0 | EA15: =K15+W15+AK15+AO15+AT15+AY15 -> 3287.367 | EB15: 0 | EC15: 0 | ED15: =EA15+EB15-EC15 -> 3287.367 | EE15: =Q15+AB15+AF15 -> 4037.02 | EF15: =R15+AC15+AG15 -> 0 | EG15: =CPP!D15+CPP!E15+CPP!F15+CPP!G15+CPP!H15+CPP!I15+CPP!J15+CPP!M15+BG15 -> 126 | EH15: =EE15+EF15-EG15 -> 3911.02 | EI15: =EL14 -> 28709.533 | EJ15: =EM15+EN15 -> 1304 | EK15: ='DAILY CEM1'!AG16+'DAILY CEM2'!AF16 -> 2171.603 | EL15: =EI15+EJ15-EK15 -> 27841.93 | EM15: 1304 | EN15: 0 | EO15: 2155.47
B16: 14 | C16: =F15 -> 1801.92 | D16: 0 | E16: 61 | F16: =C16+D16-E16 -> 1740.92 | G16: =J15 -> 1695.0496 | H16: 0 | I16: 0 | J16: =G16+H16-I16-[1]Cement!U16 -> 1628.0496 | K16: =P15 -> 0 | L16: 0 | M16: =CPP!D16 -> 0 | N16: 0 | O16: =M16+N16 -> 0 | P16: =K16+L16-O16 -> 0 | Q16: =V15 -> 0 | R16: 0 | S16: =CPP!E16 -> 0 | T16: 0 | U16: =S16+T16 -> 0 | V16: =Q16+R16-U16 -> 0 | W16: =AA15 -> 534.15 | X16: 0 | Y16: =CPP!H16 -> 0 | Z16: 227.78 | AA16: =W16+X16-Z16-Y16 -> 306.37 | AB16: =AE15 -> 0 | AC16: 0 | AD16: =CPP!F16 -> 0 | AE16: =AB16+AC16-AD16 -> 0 | AF16: =AJ15 -> 3911.02 | AG16: 0 | AH16: 0 | AI16: =CPP!G16 -> 130 | AJ16: =AF16+AG16-AH16-AI16 -> 3781.02 | AK16: =AN15 -> 0 | AL16: 0 | AM16: 0 | AN16: =AK16+AL16-AM16 -> 0 | AO16: =AS15 -> 0 | AP16: 0 | AQ16: 0 | AR16: =CPP!I16 -> 0 | AS16: =AO16+AP16-AQ16-AR16 -> 0 | AT16: =AX15 -> 28.11 | AU16: 0 | AV16: 0 | AW16: =CPP!X16 -> 0 | AX16: =AT16+AU16-AV16-AW16 -> 28.11 | AY16: =BC15 -> 2482.887 | AZ16: 0 | BA16: 0 | BB16: =CPP!M16 -> 0 | BC16: =AY16+AZ16-BA16-BB16 -> 2482.887 | BD16: =BH15 -> 0 | BE16: 0 | BF16: 0 | BG16: =CPP!K16 -> 0 | BH16: =BD16+BE16-BF16-BG16 -> 0 | BI16: =BM15 -> 0 | BJ16: 0 | BK16: 0 | BL16: =CPP!L16 -> 0 | BM16: =BI16+BJ16-BK16-BL16 -> 0 | BN16: =BR15 -> 0 | BO16: 0 | BP16: 0 | BQ16: =CPP!N16 -> 0 | BR16: =BN16+BO16-BP16-BQ16 -> 0 | BS16: =BW15 -> 0 | BT16: 0 | BU16: 0 | BV16: =CPP!O16 -> 0 | BW16: =BS16+BT16-BU16-BV16 -> 0 | BX16: =CB15 -> 0 | BY16: 0 | BZ16: 0 | CB16: =BX16+BY16-BZ16-CA16 -> 0 | CC16: =CG15 -> 0 | CD16: 0 | CE16: 0 | CF16: =CPP!P16 -> 0 | CG16: =CC16+CD16-CE16-CF16 -> 0 | CH16: =CL15 -> 0 | CI16: 0 | CJ16: 0 | CK16: =CPP!Q16 -> 0 | CL16: =CH16+CI16-CJ16-CK16 -> 0 | CM16: =CQ15 -> 0.05 | CN16: 0 | CO16: 0 | CP16: =CPP!R16 -> 0 | CQ16: =CM16+CN16-CP16 -> 0.05 | CR16: =CV15 -> 0 | CS16: 0 | CT16: 0 | CU16: =CPP!S16 -> 0 | CV16: =CR16+CS16-CT16-CU16 -> 0 | CW16: =DA15 -> 0 | CX16: 0 | CY16: 0 | CZ16: =CPP!T16 -> 0 | DA16: =CW16+CX16-CY16-CZ16 -> 0 | DB16: =DF15 -> 0.01 | DC16: 0 | DD16: 0 | DE16: =CPP!U16 -> 0 | DF16: =DB16+DC16-DD16-DE16 -> 0.01 | DG16: =DK15 -> 0 | DH16: 0 | DI16: 0 | DJ16: =CPP!V16 -> 0 | DK16: =DG16+DH16-DI16-DJ16 -> 0 | DL16: =DP15 -> 304 | DM16: 0 | DN16: 0 | DO16: =CPP!W16 -> 0 | DP16: =DL16+DM16-DN16-DO16 -> 304 | DQ16: =DU15 -> 0 | DR16: 0 | DS16: 0 | DT16: =CPP!J16 -> 0 | DU16: =DQ16+DR16-DS16-DT16 -> 0 | DV16: =DZ15 -> 0 | DW16: 0 | DX16: 0 | DY16: 0 | DZ16: =DV16+DW16-DX16-DY16 -> 0 | EA16: =K16+W16+AK16+AO16+AT16+AY16 -> 3045.147 | EB16: 0 | EC16: 0 | ED16: =EA16+EB16-EC16 -> 3045.147 | EE16: =Q16+AB16+AF16 -> 3911.02 | EF16: =R16+AC16+AG16 -> 0 | EG16: =CPP!D16+CPP!E16+CPP!F16+CPP!G16+CPP!H16+CPP!I16+CPP!J16+CPP!M16+BG16 -> 130 | EH16: =EE16+EF16-EG16 -> 3781.02 | EI16: =EL15 -> 27841.93 | EJ16: =EM16+EN16 -> 1305 | EK16: ='DAILY CEM1'!AG17+'DAILY CEM2'!AF17 -> 2083.58 | EL16: =EI16+EJ16-EK16 -> 27063.35 | EM16: 1305 | EN16: 0 | EO16: 1826.06
B17: 15 | C17: =F16 -> 1740.92 | D17: 0 | E17: 63 | F17: =C17+D17-E17 -> 1677.92 | G17: =J16 -> 1628.0496 | H17: 0 | I17: 0 | J17: =G17+H17-I17-[1]Cement!U17 -> 1531.0496 | K17: =P16 -> 0 | L17: 0 | M17: =CPP!D17 -> 0 | N17: 0 | O17: =M17+N17 -> 0 | P17: =K17+L17-O17 -> 0 | Q17: =V16 -> 0 | R17: 0 | S17: =CPP!E17 -> 0 | T17: 0 | U17: =S17+T17 -> 0 | V17: =Q17+R17-U17 -> 0 | W17: =AA16 -> 306.37 | X17: 0 | Y17: =CPP!H17 -> 0 | Z17: 205.23 | AA17: =W17+X17-Z17-Y17 -> 101.14 | AB17: =AE16 -> 0 | AC17: 0 | AD17: =CPP!F17 -> 0 | AE17: =AB17+AC17-AD17 -> 0 | AF17: =AJ16 -> 3781.02 | AG17: 764.75 | AH17: 0 | AI17: =CPP!G17 -> 147 | AJ17: =AF17+AG17-AH17-AI17 -> 4398.77 | AK17: =AN16 -> 0 | AL17: 0 | AM17: 0 | AN17: =AK17+AL17-AM17 -> 0 | AO17: =AS16 -> 0 | AP17: 0 | AQ17: 0 | AR17: =CPP!I17 -> 0 | AS17: =AO17+AP17-AQ17-AR17 -> 0 | AT17: =AX16 -> 28.11 | AU17: 0 | AV17: 28.1 | AW17: =CPP!X17 -> 0 | AX17: =AT17+AU17-AV17-AW17 -> 0.01 | AY17: =BC16 -> 2482.887 | AZ17: 155.24 | BA17: 0 | BB17: =CPP!M17 -> 0 | BC17: =AY17+AZ17-BA17-BB17 -> 2638.127 | BD17: =BH16 -> 0 | BE17: 0 | BF17: 0 | BG17: =CPP!K17 -> 0 | BH17: =BD17+BE17-BF17-BG17 -> 0 | BI17: =BM16 -> 0 | BJ17: 0 | BK17: 0 | BL17: =CPP!L17 -> 0 | BM17: =BI17+BJ17-BK17-BL17 -> 0 | BN17: =BR16 -> 0 | BO17: 0 | BP17: 0 | BQ17: =CPP!N17 -> 0 | BR17: =BN17+BO17-BP17-BQ17 -> 0 | BS17: =BW16 -> 0 | BT17: 0 | BU17: 0 | BV17: =CPP!O17 -> 0 | BW17: =BS17+BT17-BU17-BV17 -> 0 | BX17: =CB16 -> 0 | BY17: 0 | BZ17: 0 | CB17: =BX17+BY17-BZ17-CA17 -> 0 | CC17: =CG16 -> 0 | CD17: 0 | CE17: 0 | CF17: =CPP!P17 -> 0 | CG17: =CC17+CD17-CE17-CF17 -> 0 | CH17: =CL16 -> 0 | CI17: 0 | CJ17: 0 | CK17: =CPP!Q17 -> 0 | CL17: =CH17+CI17-CJ17-CK17 -> 0 | CM17: =CQ16 -> 0.05 | CN17: 0 | CO17: 0 | CP17: =CPP!R17 -> 0 | CQ17: =CM17+CN17-CP17 -> 0.05 | CR17: =CV16 -> 0 | CS17: 0 | CT17: 0 | CU17: =CPP!S17 -> 0 | CV17: =CR17+CS17-CT17-CU17 -> 0 | CW17: =DA16 -> 0 | CX17: 0 | CY17: 0 | CZ17: =CPP!T17 -> 0 | DA17: =CW17+CX17-CY17-CZ17 -> 0 | DB17: =DF16 -> 0.01 | DC17: 0 | DD17: 0 | DE17: =CPP!U17 -> 0 | DF17: =DB17+DC17-DD17-DE17 -> 0.01 | DG17: =DK16 -> 0 | DH17: 0 | DI17: 0 | DJ17: =CPP!V17 -> 0 | DK17: =DG17+DH17-DI17-DJ17 -> 0 | DL17: =DP16 -> 304 | DM17: 0 | DN17: 0 | DO17: =CPP!W17 -> 0 | DP17: =DL17+DM17-DN17-DO17 -> 304 | DQ17: =DU16 -> 0 | DR17: 0 | DS17: 0 | DT17: =CPP!J17 -> 0 | DU17: =DQ17+DR17-DS17-DT17 -> 0 | DV17: =DZ16 -> 0 | DW17: 0 | DX17: 0 | DY17: 0 | DZ17: =DV17+DW17-DX17-DY17 -> 0 | EA17: =K17+W17+AK17+AO17+AT17+AY17 -> 2817.367 | EB17: 0 | EC17: 0 | ED17: =EA17+EB17-EC17 -> 2817.367 | EE17: =Q17+AB17+AF17 -> 3781.02 | EF17: =R17+AC17+AG17 -> 764.75 | EG17: =CPP!D17+CPP!E17+CPP!F17+CPP!G17+CPP!H17+CPP!I17+CPP!J17+CPP!M17+BG17 -> 147 | EH17: =EE17+EF17-EG17 -> 4398.77 | EI17: =EL16 -> 27063.35 | EJ17: =EM17+EN17 -> 1350 | EK17: ='DAILY CEM1'!AG18+'DAILY CEM2'!AF18 -> 1946.668 | EL17: =EI17+EJ17-EK17 -> 26466.682 | EM17: 1350 | EN17: 0 | EO17: 2287.62
B18: 16 | C18: =F17 -> 1677.92 | D18: 0 | E18: 72 | F18: =C18+D18-E18 -> 1605.92 | G18: =J17 -> 1531.0496 | H18: 0 | I18: 0 | J18: =G18+H18-I18-[1]Cement!U18 -> 1440.0496 | K18: =P17 -> 0 | L18: 0 | M18: =CPP!D18 -> 0 | N18: 0 | O18: =M18+N18 -> 0 | P18: =K18+L18-O18 -> 0 | Q18: =V17 -> 0 | R18: 0 | S18: =CPP!E18 -> 0 | T18: 0 | U18: =S18+T18 -> 0 | V18: =Q18+R18-U18 -> 0 | W18: =AA17 -> 101.14 | X18: 0 | Y18: =CPP!H18 -> 0 | Z18: 101.1 | AA18: =W18+X18-Z18-Y18 -> 0.04 | AB18: =AE17 -> 0 | AC18: 0 | AD18: =CPP!F18 -> 0 | AE18: =AB18+AC18-AD18 -> 0 | AF18: =AJ17 -> 4398.77 | AG18: 124.25 | AH18: 0 | AI18: =CPP!G18 -> 172 | AJ18: =AF18+AG18-AH18-AI18 -> 4351.02 | AK18: =AN17 -> 0 | AL18: 0 | AM18: 0 | AN18: =AK18+AL18-AM18 -> 0 | AO18: =AS17 -> 0 | AP18: 0 | AQ18: 0 | AR18: =CPP!I18 -> 0 | AS18: =AO18+AP18-AQ18-AR18 -> 0 | AT18: =AX17 -> 0.01 | AU18: 0 | AV18: 0 | AW18: =CPP!X18 -> 0 | AX18: =AT18+AU18-AV18-AW18 -> 0.01 | AY18: =BC17 -> 2638.127 | AZ18: 123.28 | BA18: 143.34 | BB18: =CPP!M18 -> 0 | BC18: =AY18+AZ18-BA18-BB18 -> 2618.067 | BD18: =BH17 -> 0 | BE18: 0 | BF18: 0 | BG18: =CPP!K18 -> 0 | BH18: =BD18+BE18-BF18-BG18 -> 0 | BI18: =BM17 -> 0 | BJ18: 0 | BK18: 0 | BL18: =CPP!L18 -> 0 | BM18: =BI18+BJ18-BK18-BL18 -> 0 | BN18: =BR17 -> 0 | BO18: 0 | BP18: 0 | BQ18: =CPP!N18 -> 0 | BR18: =BN18+BO18-BP18-BQ18 -> 0 | BS18: =BW17 -> 0 | BT18: 0 | BU18: 0 | BV18: =CPP!O18 -> 0 | BW18: =BS18+BT18-BU18-BV18 -> 0 | BX18: =CB17 -> 0 | BY18: 0 | BZ18: 0 | CB18: =BX18+BY18-BZ18-CA18 -> 0 | CC18: =CG17 -> 0 | CD18: 0 | CE18: 0 | CF18: =CPP!P18 -> 0 | CG18: =CC18+CD18-CE18-CF18 -> 0 | CH18: =CL17 -> 0 | CI18: 0 | CJ18: 0 | CK18: =CPP!Q18 -> 0 | CL18: =CH18+CI18-CJ18-CK18 -> 0 | CM18: =CQ17 -> 0.05 | CN18: 0 | CO18: 0 | CP18: =CPP!R18 -> 0 | CQ18: =CM18+CN18-CP18 -> 0.05 | CR18: =CV17 -> 0 | CS18: 0 | CT18: 0 | CU18: =CPP!S18 -> 0 | CV18: =CR18+CS18-CT18-CU18 -> 0 | CW18: =DA17 -> 0 | CX18: 0 | CY18: 0 | CZ18: =CPP!T18 -> 0 | DA18: =CW18+CX18-CY18-CZ18 -> 0 | DB18: =DF17 -> 0.01 | DC18: 0 | DD18: 0 | DE18: =CPP!U18 -> 0 | DF18: =DB18+DC18-DD18-DE18 -> 0.01 | DG18: =DK17 -> 0 | DH18: 0 | DI18: 0 | DJ18: =CPP!V18 -> 0 | DK18: =DG18+DH18-DI18-DJ18 -> 0 | DL18: =DP17 -> 304 | DM18: 0 | DN18: 0 | DO18: =CPP!W18 -> 0 | DP18: =DL18+DM18-DN18-DO18 -> 304 | DQ18: =DU17 -> 0 | DR18: 0 | DS18: 0 | DT18: =CPP!J18 -> 0 | DU18: =DQ18+DR18-DS18-DT18 -> 0 | DV18: =DZ17 -> 0 | DW18: 0 | DX18: 0 | DY18: 0 | DZ18: =DV18+DW18-DX18-DY18 -> 0 | EA18: =K18+W18+AK18+AO18+AT18+AY18 -> 2739.277 | EB18: 0 | EC18: 0 | ED18: =EA18+EB18-EC18 -> 2739.277 | EE18: =Q18+AB18+AF18 -> 4398.77 | EF18: =R18+AC18+AG18 -> 124.25 | EG18: =CPP!D18+CPP!E18+CPP!F18+CPP!G18+CPP!H18+CPP!I18+CPP!J18+CPP!M18+BG18 -> 172 | EH18: =EE18+EF18-EG18 -> 4351.02 | EI18: =EL17 -> 26466.682 | EJ18: =EM18+EN18 -> 1390 | EK18: ='DAILY CEM1'!AG19+'DAILY CEM2'!AF19 -> 2298.529 | EL18: =EI18+EJ18-EK18 -> 25558.153 | EM18: 1390 | EN18: 0 | EO18: 2324.5
B19: 17 | C19: =F18 -> 1605.92 | D19: 0 | E19: 47 | F19: =C19+D19-E19 -> 1558.92 | G19: =J18 -> 1440.0496 | H19: 0 | I19: 0 | J19: =G19+H19-I19-[1]Cement!U19 -> 1365.0496 | K19: =P18 -> 0 | L19: 0 | M19: =CPP!D19 -> 0 | N19: 0 | O19: =M19+N19 -> 0 | P19: =K19+L19-O19 -> 0 | Q19: =V18 -> 0 | R19: 0 | S19: =CPP!E19 -> 0 | T19: 0 | U19: =S19+T19 -> 0 | V19: =Q19+R19-U19 -> 0 | W19: =AA18 -> 0.04 | X19: 0 | Y19: =CPP!H19 -> 0 | Z19: 0 | AA19: =W19+X19-Z19-Y19 -> 0.04 | AB19: =AE18 -> 0 | AC19: 0 | AD19: =CPP!F19 -> 0 | AE19: =AB19+AC19-AD19 -> 0 | AF19: =AJ18 -> 4351.02 | AG19: 32 | AH19: 0 | AI19: =CPP!G19 -> 155 | AJ19: =AF19+AG19-AH19-AI19 -> 4228.02 | AK19: =AN18 -> 0 | AL19: 0 | AM19: 0 | AN19: =AK19+AL19-AM19 -> 0 | AO19: =AS18 -> 0 | AP19: 0 | AQ19: 0 | AR19: =CPP!I19 -> 0 | AS19: =AO19+AP19-AQ19-AR19 -> 0 | AT19: =AX18 -> 0.01 | AU19: 0 | AV19: 0 | AW19: =CPP!X19 -> 0 | AX19: =AT19+AU19-AV19-AW19 -> 0.01 | AY19: =BC18 -> 2618.067 | AZ19: 64.14 | BA19: 244.44 | BB19: =CPP!M19 -> 0 | BC19: =AY19+AZ19-BA19-BB19 -> 2437.767 | BD19: =BH18 -> 0 | BE19: 0 | BF19: 0 | BG19: =CPP!K19 -> 0 | BH19: =BD19+BE19-BF19-BG19 -> 0 | BI19: =BM18 -> 0 | BJ19: 0 | BK19: 0 | BL19: =CPP!L19 -> 0 | BM19: =BI19+BJ19-BK19-BL19 -> 0 | BN19: =BR18 -> 0 | BO19: 0 | BP19: 0 | BQ19: =CPP!N19 -> 0 | BR19: =BN19+BO19-BP19-BQ19 -> 0 | BS19: =BW18 -> 0 | BT19: 0 | BU19: 0 | BV19: =CPP!O19 -> 0 | BW19: =BS19+BT19-BU19-BV19 -> 0 | BX19: =CB18 -> 0 | BY19: 0 | BZ19: 0 | CB19: =BX19+BY19-BZ19-CA19 -> 0 | CC19: =CG18 -> 0 | CD19: 0 | CE19: 0 | CF19: =CPP!P19 -> 0 | CG19: =CC19+CD19-CE19-CF19 -> 0 | CH19: =CL18 -> 0 | CI19: 0 | CJ19: 0 | CK19: =CPP!Q19 -> 0 | CL19: =CH19+CI19-CJ19-CK19 -> 0 | CM19: =CQ18 -> 0.05 | CN19: 0 | CO19: 0 | CP19: =CPP!R19 -> 0 | CQ19: =CM19+CN19-CP19 -> 0.05 | CR19: =CV18 -> 0 | CS19: 0 | CT19: 0 | CU19: =CPP!S19 -> 0 | CV19: =CR19+CS19-CT19-CU19 -> 0 | CW19: =DA18 -> 0 | CX19: 0 | CY19: 0 | CZ19: =CPP!T19 -> 0 | DA19: =CW19+CX19-CY19-CZ19 -> 0 | DB19: =DF18 -> 0.01 | DC19: 0 | DD19: 0 | DE19: =CPP!U19 -> 0 | DF19: =DB19+DC19-DD19-DE19 -> 0.01 | DG19: =DK18 -> 0 | DH19: 0 | DI19: 0 | DJ19: =CPP!V19 -> 0 | DK19: =DG19+DH19-DI19-DJ19 -> 0 | DL19: =DP18 -> 304 | DM19: 0 | DN19: 0 | DO19: =CPP!W19 -> 0 | DP19: =DL19+DM19-DN19-DO19 -> 304 | DQ19: =DU18 -> 0 | DR19: 0 | DS19: 0 | DT19: =CPP!J19 -> 0 | DU19: =DQ19+DR19-DS19-DT19 -> 0 | DV19: =DZ18 -> 0 | DW19: 0 | DX19: 0 | DY19: 0 | DZ19: =DV19+DW19-DX19-DY19 -> 0 | EA19: =K19+W19+AK19+AO19+AT19+AY19 -> 2618.117 | EB19: 0 | EC19: 0 | ED19: =EA19+EB19-EC19 -> 2618.117 | EE19: =Q19+AB19+AF19 -> 4351.02 | EF19: =R19+AC19+AG19 -> 32 | EG19: =CPP!D19+CPP!E19+CPP!F19+CPP!G19+CPP!H19+CPP!I19+CPP!J19+CPP!M19+BG19 -> 155 | EH19: =EE19+EF19-EG19 -> 4228.02 | EI19: =EL18 -> 25558.153 | EJ19: =EM19+EN19 -> 1425 | EK19: ='DAILY CEM1'!AG20+'DAILY CEM2'!AF20 -> 2169.69 | EL19: =EI19+EJ19-EK19 -> 24813.463 | EM19: 1425 | EN19: 0 | EO19: 2176.78
B20: 18 | C20: =F19 -> 1558.92 | D20: 0 | E20: 88 | F20: =C20+D20-E20 -> 1470.92 | G20: =J19 -> 1365.0496 | H20: 0 | I20: 0 | J20: =G20+H20-I20-[1]Cement!U20 -> 1271.0496 | K20: =P19 -> 0 | L20: 0 | M20: =CPP!D20 -> 0 | N20: 0 | O20: =M20+N20 -> 0 | P20: =K20+L20-O20 -> 0 | Q20: =V19 -> 0 | R20: 0 | S20: =CPP!E20 -> 0 | T20: 0 | U20: =S20+T20 -> 0 | V20: =Q20+R20-U20 -> 0 | W20: =AA19 -> 0.04 | X20: 0 | Y20: =CPP!H20 -> 0 | Z20: 0 | AA20: =W20+X20-Z20-Y20 -> 0.04 | AB20: =AE19 -> 0 | AC20: 0 | AD20: =CPP!F20 -> 0 | AE20: =AB20+AC20-AD20 -> 0 | AF20: =AJ19 -> 4228.02 | AG20: 251.7 | AH20: 0 | AI20: =CPP!G20 -> 164 | AJ20: =AF20+AG20-AH20-AI20 -> 4315.72 | AK20: =AN19 -> 0 | AL20: 0 | AM20: 0 | AN20: =AK20+AL20-AM20 -> 0 | AO20: =AS19 -> 0 | AP20: 0 | AQ20: 0 | AR20: =CPP!I20 -> 0 | AS20: =AO20+AP20-AQ20-AR20 -> 0 | AT20: =AX19 -> 0.01 | AU20: 0 | AV20: 0 | AW20: =CPP!X20 -> 0 | AX20: =AT20+AU20-AV20-AW20 -> 0.01 | AY20: =BC19 -> 2437.767 | AZ20: 186.46 | BA20: 237.78 | BB20: =CPP!M20 -> 0 | BC20: =AY20+AZ20-BA20-BB20 -> 2386.447 | BD20: =BH19 -> 0 | BE20: 0 | BF20: 0 | BG20: =CPP!K20 -> 0 | BH20: =BD20+BE20-BF20-BG20 -> 0 | BI20: =BM19 -> 0 | BJ20: 0 | BK20: 0 | BL20: =CPP!L20 -> 0 | BM20: =BI20+BJ20-BK20-BL20 -> 0 | BN20: =BR19 -> 0 | BO20: 0 | BP20: 0 | BQ20: =CPP!N20 -> 0 | BR20: =BN20+BO20-BP20-BQ20 -> 0 | BS20: =BW19 -> 0 | BT20: 0 | BU20: 0 | BV20: =CPP!O20 -> 0 | BW20: =BS20+BT20-BU20-BV20 -> 0 | BX20: =CB19 -> 0 | BY20: 0 | BZ20: 0 | CB20: =BX20+BY20-BZ20-CA20 -> 0 | CC20: =CG19 -> 0 | CD20: 0 | CE20: 0 | CF20: =CPP!P20 -> 0 | CG20: =CC20+CD20-CE20-CF20 -> 0 | CH20: =CL19 -> 0 | CI20: 0 | CJ20: 0 | CK20: =CPP!Q20 -> 0 | CL20: =CH20+CI20-CJ20-CK20 -> 0 | CM20: =CQ19 -> 0.05 | CN20: 0 | CO20: 0 | CP20: =CPP!R20 -> 0 | CQ20: =CM20+CN20-CP20 -> 0.05 | CR20: =CV19 -> 0 | CS20: 0 | CT20: 0 | CU20: =CPP!S20 -> 0 | CV20: =CR20+CS20-CT20-CU20 -> 0 | CW20: =DA19 -> 0 | CX20: 0 | CY20: 0 | CZ20: =CPP!T20 -> 0 | DA20: =CW20+CX20-CY20-CZ20 -> 0 | DB20: =DF19 -> 0.01 | DC20: 0 | DD20: 0 | DE20: =CPP!U20 -> 0 | DF20: =DB20+DC20-DD20-DE20 -> 0.01 | DG20: =DK19 -> 0 | DH20: 0 | DI20: 0 | DJ20: =CPP!V20 -> 0 | DK20: =DG20+DH20-DI20-DJ20 -> 0 | DL20: =DP19 -> 304 | DM20: 0 | DN20: 0 | DO20: =CPP!W20 -> 0 | DP20: =DL20+DM20-DN20-DO20 -> 304 | DQ20: =DU19 -> 0 | DR20: 0 | DS20: 0 | DT20: =CPP!J20 -> 0 | DU20: =DQ20+DR20-DS20-DT20 -> 0 | DV20: =DZ19 -> 0 | DW20: 0 | DX20: 0 | DY20: 0 | DZ20: =DV20+DW20-DX20-DY20 -> 0 | EA20: =K20+W20+AK20+AO20+AT20+AY20 -> 2437.817 | EB20: 0 | EC20: 0 | ED20: =EA20+EB20-EC20 -> 2437.817 | EE20: =Q20+AB20+AF20 -> 4228.02 | EF20: =R20+AC20+AG20 -> 251.7 | EG20: =CPP!D20+CPP!E20+CPP!F20+CPP!G20+CPP!H20+CPP!I20+CPP!J20+CPP!M20+BG20 -> 164 | EH20: =EE20+EF20-EG20 -> 4315.72 | EI20: =EL19 -> 24813.463 | EJ20: =EM20+EN20 -> 1350 | EK20: ='DAILY CEM1'!AG21+'DAILY CEM2'!AF21 -> 2232.55 | EL20: =EI20+EJ20-EK20 -> 23930.913 | EM20: 1350 | EN20: 0 | EO20: 2219.1
B21: 19 | C21: =F20 -> 1470.92 | D21: 0 | E21: 80 | F21: =C21+D21-E21 -> 1390.92 | G21: =J20 -> 1271.0496 | H21: 0 | I21: 0 | J21: =G21+H21-I21-[1]Cement!U21 -> 1165.0496 | K21: =P20 -> 0 | L21: 0 | M21: =CPP!D21 -> 0 | N21: 0 | O21: =M21+N21 -> 0 | P21: =K21+L21-O21 -> 0 | Q21: =V20 -> 0 | R21: 0 | S21: =CPP!E21 -> 0 | T21: 0 | U21: =S21+T21 -> 0 | V21: =Q21+R21-U21 -> 0 | W21: =AA20 -> 0.04 | X21: 0 | Y21: =CPP!H21 -> 0 | Z21: 0 | AA21: =W21+X21-Z21-Y21 -> 0.04 | AB21: =AE20 -> 0 | AC21: 0 | AD21: =CPP!F21 -> 0 | AE21: =AB21+AC21-AD21 -> 0 | AF21: =AJ20 -> 4315.72 | AG21: 59.3 | AH21: 0 | AI21: =CPP!G21 -> 172 | AJ21: =AF21+AG21-AH21-AI21 -> 4203.02 | AK21: =AN20 -> 0 | AL21: 0 | AM21: 0 | AN21: =AK21+AL21-AM21 -> 0 | AO21: =AS20 -> 0 | AP21: 0 | AQ21: 0 | AR21: =CPP!I21 -> 0 | AS21: =AO21+AP21-AQ21-AR21 -> 0 | AT21: =AX20 -> 0.01 | AU21: 0 | AV21: 0 | AW21: =CPP!X21 -> 0 | AX21: =AT21+AU21-AV21-AW21 -> 0.01 | AY21: =BC20 -> 2386.447 | AZ21: 120.74 | BA21: 236.67 | BB21: =CPP!M21 -> 0 | BC21: =AY21+AZ21-BA21-BB21 -> 2270.517 | BD21: =BH20 -> 0 | BE21: 0 | BF21: 0 | BG21: =CPP!K21 -> 0 | BH21: =BD21+BE21-BF21-BG21 -> 0 | BI21: =BM20 -> 0 | BJ21: 0 | BK21: 0 | BL21: =CPP!L21 -> 0 | BM21: =BI21+BJ21-BK21-BL21 -> 0 | BN21: =BR20 -> 0 | BO21: 0 | BP21: 0 | BQ21: =CPP!N21 -> 0 | BR21: =BN21+BO21-BP21-BQ21 -> 0 | BS21: =BW20 -> 0 | BT21: 0 | BU21: 0 | BV21: =CPP!O21 -> 0 | BW21: =BS21+BT21-BU21-BV21 -> 0 | BX21: =CB20 -> 0 | BY21: 0 | BZ21: 0 | CB21: =BX21+BY21-BZ21-CA21 -> 0 | CC21: =CG20 -> 0 | CD21: 0 | CE21: 0 | CF21: =CPP!P21 -> 0 | CG21: =CC21+CD21-CE21-CF21 -> 0 | CH21: =CL20 -> 0 | CI21: 0 | CJ21: 0 | CK21: =CPP!Q21 -> 0 | CL21: =CH21+CI21-CJ21-CK21 -> 0 | CM21: =CQ20 -> 0.05 | CN21: 0 | CO21: 0 | CP21: =CPP!R21 -> 0 | CQ21: =CM21+CN21-CP21 -> 0.05 | CR21: =CV20 -> 0 | CS21: 0 | CT21: 0 | CU21: =CPP!S21 -> 0 | CV21: =CR21+CS21-CT21-CU21 -> 0 | CW21: =DA20 -> 0 | CX21: 0 | CY21: 0 | CZ21: =CPP!T21 -> 0 | DA21: =CW21+CX21-CY21-CZ21 -> 0 | DB21: =DF20 -> 0.01 | DC21: 0 | DD21: 0 | DE21: =CPP!U21 -> 0 | DF21: =DB21+DC21-DD21-DE21 -> 0.01 | DG21: =DK20 -> 0 | DH21: 0 | DI21: 0 | DJ21: =CPP!V21 -> 0 | DK21: =DG21+DH21-DI21-DJ21 -> 0 | DL21: =DP20 -> 304 | DM21: 0 | DN21: 0 | DO21: =CPP!W21 -> 0 | DP21: =DL21+DM21-DN21-DO21 -> 304 | DQ21: =DU20 -> 0 | DR21: 0 | DS21: 0 | DT21: =CPP!J21 -> 0 | DU21: =DQ21+DR21-DS21-DT21 -> 0 | DV21: =DZ20 -> 0 | DW21: 0 | DX21: 0 | DY21: 0 | DZ21: =DV21+DW21-DX21-DY21 -> 0 | EA21: =K21+W21+AK21+AO21+AT21+AY21 -> 2386.497 | EB21: 0 | EC21: 0 | ED21: =EA21+EB21-EC21 -> 2386.497 | EE21: =Q21+AB21+AF21 -> 4315.72 | EF21: =R21+AC21+AG21 -> 59.3 | EG21: =CPP!D21+CPP!E21+CPP!F21+CPP!G21+CPP!H21+CPP!I21+CPP!J21+CPP!M21+BG21 -> 172 | EH21: =EE21+EF21-EG21 -> 4203.02 | EI21: =EL20 -> 23930.913 | EJ21: =EM21+EN21 -> 1335 | EK21: ='DAILY CEM1'!AG22+'DAILY CEM2'!AF22 -> 2382.808 | EL21: =EI21+EJ21-EK21 -> 22883.105 | EM21: 1335 | EN21: 0 | EO21: 2143.6
B22: 20 | C22: =F21 -> 1390.92 | D22: 0 | E22: 68 | F22: =C22+D22-E22 -> 1322.92 | G22: =J21 -> 1165.0496 | H22: 0 | I22: 0 | J22: =G22+H22-I22-[1]Cement!U22 -> 1061.0496 | K22: =P21 -> 0 | L22: 0 | M22: =CPP!D22 -> 0 | N22: 0 | O22: =M22+N22 -> 0 | P22: =K22+L22-O22 -> 0 | Q22: =V21 -> 0 | R22: 0 | S22: =CPP!E22 -> 0 | T22: 0 | U22: =S22+T22 -> 0 | V22: =Q22+R22-U22 -> 0 | W22: =AA21 -> 0.04 | X22: 0 | Y22: =CPP!H22 -> 0 | Z22: 0 | AA22: =W22+X22-Z22-Y22 -> 0.04 | AB22: =AE21 -> 0 | AC22: 0 | AD22: =CPP!F22 -> 0 | AE22: =AB22+AC22-AD22 -> 0 | AF22: =AJ21 -> 4203.02 | AG22: 0 | AH22: 0 | AI22: =CPP!G22 -> 171 | AJ22: =AF22+AG22-AH22-AI22 -> 4032.02 | AK22: =AN21 -> 0 | AL22: 0 | AM22: 0 | AN22: =AK22+AL22-AM22 -> 0 | AO22: =AS21 -> 0 | AP22: 0 | AQ22: 0 | AR22: =CPP!I22 -> 0 | AS22: =AO22+AP22-AQ22-AR22 -> 0 | AT22: =AX21 -> 0.01 | AU22: 0 | AV22: 0 | AW22: =CPP!X22 -> 0 | AX22: =AT22+AU22-AV22-AW22 -> 0.01 | AY22: =BC21 -> 2270.517 | AZ22: 0 | BA22: 227.78 | BB22: =CPP!M22 -> 0 | BC22: =AY22+AZ22-BA22-BB22 -> 2042.737 | BD22: =BH21 -> 0 | BE22: 0 | BF22: 0 | BG22: =CPP!K22 -> 0 | BH22: =BD22+BE22-BF22-BG22 -> 0 | BI22: =BM21 -> 0 | BJ22: 0 | BK22: 0 | BL22: =CPP!L22 -> 0 | BM22: =BI22+BJ22-BK22-BL22 -> 0 | BN22: =BR21 -> 0 | BO22: 0 | BP22: 0 | BQ22: =CPP!N22 -> 0 | BR22: =BN22+BO22-BP22-BQ22 -> 0 | BS22: =BW21 -> 0 | BT22: 0 | BU22: 0 | BV22: =CPP!O22 -> 0 | BW22: =BS22+BT22-BU22-BV22 -> 0 | BX22: =CB21 -> 0 | BY22: 0 | BZ22: 0 | CB22: =BX22+BY22-BZ22-CA22 -> 0 | CC22: =CG21 -> 0 | CD22: 0 | CE22: 0 | CF22: =CPP!P22 -> 0 | CG22: =CC22+CD22-CE22-CF22 -> 0 | CH22: =CL21 -> 0 | CI22: 0 | CJ22: 0 | CK22: =CPP!Q22 -> 0 | CL22: =CH22+CI22-CJ22-CK22 -> 0 | CM22: =CQ21 -> 0.05 | CN22: 0 | CO22: 0 | CP22: =CPP!R22 -> 0 | CQ22: =CM22+CN22-CP22 -> 0.05 | CR22: =CV21 -> 0 | CS22: 0 | CT22: 0 | CU22: =CPP!S22 -> 0 | CV22: =CR22+CS22-CT22-CU22 -> 0 | CW22: =DA21 -> 0 | CX22: 0 | CY22: 0 | CZ22: =CPP!T22 -> 0 | DA22: =CW22+CX22-CY22-CZ22 -> 0 | DB22: =DF21 -> 0.01 | DC22: 0 | DD22: 0 | DE22: =CPP!U22 -> 0 | DF22: =DB22+DC22-DD22-DE22 -> 0.01 | DG22: =DK21 -> 0 | DH22: 0 | DI22: 0 | DJ22: =CPP!V22 -> 0 | DK22: =DG22+DH22-DI22-DJ22 -> 0 | DL22: =DP21 -> 304 | DM22: 0 | DN22: 0 | DO22: =CPP!W22 -> 0 | DP22: =DL22+DM22-DN22-DO22 -> 304 | DQ22: =DU21 -> 0 | DR22: 0 | DS22: 0 | DT22: =CPP!J22 -> 0 | DU22: =DQ22+DR22-DS22-DT22 -> 0 | DV22: =DZ21 -> 0 | DW22: 0 | DX22: 0 | DY22: 0 | DZ22: =DV22+DW22-DX22-DY22 -> 0 | EA22: =K22+W22+AK22+AO22+AT22+AY22 -> 2270.567 | EB22: 0 | EC22: 0 | ED22: =EA22+EB22-EC22 -> 2270.567 | EE22: =Q22+AB22+AF22 -> 4203.02 | EF22: =R22+AC22+AG22 -> 0 | EG22: =CPP!D22+CPP!E22+CPP!F22+CPP!G22+CPP!H22+CPP!I22+CPP!J22+CPP!M22+BG22 -> 171 | EH22: =EE22+EF22-EG22 -> 4032.02 | EI22: =EL21 -> 22883.105 | EJ22: =EM22+EN22 -> 1270 | EK22: ='DAILY CEM1'!AG23+'DAILY CEM2'!AF23 -> 2446.567 | EL22: =EI22+EJ22-EK22 -> 21706.538 | EM22: 1270 | EN22: 0 | EO22: 2112.93
