Workbook
Name NativeTimeline_GrossDate: #N/A
Name NativeTimeline_GrossDate1: #N/A

Sheet Supply to date 2026
B3: SUMMARY April 2026 -UP TO DATE STOCK LEVELS
B4: Material Type | C4: Opening stock start of April 2026 | D4: Mines to stock | E4: stock to Pile/Other Usages | F4: Closing Stock(on date) | G4: Odoo Stock level | H4: Diff due to Lcl Transfers
B5: HG | C5: 44414.57 | D5: ='DAILY TMH April 2026'!D36+'DAILY TMH April 2026'!G36 -> 9930.96 | E5: ='DAILY TMH April 2026'!H36+'DAILY TMH April 2026'!I36 -> 10607.64 | F5: =(C5+D5)-E5 -> 43737.89 | H5: =F5-G5 -> 43737.89
B6: LG1 | C6: 394234.2 | D6: ='DAILY TMH April 2026'!L36+'DAILY TMH April 2026'!O36 -> 7225.9 | E6: ='DAILY TMH April 2026'!P36+'DAILY TMH April 2026'!Q36+'DAILY TMH April 2026'!R36 -> 19464.9 | F6: =(C6+D6)-E6 -> 381995.2 | H6: =F6-G6 -> 381995.2
B7: HGHMGO | C7: 9895.62 | D7: ='DAILY TMH April 2026'!AH36 -> 0 | E7: ='DAILY TMH April 2026'!AI36 -> 0 | F7: =(C7+D7)-E7 -> 9895.62 | H7: =F7-G7 -> 9895.62
B8: OB | C8: 11123.38 | D8: ='DAILY TMH April 2026'!W36+'DAILY TMH April 2026'!AA36 -> 0 | E8: ='DAILY TMH April 2026'!AC36+'DAILY TMH April 2026'!AD36+'DAILY TMH April 2026'!AE36 -> 594.14 | F8: =(C8+D8)-E8 -> 10529.24 | H8: =F8-G8 -> 10529.24
B9: ID CLAY | C9: 148.76 | D9: ='DAILY TMH April 2026'!AT36 -> 0 | E9: ='DAILY TMH April 2026'!AR36+'DAILY TMH April 2026'!AS36 -> 137.76 | F9: =(C9+D9)-E9 -> 11 | H9: =F9-G9 -> 11
E10: ='DAILY TMH April 2026'!S36+'DAILY TMH April 2026'!T36 -> 0 | F10: =(C10+D10)-E10 -> 0 | H10: =F10-G10 -> 0
A12: Month | B12: MATERIAL SUPPLY TO PILE-February 2026
B13: HG | C13: LG1 | D13: OB | E13: LIMESTONE SPG | F13: HG-HMGO | G13: GYPSUM | H13: ID CLAY
A14: ='DAILY TMH April 2026'!A5 -> 46113 | B14: ='DAILY TMH April 2026'!B5+'DAILY TMH April 2026'!H5+'DAILY TMH April 2026'!C5+'DAILY TMH April 2026'!I5+'DAILY TMH April 2026'!E5+'DAILY TMH April 2026'!F5 -> 0 | C14: ='DAILY TMH April 2026'!J5+'DAILY TMH April 2026'!P5+'DAILY TMH April 2026'!K5+'DAILY TMH April 2026'!Q5+'DAILY TMH April 2026'!M5+'DAILY TMH April 2026'!N5 -> 401.14 | D14: ='DAILY TMH April 2026'!U5+'DAILY TMH April 2026'!AC5+'DAILY TMH April 2026'!V5+'DAILY TMH April 2026'!AE5+'DAILY TMH April 2026'!Y5+'DAILY TMH April 2026'!Z5 -> 0 | E14: ='DAILY TMH April 2026'!S5 -> 0 | F14: ='DAILY TMH April 2026'!AF5+'DAILY TMH April 2026'!AI5+'DAILY TMH April 2026'!AG5 -> 0 | G14: ='DAILY TMH April 2026'!AP5+'DAILY TMH April 2026'!AQ5 -> 0 | H14: ='DAILY TMH April 2026'!AS5 -> 0
A15: ='DAILY TMH April 2026'!A6 -> 46114 | B15: ='DAILY TMH April 2026'!B6+'DAILY TMH April 2026'!H6+'DAILY TMH April 2026'!C6+'DAILY TMH April 2026'!I6+'DAILY TMH April 2026'!E6+'DAILY TMH April 2026'!F6 -> 0 | C15: ='DAILY TMH April 2026'!J6+'DAILY TMH April 2026'!P6+'DAILY TMH April 2026'!K6+'DAILY TMH April 2026'!Q6+'DAILY TMH April 2026'!M6+'DAILY TMH April 2026'!N6 -> 808.48 | D15: ='DAILY TMH April 2026'!U6+'DAILY TMH April 2026'!AC6+'DAILY TMH April 2026'!V6+'DAILY TMH April 2026'!AE6+'DAILY TMH April 2026'!Y6+'DAILY TMH April 2026'!Z6 -> 0 | E15: ='DAILY TMH April 2026'!S6 -> 0 | F15: ='DAILY TMH April 2026'!AF6+'DAILY TMH April 2026'!AI6+'DAILY TMH April 2026'!AG6 -> 0 | G15: ='DAILY TMH April 2026'!AP6+'DAILY TMH April 2026'!AQ6 -> 0 | H15: ='DAILY TMH April 2026'!AS6 -> 0
A16: ='DAILY TMH April 2026'!A7 -> 46115 | B16: ='DAILY TMH April 2026'!B7+'DAILY TMH April 2026'!H7+'DAILY TMH April 2026'!C7+'DAILY TMH April 2026'!I7+'DAILY TMH April 2026'!E7+'DAILY TMH April 2026'!F7 -> 0 | C16: ='DAILY TMH April 2026'!J7+'DAILY TMH April 2026'!P7+'DAILY TMH April 2026'!K7+'DAILY TMH April 2026'!Q7+'DAILY TMH April 2026'!M7+'DAILY TMH April 2026'!N7 -> 239.08 | D16: ='DAILY TMH April 2026'!U7+'DAILY TMH April 2026'!AC7+'DAILY TMH April 2026'!V7+'DAILY TMH April 2026'!AE7+'DAILY TMH April 2026'!Y7+'DAILY TMH April 2026'!Z7 -> 0 | E16: ='DAILY TMH April 2026'!S7 -> 0 | F16: ='DAILY TMH April 2026'!AF7+'DAILY TMH April 2026'!AI7+'DAILY TMH April 2026'!AG7 -> 0 | G16: ='DAILY TMH April 2026'!AP7+'DAILY TMH April 2026'!AQ7 -> 0 | H16: ='DAILY TMH April 2026'!AS7 -> 0
A17: ='DAILY TMH April 2026'!A8 -> 46116 | B17: ='DAILY TMH April 2026'!B8+'DAILY TMH April 2026'!H8+'DAILY TMH April 2026'!C8+'DAILY TMH April 2026'!I8+'DAILY TMH April 2026'!E8+'DAILY TMH April 2026'!F8 -> 1286.4 | C17: ='DAILY TMH April 2026'!J8+'DAILY TMH April 2026'!P8+'DAILY TMH April 2026'!K8+'DAILY TMH April 2026'!Q8+'DAILY TMH April 2026'!M8+'DAILY TMH April 2026'!N8 -> 879.5 | D17: ='DAILY TMH April 2026'!U8+'DAILY TMH April 2026'!AC8+'DAILY TMH April 2026'!V8+'DAILY TMH April 2026'!AE8+'DAILY TMH April 2026'!Y8+'DAILY TMH April 2026'!Z8 -> 0 | E17: ='DAILY TMH April 2026'!S8 -> 0 | F17: ='DAILY TMH April 2026'!AF8+'DAILY TMH April 2026'!AI8+'DAILY TMH April 2026'!AG8 -> 0 | G17: ='DAILY TMH April 2026'!AP8+'DAILY TMH April 2026'!AQ8 -> 0 | H17: ='DAILY TMH April 2026'!AS8 -> 0
A18: ='DAILY TMH April 2026'!A9 -> 46117 | B18: ='DAILY TMH April 2026'!B9+'DAILY TMH April 2026'!H9+'DAILY TMH April 2026'!C9+'DAILY TMH April 2026'!I9+'DAILY TMH April 2026'!E9+'DAILY TMH April 2026'!F9 -> 697.96 | C18: ='DAILY TMH April 2026'!J9+'DAILY TMH April 2026'!P9+'DAILY TMH April 2026'!K9+'DAILY TMH April 2026'!Q9+'DAILY TMH April 2026'!M9+'DAILY TMH April 2026'!N9 -> 787.42 | D18: ='DAILY TMH April 2026'!U9+'DAILY TMH April 2026'!AC9+'DAILY TMH April 2026'!V9+'DAILY TMH April 2026'!AE9+'DAILY TMH April 2026'!Y9+'DAILY TMH April 2026'!Z9 -> 0 | E18: ='DAILY TMH April 2026'!S9 -> 0 | F18: ='DAILY TMH April 2026'!AF9+'DAILY TMH April 2026'!AI9+'DAILY TMH April 2026'!AG9 -> 0 | G18: ='DAILY TMH April 2026'!AP9+'DAILY TMH April 2026'!AQ9 -> 0 | H18: ='DAILY TMH April 2026'!AS9 -> 0
A19: ='DAILY TMH April 2026'!A10 -> 46118 | B19: ='DAILY TMH April 2026'!B10+'DAILY TMH April 2026'!H10+'DAILY TMH April 2026'!C10+'DAILY TMH April 2026'!I10+'DAILY TMH April 2026'!E10+'DAILY TMH April 2026'!F10 -> 0 | C19: ='DAILY TMH April 2026'!J10+'DAILY TMH April 2026'!P10+'DAILY TMH April 2026'!K10+'DAILY TMH April 2026'!Q10+'DAILY TMH April 2026'!M10+'DAILY TMH April 2026'!N10 -> 420.1 | D19: ='DAILY TMH April 2026'!U10+'DAILY TMH April 2026'!AC10+'DAILY TMH April 2026'!V10+'DAILY TMH April 2026'!AE10+'DAILY TMH April 2026'!Y10+'DAILY TMH April 2026'!Z10 -> 0 | E19: ='DAILY TMH April 2026'!S10 -> 0 | F19: ='DAILY TMH April 2026'!AF10+'DAILY TMH April 2026'!AI10+'DAILY TMH April 2026'!AG10 -> 0 | G19: ='DAILY TMH April 2026'!AP10+'DAILY TMH April 2026'!AQ10 -> 0 | H19: ='DAILY TMH April 2026'!AS10 -> 0
A20: ='DAILY TMH April 2026'!A11 -> 46119 | B20: ='DAILY TMH April 2026'!B11+'DAILY TMH April 2026'!H11+'DAILY TMH April 2026'!C11+'DAILY TMH April 2026'!I11+'DAILY TMH April 2026'!E11+'DAILY TMH April 2026'!F11 -> 1837.02 | C20: ='DAILY TMH April 2026'!J11+'DAILY TMH April 2026'!P11+'DAILY TMH April 2026'!K11+'DAILY TMH April 2026'!Q11+'DAILY TMH April 2026'!M11+'DAILY TMH April 2026'!N11 -> 1446.6 | D20: ='DAILY TMH April 2026'!U11+'DAILY TMH April 2026'!AC11+'DAILY TMH April 2026'!V11+'DAILY TMH April 2026'!AE11+'DAILY TMH April 2026'!Y11+'DAILY TMH April 2026'!Z11 -> 0 | E20: ='DAILY TMH April 2026'!S11 -> 0 | F20: ='DAILY TMH April 2026'!AF11+'DAILY TMH April 2026'!AI11+'DAILY TMH April 2026'!AG11 -> 0 | G20: ='DAILY TMH April 2026'!AP11+'DAILY TMH April 2026'!AQ11 -> 0 | H20: ='DAILY TMH April 2026'!AS11 -> 0
A21: ='DAILY TMH April 2026'!A12 -> 46120 | B21: ='DAILY TMH April 2026'!B12+'DAILY TMH April 2026'!H12+'DAILY TMH April 2026'!C12+'DAILY TMH April 2026'!I12+'DAILY TMH April 2026'!E12+'DAILY TMH April 2026'!F12 -> 588.58 | C21: ='DAILY TMH April 2026'!J12+'DAILY TMH April 2026'!P12+'DAILY TMH April 2026'!K12+'DAILY TMH April 2026'!Q12+'DAILY TMH April 2026'!M12+'DAILY TMH April 2026'!N12 -> 2411.22 | D21: ='DAILY TMH April 2026'!U12+'DAILY TMH April 2026'!AC12+'DAILY TMH April 2026'!V12+'DAILY TMH April 2026'!AE12+'DAILY TMH April 2026'!Y12+'DAILY TMH April 2026'!Z12 -> 0 | E21: ='DAILY TMH April 2026'!S12 -> 0 | F21: ='DAILY TMH April 2026'!AF12+'DAILY TMH April 2026'!AI12+'DAILY TMH April 2026'!AG12 -> 0 | G21: ='DAILY TMH April 2026'!AP12+'DAILY TMH April 2026'!AQ12 -> 0 | H21: ='DAILY TMH April 2026'!AS12 -> 0
A22: ='DAILY TMH April 2026'!A13 -> 46121 | B22: ='DAILY TMH April 2026'!B13+'DAILY TMH April 2026'!H13+'DAILY TMH April 2026'!C13+'DAILY TMH April 2026'!I13+'DAILY TMH April 2026'!E13+'DAILY TMH April 2026'!F13 -> 0 | C22: ='DAILY TMH April 2026'!J13+'DAILY TMH April 2026'!P13+'DAILY TMH April 2026'!K13+'DAILY TMH April 2026'!Q13+'DAILY TMH April 2026'!M13+'DAILY TMH April 2026'!N13 -> 3157.38 | D22: ='DAILY TMH April 2026'!U13+'DAILY TMH April 2026'!AC13+'DAILY TMH April 2026'!V13+'DAILY TMH April 2026'!AE13+'DAILY TMH April 2026'!Y13+'DAILY TMH April 2026'!Z13 -> 0 | E22: ='DAILY TMH April 2026'!S13 -> 0 | F22: ='DAILY TMH April 2026'!AF13+'DAILY TMH April 2026'!AI13+'DAILY TMH April 2026'!AG13 -> 0 | G22: ='DAILY TMH April 2026'!AP13+'DAILY TMH April 2026'!AQ13 -> 0 | H22: ='DAILY TMH April 2026'!AS13 -> 0
A23: ='DAILY TMH April 2026'!A14 -> 46122 | B23: ='DAILY TMH April 2026'!B14+'DAILY TMH April 2026'!H14+'DAILY TMH April 2026'!C14+'DAILY TMH April 2026'!I14+'DAILY TMH April 2026'!E14+'DAILY TMH April 2026'!F14 -> 1458.14 | C23: ='DAILY TMH April 2026'!J14+'DAILY TMH April 2026'!P14+'DAILY TMH April 2026'!K14+'DAILY TMH April 2026'!Q14+'DAILY TMH April 2026'!M14+'DAILY TMH April 2026'!N14 -> 1302.46 | D23: ='DAILY TMH April 2026'!U14+'DAILY TMH April 2026'!AC14+'DAILY TMH April 2026'!V14+'DAILY TMH April 2026'!AE14+'DAILY TMH April 2026'!Y14+'DAILY TMH April 2026'!Z14 -> 0 | E23: ='DAILY TMH April 2026'!S14 -> 0 | F23: ='DAILY TMH April 2026'!AF14+'DAILY TMH April 2026'!AI14+'DAILY TMH April 2026'!AG14 -> 0 | G23: ='DAILY TMH April 2026'!AP14+'DAILY TMH April 2026'!AQ14 -> 0 | H23: ='DAILY TMH April 2026'!AS14 -> 0
A24: ='DAILY TMH April 2026'!A15 -> 46123 | B24: ='DAILY TMH April 2026'!B15+'DAILY TMH April 2026'!H15+'DAILY TMH April 2026'!C15+'DAILY TMH April 2026'!I15+'DAILY TMH April 2026'!E15+'DAILY TMH April 2026'!F15 -> 1032.84 | C24: ='DAILY TMH April 2026'!J15+'DAILY TMH April 2026'!P15+'DAILY TMH April 2026'!K15+'DAILY TMH April 2026'!Q15+'DAILY TMH April 2026'!M15+'DAILY TMH April 2026'!N15 -> 2249.46 | D24: ='DAILY TMH April 2026'!U15+'DAILY TMH April 2026'!AC15+'DAILY TMH April 2026'!V15+'DAILY TMH April 2026'!AE15+'DAILY TMH April 2026'!Y15+'DAILY TMH April 2026'!Z15 -> 0 | E24: ='DAILY TMH April 2026'!S15 -> 0 | F24: ='DAILY TMH April 2026'!AF15+'DAILY TMH April 2026'!AI15+'DAILY TMH April 2026'!AG15 -> 0 | G24: ='DAILY TMH April 2026'!AP15+'DAILY TMH April 2026'!AQ15 -> 0 | H24: ='DAILY TMH April 2026'!AS15 -> 0
A25: ='DAILY TMH April 2026'!A16 -> 46124 | B25: ='DAILY TMH April 2026'!B16+'DAILY TMH April 2026'!H16+'DAILY TMH April 2026'!C16+'DAILY TMH April 2026'!I16+'DAILY TMH April 2026'!E16+'DAILY TMH April 2026'!F16 -> 1071.7 | C25: ='DAILY TMH April 2026'!J16+'DAILY TMH April 2026'!P16+'DAILY TMH April 2026'!K16+'DAILY TMH April 2026'!Q16+'DAILY TMH April 2026'!M16+'DAILY TMH April 2026'!N16 -> 1827.24 | D25: ='DAILY TMH April 2026'!U16+'DAILY TMH April 2026'!AC16+'DAILY TMH April 2026'!V16+'DAILY TMH April 2026'!AE16+'DAILY TMH April 2026'!Y16+'DAILY TMH April 2026'!Z16 -> 0 | E25: ='DAILY TMH April 2026'!S16 -> 0 | F25: ='DAILY TMH April 2026'!AF16+'DAILY TMH April 2026'!AI16+'DAILY TMH April 2026'!AG16 -> 0 | G25: ='DAILY TMH April 2026'!AP16+'DAILY TMH April 2026'!AQ16 -> 0 | H25: ='DAILY TMH April 2026'!AS16 -> 0
... A44: ='DAILY TMH April 2026'!A35 -> 0 | B44: ='DAILY TMH April 2026'!B35+'DAILY TMH April 2026'!H35+'DAILY TMH April 2026'!C35+'DAILY TMH April 2026'!I35+'DAILY TMH April 2026'!E35+'DAILY TMH April 2026'!F35 -> 0 | C44: ='DAILY TMH April 2026'!J35+'DAILY TMH April 2026'!P35+'DAILY TMH April 2026'!K35+'DAILY TMH April 2026'!Q35+'DAILY TMH April 2026'!M35+'DAILY TMH April 2026'!N35 -> 0 | D44: ='DAILY TMH April 2026'!U35+'DAILY TMH April 2026'!AC35+'DAILY TMH April 2026'!V35+'DAILY TMH April 2026'!AE35+'DAILY TMH April 2026'!Y35+'DAILY TMH April 2026'!Z35 -> 0 | E44: ='DAILY TMH April 2026'!S35 -> 0 | F44: ='DAILY TMH April 2026'!AF35+'DAILY TMH April 2026'!AI35+'DAILY TMH April 2026'!AG35 -> 0 | G44: ='DAILY TMH April 2026'!AP35+'DAILY TMH April 2026'!AQ35 -> 0 | H44: ='DAILY TMH April 2026'!AS35 -> 0
B45: =SUM(B14:B44) -> 19147.66 | C45: =SUM(C14:C44) -> 28731.24 | D45: =SUM(D14:D44) -> 594.14 | E45: =SUM(E14:E44) -> 0 | F45: =SUM(F14:F44) -> 0 | G45: =SUM(G14:G44) -> 0 | H45: =SUM(H14:H44) -> 137.76
B46: =B45 -> 19147.66 | C46: =C45 -> 28731.24 | D46: =D45 -> 594.14 | E46: =E45 -> 0 | F46: =F45 -> 0 | G46: =G45 -> 0 | H46: =H45 -> 137.76
B47: =B46/SUM($B$46:$H$46) -> 0.39389724 | C47: =C46/SUM($B$46:$H$46) -> 0.59104643 | D47: =D46/SUM($B$46:$H$46) -> 0.012222387 | E47: =E46/SUM($B$46:$H$46) -> 0 | F47: =F46/SUM($B$46:$H$46) -> 0 | G47: =G46/SUM($B$46:$H$46) -> 0 | H47: =H46/SUM($B$46:$H$46) -> 0.0028339381
A48: Month | B48: Stock Levels
B49: HG | C49: LG1 | D49: OB | E49: HG-HMGO | F49: ID CLAY
A50: ='DAILY TMH April 2026'!A5 -> 46113 | B50: =C5 -> 44414.57 | C50: =C6 -> 394234.2 | D50: =C8 -> 11123.38 | E50: =C7 -> 9895.62 | F50: =C9 -> 148.76
A51: ='DAILY TMH April 2026'!A6 -> 46114 | B51: =(B50+'DAILY TMH April 2026'!D5+'DAILY TMH April 2026'!G5)-('DAILY TMH April 2026'!H5+'DAILY TMH April 2026'!I5) -> 44414.57 | C51: =(C50+'DAILY TMH April 2026'!L5+'DAILY TMH April 2026'!O5)-('DAILY TMH April 2026'!P5+'DAILY TMH April 2026'!Q5+'DAILY TMH April 2026'!R5+'DAILY TMH April 2026'!AW5+'DAILY TMH April 2026'!AX5+'DAILY TMH April 2026'!AY5) -> 394511.46 | D51: =(D50+'DAILY TMH April 2026'!W5+'DAILY TMH April 2026'!AA5)-('DAILY TMH April 2026'!AC5+'DAILY TMH April 2026'!AD5+'DAILY TMH April 2026'!AE5) -> 11123.38 | E51: =(E50+'DAILY TMH April 2026'!AH5)-('DAILY TMH April 2026'!AI5) -> 9895.62 | F51: =(F50+'DAILY TMH April 2026'!AT5)-'DAILY TMH April 2026'!AR5-'DAILY TMH April 2026'!AS5 -> 148.76
A52: ='DAILY TMH April 2026'!A7 -> 46115 | B52: =(B51+'DAILY TMH April 2026'!D6+'DAILY TMH April 2026'!G6)-('DAILY TMH April 2026'!H6+'DAILY TMH April 2026'!I6) -> 44414.57 | C52: =(C51+'DAILY TMH April 2026'!L6+'DAILY TMH April 2026'!O6)-('DAILY TMH April 2026'!P6+'DAILY TMH April 2026'!Q6+'DAILY TMH April 2026'!R6+'DAILY TMH April 2026'!AW6+'DAILY TMH April 2026'!AX6+'DAILY TMH April 2026'!AY6) -> 394428.42 | D52: =(D51+'DAILY TMH April 2026'!W6+'DAILY TMH April 2026'!AA6)-('DAILY TMH April 2026'!AC6+'DAILY TMH April 2026'!AD6+'DAILY TMH April 2026'!AE6) -> 11123.38 | E52: =(E51+'DAILY TMH April 2026'!AH6)-('DAILY TMH April 2026'!AI6) -> 9895.62 | F52: =(F51+'DAILY TMH April 2026'!AT6)-'DAILY TMH April 2026'!AR6-'DAILY TMH April 2026'!AS6 -> 148.76
A53: ='DAILY TMH April 2026'!A8 -> 46116 | B53: =(B52+'DAILY TMH April 2026'!D7+'DAILY TMH April 2026'!G7)-('DAILY TMH April 2026'!H7+'DAILY TMH April 2026'!I7) -> 44765.31 | C53: =(C52+'DAILY TMH April 2026'!L7+'DAILY TMH April 2026'!O7)-('DAILY TMH April 2026'!P7+'DAILY TMH April 2026'!Q7+'DAILY TMH April 2026'!R7+'DAILY TMH April 2026'!AW7+'DAILY TMH April 2026'!AX7+'DAILY TMH April 2026'!AY7) -> 395085.88 | D53: =(D52+'DAILY TMH April 2026'!W7+'DAILY TMH April 2026'!AA7)-('DAILY TMH April 2026'!AC7+'DAILY TMH April 2026'!AD7+'DAILY TMH April 2026'!AE7) -> 11123.38 | E53: =(E52+'DAILY TMH April 2026'!AH7)-('DAILY TMH April 2026'!AI7) -> 9895.62 | F53: =(F52+'DAILY TMH April 2026'!AT7)-'DAILY TMH April 2026'!AR7-'DAILY TMH April 2026'!AS7 -> 148.76
A54: ='DAILY TMH April 2026'!A9 -> 46117 | B54: =(B53+'DAILY TMH April 2026'!D8+'DAILY TMH April 2026'!G8)-('DAILY TMH April 2026'!H8+'DAILY TMH April 2026'!I8) -> 45547.01 | C54: =(C53+'DAILY TMH April 2026'!L8+'DAILY TMH April 2026'!O8)-('DAILY TMH April 2026'!P8+'DAILY TMH April 2026'!Q8+'DAILY TMH April 2026'!R8+'DAILY TMH April 2026'!AW8+'DAILY TMH April 2026'!AX8+'DAILY TMH April 2026'!AY8) -> 395085.88 | D54: =(D53+'DAILY TMH April 2026'!W8+'DAILY TMH April 2026'!AA8)-('DAILY TMH April 2026'!AC8+'DAILY TMH April 2026'!AD8+'DAILY TMH April 2026'!AE8) -> 11123.38 | E54: =(E53+'DAILY TMH April 2026'!AH8)-('DAILY TMH April 2026'!AI8) -> 9895.62 | F54: =(F53+'DAILY TMH April 2026'!AT8)-'DAILY TMH April 2026'!AR8-'DAILY TMH April 2026'!AS8 -> 148.76
A55: ='DAILY TMH April 2026'!A10 -> 46118 | B55: =(B54+'DAILY TMH April 2026'!D9+'DAILY TMH April 2026'!G9)-('DAILY TMH April 2026'!H9+'DAILY TMH April 2026'!I9) -> 45507.55 | C55: =(C54+'DAILY TMH April 2026'!L9+'DAILY TMH April 2026'!O9)-('DAILY TMH April 2026'!P9+'DAILY TMH April 2026'!Q9+'DAILY TMH April 2026'!R9+'DAILY TMH April 2026'!AW9+'DAILY TMH April 2026'!AX9+'DAILY TMH April 2026'!AY9) -> 396682.36 | D55: =(D54+'DAILY TMH April 2026'!W9+'DAILY TMH April 2026'!AA9)-('DAILY TMH April 2026'!AC9+'DAILY TMH April 2026'!AD9+'DAILY TMH April 2026'!AE9) -> 11123.38 | E55: =(E54+'DAILY TMH April 2026'!AH9)-('DAILY TMH April 2026'!AI9) -> 9895.62 | F55: =(F54+'DAILY TMH April 2026'!AT9)-'DAILY TMH April 2026'!AR9-'DAILY TMH April 2026'!AS9 -> 148.76
A56: ='DAILY TMH April 2026'!A11 -> 46119 | B56: =(B55+'DAILY TMH April 2026'!D10+'DAILY TMH April 2026'!G10)-('DAILY TMH April 2026'!H10+'DAILY TMH April 2026'!I10) -> 46263.87 | C56: =(C55+'DAILY TMH April 2026'!L10+'DAILY TMH April 2026'!O10)-('DAILY TMH April 2026'!P10+'DAILY TMH April 2026'!Q10+'DAILY TMH April 2026'!R10+'DAILY TMH April 2026'!AW10+'DAILY TMH April 2026'!AX10+'DAILY TMH April 2026'!AY10) -> 396744.48 | D56: =(D55+'DAILY TMH April 2026'!W10+'DAILY TMH April 2026'!AA10)-('DAILY TMH April 2026'!AC10+'DAILY TMH April 2026'!AD10+'DAILY TMH April 2026'!AE10) -> 11123.38 | E56: =(E55+'DAILY TMH April 2026'!AH10)-('DAILY TMH April 2026'!AI10) -> 9895.62 | F56: =(F55+'DAILY TMH April 2026'!AT10)-'DAILY TMH April 2026'!AR10-'DAILY TMH April 2026'!AS10 -> 148.76
A57: ='DAILY TMH April 2026'!A12 -> 46120 | B57: =(B56+'DAILY TMH April 2026'!D11+'DAILY TMH April 2026'!G11)-('DAILY TMH April 2026'!H11+'DAILY TMH April 2026'!I11) -> 45095.07 | C57: =(C56+'DAILY TMH April 2026'!L11+'DAILY TMH April 2026'!O11)-('DAILY TMH April 2026'!P11+'DAILY TMH April 2026'!Q11+'DAILY TMH April 2026'!R11+'DAILY TMH April 2026'!AW11+'DAILY TMH April 2026'!AX11+'DAILY TMH April 2026'!AY11) -> 395791.04 | D57: =(D56+'DAILY TMH April 2026'!W11+'DAILY TMH April 2026'!AA11)-('DAILY TMH April 2026'!AC11+'DAILY TMH April 2026'!AD11+'DAILY TMH April 2026'!AE11) -> 11123.38 | E57: =(E56+'DAILY TMH April 2026'!AH11)-('DAILY TMH April 2026'!AI11) -> 9895.62 | F57: =(F56+'DAILY TMH April 2026'!AT11)-'DAILY TMH April 2026'!AR11-'DAILY TMH April 2026'!AS11 -> 148.76
A58: ='DAILY TMH April 2026'!A13 -> 46121 | B58: =(B57+'DAILY TMH April 2026'!D12+'DAILY TMH April 2026'!G12)-('DAILY TMH April 2026'!H12+'DAILY TMH April 2026'!I12) -> 45283.01 | C58: =(C57+'DAILY TMH April 2026'!L12+'DAILY TMH April 2026'!O12)-('DAILY TMH April 2026'!P12+'DAILY TMH April 2026'!Q12+'DAILY TMH April 2026'!R12+'DAILY TMH April 2026'!AW12+'DAILY TMH April 2026'!AX12+'DAILY TMH April 2026'!AY12) -> 393379.82 | D58: =(D57+'DAILY TMH April 2026'!W12+'DAILY TMH April 2026'!AA12)-('DAILY TMH April 2026'!AC12+'DAILY TMH April 2026'!AD12+'DAILY TMH April 2026'!AE12) -> 11123.38 | E58: =(E57+'DAILY TMH April 2026'!AH12)-('DAILY TMH April 2026'!AI12) -> 9895.62 | F58: =(F57+'DAILY TMH April 2026'!AT12)-'DAILY TMH April 2026'!AR12-'DAILY TMH April 2026'!AS12 -> 148.76
A59: ='DAILY TMH April 2026'!A14 -> 46122 | B59: =(B58+'DAILY TMH April 2026'!D13+'DAILY TMH April 2026'!G13)-('DAILY TMH April 2026'!H13+'DAILY TMH April 2026'!I13) -> 45283.01 | C59: =(C58+'DAILY TMH April 2026'!L13+'DAILY TMH April 2026'!O13)-('DAILY TMH April 2026'!P13+'DAILY TMH April 2026'!Q13+'DAILY TMH April 2026'!R13+'DAILY TMH April 2026'!AW13+'DAILY TMH April 2026'!AX13+'DAILY TMH April 2026'!AY13) -> 390415.06 | D59: =(D58+'DAILY TMH April 2026'!W13+'DAILY TMH April 2026'!AA13)-('DAILY TMH April 2026'!AC13+'DAILY TMH April 2026'!AD13+'DAILY TMH April 2026'!AE13) -> 11123.38 | E59: =(E58+'DAILY TMH April 2026'!AH13)-('DAILY TMH April 2026'!AI13) -> 9895.62 | F59: =(F58+'DAILY TMH April 2026'!AT13)-'DAILY TMH April 2026'!AR13-'DAILY TMH April 2026'!AS13 -> 148.76
A60: ='DAILY TMH April 2026'!A15 -> 46123 | B60: =(B59+'DAILY TMH April 2026'!D14+'DAILY TMH April 2026'!G14)-('DAILY TMH April 2026'!H14+'DAILY TMH April 2026'!I14) -> 43824.87 | C60: =(C59+'DAILY TMH April 2026'!L14+'DAILY TMH April 2026'!O14)-('DAILY TMH April 2026'!P14+'DAILY TMH April 2026'!Q14+'DAILY TMH April 2026'!R14+'DAILY TMH April 2026'!AW14+'DAILY TMH April 2026'!AX14+'DAILY TMH April 2026'!AY14) -> 389232.84 | D60: =(D59+'DAILY TMH April 2026'!W14+'DAILY TMH April 2026'!AA14)-('DAILY TMH April 2026'!AC14+'DAILY TMH April 2026'!AD14+'DAILY TMH April 2026'!AE14) -> 11123.38 | E60: =(E59+'DAILY TMH April 2026'!AH14)-('DAILY TMH April 2026'!AI14) -> 9895.62 | F60: =(F59+'DAILY TMH April 2026'!AT14)-'DAILY TMH April 2026'!AR14-'DAILY TMH April 2026'!AS14 -> 148.76
A61: ='DAILY TMH April 2026'!A16 -> 46124 | B61: =(B60+'DAILY TMH April 2026'!D15+'DAILY TMH April 2026'!G15)-('DAILY TMH April 2026'!H15+'DAILY TMH April 2026'!I15) -> 42792.03 | C61: =(C60+'DAILY TMH April 2026'!L15+'DAILY TMH April 2026'!O15)-('DAILY TMH April 2026'!P15+'DAILY TMH April 2026'!Q15+'DAILY TMH April 2026'!R15+'DAILY TMH April 2026'!AW15+'DAILY TMH April 2026'!AX15+'DAILY TMH April 2026'!AY15) -> 386983.38 | D61: =(D60+'DAILY TMH April 2026'!W15+'DAILY TMH April 2026'!AA15)-('DAILY TMH April 2026'!AC15+'DAILY TMH April 2026'!AD15+'DAILY TMH April 2026'!AE15) -> 11123.38 | E61: =(E60+'DAILY TMH April 2026'!AH15)-('DAILY TMH April 2026'!AI15) -> 9895.62 | F61: =(F60+'DAILY TMH April 2026'!AT15)-'DAILY TMH April 2026'!AR15-'DAILY TMH April 2026'!AS15 -> 148.76
...

Sheet MTD & YTD for Supply (SOUTH)
B1: Supply April TO DATE 2027
C2: 46113 | D2: 46143 | E2: 46174 | F2: 46204 | G2: 46235 | H2: 46266 | I2: 46296 | J2: 46327 | K2: 46357 | L2: 46388 | M2: 46419 | N2: 46447 | O2: YTD
A3: MINES TO STOCK YARD | B3: HG | C3: ='DAILY TMH April 2026'!$D36 -> 3018.22 | O3: =SUM(C3:N3) -> 3018.22
B4: LG1 | C4: ='DAILY TMH April 2026'!$L36 -> 1935.54 | O4: =SUM(C4:N4) -> 1935.54
B5: HGHMGO | C5: ='DAILY TMH April 2026'!$AH36 -> 0 | O5: =SUM(C5:N5) -> 0
B6: OB | C6: ='DAILY TMH April 2026'!$W36 -> 0 | O6: =SUM(C6:N6) -> 0
B7: ID CLAY | O7: =SUM(C7:N7) -> 0
B8: LIMESTONE SPG | O8: =SUM(C8:N8) -> 0
C9: =+C3+C4+C5+C6+C7+C8 -> 4953.76 | D9: =+D3+D4+D5+D6+D7+D8 -> 0 | E9: =+E3+E4+E5+E6+E7+E8 -> 0 | F9: =+F3+F4+F5+F6+F7+F8 -> 0 | G9: =+G3+G4+G5+G6+G7+G8 -> 0 | H9: =+H3+H4+H5+H6+H7+H8 -> 0 | I9: =+I3+I4+I5+I6+I7+I8 -> 0 | J9: =+J3+J4+J5+J6+J7+J8 -> 0 | ... N9: =+N3+N4+N5+N6+N7+N8 -> 0 | O9: =SUM(C9:N9) -> 4953.76
A11: MINES TO PILE THROUGH CRUSHER | B11: HG | C11: ='DAILY TMH April 2026'!$B36 -> 1157.88 | O11: =SUM(C11:N11) -> 1157.88
B12: LG1 | C12: ='DAILY TMH April 2026'!$J36 -> 2448.76 | O12: =SUM(C12:N12) -> 2448.76
B13: HGHMGO | C13: ='DAILY TMH April 2026'!$AF36 -> 0 | O13: =SUM(C13:N13) -> 0
B14: OB | C14: ='DAILY TMH April 2026'!$U36 -> 0 | O14: =SUM(C14:N14) -> 0
B15: ID CLAY | O15: =SUM(C15:N15) -> 0
C16: =+C11+C12+C13+C14+C15 -> 3606.64 | D16: =+D11+D12+D13+D14+D15 -> 0 | E16: =+E11+E12+E13+E14+E15 -> 0 | F16: =+F11+F12+F13+F14+F15 -> 0 | G16: =+G11+G12+G13+G14+G15 -> 0 | H16: =+H11+H12+H13+H14+H15 -> 0 | I16: =+I11+I12+I13+I14+I15 -> 0 | J16: =+J11+J12+J13+J14+J15 -> 0 | ... N16: =+N11+N12+N13+N14+N15 -> 0 | O16: =SUM(C16:N16) -> 3606.64
A18: MINES TO PILE BYPASS CRUSHER | B18: HG | C18: ='DAILY TMH April 2026'!$C36 -> 0 | O18: =SUM(C18:N18) -> 0
B19: LG1 | C19: ='DAILY TMH April 2026'!$K36 -> 1567.56 | O19: =SUM(C19:N19) -> 1567.56
B20: MG - HG | C20: ='DAILY TMH April 2026'!$AG36 -> 0 | O20: =SUM(C20:N20) -> 0
B21: OB | C21: ='DAILY TMH April 2026'!$V36 -> 0 | O21: =SUM(C21:N21) -> 0
B22: ID CLAY | O22: =SUM(C22:N22) -> 0
C23: =+C18+C19+C20+C21+C22 -> 1567.56 | D23: =+D18+D19+D20+D21+D22 -> 0 | E23: =+E18+E19+E20+E21+E22 -> 0 | F23: =+F18+F19+F20+F21+F22 -> 0 | G23: =+G18+G19+G20+G21+G22 -> 0 | H23: =+H18+H19+H20+H21+H22 -> 0 | I23: =+I18+I19+I20+I21+I22 -> 0 | J23: =+J18+J19+J20+J21+J22 -> 0 | ... N23: =+N18+N19+N20+N21+N22 -> 0 | O23: =SUM(C23:N23) -> 1567.56
A25: STOCK YARD TO PILE THROUGH CRUSHER | B25: HG | C25: ='DAILY TMH April 2026'!$H36 -> 9985.72 | O25: =SUM(C25:N25) -> 9985.72
B26: LG1 | C26: ='DAILY TMH April 2026'!$P36 -> 18797.68 | O26: =SUM(C26:N26) -> 18797.68
B27: HGHMGO | C27: ='DAILY TMH April 2026'!$AI36 -> 0 | O27: =SUM(C27:N27) -> 0
B28: OB | C28: ='DAILY TMH April 2026'!$AC36 -> 432.8 | O28: =SUM(C28:N28) -> 432.8
B29: SPG | C29: ='DAILY TMH April 2026'!$S36 -> 0 | O29: =SUM(C29:N29) -> 0
B30: ID CLAY | C30: ='DAILY TMH April 2026'!$AS36 -> 137.76 | O30: =SUM(C30:N30) -> 137.76
C31: =+C25+C26+C27+C28+C29+C30 -> 29353.96 | D31: =+D25+D26+D27+D28+D29+D30 -> 0 | E31: =+E25+E26+E27+E28+E29+E30 -> 0 | F31: =+F25+F26+F27+F28+F29+F30 -> 0 | G31: =+G25+G26+G27+G28+G29+G30 -> 0 | H31: =+H25+H26+H27+H28+H29+H30 -> 0 | I31: =+I25+I26+I27+I28+I29+I30 -> 0 | J31: =+J25+J26+J27+J28+J29+J30 -> 0 | ... N31: =+N25+N26+N27+N28+N29+N30 -> 0 | O31: =SUM(C31:N31) -> 29353.96
A33: STOCK YARD TO PILE BYPASS CRUSHER | B33: HG | C33: ='DAILY TMH April 2026'!$I36 -> 621.92 | O33: =SUM(C33:N33) -> 621.92
B34: LG1 | C34: ='DAILY TMH April 2026'!$Q36 -> 667.22 | O34: =SUM(C34:N34) -> 667.22
B35: HGHMGO | C35: ='DAILY TMH April 2026'!$AM36 -> 0 | O35: =SUM(C35:N35) -> 0
B36: OB | C36: ='DAILY TMH April 2026'!$AE36 -> 161.34 | O36: =SUM(C36:N36) -> 161.34
B37: SPG | C37: ='DAILY TMH April 2026'!$T36 -> 0 | O37: =SUM(C37:N37) -> 0
B38: ID CLAY | O38: =SUM(C38:N38) -> 0
C39: =+C33+C34+C35+C36+C37+C38 -> 1450.48 | D39: =+D33+D34+D35+D36+D37+D38 -> 0 | E39: =+E33+E34+E35+E36+E37+E38 -> 0 | F39: =+F33+F34+F35+F36+F37+F38 -> 0 | G39: =+G33+G34+G35+G36+G37+G38 -> 0 | H39: =+H33+H34+H35+H36+H37+H38 -> 0 | I39: =+I33+I34+I35+I36+I37+I38 -> 0 | J39: =+J33+J34+J35+J36+J37+J38 -> 0 | ... N39: =+N33+N34+N35+N36+N37+N38 -> 0 | O39: =SUM(C39:N39) -> 1450.48
A41: GYPSUM STOCK YARD TO PILE | B41: GYPSUM | C41: ='DAILY TMH April 2026'!$AP36+'DAILY TMH April 2026'!$AQ36 -> 0 | O41: =SUM(C41:N41) -> 0
O42: =SUM(C42:N42) -> 0
A43: OTHER USAGES/PLANT USAGE/Dump | B43: HG | O43: =SUM(C43:N43) -> 0
B44: LG1 | C44: ='DAILY TMH April 2026'!$R36+'DAILY TMH April 2026'!$AX36+'DAILY TMH April 2026'!$AY36+'DAILY TMH April 2026'!$AX36 -> 0 | O44: =SUM(C44:N44) -> 0
B45: MG - HG | O45: =SUM(C45:N45) -> 0
...

Sheet MTD & YTD for Supply(NORTH)
B1: Supply April TO DATE 2027
C2: 46113 | D2: 46143 | E2: 46174 | F2: 46204 | G2: 46235 | H2: 46266 | I2: 46296 | J2: 46327 | K2: 46357 | L2: 46388 | M2: 46419 | N2: 46447 | O2: YTD
A3: MINES TO STOCK YARD | B3: HG | C3: ='DAILY TMH April 2026'!$G36 -> 6912.74 | O3: =SUM(C3:N3) -> 6912.74
B4: LG1 | C4: ='DAILY TMH April 2026'!$O36 -> 5290.36 | O4: =SUM(C4:N4) -> 5290.36
B5: HGHMGO | C5: ='DAILY TMH April 2026'!$O37 -> 0 | O5: =SUM(C5:N5) -> 0
B6: OB | C6: ='DAILY TMH April 2026'!$AA36 -> 0 | O6: =SUM(C6:N6) -> 0
B7: ID CLAY | O7: =SUM(C7:N7) -> 0
B8: LIMESTONE SPG | O8: =SUM(C8:N8) -> 0
C9: =+C3+C4+C5+C6+C7+C8 -> 12203.1 | D9: =+D3+D4+D5+D6+D7+D8 -> 0 | E9: =+E3+E4+E5+E6+E7+E8 -> 0 | F9: =+F3+F4+F5+F6+F7+F8 -> 0 | G9: =+G3+G4+G5+G6+G7+G8 -> 0 | H9: =+H3+H4+H5+H6+H7+H8 -> 0 | I9: =+I3+I4+I5+I6+I7+I8 -> 0 | J9: =+J3+J4+J5+J6+J7+J8 -> 0 | ... N9: =+N3+N4+N5+N6+N7+N8 -> 0 | O9: =SUM(C9:N9) -> 12203.1
A11: MINES TO PILE THROUGH CRUSHER | B11: HG | C11: ='DAILY TMH April 2026'!$E36 -> 5898.14 | O11: =SUM(C11:N11) -> 5898.14
B12: LG1 | C12: ='DAILY TMH April 2026'!$M36 -> 4803.74 | O12: =SUM(C12:N12) -> 4803.74
B13: HGHMGO | O13: =SUM(C13:N13) -> 0
B14: OB | C14: ='DAILY TMH April 2026'!$Y36 -> 0 | O14: =SUM(C14:N14) -> 0
B15: ID CLAY | O15: =SUM(C15:N15) -> 0
C16: =+C11+C12+C13+C14+C15 -> 10701.88 | D16: =+D11+D12+D13+D14+D15 -> 0 | E16: =+E11+E12+E13+E14+E15 -> 0 | F16: =+F11+F12+F13+F14+F15 -> 0 | G16: =+G11+G12+G13+G14+G15 -> 0 | H16: =+H11+H12+H13+H14+H15 -> 0 | I16: =+I11+I12+I13+I14+I15 -> 0 | J16: =+J11+J12+J13+J14+J15 -> 0 | ... N16: =+N11+N12+N13+N14+N15 -> 0 | O16: =SUM(C16:N16) -> 10701.88
A18: MINES TO PILE BYPASS CRUSHER | B18: HG | C18: ='DAILY TMH April 2026'!$F36 -> 1484 | O18: =SUM(C18:N18) -> 1484
B19: LG1 | C19: ='DAILY TMH April 2026'!$N36 -> 446.28 | O19: =SUM(C19:N19) -> 446.28
B20: MG - HG | O20: =SUM(C20:N20) -> 0
B21: OB | C21: ='DAILY TMH April 2026'!$Z36 -> 0 | O21: =SUM(C21:N21) -> 0
B22: ID CLAY | O22: =SUM(C22:N22) -> 0
C23: =+C18+C19+C20+C21+C22 -> 1930.28 | D23: =+D18+D19+D20+D21+D22 -> 0 | E23: =+E18+E19+E20+E21+E22 -> 0 | F23: =+F18+F19+F20+F21+F22 -> 0 | G23: =+G18+G19+G20+G21+G22 -> 0 | H23: =+H18+H19+H20+H21+H22 -> 0 | I23: =+I18+I19+I20+I21+I22 -> 0 | J23: =+J18+J19+J20+J21+J22 -> 0 | ... N23: =+N18+N19+N20+N21+N22 -> 0 | O23: =SUM(C23:N23) -> 1930.28
A25: STOCK YARD TO PILE THROUGH CRUSHER | B25: HG | O25: =SUM(C25:N25) -> 0
B26: LG1 | O26: =SUM(C26:N26) -> 0
B27: HGHMGO | O27: =SUM(C27:N27) -> 0
B28: OB | O28: =SUM(C28:N28) -> 0
B29: SPG | O29: =SUM(C29:N29) -> 0
B30: ID CLAY | O30: =SUM(C30:N30) -> 0
C31: =+C25+C26+C27+C28+C29+C30 -> 0 | D31: =+D25+D26+D27+D28+D29+D30 -> 0 | E31: =+E25+E26+E27+E28+E29+E30 -> 0 | F31: =+F25+F26+F27+F28+F29+F30 -> 0 | G31: =+G25+G26+G27+G28+G29+G30 -> 0 | H31: =+H25+H26+H27+H28+H29+H30 -> 0 | I31: =+I25+I26+I27+I28+I29+I30 -> 0 | J31: =+J25+J26+J27+J28+J29+J30 -> 0 | ... N31: =+N25+N26+N27+N28+N29+N30 -> 0 | O31: =SUM(C31:N31) -> 0
A33: STOCK YARD TO PILE BYPASS CRUSHER | B33: HG | O33: =SUM(C33:N33) -> 0
B34: LG1 | O34: =SUM(C34:N34) -> 0
B35: HGHMGO | O35: =SUM(C35:N35) -> 0
B36: OB | O36: =SUM(C36:N36) -> 0
B37: SPG | O37: =SUM(C37:N37) -> 0 | U37: ='MTD & YTD for Supply(NORTH)'!#REF! -> #REF!
B38: ID CLAY | O38: =SUM(C38:N38) -> 0
C39: =+C33+C34+C35+C36+C37+C38 -> 0 | D39: =+D33+D34+D35+D36+D37+D38 -> 0 | E39: =+E33+E34+E35+E36+E37+E38 -> 0 | F39: =+F33+F34+F35+F36+F37+F38 -> 0 | G39: =+G33+G34+G35+G36+G37+G38 -> 0 | H39: =+H33+H34+H35+H36+H37+H38 -> 0 | I39: =+I33+I34+I35+I36+I37+I38 -> 0 | J39: =+J33+J34+J35+J36+J37+J38 -> 0 | ... N39: =+N33+N34+N35+N36+N37+N38 -> 0 | O39: =SUM(C39:N39) -> 0
A41: GYPSUM STOCK YARD TO PILE | B41: GYPSUM | O41: =SUM(C41:N41) -> 0
O42: =SUM(C42:N42) -> 0
A43: OTHER USAGES/PLANT USAGE/Dump | B43: HG | O43: =SUM(C43:N43) -> 0
B44: LG1 | O44: =SUM(C44:N44) -> 0
B45: MG - HG | O45: =SUM(C45:N45) -> 0
...

Sheet DAILY TMH April 2026
J1: Raw Material
A3: Date | B3: HG from South | E3: HG from North | H3: HG from Stock | J3: LG1 from South | M3: LG1 from North | P3: LG1 from Stock | S3: LIMESTONE SPG | U3: OB from South | Y3: OB from North | AC3: OB from Stock | AF3: MG-HG from South | AI3: MG -HG Stock to crusher | AJ3: MG-LG from South | AM3: MG-LG Stock to Crusher | AN3: TMH | AP3: Gypsum to Crusher | AR3: Id Clay | AU3: TOTAL TMH | AV3: without Overburden | AW3: LG1 Limestone hauled by lcl truck | AX3: LG1 to Other usage by `Digalla | AY3: LG1 to Other usage by On Africa
B4: Crusher | C4: Direct to Pile | D4: Stock | E4: Crusher | F4: Direct to Pile | G4: Stock | H4: Crusher | I4: Direct to Pile | J4: Crusher | K4: Direct to Pile | L4: Stock | M4: Crusher | N4: Direct to Pile | O4: Stock | P4: Crusher | Q4: Direct to Pile | R4: Other Usage | S4: Crusher | T4: Direct to Pile | U4: Crusher | V4: Direct to Pile | W4: Stock | X4: Waste Dump | Y4: Crusher | Z4: Direct to Pile | AA4: Stock | AB4: Waste Dump | AC4: Crusher | AD4: Other Usages | AE4: Direct to Pile | AF4: Crusher | AG4: Direct to Pile | AH4: stock | AJ4: Crusher | AK4: Direct to Pile | AL4: STOCK | AP4: Crusher | AQ4: Direct(Lcl) | AR4: Stock to Other Usages | AS4: Stock to pile | AT4: kijaka-Stock | AZ4: VIA CRUSHER | BA4: TOTAL
A5: 46113 | B5: {=SUMPRODUCT((Uploaded_Data!$D$2:$D$59696="Production Transfers")*(Uploaded_Data!$E$2:$E$59696="South Mine to Pile (through Crusher)")*(Uploaded_Data!$F$2:$F$59696="HG")*((Uploaded_Data!$H$2:$H$59696=$A$5-1)+(Uploaded_Data!$H$2:$H$59696=$A$5))*Uploaded_Data!$N$2:$N$59696)} -> 0 | C5: {=SUMPRODUCT((Uploaded_Data!$D$2:$D$59696="Production Transfers")*(Uploaded_Data!$E$2:$E$59696="South Mine to Direct Pile (Bypass Crusher)")*(Uploaded_Data!$F$2:$F$59696="HG")*((Uploaded_Data!$H$2:$H$59696=$A$5-1)+(Uploaded_Data!$H$2:$H$59696=$A$5))*Uploaded_Data!$N$2:$N$59696)} -> 0 | D5: {=SUMPRODUCT((Uploaded_Data!$D$2:$D$59696="Production Transfers")*(Uploaded_Data!$E$2:$E$59696="South Mine to Stock Yard")*(Uploaded_Data!$F$2:$F$59696="HG")*((Uploaded_Data!$H$2:$H$59696=$A$5-1)+(Uploaded_Data!$H$2:$H$59696=$A$5))*Uploaded_Data!$N$2:$N$59696)} -> 0 | E5: {=SUMPRODUCT((Uploaded_Data!$D$2:$D$59696="Production Transfers")*(Uploaded_Data!$E$2:$E$59696="North Mine to Pile (through Crusher)")*(Uploaded_Data!$F$2:$F$59696="HG")*((Uploaded_Data!$H$2:$H$59696=$A$5-1)+(Uploaded_Data!$H$2:$H$59696=$A$5))*Uploaded_Data!$N$2:$N$59696)} -> 0 | F5: {=SUMPRODUCT((Uploaded_Data!$D$2:$D$59696="Production Transfers")*(Uploaded_Data!$E$2:$E$59696="North Mine to Direct Pile (Bypass Crusher)")*(Uploaded_Data!$F$2:$F$59696="HG")*((Uploaded_Data!$H$2:$H$59696=$A$5-1)+(Uploaded_Data!$H$2:$H$59696=$A$5))*Uploaded_Data!$N$2:$N$59696)} -> 0 | G5: {=SUMPRODUCT((Uploaded_Data!$D$2:$D$59696="Production Transfers")*(Uploaded_Data!$E$2:$E$59696="North Mine to Stock Yard")*(Uploaded_Data!$F$2:$F$59696="HG")*((Uploaded_Data!$H$2:$H$59696=$A$5-1)+(Uploaded_Data!$H$2:$H$59696=$A$5))*Uploaded_Data!$N$2:$N$59696)} -> 0 | H5: {=SUMPRODUCT((Uploaded_Data!$D$2:$D$59696="Internal Transfers")*(Uploaded_Data!$E$2:$E$59696="Stock Yard to Pile (through Crusher)")*(Uploaded_Data!$F$2:$F$59696="HG")*((Uploaded_Data!$H$2:$H$59696=$A$5-1)+(Uploaded_Data!$H$2:$H$59696=$A$5))*Uploaded_Data!$N$2:$N$59696)} -> 0 | I5: {=SUMPRODUCT((Uploaded_Data!$D$2:$D$59696="Internal Transfers")*(Uploaded_Data!$E$2:$E$59696="Stock Yard to Direct Pile (Bypass Crusher)")*(Uploaded_Data!$F$2:$F$59696="HG")*((Uploaded_Data!$H$2:$H$59696=$A$5-1)+(Uploaded_Data!$H$2:$H$59696=$A$5))*Uploaded_Data!$N$2:$N$59696)} -> 0 | J5: {=SUMPRODUCT((Uploaded_Data!$D$2:$D$59696="Production Transfers")*(Uploaded_Data!$E$2:$E$59696="South Mine to Pile (through Crusher)")*(Uploaded_Data!$F$2:$F$59696="LG1")*((Uploaded_Data!$H$2:$H$59696=$A$5-1)+(Uploaded_Data!$H$2:$H$59696=$A$5))*Uploaded_Data!$N$2:$N$59696)} -> 0 | K5: {=SUMPRODUCT((Uploaded_Data!$D$2:$D$59696="Production Transfers")*(Uploaded_Data!$E$2:$E$59696="South Mine to Direct Pile (Bypass Crusher)")*(Uploaded_Data!$F$2:$F$59696="LG1")*((Uploaded_Data!$H$2:$H$59696=$A$5-1)+(Uploaded_Data!$H$2:$H$59696=$A$5))*Uploaded_Data!$N$2:$N$59696)} -> 0 | L5: {=SUMPRODUCT((Uploaded_Data!$D$2:$D$59696="Production Transfers")*(Uploaded_Data!$E$2:$E$59696="South Mine to Stock Yard")*(Uploaded_Data!$F$2:$F$59696="LG1")*((Uploaded_Data!$H$2:$H$59696=$A$5-1)+(Uploaded_Data!$H$2:$H$59696=$A$5))*Uploaded_Data!$N$2:$N$59696)} -> 0 | M5: {=SUMPRODUCT((Uploaded_Data!$D$2:$D$59696="Production Transfers")*(Uploaded_Data!$E$2:$E$59696="North Mine to Pile (through Crusher)")*(Uploaded_Data!$F$2:$F$59696="LG1")*((Uploaded_Data!$H$2:$H$59696=$A$5-1)+(Uploaded_Data!$H$2:$H$59696=$A$5))*Uploaded_Data!$N$2:$N$59696)} -> 0 | N5: {=SUMPRODUCT((Uploaded_Data!$D$2:$D$59696="Production Transfers")*(Uploaded_Data!$E$2:$E$59696="North Mine to Direct Pile (Bypass Crusher)")*(Uploaded_Data!$F$2:$F$59696="LG1")*((Uploaded_Data!$H$2:$H$59696=$A$5-1)+(Uploaded_Data!$H$2:$H$59696=$A$5))*Uploaded_Data!$N$2:$N$59696)} -> 0 | O5: {=SUMPRODUCT((Uploaded_Data!$D$2:$D$59696="Production Transfers")*(Uploaded_Data!$E$2:$E$59696="North Mine to Stock Yard")*(Uploaded_Data!$F$2:$F$59696="LG1")*((Uploaded_Data!$H$2:$H$59696=$A$5-1)+(Uploaded_Data!$H$2:$H$59696=$A$5))*Uploaded_Data!$N$2:$N$59696)} -> 678.4 | P5: {=SUMPRODUCT((Uploaded_Data!$D$2:$D$59696="Internal Transfers")*(Uploaded_Data!$E$2:$E$59696="Stock Yard to Pile (through Crusher)")*(Uploaded_Data!$F$2:$F$59696="LG1")*((Uploaded_Data!$H$2:$H$59696=$A$5-1)+(Uploaded_Data!$H$2:$H$59696=$A$5))*Uploaded_Data!$N$2:$N$59696)} -> 0 | Q5: {=SUMPRODUCT((Uploaded_Data!$D$2:$D$59696="Internal Transfers")*(Uploaded_Data!$E$2:$E$59696="Stock Yard to Direct Pile (Bypass Crusher)")*(Uploaded_Data!$F$2:$F$59696="LG1")*((Uploaded_Data!$H$2:$H$59696=$A$5-1)+(Uploaded_Data!$H$2:$H$59696=$A$5))*Uploaded_Data!$N$2:$N$59696)} -> 401.14 | R5: {=SUMPRODUCT((Uploaded_Data!$D$2:$D$59696="Internal Transfers")*(Uploaded_Data!$E$2:$E$59696="Stock Yard to Other Usages")*(Uploaded_Data!$F$2:$F$59696="LG1")*((Uploaded_Data!$H$2:$H$59696=$A$5-1)+(Uploaded_Data!$H$2:$H$59696=$A$5))*Uploaded_Data!$N$2:$N$59696)} -> 0 | S5: {=SUMPRODUCT((Uploaded_Data!$D$2:$D$59696="Internal Transfers")*(Uploaded_Data!$E$2:$E$59696="Stock Yard to Pile (through Crusher)")*(Uploaded_Data!$F$2:$F$59696="LIMESTONE SPG")*((Uploaded_Data!$H$2:$H$59696=$A$5-1)+(Uploaded_Data!$H$2:$H$59696=$A$5))*Uploaded_Data!$N$2:$N$59696)} -> 0 | T5: {=SUMPRODUCT((Uploaded_Data!$D$2:$D$59696="Internal Transfers")*(Uploaded_Data!$E$2:$E$59696="Stock Yard to Direct Pile (Bypass Crusher)")*(Uploaded_Data!$F$2:$F$59696="LIMESTONE SPG")*((Uploaded_Data!$H$2:$H$59696=$A$5-1)+(Uploaded_Data!$H$2:$H$59696=$A$5))*Uploaded_Data!$N$2:$N$59696)} -> 0 | U5: {=SUMPRODUCT((Uploaded_Data!$D$2:$D$59696="Production Transfers")*(Uploaded_Data!$E$2:$E$59696="South Mine to Pile (through Crusher)")*(Uploaded_Data!$F$2:$F$59696="OB/CLAY")*((Uploaded_Data!$H$2:$H$59696=$A$5-1)+(Uploaded_Data!$H$2:$H$59696=$A$5))*Uploaded_Data!$N$2:$N$59696)} -> 0 | V5: {=SUMPRODUCT((Uploaded_Data!$D$2:$D$59696="Production Transfers")*(Uploaded_Data!$E$2:$E$59696="South Mine to Direct Pile (Bypass Crusher)")*(Uploaded_Data!$F$2:$F$59696="OB/CLAY")*((Uploaded_Data!$H$2:$H$59696=$A$5-1)+(Uploaded_Data!$H$2:$H$59696=$A$5))*Uploaded_Data!$N$2:$N$59696)} -> 0 | W5: {=SUMPRODUCT((Uploaded_Data!$D$2:$D$59696="Production Transfers")*(Uploaded_Data!$E$2:$E$59696="South Mine to Stock Yard")*(Uploaded_Data!$F$2:$F$59696="OB/CLAY")*((Uploaded_Data!$H$2:$H$59696=$A$5-1)+(Uploaded_Data!$H$2:$H$59696=$A$5))*Uploaded_Data!$N$2:$N$59696)} -> 0 | X5: {=SUMPRODUCT((Uploaded_Data!$D$2:$D$59696="Production Transfers")*(Uploaded_Data!$E$2:$E$59696="South Mine to Golani Waste dump")*(Uploaded_Data!$F$2:$F$59696="WASTE")*((Uploaded_Data!$H$2:$H$59696=$A$5-1)+(Uploaded_Data!$H$2:$H$59696=$A$5))*Uploaded_Data!$N$2:$N$59696)} -> 0 | Y5: {=SUMPRODUCT((Uploaded_Data!$D$2:$D$59696="Production Transfers")*(Uploaded_Data!$E$2:$E$59696="North Mine to Pile (through Crusher)")*(Uploaded_Data!$F$2:$F$59696="OB/CLAY")*((Uploaded_Data!$H$2:$H$59696=$A$5-1)+(Uploaded_Data!$H$2:$H$59696=$A$5))*Uploaded_Data!$N$2:$N$59696)} -> 0 | Z5: {=SUMPRODUCT((Uploaded_Data!$D$2:$D$59696="Production Transfers")*(Uploaded_Data!$E$2:$E$59696="North Mine to Direct Pile (Bypass Crusher)")*(Uploaded_Data!$F$2:$F$59696="OB/CLAY")*((Uploaded_Data!$H$2:$H$59696=$A$5-1)+(Uploaded_Data!$H$2:$H$59696=$A$5))*Uploaded_Data!$N$2:$N$59696)} -> 0 | AA5: {=SUMPRODUCT((Uploaded_Data!$D$2:$D$59696="Production Transfers")*(Uploaded_Data!$E$2:$E$59696="North Mine to Stock Yard")*(Uploaded_Data!$F$2:$F$59696="OB/CLAY")*((Uploaded_Data!$H$2:$H$59696=$A$5-1)+(Uploaded_Data!$H$2:$H$59696=$A$5))*Uploaded_Data!$N$2:$N$59696)} -> 0 | AB5: {=SUMPRODUCT((Uploaded_Data!$D$2:$D$59696="Production Transfers")*(Uploaded_Data!$E$2:$E$59696="North Mine to Golani Waste dump")*(Uploaded_Data!$F$2:$F$59696="WASTE")*((Uploaded_Data!$H$2:$H$59696=$A$5-1)+(Uploaded_Data!$H$2:$H$59696=$A$5))*Uploaded_Data!$N$2:$N$59696)} -> 1500 | AC5: {=SUMPRODUCT((Uploaded_Data!$D$2:$D$59696="Internal Transfers")*(Uploaded_Data!$E$2:$E$59696="Stock Yard to Pile (through Crusher)")*(Uploaded_Data!$F$2:$F$59696="OB/CLAY")*((Uploaded_Data!$H$2:$H$59696=$A$5-1)+(Uploaded_Data!$H$2:$H$59696=$A$5))*Uploaded_Data!$N$2:$N$59696)} -> 0 | AD5: {=SUMPRODUCT((Uploaded_Data!$D$2:$D$59696="Internal Transfers")*(Uploaded_Data!$E$2:$E$59696="Stock Yard to Other Usages")*(Uploaded_Data!$F$2:$F$59696="OB/CLAY")*((Uploaded_Data!$H$2:$H$59696=$A$5-1)+(Uploaded_Data!$H$2:$H$59696=$A$5))*Uploaded_Data!$N$2:$N$59696)} -> 0 | AE5: {=SUMPRODUCT((Uploaded_Data!$D$2:$D$59696="Internal Transfers")*(Uploaded_Data!$E$2:$E$59696="Stock Yard to Direct Pile (Bypass Crusher)")*(Uploaded_Data!$F$2:$F$59696="OB/CLAY")*((Uploaded_Data!$H$2:$H$59696=$A$5-1)+(Uploaded_Data!$H$2:$H$59696=$A$5))*Uploaded_Data!$N$2:$N$59696)} -> 0 | AF5: {=SUMPRODUCT((Uploaded_Data!$D$2:$D$59696="Production Transfers")*(Uploaded_Data!$E$2:$E$59696="South Mine to Pile (through Crusher)")*(Uploaded_Data!$F$2:$F$59696="HGHMGO")*((Uploaded_Data!$H$2:$H$59696=$A$5-1)+(Uploaded_Data!$H$2:$H$59696=$A$5))*Uploaded_Data!$N$2:$N$59696)} -> 0 | AG5: {=SUMPRODUCT((Uploaded_Data!$D$2:$D$59696="Production Transfers")*(Uploaded_Data!$E$2:$E$59696="South Mine to Direct Pile (Bypass Crusher)")*(Uploaded_Data!$F$2:$F$59696="HGHMGO")*((Uploaded_Data!$H$2:$H$59696=$A$5-1)+(Uploaded_Data!$H$2:$H$59696=$A$5))*Uploaded_Data!$N$2:$N$59696)} -> 0 | AH5: {=SUMPRODUCT((Uploaded_Data!$D$2:$D$59696="Production Transfers")*(Uploaded_Data!$E$2:$E$59696="South Mine to Stock Yard")*(Uploaded_Data!$F$2:$F$59696="HGHMGO")*((Uploaded_Data!$H$2:$H$59696=$A$5-1)+(Uploaded_Data!$H$2:$H$59696=$A$5))*Uploaded_Data!$N$2:$N$59696)} -> 0 | AI5: {=SUMPRODUCT((Uploaded_Data!$D$2:$D$59696="Internal Transfers")*(Uploaded_Data!$E$2:$E$59696="Stock Yard to Pile (through Crusher)")*(Uploaded_Data!$F$2:$F$59696="HGHMGO")*((Uploaded_Data!$H$2:$H$59696=$A$5-1)+(Uploaded_Data!$H$2:$H$59696=$A$5))*Uploaded_Data!$N$2:$N$59696)} -> 0 | AJ5: {=SUMPRODUCT((Uploaded_Data!$D$2:$D$59696="Production Transfers")*(Uploaded_Data!$E$2:$E$59696="South Mine to Pile (through Crusher)")*(Uploaded_Data!$F$2:$F$59696="LGHMGO")*((Uploaded_Data!$H$2:$H$59696=$A$5-1)+(Uploaded_Data!$H$2:$H$59696=$A$5))*Uploaded_Data!$N$2:$N$59696)} -> 0 | AK5: {=SUMPRODUCT((Uploaded_Data!$D$2:$D$59696="Production Transfers")*(Uploaded_Data!$E$2:$E$59696="South Mine to Direct Pile (Bypass Crusher)")*(Uploaded_Data!$F$2:$F$59696="LGHMGO")*((Uploaded_Data!$H$2:$H$59696=$A$5-1)+(Uploaded_Data!$H$2:$H$59696=$A$5))*Uploaded_Data!$N$2:$N$59696)} -> 0 | AL5: {=SUMPRODUCT((Uploaded_Data!$D$2:$D$59696="Production Transfers")*(Uploaded_Data!$E$2:$E$59696="South Mine to Stock Yard")*(Uploaded_Data!$F$2:$F$59696="LGHMGO")*((Uploaded_Data!$H$2:$H$59696=$A$5-1)+(Uploaded_Data!$H$2:$H$59696=$A$5))*Uploaded_Data!$N$2:$N$59696)} -> 0 | AM5: {=SUMPRODUCT((Uploaded_Data!$D$2:$D$59696="Internal Transfers")*(Uploaded_Data!$E$2:$E$59696="Stock Yard to Pile (through Crusher)")*(Uploaded_Data!$F$2:$F$59696="LGHMGO")*((Uploaded_Data!$H$2:$H$59696=$A$5-1)+(Uploaded_Data!$H$2:$H$59696=$A$5))*Uploaded_Data!$N$2:$N$59696)} -> 0 | AN5: =SUM(B5:AM5) -> 2579.54 | AP5: {=SUMPRODUCT((Uploaded_Data!$D$2:$D$59696="Internal Transfers")*(Uploaded_Data!$E$2:$E$59696="Stock Yard to Pile (through Crusher)")*(Uploaded_Data!$F$2:$F$59696="GYPSUM")*((Uploaded_Data!$H$2:$H$59696=$A$5-1)+(Uploaded_Data!$H$2:$H$59696=$A$5))*Uploaded_Data!$N$2:$N$59696)} -> 0 | AQ5: {=SUMPRODUCT((Uploaded_Data!$D$2:$D$59696="Internal Transfers")*(Uploaded_Data!$E$2:$E$59696="Stock Yard to Direct Pile (Bypass Crusher)")*(Uploaded_Data!$F$2:$F$59696="GYPSUM")*((Uploaded_Data!$H$2:$H$59696=$A$5-1)+(Uploaded_Data!$H$2:$H$59696=$A$5))*Uploaded_Data!$N$2:$N$59696)} -> 0 | AR5: {=SUMPRODUCT((Uploaded_Data!$D$2:$D$59696="Internal Transfers")*(Uploaded_Data!$E$2:$E$59696="Stock Yard to Other Usages")*(Uploaded_Data!$F$2:$F$59696="ID Clay")*((Uploaded_Data!$H$2:$H$59696=$A$5-1)+(Uploaded_Data!$H$2:$H$59696=$A$5))*Uploaded_Data!$N$2:$N$59696)} -> 0 | AS5: {=SUMPRODUCT((Uploaded_Data!$D$2:$D$59696="Internal Transfers")*(Uploaded_Data!$E$2:$E$59696="Stock Yard to Direct Pile (Bypass Crusher)")*(Uploaded_Data!$F$2:$F$59696="ID Clay")*((Uploaded_Data!$H$2:$H$59696=$A$5-1)+(Uploaded_Data!$H$2:$H$59696=$A$5))*Uploaded_Data!$N$2:$N$59696)} -> 0 | AT5: {=SUMPRODUCT((Uploaded_Data!$D$2:$D$59696="Production Transfers")*(Uploaded_Data!$E$2:$E$59696="Kijaka Mine to Stock Yard")*(Uploaded_Data!$F$2:$F$59696="ID Clay")*((Uploaded_Data!$H$2:$H$59696=$A$5-1)+(Uploaded_Data!$H$2:$H$59696=$A$5))*Uploaded_Data!$N$2:$N$59696)} -> 0 | AU5: =AN5+AP5+AQ5+AR5+AS5+AT5 -> 2579.54 | AV5: =AU5-AB5-X5 -> 1079.54 | AZ5: =B5+H5+J5+P5+U5+AC5+AF5+AJ5+AP5+S5+AI5+Y5+M5+E5 -> 0 | BA5: =AU5 -> 2579.54
A6: 46114 | B6: {=SUMPRODUCT((Uploaded_Data!$D$2:$D$59696="Production Transfers")*(Uploaded_Data!$E$2:$E$59696="South Mine to Pile (through Crusher)")*(Uploaded_Data!$F$2:$F$59696="HG")*(Uploaded_Data!$H$2:$H$59696=$A6)*Uploaded_Data!$N$2:$N$59696)} -> 0 | C6: {=SUMPRODUCT((Uploaded_Data!$D$2:$D$59696="Production Transfers")*(Uploaded_Data!$E$2:$E$59696="South Mine to Direct Pile (Bypass Crusher)")*(Uploaded_Data!$F$2:$F$59696="HG")*(Uploaded_Data!$H$2:$H$59696=$A6)*Uploaded_Data!$N$2:$N$59696)} -> 0 | D6: {=SUMPRODUCT((Uploaded_Data!$D$2:$D$59696="Production Transfers")*(Uploaded_Data!$E$2:$E$59696="South Mine to Stock Yard")*(Uploaded_Data!$F$2:$F$59696="HG")*(Uploaded_Data!$H$2:$H$59696=$A6)*Uploaded_Data!$N$2:$N$59696)} -> 0 | E6: {=SUMPRODUCT((Uploaded_Data!$D$2:$D$59696="Production Transfers")*(Uploaded_Data!$E$2:$E$59696="North Mine to Pile (through Crusher)")*(Uploaded_Data!$F$2:$F$59696="HG")*(Uploaded_Data!$H$2:$H$59696=$A6)*Uploaded_Data!$N$2:$N$59696)} -> 0 | F6: {=SUMPRODUCT((Uploaded_Data!$D$2:$D$59696="Production Transfers")*(Uploaded_Data!$E$2:$E$59696="North Mine to Direct Pile (Bypass Crusher)")*(Uploaded_Data!$F$2:$F$59696="HG")*(Uploaded_Data!$H$2:$H$59696=$A6)*Uploaded_Data!$N$2:$N$59696)} -> 0 | G6: {=SUMPRODUCT((Uploaded_Data!$D$2:$D$59696="Production Transfers")*(Uploaded_Data!$E$2:$E$59696="North Mine to Stock Yard")*(Uploaded_Data!$F$2:$F$59696="HG")*(Uploaded_Data!$H$2:$H$59696=$A6)*Uploaded_Data!$N$2:$N$59696)} -> 0 | H6: {=SUMPRODUCT((Uploaded_Data!$D$2:$D$59696="Internal Transfers")*(Uploaded_Data!$E$2:$E$59696="Stock Yard to Pile (through Crusher)")*(Uploaded_Data!$F$2:$F$59696="HG")*(Uploaded_Data!$H$2:$H$59696=$A6)*Uploaded_Data!$N$2:$N$59696)} -> 0 | I6: {=SUMPRODUCT((Uploaded_Data!$D$2:$D$59696="Internal Transfers")*(Uploaded_Data!$E$2:$E$59696="Stock Yard to Direct Pile (Bypass Crusher)")*(Uploaded_Data!$F$2:$F$59696="HG")*(Uploaded_Data!$H$2:$H$59696=$A6)*Uploaded_Data!$N$2:$N$59696)} -> 0 | J6: {=SUMPRODUCT((Uploaded_Data!$D$2:$D$59696="Production Transfers")*(Uploaded_Data!$E$2:$E$59696="South Mine to Pile (through Crusher)")*(Uploaded_Data!$F$2:$F$59696="LG1")*(Uploaded_Data!$H$2:$H$59696=$A6)*Uploaded_Data!$N$2:$N$59696)} -> 527.4 | K6: {=SUMPRODUCT((Uploaded_Data!$D$2:$D$59696="Production Transfers")*(Uploaded_Data!$E$2:$E$59696="South Mine to Direct Pile (Bypass Crusher)")*(Uploaded_Data!$F$2:$F$59696="LG1")*(Uploaded_Data!$H$2:$H$59696=$A6)*Uploaded_Data!$N$2:$N$59696)} -> 198.04 | L6: {=SUMPRODUCT((Uploaded_Data!$D$2:$D$59696="Production Transfers")*(Uploaded_Data!$E$2:$E$59696="South Mine to Stock Yard")*(Uploaded_Data!$F$2:$F$59696="LG1")*(Uploaded_Data!$H$2:$H$59696=$A6)*Uploaded_Data!$N$2:$N$59696)} -> 0 | M6: {=SUMPRODUCT((Uploaded_Data!$D$2:$D$59696="Production Transfers")*(Uploaded_Data!$E$2:$E$59696="North Mine to Pile (through Crusher)")*(Uploaded_Data!$F$2:$F$59696="LG1")*(Uploaded_Data!$H$2:$H$59696=$A6)*Uploaded_Data!$N$2:$N$59696)} -> 0 | N6: {=SUMPRODUCT((Uploaded_Data!$D$2:$D$59696="Production Transfers")*(Uploaded_Data!$E$2:$E$59696="North Mine to Direct Pile (Bypass Crusher)")*(Uploaded_Data!$F$2:$F$59696="LG1")*(Uploaded_Data!$H$2:$H$59696=$A6)*Uploaded_Data!$N$2:$N$59696)} -> 0 | O6: {=SUMPRODUCT((Uploaded_Data!$D$2:$D$59696="Production Transfers")*(Uploaded_Data!$E$2:$E$59696="North Mine to Stock Yard")*(Uploaded_Data!$F$2:$F$59696="LG1")*(Uploaded_Data!$H$2:$H$59696=$A6)*Uploaded_Data!$N$2:$N$59696)} -> 0 | P6: {=SUMPRODUCT((Uploaded_Data!$D$2:$D$59696="Internal Transfers")*(Uploaded_Data!$E$2:$E$59696="Stock Yard to Pile (through Crusher)")*(Uploaded_Data!$F$2:$F$59696="LG1")*(Uploaded_Data!$H$2:$H$59696=$A6)*Uploaded_Data!$N$2:$N$59696)} -> 41.38 | Q6: {=SUMPRODUCT((Uploaded_Data!$D$2:$D$59696="Internal Transfers")*(Uploaded_Data!$E$2:$E$59696="Stock Yard to Direct Pile (Bypass Crusher)")*(Uploaded_Data!$F$2:$F$59696="LG1")*(Uploaded_Data!$H$2:$H$59696=$A6)*Uploaded_Data!$N$2:$N$59696)} -> 41.66 | R6: {=SUMPRODUCT((Uploaded_Data!$D$2:$D$59696="Internal Transfers")*(Uploaded_Data!$E$2:$E$59696="Stock Yard to Other Usages")*(Uploaded_Data!$F$2:$F$59696="LG1")*(Uploaded_Data!$H$2:$H$59696=$A6)*Uploaded_Data!$N$2:$N$59696)} -> 0 | S6: {=SUMPRODUCT((Uploaded_Data!$D$2:$D$59696="Internal Transfers")*(Uploaded_Data!$E$2:$E$59696="Stock Yard to Pile (through Crusher)")*(Uploaded_Data!$F$2:$F$59696="LIMESTONE SPG")*(Uploaded_Data!$H$2:$H$59696=$A6)*Uploaded_Data!$N$2:$N$59696)} -> 0 | T6: {=SUMPRODUCT((Uploaded_Data!$D$2:$D$59696="Internal Transfers")*(Uploaded_Data!$E$2:$E$59696="Stock Yard to Direct Pile (Bypass Crusher)")*(Uploaded_Data!$F$2:$F$59696="LIMESTONE SPG")*(Uploaded_Data!$H$2:$H$59696=$A6)*Uploaded_Data!$N$2:$N$59696)} -> 0 | U6: {=SUMPRODUCT((Uploaded_Data!$D$2:$D$59696="Production Transfers")*(Uploaded_Data!$E$2:$E$59696="South Mine to Pile (through Crusher)")*(Uploaded_Data!$F$2:$F$59696="OB/CLAY")*(Uploaded_Data!$H$2:$H$59696=$A6)*Uploaded_Data!$N$2:$N$59696)} -> 0 | V6: {=SUMPRODUCT((Uploaded_Data!$D$2:$D$59696="Production Transfers")*(Uploaded_Data!$E$2:$E$59696="South Mine to Direct Pile (Bypass Crusher)")*(Uploaded_Data!$F$2:$F$59696="OB/CLAY")*(Uploaded_Data!$H$2:$H$59696=$A6)*Uploaded_Data!$N$2:$N$59696)} -> 0 | W6: {=SUMPRODUCT((Uploaded_Data!$D$2:$D$59696="Production Transfers")*(Uploaded_Data!$E$2:$E$59696="South Mine to Stock Yard")*(Uploaded_Data!$F$2:$F$59696="OB/CLAY")*(Uploaded_Data!$H$2:$H$59696=$A6)*Uploaded_Data!$N$2:$N$59696)} -> 0 | X6: {=SUMPRODUCT((Uploaded_Data!$D$2:$D$59696="Production Transfers")*(Uploaded_Data!$E$2:$E$59696="South Mine to Golani Waste dump")*(Uploaded_Data!$F$2:$F$59696="WASTE")*(Uploaded_Data!$H$2:$H$59696=$A6)*Uploaded_Data!$N$2:$N$59696)} -> 0 | Y6: {=SUMPRODUCT((Uploaded_Data!$D$2:$D$59696="Production Transfers")*(Uploaded_Data!$E$2:$E$59696="North Mine to Pile (through Crusher)")*(Uploaded_Data!$F$2:$F$59696="OB/CLAY")*(Uploaded_Data!$H$2:$H$59696=$A6)*Uploaded_Data!$N$2:$N$59696)} -> 0 | Z6: {=SUMPRODUCT((Uploaded_Data!$D$2:$D$59696="Production Transfers")*(Uploaded_Data!$E$2:$E$59696="North Mine to Direct Pile (Bypass Crusher)")*(Uploaded_Data!$F$2:$F$59696="OB/CLAY")*(Uploaded_Data!$H$2:$H$59696=$A6)*Uploaded_Data!$N$2:$N$59696)} -> 0 | AA6: {=SUMPRODUCT((Uploaded_Data!$D$2:$D$59696="Production Transfers")*(Uploaded_Data!$E$2:$E$59696="North Mine to Stock Yard")*(Uploaded_Data!$F$2:$F$59696="OB/CLAY")*(Uploaded_Data!$H$2:$H$59696=$A6)*Uploaded_Data!$N$2:$N$59696)} -> 0 | AB6: {=SUMPRODUCT((Uploaded_Data!$D$2:$D$59696="Production Transfers")*(Uploaded_Data!$E$2:$E$59696="North Mine to Golani Waste dump")*(Uploaded_Data!$F$2:$F$59696="WASTE")*(Uploaded_Data!$H$2:$H$59696=$A6)*Uploaded_Data!$N$2:$N$59696)} -> 2300 | AC6: {=SUMPRODUCT((Uploaded_Data!$D$2:$D$59696="Internal Transfers")*(Uploaded_Data!$E$2:$E$59696="Stock Yard to Pile (through Crusher)")*(Uploaded_Data!$F$2:$F$59696="OB/CLAY")*(Uploaded_Data!$H$2:$H$59696=$A6)*Uploaded_Data!$N$2:$N$59696)} -> 0 | AD6: {=SUMPRODUCT((Uploaded_Data!$D$2:$D$59696="Internal Transfers")*(Uploaded_Data!$E$2:$E$59696="Stock Yard to Other Usages")*(Uploaded_Data!$F$2:$F$59696="OB/CLAY")*(Uploaded_Data!$H$2:$H$59696=$A6)*Uploaded_Data!$N$2:$N$59696)} -> 0 | AE6: {=SUMPRODUCT((Uploaded_Data!$D$2:$D$59696="Internal Transfers")*(Uploaded_Data!$E$2:$E$59696="Stock Yard to Direct Pile (Bypass Crusher)")*(Uploaded_Data!$F$2:$F$59696="OB/CLAY")*(Uploaded_Data!$H$2:$H$59696=$A6)*Uploaded_Data!$N$2:$N$59696)} -> 0 | AF6: {=SUMPRODUCT((Uploaded_Data!$D$2:$D$59696="Production Transfers")*(Uploaded_Data!$E$2:$E$59696="South Mine to Pile (through Crusher)")*(Uploaded_Data!$F$2:$F$59696="HGHMGO")*(Uploaded_Data!$H$2:$H$59696=$A6)*Uploaded_Data!$N$2:$N$59696)} -> 0 | AG6: {=SUMPRODUCT((Uploaded_Data!$D$2:$D$59696="Production Transfers")*(Uploaded_Data!$E$2:$E$59696="South Mine to Direct Pile (Bypass Crusher)")*(Uploaded_Data!$F$2:$F$59696="HGHMGO")*(Uploaded_Data!$H$2:$H$59696=$A6)*Uploaded_Data!$N$2:$N$59696)} -> 0 | AH6: {=SUMPRODUCT((Uploaded_Data!$D$2:$D$59696="Production Transfers")*(Uploaded_Data!$E$2:$E$59696="South Mine to Stock Yard")*(Uploaded_Data!$F$2:$F$59696="HGHMGO")*(Uploaded_Data!$H$2:$H$59696=$A6)*Uploaded_Data!$N$2:$N$59696)} -> 0 | AI6: {=SUMPRODUCT((Uploaded_Data!$D$2:$D$59696="Internal Transfers")*(Uploaded_Data!$E$2:$E$59696="Stock Yard to Pile (through Crusher)")*(Uploaded_Data!$F$2:$F$59696="HGHMGO")*(Uploaded_Data!$H$2:$H$59696=$A6)*Uploaded_Data!$N$2:$N$59696)} -> 0 | AJ6: {=SUMPRODUCT((Uploaded_Data!$D$2:$D$59696="Production Transfers")*(Uploaded_Data!$E$2:$E$59696="South Mine to Pile (through Crusher)")*(Uploaded_Data!$F$2:$F$59696="LGHMGO")*(Uploaded_Data!$H$2:$H$59696=$A6)*Uploaded_Data!$N$2:$N$59696)} -> 0 | AK6: {=SUMPRODUCT((Uploaded_Data!$D$2:$D$59696="Production Transfers")*(Uploaded_Data!$E$2:$E$59696="South Mine to Direct Pile (Bypass Crusher)")*(Uploaded_Data!$F$2:$F$59696="LGHMGO")*(Uploaded_Data!$H$2:$H$59696=$A6)*Uploaded_Data!$N$2:$N$59696)} -> 0 | AL6: {=SUMPRODUCT((Uploaded_Data!$D$2:$D$59696="Production Transfers")*(Uploaded_Data!$E$2:$E$59696="South Mine to Stock Yard")*(Uploaded_Data!$F$2:$F$59696="LGHMGO")*(Uploaded_Data!$H$2:$H$59696=$A6)*Uploaded_Data!$N$2:$N$59696)} -> 0 | AM6: {=SUMPRODUCT((Uploaded_Data!$D$2:$D$59696="Internal Transfers")*(Uploaded_Data!$E$2:$E$59696="Stock Yard to Pile (through Crusher)")*(Uploaded_Data!$F$2:$F$59696="LGHMGO")*(Uploaded_Data!$H$2:$H$59696=$A6)*Uploaded_Data!$N$2:$N$59696)} -> 0 | AN6: =SUM(B6:AM6) -> 3108.48 | AP6: {=SUMPRODUCT((Uploaded_Data!$D$2:$D$59696="Internal Transfers")*(Uploaded_Data!$E$2:$E$59696="Stock Yard to Pile (through Crusher)")*(Uploaded_Data!$F$2:$F$59696="GYPSUM")*(Uploaded_Data!$H$2:$H$59696=$A6)*Uploaded_Data!$N$2:$N$59696)} -> 0 | AQ6: {=SUMPRODUCT((Uploaded_Data!$D$2:$D$59696="Internal Transfers")*(Uploaded_Data!$E$2:$E$59696="Stock Yard to Direct Pile (Bypass Crusher)")*(Uploaded_Data!$F$2:$F$59696="GYPSUM")*(Uploaded_Data!$H$2:$H$59696=$A6)*Uploaded_Data!$N$2:$N$59696)} -> 0 | AR6: {=SUMPRODUCT((Uploaded_Data!$D$2:$D$59696="Internal Transfers")*(Uploaded_Data!$E$2:$E$59696="Stock Yard to Other Usages")*(Uploaded_Data!$F$2:$F$59696="ID Clay")*(Uploaded_Data!$H$2:$H$59696=$A6)*Uploaded_Data!$N$2:$N$59696)} -> 0 | AS6: {=SUMPRODUCT((Uploaded_Data!$D$2:$D$59696="Internal Transfers")*(Uploaded_Data!$E$2:$E$59696="Stock Yard to Direct Pile (Bypass Crusher)")*(Uploaded_Data!$F$2:$F$59696="ID Clay")*(Uploaded_Data!$H$2:$H$59696=$A6)*Uploaded_Data!$N$2:$N$59696)} -> 0 | AT6: {=SUMPRODUCT((Uploaded_Data!$D$2:$D$59696="Production Transfers")*(Uploaded_Data!$E$2:$E$59696="Kijaka Mine to Stock Yard")*(Uploaded_Data!$F$2:$F$59696="ID Clay")*(Uploaded_Data!$H$2:$H$59696=$A6)*Uploaded_Data!$N$2:$N$59696)} -> 0 | AU6: =AN6+AP6+AQ6+AR6+AS6+AT6 -> 3108.48 | AV6: =AU6-AB6-X6 -> 808.48 | AZ6: =B6+H6+J6+P6+U6+AC6+AF6+AJ6+AP6+S6+AI6+Y6+M6+E6 -> 568.78 | BA6: =AU6 -> 3108.48
