Workbook

Sheet Mines (2)
B1: MARCH | C1: HG LS | H1: LG LS | L1: Clay | Q1: Sand | V1: TG | Z1: HGHMGO | AD1: PURCHASED LIMESTONE | AH1: BAUXITE | AM1: Total
B2: Date | C2: Opening Stock | D2: Production | E2: Total Consumption | F2: CONS R/M1 | G2: Closing Stock | H2: Opening Stock | I2: Production | J2: Consumption | K2: Closing Stock | L2: Opening Stock | M2: Production | N2: TOTAL Consumption | O2: Cons R/M1 | P2: Closing Stock | Q2: Opening Stock | R2: Production | S2: TOTALConsumption | T2: Cons R/M1 | U2: Closing Stock | V2: Opening Stock | W2: Production | X2: Consumption | Y2: Closing Stock | Z2: Opening Stock | AA2: Production | AB2: Consumption | AC2: Closing Stock | AD2: Opening Stock | AE2: Production | AF2: Consumption | AG2: Closing Stock | AH2: Opening Stock | AI2: Production | AJ2: Total Consumption | AK2: Consumption | AL2: Closing Stock | AM2: P | AN2: C | AO2: Raw meal | AP2: diff | AQ2: LG | AW2: MINES CONS | AX2: MINES RECEIPT
B3: 1 | C3: 7522.7832 | D3: 3207.88 | E3: =F3+'RAW MILL 2'!C3 -> 3401 | F3: 3145 | G3: =C3+D3-E3 -> 7329.6632 | H3: 11945.017 | I3: 2235.84 | J3: 0 | K3: =H3+I3-J3-Cement!S3 -> 13842.179 | L3: 2911.44 | M3: 0 | N3: =O3+'RAW MILL 2'!D3 -> 2 | O3: 2 | P3: =L3+M3-N3 -> 2909.44 | Q3: 0.04 | R3: 0 | S3: =T3+'RAW MILL 2'!E3 -> 0 | T3: 0 | U3: =Q3+R3-S3 -> 0.04 | V3: 0 | W3: 0 | X3: 0 | Y3: =V3+W3-X3 -> 0 | Z3: 0 | AA3: 0 | AB3: 0 | AC3: =Z3+AA3-AB3 -> 0 | AD3: 0 | AE3: 0 | AF3: 0 | AG3: =AD3+AE3-AF3 -> 0 | AH3: 298.36 | AJ3: =AK3+'RAW MILL 2'!G3 -> 0 | AL3: =AH3+AI3-AJ3 -> 298.36 | AM3: =D3+I3+M3+R3+W3+AA3+Cement!Q3+Cement!V3+AE3 -> 5443.72 | AN3: =E3+J3+N3+S3+X3+AB3+Clinker!E3+AF3+AK3 -> 3455 | AO3: =Production2!N3 -> 2876 | AQ3: 3103 | AV3: =D3+I3+M3+R3+Cement!Q3 -> 5443.72 | AW3: =AN3+Cement!R3-Clinker!E3 -> 3707.81 | AX3: 940.1 | AY3: =AN3-Production2!N3 -> 579 | AZ3: =AN3 -> 3455 | BA3: =E3+J3 -> 3401 | BB3: =AX3-D3 -> -2267.78 | BC3: =I3-BD3 -> 616.34 | BD3: 1619.5 | BE3: =(AN3-Production2!N3)/'Mines (2)'!AN3 -> 0.16758321 | BF3: =BE3*100 -> 16.758321 | BG3: =E3+J3+AB3 -> 3401
B4: 2 | C4: =G3 -> 7329.6632 | D4: 2217.12 | E4: =F4+'RAW MILL 2'!C4 -> 1916 | F4: 1724 | G4: =C4+D4-E4 -> 7630.7832 | H4: =K3 -> 13842.179 | I4: 500.2 | J4: 0 | K4: =H4+I4-J4-Cement!S4 -> 13921.779 | L4: =P3 -> 2909.44 | M4: 0 | N4: =O4+'RAW MILL 2'!D4 -> 10 | O4: 9 | P4: =L4+M4-N4 -> 2899.44 | Q4: =U3 -> 0.04 | R4: 0 | S4: =T4+'RAW MILL 2'!E4 -> 0 | T4: 0 | U4: =Q4+R4-S4 -> 0.04 | V4: =Y3 -> 0 | W4: 0 | X4: 0 | Y4: =V4+W4-X4 -> 0 | Z4: =AC3 -> 0 | AA4: 0 | AB4: 0 | AC4: =Z4+AA4-AB4 -> 0 | AD4: =AG3 -> 0 | AE4: 0 | AF4: 0 | AG4: =AD4+AE4-AF4 -> 0 | AH4: =AL3 -> 298.36 | AJ4: =AK4+'RAW MILL 2'!G4 -> 0 | AL4: =AH4+AI4-AJ4 -> 298.36 | AM4: =D4+I4+M4+R4+W4+AA4+Cement!Q4+Cement!V4+AE4 -> 2717.32 | AN4: =E4+J4+N4+S4+X4+AB4+Clinker!E4+AF4+AK4 -> 1975 | AO4: =Production2!N4 -> 1599 | AP4: =AO4-AN4 -> -376 | AQ4: 3286 | AV4: =D4+I4+M4+R4+Cement!Q4 -> 2717.32 | AW4: =AN4+Cement!R4-Clinker!E4 -> 2304.54 | AX4: 987.54 | AY4: =AN4-Production2!N4 -> 376 | AZ4: =AN4 -> 1975 | BA4: =E4+J4 -> 1916 | BB4: =AX4-D4 -> -1229.58 | BC4: =I4-BD4 -> -123.08 | BD4: 623.28 | BE4: =(AN4-Production2!N4)/'Mines (2)'!AN4 -> 0.19037975 | BF4: =BE4*100 -> 19.037975 | BG4: =E4+J4+AB4 -> 1916
B5: 3 | C5: =G4 -> 7630.7832 | D5: 1778.02 | E5: =F5+'RAW MILL 2'!C5 -> 1530 | F5: 1336 | G5: =C5+D5-E5 -> 7878.8032 | H5: =K4 -> 13921.779 | I5: 1686.64 | J5: 1000 | K5: =H5+I5-J5-Cement!S5 -> 14043.819 | L5: =P4 -> 2899.44 | M5: 140.24 | N5: =O5+'RAW MILL 2'!D5 -> 80 | O5: 74 | P5: =L5+M5-N5 -> 2959.68 | Q5: =U4 -> 0.04 | R5: 0 | S5: =T5+'RAW MILL 2'!E5 -> 0 | T5: 0 | U5: =Q5+R5-S5 -> 0.04 | V5: =Y4 -> 0 | W5: 0 | X5: 0 | Y5: =V5+W5-X5 -> 0 | Z5: =AC4 -> 0 | AA5: 0 | AB5: 0 | AC5: =Z5+AA5-AB5 -> 0 | AD5: =AG4 -> 0 | AE5: 0 | AF5: 0 | AG5: =AD5+AE5-AF5 -> 0 | AH5: =AL4 -> 298.36 | AJ5: =AK5+'RAW MILL 2'!G5 -> 0 | AL5: =AH5+AI5-AJ5 -> 298.36 | AM5: =D5+I5+M5+R5+W5+AA5+Cement!Q5+Cement!V5+AE5 -> 3604.9 | AN5: =E5+J5+N5+S5+X5+AB5+Clinker!E5+AF5+AK5 -> 2677 | AO5: =Production2!N5 -> 2226 | AP5: =AO5-AN5 -> -451 | AQ5: 2899 | AV5: =D5+I5+M5+R5+Cement!Q5 -> 3604.9 | AW5: =AN5+Cement!R5-Clinker!E5 -> 3118.14 | AX5: 249.34 | AY5: =AN5-Production2!N5 -> 451 | AZ5: =AN5 -> 2677 | BA5: =E5+J5 -> 2530 | BB5: =AX5-D5 -> -1528.68 | BC5: =I5-BD5 -> 1244.14 | BD5: 442.5 | BE5: =(AN5-Production2!N5)/'Mines (2)'!AN5 -> 0.16847217 | BF5: =BE5*100 -> 16.847217 | BG5: =E5+J5+AB5 -> 2530
B6: 4 | C6: =G5 -> 7878.8032 | D6: 0 | E6: =F6+'RAW MILL 2'!C6 -> 3136 | F6: 2917 | G6: =C6+D6-E6 -> 4742.8032 | H6: =K5 -> 14043.819 | I6: 1139.1 | J6: 0 | K6: =H6+I6-J6-Cement!S6 -> 14675.608 | L6: =P5 -> 2959.68 | M6: 81.98 | N6: =O6+'RAW MILL 2'!D6 -> 66 | O6: 61 | P6: =L6+M6-N6 -> 2975.66 | Q6: =U5 -> 0.04 | R6: 0 | S6: =T6+'RAW MILL 2'!E6 -> 0 | T6: 0 | U6: =Q6+R6-S6 -> 0.04 | V6: =Y5 -> 0 | W6: 0 | X6: 0 | Y6: =V6+W6-X6 -> 0 | Z6: =AC5 -> 0 | AA6: 0 | AB6: 0 | AC6: =Z6+AA6-AB6 -> 0 | AD6: =AG5 -> 0 | AE6: 0 | AF6: 0 | AG6: =AD6+AE6-AF6 -> 0 | AH6: =AL5 -> 298.36 | AJ6: =AK6+'RAW MILL 2'!G6 -> 0 | AL6: =AH6+AI6-AJ6 -> 298.36 | AM6: =D6+I6+M6+R6+W6+AA6+Cement!Q6+Cement!V6+AE6 -> 1221.08 | AN6: =E6+J6+N6+S6+X6+AB6+Clinker!E6+AF6+AK6 -> 3284 | AO6: =Production2!N6 -> 2751 | AP6: =AO6-AN6 -> -533 | AQ6: 3290 | AV6: =D6+I6+M6+R6+Cement!Q6 -> 1221.08 | AW6: =AN6+Cement!R6-Clinker!E6 -> 3658.58 | AX6: 1108.96 | AY6: =AN6-Production2!N6 -> 533 | AZ6: =AN6 -> 3284 | BA6: =E6+J6 -> 3136 | BB6: =AX6-D6 -> 1108.96 | BC6: =I6-BD6 -> -1097.66 | BD6: 2236.76 | BE6: =(AN6-Production2!N6)/'Mines (2)'!AN6 -> 0.16230207 | BF6: =BE6*100 -> 16.230207 | BG6: =E6+J6+AB6 -> 3136
B7: 5 | C7: =G6 -> 4742.8032 | D7: 1960.4 | E7: =F7+'RAW MILL 2'!C7 -> 1777 | F7: 1587 | G7: =C7+D7-E7 -> 4926.2032 | H7: =K6 -> 14675.608 | I7: 1204.24 | J7: 1000 | K7: =H7+I7-J7-Cement!S7 -> 14417.203 | L7: =P6 -> 2975.66 | M7: 0 | N7: =O7+'RAW MILL 2'!D7 -> 58 | O7: 54 | P7: =L7+M7-N7 -> 2917.66 | Q7: =U6 -> 0.04 | R7: 0 | S7: =T7+'RAW MILL 2'!E7 -> 0 | T7: 0 | U7: =Q7+R7-S7 -> 0.04 | V7: =Y6 -> 0 | W7: 0 | X7: 0 | Y7: =V7+W7-X7 -> 0 | Z7: =AC6 -> 0 | AA7: 0 | AB7: 0 | AC7: =Z7+AA7-AB7 -> 0 | AD7: =AG6 -> 0 | AE7: 0 | AF7: 0 | AG7: =AD7+AE7-AF7 -> 0 | AH7: =AL6 -> 298.36 | AJ7: =AK7+'RAW MILL 2'!G7 -> 0 | AL7: =AH7+AI7-AJ7 -> 298.36 | AM7: =D7+I7+M7+R7+W7+AA7+Cement!Q7+Cement!V7+AE7 -> 3164.64 | AN7: =E7+J7+N7+S7+X7+AB7+Clinker!E7+AF7+AK7 -> 2908 | AO7: =Production2!N7 -> 2439 | AP7: =AO7-AN7 -> -469 | AQ7: 3245 | AV7: =D7+I7+R7+Cement!Q7 -> 3164.64 | AW7: =AN7+Cement!R7-Clinker!E7 -> 3251.381 | AX7: 0 | AY7: =AN7-Production2!N7 -> 469 | AZ7: =AN7 -> 2908 | BA7: =E7+J7 -> 2777 | BB7: =AX7-D7 -> -1960.4 | BC7: =I7-BD7 -> 1204.24 | BD7: 0 | BE7: =(AN7-Production2!N7)/'Mines (2)'!AN7 -> 0.16127923 | BF7: =BE7*100 -> 16.127923 | BG7: =E7+J7+AB7 -> 2777
B8: 6 | C8: =G7 -> 4926.2032 | D8: 1955.56 | E8: =F8+'RAW MILL 2'!C8 -> 1377 | F8: 1258 | G8: =C8+D8-E8 -> 5504.7632 | H8: =K7 -> 14417.203 | I8: 1362.52 | J8: 1000 | K8: =H8+I8-J8-Cement!S8 -> 14280.984 | L8: =P7 -> 2917.66 | M8: 0 | N8: =O8+'RAW MILL 2'!D8 -> 50 | O8: 47 | P8: =L8+M8-N8 -> 2867.66 | Q8: =U7 -> 0.04 | R8: 0 | S8: =T8+'RAW MILL 2'!E8 -> 0 | T8: 0 | U8: =Q8+R8-S8 -> 0.04 | V8: =Y7 -> 0 | W8: 0 | X8: 0 | Y8: =V8+W8-X8 -> 0 | Z8: =AC7 -> 0 | AA8: 0 | AB8: 0 | AC8: =Z8+AA8-AB8 -> 0 | AD8: =AG7 -> 0 | AE8: 0 | AF8: 0 | AG8: =AD8+AE8-AF8 -> 0 | AH8: =AL7 -> 298.36 | AJ8: =AK8+'RAW MILL 2'!G8 -> 0 | AL8: =AH8+AI8-AJ8 -> 298.36 | AM8: =D8+I8+M8+R8+W8+AA8+Cement!Q8+Cement!V8+AE8 -> 3318.08 | AN8: =E8+J8+N8+S8+X8+AB8+Clinker!E8+AF8+AK8 -> 2489 | AO8: =Production2!N8 -> 2128 | AP8: =AO8-AN8 -> -361 | AQ8: 3139 | AV8: =D8+I8+M8+R8+Cement!Q8 -> 3318.08 | AW8: =AN8+Cement!R8-Clinker!E8 -> 2875.865 | AX8: 1300 | AY8: =AN8-Production2!N8 -> 361 | AZ8: =AN8 -> 2489 | BA8: =E8+J8 -> 2377 | BB8: =AX8-D8 -> -655.56 | BC8: =I8-BD8 -> 522.52 | BD8: 840 | BE8: =(AN8-Production2!N8)/'Mines (2)'!AN8 -> 0.14503817 | BF8: =BE8*100 -> 14.503817 | BG8: =E8+J8+AB8 -> 2377
B9: 7 | C9: =G8 -> 5504.7632 | D9: 631.7 | E9: =F9+'RAW MILL 2'!C9 -> 1410 | F9: 1276 | G9: =C9+D9-E9 -> 4726.4632 | H9: =K8 -> 14280.984 | I9: 1680.34 | J9: 1000 | K9: =H9+I9-J9-Cement!S9 -> 14664.435 | L9: =P8 -> 2867.66 | M9: 0 | N9: =O9+'RAW MILL 2'!D9 -> 77 | O9: 73 | P9: =L9+M9-N9 -> 2790.66 | Q9: =U8 -> 0.04 | R9: 0 | S9: =T9+'RAW MILL 2'!E9 -> 0 | T9: 0 | U9: =Q9+R9-S9 -> 0.04 | V9: =Y8 -> 0 | W9: 0 | X9: 0 | Y9: =V9+W9-X9 -> 0 | Z9: =AC8 -> 0 | AA9: 0 | AB9: 0 | AC9: =Z9+AA9-AB9 -> 0 | AD9: =AG8 -> 0 | AE9: 0 | AF9: 0 | AG9: =AD9+AE9-AF9 -> 0 | AH9: =AL8 -> 298.36 | AJ9: =AK9+'RAW MILL 2'!G9 -> 0 | AL9: =AH9+AI9-AJ9 -> 298.36 | AM9: =D9+I9+M9+R9+W9+AA9+Cement!Q9+Cement!V9+AE9 -> 2312.04 | AN9: =E9+J9+N9+S9+X9+AB9+Clinker!E9+AF9+AK9 -> 2564 | AO9: =Production2!N9 -> 2180 | AP9: =AO9-AN9 -> -384 | AQ9: 1732 | AV9: =D9+I9+M9+R9+Cement!Q9 -> 2312.04 | AW9: =AN9+Cement!R9-Clinker!E9 -> 2754.2 | AX9: 480 | AY9: =AN9-Production2!N9 -> 384 | AZ9: =AN9 -> 2564 | BA9: =E9+J9 -> 2410 | BB9: =AX9-D9 -> -151.7 | BC9: =I9-BD9 -> -499.66 | BD9: 2180 | BE9: =(AN9-Production2!N9)/'Mines (2)'!AN9 -> 0.14976599 | BF9: =BE9*100 -> 14.976599 | BG9: =E9+J9+AB9 -> 2410
B10: 8 | C10: =G9 -> 4726.4632 | D10: 754.74 | E10: =F10+'RAW MILL 2'!C10 -> 2283 | F10: 2124 | G10: =C10+D10-E10 -> 3198.2032 | H10: =K9 -> 14664.435 | I10: 2206.98 | J10: 0 | K10: =H10+I10-J10-Cement!S10 -> 16563.239 | L10: =P9 -> 2790.66 | M10: 43.14 | N10: =O10+'RAW MILL 2'!D10 -> 24 | O10: 22 | P10: =L10+M10-N10 -> 2809.8 | Q10: =U9 -> 0.04 | R10: 0 | S10: =T10+'RAW MILL 2'!E10 -> 0 | T10: 0 | U10: =Q10+R10-S10 -> 0.04 | V10: =Y9 -> 0 | W10: 0 | X10: 0 | Y10: =V10+W10-X10 -> 0 | Z10: =AC9 -> 0 | AA10: 0 | AB10: 0 | AC10: =Z10+AA10-AB10 -> 0 | AD10: =AG9 -> 0 | AE10: 0 | AF10: 0 | AG10: =AD10+AE10-AF10 -> 0 | AH10: =AL9 -> 298.36 | AJ10: =AK10+'RAW MILL 2'!G10 -> 0 | AL10: =AH10+AI10-AJ10 -> 298.36 | AM10: =D10+I10+M10+R10+W10+AA10+Cement!Q10+Cement!V10+AE10 -> 3004.86 | AN10: =E10+J10+N10+S10+X10+AB10+Clinker!E10+AF10+AK10 -> 2371 | AO10: =Production2!N10 -> 1986 | AP10: =AO10-AN10 -> -385 | AQ10: 1959 | AV10: =D10+I10+M10+R10+Cement!Q10 -> 3004.86 | AW10: =AN10+Cement!R10-Clinker!E10 -> 2584.3585 | AX10: 1612.08 | AY10: =AN10-Production2!N10 -> 385 | AZ10: =AN10 -> 2371 | BA10: =E10+J10 -> 2283 | BB10: =AX10-D10 -> 857.34 | BC10: =I10-BD10 -> 1566.98 | BD10: 640 | BE10: =(AN10-Production2!N10)/'Mines (2)'!AN10 -> 0.16237874 | BF10: =BE10*100 -> 16.237874 | BG10: =E10+J10+AB10 -> 2283
B11: 9 | C11: =G10 -> 3198.2032 | D11: 2088.86 | E11: =F11+'RAW MILL 2'!C11 -> 2350 | F11: 2144 | G11: =C11+D11-E11 -> 2937.0632 | H11: =K10 -> 16563.239 | I11: 1077.64 | J11: 0 | K11: =H11+I11-J11-Cement!S11 -> 17345.734 | L11: =P10 -> 2809.8 | M11: 0 | N11: =O11+'RAW MILL 2'!D11 -> 37 | O11: 34 | P11: =L11+M11-N11 -> 2772.8 | Q11: =U10 -> 0.04 | R11: 0 | S11: =T11+'RAW MILL 2'!E11 -> 0 | T11: 0 | U11: =Q11+R11-S11 -> 0.04 | V11: =Y10 -> 0 | W11: 0 | X11: 0 | Y11: =V11+W11-X11 -> 0 | Z11: =AC10 -> 0 | AA11: 0 | AB11: 0 | AC11: =Z11+AA11-AB11 -> 0 | AD11: =AG10 -> 0 | AE11: 0 | AF11: 0 | AG11: =AD11+AE11-AF11 -> 0 | AH11: =AL10 -> 298.36 | AJ11: =AK11+'RAW MILL 2'!G11 -> 0 | AL11: =AH11+AI11-AJ11 -> 298.36 | AM11: =D11+I11+M11+R11+W11+AA11+Cement!Q11+Cement!V11+AE11 -> 3166.5 | AN11: =E11+J11+N11+S11+X11+AB11+Clinker!E11+AF11+AK11 -> 2460 | AO11: =Production2!N11 -> 2021 | AP11: =AO11-AN11 -> -439 | AQ11: 3119 | AV11: =D11+I11+M11+R11+Cement!Q11 -> 3166.5 | AW11: =AN11+Cement!R11-Clinker!E11 -> 2652.63 | AX11: 2277.26 | AY11: =AN11-Production2!N11 -> 439 | AZ11: =AN11 -> 2460 | BA11: =E11+J11 -> 2350 | BB11: =AX11-D11 -> 188.4 | BC11: =I11-BD11 -> 459.86 | BD11: 617.78 | BE11: =(AN11-Production2!N11)/'Mines (2)'!AN11 -> 0.17845528 | BF11: =BE11*100 -> 17.845528 | BG11: =E11+J11+AB11 -> 2350
B12: 10 | C12: =G11 -> 2937.0632 | D12: 2110.74 | E12: =F12+'RAW MILL 2'!C12 -> 1004 | F12: 828 | G12: =C12+D12-E12 -> 4043.8032 | H12: =K11 -> 17345.734 | I12: 993.96 | J12: 2000 | K12: =H12+I12-J12-Cement!S12 -> 15842.105 | L12: =P11 -> 2772.8 | M12: 292.9 | N12: =O12+'RAW MILL 2'!D12 -> 64 | O12: 60 | P12: =L12+M12-N12 -> 3001.7 | Q12: =U11 -> 0.04 | R12: 0 | S12: =T12+'RAW MILL 2'!E12 -> 0 | T12: 0 | U12: =Q12+R12-S12 -> 0.04 | V12: =Y11 -> 0 | W12: 0 | X12: 0 | Y12: =V12+W12-X12 -> 0 | Z12: =AC11 -> 0 | AA12: 0 | AB12: 0 | AC12: =Z12+AA12-AB12 -> 0 | AD12: =AG11 -> 0 | AE12: 0 | AF12: 0 | AG12: =AD12+AE12-AF12 -> 0 | AH12: =AL11 -> 298.36 | AJ12: =AK12+'RAW MILL 2'!G12 -> 0 | AL12: =AH12+AI12-AJ12 -> 298.36 | AM12: =D12+I12+M12+R12+W12+AA12+Cement!Q12+Cement!V12+AE12 -> 3397.6 | AN12: =E12+J12+N12+S12+X12+AB12+Clinker!E12+AF12+AK12 -> 3163 | AO12: =Production2!N12 -> 2681 | AP12: =AO12-AN12 -> -482 | AQ12: 3017 | AV12: =D12+I12+M12+R12+Cement!Q12 -> 3397.6 | AW12: =AN12+Cement!R12-Clinker!E12 -> 3515.83 | AX12: 400.64 | AY12: =AN12-Production2!N12 -> 482 | AZ12: =AN12 -> 3163 | BA12: =E12+J12 -> 3004 | BB12: =AX12-D12 -> -1710.1 | BC12: =I12-BD12 -> -148.62 | BD12: 1142.58 | BE12: =(AN12-Production2!N12)/'Mines (2)'!AN12 -> 0.15238697 | BF12: =BE12*100 -> 15.238697 | BG12: =E12+J12+AB12 -> 3004
B13: 11 | C13: =G12 -> 4043.8032 | D13: 1341.1 | E13: =F13+'RAW MILL 2'!C13 -> 1132 | F13: 944 | G13: =C13+D13-E13 -> 4252.9032 | H13: =K12 -> 15842.105 | I13: 1452.6 | J13: 1000 | K13: =H13+I13-J13-Cement!S13 -> 15772.483 | L13: =P12 -> 3001.7 | M13: 299.16 | N13: =O13+'RAW MILL 2'!D13 -> 54 | O13: 49 | P13: =L13+M13-N13 -> 3246.86 | Q13: =U12 -> 0.04 | R13: 0 | S13: =T13+'RAW MILL 2'!E13 -> 0 | T13: 0 | U13: =Q13+R13-S13 -> 0.04 | V13: =Y12 -> 0 | W13: 0 | X13: 0 | Y13: =V13+W13-X13 -> 0 | Z13: =AC12 -> 0 | AA13: 0 | AB13: 0 | AC13: =Z13+AA13-AB13 -> 0 | AD13: =AG12 -> 0 | AE13: 0 | AF13: 0 | AG13: =AD13+AE13-AF13 -> 0 | AH13: =AL12 -> 298.36 | AJ13: =AK13+'RAW MILL 2'!G13 -> 0 | AL13: =AH13+AI13-AJ13 -> 298.36 | AM13: =D13+I13+M13+R13+W13+AA13+Cement!Q13+Cement!V13+AE13 -> 3092.86 | AN13: =E13+J13+N13+S13+X13+AB13+Clinker!E13+AF13+AK13 -> 2233 | AO13: =Production2!N13 -> 1832 | AP13: =AO13-AN13 -> -401 | AQ13: 3256 | AV13: =D13+I13+M13+R13+Cement!Q13 -> 3092.86 | AW13: =AN13+Cement!R13-Clinker!E13 -> 2656 | AX13: 1843.24 | AY13: =AN13-Production2!N13 -> 401 | AZ13: =AN13 -> 2233 | BA13: =E13+J13 -> 2132 | BB13: =AX13-D13 -> 502.14 | BC13: =I13-BD13 -> 359.12 | BD13: 1093.48 | BE13: =(AN13-Production2!N13)/'Mines (2)'!AN13 -> 0.17957904 | BF13: =BE13*100 -> 17.957904 | BG13: =E13+J13+AB13 -> 2132
B14: 12 | C14: =G13 -> 4252.9032 | D14: 1398.06 | E14: =F14+'RAW MILL 2'!C14 -> 628 | F14: 458 | G14: =C14+D14-E14 -> 5022.9632 | H14: =K13 -> 15772.483 | I14: 1054.4 | J14: 2000 | K14: =H14+I14-J14-Cement!S14 -> 14342.588 | L14: =P13 -> 3246.86 | M14: 0 | N14: =O14+'RAW MILL 2'!D14 -> 67 | O14: 62 | P14: =L14+M14-N14 -> 3179.86 | Q14: =U13 -> 0.04 | R14: 0 | S14: =T14+'RAW MILL 2'!E14 -> 0 | T14: 0 | U14: =Q14+R14-S14 -> 0.04 | V14: =Y13 -> 0 | W14: 0 | X14: 0 | Y14: =V14+W14-X14 -> 0 | Z14: =AC13 -> 0 | AA14: 0 | AB14: 0 | AC14: =Z14+AA14-AB14 -> 0 | AD14: =AG13 -> 0 | AE14: 0 | AF14: 0 | AG14: =AD14+AE14-AF14 -> 0 | AH14: =AL13 -> 298.36 | AJ14: =AK14+'RAW MILL 2'!G14 -> 0 | AL14: =AH14+AI14-AJ14 -> 298.36 | AM14: =D14+I14+M14+R14+W14+AA14+Cement!Q14+Cement!V14+AE14 -> 2452.46 | AN14: =E14+J14+N14+S14+X14+AB14+Clinker!E14+AF14+AK14 -> 2754 | AO14: =Production2!N14 -> 2318 | AP14: =AO14-AN14 -> -436 | AQ14: 3209 | AV14: =D14+I14+M14+R14+Cement!Q14 -> 2452.46 | AW14: =AN14+Cement!R14-Clinker!E14 -> 3130.866 | AX14: 665.76 | AY14: =AN14-Production2!N14 -> 436 | AZ14: =AN14 -> 2754 | BA14: =E14+J14 -> 2628 | BB14: =AX14-D14 -> -732.3 | BC14: =I14-BD14 -> -131.02 | BD14: 1185.42 | BE14: =(AN14-Production2!N14)/'Mines (2)'!AN14 -> 0.15831518 | BF14: =BE14*100 -> 15.831518 | BG14: =E14+J14+AB14 -> 2628
B15: 13 | C15: =G14 -> 5022.9632 | D15: 717.94 | E15: =F15+'RAW MILL 2'!C15 -> 1071 | F15: 930 | G15: =C15+D15-E15 -> 4669.9032 | H15: =K14 -> 14342.588 | I15: 1817.94 | J15: 1000 | K15: =H15+I15-J15-Cement!S15 -> 14625.639 | L15: =P14 -> 3179.86 | M15: 0 | N15: =O15+'RAW MILL 2'!D15 -> 54 | O15: 50 | P15: =L15+M15-N15 -> 3125.86 | Q15: =U14 -> 0.04 | R15: 0 | S15: =T15+'RAW MILL 2'!E15 -> 0 | T15: 0 | U15: =Q15+R15-S15 -> 0.04 | V15: =Y14 -> 0 | W15: 0 | X15: 0 | Y15: =V15+W15-X15 -> 0 | Z15: =AC14 -> 0 | AA15: 0 | AB15: 0 | AC15: =Z15+AA15-AB15 -> 0 | AD15: =AG14 -> 0 | AE15: 0 | AF15: 0 | AG15: =AD15+AE15-AF15 -> 0 | AH15: =AL14 -> 298.36 | AJ15: =AK15+'RAW MILL 2'!G15 -> 0 | AL15: =AH15+AI15-AJ15 -> 298.36 | AM15: =D15+I15+M15+R15+W15+AA15+Cement!Q15+Cement!V15+AE15 -> 2535.88 | AN15: =E15+J15+N15+S15+X15+AB15+Clinker!E15+AF15+AK15 -> 2171 | AO15: =Production2!N15 -> 1820 | AP15: =AO15-AN15 -> -351 | AQ15: 3075 | AV15: =D15+I15+M15+R15+Cement!Q15 -> 2535.88 | AW15: =AN15+Cement!R15-Clinker!E15 -> 2606.4 | AX15: 776.72 | AY15: =AN15-Production2!N15 -> 351 | AZ15: =AN15 -> 2171 | BA15: =E15+J15 -> 2071 | BB15: =AX15-D15 -> 58.78 | BC15: =I15-BD15 -> 597.42 | BD15: 1220.52 | BE15: =(AN15-Production2!N15)/'Mines (2)'!AN15 -> 0.16167665 | BF15: =BE15*100 -> 16.167665 | BG15: =E15+J15+AB15 -> 2071
B16: 14 | C16: =G15 -> 4669.9032 | D16: 1782.02 | E16: =F16+'RAW MILL 2'!C16 -> 1135 | F16: 967 | G16: =C16+D16-E16 -> 5316.9232 | H16: =K15 -> 14625.639 | I16: 2027.96 | J16: 1000 | K16: =H16+I16-J16-Cement!S16 -> 15166.243 | L16: =P15 -> 3125.86 | M16: 0 | N16: =O16+'RAW MILL 2'!D16 -> 49 | O16: 45 | P16: =L16+M16-N16 -> 3076.86 | Q16: =U15 -> 0.04 | R16: 0 | S16: =T16+'RAW MILL 2'!E16 -> 0 | T16: 0 | U16: =Q16+R16-S16 -> 0.04 | V16: =Y15 -> 0 | W16: 0 | X16: 0 | Y16: =V16+W16-X16 -> 0 | Z16: =AC15 -> 0 | AA16: 0 | AB16: 0 | AC16: =Z16+AA16-AB16 -> 0 | AD16: =AG15 -> 0 | AE16: 0 | AF16: 0 | AG16: =AD16+AE16-AF16 -> 0 | AH16: =AL15 -> 298.36 | AJ16: =AK16+'RAW MILL 2'!G16 -> 0 | AL16: =AH16+AI16-AJ16 -> 298.36 | AM16: =D16+I16+M16+R16+W16+AA16+Cement!Q16+Cement!V16+AE16 -> 3809.98 | AN16: =E16+J16+N16+S16+X16+AB16+Clinker!E16+AF16+AK16 -> 2245 | AO16: =Production2!N16 -> 1862 | AP16: =AO16-AN16 -> -383 | AQ16: 2456 | AV16: =D16+I16+M16+R16+Cement!Q16 -> 3809.98 | AW16: =AN16+Cement!R16-Clinker!E16 -> 2622.62 | AX16: 1682.06 | AY16: =AN16-Production2!N16 -> 383 | AZ16: =AN16 -> 2245 | BA16: =E16+J16 -> 2135 | BB16: =AX16-D16 -> -99.96 | BC16: =I16-BD16 -> 969.8 | BD16: 1058.16 | BE16: =(AN16-Production2!N16)/'Mines (2)'!AN16 -> 0.17060134 | BF16: =BE16*100 -> 17.060134 | BG16: =E16+J16+AB16 -> 2135
B17: 15 | C17: =G16 -> 5316.9232 | D17: 1714.3 | E17: =F17+'RAW MILL 2'!C17 -> 455 | F17: 388 | G17: =C17+D17-E17 -> 6576.2232 | H17: =K16 -> 15166.243 | I17: 1977.68 | J17: 2000 | K17: =H17+I17-J17-Cement!S17 -> 14709.157 | L17: =P16 -> 3076.86 | M17: 182.56 | N17: =O17+'RAW MILL 2'!D17 -> 48 | O17: 47 | P17: =L17+M17-N17 -> 3211.42 | Q17: =U16 -> 0.04 | R17: 0 | S17: =T17+'RAW MILL 2'!E17 -> 0 | T17: 0 | U17: =Q17+R17-S17 -> 0.04 | V17: =Y16 -> 0 | W17: 0 | X17: 0 | Y17: =V17+W17-X17 -> 0 | Z17: =AC16 -> 0 | AA17: 0 | AB17: 0 | AC17: =Z17+AA17-AB17 -> 0 | AD17: =AG16 -> 0 | AE17: 0 | AF17: 0 | AG17: =AD17+AE17-AF17 -> 0 | AH17: =AL16 -> 298.36 | AJ17: =AK17+'RAW MILL 2'!G17 -> 0 | AL17: =AH17+AI17-AJ17 -> 298.36 | AM17: =D17+I17+M17+R17+W17+AA17+Cement!Q17+Cement!V17+AE17 -> 3874.54 | AN17: =E17+J17+N17+S17+X17+AB17+Clinker!E17+AF17+AK17 -> 2566 | AO17: =Production2!N17 -> 2247 | AP17: =AO17-AN17 -> -319 | AQ17: 2956 | AR17: =E17/AO17 -> 0.20249221 | AS17: =J17/AO17 -> 0.89007566 | AT17: =N17/AO17 -> 0.021361816 | AU17: =S17/AO17 -> 0 | AV17: =D17+I17+M17+R17+Cement!Q17 -> 3874.54 | AW17: =AN17+Cement!R17-Clinker!E17 -> 2894.29 | AX17: 593.68 | AY17: =AN17-Production2!N17 -> 319 | AZ17: =AN17 -> 2566 | BA17: =E17+J17 -> 2455 | BB17: =AX17-D17 -> -1120.62 | BC17: =I17-BD17 -> 1406.76 | BD17: 570.92 | BE17: =(AN17-Production2!N17)/'Mines (2)'!AN17 -> 0.124318 | BF17: =BE17*100 -> 12.4318 | BG17: =E17+J17+AB17 -> 2455
B18: 16 | C18: =G17 -> 6576.2232 | D18: 873.52 | E18: =F18+'RAW MILL 2'!C18 -> 547 | F18: 547 | G18: =C18+D18-E18 -> 6902.7432 | H18: =K17 -> 14709.157 | I18: 1328.24 | J18: 2000 | K18: =H18+I18-J18-Cement!S18 -> 13529.552 | L18: =P17 -> 3211.42 | M18: 133.88 | N18: =O18+'RAW MILL 2'!D18 -> 56 | O18: 56 | P18: =L18+M18-N18 -> 3289.3 | Q18: =U17 -> 0.04 | R18: 0 | S18: =T18+'RAW MILL 2'!E18 -> 0 | T18: 0 | U18: =Q18+R18-S18 -> 0.04 | V18: =Y17 -> 0 | W18: 0 | X18: 0 | Y18: =V18+W18-X18 -> 0 | Z18: =AC17 -> 0 | AA18: 0 | AB18: 0 | AC18: =Z18+AA18-AB18 -> 0 | AD18: =AG17 -> 0 | AE18: 0 | AF18: 0 | AG18: =AD18+AE18-AF18 -> 0 | AH18: =AL17 -> 298.36 | AJ18: =AK18+'RAW MILL 2'!G18 -> 0 | AL18: =AH18+AI18-AJ18 -> 298.36 | AM18: =D18+I18+M18+R18+W18+AA18+Cement!Q18+Cement!V18+AE18 -> 2335.64 | AN18: =E18+J18+N18+S18+X18+AB18+Clinker!E18+AF18+AK18 -> 2675 | AO18: =Production2!N18 -> 2409.66 | AP18: =AO18-AN18 -> -265.34 | AQ18: 3022 | AR18: =E18/AO18 -> 0.22700298 | AS18: =J18/AO18 -> 0.82999261 | AT18: =N18/AO18 -> 0.023239793 | AU18: =S18/AO18 -> 0 | AV18: =D18+I18+M18+R18+Cement!Q18 -> 2335.64 | AW18: =AN18+Cement!R18-Clinker!E18 -> 3060.06 | AX18: 1924.02 | AY18: =AN18-Production2!N18 -> 265.34 | AZ18: =AN18 -> 2675 | BA18: =E18+J18 -> 2547 | BB18: =AX18-D18 -> 1050.5 | BC18: =I18-BD18 -> -600.34 | BD18: 1928.58 | BE18: =(AN18-Production2!N18)/'Mines (2)'!AN18 -> 0.099192523 | BF18: =BE18*100 -> 9.9192523 | BG18: =E18+J18+AB18 -> 2547
B19: 17 | C19: =G18 -> 6902.7432 | D19: 1513.74 | E19: =F19+'RAW MILL 2'!C19 -> 1727 | F19: 1727 | G19: =C19+D19-E19 -> 6689.4832 | H19: =K18 -> 13529.552 | I19: 450.96 | J19: 0 | K19: =H19+I19-J19-Cement!S19 -> 13419.89 | L19: =P18 -> 3289.3 | M19: 0 | N19: =O19+'RAW MILL 2'!D19 -> 24 | O19: 24 | P19: =L19+M19-N19 -> 3265.3 | Q19: =U18 -> 0.04 | R19: 0 | S19: =T19+'RAW MILL 2'!E19 -> 0 | T19: 0 | U19: =Q19+R19-S19 -> 0.04 | V19: =Y18 -> 0 | W19: 0 | X19: 0 | Y19: =V19+W19-X19 -> 0 | Z19: =AC18 -> 0 | AA19: 0 | AB19: 0 | AC19: =Z19+AA19-AB19 -> 0 | AD19: =AG18 -> 0 | AE19: 0 | AF19: 0 | AG19: =AD19+AE19-AF19 -> 0 | AH19: =AL18 -> 298.36 | AJ19: =AK19+'RAW MILL 2'!G19 -> 0 | AL19: =AH19+AI19-AJ19 -> 298.36 | AM19: =D19+I19+M19+R19+W19+AA19+Cement!Q19+Cement!V19+AE19 -> 1964.7 | AN19: =E19+J19+N19+S19+X19+AB19+Clinker!E19+AF19+AK19 -> 1798 | AO19: =Production2!N19 -> 1619.61 | AP19: =AO19-AN19 -> -178.39 | AQ19: 2379 | AR19: =E19/AO19 -> 1.0663061 | AS19: =J19/AO19 -> 0 | AT19: =N19/AO19 -> 0.014818382 | AU19: =S19/AO19 -> 0 | AV19: =D19+I19+M19+R19+Cement!Q19 -> 1964.7 | AW19: =AN19+Cement!R19-Clinker!E19 -> 2255.56 | AX19: 2200 | AY19: =AN19-Production2!N19 -> 178.39 | AZ19: =AN19 -> 1798 | BA19: =E19+J19 -> 1727 | BB19: =AX19-D19 -> 686.26 | BC19: =I19-BD19 -> -449.04 | BD19: 900 | BE19: =(AN19-Production2!N19)/'Mines (2)'!AN19 -> 0.099215795 | BF19: =BE19*100 -> 9.9215795 | BG19: =E19+J19+AB19 -> 1727
B20: 18 | C20: =G19 -> 6689.4832 | D20: 1953.68 | E20: =F20+'RAW MILL 2'!C20 -> 1148 | F20: 1148 | G20: =C20+D20-E20 -> 7495.1632 | H20: =K19 -> 13419.89 | I20: 702.66 | J20: 1000 | K20: =H20+I20-J20-Cement!S20 -> 12637.017 | L20: =P19 -> 3265.3 | M20: 113.7 | N20: =O20+'RAW MILL 2'!D20 -> 73 | O20: 73 | P20: =L20+M20-N20 -> 3306 | Q20: =U19 -> 0.04 | R20: 0 | S20: =T20+'RAW MILL 2'!E20 -> 0 | T20: 0 | U20: =Q20+R20-S20 -> 0.04 | V20: =Y19 -> 0 | W20: 0 | X20: 0 | Y20: =V20+W20-X20 -> 0 | Z20: =AC19 -> 0 | AA20: 0 | AB20: 0 | AC20: =Z20+AA20-AB20 -> 0 | AD20: =AG19 -> 0 | AE20: 0 | AF20: 0 | AG20: =AD20+AE20-AF20 -> 0 | AH20: =AL19 -> 298.36 | AJ20: =AK20+'RAW MILL 2'!G20 -> 0 | AL20: =AH20+AI20-AJ20 -> 298.36 | AM20: =D20+I20+M20+R20+W20+AA20+Cement!Q20+Cement!V20+AE20 -> 2770.04 | AN20: =E20+J20+N20+S20+X20+AB20+Clinker!E20+AF20+AK20 -> 2309 | AO20: =Production2!N20 -> 2080.74 | AP20: =AO20-AN20 -> -228.26 | AQ20: 3157 | AR20: =E20/AO20 -> 0.55172679 | AS20: =J20/AO20 -> 0.48059825 | AT20: =N20/AO20 -> 0.035083672 | AU20: =S20/AO20 -> 0 | AV20: =D20+I20+M20+R20+Cement!Q20 -> 2770.04 | AW20: =AN20+Cement!R20-Clinker!E20 -> 2657.98 | AX20: 1275.56 | AY20: =AN20-Production2!N20 -> 228.26 | AZ20: =AN20 -> 2309 | BA20: =E20+J20 -> 2148 | BB20: =AX20-D20 -> -678.12 | BC20: =I20-BD20 -> 121.34 | BD20: 581.32 | BE20: =(AN20-Production2!N20)/'Mines (2)'!AN20 -> 0.098856648 | BF20: =BE20*100 -> 9.8856648 | BG20: =E20+J20+AB20 -> 2148
B21: 19 | C21: =G20 -> 7495.1632 | D21: 1942.16 | E21: =F21+'RAW MILL 2'!C21 -> 954 | F21: 954 | G21: =C21+D21-E21 -> 8483.3232 | H21: =K20 -> 12637.017 | I21: 1218.92 | J21: 1000 | K21: =H21+I21-J21-Cement!S21 -> 12358.713 | L21: =P20 -> 3306 | M21: 0 | N21: =O21+'RAW MILL 2'!D21 -> 67 | O21: 67 | P21: =L21+M21-N21 -> 3239 | Q21: =U20 -> 0.04 | R21: 0 | S21: =T21+'RAW MILL 2'!E21 -> 0 | T21: 0 | U21: =Q21+R21-S21 -> 0.04 | V21: =Y20 -> 0 | W21: 0 | X21: 0 | Y21: =V21+W21-X21 -> 0 | Z21: =AC20 -> 0 | AA21: 321.88 | AB21: 0 | AC21: =Z21+AA21-AB21 -> 321.88 | AD21: =AG20 -> 0 | AE21: 0 | AF21: 0 | AG21: =AD21+AE21-AF21 -> 0 | AH21: =AL20 -> 298.36 | AJ21: =AK21+'RAW MILL 2'!G21 -> 0 | AL21: =AH21+AI21-AJ21 -> 298.36 | AM21: =D21+I21+M21+R21+W21+AA21+Cement!Q21+Cement!V21+AE21 -> 3482.96 | AN21: =E21+J21+N21+S21+X21+AB21+Clinker!E21+AF21+AK21 -> 2101 | AO21: =Production2!N21 -> 1893.3 | AP21: =AO21-AN21 -> -207.7 | AQ21: 2838 | AR21: =E21/AO21 -> 0.50388211 | AS21: =J21/AO21 -> 0.52817831 | AT21: =N21/AO21 -> 0.035387947 | AU21: =S21/AO21 -> 0 | AV21: =D21+I21+M21+R21+Cement!Q21 -> 3161.08 | AW21: =AN21+Cement!R21-Clinker!E21 -> 2468.501 | AX21: 244.68 | AY21: =AN21-Production2!N21 -> 207.7 | AZ21: =AN21 -> 2101 | BA21: =E21+J21 -> 1954 | BB21: =AX21-D21 -> -1697.48 | BC21: =I21-BD21 -> -161.2 | BD21: 1380.12 | BE21: =(AN21-Production2!N21)/'Mines (2)'!AN21 -> 0.098857687 | BF21: =BE21*100 -> 9.8857687 | BG21: =E21+J21+AB21 -> 1954
B22: 20 | C22: =G21 -> 8483.3232 | D22: 252.16 | E22: =F22+'RAW MILL 2'!C22 -> 664 | F22: 664 | G22: =C22+D22-E22 -> 8071.4832 | H22: =K21 -> 12358.713 | I22: 1673.04 | J22: 1000 | K22: =H22+I22-J22-Cement!S22 -> 12577.014 | L22: =P21 -> 3239 | M22: 0 | N22: =O22+'RAW MILL 2'!D22 -> 57 | O22: 57 | P22: =L22+M22-N22 -> 3182 | Q22: =U21 -> 0.04 | R22: 0 | S22: =T22+'RAW MILL 2'!E22 -> 0 | T22: 0 | U22: =Q22+R22-S22 -> 0.04 | V22: =Y21 -> 0 | W22: 0 | X22: 0 | Y22: =V22+W22-X22 -> 0 | Z22: =AC21 -> 321.88 | AA22: 156.24 | AB22: 0 | AC22: =Z22+AA22-AB22 -> 478.12 | AD22: =AG21 -> 0 | AE22: 0 | AF22: 0 | AG22: =AD22+AE22-AF22 -> 0 | AH22: =AL21 -> 298.36 | AJ22: =AK22+'RAW MILL 2'!G22 -> 0 | AL22: =AH22+AI22-AJ22 -> 298.36 | AM22: =D22+I22+M22+R22+W22+AA22+Cement!Q22+Cement!V22+AE22 -> 2081.44 | AN22: =E22+J22+N22+S22+X22+AB22+Clinker!E22+AF22+AK22 -> 1789 | AO22: =Production2!N22 -> 1612.14 | AP22: =AO22-AN22 -> -176.86 | AQ22: 3051 | AR22: =E22/AO22 -> 0.4118749 | AS22: =J22/AO22 -> 0.62029352 | AT22: =N22/AO22 -> 0.035356731 | AU22: =S22/AO22 -> 0 | AV22: =D22+I22+M22+R22+Cement!Q22 -> 1925.2 | AW22: =AN22+Cement!R22-Clinker!E22 -> 2130.265 | AX22: 841.18 | AY22: =AN22-Production2!N22 -> 176.86 | AZ22: =AN22 -> 1789 | BA22: =E22+J22 -> 1664 | BB22: =AX22-D22 -> 589.02 | BC22: =I22-BD22 -> 72.24 | BD22: 1600.8 | BE22: =(AN22-Production2!N22)/'Mines (2)'!AN22 -> 0.098859698 | BF22: =BE22*100 -> 9.8859698
B23: 21 | C23: =G22 -> 8071.4832 | D23: 2063.6 | E23: =F23+'RAW MILL 2'!C23 -> 1906 | F23: 1906 | G23: =C23+D23-E23 -> 8229.0832 | H23: =K22 -> 12577.014 | I23: 1306.88 | J23: 0 | K23: =H23+I23-J23-Cement!S23 -> 13466.717 | L23: =P22 -> 3182 | M23: 0 | N23: =O23+'RAW MILL 2'!D23 -> 41 | O23: 41 | P23: =L23+M23-N23 -> 3141 | Q23: =U22 -> 0.04 | R23: 0 | S23: =T23+'RAW MILL 2'!E23 -> 0 | T23: 0 | U23: =Q23+R23-S23 -> 0.04 | V23: =Y22 -> 0 | W23: 0 | X23: 0 | Y23: =V23+W23-X23 -> 0 | Z23: =AC22 -> 478.12 | AA23: 0 | AB23: 0 | AC23: =Z23+AA23-AB23 -> 478.12 | AD23: =AG22 -> 0 | AE23: 0 | AF23: 0 | AG23: =AD23+AE23-AF23 -> 0 | AH23: =AL22 -> 298.36 | AI23: 0 | AJ23: =AK23+'RAW MILL 2'!G23 -> 20 | AK23: 20 | AL23: =AH23+AI23-AJ23 -> 278.36 | AM23: =D23+I23+M23+R23+W23+AA23+Cement!Q23+Cement!V23+AE23 -> 3370.48 | AN23: =E23+J23+N23+S23+X23+AB23+Clinker!E23+AF23+AK23 -> 2009 | AO23: =Production2!N23 -> 1809.96 | AP23: =AO23-AN23 -> -199.04 | AQ23: 2232 | AR23: =E23/AO23 -> 1.0530619 | AS23: =J23/AO23 -> 0 | AT23: =N23/AO23 -> 0.022652434 | AU23: =S23/AO23 -> 0 | AV23: =D23+I23+R23+#REF!+Cement!Q23 -> #REF! | AW23: =AN23+Cement!R23-Clinker!E23 -> 2342.46 | AX23: 0 | AY23: =AN23-Production2!N23 -> 199.04 | AZ23: =AN23 -> 2009 | BA23: =E23+J23 -> 1906 | BB23: =AX23-D23 -> -2063.6 | BC23: =I23-BD23 -> 279.3 | BD23: 1027.58 | BE23: =(AN23-Production2!N23)/'Mines (2)'!AN23 -> 0.099074166 | BF23: =BE23*100 -> 9.9074166
B24: 22 | C24: =G23 -> 8229.0832 | D24: 1013.84 | E24: =F24+'RAW MILL 2'!C24 -> 1587 | F24: 1587 | G24: =C24+D24-E24 -> 7655.9232 | H24: =K23 -> 13466.717 | I24: 1524.44 | J24: 0 | K24: =H24+I24-J24-Cement!S24 -> 14558.848 | L24: =P23 -> 3141 | M24: 120.46 | N24: =O24+'RAW MILL 2'!D24 -> 17 | O24: 17 | P24: =L24+M24-N24 -> 3244.46 | Q24: =U23 -> 0.04 | R24: 0 | S24: =T24+'RAW MILL 2'!E24 -> 0 | T24: 0 | U24: =Q24+R24-S24 -> 0.04 | V24: =Y23 -> 0 | W24: 0 | X24: 0 | Y24: =V24+W24-X24 -> 0 | Z24: =AC23 -> 478.12 | AA24: 0 | AB24: 0 | AC24: =Z24+AA24-AB24 -> 478.12 | AD24: =AG23 -> 0 | AE24: 0 | AF24: 0 | AG24: =AD24+AE24-AF24 -> 0 | AH24: =AL23 -> 278.36 | AI24: 90.7 | AJ24: =AK24+'RAW MILL 2'!G24 -> 16 | AK24: 16 | AL24: =AH24+AI24-AJ24 -> 353.06 | AM24: =D24+I24+M24+R24+W24+AA24+Cement!Q24+Cement!V24+AE24 -> 2658.74 | AN24: =E24+J24+N24+S24+X24+AB24+Clinker!E24+AF24+AK24 -> 1675 | AO24: =Production2!N24 -> 1509.63 | AP24: =AO24-AN24 -> -165.37 | AR24: =E24/AO24 -> 1.051251 | AS24: =J24/AO24 -> 0 | AT24: =N24/AO24 -> 0.011261037 | AU24: =S24/AO24 -> 0 | AV24: =D24+I24+M24+R24+Cement!Q24 -> 2658.74 | AW24: =AN24+Cement!R24-Clinker!E24 -> 2009.078 | AY24: =AN24-Production2!N24 -> 165.37 | AZ24: =AN24 -> 1675 | BA24: =E24+J24 -> 1587 | BB24: =AX24-D24 -> -1013.84 | BC24: =I24-BD24 -> 1524.44 | BD24: 0 | BE24: =(AN24-Production2!N24)/'Mines (2)'!AN24 -> 0.098728358 | BF24: =BE24*100 -> 9.8728358
B25: 23 | C25: =G24 -> 7655.9232 | D25: 800.58 | E25: =F25+'RAW MILL 2'!C25 -> 0 | F25: 0 | G25: =C25+D25-E25 -> 8456.5032 | H25: =K24 -> 14558.848 | I25: 1822.7 | J25: 0 | K25: =H25+I25-J25-Cement!S25 -> 15980.935 | L25: =P24 -> 3244.46 | M25: 0 | N25: =O25+'RAW MILL 2'!D25 -> 0 | O25: 0 | P25: =L25+M25-N25 -> 3244.46 | Q25: =U24 -> 0.04 | R25: 0 | S25: =T25+'RAW MILL 2'!E25 -> 0 | T25: 0 | U25: =Q25+R25-S25 -> 0.04 | V25: =Y24 -> 0 | W25: 0 | X25: 0 | Y25: =V25+W25-X25 -> 0 | Z25: =AC24 -> 478.12 | AA25: 250.08 | AB25: 0 | AC25: =Z25+AA25-AB25 -> 728.2 | AD25: =AG24 -> 0 | AE25: 0 | AF25: 0 | AG25: =AD25+AE25-AF25 -> 0 | AH25: =AL24 -> 353.06 | AI25: 30.38 | AJ25: =AK25+'RAW MILL 2'!G25 -> 0 | AK25: 0 | AL25: =AH25+AI25-AJ25 -> 383.44 | AM25: =D25+I25+M25+R25+W25+AA25+Cement!Q25+Cement!V25+AE25 -> 2873.36 | AN25: =E25+J25+N25+S25+X25+AB25+Clinker!E25+AF25+AK25 -> 0 | AO25: =Production2!N25 -> 0 | AP25: =AO25-AN25 -> 0 | AR25: =E25/AO25 -> #DIV/0! | AS25: =J25/AO25 -> #DIV/0! | AT25: =N25/AO25 -> #DIV/0! | AU25: =S25/AO25 -> #DIV/0! | AV25: =D25+I25+M25+R25+Cement!Q25 -> 2623.28 | AW25: =AN25+Cement!R25-Clinker!E25 -> 360.551 | AY25: =AN25-Production2!N25 -> 0 | AZ25: =AN25 -> 0 | BA25: =E25+J25 -> 0 | BB25: =AX25-D25 -> -800.58 | BC25: =I25-BD25 -> 1822.7 | BD25: 0 | BE25: =(AN25-Production2!N25)/'Mines (2)'!AN25 -> #DIV/0! | BF25: =BE25*100 -> #DIV/0!
B26: 24 | C26: =G25 -> 8456.5032 | D26: 938.74 | E26: =F26+'RAW MILL 2'!C26 -> 1614 | F26: 1614 | G26: =C26+D26-E26 -> 7781.2432 | H26: =K25 -> 15980.935 | I26: 1305.1 | J26: 0 | K26: =H26+I26-J26-Cement!S26 -> 16881.313 | L26: =P25 -> 3244.46 | M26: 0 | N26: =O26+'RAW MILL 2'!D26 -> 19 | O26: 19 | P26: =L26+M26-N26 -> 3225.46 | Q26: =U25 -> 0.04 | R26: 0 | S26: =T26+'RAW MILL 2'!E26 -> 0 | T26: 0 | U26: =Q26+R26-S26 -> 0.04 | V26: =Y25 -> 0 | W26: 0 | X26: 0 | Y26: =V26+W26-X26 -> 0 | Z26: =AC25 -> 728.2 | AA26: 0 | AB26: 0 | AC26: =Z26+AA26-AB26 -> 728.2 | AD26: =AG25 -> 0 | AE26: 0 | AF26: 0 | AG26: =AD26+AE26-AF26 -> 0 | AH26: =AL25 -> 383.44 | AI26: 0 | AJ26: =AK26+'RAW MILL 2'!G26 -> 17 | AK26: 17 | AL26: =AH26+AI26-AJ26 -> 366.44 | AM26: =D26+I26+M26+R26+W26+AA26+Cement!Q26+Cement!V26+AE26 -> 2243.84 | AN26: =E26+J26+N26+S26+X26+AB26+Clinker!E26+AF26+AK26 -> 1687 | AO26: =Production2!N26 -> 1519.92 | AP26: =AO26-AN26 -> -167.08 | AR26: =E26/AO26 -> 1.061898 | AS26: =J26/AO26 -> 0 | AT26: =N26/AO26 -> 0.012500658 | AU26: =S26/AO26 -> 0 | AV26: =D26+I26+M26+R26+Cement!Q26 -> 2243.84 | AW26: =AN26+Cement!R26-Clinker!E26 -> 2014.25 | AY26: =AN26-Production2!N26 -> 167.08 | AZ26: =AN26 -> 1687 | BA26: =E26+J26 -> 1614 | BB26: =AX26-D26 -> -938.74 | BC26: =D26-BD26 -> 938.74 | BD26: 0 | BE26: =(AN26-Production2!N26)/'Mines (2)'!AN26 -> 0.099039715 | BF26: =BE26*100 -> 9.9039715
B27: 25 | C27: =G26 -> 7781.2432 | D27: 1172.54 | E27: =F27+'RAW MILL 2'!C27 -> 2600 | F27: 2393 | G27: =C27+D27-E27 -> 6353.7832 | H27: =K26 -> 16881.313 | I27: 1021.82 | J27: 0 | K27: =H27+I27-J27-Cement!S27 -> 17465.669 | L27: =P26 -> 3225.46 | M27: 0 | N27: =O27+'RAW MILL 2'!D27 -> 17 | O27: 16 | P27: =L27+M27-N27 -> 3208.46 | Q27: =U26 -> 0.04 | R27: 0 | S27: =T27+'RAW MILL 2'!E27 -> 0 | T27: 0 | U27: =Q27+R27-S27 -> 0.04 | V27: =Y26 -> 0 | W27: 0 | X27: 0 | Y27: =V27+W27-X27 -> 0 | Z27: =AC26 -> 728.2 | AA27: 0 | AB27: 0 | AC27: =Z27+AA27-AB27 -> 728.2 | AD27: =AG26 -> 0 | AE27: 0 | AF27: 0 | AG27: =AD27+AE27-AF27 -> 0 | AH27: =AL26 -> 366.44 | AI27: 0 | AJ27: =AK27+'RAW MILL 2'!G27 -> 26 | AK27: 24 | AL27: =AH27+AI27-AJ27 -> 340.44 | AM27: =D27+I27+M27+R27+W27+AA27+Cement!Q27+Cement!V27+AE27 -> 2194.36 | AN27: =E27+J27+N27+S27+X27+AB27+Clinker!E27+AF27+AK27 -> 2692 | AO27: =Production2!N27 -> 2232 | AP27: =AO27-AN27 -> -460 | AR27: =E27/AO27 -> 1.1648746 | AS27: =J27/AO27 -> 0 | AT27: =N27/AO27 -> 0.0076164875 | AU27: =S27/AO27 -> 0 | AV27: =D27+I27+M27+R27+Cement!Q27 -> 2194.36 | AW27: =AN27+Cement!R27-Clinker!E27 -> 3034.718 | AY27: =AN27-Production2!N27 -> 460 | AZ27: =AN27 -> 2692 | BA27: 25 | BD27: 0 | BE27: =(AN27-Production2!N27)/'Mines (2)'!AN27 -> 0.17087667 | BF27: =BE27*100 -> 17.087667
B28: 26 | C28: =G27 -> 6353.7832 | D28: 1281.98 | E28: =F28+'RAW MILL 2'!C28 -> 675 | F28: 488 | G28: =C28+D28-E28 -> 6960.7632 | H28: =K27 -> 17465.669 | I28: 1341.18 | J28: 2000 | K28: =H28+I28-J28-Cement!S28 -> 16368.424 | L28: =P27 -> 3208.46 | M28: 73.12 | N28: =O28+'RAW MILL 2'!D28 -> 18 | O28: 17 | P28: =L28+M28-N28 -> 3263.58 | Q28: =U27 -> 0.04 | R28: 0 | S28: =T28+'RAW MILL 2'!E28 -> 0 | T28: 0 | U28: =Q28+R28-S28 -> 0.04 | V28: =Y27 -> 0 | W28: 0 | X28: 0 | Y28: =V28+W28-X28 -> 0 | Z28: =AC27 -> 728.2 | AA28: 0 | AB28: 0 | AC28: =Z28+AA28-AB28 -> 728.2 | AD28: =AG27 -> 0 | AE28: 0 | AF28: 0 | AG28: =AD28+AE28-AF28 -> 0 | AH28: =AL27 -> 340.44 | AI28: 0 | AJ28: =AK28+'RAW MILL 2'!G28 -> 28 | AK28: 26 | AL28: =AH28+AI28-AJ28 -> 312.44 | AM28: =D28+I28+M28+R28+W28+AA28+Cement!Q28+Cement!V28+AE28 -> 2696.28 | AN28: =E28+J28+N28+S28+X28+AB28+Clinker!E28+AF28+AK28 -> 2769 | AO28: =Production2!N28 -> 2320 | AP28: =AO28-AN28 -> -449 | AR28: =E28/AO28 -> 0.29094828 | AS28: =J28/AO28 -> 0.86206897 | AT28: =N28/AO28 -> 0.0077586207 | AU28: =S28/AO28 -> 0 | AV28: =D28+I28+M28+R28+Cement!Q28 -> 2696.28 | AW28: =AN28+Cement!R28-Clinker!E28 -> 3113.582 | AY28: =AN28-Production2!N28 -> 449 | AZ28: =AN28 -> 2769 | BA28: 26 | BD28: 0 | BE28: =(AN28-Production2!N28)/'Mines (2)'!AN28 -> 0.1621524 | BF28: =BE28*100 -> 16.21524
B29: 27 | C29: =G28 -> 6960.7632 | D29: 573.82 | E29: =F29+'RAW MILL 2'!C29 -> 197 | F29: 49 | G29: =C29+D29-E29 -> 7337.5832 | H29: =K28 -> 16368.424 | I29: 1963.58 | J29: 2000 | K29: =H29+I29-J29-Cement!S29 -> 15968.657 | L29: =P28 -> 3263.58 | M29: 382.08 | N29: =O29+'RAW MILL 2'!D29 -> 16 | O29: 15 | P29: =L29+M29-N29 -> 3629.66 | Q29: =U28 -> 0.04 | R29: 0 | S29: =T29+'RAW MILL 2'!E29 -> 0 | T29: 0 | U29: =Q29+R29-S29 -> 0.04 | V29: =Y28 -> 0 | W29: 0 | X29: 0 | Y29: =V29+W29-X29 -> 0 | Z29: =AC28 -> 728.2 | AA29: 0 | AB29: 0 | AC29: =Z29+AA29-AB29 -> 728.2 | AD29: =AG28 -> 0 | AE29: 0 | AF29: 0 | AG29: =AD29+AE29-AF29 -> 0 | AH29: =AL28 -> 312.44 | AI29: 0 | AJ29: =AK29+'RAW MILL 2'!G29 -> 23 | AK29: 21 | AL29: =AH29+AI29-AJ29 -> 289.44 | AM29: =D29+I29+M29+R29+W29+AA29+Cement!Q29+Cement!V29+AE29 -> 2919.48 | AN29: =E29+J29+N29+S29+X29+AB29+Clinker!E29+AF29+AK29 -> 2274 | AO29: =Production2!N29 -> 1910 | AP29: =AO29-AN29 -> -364 | AR29: =E29/AO29 -> 0.10314136 | AS29: =J29/AO29 -> 1.0471204 | AT29: =N29/AO29 -> 0.0083769634 | AU29: =S29/AO29 -> 0 | AW29: =AN29+Cement!R29-Clinker!E29 -> 2561.013 | AY29: =AN29-Production2!N29 -> 364 | AZ29: =AN29 -> 2274 | BA29: 27 | BD29: 0 | BE29: =(AN29-Production2!N29)/'Mines (2)'!AN29 -> 0.16007036 | BF29: =BE29*100 -> 16.007036
B30: 28 | C30: =G29 -> 7337.5832 | D30: 1262.16 | E30: =F30+'RAW MILL 2'!C30 -> 571 | F30: 385 | G30: =C30+D30-E30 -> 8028.7432 | H30: =K29 -> 15968.657 | I30: 1537.4 | J30: 2000 | K30: =H30+I30-J30-Cement!S30 -> 15089.05 | L30: =P29 -> 3629.66 | M30: 267.62 | N30: =O30+'RAW MILL 2'!D30 -> 18 | O30: 17 | P30: =L30+M30-N30 -> 3879.28 | Q30: =U29 -> 0.04 | R30: 0 | S30: =T30+'RAW MILL 2'!E30 -> 0 | T30: 0 | U30: =Q30+R30-S30 -> 0.04 | V30: =Y29 -> 0 | W30: 0 | X30: 0 | Y30: =V30+W30-X30 -> 0 | Z30: =AC29 -> 728.2 | AA30: 0 | AB30: 0 | AC30: =Z30+AA30-AB30 -> 728.2 | AD30: =AG29 -> 0 | AE30: 0 | AF30: 0 | AG30: =AD30+AE30-AF30 -> 0 | AH30: =AL29 -> 289.44 | AI30: 0 | AJ30: =AK30+'RAW MILL 2'!G30 -> 23 | AK30: 22 | AL30: =AH30+AI30-AJ30 -> 266.44 | AM30: =D30+I30+M30+R30+W30+AA30+Cement!Q30+Cement!V30+AE30 -> 3067.18 | AN30: =E30+J30+N30+S30+X30+AB30+Clinker!E30+AF30+AK30 -> 2645 | AO30: =Production2!N30 -> 2210 | AP30: =AO30-AN30 -> -435 | AR30: =E30/AO30 -> 0.25837104 | AS30: =J30/AO30 -> 0.90497738 | AT30: =N30/AO30 -> 0.0081447964 | AU30: =S30/AO30 -> 0 | AW30: =AN30+Cement!R30-Clinker!E30 -> 2986.306 | AY30: =AN30-Production2!N30 -> 435 | AZ30: =AN30 -> 2645 | BA30: 28 | BD30: 0 | BE30: =(AN30-Production2!N30)/'Mines (2)'!AN30 -> 0.16446125 | BF30: =BE30*100 -> 16.446125
B31: 29 | C31: =G30 -> 8028.7432 | D31: 2360.7 | E31: =F31+'RAW MILL 2'!C31 -> 626 | F31: 466 | G31: =C31+D31-E31 -> 9763.4432 | H31: =K30 -> 15089.05 | I31: 1259.26 | J31: 2000 | K31: =H31+I31-J31-Cement!S31 -> 13983.843 | L31: =P30 -> 3879.28 | M31: 0 | N31: =O31+'RAW MILL 2'!D31 -> 14 | O31: 13 | P31: =L31+M31-N31 -> 3865.28 | Q31: =U30 -> 0.04 | R31: 0 | S31: =T31+'RAW MILL 2'!E31 -> 0 | T31: 0 | U31: =Q31+R31-S31 -> 0.04 | V31: =Y30 -> 0 | W31: 0 | X31: 0 | Y31: =V31+W31-X31 -> 0 | Z31: =AC30 -> 728.2 | AA31: 0 | AB31: 0 | AC31: =Z31+AA31-AB31 -> 728.2 | AD31: =AG30 -> 0 | AE31: 0 | AF31: 0 | AG31: =AD31+AE31-AF31 -> 0 | AH31: =AL30 -> 266.44 | AI31: 31.06 | AJ31: =AK31+'RAW MILL 2'!G31 -> 26 | AK31: 25 | AL31: =AH31+AI31-AJ31 -> 271.5 | AM31: =D31+I31+M31+R31+W31+AA31+Cement!Q31+Cement!V31+AE31 -> 3619.96 | AN31: =E31+J31+N31+S31+X31+AB31+Clinker!E31+AF31+AK31 -> 2742 | AO31: =Production2!N31 -> 2320 | AP31: =AO31-AN31 -> -422 | AR31: =E31/AO31 -> 0.26982759 | AS31: =J31/AO31 -> 0.86206897 | AT31: =N31/AO31 -> 0.0060344828 | AU31: =S31/AO31 -> 0 | AW31: =AN31+Cement!R31-Clinker!E31 -> 2993.02 | AY31: =AN31-Production2!N31 -> 422 | AZ31: =AN31 -> 2742 | BA31: 29 | BD31: 0 | BE31: =(AN31-Production2!N31)/'Mines (2)'!AN31 -> 0.15390226 | BF31: =BE31*100 -> 15.390226
B32: 30 | C32: =G31 -> 9763.4432 | D32: 1731.64 | E32: =F32+'RAW MILL 2'!C32 -> 1628 | F32: 1538 | G32: =C32+D32-E32 -> 9867.0832 | H32: =K31 -> 13983.843 | I32: 526.22 | J32: 0 | K32: =H32+I32-J32-Cement!S32 -> 14102.211 | L32: =P31 -> 3865.28 | M32: 0 | N32: =O32+'RAW MILL 2'!D32 -> 46 | O32: 43 | P32: =L32+M32-N32 -> 3819.28 | Q32: =U31 -> 0.04 | R32: 0 | S32: =T32+'RAW MILL 2'!E32 -> 0 | T32: 0 | U32: =Q32+R32-S32 -> 0.04 | V32: =Y31 -> 0 | W32: 0 | X32: 0 | Y32: =V32+W32-X32 -> 0 | Z32: =AC31 -> 728.2 | AA32: 0 | AB32: 0 | AC32: =Z32+AA32-AB32 -> 728.2 | AD32: =AG31 -> 0 | AE32: 0 | AF32: 0 | AG32: =AD32+AE32-AF32 -> 0 | AH32: =AL31 -> 271.5 | AI32: 65.2 | AJ32: =AK32+'RAW MILL 2'!G32 -> 19 | AK32: 18 | AL32: =AH32+AI32-AJ32 -> 317.7 | AM32: =D32+I32+M32+R32+W32+AA32+Cement!Q32+Cement!V32+AE32 -> 2257.86 | AN32: =E32+J32+N32+S32+X32+AB32+Clinker!E32+AF32+AK32 -> 1735 | AO32: =Production2!N32 -> 1476 | AP32: =AO32-AN32 -> -259 | AR32: =E32/AO32 -> 1.102981 | AS32: =J32/AO32 -> 0 | AT32: =N32/AO32 -> 0.031165312 | AU32: =S32/AO32 -> 0 | AW32: =AN32+Cement!R32-Clinker!E32 -> 2059.067 | AY32: =AN32-Production2!N32 -> 259 | AZ32: =AN32 -> 1735 | BA32: 30 | BD32: 0 | BE32: =(AN32-Production2!N32)/'Mines (2)'!AN32 -> 0.14927954
B33: 31 | C33: =G32 -> 9867.0832 | D33: 0 | E33: =F33+'RAW MILL 2'!C33 -> 0 | F33: 0 | G33: =C33+D33-E33 -> 9867.0832 | H33: =K32 -> 14102.211 | I33: 0 | J33: 0 | K33: =H33+I33-J33-Cement!S33 -> 14102.211 | L33: =P32 -> 3819.28 | M33: 0 | N33: =O33+'RAW MILL 2'!D33 -> 0 | O33: 0 | P33: =L33+M33-N33 -> 3819.28 | Q33: =U32 -> 0.04 | R33: 0 | S33: =T33+'RAW MILL 2'!E33 -> 0 | T33: 0 | U33: =Q33+R33-S33 -> 0.04 | V33: =Y32 -> 0 | W33: 0 | X33: 0 | Y33: =V33+W33-X33 -> 0 | Z33: =AC32 -> 728.2 | AA33: 0 | AB33: 0 | AC33: =Z33+AA33-AB33 -> 728.2 | AD33: =AG32 -> 0 | AE33: 0 | AF33: 0 | AG33: =AD33+AE33-AF33 -> 0 | AH33: =AL32 -> 317.7 | AI33: 0 | AJ33: =AK33+'RAW MILL 2'!G33 -> 0 | AK33: 0 | AL33: =AH33+AI33-AJ33 -> 317.7 | AM33: =D33+I33+M33+R33+W33+AA33+Cement!Q33+Cement!V33+AE33 -> 0 | AN33: =E33+J33+N33+S33+X33+AB33+Clinker!E33+AF33+AK33 -> 0 | AY33: =AN33-Production2!N33 -> 0
B34: MTD | D34: =SUM(D3:D33) -> 43393.3 | E34: =SUM(E3:E33) -> 41049 | I34: =SUM(I3:I33) -> 41400.44 | J34: =SUM(J3:J33) -> 26000 | M34: =SUM(M3:M33) -> 2130.84 | N34: =SUM(N3:N33) -> 1223 | O34: =SUM(O3:O33) -> 1164 | R34: =SUM(R3:R33) -> 0 | S34: =SUM(S3:S33) -> 0 | T34: =SUM(T3:T33) -> 0 | U34: =SUM(U3:U33) -> 1.24 | V34: =SUM(V3:V33) -> 0 | W34: =SUM(W3:W33) -> 0 | X34: =SUM(X3:X33) -> 0 | Y34: =SUM(Y3:Y33) -> 0 | ... AG34: =SUM(AG3:AG33) -> 0 | AI34: =SUM(AI3:AI33) -> 217.34 | AJ34: =SUM(AJ3:AJ33) -> 198 | AK34: =SUM(AK3:AK33) -> 189 | AN34: =SUM(AN3:AN33) -> 70215
B35: YTD | D35: =D36+SUM(D3:D33) -> 132051.02 | E35: =E36+SUM(E3:E33) -> 131690 | I35: =I36+SUM(I3:I33) -> 109610 | J35: =J36+SUM(J3:J33) -> 75390 | M35: =M36+SUM(M3:M33) -> 7400.24 | N35: =N36+SUM(N3:N33) -> 3705 | O35: =O36+SUM(O3:O33) -> 3554 | R35: =R36+SUM(R3:R33) -> 137.76 | S35: =S36+SUM(S3:S33) -> 738 | T35: =T36+SUM(T3:T33) -> 705 | W35: =W36+SUM(W3:W33) -> 0 | X35: =X36+SUM(X3:X33) -> 0 | AA35: =AA36+SUM(AA3:AA33) -> 728.2 | AB35: =AB36+SUM(AB3:AB33) -> 0 | AE35: =AE36+SUM(AE3:AE33) -> 0 | AF35: =AF36+SUM(AF3:AF33) -> 0 | AI35: =AI36+SUM(AI3:AI33) -> 217.34 | AJ35: =AJ36+SUM(AJ3:AJ33) -> 198 | AK35: =AK36+SUM(AK3:AK33) -> 189
B36: YTD | D36: 88657.72 | E36: 90641 | I36: 68209.56 | J36: 49390 | M36: 5269.4 | N36: 2482 | O36: 2390 | R36: 137.76 | S36: 738 | T36: 705 | W36: 0 | X36: 0 | AA36: 0 | AB36: 0 | AE36: 0 | AF36: 0 | AI36: 0 | AJ36: 0 | AK36: 0
I39: =D36+I36+W36+AA36+Cement!Q36+Cement!V36 -> 156867.28 | J39: =E36+J36+X36+AB36+Cement!R36+Cement!W36 -> 159423.93 | Q39: 3103 | R39: 3286 | S39: 2899 | T39: 2899 | U39: 3290 | V39: 3245 | W39: 3139 | X39: 1732 | Y39: 1959 | Z39: 3119 | AA39: 3017 | AB39: 3256 | AC39: 3209 | AD39: 3075 | AE39: 2456 | AF39: 2956 | AG39: 3022 | AM39: 2379 | AN39: 3157 | AO39: 2838 | AP39: 3051 | AQ39: 2232

Sheet Clinker
B1: DEC | C1: Iron Ore | H1: Raw Meal | L1: Tan Coal | R1: EDENVILLEY coal | X1: RUVUMA coal | AC1: GODMWANGA coal | AG1: STAMICO coal | AL1: Ash Coal | AP1: Ariim Coal | AU1: Lik & Lambert coal | AZ1: JITEGEMEE | BE1: MAX COAL | BJ1: SINO COAL | BO1: Ibrico | BT1: MEGA CJ | BY1: MABENGA COAL | CD1: TENCO | CI1: Scolastica | CN1: Connect | CS1: Yongda | CX1: Kindaini | DC1: MONTREAL | DH1: ludewa | DM1: MCHEKANE | DR1: MARKET | DW1: SIAAS | EB1: KILN COAL | EF1: cpp coal | EJ1: Clinker | EP1: Spg TRACKING
B2: Date | C2: Opening Stock | D2: Production | E2: Consumption/RM1 | G2: Closing Stock | H2: Opening Stock | I2: Production | J2: total Consumption | K2: Closing Stock | L2: Opening Stock | M2: Production | N2: CPP | O2: KILN | P2: Consumption | Q2: Closing Stock | R2: Opening Stock | S2: Production | T2: Consumption CPP | U2: Consump Kiln | V2: Total Consumption | W2: Closing Stock | X2: Opening Stock | Y2: Production | Z2: CPP | AA2: Consumption | AB2: Closing Stock | AC2: Opening Stock | AD2: Production | AE2: Consumption | AF2: Closing Stock | AG2: Opening Stock | AH2: Production | AI2: Kiln cons | AJ2: Consumption | AK2: Closing Stock | AL2: Opening Stock | AM2: Production | AN2: Consumption | AO2: Closing Stock | AP2: Opening Stock | AQ2: Production | AR2: Consumption | AS2: CONS CPP | AT2: Closing Stock | AU2: Opening Stock | AV2: Production | AW2: Consumption | AX2: CONS CPP | AY2: Closing Stock | AZ2: Opening Stock | BA2: Production | BB2: Consumption | BC2: CONS CPP | BD2: Closing Stock | BE2: Opening Stock | BF2: Production | BG2: Consumption | BH2: CONS CPP | BI2: Closing Stock | BJ2: Opening Stock | BK2: Production | BL2: Consumption | BM2: CONS CPP | BN2: Closing Stock | BO2: Opening Stock | BP2: Production | BQ2: Consumption | BR2: CONS CPP | BS2: Closing Stock | BT2: Opening Stock | BU2: Production | BV2: Consumption | BW2: CONS CPP | BX2: Closing Stock | BY2: Opening Stock | BZ2: Production | CA2: Consumption | CB2: CONS CPP | CC2: Closing Stock | CD2: Opening Stock | CE2: Production | CF2: Consumption | CG2: CONS CPP | CH2: Closing Stock | CI2: Opening Stock | CJ2: Production | CK2: Consumption | CL2: CONS CPP | CM2: Closing Stock | CN2: Opening Stock | CO2: Production | CP2: Consumption | CQ2: CONS CPP | CR2: Closing Stock | CS2: Opening Stock | CT2: Production | CU2: Consumption | CV2: CONS CPP | CW2: Closing Stock | CX2: Opening Stock | CY2: Production | CZ2: Consumption | DA2: CONS CPP | DB2: Closing Stock | DC2: Opening Stock | DD2: Production | DE2: Consumption | DF2: CONS CPP | DG2: Closing Stock | DH2: Opening Stock | DI2: Production | DJ2: Consumption | DK2: CONS CPP | DL2: Closing Stock | DM2: Opening Stock | DN2: Production | DO2: Consumption | DP2: CONS CPP | DQ2: Closing Stock | DR2: Opening Stock | DS2: Production | DT2: Consumption | DU2: CONS CPP | DV2: Closing Stock | DW2: Opening Stock | DX2: Production | DY2: Consumption | DZ2: CONS CPP | EA2: Closing Stock | EB2: Closing Stock | EC2: Production | ED2: Consumption | EE2: Closing Stock | EF2: Opening Stock | EG2: Production | EH2: Consumption | EI2: Closing Stock | EJ2: Opening Stock | EK2: Production | EL2: Consumption | EM2: Closing Stock | EN2: clinker despatch | EO2: OP | EP2: CLINKER PURCHASED | EQ2: CLINKER CONS | ER2: CLOSING
B3: 1 | C3: 2647.92 | D3: 0 | E3: =F3+'RAW MILL 2'!F3 -> 52 | F3: 48 | G3: =C3+D3-E3 -> 2595.92 | H3: 1267.64 | I3: =Production2!N3+Production2!Q3 -> 3111.06 | J3: =Production2!K3 -> 3053.5 | K3: =H3+I3-J3 -> 1325.2 | L3: 0 | M3: 0 | N3: =CPP!D3 -> 0 | O3: 0 | P3: =N3+O3 -> 0 | Q3: =L3+M3-O3-N3 -> 0 | R3: 0 | S3: 0 | T3: =CPP!E3 -> 0 | U3: 0 | V3: =T3+U3 -> 0 | W3: =R3+S3-V3 -> 0 | X3: 1063.04 | Y3: 0 | Z3: =CPP!H3 -> 0 | AA3: 0 | AB3: =X3+Y3-AA3-Z3 -> 1063.04 | AC3: 0 | AD3: 0 | AE3: 0 | AF3: =AC3+AD3-AE3 -> 0 | AG3: 4048.67 | AH3: 272.05 | AI3: 0 | AJ3: =CPP!G3 -> 156 | AK3: =AG3+AH3-AJ3 -> 4164.72 | AL3: 0 | AM3: 0 | AN3: 0 | AO3: =AL3+AM3-AN3 -> 0 | AP3: 0 | AQ3: 0 | AR3: 0 | AS3: =CPP!I3 -> 0 | AT3: =AP3+AQ3-AR3-AS3 -> 0 | AU3: 0 | AV3: 0 | AW3: 0 | AX3: =CPP!J3 -> 0 | AY3: =AU3+AV3-AW3-AX3 -> 0 | AZ3: 412.027 | BA3: 121.76 | BB3: 0 | BC3: =CPP!K3 -> 0 | BD3: =AZ3+BA3-BB3-BC3 -> 533.787 | BE3: 0 | BF3: 0 | BG3: 0 | BH3: =CPP!L3 -> 0 | BI3: =BE3+BF3-BG3-BH3 -> 0 | BJ3: 0 | BK3: 0 | BL3: 0 | BM3: =CPP!M3 -> 0 | BN3: =BJ3+BK3-BL3-BM3 -> 0 | BO3: 0 | BP3: 0 | BQ3: 0 | BR3: =CPP!N3 -> 0 | BS3: =BO3+BP3-BQ3-BR3 -> 0 | BT3: 0 | BU3: 0 | BV3: 0 | BW3: =CPP!O3 -> 0 | BX3: =BT3+BU3-BV3-BW3 -> 0 | BY3: 0.01 | BZ3: 0 | CA3: 0 | CC3: 0 | CD3: 0 | CE3: 0 | CF3: 0 | CG3: =CPP!P3 -> 0 | CH3: =CD3+CE3-CF3-CG3 -> 0 | CI3: 0 | CJ3: 0 | CK3: 0 | CL3: =CPP!Q3 -> 0 | CM3: =CI3+CJ3-CK3-CL3 -> 0 | CN3: 0.05 | CO3: 0 | CP3: 0 | CQ3: =CPP!R3 -> 0 | CR3: =CN3+CO3-CP3-CQ3 -> 0.05 | CS3: 0 | CT3: 0 | CU3: 0 | CV3: =CPP!S3 -> 0 | CW3: =CS3+CT3-CU3-CV3 -> 0 | CX3: 0 | CY3: 0 | CZ3: 0 | DA3: =CPP!T3 -> 0 | DB3: =CX3+CY3-CZ3-DA3 -> 0 | DC3: 7.11 | DD3: 0 | DE3: 7.1 | DF3: =CPP!U3 -> 0 | DG3: =DC3+DD3-DE3-DF3 -> 0.01 | DH3: 0 | DI3: 0 | DJ3: 0 | DK3: =CPP!V3 -> 0 | DL3: =DH3+DI3-DJ3-DK3 -> 0 | DM3: 212 | DN3: 30 | DO3: 0 | DP3: =CPP!W3 -> 0 | DQ3: =DM3+DN3-DO3-DP3 -> 242 | DR3: 2933.9 | DS3: 0 | DT3: 306.23 | DU3: =CPP!X3 -> 0 | DV3: =DR3+DS3-DT3-DU3 -> 2627.67 | DW3: 0 | DX3: 0 | DY3: 0 | DZ3: =CPP!Y3 -> 0 | EA3: =DW3+DX3-DY3-DZ3 -> 0 | EB3: =L3+AP3+AU3+AZ3+BE3+BJ3+BT3+BY3+CD3+CI3+CS3+CX3+DC3+DH3+DM3+DW3+X3+DR3 -> 4628.087 | EC3: =M3+Y3+AM3+AQ3+AV3+BA3+BF3+BK3+BP3+BU3+BZ3+CT3+CY3+DD3+DI3+DN3+DX3+DS3 -> 151.76 | ED3: =O3+AA3+AN3+AR3+AW3+BB3+BG3+BL3+BQ3+BV3+CA3+CU3+CZ3+DE3+DJ3+DO3+DY3+DT3 -> 313.33 | EE3: =EB3+EC3-ED3-N3-Z3-AS3-AX3-BC3-BH3-BM3-BR3-BW3-CV3-DA3-DF3-DK3-DP3-DZ3-DU3 -> 4466.517 | EF3: =R3+AC3+AG3+AL3+CN3 -> 4048.72 | EG3: =S3+AD3+AH3+CE3+CJ3+CO3 -> 272.05 | EH3: =CPP!D3+CPP!E3+CPP!F3+CPP!G3+CPP!H3+CPP!I3+CPP!J3+CPP!K3+CPP!L3+CPP!M3+CPP!N3+CPP!O3+CPP!P3+CPP!Q3+CPP!R3+CPP!S3+DA3+DF3+DK3+CPP!W3+DU3 -> 156 | EI3: =EF3+EG3-CPP!G3-CPP!E3-CPP!F3-CPP!P3-CPP!Q3-CL3-CQ3-DU3 -> 4164.77 | EJ3: 25945.809 | EK3: 1970 | EL3: ='Daily CEM-1'!AG4+'Daily CEM - 2'!AF4-EQ3 -> 1611.34 | EM3: =EJ3+EK3-EL3-EN3 -> 26304.469 | EN3: 0 | EO3: 5306.109 | EP3: 0 | EQ3: 0 | ER3: =EO3+EP3-EQ3 -> 5306.109 | ES3: =ET3-EP3 -> 1722.57 | ET3: 1722.57 | EU3: =EL3+EQ3 -> 1611.34 | EV3: =EL3+EQ3 -> 1611.34 | EW3: =(EU3/Production2!CG3)*100 -> 79.887952 | EX3: 74.814815 | EY3: =EX3*100 -> 7481.4815
B4: 2 | C4: =G3 -> 2595.92 | D4: 0 | E4: =F4+'RAW MILL 2'!F4 -> 49 | F4: 44 | G4: =C4+D4-E4 -> 2546.92 | H4: =K3 -> 1325.2 | I4: =Production2!N4+Production2!Q4 -> 1778.97 | J4: =Production2!K4 -> 2503.25 | K4: =H4+I4-J4 -> 600.92002 | L4: =Q3 -> 0 | M4: 0 | N4: =CPP!D4 -> 0 | O4: 0 | P4: =N4+O4 -> 0 | Q4: =L4+M4-O4-N4 -> 0 | R4: =W3 -> 0 | S4: 0 | T4: =CPP!E4 -> 0 | U4: 0 | V4: =T4+U4 -> 0 | W4: =R4+S4-V4 -> 0 | X4: =AB3 -> 1063.04 | Y4: 0 | Z4: =CPP!H4 -> 0 | AA4: 0 | AB4: =X4+Y4-AA4-Z4 -> 1063.04 | AC4: =AF3 -> 0 | AD4: 0 | AE4: 0 | AF4: =AC4+AD4-AE4 -> 0 | AG4: =AK3 -> 4164.72 | AH4: 150.1 | AI4: 0 | AJ4: =CPP!G4 -> 130 | AK4: =AG4+AH4-AJ4 -> 4184.82 | AL4: =AO3 -> 0 | AM4: 0 | AN4: 0 | AO4: =AL4+AM4-AN4 -> 0 | AP4: =AT3 -> 0 | AQ4: 0 | AR4: 0 | AS4: =CPP!I4 -> 0 | AT4: =AP4+AQ4-AR4-AS4 -> 0 | AU4: =AY3 -> 0 | AV4: 0 | AW4: 0 | AX4: =CPP!J4 -> 0 | AY4: =AU4+AV4-AW4-AX4 -> 0 | AZ4: =BD3 -> 533.787 | BA4: 156.98 | BB4: 0 | BC4: =CPP!K4 -> 0 | BD4: =AZ4+BA4-BB4-BC4 -> 690.767 | BE4: =BI3 -> 0 | BF4: 0 | BG4: 0 | BH4: =CPP!L4 -> 0 | BI4: =BE4+BF4-BG4-BH4 -> 0 | BJ4: =BN3 -> 0 | BK4: 0 | BL4: 0 | BM4: =CPP!M4 -> 0 | BN4: =BJ4+BK4-BL4-BM4 -> 0 | BO4: =BS3 -> 0 | BP4: 0 | BQ4: 0 | BR4: =CPP!N4 -> 0 | BS4: =BO4+BP4-BQ4-BR4 -> 0 | BT4: =BX3 -> 0 | BU4: 0 | BV4: 0 | BW4: =CPP!O4 -> 0 | BX4: =BT4+BU4-BV4-BW4 -> 0 | BY4: =CC3 -> 0 | BZ4: 0 | CA4: 0 | CC4: =BY4+BZ4-CA4-CB4 -> 0 | CD4: =CH3 -> 0 | CE4: 0 | CF4: 0 | CG4: =CPP!P4 -> 0 | CH4: =CD4+CE4-CF4-CG4 -> 0 | CI4: =CM3 -> 0 | CJ4: 0 | CK4: 0 | CL4: =CPP!Q4 -> 0 | CM4: =CI4+CJ4-CK4-CL4 -> 0 | CN4: =CR3 -> 0.05 | CO4: 0 | CP4: 0 | CQ4: =CPP!R4 -> 0 | CR4: =CN4+CO4-CP4-CQ4 -> 0.05 | CS4: =CW3 -> 0 | CT4: 0 | CU4: 0 | CV4: =CPP!S4 -> 0 | CW4: =CS4+CT4-CU4-CV4 -> 0 | CX4: =DB3 -> 0 | CY4: 0 | CZ4: 0 | DA4: =CPP!T4 -> 0 | DB4: =CX4+CY4-CZ4-DA4 -> 0 | DC4: =DG3 -> 0.01 | DD4: 0 | DE4: 0 | DF4: =CPP!U4 -> 0 | DG4: =DC4+DD4-DE4-DF4 -> 0.01 | DH4: =DL3 -> 0 | DI4: 0 | DJ4: 0 | DK4: =CPP!V4 -> 0 | DL4: =DH4+DI4-DJ4-DK4 -> 0 | DM4: =DQ3 -> 242 | DN4: 30 | DO4: 0 | DP4: =CPP!W4 -> 0 | DQ4: =DM4+DN4-DO4-DP4 -> 272 | DR4: =DV3 -> 2627.67 | DS4: 0 | DT4: 277.78 | DU4: =CPP!X4 -> 0 | DV4: =DR4+DS4-DT4-DU4 -> 2349.89 | DW4: =EA3 -> 0 | DX4: 0 | DY4: 0 | DZ4: =CPP!Y4 -> 0 | EA4: =DW4+DX4-DY4-DZ4 -> 0 | EB4: =L4+AP4+AU4+AZ4+BE4+BJ4+BT4+BY4+CD4+CI4+CS4+CX4+DC4+DH4+DM4+DW4+X4+DR4 -> 4466.507 | EC4: =M4+Y4+AM4+AQ4+AV4+BA4+BF4+BK4+BP4+BU4+BZ4+CT4+CY4+DD4+DI4+DN4+DX4+DS4 -> 186.98 | ED4: =O4+AA4+AN4+AR4+AW4+BB4+BG4+BL4+BQ4+BV4+CA4+CU4+CZ4+DE4+DJ4+DO4+DY4+DT4 -> 277.78 | EE4: =EB4+EC4-ED4-N4-Z4-AS4-AX4-BC4-BH4-BM4-BR4-BW4-CV4-DA4-DF4-DK4-DP4-DZ4-DU4 -> 4375.707 | EF4: =R4+AC4+AG4+AL4+CN4 -> 4164.77 | EG4: =S4+AD4+AH4+CE4+CJ4+CO4 -> 150.1 | EH4: =CPP!D4+CPP!E4+CPP!F4+CPP!G4+CPP!H4+CPP!I4+CPP!J4+CPP!K4+CPP!L4+CPP!M4+CPP!N4+CPP!O4+CPP!P4+CPP!Q4+CPP!R4+CPP!S4+DA4+DF4+DK4+CPP!W4+DU4 -> 130 | EI4: =EF4+EG4-CPP!G4-CPP!E4-CPP!F4-CPP!P4-CPP!Q4-CL4-CQ4-DU4 -> 4184.87 | EJ4: =EM3 -> 26304.469 | EK4: 1615 | EL4: ='Daily CEM-1'!AG5+'Daily CEM - 2'!AF5-EQ4 -> 1783.008 | EM4: =EJ4+EK4-EL4-EN4 -> 26136.461 | EN4: 0 | EO4: =ER3 -> 5306.109 | EP4: 0 | EQ4: 0 | ER4: =EO4+EP4-EQ4 -> 5306.109 | ES4: =ET4-EP4 -> 1171.1 | ET4: 1171.1 | EU4: =EL4+EQ4 -> 1783.008 | EV4: =EL4+EQ4 -> 1783.008 | EW4: =(EU4/Production2!CG4)*100 -> 78.442939 | EX4: 73.844178 | EY4: =EX4*100 -> 7384.4178
B5: 3 | C5: =G4 -> 2546.92 | D5: 0 | E5: =F5+'RAW MILL 2'!F5 -> 67 | F5: 62 | G5: =C5+D5-E5 -> 2479.92 | H5: =K4 -> 600.92002 | I5: =Production2!N5+Production2!Q5 -> 2411.31 | J5: =Production2!K5 -> 2182.4 | K5: =H5+I5-J5 -> 829.83002 | L5: =Q4 -> 0 | M5: 0 | N5: =CPP!D5 -> 0 | O5: 0 | P5: =N5+O5 -> 0 | Q5: =L5+M5-O5-N5 -> 0 | R5: =W4 -> 0 | S5: 0 | T5: =CPP!E5 -> 0 | U5: 0 | V5: =T5+U5 -> 0 | W5: =R5+S5-V5 -> 0 | X5: =AB4 -> 1063.04 | Y5: 0 | Z5: =CPP!H5 -> 0 | AA5: 0 | AB5: =X5+Y5-AA5-Z5 -> 1063.04 | AC5: =AF4 -> 0 | AD5: 0 | AE5: 0 | AF5: =AC5+AD5-AE5 -> 0 | AG5: =AK4 -> 4184.82 | AH5: 397.15 | AI5: 0 | AJ5: =CPP!G5 -> 138 | AK5: =AG5+AH5-AJ5 -> 4443.97 | AL5: =AO4 -> 0 | AM5: 0 | AN5: 0 | AO5: =AL5+AM5-AN5 -> 0 | AP5: =AT4 -> 0 | AQ5: 0 | AR5: 0 | AS5: =CPP!I5 -> 0 | AT5: =AP5+AQ5-AR5-AS5 -> 0 | AU5: =AY4 -> 0 | AV5: 0 | AW5: 0 | AX5: =CPP!J5 -> 0 | AY5: =AU5+AV5-AW5-AX5 -> 0 | AZ5: =BD4 -> 690.767 | BA5: 221.94 | BB5: 0 | BC5: =CPP!K5 -> 0 | BD5: =AZ5+BA5-BB5-BC5 -> 912.707 | BE5: =BI4 -> 0 | BF5: 0 | BG5: 0 | BH5: =CPP!L5 -> 0 | BI5: =BE5+BF5-BG5-BH5 -> 0 | BJ5: =BN4 -> 0 | BK5: 0 | BL5: 0 | BM5: =CPP!M5 -> 0 | BN5: =BJ5+BK5-BL5-BM5 -> 0 | BO5: =BS4 -> 0 | BP5: 0 | BQ5: 0 | BR5: =CPP!N5 -> 0 | BS5: =BO5+BP5-BQ5-BR5 -> 0 | BT5: =BX4 -> 0 | BU5: 0 | BV5: 0 | BW5: =CPP!O5 -> 0 | BX5: =BT5+BU5-BV5-BW5 -> 0 | BY5: =CC4 -> 0 | BZ5: 0 | CA5: 0 | CC5: =BY5+BZ5-CA5-CB5 -> 0 | CD5: =CH4 -> 0 | CE5: 0 | CF5: 0 | CG5: =CPP!P5 -> 0 | CH5: =CD5+CE5-CF5-CG5 -> 0 | CI5: =CM4 -> 0 | CJ5: 0 | CK5: 0 | CL5: =CPP!Q5 -> 0 | CM5: =CI5+CJ5-CK5-CL5 -> 0 | CN5: =CR4 -> 0.05 | CO5: 0 | CP5: 0 | CQ5: =CPP!R5 -> 0 | CR5: =CN5+CO5-CP5-CQ5 -> 0.05 | CS5: =CW4 -> 0 | CT5: 0 | CU5: 0 | CV5: =CPP!S5 -> 0 | CW5: =CS5+CT5-CU5-CV5 -> 0 | CX5: =DB4 -> 0 | CY5: 0 | CZ5: 0 | DA5: =CPP!T5 -> 0 | DB5: =CX5+CY5-CZ5-DA5 -> 0 | DC5: =DG4 -> 0.01 | DD5: 0 | DE5: 0 | DF5: =CPP!U5 -> 0 | DG5: =DC5+DD5-DE5-DF5 -> 0.01 | DH5: =DL4 -> 0 | DI5: 0 | DJ5: 0 | DK5: =CPP!V5 -> 0 | DL5: =DH5+DI5-DJ5-DK5 -> 0 | DM5: =DQ4 -> 272 | DN5: 0 | DO5: 0 | DP5: =CPP!W5 -> 0 | DQ5: =DM5+DN5-DO5-DP5 -> 272 | DR5: =DV4 -> 2349.89 | DS5: 0 | DT5: 239 | DU5: =CPP!X5 -> 0 | DV5: =DR5+DS5-DT5-DU5 -> 2110.89 | DW5: =EA4 -> 0 | DX5: 0 | DY5: 0 | DZ5: =CPP!Y5 -> 0 | EA5: =DW5+DX5-DY5-DZ5 -> 0 | EB5: =L5+AP5+AU5+AZ5+BE5+BJ5+BT5+BY5+CD5+CI5+CS5+CX5+DC5+DH5+DM5+DW5+X5+DR5 -> 4375.707 | EC5: =M5+Y5+AM5+AQ5+AV5+BA5+BF5+BK5+BP5+BU5+BZ5+CT5+CY5+DD5+DI5+DN5+DX5+DS5 -> 221.94 | ED5: =O5+AA5+AN5+AR5+AW5+BB5+BG5+BL5+BQ5+BV5+CA5+CU5+CZ5+DE5+DJ5+DO5+DY5+DT5 -> 239 | EE5: =EB5+EC5-ED5-N5-Z5-AS5-AX5-BC5-BH5-BM5-BR5-BW5-CV5-DA5-DF5-DK5-DP5-DZ5-DU5 -> 4358.647 | EF5: =R5+AC5+AG5+AL5+CN5 -> 4184.87 | EG5: =S5+AD5+AH5+CE5+CJ5+CO5 -> 397.15 | EH5: =CPP!D5+CPP!E5+CPP!F5+CPP!G5+CPP!H5+CPP!I5+CPP!J5+CPP!K5+CPP!L5+CPP!M5+CPP!N5+CPP!O5+CPP!P5+CPP!Q5+CPP!R5+CPP!S5+DA5+DF5+DK5+CPP!W5+DU5 -> 138 | EI5: =EF5+EG5-CPP!G5-CPP!E5-CPP!F5-CPP!P5-CPP!Q5-CL5-CQ5-DU5 -> 4444.02 | EJ5: =EM4 -> 26136.461 | EK5: 1408 | EL5: ='Daily CEM-1'!AG6+'Daily CEM - 2'!AF6-EQ5 -> 2274.24 | EM5: =EJ5+EK5-EL5-EN5 -> 25270.221 | EN5: 0 | EO5: =ER4 -> 5306.109 | EP5: 0 | EQ5: 0 | ER5: =EO5+EP5-EQ5 -> 5306.109 | ES5: =ET5-EP5 -> 1446.55 | ET5: 1446.55 | EU5: =EL5+EQ5 -> 2274.24 | EV5: =EL5+EQ5 -> 2274.24 | EW5: =(EU5/Production2!CG5)*100 -> 77.434116 | EX5: 78 | EY5: =EX5*100 -> 7800
B6: 4 | C6: =G5 -> 2479.92 | D6: 0 | E6: =F6+'RAW MILL 2'!F6 -> 82 | F6: 76 | G6: =C6+D6-E6 -> 2397.92 | H6: =K5 -> 829.83002 | I6: =Production2!N6+Production2!Q6 -> 2958.06 | J6: =Production2!K6 -> 2774.5 | K6: =H6+I6-J6 -> 1013.39 | L6: =Q5 -> 0 | M6: 0 | N6: =CPP!D6 -> 0 | O6: 0 | P6: =N6+O6 -> 0 | Q6: =L6+M6-O6-N6 -> 0 | R6: =W5 -> 0 | S6: 0 | T6: =CPP!E6 -> 0 | U6: 0 | V6: =T6+U6 -> 0 | W6: =R6+S6-V6 -> 0 | X6: =AB5 -> 1063.04 | Y6: 0 | Z6: =CPP!H6 -> 0 | AA6: 0 | AB6: =X6+Y6-AA6-Z6 -> 1063.04 | AC6: =AF5 -> 0 | AD6: 0 | AE6: 0 | AF6: =AC6+AD6-AE6 -> 0 | AG6: =AK5 -> 4443.97 | AH6: 120.2 | AI6: 0 | AJ6: =CPP!G6 -> 158 | AK6: =AG6+AH6-AJ6 -> 4406.17 | AL6: =AO5 -> 0 | AM6: 0 | AN6: 0 | AO6: =AL6+AM6-AN6 -> 0 | AP6: =AT5 -> 0 | AQ6: 0 | AR6: 0 | AS6: =CPP!I6 -> 0 | AT6: =AP6+AQ6-AR6-AS6 -> 0 | AU6: =AY5 -> 0 | AV6: 0 | AW6: 0 | AX6: =CPP!J6 -> 0 | AY6: =AU6+AV6-AW6-AX6 -> 0 | AZ6: =BD5 -> 912.707 | BA6: 92.16 | BB6: 0 | BC6: =CPP!K6 -> 0 | BD6: =AZ6+BA6-BB6-BC6 -> 1004.867 | BE6: =BI5 -> 0 | BF6: 0 | BG6: 0 | BH6: =CPP!L6 -> 0 | BI6: =BE6+BF6-BG6-BH6 -> 0 | BJ6: =BN5 -> 0 | BK6: 0 | BL6: 0 | BM6: =CPP!M6 -> 0 | BN6: =BJ6+BK6-BL6-BM6 -> 0 | BO6: =BS5 -> 0 | BP6: 0 | BQ6: 0 | BR6: =CPP!N6 -> 0 | BS6: =BO6+BP6-BQ6-BR6 -> 0 | BT6: =BX5 -> 0 | BU6: 0 | BV6: 0 | BW6: =CPP!O6 -> 0 | BX6: =BT6+BU6-BV6-BW6 -> 0 | BY6: =CC5 -> 0 | BZ6: 0 | CA6: 0 | CC6: =BY6+BZ6-CA6-CB6 -> 0 | CD6: =CH5 -> 0 | CE6: 0 | CF6: 0 | CG6: =CPP!P6 -> 0 | CH6: =CD6+CE6-CF6-CG6 -> 0 | CI6: =CM5 -> 0 | CJ6: 0 | CK6: 0 | CL6: =CPP!Q6 -> 0 | CM6: =CI6+CJ6-CK6-CL6 -> 0 | CN6: =CR5 -> 0.05 | CO6: 0 | CP6: 0 | CQ6: =CPP!R6 -> 0 | CR6: =CN6+CO6-CP6-CQ6 -> 0.05 | CS6: =CW5 -> 0 | CT6: 0 | CU6: 0 | CV6: =CPP!S6 -> 0 | CW6: =CS6+CT6-CU6-CV6 -> 0 | CX6: =DB5 -> 0 | CY6: 0 | CZ6: 0 | DA6: =CPP!T6 -> 0 | DB6: =CX6+CY6-CZ6-DA6 -> 0 | DC6: =DG5 -> 0.01 | DD6: 0 | DE6: 0 | DF6: =CPP!U6 -> 0 | DG6: =DC6+DD6-DE6-DF6 -> 0.01 | DH6: =DL5 -> 0 | DI6: 0 | DJ6: 0 | DK6: =CPP!V6 -> 0 | DL6: =DH6+DI6-DJ6-DK6 -> 0 | DM6: =DQ5 -> 272 | DN6: 32 | DO6: 0 | DP6: =CPP!W6 -> 0 | DQ6: =DM6+DN6-DO6-DP6 -> 304 | DR6: =DV5 -> 2110.89 | DS6: 0 | DT6: 316.67 | DU6: =CPP!X6 -> 0 | DV6: =DR6+DS6-DT6-DU6 -> 1794.22 | DW6: =EA5 -> 0 | DX6: 0 | DY6: 0 | DZ6: =CPP!Y6 -> 0 | EA6: =DW6+DX6-DY6-DZ6 -> 0 | EB6: =L6+AP6+AU6+AZ6+BE6+BJ6+BT6+BY6+CD6+CI6+CS6+CX6+DC6+DH6+DM6+DW6+X6+DR6 -> 4358.647 | EC6: =M6+Y6+AM6+AQ6+AV6+BA6+BF6+BK6+BP6+BU6+BZ6+CT6+CY6+DD6+DI6+DN6+DX6+DS6 -> 124.16 | ED6: =O6+AA6+AN6+AR6+AW6+BB6+BG6+BL6+BQ6+BV6+CA6+CU6+CZ6+DE6+DJ6+DO6+DY6+DT6 -> 316.67 | EE6: =EB6+EC6-ED6-N6-Z6-AS6-AX6-BC6-BH6-BM6-BR6-BW6-CV6-DA6-DF6-DK6-DP6-DZ6-DU6 -> 4166.137 | EF6: =R6+AC6+AG6+AL6+CN6 -> 4444.02 | EG6: =S6+AD6+AH6+CE6+CJ6+CO6 -> 120.2 | EH6: =CPP!D6+CPP!E6+CPP!F6+CPP!G6+CPP!H6+CPP!I6+CPP!J6+CPP!K6+CPP!L6+CPP!M6+CPP!N6+CPP!O6+CPP!P6+CPP!Q6+CPP!R6+CPP!S6+DA6+DF6+DK6+CPP!W6+DU6 -> 158 | EI6: =EF6+EG6-CPP!G6-CPP!E6-CPP!F6-CPP!P6-CPP!Q6-CL6-CQ6-DU6 -> 4406.22 | EJ6: =EM5 -> 25270.221 | EK6: 1790 | EL6: ='Daily CEM-1'!AG7+'Daily CEM - 2'!AF7-EQ6 -> 2000.12 | EM6: =EJ6+EK6-EL6-EN6 -> 25060.101 | EN6: 0 | EO6: =ER5 -> 5306.109 | EP6: 0 | EQ6: 0 | ER6: =EO6+EP6-EQ6 -> 5306.109 | ES6: =ET6-EP6 -> 1500.29 | ET6: 1500.29 | EU6: =EL6+EQ6 -> 2000.12 | EV6: =EL6+EQ6 -> 2000.12 | EW6: =(EU6/Production2!CG6)*100 -> 77.344161 | EX6: 79 | EY6: =EX6*100 -> 7900
