Workbook

Sheet Sheet5
A1: Crusher | B1: 45414 | C1: MTD | E1: TODATE FIGURE | F1: MTD FIGURE | AL1: 45413 | AM1: =AL1+1 -> 45414 | AN1: =AM1+1 -> 45415 | AO1: =AN1+1 -> 45416 | AP1: =AO1+1 -> 45417 | AQ1: =AP1+1 -> 45418 | AR1: =AQ1+1 -> 45419 | AS1: =AR1+1 -> 45420 | AT1: =AS1+1 -> 45421 | ... BP1: =BO1+1 -> 45443 | BQ1: MTD
A2: 211IC1 | B2: 163 | C2: =BQ2 -> 373 | D2: CRUSHER | E2: 2618.9 | F2: =AJ13 -> 5020.16 | AL2: 210 | AM2: 163 | AN2: 0 | AO2: 0 | AP2: 0 | AQ2: 0 | AR2: 0 | AS2: 0 | AT2: 0 | AU2: 0 | AV2: 0 | AW2: 0 | AX2: 0 | AY2: 0 | AZ2: 0 | BA2: 0 | BB2: 0 | BC2: 0 | BD2: 0 | BE2: 0 | BF2: 0 | BG2: 0 | BH2: 0 | BI2: 0 | BJ2: 0 | BK2: 0 | BL2: 0 | BM2: 0 | BN2: 0 | BO2: 0 | BP2: 0 | BQ2: =SUM(AL2:BP2) -> 373
A3: CRUSHER AUXILIRIES(IPMCC-1)-TR3 | B3: =4660-B4-B6-B7 -> 2099 | C3: =BQ3 -> 3217 | D3: RAW MILL | E3: 1793 | F3: =AJ14 -> 3418 | AL3: =3633-AL4-AL6-AL7 -> 1118 | AM3: =4660-AM4-AM6-AM7 -> 2099 | AN3: =0-AN4-AN6-AN7 -> 0 | AO3: =0-AO4-AO6-AO7 -> 0 | AP3: =0-AP4-AP6-AP7 -> 0 | AQ3: =0-AQ4-AQ6-AQ7 -> 0 | AR3: =0-AR4-AR6-AR7 -> 0 | AS3: =0-AS4-AS6-AS7 -> 0 | AT3: =0-AT4-AT6-AT7 -> 0 | AU3: =0-AU4-AU6-AU7 -> 0 | ... BP3: =0-BP4-BP6-BP7 -> 0 | BQ3: =SUM(AL3:BP3) -> 3217
A4: COLONY (TENESCO from LC-1) | B4: 2229 | C4: =BQ4 -> 4465 | D4: COAL MILL | E4: 179 | F4: =AJ15 -> 334 | AL4: 2236 | AM4: 2229 | AN4: 0 | AO4: 0 | AP4: 0 | AQ4: 0 | AR4: 0 | AS4: 0 | AT4: 0 | AU4: 0 | AV4: 0 | AW4: 0 | AX4: 0 | AY4: 0 | AZ4: 0 | BA4: 0 | BB4: 0 | BC4: 0 | BD4: 0 | BE4: 0 | BF4: 0 | BG4: 0 | BH4: 0 | BI4: 0 | BJ4: 0 | BK4: 0 | BL4: 0 | BM4: 0 | BN4: 0 | BO4: 0 | BP4: 0 | BQ4: =SUM(AL4:BP4) -> 4465
A5: STACKER(IMCC1) | B5: 217 | C5: =BQ5 -> 429 | D5: KILN | E5: 1077 | F5: =AJ16 -> 1913 | AL5: 212 | AM5: 217 | AN5: 0 | AO5: 0 | AP5: 0 | AQ5: 0 | AR5: 0 | AS5: 0 | AT5: 0 | AU5: 0 | AV5: 0 | AW5: 0 | AX5: 0 | AY5: 0 | AZ5: 0 | BA5: 0 | BB5: 0 | BC5: 0 | BD5: 0 | BE5: 0 | BF5: 0 | BG5: 0 | BH5: 0 | BI5: 0 | BJ5: 0 | BK5: 0 | BL5: 0 | BM5: 0 | BN5: 0 | BO5: 0 | BP5: 0 | BQ5: =SUM(AL5:BP5) -> 429
A6: LC-1 LIGHTING | B6: 107 | C6: =BQ6 -> 216 | D6: CEMENT MILL-1 | E6: 0 | F6: =AJ17 -> 0 | AL6: 109 | AM6: 107 | AN6: 0 | AO6: 0 | AP6: 0 | AQ6: 0 | AR6: 0 | AS6: 0 | AT6: 0 | AU6: 0 | AV6: 0 | AW6: 0 | AX6: 0 | AY6: 0 | AZ6: 0 | BA6: 0 | BB6: 0 | BC6: 0 | BD6: 0 | BE6: 0 | BF6: 0 | BG6: 0 | BH6: 0 | BI6: 0 | BJ6: 0 | BK6: 0 | BL6: 0 | BM6: 0 | BN6: 0 | BO6: 0 | BP6: 0 | BQ6: =SUM(AL6:BP6) -> 216
A7: Welding DB + A/C | B7: 225 | C7: =BQ7 -> 395 | D7: CEMENT MILL-2 | E7: 0 | F7: =AJ18 -> 1125 | AL7: 170 | AM7: 225 | AN7: 0 | AO7: 0 | AP7: 0 | AQ7: 0 | AR7: 0 | AS7: 0 | AT7: 0 | AU7: 0 | AV7: 0 | AW7: 0 | AX7: 0 | AY7: 0 | AZ7: 0 | BA7: 0 | BB7: 0 | BC7: 0 | BD7: 0 | BE7: 0 | BF7: 0 | BG7: 0 | BH7: 0 | BI7: 0 | BJ7: 0 | BK7: 0 | BL7: 0 | BM7: 0 | BN7: 0 | BO7: 0 | BP7: 0 | BQ7: =SUM(AL7:BP7) -> 395
A8: Rawmill | C8: =BQ8 -> 0 | D8: PACKING PLANT-1 | E8: 183.96 | F8: =AJ19 -> 446.46 | BQ8: =SUM(AL8:BP8) -> 0
A9: 321RM1 | B9: 15836 | C9: =BQ9 -> 26922 | D9: PACKING PLANT-2 | E9: 0 | F9: =AJ20 -> 0 | AL9: 11086 | AM9: 15836 | AN9: 0 | AO9: 0 | AP9: 0 | AQ9: 0 | AR9: 0 | AS9: 0 | AT9: 0 | AU9: 0 | AV9: 0 | AW9: 0 | AX9: 0 | AY9: 0 | AZ9: 0 | BA9: 0 | BB9: 0 | BC9: 0 | BD9: 0 | BE9: 0 | BF9: 0 | BG9: 0 | BH9: 0 | BI9: 0 | BJ9: 0 | BK9: 0 | BL9: 0 | BM9: 0 | BN9: 0 | BO9: 0 | BP9: 0 | BQ9: =SUM(AL9:BP9) -> 26922
A10: 321FN3-TR1 | B10: 15308 | C10: =BQ10 -> 27064 | AL10: 11756 | AM10: 15308 | AN10: 0 | AO10: 0 | AP10: 0 | AQ10: 0 | AR10: 0 | AS10: 0 | AT10: 0 | AU10: 0 | AV10: 0 | AW10: 0 | AX10: 0 | AY10: 0 | AZ10: 0 | BA10: 0 | BB10: 0 | BC10: 0 | BD10: 0 | BE10: 0 | BF10: 0 | BG10: 0 | BH10: 0 | BI10: 0 | BJ10: 0 | BK10: 0 | BL10: 0 | BM10: 0 | BN10: 0 | BO10: 0 | BP10: 0 | BQ10: =SUM(AL10:BP10) -> 27064
A11: IMCC-3 | B11: =7292-B12 -> 6397 | C11: =BQ11 -> 12336 | E11: 45413 | F11: 45414 | G11: 45415 | H11: 45416 | I11: 45417 | J11: 45418 | K11: 45419 | L11: 45420 | M11: 45421 | N11: 45422 | O11: 45423 | P11: 45424 | Q11: 45425 | R11: 45426 | S11: 45427 | T11: 45428 | U11: 45429 | V11: 45430 | W11: 45431 | X11: 45432 | Y11: 45433 | Z11: 45434 | AA11: 45435 | AB11: 45436 | AC11: 45437 | AD11: 45438 | AE11: 45439 | AF11: 45440 | AG11: 45441 | AH11: 45442 | AI11: 45443 | AL11: =6921-AL12 -> 5939 | AM11: =7292-AM12 -> 6397 | AN11: =0-AN12 -> 0 | AO11: =0-AO12 -> 0 | AP11: =0-AP12 -> 0 | AQ11: =0-AQ12 -> 0 | AR11: =0-AR12 -> 0 | AS11: =0-AS12 -> 0 | AT11: =0-AT12 -> 0 | AU11: =0-AU12 -> 0 | ... BP11: =0-BP12 -> 0 | BQ11: =SUM(AL11:BP11) -> 12336
A12: IMCC-2/RECLAIMER | B12: 895 | C12: =BQ12 -> 1877 | D12: SPECIFICATION | E12: PRODUCTION (MT) | F12: PRODUCTION (MT) | G12: PRODUCTION (MT) | H12: PRODUCTION (MT) | I12: PRODUCTION (MT) | J12: PRODUCTION (MT) | K12: PRODUCTION (MT) | L12: PRODUCTION (MT) | M12: PRODUCTION (MT) | N12: PRODUCTION (MT) | O12: PRODUCTION (MT) | P12: PRODUCTION (MT) | Q12: PRODUCTION (MT) | R12: PRODUCTION (MT) | S12: PRODUCTION (MT) | T12: PRODUCTION (MT) | U12: PRODUCTION (MT) | V12: PRODUCTION (MT) | W12: PRODUCTION (MT) | X12: PRODUCTION (MT) | Y12: PRODUCTION (MT) | Z12: PRODUCTION (MT) | AA12: PRODUCTION (MT) | AB12: PRODUCTION (MT) | AC12: PRODUCTION (MT) | AD12: PRODUCTION (MT) | AE12: PRODUCTION (MT) | AF12: PRODUCTION (MT) | AG12: PRODUCTION (MT) | AH12: PRODUCTION (MT) | AI12: PRODUCTION (MT) | AL12: 982 | AM12: 895 | AN12: 0 | AO12: 0 | AP12: 0 | AQ12: 0 | AR12: 0 | AS12: 0 | AT12: 0 | AU12: 0 | AV12: 0 | AW12: 0 | AX12: 0 | AY12: 0 | AZ12: 0 | BA12: 0 | BB12: 0 | BC12: 0 | BD12: 0 | BE12: 0 | BF12: 0 | BG12: 0 | BH12: 0 | BI12: 0 | BJ12: 0 | BK12: 0 | BL12: 0 | BM12: 0 | BN12: 0 | BO12: 0 | BP12: 0 | BQ12: =SUM(AL12:BP12) -> 1877
A13: TR-5(IPMCC-2 = BAGHOUSE FAN +BAG HOUSE AUX.+COMPRESSOR -3 (321CP3)- WORKSHOP) | B13: =8430-B68 -> 7956 | C13: =BQ13 -> 15730 | D13: CRUSHER | E13: 2401.26 | F13: 2618.9 | AJ13: =SUM(E13:AI13) -> 5020.16 | AL13: =8273-AL68 -> 7774 | AM13: =8430-AM68 -> 7956 | AN13: =0-AN68 -> 0 | AO13: =0-AO68 -> 0 | AP13: =0-AP68 -> 0 | AQ13: =0-AQ68 -> 0 | AR13: =0-AR68 -> 0 | AS13: =0-AS68 -> 0 | AT13: =0-AT68 -> 0 | AU13: =0-AU68 -> 0 | ... BP13: =0-BP68 -> 0 | BQ13: =SUM(AL13:BP13) -> 15730
A14: COMPRESSOR-1(PCC-1@321CP1) | B14: 0 | C14: =BQ14 -> 0 | D14: RAW MILL | E14: 1625 | F14: 1793 | AJ14: =SUM(E14:AI14) -> 3418 | AL14: 0 | AM14: 0 | AN14: 0 | AO14: 0 | AP14: 0 | AQ14: 0 | AR14: 0 | AS14: 0 | AT14: 0 | AU14: 0 | AV14: 0 | AW14: 0 | AX14: 0 | AY14: 0 | AZ14: 0 | BA14: 0 | BB14: 0 | BC14: 0 | BD14: 0 | BE14: 0 | BF14: 0 | BG14: 0 | BH14: 0 | BI14: 0 | BJ14: 0 | BK14: 0 | BL14: 0 | BM14: 0 | BN14: 0 | BO14: 0 | BP14: 0 | BQ14: =SUM(AL14:BP14) -> 0
A15: Welding DB + A/C | B15: 130 | C15: =BQ15 -> 270 | D15: COAL MILL | E15: 155 | F15: 179 | AJ15: =SUM(E15:AI15) -> 334 | AL15: 140 | AM15: 130 | AN15: 0 | AO15: 0 | AP15: 0 | AQ15: 0 | AR15: 0 | AS15: 0 | AT15: 0 | AU15: 0 | AV15: 0 | AW15: 0 | AX15: 0 | AY15: 0 | AZ15: 0 | BA15: 0 | BB15: 0 | BC15: 0 | BD15: 0 | BE15: 0 | BF15: 0 | BG15: 0 | BH15: 0 | BI15: 0 | BJ15: 0 | BK15: 0 | BL15: 0 | BM15: 0 | BN15: 0 | BO15: 0 | BP15: 0 | BQ15: =SUM(AL15:BP15) -> 270
A16: COAL MILL | C16: =BQ16 -> 0 | D16: KILN | E16: 836 | F16: 1077 | AJ16: =SUM(E16:AI16) -> 1913 | BQ16: =SUM(AL16:BP16) -> 0
A17: 521CM1 | B17: 4996 | C17: =BQ17 -> 9664 | D17: CEMENT MILL-1 | E17: 0 | F17: 0 | AJ17: =SUM(E17:AI17) -> 0 | AL17: 4668 | AM17: 4996 | AN17: 0 | AO17: 0 | AP17: 0 | AQ17: 0 | AR17: 0 | AS17: 0 | AT17: 0 | AU17: 0 | AV17: 0 | AW17: 0 | AX17: 0 | AY17: 0 | AZ17: 0 | BA17: 0 | BB17: 0 | BC17: 0 | BD17: 0 | BE17: 0 | BF17: 0 | BG17: 0 | BH17: 0 | BI17: 0 | BJ17: 0 | BK17: 0 | BL17: 0 | BM17: 0 | BN17: 0 | BO17: 0 | BP17: 0 | BQ17: =SUM(AL17:BP17) -> 9664
A18: COAL MILL AUXILIRIES-IPMCC4(TR8) | B18: =7430-B19-B20-B21-B62-B65 -> 5106.4 | C18: =BQ18 -> 9855.3 | D18: CEMENT MILL-2 | E18: 1125 | F18: 0 | AJ18: =SUM(E18:AI18) -> 1125 | AL18: =6943-AL19-AL20-AL21-AL62-AL65 -> 4748.9 | AM18: =7430-AM19-AM20-AM21-AM62-AM65 -> 5106.4 | AN18: =0-AN19-AN20-AN21-AN62-AN65 -> 0 | AO18: =0-AO19-AO20-AO21-AO62-AO65 -> 0 | AP18: =0-AP19-AP20-AP21-AP62-AP65 -> 0 | AQ18: =0-AQ19-AQ20-AQ21-AQ62-AQ65 -> 0 | AR18: =0-AR19-AR20-AR21-AR62-AR65 -> 0 | AS18: =0-AS19-AS20-AS21-AS62-AS65 -> 0 | AT18: =0-AT19-AT20-AT21-AT62-AT65 -> 0 | AU18: =0-AU19-AU20-AU21-AU62-AU65 -> 0 | ... BP18: =0-BP19-BP20-BP21-BP62-BP65 -> 0 | BQ18: =SUM(AL18:BP18) -> 9855.3
A19: WELDING SUPPLY COAL MILL & KILN | B19: 168 | C19: =BQ19 -> 348 | D19: PACKING PLANT-1 | E19: 262.5 | F19: 183.96 | AJ19: =SUM(E19:AI19) -> 446.46 | AL19: 180 | AM19: 168 | AN19: 0 | AO19: 0 | AP19: 0 | AQ19: 0 | AR19: 0 | AS19: 0 | AT19: 0 | AU19: 0 | AV19: 0 | AW19: 0 | AX19: 0 | AY19: 0 | AZ19: 0 | BA19: 0 | BB19: 0 | BC19: 0 | BD19: 0 | BE19: 0 | BF19: 0 | BG19: 0 | BH19: 0 | BI19: 0 | BJ19: 0 | BK19: 0 | BL19: 0 | BM19: 0 | BN19: 0 | BO19: 0 | BP19: 0 | BQ19: =SUM(AL19:BP19) -> 348
A20: A/C Supply LC-3 | B20: 50 | C20: =BQ20 -> 100 | D20: PACKING PLANT-2 | E20: 0 | F20: 0 | AJ20: =SUM(E20:AI20) -> 0 | AL20: 50 | AM20: 50 | AN20: 0 | AO20: 0 | AP20: 0 | AQ20: 0 | AR20: 0 | AS20: 0 | AT20: 0 | AU20: 0 | AV20: 0 | AW20: 0 | AX20: 0 | AY20: 0 | AZ20: 0 | BA20: 0 | BB20: 0 | BC20: 0 | BD20: 0 | BE20: 0 | BF20: 0 | BG20: 0 | BH20: 0 | BI20: 0 | BJ20: 0 | BK20: 0 | BL20: 0 | BM20: 0 | BN20: 0 | BO20: 0 | BP20: 0 | BQ20: =SUM(AL20:BP20) -> 100
A21: Supply for CCR | B21: 1038 | C21: =BQ21 -> 1856 | AL21: 818 | AM21: 1038 | AN21: 0 | AO21: 0 | AP21: 0 | AQ21: 0 | AR21: 0 | AS21: 0 | AT21: 0 | AU21: 0 | AV21: 0 | AW21: 0 | AX21: 0 | AY21: 0 | AZ21: 0 | BA21: 0 | BB21: 0 | BC21: 0 | BD21: 0 | BE21: 0 | BF21: 0 | BG21: 0 | BH21: 0 | BI21: 0 | BJ21: 0 | BK21: 0 | BL21: 0 | BM21: 0 | BN21: 0 | BO21: 0 | BP21: 0 | BQ21: =SUM(AL21:BP21) -> 1856
A22: KILN | C22: =BQ22 -> 0 | BQ22: =SUM(AL22:BP22) -> 0
A23: PRE-HEATER FAN(TR2) | B23: 10706 | C23: =BQ23 -> 18631 | AL23: 7925 | AM23: 10706 | AN23: 0 | AO23: 0 | AP23: 0 | AQ23: 0 | AR23: 0 | AS23: 0 | AT23: 0 | AU23: 0 | AV23: 0 | AW23: 0 | AX23: 0 | AY23: 0 | AZ23: 0 | BA23: 0 | BB23: 0 | BC23: 0 | BD23: 0 | BE23: 0 | BF23: 0 | BG23: 0 | BH23: 0 | BI23: 0 | BJ23: 0 | BK23: 0 | BL23: 0 | BM23: 0 | BN23: 0 | BO23: 0 | BP23: 0 | BQ23: =SUM(AL23:BP23) -> 18631
A24: IMCC-4 | B24: 4857 | C24: =BQ24 -> 9272 | AL24: 4415 | AM24: 4857 | AN24: 0 | AO24: 0 | AP24: 0 | AQ24: 0 | AR24: 0 | AS24: 0 | AT24: 0 | AU24: 0 | AV24: 0 | AW24: 0 | AX24: 0 | AY24: 0 | AZ24: 0 | BA24: 0 | BB24: 0 | BC24: 0 | BD24: 0 | BE24: 0 | BF24: 0 | BG24: 0 | BH24: 0 | BI24: 0 | BJ24: 0 | BK24: 0 | BL24: 0 | BM24: 0 | BN24: 0 | BO24: 0 | BP24: 0 | BQ24: =SUM(AL24:BP24) -> 9272
A25: BOOSTER FAN | B25: 0 | C25: =BQ25 -> 0 | AL25: 0 | AM25: 0 | AN25: 0 | AO25: 0 | AP25: 0 | AQ25: 0 | AR25: 0 | AS25: 0 | AT25: 0 | AU25: 0 | AV25: 0 | AW25: 0 | AX25: 0 | AY25: 0 | AZ25: 0 | BA25: 0 | BB25: 0 | BC25: 0 | BD25: 0 | BE25: 0 | BF25: 0 | BG25: 0 | BH25: 0 | BI25: 0 | BJ25: 0 | BK25: 0 | BL25: 0 | BM25: 0 | BN25: 0 | BO25: 0 | BP25: 0 | BQ25: =SUM(AL25:BP25) -> 0
A26: COOLER DRIVES(IPMCC-3)(TR7) | B26: =5730-B66 -> 5730 | C26: =BQ26 -> 10032 | AL26: =4302-AL66 -> 4302 | AM26: =5730-AM66 -> 5730 | AN26: =0-AN66 -> 0 | AO26: =0-AO66 -> 0 | AP26: =0-AP66 -> 0 | AQ26: =0-AQ66 -> 0 | AR26: =0-AR66 -> 0 | AS26: =0-AS66 -> 0 | AT26: =0-AT66 -> 0 | AU26: =0-AU66 -> 0 | ... BP26: =0-BP66 -> 0 | BQ26: =SUM(AL26:BP26) -> 10032
A27: COMPRESSOR-2(PCC-2 @ 321CP2) | B27: 2674 | C27: =BQ27 -> 5339 | AL27: 2665 | AM27: 2674 | AN27: 0 | AO27: 0 | AP27: 0 | AQ27: 0 | AR27: 0 | AS27: 0 | AT27: 0 | AU27: 0 | AV27: 0 | AW27: 0 | AX27: 0 | AY27: 0 | AZ27: 0 | BA27: 0 | BB27: 0 | BC27: 0 | BD27: 0 | BE27: 0 | BF27: 0 | BG27: 0 | BH27: 0 | BI27: 0 | BJ27: 0 | BK27: 0 | BL27: 0 | BM27: 0 | BN27: 0 | BO27: 0 | BP27: 0 | BQ27: =SUM(AL27:BP27) -> 5339
A28: COMPRESSOR-4(PCC-2 @321CP4) | B28: 2696 | C28: =BQ28 -> 5483 | AL28: 2787 | AM28: 2696 | AN28: 0 | AO28: 0 | AP28: 0 | AQ28: 0 | AR28: 0 | AS28: 0 | AT28: 0 | AU28: 0 | AV28: 0 | AW28: 0 | AX28: 0 | AY28: 0 | AZ28: 0 | BA28: 0 | BB28: 0 | BC28: 0 | BD28: 0 | BE28: 0 | BF28: 0 | BG28: 0 | BH28: 0 | BI28: 0 | BJ28: 0 | BK28: 0 | BL28: 0 | BM28: 0 | BN28: 0 | BO28: 0 | BP28: 0 | BQ28: =SUM(AL28:BP28) -> 5483
A29: KILN MAIN DRIVE(441MU1) | B29: 1291 | C29: =BQ29 -> 2379 | AL29: 1088 | AM29: 1291 | AN29: 0 | AO29: 0 | AP29: 0 | AQ29: 0 | AR29: 0 | AS29: 0 | AT29: 0 | AU29: 0 | AV29: 0 | AW29: 0 | AX29: 0 | AY29: 0 | AZ29: 0 | BA29: 0 | BB29: 0 | BC29: 0 | BD29: 0 | BE29: 0 | BF29: 0 | BG29: 0 | BH29: 0 | BI29: 0 | BJ29: 0 | BK29: 0 | BL29: 0 | BM29: 0 | BN29: 0 | BO29: 0 | BP29: 0 | BQ29: =SUM(AL29:BP29) -> 2379
A30: LC-2 LIGHTING TRAFO | B30: 387 | C30: =BQ30 -> 778 | AL30: 391 | AM30: 387 | AN30: 0 | AO30: 0 | AP30: 0 | AQ30: 0 | AR30: 0 | AS30: 0 | AT30: 0 | AU30: 0 | AV30: 0 | AW30: 0 | AX30: 0 | AY30: 0 | AZ30: 0 | BA30: 0 | BB30: 0 | BC30: 0 | BD30: 0 | BE30: 0 | BF30: 0 | BG30: 0 | BH30: 0 | BI30: 0 | BJ30: 0 | BK30: 0 | BL30: 0 | BM30: 0 | BN30: 0 | BO30: 0 | BP30: 0 | BQ30: =SUM(AL30:BP30) -> 778
A31: A/C Supply LC-2 | B31: 426 | C31: =BQ31 -> 848 | AL31: 422 | AM31: 426 | AN31: 0 | AO31: 0 | AP31: 0 | AQ31: 0 | AR31: 0 | AS31: 0 | AT31: 0 | AU31: 0 | AV31: 0 | AW31: 0 | AX31: 0 | AY31: 0 | AZ31: 0 | BA31: 0 | BB31: 0 | BC31: 0 | BD31: 0 | BE31: 0 | BF31: 0 | BG31: 0 | BH31: 0 | BI31: 0 | BJ31: 0 | BK31: 0 | BL31: 0 | BM31: 0 | BN31: 0 | BO31: 0 | BP31: 0 | BQ31: =SUM(AL31:BP31) -> 848
A32: 471FN2 -Chlorine bypass fan | B32: 0 | C32: =BQ32 -> 0 | AL32: 0 | AM32: 0 | AN32: 0 | AO32: 0 | AP32: 0 | AQ32: 0 | AR32: 0 | AS32: 0 | AT32: 0 | AU32: 0 | AV32: 0 | AW32: 0 | AX32: 0 | AY32: 0 | AZ32: 0 | BA32: 0 | BB32: 0 | BC32: 0 | BD32: 0 | BE32: 0 | BF32: 0 | BG32: 0 | BH32: 0 | BI32: 0 | BJ32: 0 | BK32: 0 | BL32: 0 | BM32: 0 | BN32: 0 | BO32: 0 | BP32: 0 | BQ32: =SUM(AL32:BP32) -> 0
A33: CEMENT MILL-1 | C33: =BQ33 -> 0 | BQ33: =SUM(AL33:BP33) -> 0
A34: 631BM1 | B34: 0 | C34: =BQ34 -> 0 | AL34: 0 | AM34: 0 | AN34: 0 | AO34: 0 | AP34: 0 | AQ34: 0 | AR34: 0 | AS34: 0 | AT34: 0 | AU34: 0 | AV34: 0 | AW34: 0 | AX34: 0 | AY34: 0 | AZ34: 0 | BA34: 0 | BB34: 0 | BC34: 0 | BD34: 0 | BE34: 0 | BF34: 0 | BG34: 0 | BH34: 0 | BI34: 0 | BJ34: 0 | BK34: 0 | BL34: 0 | BM34: 0 | BN34: 0 | BO34: 0 | BP34: 0 | BQ34: =SUM(AL34:BP34) -> 0
A35: 631CF1 (631FN6) | B35: 0 | C35: =BQ35 -> 0 | AL35: 0 | AM35: 0 | AN35: 0 | AO35: 0 | AP35: 0 | AQ35: 0 | AR35: 0 | AS35: 0 | AT35: 0 | AU35: 0 | AV35: 0 | AW35: 0 | AX35: 0 | AY35: 0 | AZ35: 0 | BA35: 0 | BB35: 0 | BC35: 0 | BD35: 0 | BE35: 0 | BF35: 0 | BG35: 0 | BH35: 0 | BI35: 0 | BJ35: 0 | BK35: 0 | BL35: 0 | BM35: 0 | BN35: 0 | BO35: 0 | BP35: 0 | BQ35: =SUM(AL35:BP35) -> 0
A36: IMCC5 + ROLLER CRUSHER | B36: =0+B67 -> 0 | C36: =BQ36 -> 0 | AL36: =0+AL67 -> 0 | AM36: =0+AM67 -> 0 | AN36: =0+AN67 -> 0 | AO36: =0+AO67 -> 0 | AP36: =0+AP67 -> 0 | AQ36: =0+AQ67 -> 0 | AR36: =0+AR67 -> 0 | AS36: =0+AS67 -> 0 | ... BP36: =0+BP67 -> 0 | BQ36: =SUM(AL36:BP36) -> 0
A37: CLASSFIER (631HC1) | B37: 0 | C37: =BQ37 -> 0 | AL37: 0 | AM37: 0 | AN37: 0 | AO37: 0 | AP37: 0 | AQ37: 0 | AR37: 0 | AS37: 0 | AT37: 0 | AU37: 0 | AV37: 0 | AW37: 0 | AX37: 0 | AY37: 0 | AZ37: 0 | BA37: 0 | BB37: 0 | BC37: 0 | BD37: 0 | BE37: 0 | BF37: 0 | BG37: 0 | BH37: 0 | BI37: 0 | BJ37: 0 | BK37: 0 | BL37: 0 | BM37: 0 | BN37: 0 | BO37: 0 | BP37: 0 | BQ37: =SUM(AL37:BP37) -> 0
A38: COMPRESSOR-6-(CP1) | B38: 0 | C38: =BQ38 -> 0 | AL38: 0 | AM38: 0 | AN38: 0 | AO38: 0 | AP38: 0 | AQ38: 0 | AR38: 0 | AS38: 0 | AT38: 0 | AU38: 0 | AV38: 0 | AW38: 0 | AX38: 0 | AY38: 0 | AZ38: 0 | BA38: 0 | BB38: 0 | BC38: 0 | BD38: 0 | BE38: 0 | BF38: 0 | BG38: 0 | BH38: 0 | BI38: 0 | BJ38: 0 | BK38: 0 | BL38: 0 | BM38: 0 | BN38: 0 | BO38: 0 | BP38: 0 | BQ38: =SUM(AL38:BP38) -> 0
A39: COMPRESSOR-7-(CP2) | B39: 0 | C39: =BQ39 -> 0 | AL39: 0 | AM39: 0 | AN39: 0 | AO39: 0 | AP39: 0 | AQ39: 0 | AR39: 0 | AS39: 0 | AT39: 0 | AU39: 0 | AV39: 0 | AW39: 0 | AX39: 0 | AY39: 0 | AZ39: 0 | BA39: 0 | BB39: 0 | BC39: 0 | BD39: 0 | BE39: 0 | BF39: 0 | BG39: 0 | BH39: 0 | BI39: 0 | BJ39: 0 | BK39: 0 | BL39: 0 | BM39: 0 | BN39: 0 | BO39: 0 | BP39: 0 | BQ39: =SUM(AL39:BP39) -> 0
A40: COMPRESSOR-8-(CP3) | B40: 0 | C40: =BQ40 -> 0 | AL40: 0 | AM40: 0 | AN40: 0 | AO40: 0 | AP40: 0 | AQ40: 0 | AR40: 0 | AS40: 0 | AT40: 0 | AU40: 0 | AV40: 0 | AW40: 0 | AX40: 0 | AY40: 0 | AZ40: 0 | BA40: 0 | BB40: 0 | BC40: 0 | BD40: 0 | BE40: 0 | BF40: 0 | BG40: 0 | BH40: 0 | BI40: 0 | BJ40: 0 | BK40: 0 | BL40: 0 | BM40: 0 | BN40: 0 | BO40: 0 | BP40: 0 | BQ40: =SUM(AL40:BP40) -> 0
...

Sheet IMS DATA
A1: Crusher | B1: 46174 | C1: =B1+1 -> 46175 | D1: =C1+1 -> 46176 | E1: =D1+1 -> 46177 | F1: =E1+1 -> 46178 | G1: =F1+1 -> 46179 | H1: =G1+1 -> 46180 | I1: =H1+1 -> 46181 | J1: =I1+1 -> 46182 | ... AE1: =AD1+1 -> 46203 | AF1: Cumulative
A2: 211IC1 | B2: ='Energy Readings'!D2 -> 220.03 | C2: ='Energy Readings'!F2 -> 213.31 | D2: ='Energy Readings'!H2 -> 227.47 | E2: ='Energy Readings'!J2 -> 162.2 | F2: ='Energy Readings'!L2 -> 241.96 | G2: ='Energy Readings'!N2 -> 286.36 | H2: ='Energy Readings'!P2 -> 247.65 | I2: ='Energy Readings'!R2 -> 310.4 | J2: ='Energy Readings'!T2 -> 236.61 | K2: ='Energy Readings'!V2 -> 278.13 | L2: ='Energy Readings'!X2 -> 243.49 | M2: ='Energy Readings'!Z2 -> 317.896 | N2: ='Energy Readings'!AB2 -> 245.124 | O2: ='Energy Readings'!AD2 -> 196.34 | P2: ='Energy Readings'!AF2 -> 208.22 | Q2: ='Energy Readings'!AH2 -> 227.76 | R2: ='Energy Readings'!AJ2 -> 209.98 | S2: ='Energy Readings'!AL2 -> 191.72 | T2: ='Energy Readings'!AN2 -> 297.16 | U2: ='Energy Readings'!AP2 -> 177.19 | V2: ='Energy Readings'!AR2 -> 317.38 | W2: ='Energy Readings'!AT2 -> 304.48 | X2: ='Energy Readings'!AV2 -> 296.69 | Y2: ='Energy Readings'!AX2 -> 213.8 | Z2: ='Energy Readings'!AZ2 -> 193.46 | AA2: ='Energy Readings'!BB2 -> 201.5 | AB2: ='Energy Readings'!BD2 -> 196.77 | AC2: ='Energy Readings'!BF2 -> 280.02 | AD2: ='Energy Readings'!BH2 -> 252.71 | AE2: ='Energy Readings'!BJ2 -> 264.08 | AF2: =SUM(B2:AE2) -> 7259.89
A3: CRUSHER AUXILIRIES(IPMCC-1)-TR3 | B3: ='Energy Readings'!D3-B4-B5-B6-B7 -> 1348.95 | C3: ='Energy Readings'!F3-C4-C5-C6-C7 -> 1116.8 | D3: ='Energy Readings'!H3-D4-D5-D6-D7 -> 1116.15 | E3: ='Energy Readings'!J3-E4-E5-E6-E7 -> 765.53 | F3: ='Energy Readings'!L3-F4-F5-F6-F7 -> 1056.03 | G3: ='Energy Readings'!N3-G4-G5-G6-G7 -> 964.9 | H3: ='Energy Readings'!P3-H4-H5-H6-H7 -> 869.84 | I3: ='Energy Readings'!R3-I4-I5-I6-I7 -> 1038.65 | J3: ='Energy Readings'!T3-J4-J5-J6-J7 -> 910.78 | K3: ='Energy Readings'!V3-K4-K5-K6-K7 -> 1053.54 | L3: ='Energy Readings'!X3-L4-L5-L6-L7 -> 1094.11 | M3: ='Energy Readings'!Z3-M4-M5-M6-M7 -> 1782.69 | N3: ='Energy Readings'!AB3-N4-N5-N6-N7 -> 2187 | O3: ='Energy Readings'!AD3-O4-O5-O6-O7 -> 2305.49 | P3: ='Energy Readings'!AF3-P4-P5-P6-P7 -> 1662.37 | Q3: ='Energy Readings'!AH3-Q4-Q5-Q6-Q7 -> 1115.43 | R3: ='Energy Readings'!AJ3-R4-R5-R6-R7 -> 1004.52 | S3: ='Energy Readings'!AL3-S4-S5-S6-S7 -> 1025.62 | T3: ='Energy Readings'!AN3-T4-T5-T6-T7 -> 1222.79 | U3: ='Energy Readings'!AP3-U4-U5-U6-U7 -> 781.91 | V3: ='Energy Readings'!AR3-V4-V5-V6-V7 -> 1239.96 | W3: ='Energy Readings'!AT3-W4-W5-W6-W7 -> 1193.05 | X3: ='Energy Readings'!AV3-X4-X5-X6-X7 -> 1171.38 | Y3: ='Energy Readings'!AX3-Y4-Y5-Y6-Y7 -> 959.53 | Z3: ='Energy Readings'!AZ3-Z4-Z5-Z6-Z7 -> 995.62 | AA3: ='Energy Readings'!BB3-AA4-AA5-AA6-AA7 -> 928.3 | AB3: ='Energy Readings'!BD3-AB4-AB5-AB6-AB7 -> 952.1 | AC3: ='Energy Readings'!BF3-AC4-AC5-AC6-AC7 -> 1200.05 | AD3: ='Energy Readings'!BH3-AD4-AD5-AD6-AD7 -> 1241.31 | AE3: ='Energy Readings'!BJ3-AE4-AE5-AE6-AE7+500 -> 1600.02 | AF3: =SUM(B3:AE3) -> 35904.42
A4: COLONY (TENESCO from LC-1) | B4: ='Energy Readings'!D4 -> 1132.09 | C4: ='Energy Readings'!F4 -> 1183.79 | D4: ='Energy Readings'!H4 -> 1291.64 | E4: ='Energy Readings'!J4 -> 1926.18 | F4: ='Energy Readings'!L4 -> 2024.42 | G4: ='Energy Readings'!N4 -> 1897.52 | H4: ='Energy Readings'!P4 -> 1325.36 | I4: ='Energy Readings'!R4 -> 1355.62 | J4: ='Energy Readings'!T4 -> 1285.42 | K4: ='Energy Readings'!V4 -> 1311.19 | L4: ='Energy Readings'!X4 -> 1194.49 | M4: ='Energy Readings'!Z4 -> 1205.45 | N4: ='Energy Readings'!AB4 -> 1012.02 | O4: ='Energy Readings'!AD4 -> 1125.25 | P4: ='Energy Readings'!AF4 -> 1199.35 | Q4: ='Energy Readings'!AH4 -> 1058.4 | R4: ='Energy Readings'!AJ4 -> 1143.72 | S4: ='Energy Readings'!AL4 -> 1120.59 | T4: ='Energy Readings'!AN4 -> 1157.65 | U4: ='Energy Readings'!AP4 -> 999.73 | V4: ='Energy Readings'!AR4 -> 1023.35 | W4: ='Energy Readings'!AT4 -> 980.12 | X4: ='Energy Readings'!AV4 -> 1023.46 | Y4: ='Energy Readings'!AX4 -> 1137.15 | Z4: ='Energy Readings'!AZ4 -> 1139.72 | AA4: ='Energy Readings'!BB4 -> 1150.96 | AB4: ='Energy Readings'!BD4 -> 1112.48 | AC4: ='Energy Readings'!BF4 -> 1088.88 | AD4: ='Energy Readings'!BH4 -> 1135.89 | AE4: ='Energy Readings'!BJ4 -> 1210.64 | AF4: =SUM(B4:AE4) -> 36952.53
A5: STACKER(IMCC1) | B5: ='Energy Readings'!D5 -> 230.39 | C5: ='Energy Readings'!F5 -> 211.76 | D5: ='Energy Readings'!H5 -> 234.29 | E5: ='Energy Readings'!J5 -> 128.59 | F5: ='Energy Readings'!L5 -> 256.07 | G5: ='Energy Readings'!N5 -> 260.87 | H5: ='Energy Readings'!P5 -> 162.3 | I5: ='Energy Readings'!R5 -> 244.19 | J5: ='Energy Readings'!T5 -> 245.21 | K5: ='Energy Readings'!V5 -> 252.83 | L5: ='Energy Readings'!X5 -> 238.72 | M5: ='Energy Readings'!Z5 -> 225.71 | N5: ='Energy Readings'!AB5 -> 185.73 | O5: ='Energy Readings'!AD5 -> 216.72 | P5: ='Energy Readings'!AF5 -> 230.52 | Q5: ='Energy Readings'!AH5 -> 217.38 | R5: ='Energy Readings'!AJ5 -> 176.31 | S5: ='Energy Readings'!AL5 -> 175.45 | T5: ='Energy Readings'!AN5 -> 243.24 | U5: ='Energy Readings'!AP5 -> 138.15 | V5: ='Energy Readings'!AR5 -> 253.4 | W5: ='Energy Readings'!AT5 -> 219.48 | X5: ='Energy Readings'!AV5 -> 246.2 | Y5: ='Energy Readings'!AX5 -> 129.48 | Z5: ='Energy Readings'!AZ5 -> 163.08 | AA5: ='Energy Readings'!BB5 -> 206.9 | AB5: ='Energy Readings'!BD5 -> 184.11 | AC5: ='Energy Readings'!BF5 -> 177.94 | AD5: ='Energy Readings'!BH5 -> 226.06 | AE5: ='Energy Readings'!BJ5 -> 204.08 | AF5: =SUM(B5:AE5) -> 6285.16
A6: LC-1 LIGHTING | B6: ='Energy Readings'!D6 -> 35.47 | C6: ='Energy Readings'!F6 -> 43.82 | D6: ='Energy Readings'!H6 -> 38.62 | E6: ='Energy Readings'!J6 -> 39.76 | F6: ='Energy Readings'!L6 -> 39.43 | G6: ='Energy Readings'!N6 -> 40.25 | H6: ='Energy Readings'!P6 -> 37.15 | I6: ='Energy Readings'!R6 -> 40.1 | J6: ='Energy Readings'!T6 -> 38.55 | K6: ='Energy Readings'!V6 -> 39.29 | L6: ='Energy Readings'!X6 -> 39.26 | M6: ='Energy Readings'!Z6 -> 39.65 | N6: ='Energy Readings'!AB6 -> 37.49 | O6: ='Energy Readings'!AD6 -> 40.7 | P6: ='Energy Readings'!AF6 -> 38.43 | Q6: ='Energy Readings'!AH6 -> 39.79 | R6: ='Energy Readings'!AJ6 -> 40.62 | S6: ='Energy Readings'!AL6 -> 38.9 | T6: ='Energy Readings'!AN6 -> 42.1 | U6: ='Energy Readings'!AP6 -> 39.86 | V6: ='Energy Readings'!AR6 -> 37.09 | W6: ='Energy Readings'!AT6 -> 36.79 | X6: ='Energy Readings'!AV6 -> 39.57 | Y6: ='Energy Readings'!AX6 -> 37.77 | Z6: ='Energy Readings'!AZ6 -> 37.16 | AA6: ='Energy Readings'!BB6 -> 37.17 | AB6: ='Energy Readings'!BD6 -> 36.94 | AC6: ='Energy Readings'!BF6 -> 36.54 | AD6: ='Energy Readings'!BH6 -> 58 | AE6: ='Energy Readings'!BJ6 -> 13.43 | AF6: =SUM(B6:AE6) -> 1159.7
A7: Welding DB + A/C | B7: ='Energy Readings'!D7 -> 7.42 | C7: ='Energy Readings'!F7 -> 2.15 | D7: ='Energy Readings'!H7 -> 2.1 | E7: ='Energy Readings'!J7 -> 11.06 | F7: ='Energy Readings'!L7 -> 2.13 | G7: ='Energy Readings'!N7 -> 2.14 | H7: ='Energy Readings'!P7 -> 50.39 | I7: ='Energy Readings'!R7 -> 0 | J7: ='Energy Readings'!T7 -> 5.88 | K7: ='Energy Readings'!V7 -> 0.11 | L7: ='Energy Readings'!X7 -> 0 | M7: ='Energy Readings'!Z7 -> 0 | N7: ='Energy Readings'!AB7 -> 2.08 | O7: ='Energy Readings'!AD7 -> 2.16 | P7: ='Energy Readings'!AF7 -> 2.09 | Q7: ='Energy Readings'!AH7 -> 2.08 | R7: ='Energy Readings'!AJ7 -> 1.95 | S7: ='Energy Readings'!AL7 -> 2 | T7: ='Energy Readings'!AN7 -> 2.7 | U7: ='Energy Readings'!AP7 -> 2.11 | V7: ='Energy Readings'!AR7 -> 2.12 | W7: ='Energy Readings'!AT7 -> 2.08 | X7: ='Energy Readings'!AV7 -> 2.59 | Y7: ='Energy Readings'!AX7 -> 2.43 | Z7: ='Energy Readings'!AZ7 -> 2.43 | AA7: ='Energy Readings'!BB7 -> 2.46 | AB7: ='Energy Readings'!BD7 -> 4.21 | AC7: ='Energy Readings'!BF7 -> 2.11 | AD7: ='Energy Readings'!BH7 -> 2.1 | AE7: ='Energy Readings'!BJ7 -> 2.07 | AF7: =SUM(B7:AE7) -> 125.15
A8: Rawmill | N8: ='Energy Readings'!AB8 -> 0 | O8: ='Energy Readings'!AD8 -> 0 | P8: ='Energy Readings'!AF8 -> 0 | Q8: ='Energy Readings'!AH8 -> 0 | R8: ='Energy Readings'!AJ8 -> 0 | S8: ='Energy Readings'!AL8 -> 0 | W8: ='Energy Readings'!AT8 -> 0 | X8: ='Energy Readings'!AV8 -> 0 | Z8: ='Energy Readings'!AZ8 -> 0 | AD8: ='Energy Readings'!BH8 -> 0 | AE8: ='Energy Readings'!BJ8 -> 0
A9: 321RM1 | B9: ='Energy Readings'!D9 -> 28075.2 | C9: ='Energy Readings'!F9 -> 11098.4 | D9: ='Energy Readings'!H9-300 -> 22270.4 | E9: ='Energy Readings'!J9+200 -> 28284 | F9: ='Energy Readings'!L9 -> 19830.4 | G9: ='Energy Readings'!N9+400 -> 20280.8 | H9: ='Energy Readings'!P9 -> 20495.2 | I9: ='Energy Readings'!R9 -> 20108 | J9: ='Energy Readings'!T9 -> 21770.4 | K9: ='Energy Readings'!V9 -> 23491.2 | L9: ='Energy Readings'!X9-300 -> 20506.4 | M9: ='Energy Readings'!Z9+877 -> 21129.8 | N9: ='Energy Readings'!AB9 -> 15836.8 | O9: ='Energy Readings'!AD9 -> 19279.2 | P9: ='Energy Readings'!AF9+500 -> 25923.2 | Q9: ='Energy Readings'!AH9+50 -> 27183.6 | R9: ='Energy Readings'!AJ9 -> 16948.8 | S9: ='Energy Readings'!AL9-650 -> 23386 | T9: ='Energy Readings'!AN9 -> 23357.6 | U9: ='Energy Readings'!AP9 -> 18761.6 | V9: ='Energy Readings'!AR9+1000 -> 19945.6 | W9: ='Energy Readings'!AT9 -> 17594.4 | X9: ='Energy Readings'!AV9 -> 0 | Y9: ='Energy Readings'!AX9 -> 13060.6 | Z9: ='Energy Readings'!AZ9 -> 24722.6 | AA9: ='Energy Readings'!BB9-150 -> 25175.6 | AB9: ='Energy Readings'!AN9 -> 23357.6 | AC9: ='Energy Readings'!BF9 -> 21912.8 | AD9: ='Energy Readings'!BH9 -> 28156 | AE9: ='Energy Readings'!BJ9+1000 -> 14750.4 | AF9: =SUM(B9:AE9) -> 616692.6
A10: 321FN3 RM FAN | B10: ='Energy Readings'!D10 -> 28114.4 | C10: ='Energy Readings'!F10 -> 12025.6 | D10: ='Energy Readings'!H10-300 -> 21337.6 | E10: ='Energy Readings'!J10+200 -> 28396.8 | F10: ='Energy Readings'!L10 -> 19753.6 | G10: ='Energy Readings'!N10+700 -> 22776 | H10: ='Energy Readings'!P10 -> 23890.4 | I10: ='Energy Readings'!R10 -> 24219.2 | J10: ='Energy Readings'!T10 -> 24186.4 | K10: ='Energy Readings'!V10 -> 26332.8 | L10: ='Energy Readings'!X10-400 -> 23315.2 | M10: ='Energy Readings'!Z10+1000 -> 23354.8 | N10: ='Energy Readings'!AB10 -> 18235.6 | O10: ='Energy Readings'!AD10 -> 21919.2 | P10: ='Energy Readings'!AF10 -> 26099.2 | Q10: ='Energy Readings'!AH10 -> 27729.6 | R10: ='Energy Readings'!AJ10-200 -> 19613.6 | S10: ='Energy Readings'!AL10 -> 23508 | T10: ='Energy Readings'!AN10 -> 23324.8 | U10: ='Energy Readings'!AP10+150 -> 18689.6 | V10: ='Energy Readings'!AR10+1300 -> 21882 | W10: ='Energy Readings'!AT10 -> 18547.2 | X10: ='Energy Readings'!AV10 -> 440 | Y10: ='Energy Readings'!AX10 -> 14293.6 | Z10: ='Energy Readings'!AZ10+7800 -> 25220.959 | AA10: ='Energy Readings'!BB10-950 -> 25985.494 | AB10: ='Energy Readings'!BD10-80 -> 24511.48 | AC10: ='Energy Readings'!BF10 -> 23791.316 | AD10: ='Energy Readings'!BH10 -> 27341.41 | AE10: ='Energy Readings'!BJ10 -> 12955.98 | AF10: =SUM(B10:AE10) -> 651791.84
A11: IMCC-3 | B11: ='Energy Readings'!D11-B12 -> 3545.7 | C11: ='Energy Readings'!F11-C12 -> 4850.74 | D11: ='Energy Readings'!H11-D12 -> 4464.63 | E11: ='Energy Readings'!J11-E12+100 -> 4840.87 | F11: ='Energy Readings'!L11-F12 -> 4346.27 | G11: ='Energy Readings'!N11-G12 -> 4168.18 | H11: ='Energy Readings'!P11-H12 -> 4388.29 | I11: ='Energy Readings'!R11-I12 -> 4439.42 | J11: ='Energy Readings'!T11-J12 -> 4490.58 | K11: ='Energy Readings'!V11-K12 -> 4892.44 | L11: ='Energy Readings'!X11-L12 -> 5439.02 | M11: ='Energy Readings'!Z11-M12 -> 4819.72 | N11: ='Energy Readings'!AB11-N12 -> 4049.07 | O11: ='Energy Readings'!AD11-O12 -> 4204.38 | P11: ='Energy Readings'!AF11-P12 -> 4606.56 | Q11: ='Energy Readings'!AH11-Q12 -> 4441.12 | R11: ='Energy Readings'!AJ11-R12 -> 4209.05 | S11: ='Energy Readings'!AL11-S12 -> 4213.05 | T11: ='Energy Readings'!AN11-T12 -> 4345.16 | U11: ='Energy Readings'!AP11-U12 -> 4239.3 | V11: ='Energy Readings'!AR11-V12 -> 4249.87 | W11: ='Energy Readings'!AT11-W12 -> 4041.49 | X11: ='Energy Readings'!AV11-X12 -> 2626.03 | Y11: ='Energy Readings'!AX11-Y12 -> 3801.05 | Z11: ='Energy Readings'!AZ11-Z12 -> 4542.94 | AA11: ='Energy Readings'!BB11-AA12 -> 4537.64 | AB11: ='Energy Readings'!BD11-AB12 -> 4447.99 | AC11: ='Energy Readings'!BF11-AC12 -> 4400.02 | AD11: ='Energy Readings'!BH11-AD12 -> 4577.07 | AE11: ='Energy Readings'!BJ11-AE12 -> 3438.78 | AF11: =SUM(B11:AE11) -> 129656.43
A12: IMCC-2/RECLAIMER | B12: ='Energy Readings'!D12 -> 1397.84 | C12: ='Energy Readings'!F12 -> 556.91 | D12: ='Energy Readings'!H12 -> 1142.16 | E12: ='Energy Readings'!J12 -> 1380.43 | F12: ='Energy Readings'!L12 -> 1135.75 | G12: ='Energy Readings'!N12 -> 1090.01 | H12: ='Energy Readings'!P12 -> 1294.16 | I12: ='Energy Readings'!R12 -> 1268.76 | J12: ='Energy Readings'!T12 -> 1310.06 | K12: ='Energy Readings'!V12 -> 1410.86 | L12: ='Energy Readings'!X12 -> 1183.76 | M12: ='Energy Readings'!Z12 -> 1297.55 | N12: ='Energy Readings'!AB12 -> 1081.2 | O12: ='Energy Readings'!AD12 -> 1120.78 | P12: ='Energy Readings'!AF12 -> 1361.83 | Q12: ='Energy Readings'!AH12 -> 1423.49 | R12: ='Energy Readings'!AJ12 -> 1022.19 | S12: ='Energy Readings'!AL12 -> 1198.59 | T12: ='Energy Readings'!AN12 -> 1205.16 | U12: ='Energy Readings'!AP12 -> 1033.51 | V12: ='Energy Readings'!AR12 -> 968.02 | W12: ='Energy Readings'!AT12 -> 918.99 | X12: ='Energy Readings'!AV12 -> 203.69 | Y12: ='Energy Readings'!AX12 -> 666.63 | Z12: ='Energy Readings'!AZ12 -> 1368.67 | AA12: ='Energy Readings'!BB12 -> 1432.51 | AB12: ='Energy Readings'!BD12 -> 1267.87 | AC12: ='Energy Readings'!BF12 -> 1328.45 | AD12: ='Energy Readings'!BH12 -> 1372.57 | AE12: ='Energy Readings'!BJ12 -> 742.81 | AF12: =SUM(B12:AE12) -> 34185.21
A13: TR-5(IPMCC-2 = BAG HOUSE AUX.- WORKSHOP) | B13: ='Energy Readings'!D13-B78-B18 -> 1330.02 | C13: ='Energy Readings'!F13-C78-C18 -> 1381.79 | D13: ='Energy Readings'!H13-D78-D18 -> 1313.83 | E13: ='Energy Readings'!J13-E78-E18 -> 1318.74 | F13: ='Energy Readings'!L13-F78-F18 -> 1365.92 | G13: ='Energy Readings'!N13-G78-G18 -> 1364.36 | H13: ='Energy Readings'!P13-H78-H18 -> 1333.23 | I13: ='Energy Readings'!R13-I78-I18 -> 1425.45 | J13: ='Energy Readings'!T13-J78-J18 -> 1198.93 | K13: ='Energy Readings'!V13-K78-K18 -> 1302.44 | L13: ='Energy Readings'!X13-L78-L18 -> 1293.06 | M13: ='Energy Readings'!Z13-M78-M18 -> 1283.94 | N13: ='Energy Readings'!AB13-N78-N18 -> 1359.98 | O13: ='Energy Readings'!AD13-O78-O18 -> 1197.41 | P13: ='Energy Readings'!AF13-P78-P18 -> 1341.98 | Q13: ='Energy Readings'!AH13-Q78-Q18 -> 1292.36 | R13: ='Energy Readings'!AJ13-R78-R18 -> 1226.79 | S13: ='Energy Readings'!AL13-S78-S18 -> 1387.64 | T13: ='Energy Readings'!AN13-T78-T18 -> 1442.58 | U13: ='Energy Readings'!AP13-U78-U18 -> 1366.17 | V13: ='Energy Readings'!AR13-V78-V18 -> 1355.38 | W13: ='Energy Readings'!AT13-W78-W18 -> 1365.94 | X13: ='Energy Readings'!AV13-X78-X18 -> 1377.57 | Y13: ='Energy Readings'!AX13-Y78-Y18 -> 1345.17 | Z13: ='Energy Readings'!AZ13-Z78 -> 2806.53 | AA13: ='Energy Readings'!BB13-AA78-150 -> 2910.06 | AB13: ='Energy Readings'!BD13-AB78-AB18 -> 1336.97 | AC13: ='Energy Readings'!BF13-AC78-AC18 -> 1354.13 | AD13: ='Energy Readings'!BH13-AD78-AD18 -> 1741.53 | AE13: ='Energy Readings'!BJ13-AE78-AE18 -> 583.55 | AF13: =SUM(B13:AE13) -> 42703.45
A14: 461FN1-TR1 | B14: ='Energy Readings'!D14 -> 5024.8 | C14: ='Energy Readings'!F14 -> 6016.92 | D14: ='Energy Readings'!H14 -> 4418.72 | E14: ='Energy Readings'!J14 -> 4769.84 | F14: ='Energy Readings'!L14 -> 5304.16 | G14: ='Energy Readings'!N14 -> 5135.64 | H14: ='Energy Readings'!P14 -> 5199.28 | I14: ='Energy Readings'!R14 -> 5201.68 | J14: ='Energy Readings'!T14 -> 5047.72 | K14: ='Energy Readings'!V14 -> 4713.88 | L14: ='Energy Readings'!X14 -> 5000.24 | M14: ='Energy Readings'!Z14 -> 5274.8 | N14: ='Energy Readings'!AB14 -> 5351.8 | O14: ='Energy Readings'!AD14 -> 5085.12 | P14: ='Energy Readings'!AF14 -> 4658.76 | Q14: ='Energy Readings'!AH14 -> 4602.4 | R14: ='Energy Readings'!AJ14 -> 5257.68 | S14: ='Energy Readings'!AL14 -> 4826.44 | T14: ='Energy Readings'!AN14 -> 4757.96 | U14: ='Energy Readings'!AP14 -> 5442.88 | V14: ='Energy Readings'!AR14 -> 4010.56 | W14: ='Energy Readings'!AT14 -> 4524.48 | X14: ='Energy Readings'!AV14 -> 1041.92 | Y14: ='Energy Readings'!AX14 -> 2951.28 | Z14: ='Energy Readings'!AZ14 -> 4587.8 | AA14: ='Energy Readings'!BB14 -> 4016.84 | AB14: ='Energy Readings'!BD14 -> 4647.04 | AC14: ='Energy Readings'!BF14 -> 4564.24 | AD14: ='Energy Readings'!BH14 -> 4446.88 | AE14: ='Energy Readings'!BJ14 -> 2668.72 | AF14: =SUM(B14:AE14) -> 138550.48
A15: COMPRESSOR-1(PCC-1@321CP1) | B15: ='Energy Readings'!D15 -> 4337.38 | C15: ='Energy Readings'!F15 -> 4426.61 | D15: ='Energy Readings'!H15-250 -> 4090.06 | E15: ='Energy Readings'!J15 -> 4256.99 | F15: ='Energy Readings'!L15 -> 4401.41 | G15: ='Energy Readings'!N15 -> 4348.91 | H15: ='Energy Readings'!P15 -> 4381.18 | I15: ='Energy Readings'!R15-500 -> 3984.56 | J15: ='Energy Readings'!T15 -> 4311.13 | K15: ='Energy Readings'!V15 -> 4392.55 | L15: ='Energy Readings'!X15 -> 4427.5 | M15: ='Energy Readings'!Z15 -> 4330.52 | N15: ='Energy Readings'!AB15 -> 4343.27 | O15: ='Energy Readings'!AD15-500 -> 3951.42 | P15: ='Energy Readings'!AF15 -> 4362.98 | Q15: ='Energy Readings'!AH15 -> 4340.85 | R15: ='Energy Readings'!AJ15 -> 4439.61 | S15: ='Energy Readings'!AL15 -> 4425.64 | T15: ='Energy Readings'!AN15 -> 4457.53 | U15: ='Energy Readings'!AP15 -> 4390.97 | V15: ='Energy Readings'!AR15 -> 4409.91 | W15: ='Energy Readings'!AT15 -> 4460.79 | X15: ='Energy Readings'!AV15 -> 4567.46 | Y15: ='Energy Readings'!AX15 -> 4482.62 | Z15: ='Energy Readings'!AZ15 -> 4420.61 | AA15: ='Energy Readings'!BB15 -> 4419.16 | AB15: ='Energy Readings'!BD15 -> 4455.01 | AC15: ='Energy Readings'!BF15 -> 4427.9 | AD15: ='Energy Readings'!BH15-1480 -> 4400.21 | AE15: ='Energy Readings'!BJ15+1000 -> 3574.77 | AF15: =SUM(B15:AE15) -> 130019.51
A16: Welding DB + A/C | B16: ='Energy Readings'!D16 -> 162 | C16: ='Energy Readings'!F16 -> 124 | D16: ='Energy Readings'!H16 -> 162 | E16: ='Energy Readings'!J16 -> 142 | F16: ='Energy Readings'!L16 -> 121 | G16: ='Energy Readings'!N16 -> 121 | H16: ='Energy Readings'!P16 -> 142 | I16: ='Energy Readings'!R16 -> 142 | J16: ='Energy Readings'!T16 -> 121 | K16: ='Energy Readings'!V16 -> 121 | L16: ='Energy Readings'!X16 -> 121 | M16: ='Energy Readings'!Z16 -> 121 | N16: ='Energy Readings'!AB16 -> 121 | O16: ='Energy Readings'!AD16 -> 121 | P16: ='Energy Readings'!AF16 -> 121 | Q16: ='Energy Readings'!AH16 -> 121 | R16: ='Energy Readings'!AJ16 -> 121 | S16: ='Energy Readings'!AL16 -> 121 | T16: ='Energy Readings'!AN16 -> 121 | U16: ='Energy Readings'!AP16 -> 121 | V16: ='Energy Readings'!AR16 -> 121 | W16: ='Energy Readings'!AT16 -> 121 | X16: ='Energy Readings'!AV16 -> 236 | Y16: ='Energy Readings'!AX16 -> 340 | Z16: ='Energy Readings'!AZ16 -> 254 | AA16: ='Energy Readings'!BB16 -> 312 | AB16: ='Energy Readings'!BD16 -> 328.9 | AC16: ='Energy Readings'!BF16 -> 322.6 | AD16: ='Energy Readings'!BH16 -> 289.2 | AE16: ='Energy Readings'!BJ16 -> 315 | AF16: =SUM(B16:AE16) -> 5207.7
A17: 100RM1 | B17: ='Energy Readings'!D17 -> 6730.8 | C17: 4300 | D17: ='Energy Readings'!H17 -> 4921.9 | E17: ='Energy Readings'!J17 -> 6187.9 | F17: ='Energy Readings'!L17 -> 5149.1 | G17: ='Energy Readings'!N17 -> 4752.5 | H17: ='Energy Readings'!P17 -> 3952.2 | I17: ='Energy Readings'!R17 -> 5360.6 | J17: ='Energy Readings'!T17 -> 6143.3 | K17: ='Energy Readings'!V17 -> 5303.8 | L17: ='Energy Readings'!X17 -> 5185.6 | M17: ='Energy Readings'!Z17 -> 5651.5 | N17: ='Energy Readings'!AB17 -> 5281.1 | O17: ='Energy Readings'!AD17 -> 5928 | P17: ='Energy Readings'!AF17 -> 2666.4 | Q17: ='Energy Readings'!AH17 -> 0 | R17: ='Energy Readings'!AJ17 -> 0 | S17: ='Energy Readings'!AL17 -> 0 | T17: ='Energy Readings'!AN17 -> 0 | U17: ='Energy Readings'!AP17 -> 0 | V17: ='Energy Readings'!AR17 -> 0 | W17: ='Energy Readings'!AT17 -> 0 | X17: ='Energy Readings'!AV17 -> 0 | Y17: ='Energy Readings'!AX17 -> 0 | Z17: ='Energy Readings'!AZ17 -> 5928.9 | AA17: ='Energy Readings'!BB17 -> 6617.9 | AB17: ='Energy Readings'!BD17 -> 6799.6 | AC17: ='Energy Readings'!BF17 -> 6116 | AD17: ='Energy Readings'!BH17 -> 6695.6 | AE17: ='Energy Readings'!BJ17 -> 2845.5 | AF17: =SUM(B17:AE17) -> 112518.2
A18: 100FN2 | B18: ='Energy Readings'!D18 -> 1639.52 | C18: ='Energy Readings'!F18 -> 1549.43 | D18: ='Energy Readings'!H18 -> 1341.9 | E18: ='Energy Readings'!J18 -> 1512.3 | F18: ='Energy Readings'!L18 -> 1593.13 | G18: ='Energy Readings'!N18 -> 1402.31 | H18: ='Energy Readings'!P18 -> 1058.48 | I18: ='Energy Readings'!R18 -> 1566.87 | J18: ='Energy Readings'!T18 -> 1696.78 | K18: ='Energy Readings'!V18 -> 1602.32 | L18: ='Energy Readings'!X18 -> 1599.6 | M18: ='Energy Readings'!Z18 -> 1564.57 | N18: ='Energy Readings'!AB18 -> 1479.9 | O18: ='Energy Readings'!AD18 -> 1516.58 | P18: ='Energy Readings'!AF18 -> 718.76 | Q18: ='Energy Readings'!AH18 -> 2.45 | R18: ='Energy Readings'!AJ18 -> 0 | S18: ='Energy Readings'!AL18 -> 5.01 | T18: ='Energy Readings'!AN18 -> -0.010000002 | U18: ='Energy Readings'!AP18 -> 0 | V18: ='Energy Readings'!AR18 -> 0 | W18: ='Energy Readings'!AT18 -> 10.3 | X18: ='Energy Readings'!AV18 -> 2.56 | Y18: ='Energy Readings'!AX18 -> 0 | Z18: ='Energy Readings'!AZ18 -> 1278 | AA18: ='Energy Readings'!BB18 -> 1676.02 | AB18: ='Energy Readings'!BD18 -> 1619.48 | AC18: ='Energy Readings'!BF18 -> 1435.47 | AD18: ='Energy Readings'!BH18 -> 1607.38 | AE18: ='Energy Readings'!BJ18 -> 636.66 | AF18: =SUM(B18:AE18) -> 30115.77
A19: Rawmill-2 Auxil | B19: 112 | C19: ='Energy Readings'!F19 -> 814.9 | D19: 920 | E19: ='Energy Readings'!J19 -> 1250 | F19: ='Energy Readings'!L19 -> 1064 | G19: ='Energy Readings'!N19 -> 822.6 | H19: ='Energy Readings'!P19 -> 905 | I19: ='Energy Readings'!R19 -> 835 | J19: ='Energy Readings'!T19 -> 1008.9 | K19: ='Energy Readings'!V19 -> 986.8 | L19: ='Energy Readings'!X19 -> 854 | M19: ='Energy Readings'!Z19 -> 910.6 | N19: ='Energy Readings'!AB19 -> 869.5 | O19: ='Energy Readings'!AD19 -> 895 | P19: ='Energy Readings'!AF19 -> 456 | Q19: ='Energy Readings'!AH19 -> 821 | R19: ='Energy Readings'!AJ19 -> 521 | S19: ='Energy Readings'!AL19 -> 120 | T19: ='Energy Readings'!AN19 -> 54 | U19: ='Energy Readings'!AP19 -> 66 | V19: ='Energy Readings'!AR19 -> 88 | W19: ='Energy Readings'!AT19 -> 345 | X19: ='Energy Readings'!AV19 -> 622 | Y19: ='Energy Readings'!AX19 -> 78 | Z19: ='Energy Readings'!AZ19 -> 822 | AA19: ='Energy Readings'!BB19 -> 655 | AB19: ='Energy Readings'!BD19 -> 232 | AC19: ='Energy Readings'!BF19 -> 68 | AD19: ='Energy Readings'!BH19 -> 35 | AE19: ='Energy Readings'!BJ19 -> 122 | AF19: =SUM(B19:AE19) -> 17353.3
A20: COAL MILL | K20: ='Energy Readings'!V20 -> 0 | Z20: ='Energy Readings'!AZ20 -> 0 | AB20: ='Energy Readings'!BD20 -> 0 | AC20: ='Energy Readings'!BF20 -> 0 | AD20: ='Energy Readings'!BH20 -> 0 | AE20: ='Energy Readings'!BJ20 -> 0
A21: 521CM1 | B21: ='Energy Readings'!D21 -> 9039 | C21: ='Energy Readings'!F21-79 -> 8531 | D21: ='Energy Readings'!H21 -> 6690 | E21: ='Energy Readings'!J21+200 -> 9228 | F21: ='Energy Readings'!L21 -> 8435 | G21: ='Energy Readings'!N21 -> 8020 | H21: ='Energy Readings'!P21 -> 7383 | I21: ='Energy Readings'!R21-500 -> 7500 | J21: ='Energy Readings'!T21 -> 7659 | K21: ='Energy Readings'!V21 -> 8936 | L21: ='Energy Readings'!X21 -> 7301 | M21: ='Energy Readings'!Z21 -> 8206 | N21: ='Energy Readings'!AB21 -> 7802 | O21: ='Energy Readings'!AD21 -> 7805 | P21: ='Energy Readings'!AF21 -> 7873 | Q21: ='Energy Readings'!AH21 -> 8574 | R21: ='Energy Readings'!AJ21 -> 8542 | S21: ='Energy Readings'!AL21 -> 8013 | T21: ='Energy Readings'!AN21 -> 7877 | U21: ='Energy Readings'!AP21 -> 7803 | V21: ='Energy Readings'!AR21 -> 6356 | W21: ='Energy Readings'!AT21 -> 6067 | X21: ='Energy Readings'!AV21 -> 752 | Y21: ='Energy Readings'!AX21 -> 4581 | Z21: ='Energy Readings'!AZ21 -> 8944 | AA21: ='Energy Readings'!BB21-300 -> 7632 | AB21: ='Energy Readings'!BD21 -> 8571 | AC21: ='Energy Readings'!BF21 -> 7865 | AD21: ='Energy Readings'!BH21 -> 7468 | AE21: ='Energy Readings'!BJ21+500 -> 4989 | AF21: =SUM(B21:AE21) -> 224442
A22: 521 FN1 | B22: ='Energy Readings'!D22 -> 768 | C22: ='Energy Readings'!F22 -> 769 | D22: ='Energy Readings'!H22 -> 767 | E22: ='Energy Readings'!J22+200 -> 969 | F22: ='Energy Readings'!L22 -> 640 | G22: ='Energy Readings'!N22 -> 768 | H22: ='Energy Readings'!P22 -> 767 | I22: ='Energy Readings'!R22 -> 768 | J22: ='Energy Readings'!T22 -> 641 | K22: ='Energy Readings'!V22 -> 767 | L22: ='Energy Readings'!X22 -> 769 | M22: ='Energy Readings'!Z22 -> 768 | N22: ='Energy Readings'!AB22 -> 767 | O22: ='Energy Readings'!AD22 -> 769 | P22: ='Energy Readings'!AF22 -> 767 | Q22: ='Energy Readings'!AH22 -> 769 | R22: ='Energy Readings'!AJ22 -> 768 | S22: ='Energy Readings'!AL22 -> 768 | T22: ='Energy Readings'!AN22 -> 639 | U22: ='Energy Readings'!AP22 -> 769 | V22: ='Energy Readings'!AR22 -> 639 | W22: ='Energy Readings'!AT22 -> 640 | X22: ='Energy Readings'!AV22 -> 257 | Y22: ='Energy Readings'!AX22 -> 512 | Z22: ='Energy Readings'!AZ22 -> 768 | AA22: ='Energy Readings'!BB22+10 -> 778 | AB22: ='Energy Readings'!BD22 -> 768 | AC22: ='Energy Readings'!BF22 -> 639 | AD22: ='Energy Readings'!BH22 -> 641 | AE22: ='Energy Readings'!BJ22 -> 512 | AF22: =SUM(B22:AE22) -> 21331
A23: COAL MILL AUXILIRIES-IPMCC4(TR8) | B23: ='Energy Readings'!D23-B26-B27-B28-B72-B75-B22 -> 5442.43 | C23: ='Energy Readings'!F23-C26-C27-C28-C72-C75-C22 -> 5312.26 | D23: ='Energy Readings'!H23-D26-D27-D28-D72-D75-D22 -> 4680.35 | E23: ='Energy Readings'!J23-E26-E27-E28-E72-E75-E22+100 -> 5348.86 | F23: ='Energy Readings'!L23-F26-F27-F28-F72-F75-F22 -> 5476.02 | G23: ='Energy Readings'!N23-G26-G27-G28-G72-G75-G22 -> 5264.81 | H23: ='Energy Readings'!P23-H26-H27-H28-H72-H75-H22 -> 5315.15 | I23: ='Energy Readings'!R23-I26-I27-I28-I72-I75-I22 -> 5355.8 | J23: ='Energy Readings'!T23-J26-J27-J28-J72-J75-J22 -> 5259.41 | K23: ='Energy Readings'!V23-K26-K27-K28-K72-K75-K22 -> 5393.75 | L23: ='Energy Readings'!X23-L26-L27-L28-L72-L75-L22 -> 5281.88 | M23: ='Energy Readings'!Z23-M26-M27-M28-M72-M75-M22 -> 5217.44 | N23: ='Energy Readings'!AB23-N26-N27-N28-N72-N75-N22 -> 5146.8 | O23: ='Energy Readings'!AD23-O26-O27-O28-O72-O75-O22 -> 5180.67 | P23: ='Energy Readings'!AF23-P26-P27-P28-P72-P75-P22 -> 5110.33 | Q23: ='Energy Readings'!AH23-Q26-Q27-Q28-Q72-Q75-Q22 -> 5252.67 | R23: ='Energy Readings'!AJ23-R26-R27-R28-R72-R75-R22 -> 5372.9 | S23: ='Energy Readings'!AL23-S26-S27-S28-S72-S75-S22 -> 5134.68 | T23: ='Energy Readings'!AN23-T26-T27-T28-T72-T75-T22 -> 5159.01 | U23: ='Energy Readings'!AP23-U26-U27-U28-U72-U75-U22 -> 5366.5 | V23: ='Energy Readings'!AR23-V26-V27-V28-V72-V75-V22 -> 5586.49 | W23: ='Energy Readings'!AT23-W26-W27-W28-W72-W75-W22 -> 5345.9 | X23: ='Energy Readings'!AV23-X26-X27-X28-X72-X75-X22 -> 2261.82 | Y23: ='Energy Readings'!AX23-Y26-Y27-Y28-Y72-Y75-Y22 -> 4109.8 | Z23: ='Energy Readings'!AZ23-Z26-Z27-Z28-Z72-Z75-Z22 -> 5495.48 | AA23: ='Energy Readings'!BB23-AA26-AA27-AA28-AA72-AA75-AA22-100 -> 5523.29 | AB23: ='Energy Readings'!BD23-AB26-AB27-AB28-AB72-AB75-AB22 -> 5611.9 | AC23: ='Energy Readings'!BF23-AC26-AC27-AC28-AC72-AC75-AC22 -> 5585.41 | AD23: ='Energy Readings'!BH23-AD26-AD27-AD28-AD72-AD75-AD22 -> 5508.68 | AE23: ='Energy Readings'!BJ23-AE26-AE27-AE28-AE72-AE75-AE22 -> 3340.73 | AF23: =SUM(B23:AE23) -> 153441.22
A24: NEW COAL MILL AUX. NEW MCC (TR12) | B24: ='Energy Readings'!D24-B25 -> 1116.7 | C24: ='Energy Readings'!F24-C25 -> 1068.3 | D24: ='Energy Readings'!H24-D25 -> 985.8 | E24: ='Energy Readings'!J24-E25 -> 1077.4 | F24: ='Energy Readings'!L24-F25 -> 1018.5 | G24: ='Energy Readings'!N24-G25 -> 1013.7 | H24: ='Energy Readings'!P24-H25 -> 1697 | I24: ='Energy Readings'!R24-I25 -> 374.9 | J24: ='Energy Readings'!T24-J25 -> 998.8 | K24: ='Energy Readings'!V24-K25 -> 1055.4 | L24: ='Energy Readings'!X24-L25 -> 959.6 | M24: ='Energy Readings'!Z24-M25 -> 960.8 | N24: ='Energy Readings'!AB24-N25 -> 988.7 | O24: ='Energy Readings'!AD24-O25 -> 1001.4 | P24: ='Energy Readings'!AF24-P25 -> 990.2 | Q24: ='Energy Readings'!AH24-Q25 -> 1029.6 | R24: ='Energy Readings'!AJ24-R25 -> 1061.6 | S24: ='Energy Readings'!AL24-S25 -> 1050.6 | T24: ='Energy Readings'!AN24-T25 -> 1046.9 | U24: ='Energy Readings'!AP24-U25 -> 1032.6 | V24: ='Energy Readings'!AR24-V25 -> 956.1 | W24: ='Energy Readings'!AT24-W25 -> 887.7 | X24: ='Energy Readings'!AV24-X25 -> 364.4 | Y24: ='Energy Readings'!AX24-Y25 -> 723.3 | Z24: ='Energy Readings'!AZ24-Z25 -> 1078 | AA24: ='Energy Readings'!BB24-AA25 -> 1054 | AB24: ='Energy Readings'!BD24-AB25 -> 1062.3 | AC24: ='Energy Readings'!BF24-AC25 -> 1055 | AD24: ='Energy Readings'!BH24-AD25 -> 1061.8 | AE24: ='Energy Readings'!BJ24-AE25 -> 820.6 | AF24: =SUM(B24:AE24) -> 29591.7
A25: LC-2A LIGHTING TR | B25: ='Energy Readings'!D25 -> 0 | C25: ='Energy Readings'!F25 -> 0 | D25: ='Energy Readings'!H25 -> 0 | E25: ='Energy Readings'!J25 -> 0 | F25: ='Energy Readings'!L25 -> 0 | G25: ='Energy Readings'!N25 -> 0 | H25: ='Energy Readings'!P25 -> 0 | I25: ='Energy Readings'!R25 -> 0 | J25: ='Energy Readings'!T25 -> 0 | K25: ='Energy Readings'!V25 -> 0 | L25: ='Energy Readings'!X25 -> 0 | M25: ='Energy Readings'!Z25 -> 0 | N25: ='Energy Readings'!AB25 -> 0 | O25: ='Energy Readings'!AD25 -> 0 | P25: ='Energy Readings'!AF25 -> 0 | Q25: ='Energy Readings'!AH25 -> 0 | R25: ='Energy Readings'!AJ25 -> 0 | S25: ='Energy Readings'!AL25 -> 0 | T25: ='Energy Readings'!AN25 -> 0 | U25: ='Energy Readings'!AP25 -> 0 | V25: ='Energy Readings'!AR25 -> 0 | W25: ='Energy Readings'!AT25 -> 0 | X25: ='Energy Readings'!AV25 -> 0 | Y25: ='Energy Readings'!AX25 -> 0 | Z25: ='Energy Readings'!AZ25 -> 0 | AA25: ='Energy Readings'!BB25 -> 0 | AB25: ='Energy Readings'!BD25 -> 0 | AC25: ='Energy Readings'!BF25 -> 0 | AD25: ='Energy Readings'!BH25 -> 0 | AE25: ='Energy Readings'!BJ25 -> 0 | AF25: =SUM(B25:AE25) -> 0
A26: WELDING SUPPLY COAL MILL & KILN | B26: ='Energy Readings'!D26 -> 79 | C26: ='Energy Readings'!F26 -> 54 | D26: ='Energy Readings'!H26 -> 42 | E26: ='Energy Readings'!J26 -> 79 | F26: ='Energy Readings'!L26 -> 54 | G26: 52 | H26: ='Energy Readings'!P26 -> 54 | I26: ='Energy Readings'!R26 -> 54 | J26: ='Energy Readings'!T26 -> 54 | K26: ='Energy Readings'!V26 -> 54 | L26: ='Energy Readings'!X26 -> 54 | M26: ='Energy Readings'!Z26 -> 54 | N26: ='Energy Readings'!AB26 -> 54 | O26: ='Energy Readings'!AD26 -> 52 | P26: ='Energy Readings'!AF26 -> 54 | Q26: ='Energy Readings'!AH26 -> 54 | R26: ='Energy Readings'!AJ26 -> 54 | S26: ='Energy Readings'!AL26 -> 54 | T26: ='Energy Readings'!AN26 -> 54 | U26: ='Energy Readings'!AP26 -> 54 | V26: ='Energy Readings'!AR26 -> 54 | W26: ='Energy Readings'!AT26 -> 54 | X26: ='Energy Readings'!AV26 -> 189 | Y26: ='Energy Readings'!AX26 -> 68 | Z26: ='Energy Readings'!AZ26 -> 89 | AA26: ='Energy Readings'!BB26 -> 89 | AB26: ='Energy Readings'!BD26 -> 79 | AC26: ='Energy Readings'!BF26 -> 102 | AD26: ='Energy Readings'!BH26 -> 98.2 | AE26: ='Energy Readings'!BJ26 -> 54 | AF26: =SUM(B26:AE26) -> 1990.2
A27: A/C Supply LC-3 | B27: ='Energy Readings'!D27 -> 50 | C27: ='Energy Readings'!F27 -> 50 | D27: ='Energy Readings'!H27 -> 50 | E27: ='Energy Readings'!J27 -> 50 | F27: ='Energy Readings'!L27 -> 50 | G27: 50 | H27: ='Energy Readings'!P27 -> 50 | I27: ='Energy Readings'!R27 -> 50 | J27: ='Energy Readings'!T27 -> 50 | K27: ='Energy Readings'!V27 -> 50 | L27: ='Energy Readings'!X27 -> 50 | M27: ='Energy Readings'!Z27 -> 50 | N27: ='Energy Readings'!AB27 -> 50 | O27: ='Energy Readings'!AD27 -> 50 | P27: ='Energy Readings'!AF27 -> 50 | Q27: ='Energy Readings'!AH27 -> 50 | R27: ='Energy Readings'!AJ27 -> 50 | S27: ='Energy Readings'!AL27 -> 50 | T27: ='Energy Readings'!AN27 -> 50 | U27: ='Energy Readings'!AP27 -> 50 | V27: ='Energy Readings'!AR27 -> 50 | W27: ='Energy Readings'!AT27 -> 50 | X27: ='Energy Readings'!AV27 -> 50 | Y27: ='Energy Readings'!AX27 -> 50 | Z27: ='Energy Readings'!AZ27 -> 50 | AA27: ='Energy Readings'!BB27 -> 50 | AB27: ='Energy Readings'!BD27 -> 50 | AC27: ='Energy Readings'!BF27 -> 50 | AD27: ='Energy Readings'!BH27 -> 50 | AE27: ='Energy Readings'!BJ27 -> 50 | AF27: =SUM(B27:AE27) -> 1500
A28: Supply for CCR | B28: ='Energy Readings'!D28 -> 881.77 | C28: ='Energy Readings'!F28 -> 994.54 | D28: ='Energy Readings'!H28 -> 946.25 | E28: ='Energy Readings'!J28 -> 878.14 | F28: ='Energy Readings'!L28 -> 862.98 | G28: ='Energy Readings'!N28 -> 760.79 | H28: ='Energy Readings'!P28 -> 724.45 | I28: ='Energy Readings'!R28 -> 955.2 | J28: ='Energy Readings'!T28 -> 875.39 | K28: ='Energy Readings'!V28 -> 797.45 | L28: ='Energy Readings'!X28 -> 746.52 | M28: ='Energy Readings'!Z28 -> 759.16 | N28: ='Energy Readings'!AB28 -> 601.8 | O28: ='Energy Readings'!AD28 -> 534.93 | P28: ='Energy Readings'!AF28 -> 742.47 | Q28: ='Energy Readings'!AH28 -> 711.53 | R28: ='Energy Readings'!AJ28 -> 702.3 | S28: ='Energy Readings'!AL28 -> 700.12 | T28: ='Energy Readings'!AN28 -> 700.59 | U28: ='Energy Readings'!AP28 -> 598.7 | V28: ='Energy Readings'!AR28 -> 458.31 | W28: ='Energy Readings'!AT28 -> 692.3 | X28: ='Energy Readings'!AV28 -> 665.38 | Y28: ='Energy Readings'!AX28 -> 722 | Z28: ='Energy Readings'!AZ28 -> 708.32 | AA28: ='Energy Readings'!BB28 -> 725.31 | AB28: ='Energy Readings'!BD28 -> 710.3 | AC28: ='Energy Readings'!BF28 -> 663.39 | AD28: ='Energy Readings'!BH28 -> 757.72 | AE28: ='Energy Readings'!BJ28 -> 755.07 | AF28: =SUM(B28:AE28) -> 22333.18
A29: KILN | K29: ='Energy Readings'!V29 -> 0 | W29: ='Energy Readings'!AT29 -> 0 | X29: ='Energy Readings'!AV29 -> 0 | Z29: ='Energy Readings'!AZ29 -> 0 | AA29: ='Energy Readings'!BB29 -> 0 | AB29: ='Energy Readings'!BD29 -> 0 | AC29: ='Energy Readings'!BF29 -> 0 | AD29: ='Energy Readings'!BH29 -> 0 | AE29: ='Energy Readings'!BJ29 -> 0
A30: 431FN1 PRE-HEATER FAN | B30: ='Energy Readings'!D30 -> 25730.4 | C30: ='Energy Readings'!F30-200 -> 21349.6 | D30: ='Energy Readings'!H30 -> 17184 | E30: ='Energy Readings'!J30 -> 22888 | F30: ='Energy Readings'!L30 -> 23616.8 | G30: ='Energy Readings'!N30 -> 19135.2 | H30: ='Energy Readings'!P30 -> 19308 | I30: ='Energy Readings'!R30 -> 18484.8 | J30: ='Energy Readings'!T30 -> 17457.6 | K30: ='Energy Readings'!V30 -> 18747.2 | L30: ='Energy Readings'!X30-500 -> 17134.4 | M30: ='Energy Readings'!Z30 -> 21185.6 | N30: ='Energy Readings'!AB30 -> 17529.6 | O30: ='Energy Readings'!AD30 -> 16692 | P30: ='Energy Readings'!AF30+500 -> 18124.8 | Q30: ='Energy Readings'!AH30 -> 17615.2 | R30: ='Energy Readings'!AJ30 -> 19337.6 | S30: ='Energy Readings'!AL30 -> 18207.2 | T30: ='Energy Readings'!AN30+600 -> 18325.6 | U30: ='Energy Readings'!AP30 -> 17404 | V30: ='Energy Readings'!AR30+550 -> 14372.4 | W30: ='Energy Readings'!AT30 -> 10869 | X30: ='Energy Readings'!AV30 -> 1974 | Y30: ='Energy Readings'!AX30 -> 7953.3716 | Z30: ='Energy Readings'!AZ30 -> 18693.604 | AA30: ='Energy Readings'!BB30-100 -> 19021.024 | AB30: ='Energy Readings'!BD30 -> 19278.896 | AC30: ='Energy Readings'!BF30 -> 17977.648 | AD30: ='Energy Readings'!BH30 -> 21235.172 | AE30: ='Energy Readings'!BJ30+500 -> 10539.54 | AF30: =SUM(B30:AE30) -> 527372.26
A31: IMCC-4 | B31: ='Energy Readings'!D31-B19 -> 5445.34 | C31: ='Energy Readings'!F31-C19 -> 4584.9 | D31: ='Energy Readings'!H31-D19 -> 4170.35 | E31: ='Energy Readings'!J31-E19+100 -> 4402.7 | F31: ='Energy Readings'!L31-F19 -> 4387.85 | G31: ='Energy Readings'!N31-G19 -> 4454.51 | H31: ='Energy Readings'!P31-H19 -> 4355.29 | I31: ='Energy Readings'!R31-I19 -> 4513.93 | J31: ='Energy Readings'!T31-J19 -> 4119.85 | K31: ='Energy Readings'!V31-K19 -> 3936.52 | L31: ='Energy Readings'!X31-L19 -> 3112.6 | M31: ='Energy Readings'!Z31-M19 -> 3309.13 | N31: ='Energy Readings'!AB31-N19 -> 3172.2 | O31: ='Energy Readings'!AD31-O19 -> 3202.04 | P31: ='Energy Readings'!AF31-P19 -> 3959.92 | Q31: ='Energy Readings'!AH31-Q19 -> 4234.05 | R31: ='Energy Readings'!AJ31-R19 -> 4569.56 | S31: ='Energy Readings'!AL31-S19 -> 4777.67 | T31: ='Energy Readings'!AN31-T19 -> 4855.9 | U31: ='Energy Readings'!AP31-U19 -> 4749.23 | V31: ='Energy Readings'!AR31-V19 -> 4367.11 | W31: ='Energy Readings'!AT31-W19 -> 4146.92 | X31: ='Energy Readings'!AV31-X19 -> 2187.37 | Y31: ='Energy Readings'!AX31-Y19 -> 3955.7 | Z31: ='Energy Readings'!AZ31-Z19 -> 4383.41 | AA31: ='Energy Readings'!BB31-AA19 -> 4632.88 | AB31: ='Energy Readings'!BD31-AB19 -> 5048.32 | AC31: ='Energy Readings'!BF31-AC19 -> 5034.26 | AD31: ='Energy Readings'!BH31-AD19 -> 6409.35 | AE31: ='Energy Readings'!BJ31-AE19+1500 -> 4265.55 | AF31: =SUM(B31:AE31) -> 128744.41
A32: BOOSTER FAN | B32: ='Energy Readings'!D32 -> 0 | C32: 0 | D32: 0 | E32: 0 | F32: 0 | G32: 0 | H32: 0 | I32: 0 | J32: 0 | K32: 0 | L32: 0 | M32: 0 | N32: 0 | O32: 0 | P32: 0 | Q32: 0 | R32: 0 | S32: 0 | T32: 0 | U32: 0 | V32: 0 | W32: 0 | X32: 0 | Y32: 0 | Z32: 0 | AA32: 0 | AB32: 0 | AE32: ='Energy Readings'!BJ32 -> 0 | AF32: =SUM(B32:AE32) -> 0
A33: COOLER DRIVES(IPMCC-3)(TR7) | B33: ='Energy Readings'!D33-B76 -> 13810.5 | C33: ='Energy Readings'!F33-C76 -> 13464 | D33: ='Energy Readings'!H33-D76 -> 12113.9 | E33: ='Energy Readings'!J33-E76+100 -> 14059.8 | F33: ='Energy Readings'!L33-F76 -> 13413.1 | G33: ='Energy Readings'!N33-G76 -> 12748.7 | H33: ='Energy Readings'!P33-H76 -> 12971.1 | I33: ='Energy Readings'!R33-I76-500 -> 12887.4 | J33: ='Energy Readings'!T33-J76 -> 12621.6 | K33: ='Energy Readings'!V33-K76 -> 12202.7 | L33: ='Energy Readings'!X33-L76 -> 11978.4 | M33: ='Energy Readings'!Z33-M76 -> 12982.6 | N33: ='Energy Readings'!AB33-N76 -> 12493.5 | O33: ='Energy Readings'!AD33-O76 -> 13479.4 | P33: ='Energy Readings'!AF33-P76 -> 12647.3 | Q33: ='Energy Readings'!AH33-Q76 -> 11925.9 | R33: ='Energy Readings'!AJ33-R76 -> 12043.1 | S33: ='Energy Readings'!AL33-S76 -> 12399.2 | T33: ='Energy Readings'!AN33-T76 -> 11821.7 | U33: ='Energy Readings'!AP33-U76 -> 12723.3 | V33: ='Energy Readings'!AR33-V76 -> 11021.9 | W33: ='Energy Readings'!AT33-W76 -> 11790.2 | X33: ='Energy Readings'!AV33-X76 -> 2169.4 | Y33: ='Energy Readings'!AX33-Y76 -> 7249.3 | Z33: ='Energy Readings'!AZ33-Z76 -> 12743.7 | AA33: ='Energy Readings'!BB33-AA76-100 -> 12834.2 | AB33: ='Energy Readings'!BD33-AB76 -> 12714.1 | AC33: ='Energy Readings'!BF33-AC76 -> 12668 | AD33: ='Energy Readings'!BH33-AD76 -> 13056.4 | AE33: ='Energy Readings'!BJ33-AE76 -> 6360.6 | AF33: =SUM(B33:AE33) -> 357395
A34: COMPRESSOR-3 (321CP3) | B34: ='Energy Readings'!D34 -> 0 | C34: ='Energy Readings'!F34 -> 0 | D34: ='Energy Readings'!H34 -> 0 | E34: ='Energy Readings'!J34 -> 0 | F34: ='Energy Readings'!L34 -> 0 | G34: ='Energy Readings'!N34 -> 0 | H34: ='Energy Readings'!P34 -> 0 | I34: ='Energy Readings'!R34 -> 0 | J34: ='Energy Readings'!T34 -> 1.07 | K34: ='Energy Readings'!V34 -> 0 | L34: ='Energy Readings'!X34 -> 2.46 | M34: ='Energy Readings'!Z34 -> 0 | N34: ='Energy Readings'!AB34 -> 1.83 | O34: ='Energy Readings'!AD34 -> 0 | P34: ='Energy Readings'!AF34 -> 0 | Q34: ='Energy Readings'!AH34 -> 12.01 | R34: ='Energy Readings'!AJ34 -> 0 | S34: ='Energy Readings'!AL34 -> 7.3 | T34: ='Energy Readings'!AN34 -> 0 | U34: ='Energy Readings'!AP34 -> 0.03 | V34: ='Energy Readings'!AR34 -> 0 | W34: ='Energy Readings'!AT34 -> 0 | X34: ='Energy Readings'!AV34 -> 0 | Y34: ='Energy Readings'!AX34 -> 0 | Z34: ='Energy Readings'!AZ34 -> 0 | AA34: ='Energy Readings'!BB34 -> 97.76 | AB34: ='Energy Readings'!BD34 -> 681.26 | AC34: ='Energy Readings'!BF34 -> 674.98 | AD34: 314 | AE34: ='Energy Readings'!BJ34 -> 0.71 | AF34: =SUM(B34:AE34) -> 1793.41
A35: COMPRESSOR-2(PCC-2 @ 321CP2) | B35: ='Energy Readings'!D35 -> 0 | C35: ='Energy Readings'!F35 -> 0 | D35: ='Energy Readings'!H35 -> 0 | E35: ='Energy Readings'!J35 -> 23.05 | F35: ='Energy Readings'!L35 -> 950.15 | G35: ='Energy Readings'!N35 -> 6.39 | H35: ='Energy Readings'!P35 -> 0 | I35: ='Energy Readings'!R35 -> 0 | J35: ='Energy Readings'!T35 -> 11.93 | K35: ='Energy Readings'!V35 -> 0 | L35: ='Energy Readings'!X35 -> 0 | M35: ='Energy Readings'!Z35 -> 0 | N35: ='Energy Readings'!AB35 -> 0 | O35: ='Energy Readings'!AD35 -> 0 | P35: ='Energy Readings'!AF35 -> 0 | Q35: ='Energy Readings'!AH35 -> 149.47 | R35: ='Energy Readings'!AJ35 -> 0 | S35: ='Energy Readings'!AL35 -> 861 | T35: ='Energy Readings'!AN35 -> 0 | U35: ='Energy Readings'!AP35 -> 11.77 | V35: ='Energy Readings'!AR35 -> 0 | W35: ='Energy Readings'!AT35 -> 14.73 | X35: ='Energy Readings'!AV35 -> 0 | Y35: ='Energy Readings'!AX35 -> 0 | Z35: ='Energy Readings'!AZ35 -> 973.66 | AA35: ='Energy Readings'!BB35 -> 1124.96 | AB35: ='Energy Readings'!BD35 -> 0 | AC35: ='Energy Readings'!BF35 -> 0 | AD35: ='Energy Readings'!BH35 -> 3.5 | AE35: ='Energy Readings'!BJ35 -> 1.91 | AF35: =SUM(B35:AE35) -> 4132.52
A36: COMPRESSOR-4(PCC-2 @321CP4) | B36: ='Energy Readings'!D36 -> 1386.04 | C36: ='Energy Readings'!F36 -> 1780.75 | D36: ='Energy Readings'!H36 -> 1510.76 | E36: ='Energy Readings'!J36 -> 800.71 | F36: ='Energy Readings'!L36 -> 1159.44 | G36: ='Energy Readings'!N36 -> 2094.23 | H36: ='Energy Readings'!P36 -> 2209.35 | I36: ='Energy Readings'!R36-500 -> 1793.23 | J36: ='Energy Readings'!T36 -> 2209.54 | K36: ='Energy Readings'!V36 -> 2206.19 | L36: ='Energy Readings'!X36 -> 1762.36 | M36: ='Energy Readings'!Z36 -> 89.68 | N36: ='Energy Readings'!AB36 -> 520.48 | O36: ='Energy Readings'!AD36-500 -> 2089.26 | P36: ='Energy Readings'!AF36 -> 2646.12 | Q36: ='Energy Readings'!AH36 -> 2183.09 | R36: ='Energy Readings'!AJ36 -> 2291.76 | S36: ='Energy Readings'!AL36 -> 1503.8 | T36: ='Energy Readings'!AN36 -> 2373.22 | U36: ='Energy Readings'!AP36 -> 2294.11 | V36: ='Energy Readings'!AR36 -> 2281.87 | W36: ='Energy Readings'!AT36 -> 2300.39 | X36: ='Energy Readings'!AV36 -> 1913.49 | Y36: ='Energy Readings'!AX36 -> 2165.12 | Z36: ='Energy Readings'!AZ36 -> 1476.37 | AA36: ='Energy Readings'!BB36 -> 959.17 | AB36: ='Energy Readings'!BD36 -> 102.59 | AC36: ='Energy Readings'!BF36 -> 67.52 | AD36: ='Energy Readings'!BH36 -> 443.07 | AE36: ='Energy Readings'!BJ36 -> 1316.35 | AF36: =SUM(B36:AE36) -> 47930.06
A37: KILN MAIN DRIVE(441MU1-TR14) | B37: ='Energy Readings'!D37 -> 2468.56 | C37: ='Energy Readings'!F37 -> 2338.4 | D37: ='Energy Readings'!H37 -> 1782.26 | E37: ='Energy Readings'!J37 -> 2306.08 | F37: ='Energy Readings'!L37 -> 2238.66 | G37: ='Energy Readings'!N37 -> 2274.66 | H37: ='Energy Readings'!P37 -> 1935.7 | I37: ='Energy Readings'!R37 -> 1664.3 | J37: ='Energy Readings'!T37 -> 1718.96 | K37: ='Energy Readings'!V37 -> 1848.4352 | L37: ='Energy Readings'!X37 -> 1694.1232 | M37: ='Energy Readings'!Z37 -> 1813.642 | N37: ='Energy Readings'!AB37 -> 1628.486 | O37: ='Energy Readings'!AD37 -> 1718.4822 | P37: ='Energy Readings'!AF37 -> 1944.4778 | Q37: ='Energy Readings'!AH37 -> 2217.665 | R37: ='Energy Readings'!AJ37 -> 2379.959 | S37: ='Energy Readings'!AL37 -> 2262.218 | T37: ='Energy Readings'!AN37 -> 2231.978 | U37: ='Energy Readings'!AP37 -> 1910.594 | V37: ='Energy Readings'!AR37 -> 1360.13 | W37: ='Energy Readings'!AT37 -> 1475.312 | X37: ='Energy Readings'!AV37 -> 23.892 | Y37: ='Energy Readings'!AX37 -> 836.348 | Z37: ='Energy Readings'!AZ37 -> 2251.336 | AA37: ='Energy Readings'!BB37 -> 2320.596 | AB37: ='Energy Readings'!BD37 -> 2034.292 | AC37: ='Energy Readings'!BF37 -> 1840.048 | AD37: ='Energy Readings'!BH37 -> 2236.204 | AE37: ='Energy Readings'!BJ37 -> 1143.064 | AF37: =SUM(B37:AE37) -> 55898.862
