Workbook

Sheet Go-Live Master Tracker
A1: Lake Cement MIS – Go-Live Master Tracker
A2: Pending work before test rollout and production go-live · Evidence checked against the code, database and live server on 17-Sep-2026 · Deadlines are PROPOSED, worked back from a pilot start of Mon 5-Oct-2026 (no dates are recorded in the project) – confirm under OPS-01
A5: Task ID | B5: Work Stream | C5: Pending Task | D5: Status | E5: Owner | F5: Owner Department | G5: Coordination Required | H5: Dependencies | I5: Deadline | J5: Cost Responsibility | K5: Rollout Gate | L5: Priority | M5: Management Input? | N5: Cross-Dept Coordination? | O5: Current State / Evidence (verified 17-Sep-2026) | P5: Source
A6: INF-01 | B6: Hosting & Infrastructure | C6: Turn on HTTPS for the MIS site: approve the hostname (atlas.lakecement.co.tz, or the interim 138.68.166.86.nip.io), create the DNS record, issue the TLS certificate, and set ALLOWED_ORIGIN / APP_URL to the https address. | D6: Not Started | E6: Teckzilla – Odoo & hosting vendor (contact: Ankita) | F6: External – Odoo vendor | G6: IT (Saurabh Bhattacharya): approve hostname and create DNS record on lakecement.co.tz. MIS: retest login and invite links on the https URL. | H6: — | I6: 46294 | J6: Nil – free Let's Encrypt certificate and existing company domain; server admin effort under the Odoo vendor arrangement (SP-04) | K6: Test rollout | L6: Critical | M6: No | N6: Yes | O6: Checked 17-Sep-2026: http://138.68.166.86/api/health answers 200 (nginx 1.24.0) but port 443 refuses connections, so passwords and session tokens travel unencrypted. atlas.lakecement.co.tz does not resolve in DNS yet. | P6: Live check of production; docs/DEPLOYMENT_DIGITALOCEAN.md §2.7
A7: INF-02 | B7: Hosting & Infrastructure | C7: Move nightly database backups off the application disk (second volume, object storage or network share), then run a restore drill on the production server and record the result. | D7: In Progress | E7: Teckzilla – Odoo & hosting vendor (contact: Ankita) | F7: External – Odoo vendor | G7: IT: choose the backup destination and how long backups are kept. Finance: approve the storage cost. MIS: run the restore drill (npm run restore:drill). | H7: — | I7: 46297 | J7: Lake Cement – recurring storage fee, amount TBC (SP-02) | K7: Test rollout | L7: High | M7: No | N7: Yes | O7: Production health on 17-Sep reports status "degraded": the last backup is 3.7 hours old, but same_disk_as_app = true, so one disk failure loses the database and its backups together. No restore drill on the server is recorded. | P7: Live /api/health; RAID I-7; DEPLOYMENT_DIGITALOCEAN.md §4
A8: INF-03 | B8: Hosting & Infrastructure | C8: Confirm which code version production is running and that the GitHub test-then-deploy pipeline is healthy (secrets set, last run green). Record the deployed commit. | D8: Not Started | E8: Razak Mbaga (MIS developer) | F8: IT / MIS | G8: Odoo vendor: server access and pm2 logs if the version cannot be read remotely. | H8: — | I8: 46290 | J8: Internal – MIS staff time, no cash cost | K8: Test rollout | L8: High | M8: No | N8: Yes | O8: The production process restarted about 06:01 UTC on 15-Sep, 3 minutes after commit 33d3691 was pushed to main, so that commit is probably what is live. This is not confirmed: the health check reports no version. RAID assumption A-1 is still open. | P8: Live /api/health uptime; git log origin/main; RAID A-1
A9: INF-04 | B9: Hosting & Infrastructure | C9: Set up a private, encrypted network path from the MIS server to the production Odoo server (VPC, VPN or firewalled endpoint). | D9: Not Started | E9: Teckzilla – Odoo & hosting vendor (contact: Ankita) | F9: External – Odoo vendor | G9: IT: network and security approval. | H9: ODO-01 | I9: 46325 | J9: TBC – a VPN or network link may carry a cost; confirm who pays under GOV-01 (SP-05) | K9: Production go-live | L9: High | M9: No | N9: Yes | O9: The Odoo connectors call a test server (46.101.75.211) over plain HTTP, with the API key in the request body. TECHNICAL_SPEC §12 Q8 (network path) is still open. | P9: backend/.env connector hosts; TECHNICAL_SPEC.md §12 Q8; DEPLOYMENT_DIGITALOCEAN.md §5
A10: INF-05 | B10: Hosting & Infrastructure | C10: Reboot test: restart the production server and confirm the site and /api/health come back with no manual step. | D10: Not Started | E10: Teckzilla – Odoo & hosting vendor (contact: Ankita) | F10: External – Odoo vendor | G10: MIS: confirm the health check and login afterwards. | H10: INF-01 | I10: 46297 | J10: Nil – no cash cost | K10: Test rollout | L10: Medium | M10: No | N10: Yes | O10: Required by the deployment guide's 'verify before calling it done' list. There is no record that it has been done. | P10: DEPLOYMENT_DIGITALOCEAN.md §2.8
A11: INF-06 | B11: Hosting & Infrastructure | C11: Move the code repository and deploy keys from the personal GitHub account (RazakMbaga3) to a company-owned GitHub organisation, keeping the test-before-deploy gate. | D11: Awaiting Decision | E11: Saurabh Bhattacharya (IT HOD) | F11: IT | G11: Management: approve company ownership. MIS: transfer the repository. Odoo vendor: update the server's deploy key. | H11: GOV-01 | I11: 46325 | J11: IT – possible GitHub paid plan for a company organisation, TBC (SP-11) | K11: Production go-live | L11: Medium | M11: Yes | N11: Yes | O11: Production pulls its code from github.com/RazakMbaga3/LakeCement-Reports-KPIDashboards. A company system of record depends on one person's account, which is a continuity and access risk. | P11: DEPLOYMENT_DIGITALOCEAN.md §0
A12: SEC-01 | B12: Security | C12: Check, and if needed change, the Odoo-bundled Postgres superuser password (openpg), which ships with a publicly documented default, on every server where it exists. | D12: Not Started | E12: Teckzilla – Odoo & hosting vendor (contact: Ankita) | F12: External – Odoo vendor | G12: IT: confirm which servers run the Odoo-bundled Postgres. | H12: — | I12: 46295 | J12: Nil – no cash cost | K12: Test rollout | L12: High | M12: No | N12: Yes | O12: RAID R-4 is unverified. It cannot be closed from the code and needs a live database check. | P12: RAID_LOG R-4; GO_LIVE_CHECKLIST §3
A13: SEC-02 | B13: Security | C13: Remove test and scratch accounts before real users log in (uitest_verify has admin rights), and decide whether the automation accounts import-pm / import-production stay active. | D13: Not Started | E13: Razak Mbaga (MIS developer) | F13: IT / MIS | G13: IT HOD: sign off the removal list. Check the production database as well as the local one. | H13: — | I13: 46295 | J13: Nil – no cash cost | K13: Test rollout | L13: Critical | M13: No | N13: Yes | O13: In the local database on 17-Sep, uitest_verify is still active with role = admin, and import-pm and import-production are active. ap_md and ap_production are already gone locally. The production database has not been checked. | P13: Local DB query 17-Sep; USER_ACCOUNT_STANDARDIZATION.md §B.5
A14: SEC-03 | B14: Security | C14: Retire every default password: send invite or reset links to all active accounts, rotate admin, and change the temporary passwords set for the stores and pm import scripts. | D14: Blocked | E14: Razak Mbaga (MIS developer) | F14: IT / MIS | G14: IT: email must work first (EML-01). All HODs: make sure each holder completes set-password. | H14: EML-01, ACC-03, INF-01 | I14: 46297 | J14: Nil – no cash cost | K14: Test rollout | L14: Critical | M14: No | N14: Yes | O14: In the local database on 17-Sep, 37 of 46 active accounts are still flagged must-change-password, and the seed passwords are committed in backend/db/seed.js. The invite flow is built but cannot send email. | P14: Local DB query 17-Sep; USER_ACCOUNT_STANDARDIZATION.md §B.3
A15: SEC-04 | B15: Security | C15: Ratify the two approval rules set on the Plant Head's behalf: DEC-003 (E&I HOD approves Power Consumption, P&M keeps submit) and DEC-004 (Packing submits Dispatch & SO, Logistics approves). | D15: Awaiting Decision | E15: Pavan Gandhi (Plant Head / COO) | F15: Operations | G15: E&I (Lokesh Thota), P&M HOD (name not yet given), Packing (Jatinder Dogra), Logistics (Pradeep Kumar). | H15: — | I15: 46289 | J15: Nil – no cash cost | K15: Test rollout | L15: High | M15: Yes | N15: Yes | O15: Both decisions were recorded by the developer 'on behalf of the Plant Head' and are marked 'should be confirmed with them'. | P15: docs/pm/DECISIONS.md DEC-003, DEC-004
A16: SEC-05 | B16: Security | C16: Decide the open access-policy gaps: (a) monthly MIS exports are readable by every role; (b) KPI viewing is restricted in the browser only, not on the server; (c) Sajiv Kumar (GM + Purchase HOD) and IPN Pathak (SBH + Sales HOD) only have their department's access. | D16: Awaiting Decision | E16: Pavan Gandhi (Plant Head / COO) | F16: Operations | G16: IT HOD. Purchase (Sajiv Kumar) and Sales (IPN Pathak) on their own access. MIS implements. | H16: — | I16: 46289 | J16: Nil – no cash cost | K16: Test rollout | L16: Medium | M16: Yes | N16: Yes | O16: Listed under 'Known gaps' 1 and 3 in the access model. Frontend-only KPI view gating is open decision 3 of the functional audit. | P16: docs/ACCESS_MODEL.md Known gaps; USER_ACCOUNT_STANDARDIZATION.md C2
A17: ACC-01 | B17: User Accounts & Access | C17: Decide the account policy: (a) staff without a company mailbox (shift operators, weighbridge): create mailboxes or allow a supervised shared login; (b) three accounts per department or one per person who enters data; (c) who approves an access request. | D17: Awaiting Decision | E17: Pavan Gandhi (Plant Head / COO) | F17: Operations | G17: IT HOD: mailbox provisioning. HR (Sophia Mkassi): staff records. Finance: licence cost if new mailboxes are needed. | H17: — | I17: 46289 | J17: IT – Microsoft 365 licences only if new mailboxes are created (SP-10) | K17: Test rollout | L17: High | M17: Yes | N17: Yes | O17: Open questions F.2–F.4 in the account standardisation plan are unanswered. | P17: USER_ACCOUNT_STANDARDIZATION.md §F
... A55: GOV-02 | B55: Governance & Budget | C55: Update the go-live documents to match the cloud setup (GO_LIVE_CHECKLIST §1 and §3: account hygiene, metrics token, sign-off record) and record the named Plant Head and MD in the RACI. | D55: Not Started | E55: Razak Mbaga (MIS developer) | F55: IT / MIS | G55: Odoo vendor: confirm server-side steps. | H55: OPS-01 | I55: 46311 | J55: Internal – MIS staff time, no cash cost | K55: Production go-live | L55: Low | M55: No | N55: Yes | O55: The checklist's own banner says §1 and §3 still need re-authoring for the cloud host. | P55: GO_LIVE_CHECKLIST banner; docs/pm/RACI.md
A57: How to read this
A58: Rollout Gate: 'Test rollout' = must be done before the pilot starts · 'Production go-live' = before the MIS replaces Excel · 'Post go-live' = improvement, not a blocker.
A59: Deadline cells turn red automatically when the date has passed and Status is not Done. Status, Priority, Gate and Yes/No columns have drop-down lists.
A60: Owner names are taken from docs/USER_ACCOUNT_STANDARDIZATION.md (3-Sep-2026). The P&M HOD has not been named in the project.
A61: Cost amounts are tracked on the 'Spending Tracker' sheet; task-to-task links and department involvement are on 'Dependency Matrix'.
A62: To add a task, insert a row above this note so the filters, drop-downs and the Top 10 snapshot counts include it.

Sheet Spending Tracker
A1: Lake Cement MIS – Spending Tracker
A2: No cost, budget, contract or invoice figures exist anywhere in the project files, so every amount is blank on purpose. Enter figures from quotes and invoices; variance and currency totals calculate automatically.
A5: Cost ID | B5: Item | C5: Category | D5: Linked Task(s) | E5: Cost Type | F5: Cost Responsibility (who pays) | G5: Budget Approver | H5: Currency | I5: Estimated Amount | J5: Approved Budget | K5: Committed (PO / contract ref.) | L5: Actual Spent to Date | M5: Variance (Budget – Actual) | N5: Status | O5: Notes / What is needed
A6: SP-01 | B6: Production application server (DigitalOcean droplet 138.68.166.86) | C6: Hosting | D6: INF-01, INF-02, INF-05 | E6: Recurring – monthly | F6: TBC – account administered by Odoo vendor (GOV-01) | G6: Sankalp Jaithalia (CFO) | H6: USD | M6: =IF(OR(J6="",L6=""),"",J6-L6) | N6: Running – cost not recorded | O6: Ask the Odoo vendor for the current plan size and last invoice. Nothing is recorded in the project.
A7: SP-02 | B7: Off-server backup storage (extra volume, object storage or network share) | C7: Hosting | D7: INF-02 | E7: Recurring – monthly | F7: Lake Cement IT (TBC) | G7: Saurabh Bhattacharya (IT HOD) | H7: USD | M7: =IF(OR(J7="",L7=""),"",J7-L7) | N7: Quote needed | O7: Needed: production backups currently sit on the app disk. Size by database dump size × retention days.
A8: SP-03 | B8: Option: DigitalOcean Managed PostgreSQL (replaces self-managed database and backups) | C8: Hosting | D8: INF-02 | E8: Recurring – monthly | F8: TBC (GOV-01) | G8: Sankalp Jaithalia (CFO) | H8: USD | M8: =IF(OR(J8="",L8=""),"",J8-L8) | N8: Option – not decided | O8: Documented as Option B in the deployment guide. It would replace SP-02. Only one of SP-02/SP-03 is needed.
A9: SP-04 | B9: HTTPS certificate and DNS record for the MIS hostname | C9: Hosting | D9: INF-01 | E9: One-off | F9: Nil | G9: Saurabh Bhattacharya (IT HOD) | H9: USD | M9: =IF(OR(J9="",L9=""),"",J9-L9) | N9: No cash cost | O9: Let's Encrypt certificates are free, and the DNS record goes on the existing lakecement.co.tz domain.
A10: SP-05 | B10: Private network link between the MIS server and production Odoo (VPC / VPN) | C10: Hosting | D10: INF-04 | E10: TBC | F10: TBC (GOV-01) | G10: Saurabh Bhattacharya (IT HOD) | H10: USD | M10: =IF(OR(J10="",L10=""),"",J10-L10) | N10: Quote needed | O10: No cost if both servers can share a private network. A VPN or tunnel may cost extra.
A11: SP-06 | B11: Odoo vendor: connect the four report endpoints to the production Odoo database | C11: Vendor services | D11: ODO-01 | E11: One-off | F11: Odoo vendor contract – confirm in-scope or change request | G11: Sankalp Jaithalia (CFO) | M11: =IF(OR(J11="",L11=""),"",J11-L11) | N11: Scope/quote needed | O11: Confirm whether this is covered by the current Teckzilla agreement.
A12: SP-07 | B12: Odoo vendor: fix defects in existing endpoints (date filters, truncation, duplicates, ticket no.) | C12: Vendor services | D12: ODO-02 | E12: One-off | F12: Odoo vendor – expected no charge (defect) | G12: Sankalp Jaithalia (CFO) | M12: =IF(OR(J12="",L12=""),"",J12-L12) | N12: Confirm no charge | O12: These are defects in endpoints already delivered.
A13: SP-08 | B13: Odoo vendor: Production Entry endpoint, API service account, inventory/purchasing endpoints | C13: Vendor services | D13: ODO-03, ODO-04 | E13: One-off | F13: TBC – change request (GOV-01) | G13: Sankalp Jaithalia (CFO) | M13: =IF(OR(J13="",L13=""),"",J13-L13) | N13: Quote needed | O13: If production Odoo is an Enterprise edition, a new API user may need a user subscription. Confirm with the vendor.
A14: SP-09 | B14: Microsoft 365: sending mailbox digital@lakecement.co.tz and SMTP AUTH or Graph API | C14: Software & licences | D14: EML-01 | E14: Recurring – annual | F14: Lake Cement IT (existing licence) | G14: Saurabh Bhattacharya (IT HOD) | H14: USD | M14: =IF(OR(J14="",L14=""),"",J14-L14) | N14: Confirm existing | O14: The SMTP AUTH setting has no licence cost. Confirm the mailbox already holds a licence.
A15: SP-10 | B15: Microsoft 365 mailboxes for staff without a company email | C15: Software & licences | D15: ACC-01 | E15: Recurring – per user | F15: Lake Cement IT | G15: Saurabh Bhattacharya (IT HOD) | H15: USD | M15: =IF(OR(J15="",L15=""),"",J15-L15) | N15: Depends on ACC-01 | O15: Only if management decides every data-entry person gets a mailbox. Cost = number of users × licence price.
A16: SP-11 | B16: GitHub: company organisation for the code repository; CI minutes if browser tests join the deploy gate | C16: Software & licences | D16: INF-06, QA-03 | E16: Recurring – monthly | F16: Lake Cement IT (TBC) | G16: Saurabh Bhattacharya (IT HOD) | H16: USD | M16: =IF(OR(J16="",L16=""),"",J16-L16) | N16: Depends on INF-06 | O16: Today the repository sits on a personal account. The cost depends on the plan chosen and CI usage.
A17: SP-12 | B17: Data-entry devices or network fixes at plant entry points | C17: Equipment | D17: OPS-04 | E17: One-off – capex | F17: Lake Cement IT | G17: Saurabh Bhattacharya (IT HOD) | H17: TZS | M17: =IF(OR(J17="",L17=""),"",J17-L17) | N17: Depends on survey | O17: Only if the OPS-04 survey finds entry points without a working device or network.
A18: SP-13 | B18: Training sessions and printed quick-reference guides | C18: Training | D18: OPS-03 | E18: One-off | F18: Operations / HR | G18: Sophia Mkassi (HR HOD) | H18: TZS | M18: =IF(OR(J18="",L18=""),"",J18-L18) | N18: Estimate needed | O18: Mostly internal time. The cash cost is printing and any venue or refreshments.
A19: SP-14 | B19: Parallel run: staff double-entry (MIS + Excel) and daily checker, 2–4 weeks | C19: Internal effort | D19: OPS-02 | E19: One-off – internal | F19: Internal – no cash cost | G19: Pavan Gandhi (Plant Head / COO) | H19: TZS | M19: =IF(OR(J19="",L19=""),"",J19-L19) | N19: Plan staff time | O19: No cash cost, but it takes HOD and officer time every day of the window.
A20: SP-15 | B20: MIS development, testing and pilot support | C20: Internal effort | D20: APP-01, QA-01, OPS-05 | E20: Ongoing – internal | F20: Internal – no cash cost | G20: Saurabh Bhattacharya (IT HOD) | H20: TZS | M20: =IF(OR(J20="",L20=""),"",J20-L20) | N20: Plan staff time | O20: Delivered in-house by the MIS developer.
G22: Totals by currency
G23: Total (USD) | H23: USD | I23: =SUMIF($H$6:$H$21,"USD",I$6:I$21) | J23: =SUMIF($H$6:$H$21,"USD",J$6:J$21) | L23: =SUMIF($H$6:$H$21,"USD",L$6:L$21) | M23: =J23-L23
G24: Total (TZS) | H24: TZS | I24: =SUMIF($H$6:$H$21,"TZS",I$6:I$21) | J24: =SUMIF($H$6:$H$21,"TZS",J$6:J$21) | L24: =SUMIF($H$6:$H$21,"TZS",L$6:L$21) | M24: =J24-L24
G25: Total (INR) | H25: INR | I25: =SUMIF($H$6:$H$21,"INR",I$6:I$21) | J25: =SUMIF($H$6:$H$21,"INR",J$6:J$21) | L25: =SUMIF($H$6:$H$21,"INR",L$6:L$21) | M25: =J25-L25
A27: Currency totals are kept separate on purpose: adding USD, TZS and INR together gives a meaningless number. Vendor lines have no currency until quoted. Insert new cost lines above the Totals block so they are included.

Sheet Dependency Matrix
A1: Lake Cement MIS – Dependency Matrix
A2: Section A: read across a row. ● means the row's task cannot finish until the column's task is done. Section B: which department owns (O), coordinates on (C) or must decide/approve (D) each task.
A5: A. Task-to-task dependencies
A6: Task ID | B6: Task | C6: Rollout Gate | D6: Depends on (count) | E6: INF-01 | F6: INF-02 | G6: INF-03 | H6: INF-04 | I6: INF-05 | J6: INF-06 | K6: SEC-01 | L6: SEC-02 | M6: SEC-03 | N6: SEC-04 | O6: SEC-05 | P6: ACC-01 | Q6: ACC-02 | R6: ACC-03 | S6: ACC-04 | T6: EML-01 | U6: EML-02 | V6: EML-03 | W6: ODO-01 | X6: ODO-02 | Y6: ODO-03 | Z6: ODO-04 | AA6: ODO-05 | AB6: ODO-06 | AC6: DAT-01 | AD6: DAT-02 | AE6: DAT-03 | AF6: DAT-04 | AG6: DAT-05 | AH6: DAT-06 | AI6: APP-01 | AJ6: APP-02 | AK6: APP-03 | AL6: APP-04 | AM6: APP-05 | AN6: APP-06 | AO6: APP-07 | AP6: APP-08 | AQ6: APP-09 | AR6: QA-01 | AS6: QA-02 | AT6: QA-03 | AU6: OPS-01 | AV6: OPS-02 | AW6: OPS-03 | AX6: OPS-04 | AY6: OPS-05 | AZ6: OPS-06 | BA6: GOV-01 | BB6: GOV-02
A7: INF-01 | B7: Turn on HTTPS for the MIS site: approve the hostname… | C7: Test rollout | D7: =COUNTIF(E7:BB7,"●")
A8: INF-02 | B8: Move nightly database backups off the application disk (second… | C8: Test rollout | D8: =COUNTIF(E8:BB8,"●")
A9: INF-03 | B9: Confirm which code version production is running and that the GitHub… | C9: Test rollout | D9: =COUNTIF(E9:BB9,"●")
A10: INF-04 | B10: Set up a private, encrypted network path from the MIS server to the… | C10: Production go-live | D10: =COUNTIF(E10:BB10,"●") | W10: ●
A11: INF-05 | B11: Reboot test: restart the production server and confirm the site and… | C11: Test rollout | D11: =COUNTIF(E11:BB11,"●") | E11: ●
A12: INF-06 | B12: Move the code repository and deploy keys from the personal GitHub… | C12: Production go-live | D12: =COUNTIF(E12:BB12,"●") | BA12: ●
A13: SEC-01 | B13: Check, and if needed change, the Odoo-bundled Postgres superuser… | C13: Test rollout | D13: =COUNTIF(E13:BB13,"●")
A14: SEC-02 | B14: Remove test and scratch accounts before real users log in… | C14: Test rollout | D14: =COUNTIF(E14:BB14,"●")
A15: SEC-03 | B15: Retire every default password: send invite or reset links to all… | C15: Test rollout | D15: =COUNTIF(E15:BB15,"●") | E15: ● | R15: ● | T15: ●
A16: SEC-04 | B16: Ratify the two approval rules set on the Plant Head's behalf:… | C16: Test rollout | D16: =COUNTIF(E16:BB16,"●")
A17: SEC-05 | B17: Decide the open access-policy gaps: (a) monthly MIS exports are… | C17: Test rollout | D17: =COUNTIF(E17:BB17,"●")
A18: ACC-01 | B18: Decide the account policy: (a) staff without a company mailbox… | C18: Test rollout | D18: =COUNTIF(E18:BB18,"●")
A19: ACC-02 | B19: Collect the holder's name, company email, mobile and staff number… | C19: Test rollout | D19: =COUNTIF(E19:BB19,"●") | P19: ●
A20: ACC-03 | B20: Load the returned names in the admin screen, confirm each person's… | C20: Test rollout | D20: =COUNTIF(E20:BB20,"●") | Q20: ●
A21: ACC-04 | B21: Update LCL_Access_Matrix_2026.xlsx to the 15 current departments and… | C21: Production go-live | D21: =COUNTIF(E21:BB21,"●") | N21: ● | O21: ●
A22: EML-01 | B22: Enable SMTP AUTH for the digital@lakecement.co.tz mailbox in… | C22: Test rollout | D22: =COUNTIF(E22:BB22,"●")
A23: EML-02 | B23: Name who receives the 06:00 daily KPI digest and who receives system… | C23: Test rollout | D23: =COUNTIF(E23:BB23,"●")
A24: EML-03 | B24: Set the digest and alert recipients on the production server, send a… | C24: Test rollout | D24: =COUNTIF(E24:BB24,"●") | E24: ● | T24: ● | U24: ●
A25: ODO-01 | B25: Connect the MIS to the production Odoo database: deploy the four… | C25: Production go-live | D25: =COUNTIF(E25:BB25,"●")
A26: ODO-02 | B26: Fix the Odoo endpoint defects already reported: customer receipts… | C26: Production go-live | D26: =COUNTIF(E26:BB26,"●")
A27: ODO-03 | B27: Send the Production Entry API request (Odoo model… | C27: Post go-live | D27: =COUNTIF(E27:BB27,"●")
A28: ODO-04 | B28: Confirm the Purchases and Stores data sources: open purchase… | C28: Post go-live | D28: =COUNTIF(E28:BB28,"●") | W28: ●
A29: ODO-05 | B29: Provide the sales master data: the real Division → Zone → Sales… | C29: Production go-live | D29: =COUNTIF(E29:BB29,"●")
A30: ODO-06 | B30: Fix or retire the 'npm run odoo:test' check so it reports each live… | C30: Production go-live | D30: =COUNTIF(E30:BB30,"●")
A31: DAT-01 | B31: Decide the data baseline for the pilot: backfill July–September 2026… | C31: Test rollout | D31: =COUNTIF(E31:BB31,"●") | AU31: ●
A32: DAT-02 | B32: Remove demo and placeholder records that make pages open on an empty… | C32: Test rollout | D32: =COUNTIF(E32:BB32,"●")
A33: DAT-03 | B33: Validate the Quality KPIs against the lab's Excel records for… | C33: Production go-live | D33: =COUNTIF(E33:BB33,"●")
A34: DAT-04 | B34: Provide the cost figures the reports need: a TZS-per-hour rate for… | C34: Post go-live | D34: =COUNTIF(E34:BB34,"●")
A35: DAT-05 | B35: Stop the Quarry page downloading every weighbridge ticket ever… | C35: Production go-live | D35: =COUNTIF(E35:BB35,"●")
A36: DAT-06 | B36: Decide what should happen when the Quarry report is opened with no… | C36: Test rollout | D36: =COUNTIF(E36:BB36,"●")
A37: APP-01 | B37: Finish and release the work in progress: fix the broken mailer test,… | C37: Test rollout | D37: =COUNTIF(E37:BB37,"●")
A38: APP-02 | B38: Check the 417-reason stoppage catalogue with maintenance and… | C38: Test rollout | D38: =COUNTIF(E38:BB38,"●") | AI38: ●
A39: APP-03 | B39: CPP HOD to confirm the Power Plant entry form (22 readings and the… | C39: Test rollout | D39: =COUNTIF(E39:BB39,"●") | AI39: ●
A40: APP-04 | B40: Stop the Sales and Purchases dashboards presenting a March-2026 test… | C40: Test rollout | D40: =COUNTIF(E40:BB40,"●")
A41: APP-05 | B41: Fix 'most recent date with data' so it ignores near-empty reports.… | C41: Test rollout | D41: =COUNTIF(E41:BB41,"●")
A42: APP-06 | B42: Complete the review page / entry form split for the remaining… | C42: Production go-live | D42: =COUNTIF(E42:BB42,"●") | AI42: ●
...

Sheet Top 10 Actions
A1: Top 10 Actions Before Test Rollout
A2: Lake Cement MIS (Nyati Dashboard) · Status verified on 17-Sep-2026 against the code, database and live production server
B5: Proposed key dates | D5: Snapshot (updates from the tracker)
B6: Management decisions | C6: 46289 | D6: Open tasks – total | E6: =COUNTIFS('Go-Live Master Tracker'!$D$6:$D$300,"?*",'Go-Live Master Tracker'!$D$6:$D$300,"<>Done")
B7: Email and HTTPS fixed | C7: 46294 | D7: Open – needed before test rollout | E7: =COUNTIFS('Go-Live Master Tracker'!$K$6:$K$300,"Test rollout",'Go-Live Master Tracker'!$D$6:$D$300,"<>Done")
B8: Release tested and deployed | C8: 46295 | D8: Open – needed before production go-live | E8: =COUNTIFS('Go-Live Master Tracker'!$K$6:$K$300,"Production go-live",'Go-Live Master Tracker'!$D$6:$D$300,"<>Done")
B9: UAT, accounts and training | C9: 46297 | D9: Open – post go-live improvements | E9: =COUNTIFS('Go-Live Master Tracker'!$K$6:$K$300,"Post go-live",'Go-Live Master Tracker'!$D$6:$D$300,"<>Done")
B10: Pilot starts (parallel run with Excel) | C10: 46300 | D10: Awaiting a management decision | E10: =COUNTIFS('Go-Live Master Tracker'!$M$6:$M$300,"Yes",'Go-Live Master Tracker'!$D$6:$D$300,"<>Done")
B11: Parallel run ends | C11: 46325 | D11: Blocked | E11: =COUNTIF('Go-Live Master Tracker'!$D$6:$D$300,"Blocked")
B12: Cutover decision | C12: 46328 | D12: Critical and not started | E12: =COUNTIFS('Go-Live Master Tracker'!$L$6:$L$300,"Critical",'Go-Live Master Tracker'!$D$6:$D$300,"Not Started")
B13: Proposed only. No rollout date exists in the project; confirm under OPS-01. | D13: Overdue (deadline passed, not Done) | E13: =COUNTIFS('Go-Live Master Tracker'!$I$6:$I$300,"<"&TODAY(),'Go-Live Master Tracker'!$D$6:$D$300,"<>Done")
A16: The 10 actions
A17: # | B17: Action | C17: Why it blocks the pilot | D17: Owner | E17: Coordinate with | F17: Deadline | G17: Management input? | H17: Dept coordination? | I17: Tracker IDs
A18: 1 | B18: Approve the pilot plan and dates | C18: Nothing can be scheduled. No rollout date, pilot scope or cutover sign-off authority is recorded anywhere. | D18: Kush Patel (Managing Director) with Pavan Gandhi (Plant Head / COO) | E18: All operating HODs; IT | F18: 46289 | G18: Yes | H18: Yes | I18: OPS-01
A19: 2 | B19: Turn on HTTPS for the MIS site | C19: Port 443 is closed on production, so logins travel unencrypted. Invite and reset links also need the final https address. | D19: Teckzilla – Odoo & hosting vendor (contact: Ankita) | E19: IT (DNS record and hostname approval); MIS | F19: 46294 | G19: No | H19: Yes | I19: INF-01
A20: 3 | B20: Unblock email and name the recipients | C20: Microsoft 365 blocks the MIS mailbox, so no invite, password reset, KPI digest or alert can be sent. Nobody has been named to receive the digest or alerts. | D20: Saurabh Bhattacharya (IT HOD) (mailbox); Pavan Gandhi (Plant Head / COO) (recipients) | E20: IT; Plant Head; MD; MIS | F20: 46290 | G20: Yes | H20: Yes | I20: EML-01, EML-02, EML-03
A21: 4 | B21: Ship one clean, tested release | C21: 36 files are uncommitted, and the test suite currently fails (a broken mailer test), which blocks every deploy. What production runs is unconfirmed. | D21: Razak Mbaga (MIS developer) | E21: Plant Head (approve page layouts) | F21: 46295 | G21: No | H21: No | I21: APP-01, QA-01, INF-03
A22: 5 | B22: Give every pilot user a named account | C22: 33 staff slots have no named person, and staff without a company mailbox have no way to receive a login. | D22: Saurabh Bhattacharya (IT HOD) (collection); Pavan Gandhi (Plant Head / COO) (mailbox policy) | E22: All 15 HODs; HR; MIS | F22: 46296 | G22: Yes | H22: Yes | I22: ACC-01, ACC-02, ACC-03
A23: 6 | B23: Remove test accounts and default passwords | C23: A test account with admin rights is still active, and 37 of 46 accounts use passwords stored in the code repository. | D23: Razak Mbaga (MIS developer) | E23: IT; all HODs (holders set passwords) | F23: 46297 | G23: No | H23: Yes | I23: SEC-02, SEC-03, SEC-01
A24: 7 | B24: Put backups on a separate disk and prove a restore | C24: Production health is 'degraded': backups share the app's disk, so one disk failure loses both. | D24: Teckzilla – Odoo & hosting vendor (contact: Ankita) | E24: IT (destination); Finance (storage cost); MIS | F24: 46297 | G24: No | H24: Yes | I24: INF-02, INF-05
A25: 8 | B25: Confirm who approves what | C25: Two approval rules (Power Consumption, Dispatch & SO) were set on the Plant Head's behalf and never ratified. Three access gaps are undecided. | D25: Pavan Gandhi (Plant Head / COO) | E25: E&I; P&M; Packing; Logistics; Sales; Purchase; IT | F25: 46289 | G25: Yes | H25: Yes | I25: SEC-04, SEC-05
A26: 9 | B26: Make pilot dashboards tell the truth | C26: Data stops at 30 Jun, demo rows make pages open on blank days, and Sales and Purchases show a March test snapshot as if it were current. | D26: Pavan Gandhi (Plant Head / COO) (data baseline); Razak Mbaga (MIS developer) (fixes) | E26: MD; Sales; Purchase; Quarry; operating HODs | F26: 46295 | G26: Yes | H26: Yes | I26: DAT-01, DAT-02, APP-04, APP-05
A27: 10 | B27: Run UAT and train the pilot users | C27: The 417-reason stoppage list and the CPP entry form have not been checked by the people who fill them. No data-entry owners, Excel checker or training exist yet. | D27: Pavan Gandhi (Plant Head / COO) (UAT sign-off); Razak Mbaga (MIS developer) (sessions) | E27: P&M; E&I; CPP; Production & QC; Packing; Logistics; Stores; Quarry; HR | F27: 46297 | G27: No | H27: Yes | I27: QA-02, APP-02, APP-03, OPS-02, OPS-03
A29: Start now: not pilot blockers, but they take the longest
B30: ODO-01 · Teckzilla – Odoo & hosting vendor (contact: Ankita) | C30: Escalate the production Odoo connection with Teckzilla. The test database stops at 28-Mar-2026, so Sales, Purchases and Quarry auto-sync cannot show current data at go-live without it. | G30: Yes
B31: GOV-01 · Sankalp Jaithalia (CFO) | C31: Settle who pays for hosting, backup storage and Odoo vendor work. No budget or contract information exists in the project. | G31: Yes
B32: DAT-03 · Razak Mbaga (MIS developer) | C32: Get the quality lab workbooks from Production & QC. Quality KPIs are validated on 1 day of data, against 91 days for everything else. | G32: No
A34: Already in place (verified)
B35: ✓ Production server is running and its database is healthy (checked 17-Sep-2026).
B36: ✓ Nightly backups are running on production (on the wrong disk; see action 7).
B37: ✓ Dispatch, mining and sales/purchase Odoo connectors are configured and pulling, but from a test snapshot.
B38: ✓ Security fixes from 13–15 Sep (forgot-password timing, invite links, log rotation, audit trail) are on main.
B39: ✓ Last UI audit (15-Sep): 72/72 responsive checks and 0 accessibility violations.
