Workbook

Sheet 0
B3: 1*10 MW CAPTIVE POWER PLANT
B4: Daily,Monthly & Yearly Generation Report (FRM-LCL-PP-06)
B6: Sr. NO. | C6: Description | D6: Unit | E6: 46265 | F6: Month to Date | G6: Year to Date(APR2026-MAR2027)
B7: 1 | C7: Gross Power Generation | D7: kWhr | E7: 174200 | F7: 5294051 | G7: 25020416
B8: 2 | C8: Auxiliary power consumption | D8: kWhr | E8: 18213 | F8: 561948 | G8: 2715493
B9: 3 | C9: Net Power Exported | D9: kWhr | E9: 155987 | F9: 4732103 | G9: 22304923
B10: 4 | C10: Auxiliary power consumption | D10: ( % ) | E10: 10.455224 | F10: 10.614707 | G10: 10.853109
B11: 5 | C11: Average Power Generation | D11: MWhr | E11: 7.2583333 | F11: 7.1156599 | G11: 6.8517923
B12: 6 | C12: Plant Running Hours | D12: Hrs | E12: 24 | F12: 744 | G12: 3651.66
B13: 6 | C13: PLF | D13: ( % ) | E13: 72.583333 | F13: 71.156599 | G13: 68.517923
B14: 7 | C14: Feed Water consumption | D14: MT | E14: 794 | F14: 24425 | G14: 116198
B15: 8 | C15: Boiler Steam Generation | D15: MT | E15: 771 | F15: 23689 | G15: 112677
B16: 9 | C16: Bleed steam | D16: MT | E16: 57 | F16: 1708 | G16: 7488
B17: 10 | C17: Turbine steam consumption | D17: MT | E17: 726 | F17: 22119 | G17: 104292
B18: 11 | C18: Condensate Generation | D18: MT | E18: 570 | F18: 17516 | G18: 83129
... B24: 17 | C24: DG Power Generation | D24: kWhr | E24: 0 | F24: 0 | G24: 1468
B25: FUEL Report
B26: 1 | C26: Coal Consumption | D26: MT | E26: 132 | F26: 3977 | G26: 20821
B27: 2 | C27: GCV ( ADB ) | D27: Kcal/kg | E27: 4601
B29: WTP Report
B30: 1 | C30: DM water Generation | D30: m3 | E30: 11 | F30: 441 | G30: 2284
B31: 2 | C31: DM water Consumption | D31: m3 | E31: 10 | F31: 439 | G31: 2296
B32: 3 | C32: CT Makeup Water Consumption | D32: m3 | E32: 18 | F32: 671 | G32: 3104
B33: 4 | C33: Fly ash combustible/ GCV | D33: % / kcal/kg | E33: 19.9 | F33: 1650
B34: FLY ASH DISPOSAL REPORT
B35: 5 | C35: Fly ash to cement mill | D35: MT | E35: 0 | F35: 858 | G35: 3807
B36: 6 | C36: Fly ash to Coalyard(Truck) | D36: nos | E36: 4 | F36: 60 | G36: 369
B37: 7 | C37: Fly ash to Dumpyard(Truck) | D37: nos | E37: 0 | F37: 0 | G37: 0

Sheet 1
B3: 1*10 MW CAPTIVE POWER PLANT
B4: Daily,Monthly & Yearly Generation Report (FRM-LCL-PP-06)
B6: Sr. NO. | C6: Description | D6: Unit | E6: ='0'!E6+1 -> 46266 | F6: Month to Date | G6: Year to Date(APR2026-MAR2027)
B7: 1 | C7: Gross Power Generation | D7: kWhr | E7: 177900 | F7: =E7 -> 177900 | G7: =E7+'0'!G7 -> 25198316
B8: 2 | C8: Auxiliary power consumption | D8: kWhr | E8: 18110 | F8: =E8 -> 18110 | G8: =E8+'0'!G8 -> 2733603
B9: 3 | C9: Net Power Exported | D9: kWhr | E9: =E7-E8 -> 159790 | F9: =E9 -> 159790 | G9: =E9+'0'!G9 -> 22464713
B10: 4 | C10: Auxiliary power consumption | D10: ( % ) | E10: =E8/E7*100 -> 10.179876 | F10: =F8/F7*100 -> 10.179876 | G10: =G8/G7*100 -> 10.848356
B11: 5 | C11: Average Power Generation | D11: MWhr | E11: =E7/E12/1000 -> 7.4125 | F11: =F7/F12/1000 -> 7.4125 | G11: =G7/G12/1000 -> 6.8554534
B12: 6 | C12: Plant Running Hours | D12: Hrs | E12: 24 | F12: =E12 -> 24 | G12: =E12+'0'!G12 -> 3675.66
B13: 6 | C13: PLF | D13: ( % ) | E13: =E11/10*100 -> 74.125 | F13: =F11/10*100 -> 74.125 | G13: =G11/10*100 -> 68.554534
B14: 7 | C14: Feed Water consumption | D14: MT | E14: 809 | F14: =E14 -> 809 | G14: =E14+'0'!G14 -> 117007
B15: 8 | C15: Boiler Steam Generation | D15: MT | E15: 787 | F15: =E15 -> 787 | G15: =E15+'0'!G15 -> 113464
B16: 9 | C16: Bleed steam | D16: MT | E16: 61 | F16: =E16 -> 61 | G16: =E16+'0'!G16 -> 7549
B17: 10 | C17: Turbine steam consumption | D17: MT | E17: 741 | F17: =E17 -> 741 | G17: =E17+'0'!G17 -> 105033
B18: 11 | C18: Condensate Generation | D18: MT | E18: 580 | F18: =E18 -> 580 | G18: =E18+'0'!G18 -> 83709
B19: 12 | C19: Auxilairy steam consumption | D19: MT | E19: 18 | F19: =E19 -> 18 | G19: =E19+'0'!G19 -> 2716
B20: 13 | C20: Specific steam consumption | D20: Kg/Kwhr | E20: =E17*1000/E7 -> 4.1652614 | F20: =F17*1000/F7 -> 4.1652614 | G20: =G17*1000/G7 -> 4.1682547
B21: 14 | C21: Specific fuel consumption | D21: Kg/Kwhr | E21: =E26*1000/E7 -> 0.75323215 | F21: =F26*1000/F7 -> 0.75323215 | G21: =G26*1000/G7 -> 0.83160319
B22: 15 | C22: Heat Rate(TG)2880 | D22: Kcal/Kwh | E22: =((E17*(803-130)+E31*(30))*1000)/E7 -> 2805.5818 | F22: =((F17*(803-130)+F31*(30))*1000)/F7 -> 2805.5818 | G22: =((G17*(803-130)+G31*(30))*1000)/G7 -> 2807.9856
B23: 16 | C23: Heat Rate ( Plant ) 3300 @ MCR | D23: Kcal/Kwh | E23: =(E15*(803-130))*1000/(E7*0.78) -> 3816.9744 | F23: =(F15*(803-130))*1000/(F7*0.78) -> 3816.9744 | G23: =(G15*(803-130))*1000/(G7*0.78) -> 3885.1432
B24: 17 | C24: DG Power Generation | D24: kWhr | E24: 0 | F24: =E24 -> 0 | G24: =E24+'0'!G24 -> 1468
B25: FUEL Report
B26: 1 | C26: Coal Consumption | D26: MT | E26: 134 | F26: =E26 -> 134 | G26: =E26+'0'!G26 -> 20955
B27: 2 | C27: GCV ( ADB ) | D27: Kcal/kg | E27: 4644
B29: WTP Report
B30: 1 | C30: DM water Generation | D30: m2 | E30: 16 | F30: =E30 -> 16 | G30: =E30+'0'!G30 -> 2300
B31: 2 | C31: DM water Consumption | D31: m3 | E31: 14 | F31: =E31 -> 14 | G31: =E31+'0'!G31 -> 2310
B32: 3 | C32: CT Makeup Water Consumption | D32: m3 | E32: 18 | F32: =E32 -> 18 | G32: =E32+'0'!G32 -> 3122
B33: 4 | C33: Fly ash combustible/ GCV | D33: % / kcal/kg | E33: 19 | F33: 1421
B34: FLY ASH DISPOSAL REPORT
B35: 5 | C35: Fly ash to cement mill | D35: MT | E35: 0 | F35: =E35 -> 0 | G35: =E35+'0'!G35 -> 3807
B36: 6 | C36: Fly ash to Coal yard(Truck) | D36: nos | E36: 5 | F36: =E36 -> 5 | G36: =E36+'0'!G36 -> 374
B37: 7 | C37: Fly ash to Dumpyard(Truck) | D37: nos | E37: 0 | F37: =E37 -> 0 | G37: =E37+'0'!G37 -> 0

Sheet 2
B3: 1*10 MW CAPTIVE POWER PLANT
B4: Daily,Monthly & Yearly Generation Report (FRM-LCL-PP-06)
B6: Sr. NO. | C6: Description | D6: Unit | E6: ='1'!E6+1 -> 46267 | F6: Month to Date | G6: Year to Date(APR2026-MAR2027)
B7: 1 | C7: Gross Power Generation | D7: kWhr | E7: 159700 | F7: =E7+'1'!F7 -> 337600 | G7: =E7+'1'!G7 -> 25358016
B8: 2 | C8: Auxiliary power consumption | D8: kWhr | E8: 17609 | F8: =E8+'1'!F8 -> 35719 | G8: =E8+'1'!G8 -> 2751212
B9: 3 | C9: Net Power Exported | D9: kWhr | E9: =E7-E8 -> 142091 | F9: =E9+'1'!F9 -> 301881 | G9: =E9+'1'!G9 -> 22606804
B10: 4 | C10: Auxiliary power consumption | D10: ( % ) | E10: =E8/E7*100 -> 11.026299 | F10: =F8/F7*100 -> 10.580273 | G10: =G8/G7*100 -> 10.849477
B11: 5 | C11: Average Power Generation | D11: MWhr | E11: =E7/E12/1000 -> 6.6541667 | F11: =F7/F12/1000 -> 7.0333333 | G11: =G7/G12/1000 -> 6.8541477
B12: 6 | C12: Plant Running Hours | D12: Hrs | E12: 24 | F12: =E12+'1'!F12 -> 48 | G12: =E12+'1'!G12 -> 3699.66
B13: 7 | C13: PLF | D13: ( % ) | E13: =E11/10*100 -> 66.541667 | F13: =F11/10*100 -> 70.333333 | G13: =G11/10*100 -> 68.541477
B14: 8 | C14: Feed Water consumption | D14: MT | E14: 749 | F14: =E14+'1'!F14 -> 1558 | G14: =E14+'1'!G14 -> 117756
B15: 9 | C15: Boiler Steam Generation | D15: MT | E15: 726 | F15: =E15+'1'!F15 -> 1513 | G15: =E15+'1'!G15 -> 114190
B16: 10 | C16: Bleed steam | D16: MT | E16: 45 | F16: =E16+'1'!F16 -> 106 | G16: =E16+'1'!G16 -> 7594
B17: 11 | C17: Turbine steam consumption | D17: MT | E17: 668 | F17: =E17+'1'!F17 -> 1409 | G17: =E17+'1'!G17 -> 105701
B18: 12 | C18: Condensate Generation | D18: MT | E18: 533 | F18: =E18+'1'!F18 -> 1113 | G18: =E18+'1'!G18 -> 84242
B19: 13 | C19: Auxilairy steam consumption | D19: MT | E19: 18 | F19: =E19+'1'!F19 -> 36 | G19: =E19+'1'!G19 -> 2734
B20: 14 | C20: Specific steam consumption | D20: Kg/Kwhr | E20: =E17*1000/E7 -> 4.1828428 | F20: =F17*1000/F7 -> 4.1735782 | G20: =G17*1000/G7 -> 4.1683466
B21: 15 | C21: Specific fuel consumption | D21: Kg/Kwhr | E21: =E26*1000/E7 -> 0.77645585 | F21: =F26*1000/F7 -> 0.76421801 | G21: =G26*1000/G7 -> 0.83125588
B22: 16 | C22: Heat Rate(TG)2880 | D22: Kcal/Kwh | E22: =((E17*(803-130)+E31*(30))*1000)/E7 -> 2817.6832 | F22: =((F17*(803-130)+F31*(30))*1000)/F7 -> 2811.3063 | G22: =((G17*(803-130)+G31*(30))*1000)/G7 -> 2808.0467
B23: 17 | C23: Heat Rate ( Plant ) 3300 @ MCR | D23: Kcal/Kwh | E23: =(E15*(803-130))*1000/(E7*0.78) -> 3922.4026 | F23: =(F15*(803-130))*1000/(F7*0.78) -> 3866.8467 | G23: =(G15*(803-130))*1000/(G7*0.78) -> 3885.3779
B24: 18 | C24: DG Power Generation | D24: kWhr | E24: 0 | F24: =E24+'1'!F24 -> 0 | G24: =E24+'1'!G24 -> 1468
B25: FUEL Report
B26: 1 | C26: Coal Consumption | D26: MT | E26: 124 | F26: =E26+'1'!F26 -> 258 | G26: =E26+'1'!G26 -> 21079
B27: 2 | C27: GCV ( ADB ) | D27: Kcal/kg | E27: 4432
B29: WTP Report
B30: 1 | C30: DM water Generation | D30: m3 | E30: 12 | F30: =E30+'1'!F30 -> 28 | G30: =E30+'1'!G30 -> 2312
B31: 2 | C31: DM water Consumption | D31: m3 | E31: 14 | F31: =E31+'1'!F31 -> 28 | G31: =E31+'1'!G31 -> 2324
B32: 3 | C32: CT Makeup Water Consumption | D32: m3 | E32: 54 | F32: =E32+'1'!F32 -> 72 | G32: =E32+'1'!G32 -> 3176
B33: 4 | C33: Fly ash combustible/ GCV | D33: % / kcal/kg | E33: 21 | F33: 1542
B34: FLY ASH DISPOSAL REPORT
B35: 5 | C35: Fly ash to cement mill | D35: MT | E35: 0 | F35: =E35+'1'!F35 -> 0 | G35: =E35+'1'!G35 -> 3807
B36: 6 | C36: Fly ash to Coal yard(Truck) | D36: nos | E36: 4 | F36: =E36+'1'!F36 -> 9 | G36: =E36+'1'!G36 -> 378
B37: 7 | C37: Fly ash to Dumpyard(Truck) | D37: nos | E37: 0 | F37: =E37+'1'!F37 -> 0 | G37: =E37+'1'!G37 -> 0

Sheet 3
B3: 1*10 MW CAPTIVE POWER PLANT
B4: Daily,Monthly & Yearly Generation Report (FRM-LCL-PP-06)
B6: Sr. NO. | C6: Description | D6: Unit | E6: ='2'!E6+1 -> 46268 | F6: Month to Date | G6: Year to Date(APR2026-MAR2027)
B7: 1 | C7: Gross Power Generation | D7: kWhr | E7: 179500 | F7: =E7+'2'!F7 -> 517100 | G7: =E7+'2'!G7 -> 25537516
B8: 2 | C8: Auxiliary power consumption | D8: kWhr | E8: 17987 | F8: =E8+'2'!F8 -> 53706 | G8: =E8+'2'!G8 -> 2769199
B9: 3 | C9: Net Power Exported | D9: kWhr | E9: =E7-E8 -> 161513 | F9: =E9+'2'!F9 -> 463394 | G9: =E9+'2'!G9 -> 22768317
B10: 4 | C10: Auxiliary power consumption | D10: ( % ) | E10: =E8/E7*100 -> 10.020613 | F10: =F8/F7*100 -> 10.385999 | G10: =G8/G7*100 -> 10.843651
B11: 5 | C11: Average Power Generation | D11: MWhr | E11: =E7/E12/1000 -> 7.4791667 | F11: =F7/F12/1000 -> 7.1819444 | G11: =G7/G12/1000 -> 6.8581761
B12: 6 | C12: Plant Running Hours | D12: Hrs | E12: 24 | F12: =E12+'2'!F12 -> 72 | G12: =E12+'2'!G12 -> 3723.66
B13: 6 | C13: PLF | D13: ( % ) | E13: =E11/10*100 -> 74.791667 | F13: =F11/10*100 -> 71.819444 | G13: =G11/10*100 -> 68.581761
B14: 7 | C14: Feed Water consumption | D14: MT | E14: 825 | F14: =E14+'2'!F14 -> 2383 | G14: =E14+'2'!G14 -> 118581
B15: 8 | C15: Boiler Steam Generation | D15: MT | E15: 795 | F15: =E15+'2'!F15 -> 2308 | G15: =E15+'2'!G15 -> 114985
B16: 9 | C16: Bleed steam | D16: MT | E16: 46 | F16: =E16+'2'!F16 -> 152 | G16: =E16+'2'!G16 -> 7640
B17: 10 | C17: Turbine steam consumption | D17: MT | E17: 743 | F17: =E17+'2'!F17 -> 2152 | G17: =E17+'2'!G17 -> 106444
B18: 11 | C18: Condensate Generation | D18: MT | E18: 597 | F18: =E18+'2'!F18 -> 1710 | G18: =E18+'2'!G18 -> 84839
B19: 12 | C19: Auxilairy steam consumption | D19: MT | E19: 17 | F19: =E19+'2'!F19 -> 53 | G19: =E19+'2'!G19 -> 2751
B20: 13 | C20: Specific steam consumption | D20: Kg/Kwhr | E20: =E17*1000/E7 -> 4.1392758 | F20: =F17*1000/F7 -> 4.1616709 | G20: =G17*1000/G7 -> 4.1681423
B21: 14 | C21: Specific fuel consumption | D21: Kg/Kwhr | E21: =E26*1000/E7 -> 0.76880223 | F21: =F26*1000/F7 -> 0.76580932 | G21: =G26*1000/G7 -> 0.8308169
B22: 15 | C22: Heat Rate(TG)2880 | D22: Kcal/Kwh | E22: =((E17*(803-130)+E31*(30))*1000)/E7 -> 2787.4039 | F22: =((F17*(803-130)+F31*(30))*1000)/F7 -> 2803.0091 | G22: =((G17*(803-130)+G31*(30))*1000)/G7 -> 2807.9016
B23: 16 | C23: Heat Rate ( Plant ) 3300 @ MCR | D23: Kcal/Kwh | E23: =(E15*(803-130))*1000/(E7*0.78) -> 3821.4056 | F23: =(F15*(803-130))*1000/(F7*0.78) -> 3851.0728 | G23: =(G15*(803-130))*1000/(G7*0.78) -> 3884.9282
B24: 17 | C24: DG Power Generation | D24: kWhr | E24: 0 | F24: =E24+'2'!F24 -> 0 | G24: =E24+'2'!G24 -> 1468
B25: FUEL Report
B26: 1 | C26: Coal Consumption | D26: MT | E26: 138 | F26: =E26+'2'!F26 -> 396 | G26: =E26+'2'!G26 -> 21217
B27: 2 | C27: GCV ( ADB ) | D27: Kcal/kg | E27: 4767
B29: WTP Report
B30: 1 | C30: DM water Generation | D30: m3 | E30: 9 | F30: =E30+'2'!F30 -> 37 | G30: =E30+'2'!G30 -> 2321
B31: 2 | C31: DM water Consumption | D31: m3 | E31: 10 | F31: =E31+'2'!F31 -> 38 | G31: =E31+'2'!G31 -> 2334
B32: 3 | C32: CT Makeup Water Consumption | D32: m3 | E32: 18 | F32: =E32+'2'!F32 -> 90 | G32: =E32+'2'!G32 -> 3194
B33: 4 | C33: Fly ash combustible/ GCV | D33: % / kcal/kg | E33: 22 | F33: 1708
B34: FLY ASH DISPOSAL REPORT
B35: 5 | C35: Fly ash to cement mill | D35: MT | E35: 0 | F35: =E35+'2'!F35 -> 0 | G35: =E35+'2'!G35 -> 3807
B36: 6 | C36: Fly ash to Coal yard(Truck) | D36: nos | E36: 6 | F36: =E36+'2'!F36 -> 15 | G36: =E36+'2'!G36 -> 384
B37: 7 | C37: Fly ash to Dumpyard(Truck) | D37: nos | E37: 0 | F37: =E37+'2'!F37 -> 0 | G37: =E37+'2'!G37 -> 0

Sheet 4
B3: 1*10 MW CAPTIVE POWER PLANT
B4: Daily,Monthly & Yearly Generation Report (FRM-LCL-PP-06)
B6: Sr. NO. | C6: Description | D6: Unit | E6: ='3'!E6+1 -> 46269 | F6: Month to Date | G6: Year to Date(APR2026-MAR2027)
B7: 1 | C7: Gross Power Generation | D7: kWhr | E7: 185500 | F7: =E7+'3'!F7 -> 702600 | G7: =E7+'3'!G7 -> 25723016
B8: 2 | C8: Auxiliary power consumption | D8: kWhr | E8: 18143 | F8: =E8+'3'!F8 -> 71849 | G8: =E8+'3'!G8 -> 2787342
B9: 3 | C9: Net Power Exported | D9: kWhr | E9: =E7-E8 -> 167357 | F9: =E9+'3'!F9 -> 630751 | G9: =E9+'3'!G9 -> 22935674
B10: 4 | C10: Auxiliary power consumption | D10: ( % ) | E10: =E8/E7*100 -> 9.780593 | F10: =F8/F7*100 -> 10.22616 | G10: =G8/G7*100 -> 10.835984
B11: 5 | C11: Average Power Generation | D11: MWhr | E11: =E7/E12/1000 -> 7.7291667 | F11: =F7/F12/1000 -> 7.31875 | G11: =G7/G12/1000 -> 6.8637539
B12: 6 | C12: Plant Running Hours | D12: Hrs | E12: 24 | F12: =E12+'3'!F12 -> 96 | G12: =E12+'3'!G12 -> 3747.66
B13: 6 | C13: PLF | D13: ( % ) | E13: =E11/10*100 -> 77.291667 | F13: =F11/10*100 -> 73.1875 | G13: =G11/10*100 -> 68.637539
B14: 7 | C14: Feed Water consumption | D14: MT | E14: 839 | F14: =E14+'3'!F14 -> 3222 | G14: =E14+'3'!G14 -> 119420
B15: 8 | C15: Boiler Steam Generation | D15: MT | E15: 817 | F15: =E15+'3'!F15 -> 3125 | G15: =E15+'3'!G15 -> 115802
B16: 9 | C16: Bleed steam | D16: MT | E16: 63 | F16: =E16+'3'!F16 -> 215 | G16: =E16+'3'!G16 -> 7703
B17: 10 | C17: Turbine steam consumption | D17: MT | E17: 772 | F17: =E17+'3'!F17 -> 2924 | G17: =E17+'3'!G17 -> 107216
B18: 11 | C18: Condensate Generation | D18: MT | E18: 603 | F18: =E18+'3'!F18 -> 2313 | G18: =E18+'3'!G18 -> 85442
B19: 12 | C19: Auxilairy steam consumption | D19: MT | E19: 18 | F19: =E19+'3'!F19 -> 71 | G19: =E19+'3'!G19 -> 2769
B20: 13 | C20: Specific steam consumption | D20: Kg/Kwhr | E20: =E17*1000/E7 -> 4.1617251 | F20: =F17*1000/F7 -> 4.1616852 | G20: =G17*1000/G7 -> 4.168096
B21: 14 | C21: Specific fuel consumption | D21: Kg/Kwhr | E21: =E26*1000/E7 -> 0.72237197 | F21: =F26*1000/F7 -> 0.75434102 | G21: =G26*1000/G7 -> 0.83003486
B22: 15 | C22: Heat Rate(TG)2880 | D22: Kcal/Kwh | E22: =((E17*(803-130)+E31*(30))*1000)/E7 -> 2802.6199 | F22: =((F17*(803-130)+F31*(30))*1000)/F7 -> 2802.9063 | G22: =((G17*(803-130)+G31*(30))*1000)/G7 -> 2807.8635
B23: 16 | C23: Heat Rate ( Plant ) 3300 @ MCR | D23: Kcal/Kwh | E23: =(E15*(803-130))*1000/(E7*0.78) -> 3800.1313 | F23: =(F15*(803-130))*1000/(F7*0.78) -> 3837.6233 | G23: =(G15*(803-130))*1000/(G7*0.78) -> 3884.3167
B24: 17 | C24: DG Power Generation | D24: kWhr | E24: 0 | F24: =E24+'3'!F24 -> 0 | G24: =E24+'3'!G24 -> 1468
B25: FUEL Report
B26: 1 | C26: Coal Consumption | D26: MT | E26: 134 | F26: =E26+'3'!F26 -> 530 | G26: =E26+'3'!G26 -> 21351
B27: 2 | C27: GCV ( ADB ) | D27: Kcal/kg | E27: 5472
B29: WTP Report
B30: 1 | C30: DM water Generation | D30: m3 | E30: 11 | F30: =E30+'3'!F30 -> 48 | G30: =E30+'3'!G30 -> 2332
B31: 2 | C31: DM water Consumption | D31: m3 | E31: 11 | F31: =E31+'3'!F31 -> 49 | G31: =E31+'3'!G31 -> 2345
B32: 3 | C32: CT Makeup Water Consumption | D32: m3 | E32: 20 | F32: =E32+'3'!F32 -> 110 | G32: =E32+'3'!G32 -> 3214
B33: 4 | C33: Fly ash combustible/ GCV | D33: % / kcal/kg | E33: 24.5 | F33: 1839
B35: 5 | C35: Fly ash to cement mill | D35: MT | E35: 0 | F35: =E35+'3'!F35 -> 0 | G35: =E35+'3'!G35 -> 3807
B36: 6 | C36: Fly ash to Coal yard(Truck) | D36: nos | E36: 5 | F36: =E36+'3'!F36 -> 20 | G36: =E36+'3'!G36 -> 389
B37: 7 | C37: Fly ash to Dumpyard(Truck) | D37: nos | E37: 0 | F37: =E37+'3'!F37 -> 0 | G37: =E37+'3'!G37 -> 0

Sheet 5
B3: 1*10 MW CAPTIVE POWER PLANT
B4: Daily,Monthly & Yearly Generation Report (FRM-LCL-PP-06)
B6: Sr. NO. | C6: Description | D6: Unit | E6: ='4'!E6+1 -> 46270 | F6: Month to Date | G6: Year to Date(APR2026-MAR2027)
B7: 1 | C7: Gross Power Generation | D7: kWhr | E7: 178400 | F7: =E7+'4'!F7 -> 881000 | G7: =E7+'4'!G7 -> 25901416
B8: 2 | C8: Auxiliary power consumption | D8: kWhr | E8: 18081 | F8: =E8+'4'!F8 -> 89930 | G8: =E8+'4'!G8 -> 2805423
B9: 3 | C9: Net Power Exported | D9: kWhr | E9: =E7-E8 -> 160319 | F9: =E9+'4'!F9 -> 791070 | G9: =E9+'4'!G9 -> 23095993
B10: 4 | C10: Auxiliary power consumption | D10: ( % ) | E10: =E8/E7*100 -> 10.13509 | F10: =F8/F7*100 -> 10.207719 | G10: =G8/G7*100 -> 10.831157
B11: 5 | C11: Average Power Generation | D11: MWhr | E11: =E7/E12/1000 -> 7.4333333 | F11: =F7/F12/1000 -> 7.3416667 | G11: =G7/G12/1000 -> 6.8673783
B12: 6 | C12: Plant Running Hours | D12: Hrs | E12: 24 | F12: =E12+'4'!F12 -> 120 | G12: =E12+'4'!G12 -> 3771.66
B13: 6 | C13: PLF | D13: ( % ) | E13: =E11/10*100 -> 74.333333 | F13: =F11/10*100 -> 73.416667 | G13: =G11/10*100 -> 68.673783
B14: 7 | C14: Feed Water consumption | D14: MT | E14: 817 | F14: =E14+'4'!F14 -> 4039 | G14: =E14+'4'!G14 -> 120237
B15: 8 | C15: Boiler Steam Generation | D15: MT | E15: 788 | F15: =E15+'4'!F15 -> 3913 | G15: =E15+'4'!G15 -> 116590
B16: 9 | C16: Bleed steam | D16: MT | E16: 57 | F16: =E16+'4'!F16 -> 272 | G16: =E16+'4'!G16 -> 7760
B17: 10 | C17: Turbine steam consumption | D17: MT | E17: 744 | F17: =E17+'4'!F17 -> 3668 | G17: =E17+'4'!G17 -> 107960
B18: 11 | C18: Condensate Generation | D18: MT | E18: 588 | F18: =E18+'4'!F18 -> 2901 | G18: =E18+'4'!G18 -> 86030
B19: 12 | C19: Auxilairy steam consumption | D19: MT | E19: 17 | F19: =E19+'4'!F19 -> 88 | G19: =E19+'4'!G19 -> 2786
B20: 13 | C20: Specific steam consumption | D20: Kg/Kwhr | E20: =E17*1000/E7 -> 4.1704036 | F20: =F17*1000/F7 -> 4.1634506 | G20: =G17*1000/G7 -> 4.1681119
B21: 14 | C21: Specific fuel consumption | D21: Kg/Kwhr | E21: =E26*1000/E7 -> 0.71748879 | F21: =F26*1000/F7 -> 0.74687855 | G21: =G26*1000/G7 -> 0.82925968
B22: 15 | C22: Heat Rate(TG)2880 | D22: Kcal/Kwh | E22: =((E17*(803-130)+E31*(30))*1000)/E7 -> 2808.8677 | F22: =((F17*(803-130)+F31*(30))*1000)/F7 -> 2804.1135 | G22: =((G17*(803-130)+G31*(30))*1000)/G7 -> 2807.8704
B23: 16 | C23: Heat Rate ( Plant ) 3300 @ MCR | D23: Kcal/Kwh | E23: =(E15*(803-130))*1000/(E7*0.78) -> 3811.113 | F23: =(F15*(803-130))*1000/(F7*0.78) -> 3832.255 | G23: =(G15*(803-130))*1000/(G7*0.78) -> 3883.8125
B24: 17 | C24: DG Power Generation | D24: kWhr | E24: 0 | F24: =E24+'4'!F24 -> 0 | G24: =E24+'4'!G24 -> 1468
B25: FUEL Report
B26: 1 | C26: Coal Consumption | D26: MT | E26: 128 | F26: =E26+'4'!F26 -> 658 | G26: =E26+'4'!G26 -> 21479
B27: 2 | C27: GCV ( ADB ) | D27: Kcal/kg | E27: 5609
B29: WTP Report
B30: 1 | C30: DM water Generation | D30: m3 | E30: 15 | F30: =E30+'4'!F30 -> 63 | G30: =E30+'4'!G30 -> 2347
B31: 2 | C31: DM water Consumption | D31: m3 | E31: 13 | F31: =E31+'4'!F31 -> 62 | G31: =E31+'4'!G31 -> 2358
B32: 3 | C32: CT Makeup Water Consumption | D32: m3 | E32: 18 | F32: =E32+'4'!F32 -> 128 | G32: =E32+'4'!G32 -> 3232
B33: 4 | C33: Fly ash combustible/ GCV | D33: % / kcal/kg | E33: 28 | F33: 1963
B34: FLY ASH DISPOSAL REPORT
B35: 5 | C35: Fly ash to cement mill | D35: MT | E35: 0 | F35: =E35+'4'!F35 -> 0 | G35: =E35+'4'!G35 -> 3807
B36: 6 | C36: Fly ash to Coal yard(Truck) | D36: nos | E36: 5 | F36: =E36+'4'!F36 -> 25 | G36: =E36+'4'!G36 -> 394
B37: 7 | C37: Fly ash to Dumpyard(Truck) | D37: nos | E37: 0 | F37: =E37+'4'!F37 -> 0 | G37: =E37+'4'!G37 -> 0

Sheet 6
B3: 1*10 MW CAPTIVE POWER PLANT
B4: Daily,Monthly & Yearly Generation Report (FRM-LCL-PP-06)
B6: Sr. NO. | C6: Description | D6: Unit | E6: ='5'!E6+1 -> 46271 | F6: Month to Date | G6: Year to Date(APR2026-MAR2027)
B7: 1 | C7: Gross Power Generation | D7: kWhr | E7: 174700 | F7: =E7+'5'!F7 -> 1055700 | G7: =E7+'5'!G7 -> 26076116
B8: 2 | C8: Auxiliary power consumption | D8: kWhr | E8: 17849 | F8: =E8+'5'!F8 -> 107779 | G8: =E8+'5'!G8 -> 2823272
B9: 3 | C9: Net Power Exported | D9: kWhr | E9: =E7-E8 -> 156851 | F9: =E9+'5'!F9 -> 947921 | G9: =E9+'5'!G9 -> 23252844
B10: 4 | C10: Auxiliary power consumption | D10: ( % ) | E10: =E8/E7*100 -> 10.216943 | F10: =F8/F7*100 -> 10.209245 | G10: =G8/G7*100 -> 10.827042
B11: 5 | C11: Average Power Generation | D11: MWhr | E11: =E7/E12/1000 -> 7.2791667 | F11: =F7/F12/1000 -> 7.33125 | G11: =G7/G12/1000 -> 6.869982
B12: 6 | C12: Plant Running Hours | D12: Hrs | E12: 24 | F12: =E12+'5'!F12 -> 144 | G12: =E12+'5'!G12 -> 3795.66
B13: 6 | C13: PLF | D13: ( % ) | E13: =E11/10*100 -> 72.791667 | F13: =F11/10*100 -> 73.3125 | G13: =G11/10*100 -> 68.69982
B14: 7 | C14: Feed Water consumption | D14: MT | E14: 798 | F14: =E14+'5'!F14 -> 4837 | G14: =E14+'5'!G14 -> 121035
B15: 8 | C15: Boiler Steam Generation | D15: MT | E15: 773 | F15: =E15+'5'!F15 -> 4686 | G15: =E15+'5'!G15 -> 117363
B16: 9 | C16: Bleed steam | D16: MT | E16: 58 | F16: =E16+'5'!F16 -> 330 | G16: =E16+'5'!G16 -> 7818
B17: 10 | C17: Turbine steam consumption | D17: MT | E17: 731 | F17: =E17+'5'!F17 -> 4399 | G17: =E17+'5'!G17 -> 108691
B18: 11 | C18: Condensate Generation | D18: MT | E18: 572 | F18: =E18+'5'!F18 -> 3473 | G18: =E18+'5'!G18 -> 86602
B19: 12 | C19: Auxilairy steam consumption | D19: MT | E19: 18 | F19: =E19+'5'!F19 -> 106 | G19: =E19+'5'!G19 -> 2804
B20: 13 | C20: Specific steam consumption | D20: Kg/Kwhr | E20: =E17*1000/E7 -> 4.184316 | F20: =F17*1000/F7 -> 4.1669035 | G20: =G17*1000/G7 -> 4.1682205
B21: 14 | C21: Specific fuel consumption | D21: Kg/Kwhr | E21: =E26*1000/E7 -> 0.7441328 | F21: =F26*1000/F7 -> 0.74642417 | G21: =G26*1000/G7 -> 0.82868936
B22: 15 | C22: Heat Rate(TG)2880 | D22: Kcal/Kwh | E22: =((E17*(803-130)+E31*(30))*1000)/E7 -> 2818.1053 | F22: =((F17*(803-130)+F31*(30))*1000)/F7 -> 2806.4289 | G22: =((G17*(803-130)+G31*(30))*1000)/G7 -> 2807.939
B23: 16 | C23: Heat Rate ( Plant ) 3300 @ MCR | D23: Kcal/Kwh | E23: =(E15*(803-130))*1000/(E7*0.78) -> 3817.7462 | F23: =(F15*(803-130))*1000/(F7*0.78) -> 3829.8541 | G23: =(G15*(803-130))*1000/(G7*0.78) -> 3883.3699
B24: 17 | C24: DG Power Generation | D24: kWhr | F24: =E24+'5'!F24 -> 0 | G24: =E24+'5'!G24 -> 1468
B25: FUEL Report
B26: 1 | C26: Coal Consumption | D26: MT | E26: 130 | F26: =E26+'5'!F26 -> 788 | G26: =E26+'5'!G26 -> 21609
B27: 2 | C27: GCV ( ADB ) | D27: Kcal/kg | E27: 4121
B29: WTP Report
B30: 1 | C30: DM water Generation | D30: m3 | E30: 12 | F30: =E30+'5'!F30 -> 75 | G30: =E30+'5'!G30 -> 2359
B31: 2 | C31: DM water Consumption | D31: m3 | E31: 12 | F31: =E31+'5'!F31 -> 74 | G31: =E31+'5'!G31 -> 2370
B32: 3 | C32: CT Makeup Water Consumption | D32: m3 | E32: 18 | F32: =E32+'5'!F32 -> 146 | G32: =E32+'5'!G32 -> 3250
B33: 4 | C33: Fly ash combustible/ GCV | D33: % / kcal/kg | E33: 22 | F33: 1647
B34: FLY ASH DISPOSAL REPORT
B35: 5 | C35: Fly ash to cement mill | D35: MT | E35: 18 | F35: =E35+'5'!F35 -> 18 | G35: =E35+'5'!G35 -> 3825
B36: 6 | C36: Fly ash to Coal yard(Truck) | D36: nos | E36: 3 | F36: =E36+'5'!F36 -> 28 | G36: =E36+'5'!G36 -> 397
B37: 7 | C37: Fly ash to Dumpyard(Truck) | D37: nos | E37: 0 | F37: =E37+'5'!F37 -> 0 | G37: =E37+'5'!G37 -> 0

Sheet 7
B3: 1*10 MW CAPTIVE POWER PLANT
B4: Daily,Monthly & Yearly Generation Report (FRM-LCL-PP-06)
B6: Sr. NO. | C6: Description | D6: Unit | E6: ='6'!E6+1 -> 46272 | F6: Month to Date | G6: Year to Date(APR2026-MAR2027)
B7: 1 | C7: Gross Power Generation | D7: kWhr | E7: 172100 | F7: =E7+'6'!F7 -> 1227800 | G7: =E7+'6'!G7 -> 26248216
B8: 2 | C8: Auxiliary power consumption | D8: kWhr | E8: 17662 | F8: =E8+'6'!F8 -> 125441 | G8: =E8+'6'!G8 -> 2840934
B9: 3 | C9: Net Power Exported | D9: kWhr | E9: =E7-E8 -> 154438 | F9: =E9+'6'!F9 -> 1102359 | G9: =E9+'6'!G9 -> 23407282
B10: 4 | C10: Auxiliary power consumption | D10: ( % ) | E10: =E8/E7*100 -> 10.262638 | F10: =F8/F7*100 -> 10.216729 | G10: =G8/G7*100 -> 10.823341
B11: 5 | C11: Average Power Generation | D11: MWhr | E11: =E7/E12/1000 -> 7.1708333 | F11: =F7/F12/1000 -> 7.3083333 | G11: =G7/G12/1000 -> 6.8718724
B12: 6 | C12: Plant Running Hours | D12: Hrs | E12: 24 | F12: =E12+'6'!F12 -> 168 | G12: =E12+'6'!G12 -> 3819.66
B13: 6 | C13: PLF | D13: ( % ) | E13: =E11/10*100 -> 71.708333 | F13: =F11/10*100 -> 73.083333 | G13: =G11/10*100 -> 68.718724
B14: 7 | C14: Feed Water consumption | D14: MT | E14: 786 | F14: =E14+'6'!F14 -> 5623 | G14: =E14+'6'!G14 -> 121821
B15: 8 | C15: Boiler Steam Generation | D15: MT | E15: 767 | F15: =E15+'6'!F15 -> 5453 | G15: =E15+'6'!G15 -> 118130
B16: 9 | C16: Bleed steam | D16: MT | E16: 57 | F16: =E16+'6'!F16 -> 387 | G16: =E16+'6'!G16 -> 7875
B17: 10 | C17: Turbine steam consumption | D17: MT | E17: 721 | F17: =E17+'6'!F17 -> 5120 | G17: =E17+'6'!G17 -> 109412
B18: 11 | C18: Condensate Generation | D18: MT | E18: 566 | F18: =E18+'6'!F18 -> 4039 | G18: =E18+'6'!G18 -> 87168
B19: 12 | C19: Auxilairy steam consumption | D19: MT | E19: 17 | F19: =E19+'6'!F19 -> 123 | G19: =E19+'6'!G19 -> 2821
B20: 13 | C20: Specific steam consumption | D20: Kg/Kwhr | E20: =E17*1000/E7 -> 4.1894248 | F20: =F17*1000/F7 -> 4.1700603 | G20: =G17*1000/G7 -> 4.1683595
B21: 14 | C21: Specific fuel consumption | D21: Kg/Kwhr | E21: =E26*1000/E7 -> 0.74956421 | F21: =F26*1000/F7 -> 0.74686431 | G21: =G26*1000/G7 -> 0.82817057
B22: 15 | C22: Heat Rate(TG)2880 | D22: Kcal/Kwh | E22: =((E17*(803-130)+E31*(30))*1000)/E7 -> 2821.4003 | F22: =((F17*(803-130)+F31*(30))*1000)/F7 -> 2808.5274 | G22: =((G17*(803-130)+G31*(30))*1000)/G7 -> 2808.0273
B23: 16 | C23: Heat Rate ( Plant ) 3300 @ MCR | D23: Kcal/Kwh | E23: =(E15*(803-130))*1000/(E7*0.78) -> 3845.3419 | F23: =(F15*(803-130))*1000/(F7*0.78) -> 3832.025 | G23: =(G15*(803-130))*1000/(G7*0.78) -> 3883.1206
B24: 17 | C24: DG Power Generation | D24: kWhr | E24: 0 | F24: =E24+'6'!F24 -> 0 | G24: =E24+'6'!G24 -> 1468
B25: FUEL Report
B26: 1 | C26: Coal Consumption | D26: MT | E26: 129 | F26: =E26+'6'!F26 -> 917 | G26: =E26+'6'!G26 -> 21738
B27: 2 | C27: GCV ( ADB ) | D27: Kcal/kg | E27: 4397
B30: 1 | C30: DM water Generation | D30: m3 | E30: 10 | F30: =E30+'6'!F30 -> 85 | G30: =E30+'6'!G30 -> 2369
B31: 2 | C31: DM water Consumption | D31: m3 | E31: 11 | F31: =E31+'6'!F31 -> 85 | G31: =E31+'6'!G31 -> 2381
B32: 3 | C32: CT Makeup Water Consumption | D32: m3 | E32: 18 | F32: =E32+'6'!F32 -> 164 | G32: =E32+'6'!G32 -> 3268
B33: 4 | C33: Fly ash combustible/ GCV | D33: % / kcal/kg | E33: 18.95 | F33: 1498
B34: FLY ASH DISPOSAL REPORT
B35: 5 | C35: Fly ash to cement mill | D35: MT | E35: 17 | F35: =E35+'6'!F35 -> 35 | G35: =E35+'6'!G35 -> 3842
B36: 6 | C36: Fly ash to Coal yard(Truck) | D36: nos | E36: 3 | F36: =E36+'6'!F36 -> 31 | G36: =E36+'6'!G36 -> 400
B37: 7 | C37: Fly ash to Dumpyard(Truck) | D37: nos | E37: 0 | F37: =E37+'6'!F37 -> 0 | G37: =E37+'6'!G37 -> 0

Sheet 8
B3: 1*10 MW CAPTIVE POWER PLANT
B4: Daily,Monthly & Yearly Generation Report (FRM-LCL-PP-06)
B6: Sr. NO. | C6: Description | D6: Unit | E6: ='7'!E6+1 -> 46273 | F6: Month to Date | G6: Year to Date(APR2026-MAR2027)
B7: 1 | C7: Gross Power Generation | D7: kWhr | E7: 179400 | F7: =E7+'7'!F7 -> 1407200 | G7: =E7+'7'!G7 -> 26427616
B8: 2 | C8: Auxiliary power consumption | D8: kWhr | E8: 18035 | F8: =E8+'7'!F8 -> 143476 | G8: =E8+'7'!G8 -> 2858969
B9: 3 | C9: Net Power Exported | D9: kWhr | E9: =E7-E8 -> 161365 | F9: =E9+'7'!F9 -> 1263724 | G9: =E9+'7'!G9 -> 23568647
B10: 4 | C10: Auxiliary power consumption | D10: ( % ) | E10: =E8/E7*100 -> 10.052954 | F10: =F8/F7*100 -> 10.19585 | G10: =G8/G7*100 -> 10.818112
B11: 5 | C11: Average Power Generation | D11: MWhr | E11: =E7/E12/1000 -> 7.475 | F11: =F7/F12/1000 -> 7.3291667 | G11: =G7/G12/1000 -> 6.8756383
B12: 6 | C12: Plant Running Hours | D12: Hrs | E12: 24 | F12: =E12+'7'!F12 -> 192 | G12: =E12+'7'!G12 -> 3843.66
B13: 6 | C13: PLF | D13: ( % ) | E13: =E11/10*100 -> 74.75 | F13: =F11/10*100 -> 73.291667 | G13: =G11/10*100 -> 68.756383
B14: 7 | C14: Feed Water consumption | D14: MT | E14: 819 | F14: =E14+'7'!F14 -> 6442 | G14: =E14+'7'!G14 -> 122640
B15: 8 | C15: Boiler Steam Generation | D15: MT | E15: 795 | F15: =E15+'7'!F15 -> 6248 | G15: =E15+'7'!G15 -> 118925
B16: 9 | C16: Bleed steam | D16: MT | E16: 61 | F16: =E16+'7'!F16 -> 448 | G16: =E16+'7'!G16 -> 7936
B17: 10 | C17: Turbine steam consumption | D17: MT | E17: 752 | F17: =E17+'7'!F17 -> 5872 | G17: =E17+'7'!G17 -> 110164
B18: 11 | C18: Condensate Generation | D18: MT | E18: 588 | F18: =E18+'7'!F18 -> 4627 | G18: =E18+'7'!G18 -> 87756
B19: 12 | C19: Auxilairy steam consumption | D19: MT | E19: 19 | F19: =E19+'7'!F19 -> 142 | G19: =E19+'7'!G19 -> 2840
B20: 13 | C20: Specific steam consumption | D20: Kg/Kwhr | E20: =E17*1000/E7 -> 4.1917503 | F20: =F17*1000/F7 -> 4.1728255 | G20: =G17*1000/G7 -> 4.1685183
B21: 14 | C21: Specific fuel consumption | D21: Kg/Kwhr | E21: =E26*1000/E7 -> 0.74693423 | F21: =F26*1000/F7 -> 0.74687322 | G21: =G26*1000/G7 -> 0.82761911
B22: 15 | C22: Heat Rate(TG)2880 | D22: Kcal/Kwh | E22: =((E17*(803-130)+E31*(30))*1000)/E7 -> 2823.0546 | F22: =((F17*(803-130)+F31*(30))*1000)/F7 -> 2810.3795 | G22: =((G17*(803-130)+G31*(30))*1000)/G7 -> 2808.1293
B23: 16 | C23: Heat Rate ( Plant ) 3300 @ MCR | D23: Kcal/Kwh | E23: =(E15*(803-130))*1000/(E7*0.78) -> 3823.5357 | F23: =(F15*(803-130))*1000/(F7*0.78) -> 3830.9427 | G23: =(G15*(803-130))*1000/(G7*0.78) -> 3882.7161
B24: 17 | C24: DG Power Generation | D24: kWhr | E24: 0 | F24: =E24+'7'!F24 -> 0 | G24: =E24+'7'!G24 -> 1468
B25: FUEL Report
B26: 1 | C26: Coal Consumption | D26: MT | E26: 134 | F26: =E26+'7'!F26 -> 1051 | G26: =E26+'7'!G26 -> 21872
B27: 2 | C27: GCV ( ADB ) | D27: Kcal/kg | E27: 4382
B29: WTP Report
B30: 1 | C30: DM water Generation | D30: m3 | E30: 14 | F30: =E30+'7'!F30 -> 99 | G30: =E30+'7'!G30 -> 2383
B31: 2 | C31: DM water Consumption | D31: m3 | E31: 12 | F31: =E31+'7'!F31 -> 97 | G31: =E31+'7'!G31 -> 2393
B32: 3 | C32: CT Makeup Water Consumption | D32: m3 | E32: 18 | F32: =E32+'7'!F32 -> 182 | G32: =E32+'7'!G32 -> 3286
B33: 4 | C33: Fly ash combustible/ GCV | D33: % / kcal/kg | E33: 19 | F33: 1402
B34: FLY ASH DISPOSAL REPORT
B35: 5 | C35: Fly ash to cement mill | D35: MT | E35: 0 | F35: =E35+'7'!F35 -> 35 | G35: =E35+'7'!G35 -> 3842
B36: 6 | C36: Fly ash to Coal yard(Truck) | D36: nos | E36: 5 | F36: =E36+'7'!F36 -> 36 | G36: =E36+'7'!G36 -> 405
B37: 7 | C37: Fly ash to Dumpyard(Truck) | D37: nos | E37: 0 | F37: =E37+'7'!F37 -> 0 | G37: =E37+'7'!G37 -> 0

Sheet 9
B3: 1*10 MW CAPTIVE POWER PLANT
B4: Daily,Monthly & Yearly Generation Report (FRM-LCL-PP-06)
B6: Sr. NO. | C6: Description | D6: Unit | E6: ='8'!E6+1 -> 46274 | F6: Month to Date | G6: Year to Date(APR2026-MAR2027)
B7: 1 | C7: Gross Power Generation | D7: kWhr | E7: 183200 | F7: =E7+'8'!F7 -> 1590400 | G7: =E7+'8'!G7 -> 26610816
B8: 2 | C8: Auxiliary power consumption | D8: kWhr | E8: 18049 | F8: =E8+'8'!F8 -> 161525 | G8: =E8+'8'!G8 -> 2877018
B9: 3 | C9: Net Power Exported | D9: kWhr | E9: =E7-E8 -> 165151 | F9: =E9+'8'!F9 -> 1428875 | G9: =E9+'8'!G9 -> 23733798
B10: 4 | C10: Auxiliary power consumption | D10: ( % ) | E10: =E8/E7*100 -> 9.8520742 | F10: =F8/F7*100 -> 10.15625 | G10: =G8/G7*100 -> 10.811461
B11: 5 | C11: Average Power Generation | D11: MWhr | E11: =E7/E12/1000 -> 7.6333333 | F11: =F7/F12/1000 -> 7.362963 | G11: =G7/G12/1000 -> 6.8803401
B12: 6 | C12: Plant Running Hours | D12: Hrs | E12: 24 | F12: =E12+'8'!F12 -> 216 | G12: =E12+'8'!G12 -> 3867.66
B13: 6 | C13: PLF | D13: ( % ) | E13: =E11/10*100 -> 76.333333 | F13: =F11/10*100 -> 73.62963 | G13: =G11/10*100 -> 68.803401
B14: 7 | C14: Feed Water consumption | D14: MT | E14: 832 | F14: =E14+'8'!F14 -> 7274 | G14: =E14+'8'!G14 -> 123472
B15: 8 | C15: Boiler Steam Generation | D15: MT | E15: 811 | F15: =E15+'8'!F15 -> 7059 | G15: =E15+'8'!G15 -> 119736
B16: 9 | C16: Bleed steam | D16: MT | E16: 61 | F16: =E16+'8'!F16 -> 509 | G16: =E16+'8'!G16 -> 7997
B17: 10 | C17: Turbine steam consumption | D17: MT | E17: 765 | F17: =E17+'8'!F17 -> 6637 | G17: =E17+'8'!G17 -> 110929
B18: 11 | C18: Condensate Generation | D18: MT | E18: 609 | F18: =E18+'8'!F18 -> 5236 | G18: =E18+'8'!G18 -> 88365
B19: 12 | C19: Auxilairy steam consumption | D19: MT | E19: 17 | F19: =E19+'8'!F19 -> 159 | G19: =E19+'8'!G19 -> 2857
B20: 13 | C20: Specific steam consumption | D20: Kg/Kwhr | E20: =E17*1000/E7 -> 4.1757642 | F20: =F17*1000/F7 -> 4.173164 | G20: =G17*1000/G7 -> 4.1685681
B21: 14 | C21: Specific fuel consumption | D21: Kg/Kwhr | E21: =E26*1000/E7 -> 0.74781659 | F21: =F26*1000/F7 -> 0.74698189 | G21: =G26*1000/G7 -> 0.82706971
B22: 15 | C22: Heat Rate(TG)2880 | D22: Kcal/Kwh | E22: =((E17*(803-130)+E31*(30))*1000)/E7 -> 2812.0906 | F22: =((F17*(803-130)+F31*(30))*1000)/F7 -> 2810.5766 | G22: =((G17*(803-130)+G31*(30))*1000)/G7 -> 2808.1565
B23: 16 | C23: Heat Rate ( Plant ) 3300 @ MCR | D23: Kcal/Kwh | E23: =(E15*(803-130))*1000/(E7*0.78) -> 3819.5821 | F23: =(F15*(803-130))*1000/(F7*0.78) -> 3829.6341 | G23: =(G15*(803-130))*1000/(G7*0.78) -> 3882.2814
B24: 17 | C24: DG Power Generation | D24: kWhr | E24: 0 | F24: =E24+'8'!F24 -> 0 | G24: =E24+'8'!G24 -> 1468
B25: FUEL Report
B26: 1 | C26: Coal Consumption | D26: MT | E26: 137 | F26: =E26+'8'!F26 -> 1188 | G26: =E26+'8'!G26 -> 22009
B27: 2 | C27: GCV ( ADB ) | D27: Kcal/kg | E27: 4134
B29: WTP Report
B30: 1 | C30: DM water Generation | D30: m3 | E30: 12 | F30: =E30+'8'!F30 -> 111 | G30: =E30+'8'!G30 -> 2395
B31: 2 | C31: DM water Consumption | D31: m3 | E31: 11 | F31: =E31+'8'!F31 -> 108 | G31: =E31+'8'!G31 -> 2404
B32: 3 | C32: CT Makeup Water Consumption | D32: m3 | E32: 18 | F32: =E32+'8'!F32 -> 200 | G32: =E32+'8'!G32 -> 3304
B33: 4 | C33: Fly ash combustible/ GCV | D33: % / kcal/kg | E33: 18 | F33: 1540
B34: FLY ASH DISPOSAL REPORT
B35: 5 | C35: Fly ash to cement mill | D35: MT | E35: 0 | F35: =E35+'8'!F35 -> 35 | G35: =E35+'8'!G35 -> 3842
B36: 6 | C36: Fly ash to Coal yard(Truck) | D36: nos | E36: 5 | F36: =E36+'8'!F36 -> 41 | G36: =E36+'8'!G36 -> 410
B37: 7 | C37: Fly ash to Dumpyard(Truck) | D37: nos | E37: 0 | F37: =E37+'8'!F37 -> 0 | G37: =E37+'8'!G37 -> 0

Sheet 10
B3: 1*10 MW CAPTIVE POWER PLANT
B4: Daily,Monthly & Yearly Generation Report (FRM-LCL-PP-06)
B6: Sr. NO. | C6: Description | D6: Unit | E6: ='9'!E6+1 -> 46275 | F6: Month to Date | G6: Year to Date(APR2026-MAR2027)
B7: 1 | C7: Gross Power Generation | D7: kWhr | E7: 185100 | F7: =E7+'9'!F7 -> 1775500 | G7: =E7+'9'!G7 -> 26795916
B8: 2 | C8: Auxiliary power consumption | D8: kWhr | E8: 18232 | F8: =E8+'9'!F8 -> 179757 | G8: =E8+'9'!G8 -> 2895250
B9: 3 | C9: Net Power Exported | D9: kWhr | E9: =E7-E8 -> 166868 | F9: =E9+'9'!F9 -> 1595743 | G9: =E9+'9'!G9 -> 23900666
B10: 4 | C10: Auxiliary power consumption | D10: ( % ) | E10: =E8/E7*100 -> 9.8498109 | F10: =F8/F7*100 -> 10.124303 | G10: =G8/G7*100 -> 10.804818
B11: 5 | C11: Average Power Generation | D11: MWhr | E11: =E7/E12/1000 -> 7.7125 | F11: =F7/F12/1000 -> 7.3979167 | G11: =G7/G12/1000 -> 6.885472
B12: 6 | C12: Plant Running Hours | D12: Hrs | E12: 24 | F12: =E12+'9'!F12 -> 240 | G12: =E12+'9'!G12 -> 3891.66
B13: 6 | C13: PLF | D13: ( % ) | E13: =E11/10*100 -> 77.125 | F13: =F11/10*100 -> 73.979167 | G13: =G11/10*100 -> 68.85472
B14: 7 | C14: Feed Water consumption | D14: MT | E14: 845 | F14: =E14+'9'!F14 -> 8119 | G14: =E14+'9'!G14 -> 124317
B15: 8 | C15: Boiler Steam Generation | D15: MT | E15: 817 | F15: =E15+'9'!F15 -> 7876 | G15: =E15+'9'!G15 -> 120553
B16: 9 | C16: Bleed steam | D16: MT | E16: 62 | F16: =E16+'9'!F16 -> 571 | G16: =E16+'9'!G16 -> 8059
B17: 10 | C17: Turbine steam consumption | D17: MT | E17: 776 | F17: =E17+'9'!F17 -> 7413 | G17: =E17+'9'!G17 -> 111705
B18: 11 | C18: Condensate Generation | D18: MT | E18: 608 | F18: =E18+'9'!F18 -> 5844 | G18: =E18+'9'!G18 -> 88973
B19: 12 | C19: Auxilairy steam consumption | D19: MT | E19: 18 | F19: =E19+'9'!F19 -> 177 | G19: =E19+'9'!G19 -> 2875
B20: 13 | C20: Specific steam consumption | D20: Kg/Kwhr | E20: =E17*1000/E7 -> 4.1923285 | F20: =F17*1000/F7 -> 4.1751619 | G20: =G17*1000/G7 -> 4.1687323
B21: 14 | C21: Specific fuel consumption | D21: Kg/Kwhr | E21: =E26*1000/E7 -> 0.74554295 | F21: =F26*1000/F7 -> 0.74683188 | G21: =G26*1000/G7 -> 0.82650655
B22: 15 | C22: Heat Rate(TG)2880 | D22: Kcal/Kwh | E22: =((E17*(803-130)+E31*(30))*1000)/E7 -> 2823.544 | F22: =((F17*(803-130)+F31*(30))*1000)/F7 -> 2811.9285 | G22: =((G17*(803-130)+G31*(30))*1000)/G7 -> 2808.2628
B23: 16 | C23: Heat Rate ( Plant ) 3300 @ MCR | D23: Kcal/Kwh | E23: =(E15*(803-130))*1000/(E7*0.78) -> 3808.3434 | F23: =(F15*(803-130))*1000/(F7*0.78) -> 3827.4145 | G23: =(G15*(803-130))*1000/(G7*0.78) -> 3881.7707
B24: 17 | C24: DG Power Generation | D24: kWhr | E24: 0 | F24: =E24+'9'!F24 -> 0 | G24: =E24+'9'!G24 -> 1468
B25: FUEL Report
B26: 1 | C26: Coal Consumption | D26: MT | E26: 138 | F26: =E26+'9'!F26 -> 1326 | G26: =E26+'9'!G26 -> 22147
B27: 2 | C27: GCV ( ADB ) | D27: Kcal/kg | E27: 4205
B29: WTP Report
B30: 1 | C30: DM water Generation | D30: m3 | E30: 10 | F30: =E30+'9'!F30 -> 121 | G30: =E30+'9'!G30 -> 2405
B31: 2 | C31: DM water Consumption | D31: m3 | E31: 13 | F31: =E31+'9'!F31 -> 121 | G31: =E31+'9'!G31 -> 2417
B32: 3 | C32: CT Makeup Water Consumption | D32: m3 | E32: 18 | F32: =E32+'9'!F32 -> 218 | G32: =E32+'9'!G32 -> 3322
B33: 4 | C33: Fly ash combustible/ GCV | D33: % / kcal/kg | E33: 19 | F33: 1533
B34: FLY ASH DISPOSAL REPORT
B35: 5 | C35: Fly ash to cement mill | D35: MT | E35: 52 | F35: =E35+'9'!F35 -> 87 | G35: =E35+'9'!G35 -> 3894
B36: 6 | C36: Fly ash to Coal yard(Truck) | D36: nos | E36: 0 | F36: =E36+'9'!F36 -> 41 | G36: =E36+'9'!G36 -> 410
B37: 7 | C37: Fly ash to Dumpyard(Truck) | D37: nos | E37: 0 | F37: =E37+'9'!F37 -> 0 | G37: =E37+'9'!G37 -> 0

Sheet 11
B3: 1*10 MW CAPTIVE POWER PLANT
B4: Daily,Monthly & Yearly Generation Report (FRM-LCL-PP-06)
B6: Sr. NO. | C6: Description | D6: Unit | E6: ='10'!E6+1 -> 46276 | F6: Month to Date | G6: Year to Date(APR2026-MAR2027)
B7: 1 | C7: Gross Power Generation | D7: kWhr | E7: 165700 | F7: =E7+'10'!F7 -> 1941200 | G7: =E7+'10'!G7 -> 26961616
B8: 2 | C8: Auxiliary power consumption | D8: kWhr | E8: 17719 | F8: =E8+'10'!F8 -> 197476 | G8: =E8+'10'!G8 -> 2912969
B9: 3 | C9: Net Power Exported | D9: kWhr | E9: =E7-E8 -> 147981 | F9: =E9+'10'!F9 -> 1743724 | G9: =E9+'10'!G9 -> 24048647
B10: 4 | C10: Auxiliary power consumption | D10: ( % ) | E10: =E8/E7*100 -> 10.693422 | F10: =F8/F7*100 -> 10.172883 | G10: =G8/G7*100 -> 10.804134
B11: 5 | C11: Average Power Generation | D11: MWhr | E11: =E7/E12/1000 -> 6.9041667 | F11: =F7/F12/1000 -> 7.3530303 | G11: =G7/G12/1000 -> 6.8855866
B12: 6 | C12: Plant Running Hours | D12: Hrs | E12: 24 | F12: =E12+'10'!F12 -> 264 | G12: =E12+'10'!G12 -> 3915.66
B13: 6 | C13: PLF | D13: ( % ) | E13: =E11/10*100 -> 69.041667 | F13: =F11/10*100 -> 73.530303 | G13: =G11/10*100 -> 68.855866
B14: 7 | C14: Feed Water consumption | D14: MT | E14: 759 | F14: =E14+'10'!F14 -> 8878 | G14: =E14+'10'!G14 -> 125076
B15: 8 | C15: Boiler Steam Generation | D15: MT | E15: 737 | F15: =E15+'10'!F15 -> 8613 | G15: =E15+'10'!G15 -> 121290
B16: 9 | C16: Bleed steam | D16: MT | E16: 56 | F16: =E16+'10'!F16 -> 627 | G16: =E16+'10'!G16 -> 8115
B17: 10 | C17: Turbine steam consumption | D17: MT | E17: 691 | F17: =E17+'10'!F17 -> 8104 | G17: =E17+'10'!G17 -> 112396
B18: 11 | C18: Condensate Generation | D18: MT | E18: 576 | F18: =E18+'10'!F18 -> 6420 | G18: =E18+'10'!G18 -> 89549
B19: 12 | C19: Auxilairy steam consumption | D19: MT | E19: 17 | F19: =E19+'10'!F19 -> 194 | G19: =E19+'10'!G19 -> 2892
B20: 13 | C20: Specific steam consumption | D20: Kg/Kwhr | E20: =E17*1000/E7 -> 4.1701871 | F20: =F17*1000/F7 -> 4.1747373 | G20: =G17*1000/G7 -> 4.1687412
B21: 14 | C21: Specific fuel consumption | D21: Kg/Kwhr | E21: =E26*1000/E7 -> 0.74230537 | F21: =F26*1000/F7 -> 0.7464455 | G21: =G26*1000/G7 -> 0.82598907
B22: 15 | C22: Heat Rate(TG)2880 | D22: Kcal/Kwh | E22: =((E17*(803-130)+E31*(30))*1000)/E7 -> 2808.8896 | F22: =((F17*(803-130)+F31*(30))*1000)/F7 -> 2811.6691 | G22: =((G17*(803-130)+G31*(30))*1000)/G7 -> 2808.2667
B23: 16 | C23: Heat Rate ( Plant ) 3300 @ MCR | D23: Kcal/Kwh | E23: =(E15*(803-130))*1000/(E7*0.78) -> 3837.6507 | F23: =(F15*(803-130))*1000/(F7*0.78) -> 3828.2882 | G23: =(G15*(803-130))*1000/(G7*0.78) -> 3881.4995
B24: 17 | C24: DG Power Generation | D24: kWhr | E24: 0 | F24: =E24+'10'!F24 -> 0 | G24: =E24+'10'!G24 -> 1468
B25: FUEL Report
B26: 1 | C26: Coal Consumption | D26: MT | E26: 123 | F26: =E26+'10'!F26 -> 1449 | G26: =E26+'10'!G26 -> 22270
B27: 2 | C27: GCV ( ADB ) | D27: Kcal/kg | E27: 4371
B29: WTP Report
B30: 1 | C30: DM water Generation | D30: m3 | E30: 13 | F30: =E30+'10'!F30 -> 134 | G30: =E30+'10'!G30 -> 2418
B31: 2 | C31: DM water Consumption | D31: m3 | E31: 13 | F31: =E31+'10'!F31 -> 134 | G31: =E31+'10'!G31 -> 2430
B32: 3 | C32: CT Makeup Water Consumption | D32: m3 | E32: 18 | F32: =E32+'10'!F32 -> 236 | G32: =E32+'10'!G32 -> 3340
B33: 4 | C33: Fly ash combustible/ GCV | D33: % / kcal/kg | E33: 19 | F33: 1599
B34: FLY ASH DISPOSAL REPORT
B35: 5 | C35: Fly ash to cement mill | D35: MT | E35: 25 | F35: =E35+'10'!F35 -> 112 | G35: =E35+'10'!G35 -> 3919
B36: 6 | C36: Fly ash to Coal yard(Truck) | D36: nos | E36: 2 | F36: =E36+'10'!F36 -> 43 | G36: =E36+'10'!G36 -> 412
B37: 7 | C37: Fly ash to Dumpyard(Truck) | D37: nos | E37: 0 | F37: =E37+'10'!F37 -> 0 | G37: =E37+'10'!G37 -> 0

Sheet 12
B3: 1*10 MW CAPTIVE POWER PLANT
B4: Daily,Monthly & Yearly Generation Report (FRM-LCL-PP-06)
B6: Sr. NO. | C6: Description | D6: Unit | E6: ='11'!E6+1 -> 46277 | F6: Month to Date | G6: Year to Date(APR2026-MAR2027)
B7: 1 | C7: Gross Power Generation | D7: kWhr | E7: 168100 | F7: =E7+'11'!F7 -> 2109300 | G7: =E7+'11'!G7 -> 27129716
B8: 2 | C8: Auxiliary power consumption | D8: kWhr | E8: 17857 | F8: =E8+'11'!F8 -> 215333 | G8: =E8+'11'!G8 -> 2930826
B9: 3 | C9: Net Power Exported | D9: kWhr | E9: =E7-E8 -> 150243 | F9: =E9+'11'!F9 -> 1893967 | G9: =E9+'11'!G9 -> 24198890
B10: 4 | C10: Auxiliary power consumption | D10: ( % ) | E10: =E8/E7*100 -> 10.622844 | F10: =F8/F7*100 -> 10.208742 | G10: =G8/G7*100 -> 10.80301
B11: 5 | C11: Average Power Generation | D11: MWhr | E11: =E7/E12/1000 -> 7.0041667 | F11: =F7/F12/1000 -> 7.3239583 | G11: =G7/G12/1000 -> 6.886309
B12: 6 | C12: Plant Running Hours | D12: Hrs | E12: 24 | F12: =E12+'11'!F12 -> 288 | G12: =E12+'11'!G12 -> 3939.66
B13: 6 | C13: PLF | D13: ( % ) | E13: =E11/10*100 -> 70.041667 | F13: =F11/10*100 -> 73.239583 | G13: =G11/10*100 -> 68.86309
B14: 7 | C14: Feed Water consumption | D14: MT | E14: 764 | F14: =E14+'11'!F14 -> 9642 | G14: =E14+'11'!G14 -> 125840
B15: 8 | C15: Boiler Steam Generation | D15: MT | E15: 743 | F15: =E15+'11'!F15 -> 9356 | G15: =E15+'11'!G15 -> 122033
B16: 9 | C16: Bleed steam | D16: MT | E16: 57 | F16: =E16+'11'!F16 -> 684 | G16: =E16+'11'!G16 -> 8172
B17: 10 | C17: Turbine steam consumption | D17: MT | E17: 698 | F17: =E17+'11'!F17 -> 8802 | G17: =E17+'11'!G17 -> 113094
B18: 11 | C18: Condensate Generation | D18: MT | E18: 551 | F18: =E18+'11'!F18 -> 6971 | G18: =E18+'11'!G18 -> 90100
B19: 12 | C19: Auxilairy steam consumption | D19: MT | E19: 18 | F19: =E19+'11'!F19 -> 212 | G19: =E19+'11'!G19 -> 2910
B20: 13 | C20: Specific steam consumption | D20: Kg/Kwhr | E20: =E17*1000/E7 -> 4.1522903 | F20: =F17*1000/F7 -> 4.1729484 | G20: =G17*1000/G7 -> 4.1686393
B21: 14 | C21: Specific fuel consumption | D21: Kg/Kwhr | E21: =E26*1000/E7 -> 0.73765616 | F21: =F26*1000/F7 -> 0.74574503 | G21: =G26*1000/G7 -> 0.82544174
B22: 15 | C22: Heat Rate(TG)2880 | D22: Kcal/Kwh | E22: =((E17*(803-130)+E31*(30))*1000)/E7 -> 2796.4545 | F22: =((F17*(803-130)+F31*(30))*1000)/F7 -> 2810.4565 | G22: =((G17*(803-130)+G31*(30))*1000)/G7 -> 2808.1935
B23: 16 | C23: Heat Rate ( Plant ) 3300 @ MCR | D23: Kcal/Kwh | E23: =(E15*(803-130))*1000/(E7*0.78) -> 3813.6564 | F23: =(F15*(803-130))*1000/(F7*0.78) -> 3827.1221 | G23: =(G15*(803-130))*1000/(G7*0.78) -> 3881.0792
B24: 17 | C24: DG Power Generation | D24: kWhr | E24: 0 | F24: =E24+'11'!F24 -> 0 | G24: =E24+'11'!G24 -> 1468
B25: FUEL Report
B26: 1 | C26: Coal Consumption | D26: MT | E26: 124 | F26: =E26+'11'!F26 -> 1573 | G26: =E26+'11'!G26 -> 22394
B27: 2 | C27: GCV ( ADB ) | D27: Kcal/kg | E27: 4614
B29: WTP Report
B30: 1 | C30: DM water Generation | D30: m3 | E30: 13 | F30: =E30+'11'!F30 -> 147 | G30: =E30+'11'!G30 -> 2431
B31: 2 | C31: DM water Consumption | D31: m3 | E31: 11 | F31: =E31+'11'!F31 -> 145 | G31: =E31+'11'!G31 -> 2441
B32: 3 | C32: CT Makeup Water Consumption | D32: m3 | E32: 18 | F32: =E32+'11'!F32 -> 254 | G32: =E32+'11'!G32 -> 3358
B33: 4 | C33: Fly ash combustible/ GCV | D33: % / kcal/kg | E33: 20 | F33: 1523
B34: FLY ASH DISPOSAL REPORT
B35: 5 | C35: Fly ash to cement mill | D35: MT | E35: 0 | F35: =E35+'11'!F35 -> 112 | G35: =E35+'11'!G35 -> 3919
B36: 6 | C36: Fly ash to Coal yard(Truck) | D36: nos | E36: 4 | F36: =E36+'11'!F36 -> 47 | G36: =E36+'11'!G36 -> 416
B37: 7 | C37: Fly ash to Dumpyard(Truck) | D37: nos | E37: 0 | F37: =E37+'11'!F37 -> 0 | G37: =E37+'11'!G37 -> 0

Sheet 13
B3: 1*10 MW CAPTIVE POWER PLANT
B4: Daily,Monthly & Yearly Generation Report (FRM-LCL-PP-06)
B6: Sr. NO. | C6: Description | D6: Unit | E6: ='12'!E6+1 -> 46278 | F6: Month to Date | G6: Year to Date(APR2026-MAR2027)
B7: 1 | C7: Gross Power Generation | D7: kWhr | E7: 134000 | F7: =E7+'12'!F7 -> 2243300 | G7: =E7+'12'!G7 -> 27263716
B8: 2 | C8: Auxiliary power consumption | D8: kWhr | E8: 18045 | F8: =E8+'12'!F8 -> 233378 | G8: =E8+'12'!G8 -> 2948871
B9: 3 | C9: Net Power Exported | D9: kWhr | E9: =E7-E8 -> 115955 | F9: =E9+'12'!F9 -> 2009922 | G9: =E9+'12'!G9 -> 24314845
B10: 4 | C10: Auxiliary power consumption | D10: ( % ) | E10: =E8/E7*100 -> 13.466418 | F10: =F8/F7*100 -> 10.403334 | G10: =G8/G7*100 -> 10.816101
B11: 5 | C11: Average Power Generation | D11: MWhr | E11: =E7/E12/1000 -> 5.5833333 | F11: =F7/F12/1000 -> 7.1900641 | G11: =G7/G12/1000 -> 6.8784194
B12: 6 | C12: Plant Running Hours | D12: Hrs | E12: 24 | F12: =E12+'12'!F12 -> 312 | G12: =E12+'12'!G12 -> 3963.66
B13: 6 | C13: PLF | D13: ( % ) | E13: =E11/10*100 -> 55.833333 | F13: =F11/10*100 -> 71.900641 | G13: =G11/10*100 -> 68.784194
B14: 7 | C14: Feed Water consumption | D14: MT | E14: 640 | F14: =E14+'12'!F14 -> 10282 | G14: =E14+'12'!G14 -> 126480
B15: 8 | C15: Boiler Steam Generation | D15: MT | E15: 610 | F15: =E15+'12'!F15 -> 9966 | G15: =E15+'12'!G15 -> 122643
B16: 9 | C16: Bleed steam | D16: MT | E16: 43 | F16: =E16+'12'!F16 -> 727 | G16: =E16+'12'!G16 -> 8215
B17: 10 | C17: Turbine steam consumption | D17: MT | E17: 565 | F17: =E17+'12'!F17 -> 9367 | G17: =E17+'12'!G17 -> 113659
B18: 11 | C18: Condensate Generation | D18: MT | E18: 479 | F18: =E18+'12'!F18 -> 7450 | G18: =E18+'12'!G18 -> 90579
B19: 12 | C19: Auxilairy steam consumption | D19: MT | E19: 16 | F19: =E19+'12'!F19 -> 228 | G19: =E19+'12'!G19 -> 2926
B20: 13 | C20: Specific steam consumption | D20: Kg/Kwhr | E20: =E17*1000/E7 -> 4.2164179 | F20: =F17*1000/F7 -> 4.175545 | G20: =G17*1000/G7 -> 4.1688741
B21: 14 | C21: Specific fuel consumption | D21: Kg/Kwhr | E21: =E26*1000/E7 -> 0.75373134 | F21: =F26*1000/F7 -> 0.74622208 | G21: =G26*1000/G7 -> 0.82508929
B22: 15 | C22: Heat Rate(TG)2880 | D22: Kcal/Kwh | E22: =((E17*(803-130)+E31*(30))*1000)/E7 -> 2843.0224 | F22: =((F17*(803-130)+F31*(30))*1000)/F7 -> 2812.4018 | G22: =((G17*(803-130)+G31*(30))*1000)/G7 -> 2808.3647
B23: 16 | C23: Heat Rate ( Plant ) 3300 @ MCR | D23: Kcal/Kwh | E23: =(E15*(803-130))*1000/(E7*0.78) -> 3927.765 | F23: =(F15*(803-130))*1000/(F7*0.78) -> 3833.1339 | G23: =(G15*(803-130))*1000/(G7*0.78) -> 3881.3086
B24: 17 | C24: DG Power Generation | D24: kWhr | E24: 0 | F24: =E24+'12'!F24 -> 0 | G24: =E24+'12'!G24 -> 1468
B25: FUEL Report
B26: 1 | C26: Coal Consumption | D26: MT | E26: 101 | F26: =E26+'12'!F26 -> 1674 | G26: =E26+'12'!G26 -> 22495
B27: 2 | C27: GCV ( ADB ) | D27: Kcal/kg | E27: 4542
B29: WTP Report
B30: 1 | C30: DM water Generation | D30: m3 | E30: 21 | F30: =E30+'12'!F30 -> 168 | G30: =E30+'12'!G30 -> 2452
B31: 2 | C31: DM water Consumption | D31: m3 | E31: 24 | F31: =E31+'12'!F31 -> 169 | G31: =E31+'12'!G31 -> 2465
B32: 3 | C32: CT Makeup Water Consumption | D32: m3 | E32: 18 | F32: =E32+'12'!F32 -> 272 | G32: =E32+'12'!G32 -> 3376
B33: 4 | C33: Fly ash combustible/ GCV | D33: % / kcal/kg | E33: 21.8 | F33: 1674
B34: FLY ASH DISPOSAL REPORT
B35: 5 | C35: Fly ash to cement mill | D35: MT | E35: 0 | F35: =E35+'12'!F35 -> 112 | G35: =E35+'12'!G35 -> 3919
B36: 6 | C36: Fly ash to Coal yard(Truck) | D36: nos | E36: 3 | F36: =E36+'12'!F36 -> 50 | G36: =E36+'12'!G36 -> 419
B37: 7 | C37: Fly ash to Dumpyard(Truck) | D37: nos | E37: 0 | F37: =E37+'12'!F37 -> 0 | G37: =E37+'12'!G37 -> 0

Sheet 14
B3: 1*10 MW CAPTIVE POWER PLANT
B4: Daily,Monthly & Yearly Generation Report (FRM-LCL-PP-06)
B6: Sr. NO. | C6: Description | D6: Unit | E6: ='13'!E6+1 -> 46279 | F6: Month to Date | G6: Year to Date(APR2026-MAR2027)
B7: 1 | C7: Gross Power Generation | D7: kWhr | E7: 0 | F7: =E7+'13'!F7 -> 2243300 | G7: =E7+'13'!G7 -> 27263716
B8: 2 | C8: Auxiliary power consumption | D8: kWhr | E8: 0 | F8: =E8+'13'!F8 -> 233378 | G8: =E8+'13'!G8 -> 2948871
B9: 3 | C9: Net Power Exported | D9: kWhr | E9: =E7-E8 -> 0 | F9: =E9+'13'!F9 -> 2009922 | G9: =E9+'13'!G9 -> 24314845
B10: 4 | C10: Auxiliary power consumption | D10: ( % ) | E10: =E8/E7*100 -> #DIV/0! | F10: =F8/F7*100 -> 10.403334 | G10: =G8/G7*100 -> 10.816101
B11: 5 | C11: Average Power Generation | D11: MWhr | E11: =E7/E12/1000 -> #DIV/0! | F11: =F7/F12/1000 -> 7.1900641 | G11: =G7/G12/1000 -> 6.8784194
B12: 6 | C12: Plant Running Hours | D12: Hrs | E12: 0 | F12: =E12+'13'!F12 -> 312 | G12: =E12+'13'!G12 -> 3963.66
B13: 6 | C13: PLF | D13: ( % ) | E13: =E11/10*100 -> #DIV/0! | F13: =F11/10*100 -> 71.900641 | G13: =G11/10*100 -> 68.784194
B14: 7 | C14: Feed Water consumption | D14: MT | E14: 0 | F14: =E14+'13'!F14 -> 10282 | G14: =E14+'13'!G14 -> 126480
B15: 8 | C15: Boiler Steam Generation | D15: MT | E15: 0 | F15: =E15+'13'!F15 -> 9966 | G15: =E15+'13'!G15 -> 122643
B16: 9 | C16: Bleed steam | D16: MT | E16: 0 | F16: =E16+'13'!F16 -> 727 | G16: =E16+'13'!G16 -> 8215
B17: 10 | C17: Turbine steam consumption | D17: MT | E17: 0 | F17: =E17+'13'!F17 -> 9367 | G17: =E17+'13'!G17 -> 113659
B18: 11 | C18: Condensate Generation | D18: MT | E18: 0 | F18: =E18+'13'!F18 -> 7450 | G18: =E18+'13'!G18 -> 90579
B19: 12 | C19: Auxilairy steam consumption | D19: MT | E19: 0 | F19: =E19+'13'!F19 -> 228 | G19: =E19+'13'!G19 -> 2926
B20: 13 | C20: Specific steam consumption | D20: Kg/Kwhr | E20: =E17*1000/E7 -> #DIV/0! | F20: =F17*1000/F7 -> 4.175545 | G20: =G17*1000/G7 -> 4.1688741
B21: 14 | C21: Specific fuel consumption | D21: Kg/Kwhr | E21: =E26*1000/E7 -> #DIV/0! | F21: =F26*1000/F7 -> 0.74622208 | G21: =G26*1000/G7 -> 0.82508929
B22: 15 | C22: Heat Rate(TG)2880 | D22: Kcal/Kwh | E22: =((E17*(803-130)+E31*(30))*1000)/E7 -> #DIV/0! | F22: =((F17*(803-130)+F31*(30))*1000)/F7 -> 2812.4018 | G22: =((G17*(803-130)+G31*(30))*1000)/G7 -> 2808.3647
B23: 16 | C23: Heat Rate ( Plant ) 3300 @ MCR | D23: Kcal/Kwh | E23: =(E15*(803-130))*1000/(E7*0.78) -> #DIV/0! | F23: =(F15*(803-130))*1000/(F7*0.78) -> 3833.1339 | G23: =(G15*(803-130))*1000/(G7*0.78) -> 3881.3086
B24: 17 | C24: DG Power Generation | D24: kWhr | E24: 0 | F24: =E24+'13'!F24 -> 0 | G24: =E24+'13'!G24 -> 1468
B25: FUEL Report
B26: 1 | C26: Coal Consumption | D26: MT | E26: 0 | F26: =E26+'13'!F26 -> 1674 | G26: =E26+'13'!G26 -> 22495
B27: 2 | C27: GCV ( ADB ) | D27: Kcal/kg | E27: 0
B29: WTP Report
B30: 1 | C30: DM water Generation | D30: m3 | E30: 0 | F30: =E30+'13'!F30 -> 168 | G30: =E30+'13'!G30 -> 2452
B31: 2 | C31: DM water Consumption | D31: m3 | E31: 0 | F31: =E31+'13'!F31 -> 169 | G31: =E31+'13'!G31 -> 2465
B32: 3 | C32: CT Makeup Water Consumption | D32: m3 | E32: 0 | F32: =E32+'13'!F32 -> 272 | G32: =E32+'13'!G32 -> 3376
B33: 4 | C33: Fly ash combustible/ GCV | D33: % / kcal/kg | E33: 0 | F33: 0
B34: FLY ASH DISPOSAL REPORT
B35: 5 | C35: Fly ash to cement mill | D35: MT | E35: 0 | F35: =E35+'13'!F35 -> 112 | G35: =E35+'13'!G35 -> 3919
B36: 6 | C36: Fly ash to Coal yard(Truck) | D36: nos | E36: 0 | F36: =E36+'13'!F36 -> 50 | G36: =E36+'13'!G36 -> 419
B37: 7 | C37: Fly ash to Dumpyard(Truck) | D37: nos | E37: 0 | F37: =E37+'13'!F37 -> 0 | G37: =E37+'13'!G37 -> 0

Sheet 15
B3: 1*10 MW CAPTIVE POWER PLANT
B4: Daily,Monthly & Yearly Generation Report (FRM-LCL-PP-06)
B6: Sr. NO. | C6: Description | D6: Unit | E6: ='14'!E6+1 -> 46280 | F6: Month to Date | G6: Year to Date(APR2026-MAR2027)
B7: 1 | C7: Gross Power Generation | D7: kWhr | E7: 0 | F7: =E7+'14'!F7 -> 2243300 | G7: =E7+'14'!G7 -> 27263716
B8: 2 | C8: Auxiliary power consumption | D8: kWhr | E8: 0 | F8: =E8+'14'!F8 -> 233378 | G8: =E8+'14'!G8 -> 2948871
B9: 3 | C9: Net Power Exported | D9: kWhr | E9: =E7-E8 -> 0 | F9: =E9+'14'!F9 -> 2009922 | G9: =E9+'14'!G9 -> 24314845
B10: 4 | C10: Auxiliary power consumption | D10: ( % ) | E10: =E8/E7*100 -> #DIV/0! | F10: =F8/F7*100 -> 10.403334 | G10: =G8/G7*100 -> 10.816101
B11: 5 | C11: Average Power Generation | D11: MWhr | E11: =E7/E12/1000 -> #DIV/0! | F11: =F7/F12/1000 -> 7.1900641 | G11: =G7/G12/1000 -> 6.8784194
B12: 6 | C12: Plant Running Hours | D12: Hrs | E12: 0 | F12: =E12+'14'!F12 -> 312 | G12: =E12+'14'!G12 -> 3963.66
B13: 6 | C13: PLF | D13: ( % ) | E13: =E11/10*100 -> #DIV/0! | F13: =F11/10*100 -> 71.900641 | G13: =G11/10*100 -> 68.784194
B14: 7 | C14: Feed Water consumption | D14: MT | E14: 0 | F14: =E14+'14'!F14 -> 10282 | G14: =E14+'14'!G14 -> 126480
B15: 8 | C15: Boiler Steam Generation | D15: MT | E15: 0 | F15: =E15+'14'!F15 -> 9966 | G15: =E15+'14'!G15 -> 122643
B16: 9 | C16: Bleed steam | D16: MT | E16: 0 | F16: =E16+'14'!F16 -> 727 | G16: =E16+'14'!G16 -> 8215
B17: 10 | C17: Turbine steam consumption | D17: MT | E17: 0 | F17: =E17+'14'!F17 -> 9367 | G17: =E17+'14'!G17 -> 113659
B18: 11 | C18: Condensate Generation | D18: MT | E18: 0 | F18: =E18+'14'!F18 -> 7450 | G18: =E18+'14'!G18 -> 90579
B19: 12 | C19: Auxilairy steam consumption | D19: MT | E19: 0 | F19: =E19+'14'!F19 -> 228 | G19: =E19+'14'!G19 -> 2926
B20: 13 | C20: Specific steam consumption | D20: Kg/Kwhr | E20: =E17*1000/E7 -> #DIV/0! | F20: =F17*1000/F7 -> 4.175545 | G20: =G17*1000/G7 -> 4.1688741
B21: 14 | C21: Specific fuel consumption | D21: Kg/Kwhr | E21: =E26*1000/E7 -> #DIV/0! | F21: =F26*1000/F7 -> 0.74622208 | G21: =G26*1000/G7 -> 0.82508929
B22: 15 | C22: Heat Rate(TG)2880 | D22: Kcal/Kwh | E22: =((E17*(803-130)+E31*(30))*1000)/E7 -> #DIV/0! | F22: =((F17*(803-130)+F31*(30))*1000)/F7 -> 2812.4018 | G22: =((G17*(803-130)+G31*(30))*1000)/G7 -> 2808.3647
B23: 16 | C23: Heat Rate ( Plant ) 3300 @ MCR | D23: Kcal/Kwh | E23: =(E15*(803-130))*1000/(E7*0.78) -> #DIV/0! | F23: =(F15*(803-130))*1000/(F7*0.78) -> 3833.1339 | G23: =(G15*(803-130))*1000/(G7*0.78) -> 3881.3086
B24: 17 | C24: DG Power Generation | D24: kWhr | E24: 0 | F24: =E24+'14'!F24 -> 0 | G24: =E24+'14'!G24 -> 1468
B25: FUEL Report
B26: 1 | C26: Coal Consumption | D26: MT | E26: 0 | F26: =E26+'14'!F26 -> 1674 | G26: =E26+'14'!G26 -> 22495
B27: 2 | C27: GCV ( ADB ) | D27: Kcal/kg | E27: 0
B29: WTP Report
B30: 1 | C30: DM water Generation | D30: m3 | E30: 0 | F30: =E30+'14'!F30 -> 168 | G30: =E30+'14'!G30 -> 2452
B31: 2 | C31: DM water Consumption | D31: m3 | E31: 0 | F31: =E31+'14'!F31 -> 169 | G31: =E31+'14'!G31 -> 2465
B32: 3 | C32: CT Makeup Water Consumption | D32: m3 | E32: 0 | F32: =E32+'14'!F32 -> 272 | G32: =E32+'14'!G32 -> 3376
B33: 4 | C33: Fly ash combustible/ GCV | D33: % / kcal/kg | E33: 0 | F33: 0
B34: FLY ASH DISPOSAL REPORT
B35: 5 | C35: Fly ash to cement mill | D35: MT | E35: 0 | F35: =E35+'14'!F35 -> 112 | G35: =E35+'14'!G35 -> 3919
B36: 6 | C36: Fly ash to Coal yard(Truck) | D36: nos | E36: 0 | F36: =E36+'14'!F36 -> 50 | G36: =E36+'14'!G36 -> 419
B37: 7 | C37: Fly ash to Dumpyard(Truck) | D37: nos | E37: 0 | F37: =E37+'14'!F37 -> 0 | G37: =E37+'14'!G37 -> 0

Sheet 16
B3: 1*10 MW CAPTIVE POWER PLANT
B4: Daily,Monthly & Yearly Generation Report (FRM-LCL-PP-06)
B6: Sr. NO. | C6: Description | D6: Unit | E6: ='15'!E6+1 -> 46281 | F6: Month to Date | G6: Year to Date(APR2026-MAR2027)
B7: 1 | C7: Gross Power Generation | D7: kWhr | E7: 0 | F7: =E7+'15'!F7 -> 2243300 | G7: =E7+'15'!G7 -> 27263716
B8: 2 | C8: Auxiliary power consumption | D8: kWhr | E8: 0 | F8: =E8+'15'!F8 -> 233378 | G8: =E8+'15'!G8 -> 2948871
B9: 3 | C9: Net Power Exported | D9: kWhr | E9: =E7-E8 -> 0 | F9: =E9+'15'!F9 -> 2009922 | G9: =E9+'15'!G9 -> 24314845
B10: 4 | C10: Auxiliary power consumption | D10: ( % ) | E10: =E8/E7*100 -> #DIV/0! | F10: =F8/F7*100 -> 10.403334 | G10: =G8/G7*100 -> 10.816101
B11: 5 | C11: Average Power Generation | D11: MWhr | E11: =E7/E12/1000 -> #DIV/0! | F11: =F7/F12/1000 -> 7.1900641 | G11: =G7/G12/1000 -> 6.8784194
B12: 6 | C12: Plant Running Hours | D12: Hrs | E12: 0 | F12: =E12+'15'!F12 -> 312 | G12: =E12+'15'!G12 -> 3963.66
B13: 6 | C13: PLF | D13: ( % ) | E13: =E11/10*100 -> #DIV/0! | F13: =F11/10*100 -> 71.900641 | G13: =G11/10*100 -> 68.784194
B14: 7 | C14: Feed Water consumption | D14: MT | E14: 0 | F14: =E14+'15'!F14 -> 10282 | G14: =E14+'15'!G14 -> 126480
B15: 8 | C15: Boiler Steam Generation | D15: MT | E15: 0 | F15: =E15+'15'!F15 -> 9966 | G15: =E15+'15'!G15 -> 122643
B16: 9 | C16: Bleed steam | D16: MT | E16: 0 | F16: =E16+'15'!F16 -> 727 | G16: =E16+'15'!G16 -> 8215
B17: 10 | C17: Turbine steam consumption | D17: MT | E17: 0 | F17: =E17+'15'!F17 -> 9367 | G17: =E17+'15'!G17 -> 113659
B18: 11 | C18: Condensate Generation | D18: MT | E18: 0 | F18: =E18+'15'!F18 -> 7450 | G18: =E18+'15'!G18 -> 90579
B19: 12 | C19: Auxilairy steam consumption | D19: MT | E19: 0 | F19: =E19+'15'!F19 -> 228 | G19: =E19+'15'!G19 -> 2926
B20: 13 | C20: Specific steam consumption | D20: Kg/Kwhr | E20: =E17*1000/E7 -> #DIV/0! | F20: =F17*1000/F7 -> 4.175545 | G20: =G17*1000/G7 -> 4.1688741
B21: 14 | C21: Specific fuel consumption | D21: Kg/Kwhr | E21: =E26*1000/E7 -> #DIV/0! | F21: =F26*1000/F7 -> 0.74622208 | G21: =G26*1000/G7 -> 0.82508929
B22: 15 | C22: Heat Rate(TG)2880 | D22: Kcal/Kwh | E22: =((E17*(803-130)+E31*(30))*1000)/E7 -> #DIV/0! | F22: =((F17*(803-130)+F31*(30))*1000)/F7 -> 2812.4018 | G22: =((G17*(803-130)+G31*(30))*1000)/G7 -> 2808.3647
B23: 16 | C23: Heat Rate ( Plant ) 3300 @ MCR | D23: Kcal/Kwh | E23: =(E15*(803-130))*1000/(E7*0.78) -> #DIV/0! | F23: =(F15*(803-130))*1000/(F7*0.78) -> 3833.1339 | G23: =(G15*(803-130))*1000/(G7*0.78) -> 3881.3086
B24: 17 | C24: DG Power Generation | D24: kWhr | E24: 0 | F24: =E24+'15'!F24 -> 0 | G24: =E24+'15'!G24 -> 1468
B25: FUEL Report
B26: 1 | C26: Coal Consumption | D26: MT | E26: 0 | F26: =E26+'15'!F26 -> 1674 | G26: =E26+'15'!G26 -> 22495
B27: 2 | C27: GCV ( ADB ) | D27: Kcal/kg | E27: 0
B29: WTP Report
B30: 1 | C30: DM water Generation | D30: m3 | E30: 0 | F30: =E30+'15'!F30 -> 168 | G30: =E30+'15'!G30 -> 2452
B31: 2 | C31: DM water Consumption | D31: m3 | E31: 0 | F31: =E31+'15'!F31 -> 169 | G31: =E31+'15'!G31 -> 2465
B32: 3 | C32: CT Makeup Water Consumption | D32: m3 | E32: 0 | F32: =E32+'15'!F32 -> 272 | G32: =E32+'15'!G32 -> 3376
B33: 4 | C33: Fly ash combustible/ GCV | D33: % / kcal/kg | E33: 0 | F33: 0
B34: FLY ASH DISPOSAL REPORT
B35: 5 | C35: Fly ash to cement mill | D35: MT | E35: 0 | F35: =E35+'15'!F35 -> 112 | G35: =E35+'15'!G35 -> 3919
B36: 6 | C36: Fly ash to Coal yard(Truck) | D36: nos | E36: 0 | F36: =E36+'15'!F36 -> 50 | G36: =E36+'15'!G36 -> 419
