Workbook

Sheet 0
B3: 1*10 MW CAPTIVE POWER PLANT
B4: Daily,Monthly & Yearly Generation Report (FRM-LCL-PP-06)
B6: Sr. NO. | C6: Description | D6: Unit | E6: 46203 | F6: Month to Date | G6: Year to Date(APR2026-MAR2027)
B7: 1 | C7: Gross Power Generation | D7: kWhr | E7: 130600 | F7: 5030865 | G7: 14319965
B8: 2 | C8: Auxiliary power consumption | D8: kWhr | E8: 17516 | F8: 544111 | G8: 1602595
B9: 3 | C9: Net Power Exported | D9: kWhr | E9: 113084 | F9: 4486754 | G9: 12717370
B10: 4 | C10: Auxiliary power consumption | D10: ( % ) | E10: 13.411945 | F10: 10.815456 | G10: 11.191333
B11: 5 | C11: Average Power Generation | D11: MWhr | E11: 5.8044444 | F11: 7.0165481 | G11: 6.6183989
B12: 6 | C12: Plant Running Hours | D12: Hrs | E12: 22.5 | F12: 717 | G12: 2163.66
B13: 6 | C13: PLF | D13: ( % ) | E13: 58.044444 | F13: 70.165481 | G13: 66.183989
B14: 7 | C14: Feed Water consumption | D14: MT | E14: 675 | F14: 23312 | G14: 67000
B15: 8 | C15: Boiler Steam Generation | D15: MT | E15: 637 | F15: 22524 | G15: 64913
B16: 9 | C16: Bleed steam | D16: MT | E16: 21 | F16: 1643 | G16: 4088
B17: 10 | C17: Turbine steam consumption | D17: MT | E17: 543 | F17: 21012 | G17: 59626
B18: 11 | C18: Condensate Generation | D18: MT | E18: 462 | F18: 16678 | G18: 47884
... B24: 17 | C24: DG Power Generation | D24: kWhr | E24: 1468 | F24: 1468 | G24: 1468
B25: FUEL Report
B26: 1 | C26: Coal Consumption | D26: MT | E26: 122 | F26: 4288 | G26: 12460
B27: 2 | C27: GCV ( ADB ) | D27: Kcal/kg | E27: 4509
B29: WTP Report
B30: 1 | C30: DM water Generation | D30: m3 | E30: 41 | F30: 478 | G30: 1433
B31: 2 | C31: DM water Consumption | D31: m3 | E31: 40 | F31: 481 | G31: 1448
B32: 3 | C32: CT Makeup Water Consumption | D32: m3 | E32: 18 | F32: 646 | G32: 1782
B33: 4 | C33: Fly ash combustible/ GCV | D33: % / kcal/kg | E33: 20.62 | F33: 1421
B34: FLY ASH DISPOSAL REPORT
B35: 5 | C35: Fly ash to cement mill | D35: MT | E35: 20 | F35: 787 | G35: 2158
B36: 6 | C36: Fly ash to Coalyard(Truck) | D36: nos | E36: 2 | F36: 61 | G36: 216
B37: 7 | C37: Fly ash to Dumpyard(Truck) | D37: nos | E37: 0 | F37: 0 | G37: 0

Sheet 1
B3: 1*10 MW CAPTIVE POWER PLANT
B4: Daily,Monthly & Yearly Generation Report (FRM-LCL-PP-06)
B6: Sr. NO. | C6: Description | D6: Unit | E6: ='0'!E6+1 -> 46204 | F6: Month to Date | G6: Year to Date(APR2026-MAR2027)
B7: 1 | C7: Gross Power Generation | D7: kWhr | E7: 129200 | F7: =E7 -> 129200 | G7: =E7+'0'!G7 -> 14449165
B8: 2 | C8: Auxiliary power consumption | D8: kWhr | E8: 17267 | F8: =E8 -> 17267 | G8: =E8+'0'!G8 -> 1619862
B9: 3 | C9: Net Power Exported | D9: kWhr | E9: =E7-E8 -> 111933 | F9: =E9 -> 111933 | G9: =E9+'0'!G9 -> 12829303
B10: 4 | C10: Auxiliary power consumption | D10: ( % ) | E10: =E8/E7*100 -> 13.364551 | F10: =F8/F7*100 -> 13.364551 | G10: =G8/G7*100 -> 11.210765
B11: 5 | C11: Average Power Generation | D11: MWhr | E11: =E7/E12/1000 -> 5.3833333 | F11: =F7/F12/1000 -> 5.3833333 | G11: =G7/G12/1000 -> 6.6048495
B12: 6 | C12: Plant Running Hours | D12: Hrs | E12: 24 | F12: =E12 -> 24 | G12: =E12+'0'!G12 -> 2187.66
B13: 6 | C13: PLF | D13: ( % ) | E13: =E11/10*100 -> 53.833333 | F13: =F11/10*100 -> 53.833333 | G13: =G11/10*100 -> 66.048495
B14: 7 | C14: Feed Water consumption | D14: MT | E14: 642 | F14: =E14 -> 642 | G14: =E14+'0'!G14 -> 67642
B15: 8 | C15: Boiler Steam Generation | D15: MT | E15: 597 | F15: =E15 -> 597 | G15: =E15+'0'!G15 -> 65510
B16: 9 | C16: Bleed steam | D16: MT | E16: 25 | F16: =E16 -> 25 | G16: =E16+'0'!G16 -> 4113
B17: 10 | C17: Turbine steam consumption | D17: MT | E17: 539 | F17: =E17 -> 539 | G17: =E17+'0'!G17 -> 60165
B18: 11 | C18: Condensate Generation | D18: MT | E18: 446 | F18: =E18 -> 446 | G18: =E18+'0'!G18 -> 48330
B19: 12 | C19: Auxilairy steam consumption | D19: MT | E19: 17 | F19: =E19 -> 17 | G19: =E19+'0'!G19 -> 1632
B20: 13 | C20: Specific steam consumption | D20: Kg/Kwhr | E20: =E17*1000/E7 -> 4.1718266 | F20: =F17*1000/F7 -> 4.1718266 | G20: =G17*1000/G7 -> 4.1639084
B21: 14 | C21: Specific fuel consumption | D21: Kg/Kwhr | E21: =E26*1000/E7 -> 0.80495356 | F21: =F26*1000/F7 -> 0.80495356 | G21: =G26*1000/G7 -> 0.86953122
B22: 15 | C22: Heat Rate(TG)2880 | D22: Kcal/Kwh | E22: =((E17*(803-130)+E31*(30))*1000)/E7 -> 2812.0511 | F22: =((F17*(803-130)+F31*(30))*1000)/F7 -> 2812.0511 | G22: =((G17*(803-130)+G31*(30))*1000)/G7 -> 2805.3562
B23: 16 | C23: Heat Rate ( Plant ) 3300 @ MCR | D23: Kcal/Kwh | E23: =(E15*(803-130))*1000/(E7*0.78) -> 3986.8719 | F23: =(F15*(803-130))*1000/(F7*0.78) -> 3986.8719 | G23: =(G15*(803-130))*1000/(G7*0.78) -> 3911.8781
B24: 17 | C24: DG Power Generation | D24: kWhr | E24: 0 | F24: =E24 -> 0 | G24: =E24+'0'!G24 -> 1468
B25: FUEL Report
B26: 1 | C26: Coal Consumption | D26: MT | E26: 104 | F26: =E26 -> 104 | G26: =E26+'0'!G26 -> 12564
B27: 2 | C27: GCV ( ADB ) | D27: Kcal/kg | E27: 4976
B29: WTP Report
B30: 1 | C30: DM water Generation | D30: m2 | E30: 18 | F30: =E30 -> 18 | G30: =E30+'0'!G30 -> 1451
B31: 2 | C31: DM water Consumption | D31: m3 | E31: 19 | F31: =E31 -> 19 | G31: =E31+'0'!G31 -> 1467
B32: 3 | C32: CT Makeup Water Consumption | D32: m3 | E32: 18 | F32: =E32 -> 18 | G32: =E32+'0'!G32 -> 1800
B33: 4 | C33: Fly ash combustible/ GCV | D33: % / kcal/kg | E33: 22.88 | F33: 1745
B34: FLY ASH DISPOSAL REPORT
B35: 5 | C35: Fly ash to cement mill | D35: MT | E35: 30 | F35: =E35 -> 30 | G35: =E35+'0'!G35 -> 2188
B36: 6 | C36: Fly ash to Coal yard(Truck) | D36: nos | E36: 0 | F36: =E36 -> 0 | G36: =E36+'0'!G36 -> 216
B37: 7 | C37: Fly ash to Dumpyard(Truck) | D37: nos | E37: 0 | F37: =E37 -> 0 | G37: =E37+'0'!G37 -> 0

Sheet 2
B3: 1*10 MW CAPTIVE POWER PLANT
B4: Daily,Monthly & Yearly Generation Report (FRM-LCL-PP-06)
B6: Sr. NO. | C6: Description | D6: Unit | E6: ='1'!E6+1 -> 46205 | F6: Month to Date | G6: Year to Date(APR2026-MAR2027)
B7: 1 | C7: Gross Power Generation | D7: kWhr | E7: 106300 | F7: =E7+'1'!F7 -> 235500 | G7: =E7+'1'!G7 -> 14555465
B8: 2 | C8: Auxiliary power consumption | D8: kWhr | E8: 16786 | F8: =E8+'1'!F8 -> 34053 | G8: =E8+'1'!G8 -> 1636648
B9: 3 | C9: Net Power Exported | D9: kWhr | E9: =E7-E8 -> 89514 | F9: =E9+'1'!F9 -> 201447 | G9: =E9+'1'!G9 -> 12918817
B10: 4 | C10: Auxiliary power consumption | D10: ( % ) | E10: =E8/E7*100 -> 15.791157 | F10: =F8/F7*100 -> 14.459873 | G10: =G8/G7*100 -> 11.244217
B11: 5 | C11: Average Power Generation | D11: MWhr | E11: =E7/E12/1000 -> 4.4291667 | F11: =F7/F12/1000 -> 4.90625 | G11: =G7/G12/1000 -> 6.5812399
B12: 6 | C12: Plant Running Hours | D12: Hrs | E12: 24 | F12: =E12+'1'!F12 -> 48 | G12: =E12+'1'!G12 -> 2211.66
B13: 7 | C13: PLF | D13: ( % ) | E13: =E11/10*100 -> 44.291667 | F13: =F11/10*100 -> 49.0625 | G13: =G11/10*100 -> 65.812399
B14: 8 | C14: Feed Water consumption | D14: MT | E14: 573 | F14: =E14+'1'!F14 -> 1215 | G14: =E14+'1'!G14 -> 68215
B15: 9 | C15: Boiler Steam Generation | D15: MT | E15: 522 | F15: =E15+'1'!F15 -> 1119 | G15: =E15+'1'!G15 -> 66032
B16: 10 | C16: Bleed steam | D16: MT | E16: 9 | F16: =E16+'1'!F16 -> 34 | G16: =E16+'1'!G16 -> 4122
B17: 11 | C17: Turbine steam consumption | D17: MT | E17: 450 | F17: =E17+'1'!F17 -> 989 | G17: =E17+'1'!G17 -> 60615
B18: 12 | C18: Condensate Generation | D18: MT | E18: 393 | F18: =E18+'1'!F18 -> 839 | G18: =E18+'1'!G18 -> 48723
B19: 13 | C19: Auxilairy steam consumption | D19: MT | E19: 19 | F19: =E19+'1'!F19 -> 36 | G19: =E19+'1'!G19 -> 1651
B20: 14 | C20: Specific steam consumption | D20: Kg/Kwhr | E20: =E17*1000/E7 -> 4.233302 | F20: =F17*1000/F7 -> 4.1995754 | G20: =G17*1000/G7 -> 4.1644152
B21: 15 | C21: Specific fuel consumption | D21: Kg/Kwhr | E21: =E26*1000/E7 -> 0.79962371 | F21: =F26*1000/F7 -> 0.80254777 | G21: =G26*1000/G7 -> 0.86902067
B22: 16 | C22: Heat Rate(TG)2880 | D22: Kcal/Kwh | E22: =((E17*(803-130)+E31*(30))*1000)/E7 -> 2853.2455 | F22: =((F17*(803-130)+F31*(30))*1000)/F7 -> 2830.6454 | G22: =((G17*(803-130)+G31*(30))*1000)/G7 -> 2805.706
B23: 17 | C23: Heat Rate ( Plant ) 3300 @ MCR | D23: Kcal/Kwh | E23: =(E15*(803-130))*1000/(E7*0.78) -> 4236.9925 | F23: =(F15*(803-130))*1000/(F7*0.78) -> 4099.7714 | G23: =(G15*(803-130))*1000/(G7*0.78) -> 3914.2524
B24: 18 | C24: DG Power Generation | D24: kWhr | E24: 0 | F24: =E24+'1'!F24 -> 0 | G24: =E24+'1'!G24 -> 1468
B25: FUEL Report
B26: 1 | C26: Coal Consumption | D26: MT | E26: 85 | F26: =E26+'1'!F26 -> 189 | G26: =E26+'1'!G26 -> 12649
B27: 2 | C27: GCV ( ADB ) | D27: Kcal/kg | E27: 5294
B29: WTP Report
B30: 1 | C30: DM water Generation | D30: m3 | E30: 14 | F30: =E30+'1'!F30 -> 32 | G30: =E30+'1'!G30 -> 1465
B31: 2 | C31: DM water Consumption | D31: m3 | E31: 15 | F31: =E31+'1'!F31 -> 34 | G31: =E31+'1'!G31 -> 1482
B32: 3 | C32: CT Makeup Water Consumption | D32: m3 | E32: 18 | F32: =E32+'1'!F32 -> 36 | G32: =E32+'1'!G32 -> 1818
B33: 4 | C33: Fly ash combustible/ GCV | D33: % / kcal/kg | E33: 33.67 | F33: 2157
B34: FLY ASH DISPOSAL REPORT
B35: 5 | C35: Fly ash to cement mill | D35: MT | E35: 20 | F35: =E35+'1'!F35 -> 50 | G35: =E35+'1'!G35 -> 2208
B36: 6 | C36: Fly ash to Coal yard(Truck) | D36: nos | E36: 0 | F36: =E36+'1'!F36 -> 0 | G36: =E36+'1'!G36 -> 216
B37: 7 | C37: Fly ash to Dumpyard(Truck) | D37: nos | E37: 0 | F37: =E37+'1'!F37 -> 0 | G37: =E37+'1'!G37 -> 0

Sheet 3
B3: 1*10 MW CAPTIVE POWER PLANT
B4: Daily,Monthly & Yearly Generation Report (FRM-LCL-PP-06)
B6: Sr. NO. | C6: Description | D6: Unit | E6: ='2'!E6+1 -> 46206 | F6: Month to Date | G6: Year to Date(APR2026-MAR2027)
B7: 1 | C7: Gross Power Generation | D7: kWhr | E7: 183400 | F7: =E7+'2'!F7 -> 418900 | G7: =E7+'2'!G7 -> 14738865
B8: 2 | C8: Auxiliary power consumption | D8: kWhr | E8: 17971 | F8: =E8+'2'!F8 -> 52024 | G8: =E8+'2'!G8 -> 1654619
B9: 3 | C9: Net Power Exported | D9: kWhr | E9: =E7-E8 -> 165429 | F9: =E9+'2'!F9 -> 366876 | G9: =E9+'2'!G9 -> 13084246
B10: 4 | C10: Auxiliary power consumption | D10: ( % ) | E10: =E8/E7*100 -> 9.7988004 | F10: =F8/F7*100 -> 12.419193 | G10: =G8/G7*100 -> 11.226231
B11: 5 | C11: Average Power Generation | D11: MWhr | E11: =E7/E12/1000 -> 7.6416667 | F11: =F7/F12/1000 -> 5.8180556 | G11: =G7/G12/1000 -> 6.5926237
B12: 6 | C12: Plant Running Hours | D12: Hrs | E12: 24 | F12: =E12+'2'!F12 -> 72 | G12: =E12+'2'!G12 -> 2235.66
B13: 6 | C13: PLF | D13: ( % ) | E13: =E11/10*100 -> 76.416667 | F13: =F11/10*100 -> 58.180556 | G13: =G11/10*100 -> 65.926237
B14: 7 | C14: Feed Water consumption | D14: MT | E14: 836 | F14: =E14+'2'!F14 -> 2051 | G14: =E14+'2'!G14 -> 69051
B15: 8 | C15: Boiler Steam Generation | D15: MT | E15: 820 | F15: =E15+'2'!F15 -> 1939 | G15: =E15+'2'!G15 -> 66852
B16: 9 | C16: Bleed steam | D16: MT | E16: 53 | F16: =E16+'2'!F16 -> 87 | G16: =E16+'2'!G16 -> 4175
B17: 10 | C17: Turbine steam consumption | D17: MT | E17: 758 | F17: =E17+'2'!F17 -> 1747 | G17: =E17+'2'!G17 -> 61373
B18: 11 | C18: Condensate Generation | D18: MT | E18: 595 | F18: =E18+'2'!F18 -> 1434 | G18: =E18+'2'!G18 -> 49318
B19: 12 | C19: Auxilairy steam consumption | D19: MT | E19: 18 | F19: =E19+'2'!F19 -> 54 | G19: =E19+'2'!G19 -> 1669
B20: 13 | C20: Specific steam consumption | D20: Kg/Kwhr | E20: =E17*1000/E7 -> 4.1330425 | F20: =F17*1000/F7 -> 4.1704464 | G20: =G17*1000/G7 -> 4.1640248
B21: 14 | C21: Specific fuel consumption | D21: Kg/Kwhr | E21: =E26*1000/E7 -> 0.83969466 | F21: =F26*1000/F7 -> 0.81881117 | G21: =G26*1000/G7 -> 0.86865576
B22: 15 | C22: Heat Rate(TG)2880 | D22: Kcal/Kwh | E22: =((E17*(803-130)+E31*(30))*1000)/E7 -> 2783.5005 | F22: =((F17*(803-130)+F31*(30))*1000)/F7 -> 2810.0048 | G22: =((G17*(803-130)+G31*(30))*1000)/G7 -> 2805.4297
B23: 16 | C23: Heat Rate ( Plant ) 3300 @ MCR | D23: Kcal/Kwh | E23: =(E15*(803-130))*1000/(E7*0.78) -> 3857.758 | F23: =(F15*(803-130))*1000/(F7*0.78) -> 3993.8147 | G23: =(G15*(803-130))*1000/(G7*0.78) -> 3913.5494
B24: 17 | C24: DG Power Generation | D24: kWhr | E24: 0 | F24: =E24+'2'!F24 -> 0 | G24: =E24+'2'!G24 -> 1468
B25: FUEL Report
B26: 1 | C26: Coal Consumption | D26: MT | E26: 154 | F26: =E26+'2'!F26 -> 343 | G26: =E26+'2'!G26 -> 12803
B27: 2 | C27: GCV ( ADB ) | D27: Kcal/kg | E27: 4570
B29: WTP Report
B30: 1 | C30: DM water Generation | D30: m3 | E30: 11 | F30: =E30+'2'!F30 -> 43 | G30: =E30+'2'!G30 -> 1476
B31: 2 | C31: DM water Consumption | D31: m3 | E31: 12 | F31: =E31+'2'!F31 -> 46 | G31: =E31+'2'!G31 -> 1494
B32: 3 | C32: CT Makeup Water Consumption | D32: m3 | E32: 18 | F32: =E32+'2'!F32 -> 54 | G32: =E32+'2'!G32 -> 1836
B33: 4 | C33: Fly ash combustible/ GCV | D33: % / kcal/kg | E33: 19 | F33: 1396
B34: FLY ASH DISPOSAL REPORT
B35: 5 | C35: Fly ash to cement mill | D35: MT | E35: 54 | F35: =E35+'2'!F35 -> 104 | G35: =E35+'2'!G35 -> 2262
B36: 6 | C36: Fly ash to Coal yard(Truck) | D36: nos | E36: 0 | F36: =E36+'2'!F36 -> 0 | G36: =E36+'2'!G36 -> 216
B37: 7 | C37: Fly ash to Dumpyard(Truck) | D37: nos | E37: 0 | F37: =E37+'2'!F37 -> 0 | G37: =E37+'2'!G37 -> 0

Sheet 4
B3: 1*10 MW CAPTIVE POWER PLANT
B4: Daily,Monthly & Yearly Generation Report (FRM-LCL-PP-06)
B6: Sr. NO. | C6: Description | D6: Unit | E6: ='3'!E6+1 -> 46207 | F6: Month to Date | G6: Year to Date(APR2026-MAR2027)
B7: 1 | C7: Gross Power Generation | D7: kWhr | E7: 176500 | F7: =E7+'3'!F7 -> 595400 | G7: =E7+'3'!G7 -> 14915365
B8: 2 | C8: Auxiliary power consumption | D8: kWhr | E8: 17747 | F8: =E8+'3'!F8 -> 69771 | G8: =E8+'3'!G8 -> 1672366
B9: 3 | C9: Net Power Exported | D9: kWhr | E9: =E7-E8 -> 158753 | F9: =E9+'3'!F9 -> 525629 | G9: =E9+'3'!G9 -> 13242999
B10: 4 | C10: Auxiliary power consumption | D10: ( % ) | E10: =E8/E7*100 -> 10.054958 | F10: =F8/F7*100 -> 11.718341 | G10: =G8/G7*100 -> 11.212371
B11: 5 | C11: Average Power Generation | D11: MWhr | E11: =E7/E12/1000 -> 7.3541667 | F11: =F7/F12/1000 -> 6.2020833 | G11: =G7/G12/1000 -> 6.6007121
B12: 6 | C12: Plant Running Hours | D12: Hrs | E12: 24 | F12: =E12+'3'!F12 -> 96 | G12: =E12+'3'!G12 -> 2259.66
B13: 6 | C13: PLF | D13: ( % ) | E13: =E11/10*100 -> 73.541667 | F13: =F11/10*100 -> 62.020833 | G13: =G11/10*100 -> 66.007121
B14: 7 | C14: Feed Water consumption | D14: MT | E14: 809 | F14: =E14+'3'!F14 -> 2860 | G14: =E14+'3'!G14 -> 69860
B15: 8 | C15: Boiler Steam Generation | D15: MT | E15: 785 | F15: =E15+'3'!F15 -> 2724 | G15: =E15+'3'!G15 -> 67637
B16: 9 | C16: Bleed steam | D16: MT | E16: 59 | F16: =E16+'3'!F16 -> 146 | G16: =E16+'3'!G16 -> 4234
B17: 10 | C17: Turbine steam consumption | D17: MT | E17: 735 | F17: =E17+'3'!F17 -> 2482 | G17: =E17+'3'!G17 -> 62108
B18: 11 | C18: Condensate Generation | D18: MT | E18: 576 | F18: =E18+'3'!F18 -> 2010 | G18: =E18+'3'!G18 -> 49894
B19: 12 | C19: Auxilairy steam consumption | D19: MT | E19: 17 | F19: =E19+'3'!F19 -> 71 | G19: =E19+'3'!G19 -> 1686
B20: 13 | C20: Specific steam consumption | D20: Kg/Kwhr | E20: =E17*1000/E7 -> 4.1643059 | F20: =F17*1000/F7 -> 4.1686261 | G20: =G17*1000/G7 -> 4.1640282
B21: 14 | C21: Specific fuel consumption | D21: Kg/Kwhr | E21: =E26*1000/E7 -> 0.83852691 | F21: =F26*1000/F7 -> 0.82465569 | G21: =G26*1000/G7 -> 0.86829923
B22: 15 | C22: Heat Rate(TG)2880 | D22: Kcal/Kwh | E22: =((E17*(803-130)+E31*(30))*1000)/E7 -> 2805.1275 | F22: =((F17*(803-130)+F31*(30))*1000)/F7 -> 2808.559 | G22: =((G17*(803-130)+G31*(30))*1000)/G7 -> 2805.4261
B23: 16 | C23: Heat Rate ( Plant ) 3300 @ MCR | D23: Kcal/Kwh | E23: =(E15*(803-130))*1000/(E7*0.78) -> 3837.4737 | F23: =(F15*(803-130))*1000/(F7*0.78) -> 3947.4691 | G23: =(G15*(803-130))*1000/(G7*0.78) -> 3912.6492
B24: 17 | C24: DG Power Generation | D24: kWhr | E24: 0 | F24: =E24+'3'!F24 -> 0 | G24: =E24+'3'!G24 -> 1468
B25: FUEL Report
B26: 1 | C26: Coal Consumption | D26: MT | E26: 148 | F26: =E26+'3'!F26 -> 491 | G26: =E26+'3'!G26 -> 12951
B27: 2 | C27: GCV ( ADB ) | D27: Kcal/kg | E27: 4565
B29: WTP Report
B30: 1 | C30: DM water Generation | D30: m3 | E30: 18 | F30: =E30+'3'!F30 -> 61 | G30: =E30+'3'!G30 -> 1494
B31: 2 | C31: DM water Consumption | D31: m3 | E31: 15 | F31: =E31+'3'!F31 -> 61 | G31: =E31+'3'!G31 -> 1509
B32: 3 | C32: CT Makeup Water Consumption | D32: m3 | E32: 18 | F32: =E32+'3'!F32 -> 72 | G32: =E32+'3'!G32 -> 1854
B33: 4 | C33: Fly ash combustible/ GCV | D33: % / kcal/kg | E33: 19 | F33: 1363
B35: 5 | C35: Fly ash to cement mill | D35: MT | E35: 51 | F35: =E35+'3'!F35 -> 155 | G35: =E35+'3'!G35 -> 2313
B36: 6 | C36: Fly ash to Coal yard(Truck) | D36: nos | E36: 0 | F36: =E36+'3'!F36 -> 0 | G36: =E36+'3'!G36 -> 216
B37: 7 | C37: Fly ash to Dumpyard(Truck) | D37: nos | E37: 0 | F37: =E37+'3'!F37 -> 0 | G37: =E37+'3'!G37 -> 0

Sheet 5
B3: 1*10 MW CAPTIVE POWER PLANT
B4: Daily,Monthly & Yearly Generation Report (FRM-LCL-PP-06)
B6: Sr. NO. | C6: Description | D6: Unit | E6: ='4'!E6+1 -> 46208 | F6: Month to Date | G6: Year to Date(APR2026-MAR2027)
B7: 1 | C7: Gross Power Generation | D7: kWhr | E7: 190000 | F7: =E7+'4'!F7 -> 785400 | G7: =E7+'4'!G7 -> 15105365
B8: 2 | C8: Auxiliary power consumption | D8: kWhr | E8: 17950 | F8: =E8+'4'!F8 -> 87721 | G8: =E8+'4'!G8 -> 1690316
B9: 3 | C9: Net Power Exported | D9: kWhr | E9: =E7-E8 -> 172050 | F9: =E9+'4'!F9 -> 697679 | G9: =E9+'4'!G9 -> 13415049
B10: 4 | C10: Auxiliary power consumption | D10: ( % ) | E10: =E8/E7*100 -> 9.4473684 | F10: =F8/F7*100 -> 11.168958 | G10: =G8/G7*100 -> 11.19017
B11: 5 | C11: Average Power Generation | D11: MWhr | E11: =E7/E12/1000 -> 7.9166667 | F11: =F7/F12/1000 -> 6.545 | G11: =G7/G12/1000 -> 6.614542
B12: 6 | C12: Plant Running Hours | D12: Hrs | E12: 24 | F12: =E12+'4'!F12 -> 120 | G12: =E12+'4'!G12 -> 2283.66
B13: 6 | C13: PLF | D13: ( % ) | E13: =E11/10*100 -> 79.166667 | F13: =F11/10*100 -> 65.45 | G13: =G11/10*100 -> 66.14542
B14: 7 | C14: Feed Water consumption | D14: MT | E14: 857 | F14: =E14+'4'!F14 -> 3717 | G14: =E14+'4'!G14 -> 70717
B15: 8 | C15: Boiler Steam Generation | D15: MT | E15: 840 | F15: =E15+'4'!F15 -> 3564 | G15: =E15+'4'!G15 -> 68477
B16: 9 | C16: Bleed steam | D16: MT | E16: 67 | F16: =E16+'4'!F16 -> 213 | G16: =E16+'4'!G16 -> 4301
B17: 10 | C17: Turbine steam consumption | D17: MT | E17: 793 | F17: =E17+'4'!F17 -> 3275 | G17: =E17+'4'!G17 -> 62901
B18: 11 | C18: Condensate Generation | D18: MT | E18: 612 | F18: =E18+'4'!F18 -> 2622 | G18: =E18+'4'!G18 -> 50506
B19: 12 | C19: Auxilairy steam consumption | D19: MT | E19: 18 | F19: =E19+'4'!F19 -> 89 | G19: =E19+'4'!G19 -> 1704
B20: 13 | C20: Specific steam consumption | D20: Kg/Kwhr | E20: =E17*1000/E7 -> 4.1736842 | F20: =F17*1000/F7 -> 4.1698498 | G20: =G17*1000/G7 -> 4.1641496
B21: 14 | C21: Specific fuel consumption | D21: Kg/Kwhr | E21: =E26*1000/E7 -> 0.84210526 | F21: =F26*1000/F7 -> 0.82887701 | G21: =G26*1000/G7 -> 0.86796976
B22: 15 | C22: Heat Rate(TG)2880 | D22: Kcal/Kwh | E22: =((E17*(803-130)+E31*(30))*1000)/E7 -> 2810.6263 | F22: =((F17*(803-130)+F31*(30))*1000)/F7 -> 2809.0591 | G22: =((G17*(803-130)+G31*(30))*1000)/G7 -> 2805.4915
B23: 16 | C23: Heat Rate ( Plant ) 3300 @ MCR | D23: Kcal/Kwh | E23: =(E15*(803-130))*1000/(E7*0.78) -> 3814.5749 | F23: =(F15*(803-130))*1000/(F7*0.78) -> 3915.32 | G23: =(G15*(803-130))*1000/(G7*0.78) -> 3911.4156
B24: 17 | C24: DG Power Generation | D24: kWhr | E24: 0 | F24: =E24+'4'!F24 -> 0 | G24: =E24+'4'!G24 -> 1468
B25: FUEL Report
B26: 1 | C26: Coal Consumption | D26: MT | E26: 160 | F26: =E26+'4'!F26 -> 651 | G26: =E26+'4'!G26 -> 13111
B27: 2 | C27: GCV ( ADB ) | D27: Kcal/kg | E27: 4525
B29: WTP Report
B30: 1 | C30: DM water Generation | D30: m3 | E30: 10 | F30: =E30+'4'!F30 -> 71 | G30: =E30+'4'!G30 -> 1504
B31: 2 | C31: DM water Consumption | D31: m3 | E31: 11 | F31: =E31+'4'!F31 -> 72 | G31: =E31+'4'!G31 -> 1520
B32: 3 | C32: CT Makeup Water Consumption | D32: m3 | E32: 18 | F32: =E32+'4'!F32 -> 90 | G32: =E32+'4'!G32 -> 1872
B33: 4 | C33: Fly ash combustible/ GCV | D33: % / kcal/kg | E33: 17 | F33: 1261
B34: FLY ASH DISPOSAL REPORT
B35: 5 | C35: Fly ash to cement mill | D35: MT | E35: 60 | F35: =E35+'4'!F35 -> 215 | G35: =E35+'4'!G35 -> 2373
B36: 6 | C36: Fly ash to Coal yard(Truck) | D36: nos | E36: 0 | F36: =E36+'4'!F36 -> 0 | G36: =E36+'4'!G36 -> 216
B37: 7 | C37: Fly ash to Dumpyard(Truck) | D37: nos | E37: 0 | F37: =E37+'4'!F37 -> 0 | G37: =E37+'4'!G37 -> 0

Sheet 6
B3: 1*10 MW CAPTIVE POWER PLANT
B4: Daily,Monthly & Yearly Generation Report (FRM-LCL-PP-06)
B6: Sr. NO. | C6: Description | D6: Unit | E6: ='5'!E6+1 -> 46209 | F6: Month to Date | G6: Year to Date(APR2026-MAR2027)
B7: 1 | C7: Gross Power Generation | D7: kWhr | E7: 170000 | F7: =E7+'5'!F7 -> 955400 | G7: =E7+'5'!G7 -> 15275365
B8: 2 | C8: Auxiliary power consumption | D8: kWhr | E8: 17602 | F8: =E8+'5'!F8 -> 105323 | G8: =E8+'5'!G8 -> 1707918
B9: 3 | C9: Net Power Exported | D9: kWhr | E9: =E7-E8 -> 152398 | F9: =E9+'5'!F9 -> 850077 | G9: =E9+'5'!G9 -> 13567447
B10: 4 | C10: Auxiliary power consumption | D10: ( % ) | E10: =E8/E7*100 -> 10.354118 | F10: =F8/F7*100 -> 11.023969 | G10: =G8/G7*100 -> 11.180865
B11: 5 | C11: Average Power Generation | D11: MWhr | E11: =E7/E12/1000 -> 7.0833333 | F11: =F7/F12/1000 -> 6.6347222 | G11: =G7/G12/1000 -> 6.6194175
B12: 6 | C12: Plant Running Hours | D12: Hrs | E12: 24 | F12: =E12+'5'!F12 -> 144 | G12: =E12+'5'!G12 -> 2307.66
B13: 6 | C13: PLF | D13: ( % ) | E13: =E11/10*100 -> 70.833333 | F13: =F11/10*100 -> 66.347222 | G13: =G11/10*100 -> 66.194175
B14: 7 | C14: Feed Water consumption | D14: MT | E14: 780 | F14: =E14+'5'!F14 -> 4497 | G14: =E14+'5'!G14 -> 71497
B15: 8 | C15: Boiler Steam Generation | D15: MT | E15: 756 | F15: =E15+'5'!F15 -> 4320 | G15: =E15+'5'!G15 -> 69233
B16: 9 | C16: Bleed steam | D16: MT | E16: 57 | F16: =E16+'5'!F16 -> 270 | G16: =E16+'5'!G16 -> 4358
B17: 10 | C17: Turbine steam consumption | D17: MT | E17: 715 | F17: =E17+'5'!F17 -> 3990 | G17: =E17+'5'!G17 -> 63616
B18: 11 | C18: Condensate Generation | D18: MT | E18: 554 | F18: =E18+'5'!F18 -> 3176 | G18: =E18+'5'!G18 -> 51060
B19: 12 | C19: Auxilairy steam consumption | D19: MT | E19: 18 | F19: =E19+'5'!F19 -> 107 | G19: =E19+'5'!G19 -> 1722
B20: 13 | C20: Specific steam consumption | D20: Kg/Kwhr | E20: =E17*1000/E7 -> 4.2058824 | F20: =F17*1000/F7 -> 4.1762613 | G20: =G17*1000/G7 -> 4.1646141
B21: 14 | C21: Specific fuel consumption | D21: Kg/Kwhr | E21: =E26*1000/E7 -> 0.86470588 | F21: =F26*1000/F7 -> 0.83525225 | G21: =G26*1000/G7 -> 0.86793343
B22: 15 | C22: Heat Rate(TG)2880 | D22: Kcal/Kwh | E22: =((E17*(803-130)+E31*(30))*1000)/E7 -> 2833.0294 | F22: =((F17*(803-130)+F31*(30))*1000)/F7 -> 2813.3243 | G22: =((G17*(803-130)+G31*(30))*1000)/G7 -> 2805.798
B23: 16 | C23: Heat Rate ( Plant ) 3300 @ MCR | D23: Kcal/Kwh | E23: =(E15*(803-130))*1000/(E7*0.78) -> 3837.0136 | F23: =(F15*(803-130))*1000/(F7*0.78) -> 3901.3865 | G23: =(G15*(803-130))*1000/(G7*0.78) -> 3910.5876
B24: 17 | C24: DG Power Generation | D24: kWhr | E24: 0 | F24: =E24+'5'!F24 -> 0 | G24: =E24+'5'!G24 -> 1468
B25: FUEL Report
B26: 1 | C26: Coal Consumption | D26: MT | E26: 147 | F26: =E26+'5'!F26 -> 798 | G26: =E26+'5'!G26 -> 13258
B27: 2 | C27: GCV ( ADB ) | D27: Kcal/kg | E27: 4414
B29: WTP Report
B30: 1 | C30: DM water Generation | D30: m3 | E30: 15 | F30: =E30+'5'!F30 -> 86 | G30: =E30+'5'!G30 -> 1519
B31: 2 | C31: DM water Consumption | D31: m3 | E31: 14 | F31: =E31+'5'!F31 -> 86 | G31: =E31+'5'!G31 -> 1534
B32: 3 | C32: CT Makeup Water Consumption | D32: m3 | E32: 18 | F32: =E32+'5'!F32 -> 108 | G32: =E32+'5'!G32 -> 1890
B33: 4 | C33: Fly ash combustible/ GCV | D33: % / kcal/kg | E33: 17 | F33: 1258
B34: FLY ASH DISPOSAL REPORT
B35: 5 | C35: Fly ash to cement mill | D35: MT | E35: 18 | F35: =E35+'5'!F35 -> 233 | G35: =E35+'5'!G35 -> 2391
B36: 6 | C36: Fly ash to Coal yard(Truck) | D36: nos | E36: 4 | F36: =E36+'5'!F36 -> 4 | G36: =E36+'5'!G36 -> 220
B37: 7 | C37: Fly ash to Dumpyard(Truck) | D37: nos | E37: 0 | F37: =E37+'5'!F37 -> 0 | G37: =E37+'5'!G37 -> 0

Sheet 7
B3: 1*10 MW CAPTIVE POWER PLANT
B4: Daily,Monthly & Yearly Generation Report (FRM-LCL-PP-06)
B6: Sr. NO. | C6: Description | D6: Unit | E6: ='6'!E6+1 -> 46210 | F6: Month to Date | G6: Year to Date(APR2026-MAR2027)
B7: 1 | C7: Gross Power Generation | D7: kWhr | E7: 164100 | F7: =E7+'6'!F7 -> 1119500 | G7: =E7+'6'!G7 -> 15439465
B8: 2 | C8: Auxiliary power consumption | D8: kWhr | E8: 17598 | F8: =E8+'6'!F8 -> 122921 | G8: =E8+'6'!G8 -> 1725516
B9: 3 | C9: Net Power Exported | D9: kWhr | E9: =E7-E8 -> 146502 | F9: =E9+'6'!F9 -> 996579 | G9: =E9+'6'!G9 -> 13713949
B10: 4 | C10: Auxiliary power consumption | D10: ( % ) | E10: =E8/E7*100 -> 10.723949 | F10: =F8/F7*100 -> 10.979991 | G10: =G8/G7*100 -> 11.176009
B11: 5 | C11: Average Power Generation | D11: MWhr | E11: =E7/E12/1000 -> 6.8375 | F11: =F7/F12/1000 -> 6.6636905 | G11: =G7/G12/1000 -> 6.6216622
B12: 6 | C12: Plant Running Hours | D12: Hrs | E12: 24 | F12: =E12+'6'!F12 -> 168 | G12: =E12+'6'!G12 -> 2331.66
B13: 6 | C13: PLF | D13: ( % ) | E13: =E11/10*100 -> 68.375 | F13: =F11/10*100 -> 66.636905 | G13: =G11/10*100 -> 66.216622
B14: 7 | C14: Feed Water consumption | D14: MT | E14: 756 | F14: =E14+'6'!F14 -> 5253 | G14: =E14+'6'!G14 -> 72253
B15: 8 | C15: Boiler Steam Generation | D15: MT | E15: 734 | F15: =E15+'6'!F15 -> 5054 | G15: =E15+'6'!G15 -> 69967
B16: 9 | C16: Bleed steam | D16: MT | E16: 54 | F16: =E16+'6'!F16 -> 324 | G16: =E16+'6'!G16 -> 4412
B17: 10 | C17: Turbine steam consumption | D17: MT | E17: 689 | F17: =E17+'6'!F17 -> 4679 | G17: =E17+'6'!G17 -> 64305
B18: 11 | C18: Condensate Generation | D18: MT | E18: 536 | F18: =E18+'6'!F18 -> 3712 | G18: =E18+'6'!G18 -> 51596
B19: 12 | C19: Auxilairy steam consumption | D19: MT | E19: 17 | F19: =E19+'6'!F19 -> 124 | G19: =E19+'6'!G19 -> 1739
B20: 13 | C20: Specific steam consumption | D20: Kg/Kwhr | E20: =E17*1000/E7 -> 4.1986594 | F20: =F17*1000/F7 -> 4.1795444 | G20: =G17*1000/G7 -> 4.1649759
B21: 14 | C21: Specific fuel consumption | D21: Kg/Kwhr | E21: =E26*1000/E7 -> 0.84095064 | F21: =F26*1000/F7 -> 0.83608754 | G21: =G26*1000/G7 -> 0.86764664
B22: 15 | C22: Heat Rate(TG)2880 | D22: Kcal/Kwh | E22: =((E17*(803-130)+E31*(30))*1000)/E7 -> 2828.0743 | F22: =((F17*(803-130)+F31*(30))*1000)/F7 -> 2815.4864 | G22: =((G17*(803-130)+G31*(30))*1000)/G7 -> 2806.0347
B23: 16 | C23: Heat Rate ( Plant ) 3300 @ MCR | D23: Kcal/Kwh | E23: =(E15*(803-130))*1000/(E7*0.78) -> 3859.2947 | F23: =(F15*(803-130))*1000/(F7*0.78) -> 3895.2165 | G23: =(G15*(803-130))*1000/(G7*0.78) -> 3910.0424
B24: 17 | C24: DG Power Generation | D24: kWhr | E24: 0 | F24: =E24+'6'!F24 -> 0 | G24: =E24+'6'!G24 -> 1468
B25: FUEL Report
B26: 1 | C26: Coal Consumption | D26: MT | E26: 138 | F26: =E26+'6'!F26 -> 936 | G26: =E26+'6'!G26 -> 13396
B27: 2 | C27: GCV ( ADB ) | D27: Kcal/kg | E27: 4587
B30: 1 | C30: DM water Generation | D30: m3 | E30: 12 | F30: =E30+'6'!F30 -> 98 | G30: =E30+'6'!G30 -> 1531
B31: 2 | C31: DM water Consumption | D31: m3 | E31: 13 | F31: =E31+'6'!F31 -> 99 | G31: =E31+'6'!G31 -> 1547
B32: 3 | C32: CT Makeup Water Consumption | D32: m3 | E32: 23 | F32: =E32+'6'!F32 -> 131 | G32: =E32+'6'!G32 -> 1913
B33: 4 | C33: Fly ash combustible/ GCV | D33: % / kcal/kg | E33: 18 | F33: 1396
B34: FLY ASH DISPOSAL REPORT
B35: 5 | C35: Fly ash to cement mill | D35: MT | E35: 47 | F35: =E35+'6'!F35 -> 280 | G35: =E35+'6'!G35 -> 2438
B36: 6 | C36: Fly ash to Coal yard(Truck) | D36: nos | E36: 0 | F36: =E36+'6'!F36 -> 4 | G36: =E36+'6'!G36 -> 220
B37: 7 | C37: Fly ash to Dumpyard(Truck) | D37: nos | E37: 0 | F37: =E37+'6'!F37 -> 0 | G37: =E37+'6'!G37 -> 0

Sheet 8
B3: 1*10 MW CAPTIVE POWER PLANT
B4: Daily,Monthly & Yearly Generation Report (FRM-LCL-PP-06)
B6: Sr. NO. | C6: Description | D6: Unit | E6: ='7'!E6+1 -> 46211 | F6: Month to Date | G6: Year to Date(APR2026-MAR2027)
B7: 1 | C7: Gross Power Generation | D7: kWhr | E7: 158800 | F7: =E7+'7'!F7 -> 1278300 | G7: =E7+'7'!G7 -> 15598265
B8: 2 | C8: Auxiliary power consumption | D8: kWhr | E8: 17416 | F8: =E8+'7'!F8 -> 140337 | G8: =E8+'7'!G8 -> 1742932
B9: 3 | C9: Net Power Exported | D9: kWhr | E9: =E7-E8 -> 141384 | F9: =E9+'7'!F9 -> 1137963 | G9: =E9+'7'!G9 -> 13855333
B10: 4 | C10: Auxiliary power consumption | D10: ( % ) | E10: =E8/E7*100 -> 10.967254 | F10: =F8/F7*100 -> 10.978409 | G10: =G8/G7*100 -> 11.173884
B11: 5 | C11: Average Power Generation | D11: MWhr | E11: =E7/E12/1000 -> 6.6166667 | F11: =F7/F12/1000 -> 6.6578125 | G11: =G7/G12/1000 -> 6.6216114
B12: 6 | C12: Plant Running Hours | D12: Hrs | E12: 24 | F12: =E12+'7'!F12 -> 192 | G12: =E12+'7'!G12 -> 2355.66
B13: 6 | C13: PLF | D13: ( % ) | E13: =E11/10*100 -> 66.166667 | F13: =F11/10*100 -> 66.578125 | G13: =G11/10*100 -> 66.216114
B14: 7 | C14: Feed Water consumption | D14: MT | E14: 738 | F14: =E14+'7'!F14 -> 5991 | G14: =E14+'7'!G14 -> 72991
B15: 8 | C15: Boiler Steam Generation | D15: MT | E15: 714 | F15: =E15+'7'!F15 -> 5768 | G15: =E15+'7'!G15 -> 70681
B16: 9 | C16: Bleed steam | D16: MT | E16: 42 | F16: =E16+'7'!F16 -> 366 | G16: =E16+'7'!G16 -> 4454
B17: 10 | C17: Turbine steam consumption | D17: MT | E17: 658 | F17: =E17+'7'!F17 -> 5337 | G17: =E17+'7'!G17 -> 64963
B18: 11 | C18: Condensate Generation | D18: MT | E18: 533 | F18: =E18+'7'!F18 -> 4245 | G18: =E18+'7'!G18 -> 52129
B19: 12 | C19: Auxilairy steam consumption | D19: MT | E19: 18 | F19: =E19+'7'!F19 -> 142 | G19: =E19+'7'!G19 -> 1757
B20: 13 | C20: Specific steam consumption | D20: Kg/Kwhr | E20: =E17*1000/E7 -> 4.1435768 | F20: =F17*1000/F7 -> 4.1750763 | G20: =G17*1000/G7 -> 4.1647581
B21: 14 | C21: Specific fuel consumption | D21: Kg/Kwhr | E21: =E26*1000/E7 -> 0.83753149 | F21: =F26*1000/F7 -> 0.83626692 | G21: =G26*1000/G7 -> 0.86734005
B22: 15 | C22: Heat Rate(TG)2880 | D22: Kcal/Kwh | E22: =((E17*(803-130)+E31*(30))*1000)/E7 -> 2791.6499 | F22: =((F17*(803-130)+F31*(30))*1000)/F7 -> 2812.5252 | G22: =((G17*(803-130)+G31*(30))*1000)/G7 -> 2805.8883
B23: 16 | C23: Heat Rate ( Plant ) 3300 @ MCR | D23: Kcal/Kwh | E23: =(E15*(803-130))*1000/(E7*0.78) -> 3879.4323 | F23: =(F15*(803-130))*1000/(F7*0.78) -> 3893.2557 | G23: =(G15*(803-130))*1000/(G7*0.78) -> 3909.7308
B24: 17 | C24: DG Power Generation | D24: kWhr | E24: 0 | F24: =E24+'7'!F24 -> 0 | G24: =E24+'7'!G24 -> 1468
B25: FUEL Report
B26: 1 | C26: Coal Consumption | D26: MT | E26: 133 | F26: =E26+'7'!F26 -> 1069 | G26: =E26+'7'!G26 -> 13529
B27: 2 | C27: GCV ( ADB ) | D27: Kcal/kg | E27: 4626
B29: WTP Report
B30: 1 | C30: DM water Generation | D30: m3 | E30: 17 | F30: =E30+'7'!F30 -> 115 | G30: =E30+'7'!G30 -> 1548
B31: 2 | C31: DM water Consumption | D31: m3 | E31: 16 | F31: =E31+'7'!F31 -> 115 | G31: =E31+'7'!G31 -> 1563
B32: 3 | C32: CT Makeup Water Consumption | D32: m3 | E32: 54 | F32: =E32+'7'!F32 -> 185 | G32: =E32+'7'!G32 -> 1967
B33: 4 | C33: Fly ash combustible/ GCV | D33: % / kcal/kg | E33: 18 | F33: 1387
B34: FLY ASH DISPOSAL REPORT
B35: 5 | C35: Fly ash to cement mill | D35: MT | E35: 45 | F35: =E35+'7'!F35 -> 325 | G35: =E35+'7'!G35 -> 2483
B36: 6 | C36: Fly ash to Coal yard(Truck) | D36: nos | E36: 0 | F36: =E36+'7'!F36 -> 4 | G36: =E36+'7'!G36 -> 220
B37: 7 | C37: Fly ash to Dumpyard(Truck) | D37: nos | E37: 0 | F37: =E37+'7'!F37 -> 0 | G37: =E37+'7'!G37 -> 0

Sheet 9
B3: 1*10 MW CAPTIVE POWER PLANT
B4: Daily,Monthly & Yearly Generation Report (FRM-LCL-PP-06)
B6: Sr. NO. | C6: Description | D6: Unit | E6: ='8'!E6+1 -> 46212 | F6: Month to Date | G6: Year to Date(APR2026-MAR2027)
B7: 1 | C7: Gross Power Generation | D7: kWhr | E7: 165600 | F7: =E7+'8'!F7 -> 1443900 | G7: =E7+'8'!G7 -> 15763865
B8: 2 | C8: Auxiliary power consumption | D8: kWhr | E8: 17402 | F8: =E8+'8'!F8 -> 157739 | G8: =E8+'8'!G8 -> 1760334
B9: 3 | C9: Net Power Exported | D9: kWhr | E9: =E7-E8 -> 148198 | F9: =E9+'8'!F9 -> 1286161 | G9: =E9+'8'!G9 -> 14003531
B10: 4 | C10: Auxiliary power consumption | D10: ( % ) | E10: =E8/E7*100 -> 10.508454 | F10: =F8/F7*100 -> 10.92451 | G10: =G8/G7*100 -> 11.166893
B11: 5 | C11: Average Power Generation | D11: MWhr | E11: =E7/E12/1000 -> 6.9 | F11: =F7/F12/1000 -> 6.6847222 | G11: =G7/G12/1000 -> 6.624419
B12: 6 | C12: Plant Running Hours | D12: Hrs | E12: 24 | F12: =E12+'8'!F12 -> 216 | G12: =E12+'8'!G12 -> 2379.66
B13: 6 | C13: PLF | D13: ( % ) | E13: =E11/10*100 -> 69 | F13: =F11/10*100 -> 66.847222 | G13: =G11/10*100 -> 66.24419
B14: 7 | C14: Feed Water consumption | D14: MT | E14: 760 | F14: =E14+'8'!F14 -> 6751 | G14: =E14+'8'!G14 -> 73751
B15: 8 | C15: Boiler Steam Generation | D15: MT | E15: 740 | F15: =E15+'8'!F15 -> 6508 | G15: =E15+'8'!G15 -> 71421
B16: 9 | C16: Bleed steam | D16: MT | E16: 50 | F16: =E16+'8'!F16 -> 416 | G16: =E16+'8'!G16 -> 4504
B17: 10 | C17: Turbine steam consumption | D17: MT | E17: 690 | F17: =E17+'8'!F17 -> 6027 | G17: =E17+'8'!G17 -> 65653
B18: 11 | C18: Condensate Generation | D18: MT | E18: 547 | F18: =E18+'8'!F18 -> 4792 | G18: =E18+'8'!G18 -> 52676
B19: 12 | C19: Auxilairy steam consumption | D19: MT | E19: 18 | F19: =E19+'8'!F19 -> 160 | G19: =E19+'8'!G19 -> 1775
B20: 13 | C20: Specific steam consumption | D20: Kg/Kwhr | E20: =E17*1000/E7 -> 4.1666667 | F20: =F17*1000/F7 -> 4.1741118 | G20: =G17*1000/G7 -> 4.1647781
B21: 14 | C21: Specific fuel consumption | D21: Kg/Kwhr | E21: =E26*1000/E7 -> 0.83937198 | F21: =F26*1000/F7 -> 0.83662303 | G21: =G26*1000/G7 -> 0.86704625
B22: 15 | C22: Heat Rate(TG)2880 | D22: Kcal/Kwh | E22: =((E17*(803-130)+E31*(30))*1000)/E7 -> 2806.7029 | F22: =((F17*(803-130)+F31*(30))*1000)/F7 -> 2811.8575 | G22: =((G17*(803-130)+G31*(30))*1000)/G7 -> 2805.8968
B23: 16 | C23: Heat Rate ( Plant ) 3300 @ MCR | D23: Kcal/Kwh | E23: =(E15*(803-130))*1000/(E7*0.78) -> 3855.5989 | F23: =(F15*(803-130))*1000/(F7*0.78) -> 3888.9368 | G23: =(G15*(803-130))*1000/(G7*0.78) -> 3909.1621
B24: 17 | C24: DG Power Generation | D24: kWhr | E24: 0 | F24: =E24+'8'!F24 -> 0 | G24: =E24+'8'!G24 -> 1468
B25: FUEL Report
B26: 1 | C26: Coal Consumption | D26: MT | E26: 139 | F26: =E26+'8'!F26 -> 1208 | G26: =E26+'8'!G26 -> 13668
B27: 2 | C27: GCV ( ADB ) | D27: Kcal/kg | E27: 4592
B29: WTP Report
B30: 1 | C30: DM water Generation | D30: m3 | E30: 15 | F30: =E30+'8'!F30 -> 130 | G30: =E30+'8'!G30 -> 1563
B31: 2 | C31: DM water Consumption | D31: m3 | E31: 14 | F31: =E31+'8'!F31 -> 129 | G31: =E31+'8'!G31 -> 1577
B32: 3 | C32: CT Makeup Water Consumption | D32: m3 | E32: 20 | F32: =E32+'8'!F32 -> 205 | G32: =E32+'8'!G32 -> 1987
B33: 4 | C33: Fly ash combustible/ GCV | D33: % / kcal/kg | E33: 18.5 | F33: 1344
B34: FLY ASH DISPOSAL REPORT
B35: 5 | C35: Fly ash to cement mill | D35: MT | E35: 26 | F35: =E35+'8'!F35 -> 351 | G35: =E35+'8'!G35 -> 2509
B36: 6 | C36: Fly ash to Coal yard(Truck) | D36: nos | E36: 2 | F36: =E36+'8'!F36 -> 6 | G36: =E36+'8'!G36 -> 222
B37: 7 | C37: Fly ash to Dumpyard(Truck) | D37: nos | E37: 0 | F37: =E37+'8'!F37 -> 0 | G37: =E37+'8'!G37 -> 0

Sheet 10
B3: 1*10 MW CAPTIVE POWER PLANT
B4: Daily,Monthly & Yearly Generation Report (FRM-LCL-PP-06)
B6: Sr. NO. | C6: Description | D6: Unit | E6: ='9'!E6+1 -> 46213 | F6: Month to Date | G6: Year to Date(APR2026-MAR2027)
B7: 1 | C7: Gross Power Generation | D7: kWhr | E7: 165400 | F7: =E7+'9'!F7 -> 1609300 | G7: =E7+'9'!G7 -> 15929265
B8: 2 | C8: Auxiliary power consumption | D8: kWhr | E8: 17476 | F8: =E8+'9'!F8 -> 175215 | G8: =E8+'9'!G8 -> 1777810
B9: 3 | C9: Net Power Exported | D9: kWhr | E9: =E7-E8 -> 147924 | F9: =E9+'9'!F9 -> 1434085 | G9: =E9+'9'!G9 -> 14151455
B10: 4 | C10: Auxiliary power consumption | D10: ( % ) | E10: =E8/E7*100 -> 10.565901 | F10: =F8/F7*100 -> 10.887653 | G10: =G8/G7*100 -> 11.160653
B11: 5 | C11: Average Power Generation | D11: MWhr | E11: =E7/E12/1000 -> 6.8916667 | F11: =F7/F12/1000 -> 6.7054167 | G11: =G7/G12/1000 -> 6.6270874
B12: 6 | C12: Plant Running Hours | D12: Hrs | E12: 24 | F12: =E12+'9'!F12 -> 240 | G12: =E12+'9'!G12 -> 2403.66
B13: 6 | C13: PLF | D13: ( % ) | E13: =E11/10*100 -> 68.916667 | F13: =F11/10*100 -> 67.054167 | G13: =G11/10*100 -> 66.270874
B14: 7 | C14: Feed Water consumption | D14: MT | E14: 755 | F14: =E14+'9'!F14 -> 7506 | G14: =E14+'9'!G14 -> 74506
B15: 8 | C15: Boiler Steam Generation | D15: MT | E15: 741 | F15: =E15+'9'!F15 -> 7249 | G15: =E15+'9'!G15 -> 72162
B16: 9 | C16: Bleed steam | D16: MT | E16: 52 | F16: =E16+'9'!F16 -> 468 | G16: =E16+'9'!G16 -> 4556
B17: 10 | C17: Turbine steam consumption | D17: MT | E17: 690 | F17: =E17+'9'!F17 -> 6717 | G17: =E17+'9'!G17 -> 66343
B18: 11 | C18: Condensate Generation | D18: MT | E18: 541 | F18: =E18+'9'!F18 -> 5333 | G18: =E18+'9'!G18 -> 53217
B19: 12 | C19: Auxilairy steam consumption | D19: MT | E19: 18 | F19: =E19+'9'!F19 -> 178 | G19: =E19+'9'!G19 -> 1793
B20: 13 | C20: Specific steam consumption | D20: Kg/Kwhr | E20: =E17*1000/E7 -> 4.171705 | F20: =F17*1000/F7 -> 4.1738644 | G20: =G17*1000/G7 -> 4.16485
B21: 14 | C21: Specific fuel consumption | D21: Kg/Kwhr | E21: =E26*1000/E7 -> 0.86457074 | F21: =F26*1000/F7 -> 0.83949543 | G21: =G26*1000/G7 -> 0.86702054
B22: 15 | C22: Heat Rate(TG)2880 | D22: Kcal/Kwh | E22: =((E17*(803-130)+E31*(30))*1000)/E7 -> 2809.9154 | F22: =((F17*(803-130)+F31*(30))*1000)/F7 -> 2811.6579 | G22: =((G17*(803-130)+G31*(30))*1000)/G7 -> 2805.9386
B23: 16 | C23: Heat Rate ( Plant ) 3300 @ MCR | D23: Kcal/Kwh | E23: =(E15*(803-130))*1000/(E7*0.78) -> 3865.4776 | F23: =(F15*(803-130))*1000/(F7*0.78) -> 3886.5258 | G23: =(G15*(803-130))*1000/(G7*0.78) -> 3908.7085
B24: 17 | C24: DG Power Generation | D24: kWhr | E24: 0 | F24: =E24+'9'!F24 -> 0 | G24: =E24+'9'!G24 -> 1468
B25: FUEL Report
B26: 1 | C26: Coal Consumption | D26: MT | E26: 143 | F26: =E26+'9'!F26 -> 1351 | G26: =E26+'9'!G26 -> 13811
B27: 2 | C27: GCV ( ADB ) | D27: Kcal/kg | E27: 4470 | F27: 0
B29: WTP Report
B30: 1 | C30: DM water Generation | D30: m3 | E30: 12 | F30: =E30+'9'!F30 -> 142 | G30: =E30+'9'!G30 -> 1575
B31: 2 | C31: DM water Consumption | D31: m3 | E31: 13 | F31: =E31+'9'!F31 -> 142 | G31: =E31+'9'!G31 -> 1590
B32: 3 | C32: CT Makeup Water Consumption | D32: m3 | E32: 21 | F32: =E32+'9'!F32 -> 226 | G32: =E32+'9'!G32 -> 2008
B33: 4 | C33: Fly ash combustible/ GCV | D33: % / kcal/kg | E33: 17 | F33: 1320
B34: FLY ASH DISPOSAL REPORT
B35: 5 | C35: Fly ash to cement mill | D35: MT | E35: 0 | F35: =E35+'9'!F35 -> 351 | G35: =E35+'9'!G35 -> 2509
B36: 6 | C36: Fly ash to Coal yard(Truck) | D36: nos | E36: 5 | F36: =E36+'9'!F36 -> 11 | G36: =E36+'9'!G36 -> 227
B37: 7 | C37: Fly ash to Dumpyard(Truck) | D37: nos | E37: 0 | F37: =E37+'9'!F37 -> 0 | G37: =E37+'9'!G37 -> 0

Sheet 11
B3: 1*10 MW CAPTIVE POWER PLANT
B4: Daily,Monthly & Yearly Generation Report (FRM-LCL-PP-06)
B6: Sr. NO. | C6: Description | D6: Unit | E6: ='10'!E6+1 -> 46214 | F6: Month to Date | G6: Year to Date(APR2026-MAR2027)
B7: 1 | C7: Gross Power Generation | D7: kWhr | E7: 175400 | F7: =E7+'10'!F7 -> 1784700 | G7: =E7+'10'!G7 -> 16104665
B8: 2 | C8: Auxiliary power consumption | D8: kWhr | E8: 17691 | F8: =E8+'10'!F8 -> 192906 | G8: =E8+'10'!G8 -> 1795501
B9: 3 | C9: Net Power Exported | D9: kWhr | E9: =E7-E8 -> 157709 | F9: =E9+'10'!F9 -> 1591794 | G9: =E9+'10'!G9 -> 14309164
B10: 4 | C10: Auxiliary power consumption | D10: ( % ) | E10: =E8/E7*100 -> 10.086089 | F10: =F8/F7*100 -> 10.808875 | G10: =G8/G7*100 -> 11.14895
B11: 5 | C11: Average Power Generation | D11: MWhr | E11: =E7/E12/1000 -> 7.3083333 | F11: =F7/F12/1000 -> 6.7602273 | G11: =G7/G12/1000 -> 6.6338223
B12: 6 | C12: Plant Running Hours | D12: Hrs | E12: 24 | F12: =E12+'10'!F12 -> 264 | G12: =E12+'10'!G12 -> 2427.66
B13: 6 | C13: PLF | D13: ( % ) | E13: =E11/10*100 -> 73.083333 | F13: =F11/10*100 -> 67.602273 | G13: =G11/10*100 -> 66.338223
B14: 7 | C14: Feed Water consumption | D14: MT | E14: 792 | F14: =E14+'10'!F14 -> 8298 | G14: =E14+'10'!G14 -> 75298
B15: 8 | C15: Boiler Steam Generation | D15: MT | E15: 776 | F15: =E15+'10'!F15 -> 8025 | G15: =E15+'10'!G15 -> 72938
B16: 9 | C16: Bleed steam | D16: MT | E16: 56 | F16: =E16+'10'!F16 -> 524 | G16: =E16+'10'!G16 -> 4612
B17: 10 | C17: Turbine steam consumption | D17: MT | E17: 727 | F17: =E17+'10'!F17 -> 7444 | G17: =E17+'10'!G17 -> 67070
B18: 11 | C18: Condensate Generation | D18: MT | E18: 568 | F18: =E18+'10'!F18 -> 5901 | G18: =E18+'10'!G18 -> 53785
B19: 12 | C19: Auxilairy steam consumption | D19: MT | E19: 17 | F19: =E19+'10'!F19 -> 195 | G19: =E19+'10'!G19 -> 1810
B20: 13 | C20: Specific steam consumption | D20: Kg/Kwhr | E20: =E17*1000/E7 -> 4.1448119 | F20: =F17*1000/F7 -> 4.1710091 | G20: =G17*1000/G7 -> 4.1646318
B21: 14 | C21: Specific fuel consumption | D21: Kg/Kwhr | E21: =E26*1000/E7 -> 0.86659065 | F21: =F26*1000/F7 -> 0.84215835 | G21: =G26*1000/G7 -> 0.86701586
B22: 15 | C22: Heat Rate(TG)2880 | D22: Kcal/Kwh | E22: =((E17*(803-130)+E31*(30))*1000)/E7 -> 2791.8529 | F22: =((F17*(803-130)+F31*(30))*1000)/F7 -> 2809.7114 | G22: =((G17*(803-130)+G31*(30))*1000)/G7 -> 2805.7852
B23: 16 | C23: Heat Rate ( Plant ) 3300 @ MCR | D23: Kcal/Kwh | E23: =(E15*(803-130))*1000/(E7*0.78) -> 3817.2675 | F23: =(F15*(803-130))*1000/(F7*0.78) -> 3879.7191 | G23: =(G15*(803-130))*1000/(G7*0.78) -> 3907.7126
B24: 17 | C24: DG Power Generation | D24: kWhr | E24: 0 | F24: =E24+'10'!F24 -> 0 | G24: =E24+'10'!G24 -> 1468
B25: FUEL Report
B26: 1 | C26: Coal Consumption | D26: MT | E26: 152 | F26: =E26+'10'!F26 -> 1503 | G26: =E26+'10'!G26 -> 13963
B27: 2 | C27: GCV ( ADB ) | D27: Kcal/kg | E27: 4398
B29: WTP Report
B30: 1 | C30: DM water Generation | D30: m3 | E30: 16 | F30: =E30+'10'!F30 -> 158 | G30: =E30+'10'!G30 -> 1591
B31: 2 | C31: DM water Consumption | D31: m3 | E31: 14 | F31: =E31+'10'!F31 -> 156 | G31: =E31+'10'!G31 -> 1604
B32: 3 | C32: CT Makeup Water Consumption | D32: m3 | E32: 17 | F32: =E32+'10'!F32 -> 243 | G32: =E32+'10'!G32 -> 2025
B33: 4 | C33: Fly ash combustible/ GCV | D33: % / kcal/kg | E33: 17 | F33: 1298
B34: FLY ASH DISPOSAL REPORT
B35: 5 | C35: Fly ash to cement mill | D35: MT | E35: 0 | F35: =E35+'10'!F35 -> 351 | G35: =E35+'10'!G35 -> 2509
B36: 6 | C36: Fly ash to Coal yard(Truck) | D36: nos | E36: 4 | F36: =E36+'10'!F36 -> 15 | G36: =E36+'10'!G36 -> 231
B37: 7 | C37: Fly ash to Dumpyard(Truck) | D37: nos | E37: 0 | F37: =E37+'10'!F37 -> 0 | G37: =E37+'10'!G37 -> 0

Sheet 12
B3: 1*10 MW CAPTIVE POWER PLANT
B4: Daily,Monthly & Yearly Generation Report (FRM-LCL-PP-06)
B6: Sr. NO. | C6: Description | D6: Unit | E6: ='11'!E6+1 -> 46215 | F6: Month to Date | G6: Year to Date(APR2026-MAR2027)
B7: 1 | C7: Gross Power Generation | D7: kWhr | E7: 172800 | F7: =E7+'11'!F7 -> 1957500 | G7: =E7+'11'!G7 -> 16277465
B8: 2 | C8: Auxiliary power consumption | D8: kWhr | E8: 17568 | F8: =E8+'11'!F8 -> 210474 | G8: =E8+'11'!G8 -> 1813069
B9: 3 | C9: Net Power Exported | D9: kWhr | E9: =E7-E8 -> 155232 | F9: =E9+'11'!F9 -> 1747026 | G9: =E9+'11'!G9 -> 14464396
B10: 4 | C10: Auxiliary power consumption | D10: ( % ) | E10: =E8/E7*100 -> 10.166667 | F10: =F8/F7*100 -> 10.752184 | G10: =G8/G7*100 -> 11.138522
B11: 5 | C11: Average Power Generation | D11: MWhr | E11: =E7/E12/1000 -> 7.2 | F11: =F7/F12/1000 -> 6.796875 | G11: =G7/G12/1000 -> 6.6393648
B12: 6 | C12: Plant Running Hours | D12: Hrs | E12: 24 | F12: =E12+'11'!F12 -> 288 | G12: =E12+'11'!G12 -> 2451.66
B13: 6 | C13: PLF | D13: ( % ) | E13: =E11/10*100 -> 72 | F13: =F11/10*100 -> 67.96875 | G13: =G11/10*100 -> 66.393648
B14: 7 | C14: Feed Water consumption | D14: MT | E14: 782 | F14: =E14+'11'!F14 -> 9080 | G14: =E14+'11'!G14 -> 76080
B15: 8 | C15: Boiler Steam Generation | D15: MT | E15: 770 | F15: =E15+'11'!F15 -> 8795 | G15: =E15+'11'!G15 -> 73708
B16: 9 | C16: Bleed steam | D16: MT | E16: 56 | F16: =E16+'11'!F16 -> 580 | G16: =E16+'11'!G16 -> 4668
B17: 10 | C17: Turbine steam consumption | D17: MT | E17: 720 | F17: =E17+'11'!F17 -> 8164 | G17: =E17+'11'!G17 -> 67790
B18: 11 | C18: Condensate Generation | D18: MT | E18: 561 | F18: =E18+'11'!F18 -> 6462 | G18: =E18+'11'!G18 -> 54346
B19: 12 | C19: Auxilairy steam consumption | D19: MT | E19: 18 | F19: =E19+'11'!F19 -> 213 | G19: =E19+'11'!G19 -> 1828
B20: 13 | C20: Specific steam consumption | D20: Kg/Kwhr | E20: =E17*1000/E7 -> 4.1666667 | F20: =F17*1000/F7 -> 4.1706258 | G20: =G17*1000/G7 -> 4.1646534
B21: 14 | C21: Specific fuel consumption | D21: Kg/Kwhr | E21: =E26*1000/E7 -> 0.85648148 | F21: =F26*1000/F7 -> 0.84342273 | G21: =G26*1000/G7 -> 0.86690403
B22: 15 | C22: Heat Rate(TG)2880 | D22: Kcal/Kwh | E22: =((E17*(803-130)+E31*(30))*1000)/E7 -> 2806.0764 | F22: =((F17*(803-130)+F31*(30))*1000)/F7 -> 2809.3905 | G22: =((G17*(803-130)+G31*(30))*1000)/G7 -> 2805.7882
B23: 16 | C23: Heat Rate ( Plant ) 3300 @ MCR | D23: Kcal/Kwh | E23: =(E15*(803-130))*1000/(E7*0.78) -> 3844.7442 | F23: =(F15*(803-130))*1000/(F7*0.78) -> 3876.6316 | G23: =(G15*(803-130))*1000/(G7*0.78) -> 3907.0441
B24: 17 | C24: DG Power Generation | D24: kWhr | E24: 0 | F24: =E24+'11'!F24 -> 0 | G24: =E24+'11'!G24 -> 1468
B25: FUEL Report
B26: 1 | C26: Coal Consumption | D26: MT | E26: 148 | F26: =E26+'11'!F26 -> 1651 | G26: =E26+'11'!G26 -> 14111
B27: 2 | C27: GCV ( ADB ) | D27: Kcal/kg | E27: 4488
B29: WTP Report
B30: 1 | C30: DM water Generation | D30: m3 | E30: 12 | F30: =E30+'11'!F30 -> 170 | G30: =E30+'11'!G30 -> 1603
B31: 2 | C31: DM water Consumption | D31: m3 | E31: 11 | F31: =E31+'11'!F31 -> 167 | G31: =E31+'11'!G31 -> 1615
B32: 3 | C32: CT Makeup Water Consumption | D32: m3 | E32: 17 | F32: =E32+'11'!F32 -> 260 | G32: =E32+'11'!G32 -> 2042
B33: 4 | C33: Fly ash combustible/ GCV | D33: % / kcal/kg | E33: 17 | F33: 1321
B34: FLY ASH DISPOSAL REPORT
B35: 5 | C35: Fly ash to cement mill | D35: MT | E35: 0 | F35: =E35+'11'!F35 -> 351 | G35: =E35+'11'!G35 -> 2509
B36: 6 | C36: Fly ash to Coal yard(Truck) | D36: nos | E36: 4 | F36: =E36+'11'!F36 -> 19 | G36: =E36+'11'!G36 -> 235
B37: 7 | C37: Fly ash to Dumpyard(Truck) | D37: nos | E37: 0 | F37: =E37+'11'!F37 -> 0 | G37: =E37+'11'!G37 -> 0

Sheet 13
B3: 1*10 MW CAPTIVE POWER PLANT
B4: Daily,Monthly & Yearly Generation Report (FRM-LCL-PP-06)
B6: Sr. NO. | C6: Description | D6: Unit | E6: ='12'!E6+1 -> 46216 | F6: Month to Date | G6: Year to Date(APR2026-MAR2027)
B7: 1 | C7: Gross Power Generation | D7: kWhr | E7: 164500 | F7: =E7+'12'!F7 -> 2122000 | G7: =E7+'12'!G7 -> 16441965
B8: 2 | C8: Auxiliary power consumption | D8: kWhr | E8: 17591 | F8: =E8+'12'!F8 -> 228065 | G8: =E8+'12'!G8 -> 1830660
B9: 3 | C9: Net Power Exported | D9: kWhr | E9: =E7-E8 -> 146909 | F9: =E9+'12'!F9 -> 1893935 | G9: =E9+'12'!G9 -> 14611305
B10: 4 | C10: Auxiliary power consumption | D10: ( % ) | E10: =E8/E7*100 -> 10.693617 | F10: =F8/F7*100 -> 10.747644 | G10: =G8/G7*100 -> 11.134071
B11: 5 | C11: Average Power Generation | D11: MWhr | E11: =E7/E12/1000 -> 6.8541667 | F11: =F7/F12/1000 -> 6.8012821 | G11: =G7/G12/1000 -> 6.6414471
B12: 6 | C12: Plant Running Hours | D12: Hrs | E12: 24 | F12: =E12+'12'!F12 -> 312 | G12: =E12+'12'!G12 -> 2475.66
B13: 6 | C13: PLF | D13: ( % ) | E13: =E11/10*100 -> 68.541667 | F13: =F11/10*100 -> 68.012821 | G13: =G11/10*100 -> 66.414471
B14: 7 | C14: Feed Water consumption | D14: MT | E14: 762 | F14: =E14+'12'!F14 -> 9842 | G14: =E14+'12'!G14 -> 76842
B15: 8 | C15: Boiler Steam Generation | D15: MT | E15: 735 | F15: =E15+'12'!F15 -> 9530 | G15: =E15+'12'!G15 -> 74443
B16: 9 | C16: Bleed steam | D16: MT | E16: 52 | F16: =E16+'12'!F16 -> 632 | G16: =E16+'12'!G16 -> 4720
B17: 10 | C17: Turbine steam consumption | D17: MT | E17: 699 | F17: =E17+'12'!F17 -> 8863 | G17: =E17+'12'!G17 -> 68489
B18: 11 | C18: Condensate Generation | D18: MT | E18: 547 | F18: =E18+'12'!F18 -> 7009 | G18: =E18+'12'!G18 -> 54893
B19: 12 | C19: Auxilairy steam consumption | D19: MT | E19: 18 | F19: =E19+'12'!F19 -> 231 | G19: =E19+'12'!G19 -> 1846
B20: 13 | C20: Specific steam consumption | D20: Kg/Kwhr | E20: =E17*1000/E7 -> 4.2492401 | F20: =F17*1000/F7 -> 4.1767201 | G20: =G17*1000/G7 -> 4.1654997
B21: 14 | C21: Specific fuel consumption | D21: Kg/Kwhr | E21: =E26*1000/E7 -> 0.86322188 | F21: =F26*1000/F7 -> 0.84495759 | G21: =G26*1000/G7 -> 0.86686719
B22: 15 | C22: Heat Rate(TG)2880 | D22: Kcal/Kwh | E22: =((E17*(803-130)+E31*(30))*1000)/E7 -> 2862.2918 | F22: =((F17*(803-130)+F31*(30))*1000)/F7 -> 2813.4915 | G22: =((G17*(803-130)+G31*(30))*1000)/G7 -> 2806.3536
B23: 16 | C23: Heat Rate ( Plant ) 3300 @ MCR | D23: Kcal/Kwh | E23: =(E15*(803-130))*1000/(E7*0.78) -> 3855.1555 | F23: =(F15*(803-130))*1000/(F7*0.78) -> 3874.9668 | G23: =(G15*(803-130))*1000/(G7*0.78) -> 3906.525
B24: 17 | C24: DG Power Generation | D24: kWhr | E24: 0 | F24: =E24+'12'!F24 -> 0 | G24: =E24+'12'!G24 -> 1468
B25: FUEL Report
B26: 1 | C26: Coal Consumption | D26: MT | E26: 142 | F26: =E26+'12'!F26 -> 1793 | G26: =E26+'12'!G26 -> 14253
B27: 2 | C27: GCV ( ADB ) | D27: Kcal/kg | E27: 4439
B29: WTP Report
B30: 1 | C30: DM water Generation | D30: m3 | E30: 14 | F30: =E30+'12'!F30 -> 184 | G30: =E30+'12'!G30 -> 1617
B31: 2 | C31: DM water Consumption | D31: m3 | E31: 14 | F31: =E31+'12'!F31 -> 181 | G31: =E31+'12'!G31 -> 1629
B32: 3 | C32: CT Makeup Water Consumption | D32: m3 | E32: 18 | F32: =E32+'12'!F32 -> 278 | G32: =E32+'12'!G32 -> 2060
B33: 4 | C33: Fly ash combustible/ GCV | D33: % / kcal/kg | E33: 18 | F33: 1317
B34: FLY ASH DISPOSAL REPORT
B35: 5 | C35: Fly ash to cement mill | D35: MT | F35: =E35+'12'!F35 -> 351 | G35: =E35+'12'!G35 -> 2509
B36: 6 | C36: Fly ash to Coal yard(Truck) | D36: nos | E36: 4 | F36: =E36+'12'!F36 -> 23 | G36: =E36+'12'!G36 -> 239
B37: 7 | C37: Fly ash to Dumpyard(Truck) | D37: nos | E37: 0 | F37: =E37+'12'!F37 -> 0 | G37: =E37+'12'!G37 -> 0

Sheet 14
B3: 1*10 MW CAPTIVE POWER PLANT
B4: Daily,Monthly & Yearly Generation Report (FRM-LCL-PP-06)
B6: Sr. NO. | C6: Description | D6: Unit | E6: ='13'!E6+1 -> 46217 | F6: Month to Date | G6: Year to Date(APR2026-MAR2027)
B7: 1 | C7: Gross Power Generation | D7: kWhr | E7: 178100 | F7: =E7+'13'!F7 -> 2300100 | G7: =E7+'13'!G7 -> 16620065
B8: 2 | C8: Auxiliary power consumption | D8: kWhr | E8: 17829 | F8: =E8+'13'!F8 -> 245894 | G8: =E8+'13'!G8 -> 1848489
B9: 3 | C9: Net Power Exported | D9: kWhr | E9: =E7-E8 -> 160271 | F9: =E9+'13'!F9 -> 2054206 | G9: =E9+'13'!G9 -> 14771576
B10: 4 | C10: Auxiliary power consumption | D10: ( % ) | E10: =E8/E7*100 -> 10.010668 | F10: =F8/F7*100 -> 10.690579 | G10: =G8/G7*100 -> 11.122032
B11: 5 | C11: Average Power Generation | D11: MWhr | E11: =E7/E12/1000 -> 7.4208333 | F11: =F7/F12/1000 -> 6.8455357 | G11: =G7/G12/1000 -> 6.6489303
B12: 6 | C12: Plant Running Hours | D12: Hrs | E12: 24 | F12: =E12+'13'!F12 -> 336 | G12: =E12+'13'!G12 -> 2499.66
B13: 6 | C13: PLF | D13: ( % ) | E13: =E11/10*100 -> 74.208333 | F13: =F11/10*100 -> 68.455357 | G13: =G11/10*100 -> 66.489303
B14: 7 | C14: Feed Water consumption | D14: MT | E14: 811 | F14: =E14+'13'!F14 -> 10653 | G14: =E14+'13'!G14 -> 77653
B15: 8 | C15: Boiler Steam Generation | D15: MT | E15: 792 | F15: =E15+'13'!F15 -> 10322 | G15: =E15+'13'!G15 -> 75235
B16: 9 | C16: Bleed steam | D16: MT | E16: 59 | F16: =E16+'13'!F16 -> 691 | G16: =E16+'13'!G16 -> 4779
B17: 10 | C17: Turbine steam consumption | D17: MT | E17: 741 | F17: =E17+'13'!F17 -> 9604 | G17: =E17+'13'!G17 -> 69230
B18: 11 | C18: Condensate Generation | D18: MT | E18: 583 | F18: =E18+'13'!F18 -> 7592 | G18: =E18+'13'!G18 -> 55476
B19: 12 | C19: Auxilairy steam consumption | D19: MT | E19: 18 | F19: =E19+'13'!F19 -> 249 | G19: =E19+'13'!G19 -> 1864
B20: 13 | C20: Specific steam consumption | D20: Kg/Kwhr | E20: =E17*1000/E7 -> 4.1605839 | F20: =F17*1000/F7 -> 4.1754706 | G20: =G17*1000/G7 -> 4.165447
B21: 14 | C21: Specific fuel consumption | D21: Kg/Kwhr | E21: =E26*1000/E7 -> 0.85345312 | F21: =F26*1000/F7 -> 0.84561541 | G21: =G26*1000/G7 -> 0.86672345
B22: 15 | C22: Heat Rate(TG)2880 | D22: Kcal/Kwh | E22: =((E17*(803-130)+E31*(30))*1000)/E7 -> 2802.4312 | F22: =((F17*(803-130)+F31*(30))*1000)/F7 -> 2812.6351 | G22: =((G17*(803-130)+G31*(30))*1000)/G7 -> 2806.3115
B23: 16 | C23: Heat Rate ( Plant ) 3300 @ MCR | D23: Kcal/Kwh | E23: =(E15*(803-130))*1000/(E7*0.78) -> 3836.911 | F23: =(F15*(803-130))*1000/(F7*0.78) -> 3872.0201 | G23: =(G15*(803-130))*1000/(G7*0.78) -> 3905.779
B24: 17 | C24: DG Power Generation | D24: kWhr | E24: 0 | F24: =E24+'13'!F24 -> 0 | G24: =E24+'13'!G24 -> 1468
B25: FUEL Report
B26: 1 | C26: Coal Consumption | D26: MT | E26: 152 | F26: =E26+'13'!F26 -> 1945 | G26: =E26+'13'!G26 -> 14405
B27: 2 | C27: GCV ( ADB ) | D27: Kcal/kg | E27: 4494
B29: WTP Report
B30: 1 | C30: DM water Generation | D30: m3 | E30: 13 | F30: =E30+'13'!F30 -> 197 | G30: =E30+'13'!G30 -> 1630
B31: 2 | C31: DM water Consumption | D31: m3 | E31: 14 | F31: =E31+'13'!F31 -> 195 | G31: =E31+'13'!G31 -> 1643
B32: 3 | C32: CT Makeup Water Consumption | D32: m3 | E32: 17 | F32: =E32+'13'!F32 -> 295 | G32: =E32+'13'!G32 -> 2077
B33: 4 | C33: Fly ash combustible/ GCV | D33: % / kcal/kg | E33: 17.75 | F33: 1330
B34: FLY ASH DISPOSAL REPORT
B35: 5 | C35: Fly ash to cement mill | D35: MT | E35: 0 | F35: =E35+'13'!F35 -> 351 | G35: =E35+'13'!G35 -> 2509
B36: 6 | C36: Fly ash to Coal yard(Truck) | D36: nos | E36: 4 | F36: =E36+'13'!F36 -> 27 | G36: =E36+'13'!G36 -> 243
B37: 7 | C37: Fly ash to Dumpyard(Truck) | D37: nos | E37: 0 | F37: =E37+'13'!F37 -> 0 | G37: =E37+'13'!G37 -> 0

Sheet 15
B3: 1*10 MW CAPTIVE POWER PLANT
B4: Daily,Monthly & Yearly Generation Report (FRM-LCL-PP-06)
B6: Sr. NO. | C6: Description | D6: Unit | E6: ='14'!E6+1 -> 46218 | F6: Month to Date | G6: Year to Date(APR2026-MAR2027)
B7: 1 | C7: Gross Power Generation | D7: kWhr | E7: 184200 | F7: =E7+'14'!F7 -> 2484300 | G7: =E7+'14'!G7 -> 16804265
B8: 2 | C8: Auxiliary power consumption | D8: kWhr | E8: 18146 | F8: =E8+'14'!F8 -> 264040 | G8: =E8+'14'!G8 -> 1866635
B9: 3 | C9: Net Power Exported | D9: kWhr | E9: =E7-E8 -> 166054 | F9: =E9+'14'!F9 -> 2220260 | G9: =E9+'14'!G9 -> 14937630
B10: 4 | C10: Auxiliary power consumption | D10: ( % ) | E10: =E8/E7*100 -> 9.8512486 | F10: =F8/F7*100 -> 10.628346 | G10: =G8/G7*100 -> 11.108103
B11: 5 | C11: Average Power Generation | D11: MWhr | E11: =E7/E12/1000 -> 7.675 | F11: =F7/F12/1000 -> 6.9008333 | G11: =G7/G12/1000 -> 6.6586882
B12: 6 | C12: Plant Running Hours | D12: Hrs | E12: 24 | F12: =E12+'14'!F12 -> 360 | G12: =E12+'14'!G12 -> 2523.66
B13: 6 | C13: PLF | D13: ( % ) | E13: =E11/10*100 -> 76.75 | F13: =F11/10*100 -> 69.008333 | G13: =G11/10*100 -> 66.586882
B14: 7 | C14: Feed Water consumption | D14: MT | E14: 832 | F14: =E14+'14'!F14 -> 11485 | G14: =E14+'14'!G14 -> 78485
B15: 8 | C15: Boiler Steam Generation | D15: MT | E15: 816 | F15: =E15+'14'!F15 -> 11138 | G15: =E15+'14'!G15 -> 76051
B16: 9 | C16: Bleed steam | D16: MT | E16: 60 | F16: =E16+'14'!F16 -> 751 | G16: =E16+'14'!G16 -> 4839
B17: 10 | C17: Turbine steam consumption | D17: MT | E17: 766 | F17: =E17+'14'!F17 -> 10370 | G17: =E17+'14'!G17 -> 69996
B18: 11 | C18: Condensate Generation | D18: MT | E18: 600 | F18: =E18+'14'!F18 -> 8192 | G18: =E18+'14'!G18 -> 56076
B19: 12 | C19: Auxilairy steam consumption | D19: MT | E19: 18 | F19: =E19+'14'!F19 -> 267 | G19: =E19+'14'!G19 -> 1882
B20: 13 | C20: Specific steam consumption | D20: Kg/Kwhr | E20: =E17*1000/E7 -> 4.1585233 | F20: =F17*1000/F7 -> 4.1742141 | G20: =G17*1000/G7 -> 4.1653711
B21: 14 | C21: Specific fuel consumption | D21: Kg/Kwhr | E21: =E26*1000/E7 -> 0.84147666 | F21: =F26*1000/F7 -> 0.84530854 | G21: =G26*1000/G7 -> 0.8664467
B22: 15 | C22: Heat Rate(TG)2880 | D22: Kcal/Kwh | E22: =((E17*(803-130)+E31*(30))*1000)/E7 -> 2800.6406 | F22: =((F17*(803-130)+F31*(30))*1000)/F7 -> 2811.7458 | G22: =((G17*(803-130)+G31*(30))*1000)/G7 -> 2806.2494
B23: 16 | C23: Heat Rate ( Plant ) 3300 @ MCR | D23: Kcal/Kwh | E23: =(E15*(803-130))*1000/(E7*0.78) -> 3822.2668 | F23: =(F15*(803-130))*1000/(F7*0.78) -> 3868.3311 | G23: =(G15*(803-130))*1000/(G7*0.78) -> 3904.8636
B24: 17 | C24: DG Power Generation | D24: kWhr | E24: 0 | F24: =E24+'14'!F24 -> 0 | G24: =E24+'14'!G24 -> 1468
B25: FUEL Report
B26: 1 | C26: Coal Consumption | D26: MT | E26: 155 | F26: =E26+'14'!F26 -> 2100 | G26: =E26+'14'!G26 -> 14560
B27: 2 | C27: GCV ( ADB ) | D27: Kcal/kg | E27: 4542
B29: WTP Report
B30: 1 | C30: DM water Generation | D30: m3 | E30: 12 | F30: =E30+'14'!F30 -> 209 | G30: =E30+'14'!G30 -> 1642
B31: 2 | C31: DM water Consumption | D31: m3 | E31: 12 | F31: =E31+'14'!F31 -> 207 | G31: =E31+'14'!G31 -> 1655
B32: 3 | C32: CT Makeup Water Consumption | D32: m3 | E32: 18 | F32: =E32+'14'!F32 -> 313 | G32: =E32+'14'!G32 -> 2095
B33: 4 | C33: Fly ash combustible/ GCV | D33: % / kcal/kg | E33: 16.8 | F33: 1280
B34: FLY ASH DISPOSAL REPORT
B35: 5 | C35: Fly ash to cement mill | D35: MT | E35: 0 | F35: =E35+'14'!F35 -> 351 | G35: =E35+'14'!G35 -> 2509
B36: 6 | C36: Fly ash to Coal yard(Truck) | D36: nos | E36: 5 | F36: =E36+'14'!F36 -> 32 | G36: =E36+'14'!G36 -> 248
B37: 7 | C37: Fly ash to Dumpyard(Truck) | D37: nos | E37: 0 | F37: =E37+'14'!F37 -> 0 | G37: =E37+'14'!G37 -> 0

Sheet 16
B3: 1*10 MW CAPTIVE POWER PLANT
B4: Daily,Monthly & Yearly Generation Report (FRM-LCL-PP-06)
B6: Sr. NO. | C6: Description | D6: Unit | E6: ='15'!E6+1 -> 46219 | F6: Month to Date | G6: Year to Date(APR2026-MAR2027)
B7: 1 | C7: Gross Power Generation | D7: kWhr | E7: 181700 | F7: =E7+'15'!F7 -> 2666000 | G7: =E7+'15'!G7 -> 16985965
B8: 2 | C8: Auxiliary power consumption | D8: kWhr | E8: 17979 | F8: =E8+'15'!F8 -> 282019 | G8: =E8+'15'!G8 -> 1884614
B9: 3 | C9: Net Power Exported | D9: kWhr | E9: =E7-E8 -> 163721 | F9: =E9+'15'!F9 -> 2383981 | G9: =E9+'15'!G9 -> 15101351
B10: 4 | C10: Auxiliary power consumption | D10: ( % ) | E10: =E8/E7*100 -> 9.8948817 | F10: =F8/F7*100 -> 10.578357 | G10: =G8/G7*100 -> 11.095125
B11: 5 | C11: Average Power Generation | D11: MWhr | E11: =E7/E12/1000 -> 7.5708333 | F11: =F7/F12/1000 -> 6.9427083 | G11: =G7/G12/1000 -> 6.667281
B12: 6 | C12: Plant Running Hours | D12: Hrs | E12: 24 | F12: =E12+'15'!F12 -> 384 | G12: =E12+'15'!G12 -> 2547.66
B13: 6 | C13: PLF | D13: ( % ) | E13: =E11/10*100 -> 75.708333 | F13: =F11/10*100 -> 69.427083 | G13: =G11/10*100 -> 66.67281
B14: 7 | C14: Feed Water consumption | D14: MT | E14: 822 | F14: =E14+'15'!F14 -> 12307 | G14: =E14+'15'!G14 -> 79307
B15: 8 | C15: Boiler Steam Generation | D15: MT | E15: 804 | F15: =E15+'15'!F15 -> 11942 | G15: =E15+'15'!G15 -> 76855
B16: 9 | C16: Bleed steam | D16: MT | E16: 60 | F16: =E16+'15'!F16 -> 811 | G16: =E16+'15'!G16 -> 4899
B17: 10 | C17: Turbine steam consumption | D17: MT | E17: 760 | F17: =E17+'15'!F17 -> 11130 | G17: =E17+'15'!G17 -> 70756
B18: 11 | C18: Condensate Generation | D18: MT | E18: 591 | F18: =E18+'15'!F18 -> 8783 | G18: =E18+'15'!G18 -> 56667
B19: 12 | C19: Auxilairy steam consumption | D19: MT | E19: 18 | F19: =E19+'15'!F19 -> 285 | G19: =E19+'15'!G19 -> 1900
B20: 13 | C20: Specific steam consumption | D20: Kg/Kwhr | E20: =E17*1000/E7 -> 4.1827188 | F20: =F17*1000/F7 -> 4.1747937 | G20: =G17*1000/G7 -> 4.1655567
B21: 14 | C21: Specific fuel consumption | D21: Kg/Kwhr | E21: =E26*1000/E7 -> 0.87506879 | F21: =F26*1000/F7 -> 0.84733683 | G21: =G26*1000/G7 -> 0.86653893
B22: 15 | C22: Heat Rate(TG)2880 | D22: Kcal/Kwh | E22: =((E17*(803-130)+E31*(30))*1000)/E7 -> 2816.951 | F22: =((F17*(803-130)+F31*(30))*1000)/F7 -> 2812.1005 | G22: =((G17*(803-130)+G31*(30))*1000)/G7 -> 2806.3638
B23: 16 | C23: Heat Rate ( Plant ) 3300 @ MCR | D23: Kcal/Kwh | E23: =(E15*(803-130))*1000/(E7*0.78) -> 3817.8739 | F23: =(F15*(803-130))*1000/(F7*0.78) -> 3864.8922 | G23: =(G15*(803-130))*1000/(G7*0.78) -> 3903.9331
B24: 17 | C24: DG Power Generation | D24: kWhr | E24: 0 | F24: =E24+'15'!F24 -> 0 | G24: =E24+'15'!G24 -> 1468
B25: FUEL Report
B26: 1 | C26: Coal Consumption | D26: MT | E26: 159 | F26: =E26+'15'!F26 -> 2259 | G26: =E26+'15'!G26 -> 14719
B27: 2 | C27: GCV ( ADB ) | D27: Kcal/kg | E27: 4355
B29: WTP Report
B30: 1 | C30: DM water Generation | D30: m3 | E30: 12 | F30: =E30+'15'!F30 -> 221 | G30: =E30+'15'!G30 -> 1654
B31: 2 | C31: DM water Consumption | D31: m3 | E31: 12 | F31: =E31+'15'!F31 -> 219 | G31: =E31+'15'!G31 -> 1667
B32: 3 | C32: CT Makeup Water Consumption | D32: m3 | E32: 18 | F32: =E32+'15'!F32 -> 331 | G32: =E32+'15'!G32 -> 2113
B33: 4 | C33: Fly ash combustible/ GCV | D33: % / kcal/kg | E33: 16.57 | F33: 1164
B34: FLY ASH DISPOSAL REPORT
B35: 5 | C35: Fly ash to cement mill | D35: MT | E35: 0 | F35: =E35+'15'!F35 -> 351 | G35: =E35+'15'!G35 -> 2509
