Workbook

Sheet Mines (2)
B1: MARCH | C1: HG LS | H1: LG LS | L1: Clay | Q1: Sand | V1: TG | Z1: HGHMGO | AD1: PURCHASED LIMESTONE | AH1: Total
B2: Date | C2: Opening Stock | D2: Production | E2: Total Consumption | F2: CONS R/M1 | G2: Closing Stock | H2: Opening Stock | I2: Production | J2: Consumption | K2: Closing Stock | L2: Opening Stock | M2: Production | N2: TOTAL Consumption | O2: Cons R/M1 | P2: Closing Stock | Q2: Opening Stock | R2: Production | S2: TOTALConsumption | T2: Cons R/M1 | U2: Closing Stock | V2: Opening Stock | W2: Production | X2: Consumption | Y2: Closing Stock | Z2: Opening Stock | AA2: Production | AB2: Consumption | AC2: Closing Stock | AD2: Opening Stock | AE2: Production | AF2: Consumption | AG2: Closing Stock | AH2: P | AI2: C | AJ2: Raw meal | AK2: diff | AL2: LG | AR2: MINES CONS | AS2: MINES RECEIPT
B3: 1 | C3: =9504.32318000297+1.74 -> 9506.0632 | D3: 0 | E3: =F3+'RAW MILL 2'!C3 -> 0 | F3: 0 | G3: =C3+D3-E3 -> 9506.0632 | H3: 13598.809 | I3: 401.14 | J3: 0 | K3: =H3+I3-J3-Cement!Q3 -> 13547.099 | L3: 124.04 | M3: 0 | N3: =O3+'RAW MILL 2'!D3 -> 0 | O3: 0 | P3: =L3+M3-N3 -> 124.04 | Q3: 600.28 | R3: 0 | S3: =T3+'RAW MILL 2'!E3 -> 0 | T3: 0 | U3: =Q3+R3-S3 -> 600.28 | V3: 0 | W3: 0 | X3: 0 | Y3: =V3+W3-X3 -> 0 | Z3: 0 | AA3: 0 | AB3: 0 | AC3: =Z3+AA3-AB3 -> 0 | AD3: 0 | AE3: 0 | AF3: 0 | AG3: =AD3+AE3-AF3 -> 0 | AH3: =D3+I3+M3+R3+W3+AA3+Cement!P3+Cement!T3+AE3 -> 401.14 | AI3: =E3+J3+N3+S3+X3+AB3+Clinker!E3+AF3 -> 0 | AJ3: =Production2!N3 -> 0 | AL3: 3103 | AQ3: =D3+I3+M3+R3+Cement!P3 -> 401.14 | AR3: =AI3+Cement!Q3-Clinker!E3 -> 452.85 | AS3: 940.1 | AT3: =AI3-Production2!N3 -> 0 | AU3: =AI3 -> 0 | AV3: =E3+J3 -> 0 | AW3: =AS3-D3 -> 940.1 | AX3: =I3-AY3 -> -1218.36 | AY3: 1619.5 | AZ3: =(AI3-Production2!N3)/'Mines (2)'!AI3 -> #DIV/0! | BA3: =AZ3*100 -> #DIV/0! | BB3: =E3+J3+AB3 -> 0
B4: 2 | C4: =G3 -> 9506.0632 | D4: 0 | E4: =F4+'RAW MILL 2'!C4 -> 0 | F4: 0 | G4: =C4+D4-E4 -> 9506.0632 | H4: =K3 -> 13547.099 | I4: 808.48 | J4: 0 | K4: =H4+I4-J4-Cement!Q4 -> 13882.179 | L4: =P3 -> 124.04 | M4: 0 | N4: =O4+'RAW MILL 2'!D4 -> 0 | O4: 0 | P4: =L4+M4-N4 -> 124.04 | Q4: =U3 -> 600.28 | R4: 0 | S4: =T4+'RAW MILL 2'!E4 -> 0 | T4: 0 | U4: =Q4+R4-S4 -> 600.28 | V4: =Y3 -> 0 | W4: 0 | X4: 0 | Y4: =V4+W4-X4 -> 0 | Z4: =AC3 -> 0 | AA4: 0 | AB4: 0 | AC4: =Z4+AA4-AB4 -> 0 | AD4: =AG3 -> 0 | AE4: 0 | AF4: 0 | AG4: =AD4+AE4-AF4 -> 0 | AH4: =D4+I4+M4+R4+W4+AA4+Cement!P4+Cement!T4+AE4 -> 808.48 | AI4: =E4+J4+N4+S4+X4+AB4+Clinker!E4+AF4 -> 0 | AJ4: =Production2!N4 -> 0 | AK4: =AJ4-AI4 -> 0 | AL4: 3286 | AQ4: =D4+I4+M4+R4+Cement!P4 -> 808.48 | AR4: =AI4+Cement!Q4-Clinker!E4 -> 473.4 | AS4: 987.54 | AT4: =AI4-Production2!N4 -> 0 | AU4: =AI4 -> 0 | AV4: =E4+J4 -> 0 | AW4: =AS4-D4 -> 987.54 | AX4: =I4-AY4 -> 185.2 | AY4: 623.28 | AZ4: =(AI4-Production2!N4)/'Mines (2)'!AI4 -> #DIV/0! | BA4: =AZ4*100 -> #DIV/0! | BB4: =E4+J4+AB4 -> 0
B5: 3 | C5: =G4 -> 9506.0632 | D5: 0 | E5: =F5+'RAW MILL 2'!C5 -> 488 | F5: 488 | G5: =C5+D5-E5 -> 9018.0632 | H5: =K4 -> 13882.179 | I5: 239.08 | J5: 0 | K5: =H5+I5-J5-Cement!Q5 -> 13671.459 | L5: =P4 -> 124.04 | M5: 0 | N5: =O5+'RAW MILL 2'!D5 -> 0 | O5: 0 | P5: =L5+M5-N5 -> 124.04 | Q5: =U4 -> 600.28 | R5: 0 | S5: =T5+'RAW MILL 2'!E5 -> 0 | T5: 0 | U5: =Q5+R5-S5 -> 600.28 | V5: =Y4 -> 0 | W5: 0 | X5: 0 | Y5: =V5+W5-X5 -> 0 | Z5: =AC4 -> 0 | AA5: 0 | AB5: 0 | AC5: =Z5+AA5-AB5 -> 0 | AD5: =AG4 -> 0 | AE5: 0 | AF5: 0 | AG5: =AD5+AE5-AF5 -> 0 | AH5: =D5+I5+M5+R5+W5+AA5+Cement!P5+Cement!T5+AE5 -> 239.08 | AI5: =E5+J5+N5+S5+X5+AB5+Clinker!E5+AF5 -> 498 | AJ5: =Production2!N5 -> 448.5 | AK5: =AJ5-AI5 -> -49.5 | AL5: 2899 | AQ5: =D5+I5+M5+R5+Cement!P5 -> 239.08 | AR5: =AI5+Cement!Q5-Clinker!E5 -> 937.8 | AS5: 249.34 | AT5: =AI5-Production2!N5 -> 49.5 | AU5: =AI5 -> 498 | AV5: =E5+J5 -> 488 | AW5: =AS5-D5 -> 249.34 | AX5: =I5-AY5 -> -203.42 | AY5: 442.5 | AZ5: =(AI5-Production2!N5)/'Mines (2)'!AI5 -> 0.09939759 | BA5: =AZ5*100 -> 9.939759 | BB5: =E5+J5+AB5 -> 488
B6: 4 | C6: =G5 -> 9018.0632 | D6: 1286.4 | E6: =F6+'RAW MILL 2'!C6 -> 1137 | F6: 1137 | G6: =C6+D6-E6 -> 9167.4632 | H6: =K5 -> 13671.459 | I6: 879.5 | J6: 0 | K6: =H6+I6-J6-Cement!Q6 -> 14149.459 | L6: =P5 -> 124.04 | M6: 0 | N6: =O6+'RAW MILL 2'!D6 -> 0 | O6: 0 | P6: =L6+M6-N6 -> 124.04 | Q6: =U5 -> 600.28 | R6: 0 | S6: =T6+'RAW MILL 2'!E6 -> 0 | T6: 0 | U6: =Q6+R6-S6 -> 600.28 | V6: =Y5 -> 0 | W6: 0 | X6: 0 | Y6: =V6+W6-X6 -> 0 | Z6: =AC5 -> 0 | AA6: 0 | AB6: 0 | AC6: =Z6+AA6-AB6 -> 0 | AD6: =AG5 -> 0 | AE6: 0 | AF6: 0 | AG6: =AD6+AE6-AF6 -> 0 | AH6: =D6+I6+M6+R6+W6+AA6+Cement!P6+Cement!T6+AE6 -> 2165.9 | AI6: =E6+J6+N6+S6+X6+AB6+Clinker!E6+AF6 -> 1160 | AJ6: =Production2!N6 -> 1044.69 | AK6: =AJ6-AI6 -> -115.31 | AL6: 3290 | AQ6: =D6+I6+M6+R6+Cement!P6 -> 2165.9 | AR6: =AI6+Cement!Q6-Clinker!E6 -> 1538.5 | AS6: 1108.96 | AT6: =AI6-Production2!N6 -> 115.31 | AU6: =AI6 -> 1160 | AV6: =E6+J6 -> 1137 | AW6: =AS6-D6 -> -177.44 | AX6: =I6-AY6 -> -1357.26 | AY6: 2236.76 | AZ6: =(AI6-Production2!N6)/'Mines (2)'!AI6 -> 0.099405172 | BA6: =AZ6*100 -> 9.9405172 | BB6: =E6+J6+AB6 -> 1137
B7: 5 | C7: =G6 -> 9167.4632 | D7: 697.96 | E7: =F7+'RAW MILL 2'!C7 -> 0 | F7: 0 | G7: =C7+D7-E7 -> 9865.4232 | H7: =K6 -> 14149.459 | I7: 787.42 | J7: 0 | K7: =H7+I7-J7-Cement!Q7 -> 14348.879 | L7: =P6 -> 124.04 | M7: 0 | N7: =O7+'RAW MILL 2'!D7 -> 0 | O7: 0 | P7: =L7+M7-N7 -> 124.04 | Q7: =U6 -> 600.28 | R7: 0 | S7: =T7+'RAW MILL 2'!E7 -> 0 | T7: 0 | U7: =Q7+R7-S7 -> 600.28 | V7: =Y6 -> 0 | W7: 0 | X7: 0 | Y7: =V7+W7-X7 -> 0 | Z7: =AC6 -> 0 | AA7: 0 | AB7: 0 | AC7: =Z7+AA7-AB7 -> 0 | AD7: =AG6 -> 0 | AE7: 0 | AF7: 0 | AG7: =AD7+AE7-AF7 -> 0 | AH7: =D7+I7+M7+R7+W7+AA7+Cement!P7+Cement!T7+AE7 -> 1485.38 | AI7: =E7+J7+N7+S7+X7+AB7+Clinker!E7+AF7 -> 0 | AJ7: =Production2!N7 -> 0 | AK7: =AJ7-AI7 -> 0 | AL7: 3245 | AQ7: =D7+I7+R7+Cement!P7 -> 1485.38 | AR7: =AI7+Cement!Q7-Clinker!E7 -> 588 | AS7: 0 | AT7: =AI7-Production2!N7 -> 0 | AU7: =AI7 -> 0 | AV7: =E7+J7 -> 0 | AW7: =AS7-D7 -> -697.96 | AX7: =I7-AY7 -> 787.42 | AY7: 0 | AZ7: =(AI7-Production2!N7)/'Mines (2)'!AI7 -> #DIV/0! | BA7: =AZ7*100 -> #DIV/0! | BB7: =E7+J7+AB7 -> 0
B8: 6 | C8: =G7 -> 9865.4232 | D8: 0 | E8: =F8+'RAW MILL 2'!C8 -> 1000 | F8: 1000 | G8: =C8+D8-E8 -> 8865.4232 | H8: =K7 -> 14348.879 | I8: 420.1 | J8: 1471 | K8: =H8+I8-J8-Cement!Q8 -> 12906.299 | L8: =P7 -> 124.04 | M8: 0 | N8: =O8+'RAW MILL 2'!D8 -> 10 | O8: 10 | P8: =L8+M8-N8 -> 114.04 | Q8: =U7 -> 600.28 | R8: 0 | S8: =T8+'RAW MILL 2'!E8 -> 12 | T8: 12 | U8: =Q8+R8-S8 -> 588.28 | V8: =Y7 -> 0 | W8: 0 | X8: 0 | Y8: =V8+W8-X8 -> 0 | Z8: =AC7 -> 0 | AA8: 0 | AB8: 0 | AC8: =Z8+AA8-AB8 -> 0 | AD8: =AG7 -> 0 | AE8: 0 | AF8: 0 | AG8: =AD8+AE8-AF8 -> 0 | AH8: =D8+I8+M8+R8+W8+AA8+Cement!P8+Cement!T8+AE8 -> 420.1 | AI8: =E8+J8+N8+S8+X8+AB8+Clinker!E8+AF8 -> 2549 | AJ8: =Production2!N8 -> 2294.1 | AK8: =AJ8-AI8 -> -254.9 | AL8: 3139 | AQ8: =D8+I8+M8+R8+Cement!P8 -> 420.1 | AR8: =AI8+Cement!Q8-Clinker!E8 -> 2884.68 | AS8: 1300 | AT8: =AI8-Production2!N8 -> 254.9 | AU8: =AI8 -> 2549 | AV8: =E8+J8 -> 2471 | AW8: =AS8-D8 -> 1300 | AX8: =I8-AY8 -> -419.9 | AY8: 840 | AZ8: =(AI8-Production2!N8)/'Mines (2)'!AI8 -> 0.1 | BA8: =AZ8*100 -> 10 | BB8: =E8+J8+AB8 -> 2471
B9: 7 | C9: =G8 -> 8865.4232 | D9: 1837.02 | E9: =F9+'RAW MILL 2'!C9 -> 1314 | F9: 1078 | G9: =C9+D9-E9 -> 9388.4432 | H9: =K8 -> 12906.299 | I9: 1446.6 | J9: 2000 | K9: =H9+I9-J9-Cement!Q9 -> 11947.949 | L9: =P8 -> 114.04 | M9: 0 | N9: =O9+'RAW MILL 2'!D9 -> 14 | O9: 13 | P9: =L9+M9-N9 -> 100.04 | Q9: =U8 -> 588.28 | R9: 0 | S9: =T9+'RAW MILL 2'!E9 -> 0 | T9: 0 | U9: =Q9+R9-S9 -> 588.28 | V9: =Y8 -> 0 | W9: 0 | X9: 0 | Y9: =V9+W9-X9 -> 0 | Z9: =AC8 -> 0 | AA9: 0 | AB9: 0 | AC9: =Z9+AA9-AB9 -> 0 | AD9: =AG8 -> 0 | AE9: 0 | AF9: 0 | AG9: =AD9+AE9-AF9 -> 0 | AH9: =D9+I9+M9+R9+W9+AA9+Cement!P9+Cement!T9+AE9 -> 3283.62 | AI9: =E9+J9+N9+S9+X9+AB9+Clinker!E9+AF9 -> 3396 | AJ9: =Production2!N9 -> 2838 | AK9: =AJ9-AI9 -> -558 | AL9: 1732 | AQ9: =D9+I9+M9+R9+Cement!P9 -> 3283.62 | AR9: =AI9+Cement!Q9-Clinker!E9 -> 3732.95 | AS9: 480 | AT9: =AI9-Production2!N9 -> 558 | AU9: =AI9 -> 3396 | AV9: =E9+J9 -> 3314 | AW9: =AS9-D9 -> -1357.02 | AX9: =I9-AY9 -> -733.4 | AY9: 2180 | AZ9: =(AI9-Production2!N9)/'Mines (2)'!AI9 -> 0.16431095 | BA9: =AZ9*100 -> 16.431095 | BB9: =E9+J9+AB9 -> 3314
B10: 8 | C10: =G9 -> 9388.4432 | D10: 588.58 | E10: =F10+'RAW MILL 2'!C10 -> 2195 | F10: 2000 | G10: =C10+D10-E10 -> 7782.0232 | H10: =K9 -> 11947.949 | I10: 2411.22 | J10: 1117 | K10: =H10+I10-J10-Cement!Q10 -> 12963.169 | L10: =P9 -> 100.04 | M10: 0 | N10: =O10+'RAW MILL 2'!D10 -> 0 | O10: 0 | P10: =L10+M10-N10 -> 100.04 | Q10: =U9 -> 588.28 | R10: 0 | S10: =T10+'RAW MILL 2'!E10 -> 14 | T10: 13 | U10: =Q10+R10-S10 -> 574.28 | V10: =Y9 -> 0 | W10: 0 | X10: 0 | Y10: =V10+W10-X10 -> 0 | Z10: =AC9 -> 0 | AA10: 0 | AB10: 0 | AC10: =Z10+AA10-AB10 -> 0 | AD10: =AG9 -> 0 | AE10: 0 | AF10: 0 | AG10: =AD10+AE10-AF10 -> 0 | AH10: =D10+I10+M10+R10+W10+AA10+Cement!P10+Cement!T10+AE10 -> 2999.8 | AI10: =E10+J10+N10+S10+X10+AB10+Clinker!E10+AF10 -> 3377 | AJ10: =Production2!N10 -> 2860 | AK10: =AJ10-AI10 -> -517 | AL10: 1959 | AQ10: =D10+I10+M10+R10+Cement!P10 -> 2999.8 | AR10: =AI10+Cement!Q10-Clinker!E10 -> 3605 | AS10: 1612.08 | AT10: =AI10-Production2!N10 -> 517 | AU10: =AI10 -> 3377 | AV10: =E10+J10 -> 3312 | AW10: =AS10-D10 -> 1023.5 | AX10: =I10-AY10 -> 1771.22 | AY10: 640 | AZ10: =(AI10-Production2!N10)/'Mines (2)'!AI10 -> 0.15309446 | BA10: =AZ10*100 -> 15.309446 | BB10: =E10+J10+AB10 -> 3312
B11: 9 | C11: =G10 -> 7782.0232 | D11: 0 | E11: =F11+'RAW MILL 2'!C11 -> 1743 | F11: 1661 | G11: =C11+D11-E11 -> 6039.0232 | H11: =K10 -> 12963.169 | I11: 3157.38 | J11: 1000 | K11: =H11+I11-J11-Cement!Q11 -> 14840.299 | L11: =P10 -> 100.04 | M11: 0 | N11: =O11+'RAW MILL 2'!D11 -> 0 | O11: 0 | P11: =L11+M11-N11 -> 100.04 | Q11: =U10 -> 574.28 | R11: 0 | S11: =T11+'RAW MILL 2'!E11 -> 9 | T11: 8 | U11: =Q11+R11-S11 -> 565.28 | V11: =Y10 -> 0 | W11: 0 | X11: 0 | Y11: =V11+W11-X11 -> 0 | Z11: =AC10 -> 0 | AA11: 0 | AB11: 0 | AC11: =Z11+AA11-AB11 -> 0 | AD11: =AG10 -> 0 | AE11: 0 | AF11: 0 | AG11: =AD11+AE11-AF11 -> 0 | AH11: =D11+I11+M11+R11+W11+AA11+Cement!P11+Cement!T11+AE11 -> 3157.38 | AI11: =E11+J11+N11+S11+X11+AB11+Clinker!E11+AF11 -> 2808 | AJ11: =Production2!N11 -> 2453 | AK11: =AJ11-AI11 -> -355 | AL11: 3119 | AQ11: =D11+I11+M11+R11+Cement!P11 -> 3157.38 | AR11: =AI11+Cement!Q11-Clinker!E11 -> 3032.25 | AS11: 2277.26 | AT11: =AI11-Production2!N11 -> 355 | AU11: =AI11 -> 2808 | AV11: =E11+J11 -> 2743 | AW11: =AS11-D11 -> 2277.26 | AX11: =I11-AY11 -> 2539.6 | AY11: 617.78 | AZ11: =(AI11-Production2!N11)/'Mines (2)'!AI11 -> 0.1264245 | BA11: =AZ11*100 -> 12.64245 | BB11: =E11+J11+AB11 -> 2743
B12: 10 | C12: =G11 -> 6039.0232 | D12: 1458.14 | E12: =F12+'RAW MILL 2'!C12 -> 2150 | F12: 1897 | G12: =C12+D12-E12 -> 5347.1632 | H12: =K11 -> 14840.299 | I12: 1302.46 | J12: 1000 | K12: =H12+I12-J12-Cement!Q12 -> 14833.259 | L12: =P11 -> 100.04 | M12: 0 | N12: =O12+'RAW MILL 2'!D12 -> 0 | O12: 0 | P12: =L12+M12-N12 -> 100.04 | Q12: =U11 -> 565.28 | R12: 0 | S12: =T12+'RAW MILL 2'!E12 -> 11 | T12: 10 | U12: =Q12+R12-S12 -> 554.28 | V12: =Y11 -> 0 | W12: 0 | X12: 0 | Y12: =V12+W12-X12 -> 0 | Z12: =AC11 -> 0 | AA12: 0 | AB12: 0 | AC12: =Z12+AA12-AB12 -> 0 | AD12: =AG11 -> 0 | AE12: 0 | AF12: 0 | AG12: =AD12+AE12-AF12 -> 0 | AH12: =D12+I12+M12+R12+W12+AA12+Cement!P12+Cement!T12+AE12 -> 2760.6 | AI12: =E12+J12+N12+S12+X12+AB12+Clinker!E12+AF12 -> 3225 | AJ12: =Production2!N12 -> 2669 | AK12: =AJ12-AI12 -> -556 | AL12: 3017 | AQ12: =D12+I12+M12+R12+Cement!P12 -> 2760.6 | AR12: =AI12+Cement!Q12-Clinker!E12 -> 3470.5 | AS12: 400.64 | AT12: =AI12-Production2!N12 -> 556 | AU12: =AI12 -> 3225 | AV12: =E12+J12 -> 3150 | AW12: =AS12-D12 -> -1057.5 | AX12: =I12-AY12 -> 159.88 | AY12: 1142.58 | AZ12: =(AI12-Production2!N12)/'Mines (2)'!AI12 -> 0.1724031 | BA12: =AZ12*100 -> 17.24031 | BB12: =E12+J12+AB12 -> 3150
B13: 11 | C13: =G12 -> 5347.1632 | D13: 1032.84 | E13: =F13+'RAW MILL 2'!C13 -> 1807 | F13: 1660 | G13: =C13+D13-E13 -> 4573.0032 | H13: =K12 -> 14833.259 | I13: 2249.46 | J13: 1000 | K13: =H13+I13-J13-Cement!Q13 -> 15864.719 | L13: =P12 -> 100.04 | M13: 0 | N13: =O13+'RAW MILL 2'!D13 -> 0 | O13: 0 | P13: =L13+M13-N13 -> 100.04 | Q13: =U12 -> 554.28 | R13: 0 | S13: =T13+'RAW MILL 2'!E13 -> 9 | T13: 8 | U13: =Q13+R13-S13 -> 545.28 | V13: =Y12 -> 0 | W13: 0 | X13: 0 | Y13: =V13+W13-X13 -> 0 | Z13: =AC12 -> 0 | AA13: 0 | AB13: 0 | AC13: =Z13+AA13-AB13 -> 0 | AD13: =AG12 -> 0 | AE13: 0 | AF13: 0 | AG13: =AD13+AE13-AF13 -> 0 | AH13: =D13+I13+M13+R13+W13+AA13+Cement!P13+Cement!T13+AE13 -> 3282.3 | AI13: =E13+J13+N13+S13+X13+AB13+Clinker!E13+AF13 -> 2874 | AJ13: =Production2!N13 -> 2451 | AK13: =AJ13-AI13 -> -423 | AL13: 3256 | AQ13: =D13+I13+M13+R13+Cement!P13 -> 3282.3 | AR13: =AI13+Cement!Q13-Clinker!E13 -> 3034 | AS13: 1843.24 | AT13: =AI13-Production2!N13 -> 423 | AU13: =AI13 -> 2874 | AV13: =E13+J13 -> 2807 | AW13: =AS13-D13 -> 810.4 | AX13: =I13-AY13 -> 1155.98 | AY13: 1093.48 | AZ13: =(AI13-Production2!N13)/'Mines (2)'!AI13 -> 0.14718163 | BA13: =AZ13*100 -> 14.718163 | BB13: =E13+J13+AB13 -> 2807
B14: 12 | C14: =G13 -> 4573.0032 | D14: 1071.7 | E14: =F14+'RAW MILL 2'!C14 -> 1141 | F14: 1007 | G14: =C14+D14-E14 -> 4503.7032 | H14: =K13 -> 15864.719 | I14: 1827.24 | J14: 2000 | K14: =H14+I14-J14-Cement!Q14 -> 15430.709 | L14: =P13 -> 100.04 | M14: 0 | N14: =O14+'RAW MILL 2'!D14 -> 5 | O14: 5 | P14: =L14+M14-N14 -> 95.04 | Q14: =U13 -> 545.28 | R14: 0 | S14: =T14+'RAW MILL 2'!E14 -> 10 | T14: 9 | U14: =Q14+R14-S14 -> 535.28 | V14: =Y13 -> 0 | W14: 0 | X14: 0 | Y14: =V14+W14-X14 -> 0 | Z14: =AC13 -> 0 | AA14: 0 | AB14: 0 | AC14: =Z14+AA14-AB14 -> 0 | AD14: =AG13 -> 0 | AE14: 0 | AF14: 0 | AG14: =AD14+AE14-AF14 -> 0 | AH14: =D14+I14+M14+R14+W14+AA14+Cement!P14+Cement!T14+AE14 -> 2898.94 | AI14: =E14+J14+N14+S14+X14+AB14+Clinker!E14+AF14 -> 3236 | AJ14: =Production2!N14 -> 2790 | AK14: =AJ14-AI14 -> -446 | AL14: 3209 | AQ14: =D14+I14+M14+R14+Cement!P14 -> 2898.94 | AR14: =AI14+Cement!Q14-Clinker!E14 -> 3417.25 | AS14: 665.76 | AT14: =AI14-Production2!N14 -> 446 | AU14: =AI14 -> 3236 | AV14: =E14+J14 -> 3141 | AW14: =AS14-D14 -> -405.94 | AX14: =I14-AY14 -> 641.82 | AY14: 1185.42 | AZ14: =(AI14-Production2!N14)/'Mines (2)'!AI14 -> 0.13782447 | BA14: =AZ14*100 -> 13.782447 | BB14: =E14+J14+AB14 -> 3141
B15: 13 | C15: =G14 -> 4503.7032 | D15: 0 | E15: =F15+'RAW MILL 2'!C15 -> 859 | F15: 639 | G15: =C15+D15-E15 -> 3644.7032 | H15: =K14 -> 15430.709 | I15: 2390.26 | J15: 2000 | K15: =H15+I15-J15-Cement!Q15 -> 15615.669 | L15: =P14 -> 95.04 | M15: 0 | N15: =O15+'RAW MILL 2'!D15 -> 23 | O15: 22 | P15: =L15+M15-N15 -> 72.04 | Q15: =U14 -> 535.28 | R15: 0 | S15: =T15+'RAW MILL 2'!E15 -> 19 | T15: 17 | U15: =Q15+R15-S15 -> 516.28 | V15: =Y14 -> 0 | W15: 0 | X15: 0 | Y15: =V15+W15-X15 -> 0 | Z15: =AC14 -> 0 | AA15: 0 | AB15: 0 | AC15: =Z15+AA15-AB15 -> 0 | AD15: =AG14 -> 0 | AE15: 0 | AF15: 0 | AG15: =AD15+AE15-AF15 -> 0 | AH15: =D15+I15+M15+R15+W15+AA15+Cement!P15+Cement!T15+AE15 -> 2390.26 | AI15: =E15+J15+N15+S15+X15+AB15+Clinker!E15+AF15 -> 2961 | AJ15: =Production2!N15 -> 2460 | AK15: =AJ15-AI15 -> -501 | AL15: 3075 | AQ15: =D15+I15+M15+R15+Cement!P15 -> 2390.26 | AR15: =AI15+Cement!Q15-Clinker!E15 -> 3106.3 | AS15: 776.72 | AT15: =AI15-Production2!N15 -> 501 | AU15: =AI15 -> 2961 | AV15: =E15+J15 -> 2859 | AW15: =AS15-D15 -> 776.72 | AX15: =I15-AY15 -> 1169.74 | AY15: 1220.52 | AZ15: =(AI15-Production2!N15)/'Mines (2)'!AI15 -> 0.16919959 | BA15: =AZ15*100 -> 16.919959 | BB15: =E15+J15+AB15 -> 2859
B16: 14 | C16: =G15 -> 3644.7032 | D16: 0 | E16: =F16+'RAW MILL 2'!C16 -> 912 | F16: 697 | G16: =C16+D16-E16 -> 2732.7032 | H16: =K15 -> 15615.669 | I16: 2389.26 | J16: 2000 | K16: =H16+I16-J16-Cement!Q16 -> 15725.329 | L16: =P15 -> 72.04 | M16: 0 | N16: =O16+'RAW MILL 2'!D16 -> 27 | O16: 25 | P16: =L16+M16-N16 -> 45.04 | Q16: =U15 -> 516.28 | R16: 0 | S16: =T16+'RAW MILL 2'!E16 -> 0 | T16: 0 | U16: =Q16+R16-S16 -> 516.28 | V16: =Y15 -> 0 | W16: 0 | X16: 0 | Y16: =V16+W16-X16 -> 0 | Z16: =AC15 -> 0 | AA16: 0 | AB16: 0 | AC16: =Z16+AA16-AB16 -> 0 | AD16: =AG15 -> 0 | AE16: 0 | AF16: 0 | AG16: =AD16+AE16-AF16 -> 0 | AH16: =D16+I16+M16+R16+W16+AA16+Cement!P16+Cement!T16+AE16 -> 2389.26 | AI16: =E16+J16+N16+S16+X16+AB16+Clinker!E16+AF16 -> 2999 | AJ16: =Production2!N16 -> 2501 | AK16: =AJ16-AI16 -> -498 | AL16: 2456 | AQ16: =D16+I16+M16+R16+Cement!P16 -> 2389.26 | AR16: =AI16+Cement!Q16-Clinker!E16 -> 3218.6 | AS16: 1682.06 | AT16: =AI16-Production2!N16 -> 498 | AU16: =AI16 -> 2999 | AV16: =E16+J16 -> 2912 | AW16: =AS16-D16 -> 1682.06 | AX16: =I16-AY16 -> 1331.1 | AY16: 1058.16 | AZ16: =(AI16-Production2!N16)/'Mines (2)'!AI16 -> 0.16605535 | BA16: =AZ16*100 -> 16.605535 | BB16: =E16+J16+AB16 -> 2912
B17: 15 | C17: =G16 -> 2732.7032 | D17: 926.16 | E17: =F17+'RAW MILL 2'!C17 -> 666 | F17: 413 | G17: =C17+D17-E17 -> 2992.8632 | H17: =K16 -> 15725.329 | I17: 1252.42 | J17: 2000 | K17: =H17+I17-J17-Cement!Q17 -> 14613.899 | L17: =P16 -> 45.04 | M17: 0 | N17: =O17+'RAW MILL 2'!D17 -> 5 | O17: 4 | P17: =L17+M17-N17 -> 40.04 | Q17: =U16 -> 516.28 | R17: 0 | S17: =T17+'RAW MILL 2'!E17 -> 0 | T17: 0 | U17: =Q17+R17-S17 -> 516.28 | V17: =Y16 -> 0 | W17: 0 | X17: 0 | Y17: =V17+W17-X17 -> 0 | Z17: =AC16 -> 0 | AA17: 0 | AB17: 0 | AC17: =Z17+AA17-AB17 -> 0 | AD17: =AG16 -> 0 | AE17: 0 | AF17: 0 | AG17: =AD17+AE17-AF17 -> 0 | AH17: =D17+I17+M17+R17+W17+AA17+Cement!P17+Cement!T17+AE17 -> 2178.58 | AI17: =E17+J17+N17+S17+X17+AB17+Clinker!E17+AF17 -> 2739 | AJ17: =Production2!N17 -> 2232 | AK17: =AJ17-AI17 -> -507 | AL17: 2956 | AM17: =E17/AJ17 -> 0.2983871 | AN17: =J17/AJ17 -> 0.89605735 | AO17: =N17/AJ17 -> 0.0022401434 | AP17: =S17/AJ17 -> 0 | AQ17: =D17+I17+M17+R17+Cement!P17 -> 2178.58 | AR17: =AI17+Cement!Q17-Clinker!E17 -> 3034.85 | AS17: 593.68 | AT17: =AI17-Production2!N17 -> 507 | AU17: =AI17 -> 2739 | AV17: =E17+J17 -> 2666 | AW17: =AS17-D17 -> -332.48 | AX17: =I17-AY17 -> 681.5 | AY17: 570.92 | AZ17: =(AI17-Production2!N17)/'Mines (2)'!AI17 -> 0.18510405 | BA17: =AZ17*100 -> 18.510405 | BB17: =E17+J17+AB17 -> 2666
B18: 16 | C18: =G17 -> 2992.8632 | D18: 1284.46 | E18: =F18+'RAW MILL 2'!C18 -> 542 | F18: 335 | G18: =C18+D18-E18 -> 3735.3232 | H18: =K17 -> 14613.899 | I18: 1488.7 | J18: 2000 | K18: =H18+I18-J18-Cement!Q18 -> 13729.749 | L18: =P17 -> 40.04 | M18: 100 | N18: =O18+'RAW MILL 2'!D18 -> 5 | O18: 4 | P18: =L18+M18-N18 -> 135.04 | Q18: =U17 -> 516.28 | R18: 0 | S18: =T18+'RAW MILL 2'!E18 -> 1 | T18: 1 | U18: =Q18+R18-S18 -> 515.28 | V18: =Y17 -> 0 | W18: 0 | X18: 0 | Y18: =V18+W18-X18 -> 0 | Z18: =AC17 -> 0 | AA18: 0 | AB18: 0 | AC18: =Z18+AA18-AB18 -> 0 | AD18: =AG17 -> 0 | AE18: 0 | AF18: 0 | AG18: =AD18+AE18-AF18 -> 0 | AH18: =D18+I18+M18+R18+W18+AA18+Cement!P18+Cement!T18+AE18 -> 2873.16 | AI18: =E18+J18+N18+S18+X18+AB18+Clinker!E18+AF18 -> 2600 | AJ18: =Production2!N18 -> 2150 | AK18: =AJ18-AI18 -> -450 | AL18: 3022 | AM18: =E18/AJ18 -> 0.25209302 | AN18: =J18/AJ18 -> 0.93023256 | AO18: =N18/AJ18 -> 0.0023255814 | AP18: =S18/AJ18 -> 0.00046511628 | AQ18: =D18+I18+M18+R18+Cement!P18 -> 2873.16 | AR18: =AI18+Cement!Q18-Clinker!E18 -> 2920.85 | AS18: 1924.02 | AT18: =AI18-Production2!N18 -> 450 | AU18: =AI18 -> 2600 | AV18: =E18+J18 -> 2542 | AW18: =AS18-D18 -> 639.56 | AX18: =I18-AY18 -> -439.88 | AY18: 1928.58 | AZ18: =(AI18-Production2!N18)/'Mines (2)'!AI18 -> 0.17307692 | BA18: =AZ18*100 -> 17.307692
B19: 17 | C19: =G18 -> 3735.3232 | D19: 295.02 | E19: =F19+'RAW MILL 2'!C19 -> 609 | F19: 406 | G19: =C19+D19-E19 -> 3421.3432 | H19: =K18 -> 13729.749 | I19: 2219.62 | J19: 2000 | K19: =H19+I19-J19-Cement!Q19 -> 13788.869 | L19: =P18 -> 135.04 | M19: 0 | N19: =O19+'RAW MILL 2'!D19 -> 5 | O19: 4 | P19: =L19+M19-N19 -> 130.04 | Q19: =U18 -> 515.28 | R19: 0 | S19: =T19+'RAW MILL 2'!E19 -> 1 | T19: 1 | U19: =Q19+R19-S19 -> 514.28 | V19: =Y18 -> 0 | W19: 0 | X19: 0 | Y19: =V19+W19-X19 -> 0 | Z19: =AC18 -> 0 | AA19: 0 | AB19: 0 | AC19: =Z19+AA19-AB19 -> 0 | AD19: =AG18 -> 0 | AE19: 0 | AF19: 0 | AG19: =AD19+AE19-AF19 -> 0 | AH19: =D19+I19+M19+R19+W19+AA19+Cement!P19+Cement!T19+AE19 -> 2514.64 | AI19: =E19+J19+N19+S19+X19+AB19+Clinker!E19+AF19 -> 2668 | AJ19: =Production2!N19 -> 2214 | AK19: =AJ19-AI19 -> -454 | AL19: 2379 | AM19: =E19/AJ19 -> 0.27506775 | AN19: =J19/AJ19 -> 0.90334237 | AO19: =N19/AJ19 -> 0.0022583559 | AP19: =S19/AJ19 -> 0.00045167118 | AQ19: =D19+I19+M19+R19+Cement!P19 -> 2514.64 | AR19: =AI19+Cement!Q19-Clinker!E19 -> 2775.5 | AS19: 2200 | AT19: =AI19-Production2!N19 -> 454 | AU19: =AI19 -> 2668 | AV19: =E19+J19 -> 2609 | AW19: =AS19-D19 -> 1904.98 | AX19: =I19-AY19 -> 1319.62 | AY19: 900 | AZ19: =(AI19-Production2!N19)/'Mines (2)'!AI19 -> 0.17016492 | BA19: =AZ19*100 -> 17.016492
B20: 18 | C20: =G19 -> 3421.3432 | D20: 1353.7 | E20: =F20+'RAW MILL 2'!C20 -> 1073 | F20: 879 | G20: =C20+D20-E20 -> 3702.0432 | H20: =K19 -> 13788.869 | I20: 853.64 | J20: 1000 | K20: =H20+I20-J20-Cement!Q20 -> 13251.509 | L20: =P19 -> 130.04 | M20: 314.56 | N20: =O20+'RAW MILL 2'!D20 -> 3 | O20: 3 | P20: =L20+M20-N20 -> 441.6 | Q20: =U19 -> 514.28 | R20: 0 | S20: =T20+'RAW MILL 2'!E20 -> 1 | T20: 1 | U20: =Q20+R20-S20 -> 513.28 | V20: =Y19 -> 0 | W20: 0 | X20: 0 | Y20: =V20+W20-X20 -> 0 | Z20: =AC19 -> 0 | AA20: 0 | AB20: 0 | AC20: =Z20+AA20-AB20 -> 0 | AD20: =AG19 -> 0 | AE20: 0 | AF20: 0 | AG20: =AD20+AE20-AF20 -> 0 | AH20: =D20+I20+M20+R20+W20+AA20+Cement!P20+Cement!T20+AE20 -> 2521.9 | AI20: =E20+J20+N20+S20+X20+AB20+Clinker!E20+AF20 -> 2120 | AJ20: =Production2!N20 -> 1729 | AK20: =AJ20-AI20 -> -391 | AL20: 3157 | AM20: =E20/AJ20 -> 0.62058994 | AN20: =J20/AJ20 -> 0.578369 | AO20: =N20/AJ20 -> 0.001735107 | AP20: =S20/AJ20 -> 0.000578369 | AQ20: =D20+I20+M20+R20+Cement!P20 -> 2521.9 | AR20: =AI20+Cement!Q20-Clinker!E20 -> 2468 | AS20: 1275.56 | AT20: =AI20-Production2!N20 -> 391 | AU20: =AI20 -> 2120 | AV20: =E20+J20 -> 2073 | AW20: =AS20-D20 -> -78.14 | AX20: =I20-AY20 -> 272.32 | AY20: 581.32 | AZ20: =(AI20-Production2!N20)/'Mines (2)'!AI20 -> 0.18443396 | BA20: =AZ20*100 -> 18.443396
B21: 19 | C21: =G20 -> 3702.0432 | D21: 2799.8 | E21: =F21+'RAW MILL 2'!C21 -> 991 | F21: 882 | G21: =C21+D21-E21 -> 5510.8432 | H21: =K20 -> 13251.509 | I21: 852.26 | J21: 1000 | K21: =H21+I21-J21-Cement!Q21 -> 12952.469 | L21: =P20 -> 441.6 | M21: 61.34 | N21: =O21+'RAW MILL 2'!D21 -> 0 | O21: 0 | P21: =L21+M21-N21 -> 502.94 | Q21: =U20 -> 513.28 | R21: 92.54 | S21: =T21+'RAW MILL 2'!E21 -> 0 | T21: 0 | U21: =Q21+R21-S21 -> 605.82 | V21: =Y20 -> 0 | W21: 0 | X21: 0 | Y21: =V21+W21-X21 -> 0 | Z21: =AC20 -> 0 | AA21: 0 | AB21: 0 | AC21: =Z21+AA21-AB21 -> 0 | AD21: =AG20 -> 0 | AE21: 0 | AF21: 0 | AG21: =AD21+AE21-AF21 -> 0 | AH21: =D21+I21+M21+R21+W21+AA21+Cement!P21+Cement!T21+AE21 -> 3805.94 | AI21: =E21+J21+N21+S21+X21+AB21+Clinker!E21+AF21 -> 2033 | AJ21: =Production2!N21 -> 1730 | AK21: =AJ21-AI21 -> -303 | AL21: 2838 | AM21: =E21/AJ21 -> 0.57283237 | AN21: =J21/AJ21 -> 0.57803468 | AO21: =N21/AJ21 -> 0 | AP21: =S21/AJ21 -> 0 | AQ21: =D21+I21+M21+R21+Cement!P21 -> 3805.94 | AR21: =AI21+Cement!Q21-Clinker!E21 -> 2142.3 | AS21: 244.68 | AT21: =AI21-Production2!N21 -> 303 | AU21: =AI21 -> 2033 | AV21: =E21+J21 -> 1991 | AW21: =AS21-D21 -> -2555.12 | AX21: =I21-AY21 -> -527.86 | AY21: 1380.12 | AZ21: =(AI21-Production2!N21)/'Mines (2)'!AI21 -> 0.14904083 | BA21: =AZ21*100 -> 14.904083
B22: 20 | C22: =G21 -> 5510.8432 | D22: 1451.92 | E22: =F22+'RAW MILL 2'!C22 -> 979 | F22: 896 | G22: =C22+D22-E22 -> 5983.7632 | H22: =K21 -> 12952.469 | I22: 1355 | J22: 1000 | K22: =H22+I22-J22-Cement!Q22 -> 13132.159 | L22: =P21 -> 502.94 | M22: 0 | N22: =O22+'RAW MILL 2'!D22 -> 0 | O22: 0 | P22: =L22+M22-N22 -> 502.94 | Q22: =U21 -> 605.82 | R22: 0 | S22: =T22+'RAW MILL 2'!E22 -> 21 | T22: 20 | U22: =Q22+R22-S22 -> 584.82 | V22: =Y21 -> 0 | W22: 0 | X22: 0 | Y22: =V22+W22-X22 -> 0 | Z22: =AC21 -> 0 | AA22: 0 | AB22: 0 | AC22: =Z22+AA22-AB22 -> 0 | AD22: =AG21 -> 0 | AE22: 0 | AF22: 0 | AG22: =AD22+AE22-AF22 -> 0 | AH22: =D22+I22+M22+R22+W22+AA22+Cement!P22+Cement!T22+AE22 -> 2806.92 | AI22: =E22+J22+N22+S22+X22+AB22+Clinker!E22+AF22 -> 2041 | AJ22: =Production2!N22 -> 1760 | AK22: =AJ22-AI22 -> -281 | AL22: 3051 | AM22: =E22/AJ22 -> 0.55625 | AN22: =J22/AJ22 -> 0.56818182 | AO22: =N22/AJ22 -> 0 | AP22: =S22/AJ22 -> 0.011931818 | AQ22: =D22+I22+M22+R22+Cement!P22 -> 2806.92 | AR22: =AI22+Cement!Q22-Clinker!E22 -> 2175.31 | AS22: 841.18 | AT22: =AI22-Production2!N22 -> 281 | AU22: =AI22 -> 2041 | AV22: =E22+J22 -> 1979 | AW22: =AS22-D22 -> -610.74 | AX22: =I22-AY22 -> -245.8 | AY22: 1600.8 | AZ22: =(AI22-Production2!N22)/'Mines (2)'!AI22 -> 0.13767761 | BA22: =AZ22*100 -> 13.767761
B23: 21 | C23: =G22 -> 5983.7632 | D23: 3063.96 | E23: =F23+'RAW MILL 2'!C23 -> 894 | F23: 788 | G23: =C23+D23-E23 -> 8153.7232 | H23: =K22 -> 13132.159 | I23: 183.94 | J23: 1000 | K23: =H23+I23-J23-Cement!Q23 -> 12099.449 | L23: =P22 -> 502.94 | M23: 118.24 | N23: =O23+'RAW MILL 2'!D23 -> 3 | O23: 2 | P23: =L23+M23-N23 -> 618.18 | Q23: =U22 -> 584.82 | R23: 45.22 | S23: =T23+'RAW MILL 2'!E23 -> 81 | T23: 76 | U23: =Q23+R23-S23 -> 549.04 | V23: =Y22 -> 0 | W23: 0 | X23: 0 | Y23: =V23+W23-X23 -> 0 | Z23: =AC22 -> 0 | AA23: 0 | AB23: 0 | AC23: =Z23+AA23-AB23 -> 0 | AD23: =AG22 -> 0 | AE23: 0 | AF23: 0 | AG23: =AD23+AE23-AF23 -> 0 | AH23: =D23+I23+M23+R23+W23+AA23+Cement!P23+Cement!T23+AE23 -> 3411.36 | AI23: =E23+J23+N23+S23+X23+AB23+Clinker!E23+AF23 -> 2025 | AJ23: =Production2!N23 -> 1720 | AK23: =AJ23-AI23 -> -305 | AL23: 2232 | AM23: =E23/AJ23 -> 0.51976744 | AN23: =J23/AJ23 -> 0.58139535 | AO23: =N23/AJ23 -> 0.001744186 | AP23: =S23/AJ23 -> 0.047093023 | AQ23: =D23+I23+R23+#REF!+Cement!P23 -> #REF! | AR23: =AI23+Cement!Q23-Clinker!E23 -> 2194.65 | AS23: 0 | AT23: =AI23-Production2!N23 -> 305 | AU23: =AI23 -> 2025 | AV23: =E23+J23 -> 1894 | AW23: =AS23-D23 -> -3063.96 | AX23: =I23-AY23 -> -843.64 | AY23: 1027.58 | AZ23: =(AI23-Production2!N23)/'Mines (2)'!AI23 -> 0.15061728 | BA23: =AZ23*100 -> 15.061728
B24: 22 | C24: =G23 -> 8153.7232 | D24: 1054.56 | E24: =F24+'RAW MILL 2'!C24 -> 419 | F24: 237 | G24: =C24+D24-E24 -> 8789.2832 | H24: =K23 -> 12099.449 | I24: 0 | J24: 2000 | K24: =H24+I24-J24-Cement!Q24 -> 10061.649 | L24: =P23 -> 618.18 | M24: 0 | N24: =O24+'RAW MILL 2'!D24 -> 15 | O24: 14 | P24: =L24+M24-N24 -> 603.18 | Q24: =U23 -> 549.04 | R24: 0 | S24: =T24+'RAW MILL 2'!E24 -> 36 | T24: 33 | U24: =Q24+R24-S24 -> 513.04 | V24: =Y23 -> 0 | W24: 0 | X24: 0 | Y24: =V24+W24-X24 -> 0 | Z24: =AC23 -> 0 | AA24: 0 | AB24: 0 | AC24: =Z24+AA24-AB24 -> 0 | AD24: =AG23 -> 0 | AE24: 0 | AF24: 0 | AG24: =AD24+AE24-AF24 -> 0 | AH24: =D24+I24+M24+R24+W24+AA24+Cement!P24+Cement!T24+AE24 -> 1054.56 | AI24: =E24+J24+N24+S24+X24+AB24+Clinker!E24+AF24 -> 2523 | AJ24: =Production2!N24 -> 2099 | AK24: =AJ24-AI24 -> -424 | AM24: =E24/AJ24 -> 0.19961887 | AN24: =J24/AJ24 -> 0.95283468 | AO24: =N24/AJ24 -> 0.0071462601 | AP24: =S24/AJ24 -> 0.017151024 | AQ24: =D24+I24+M24+R24+Cement!P24 -> 1054.56 | AR24: =AI24+Cement!Q24-Clinker!E24 -> 2507.8 | AT24: =AI24-Production2!N24 -> 424 | AU24: =AI24 -> 2523 | AV24: =E24+J24 -> 2419 | AW24: =AS24-D24 -> -1054.56 | AX24: =I24-AY24 -> 0 | AY24: 0 | AZ24: =(AI24-Production2!N24)/'Mines (2)'!AI24 -> 0.1680539 | BA24: =AZ24*100 -> 16.80539
B25: 23 | C25: =G24 -> 8789.2832 | D25: 2007.16 | E25: =F25+'RAW MILL 2'!C25 -> 1013 | F25: 895 | G25: =C25+D25-E25 -> 9783.4432 | H25: =K24 -> 10061.649 | I25: 0 | J25: 1000 | K25: =H25+I25-J25-Cement!Q25 -> 9023.0685 | L25: =P24 -> 603.18 | M25: 196.2 | N25: =O25+'RAW MILL 2'!D25 -> 90 | O25: 85 | P25: =L25+M25-N25 -> 709.38 | Q25: =U24 -> 513.04 | R25: 0 | S25: =T25+'RAW MILL 2'!E25 -> 88 | T25: 83 | U25: =Q25+R25-S25 -> 425.04 | V25: =Y24 -> 0 | W25: 0 | X25: 0 | Y25: =V25+W25-X25 -> 0 | Z25: =AC24 -> 0 | AA25: 0 | AB25: 0 | AC25: =Z25+AA25-AB25 -> 0 | AD25: =AG24 -> 0 | AE25: 0 | AF25: 0 | AG25: =AD25+AE25-AF25 -> 0 | AH25: =D25+I25+M25+R25+W25+AA25+Cement!P25+Cement!T25+AE25 -> 2203.36 | AI25: =E25+J25+N25+S25+X25+AB25+Clinker!E25+AF25 -> 2259 | AJ25: =Production2!N25 -> 1915 | AK25: =AJ25-AI25 -> -344 | AM25: =E25/AJ25 -> 0.52898172 | AN25: =J25/AJ25 -> 0.52219321 | AO25: =N25/AJ25 -> 0.046997389 | AP25: =S25/AJ25 -> 0.045953003 | AQ25: =D25+I25+M25+R25+Cement!P25 -> 2203.36 | AR25: =AI25+Cement!Q25-Clinker!E25 -> 2229.58 | AT25: =AI25-Production2!N25 -> 344 | AU25: =AI25 -> 2259 | AV25: =E25+J25 -> 2013 | AW25: =AS25-D25 -> -2007.16 | AX25: =I25-AY25 -> 0 | AY25: 0 | AZ25: =(AI25-Production2!N25)/'Mines (2)'!AI25 -> 0.15227977 | BA25: =AZ25*100 -> 15.227977
B26: 24 | C26: =G25 -> 9783.4432 | D26: 2244.14 | E26: =F26+'RAW MILL 2'!C26 -> 375 | F26: 319 | G26: =C26+D26-E26 -> 11652.583 | H26: =K25 -> 9023.0685 | I26: 990.24 | J26: 2000 | K26: =H26+I26-J26-Cement!Q26 -> 7854.9085 | L26: =P25 -> 709.38 | M26: 253.46 | N26: =O26+'RAW MILL 2'!D26 -> 16 | O26: 15 | P26: =L26+M26-N26 -> 946.84 | Q26: =U25 -> 425.04 | R26: 0 | S26: =T26+'RAW MILL 2'!E26 -> 35 | T26: 34 | U26: =Q26+R26-S26 -> 390.04 | V26: =Y25 -> 0 | W26: 0 | X26: 0 | Y26: =V26+W26-X26 -> 0 | Z26: =AC25 -> 0 | AA26: 0 | AB26: 0 | AC26: =Z26+AA26-AB26 -> 0 | AD26: =AG25 -> 0 | AE26: 0 | AF26: 0 | AG26: =AD26+AE26-AF26 -> 0 | AH26: =D26+I26+M26+R26+W26+AA26+Cement!P26+Cement!T26+AE26 -> 3487.84 | AI26: =E26+J26+N26+S26+X26+AB26+Clinker!E26+AF26 -> 2478 | AJ26: =Production2!N26 -> 2177 | AK26: =AJ26-AI26 -> -301 | AM26: =E26/AJ26 -> 0.1722554 | AN26: =J26/AJ26 -> 0.91869545 | AO26: =N26/AJ26 -> 0.0073495636 | AP26: =S26/AJ26 -> 0.01607717 | AQ26: =D26+I26+M26+R26+Cement!P26 -> 3487.84 | AR26: =AI26+Cement!Q26-Clinker!E26 -> 2584.4 | AT26: =AI26-Production2!N26 -> 301 | AU26: =AI26 -> 2478 | AV26: =E26+J26 -> 2375 | AW26: =AS26-D26 -> -2244.14 | AX26: =D26-AY26 -> 2244.14 | AY26: 0 | AZ26: =(AI26-Production2!N26)/'Mines (2)'!AI26 -> 0.12146893 | BA26: =AZ26*100 -> 12.146893
B27: 25 | C27: =G26 -> 11652.583 | D27: 1926.2 | E27: =F27+'RAW MILL 2'!C27 -> 356 | F27: 356 | G27: =C27+D27-E27 -> 13222.783 | H27: =K26 -> 7854.9085 | I27: 1783.74 | J27: 2000 | K27: =H27+I27-J27-Cement!Q27 -> 7405.6485 | L27: =P26 -> 946.84 | M27: 307.66 | N27: =O27+'RAW MILL 2'!D27 -> 15 | O27: 15 | P27: =L27+M27-N27 -> 1239.5 | Q27: =U26 -> 390.04 | R27: 0 | S27: =T27+'RAW MILL 2'!E27 -> 34 | T27: 34 | U27: =Q27+R27-S27 -> 356.04 | V27: =Y26 -> 0 | W27: 0 | X27: 0 | Y27: =V27+W27-X27 -> 0 | Z27: =AC26 -> 0 | AA27: 0 | AB27: 0 | AC27: =Z27+AA27-AB27 -> 0 | AD27: =AG26 -> 0 | AE27: 0 | AF27: 0 | AG27: =AD27+AE27-AF27 -> 0 | AH27: =D27+I27+M27+R27+W27+AA27+Cement!P27+Cement!T27+AE27 -> 4017.6 | AI27: =E27+J27+N27+S27+X27+AB27+Clinker!E27+AF27 -> 2457 | AJ27: =Production2!N27 -> 2212.86 | AK27: =AJ27-AI27 -> -244.14 | AM27: =E27/AJ27 -> 0.16087778 | AN27: =J27/AJ27 -> 0.90380774 | AO27: =N27/AJ27 -> 0.0067785581 | AP27: =S27/AJ27 -> 0.015364732 | AQ27: =D27+I27+M27+R27+Cement!P27 -> 4017.6 | AR27: =AI27+Cement!Q27-Clinker!E27 -> 2638 | AT27: =AI27-Production2!N27 -> 244.14 | AU27: =AI27 -> 2457 | AV27: 25 | AY27: 0 | AZ27: =(AI27-Production2!N27)/'Mines (2)'!AI27 -> 0.099365079 | BA27: =AZ27*100 -> 9.9365079
B28: 26 | C28: =G27 -> 13222.783 | D28: 2946.46 | E28: =F28+'RAW MILL 2'!C28 -> 634 | F28: 511 | G28: =C28+D28-E28 -> 15535.243 | H28: =K27 -> 7405.6485 | I28: 144.54 | J28: 2000 | K28: =H28+I28-J28-Cement!Q28 -> 5191.4385 | L28: =P27 -> 1239.5 | M28: 0 | N28: =O28+'RAW MILL 2'!D28 -> 27 | O28: 26 | P28: =L28+M28-N28 -> 1212.5 | Q28: =U27 -> 356.04 | R28: 0 | S28: =T28+'RAW MILL 2'!E28 -> 8 | T28: 8 | U28: =Q28+R28-S28 -> 348.04 | V28: =Y27 -> 0 | W28: 0 | X28: 0 | Y28: =V28+W28-X28 -> 0 | Z28: =AC27 -> 0 | AA28: 0 | AB28: 0 | AC28: =Z28+AA28-AB28 -> 0 | AD28: =AG27 -> 0 | AE28: 0 | AF28: 0 | AG28: =AD28+AE28-AF28 -> 0 | AH28: =D28+I28+M28+R28+W28+AA28+Cement!P28+Cement!T28+AE28 -> 3091 | AI28: =E28+J28+N28+S28+X28+AB28+Clinker!E28+AF28 -> 2710 | AJ28: =Production2!N28 -> 2325 | AK28: =AJ28-AI28 -> -385 | AM28: =E28/AJ28 -> 0.27268817 | AN28: =J28/AJ28 -> 0.86021505 | AO28: =N28/AJ28 -> 0.011612903 | AP28: =S28/AJ28 -> 0.0034408602 | AQ28: =D28+I28+M28+R28+Cement!P28 -> 3091 | AR28: =AI28+Cement!Q28-Clinker!E28 -> 3027.75 | AT28: =AI28-Production2!N28 -> 385 | AU28: =AI28 -> 2710 | AV28: 26 | AY28: 0 | AZ28: =(AI28-Production2!N28)/'Mines (2)'!AI28 -> 0.14206642 | BA28: =AZ28*100 -> 14.206642
B29: 27 | C29: =G28 -> 15535.243 | D29: =2697.24+42.3 -> 2739.54 | E29: =F29+'RAW MILL 2'!C29 -> 2871 | F29: 2665 | G29: =C29+D29-E29 -> 15403.783 | H29: =K28 -> 5191.4385 | I29: 1086.28 | J29: 0 | K29: =H29+I29-J29-Cement!Q29 -> 5975.1685 | L29: =P28 -> 1212.5 | M29: 0 | N29: =O29+'RAW MILL 2'!D29 -> 12 | O29: 11 | P29: =L29+M29-N29 -> 1200.5 | Q29: =U28 -> 348.04 | R29: 0 | S29: =T29+'RAW MILL 2'!E29 -> 12 | T29: 11 | U29: =Q29+R29-S29 -> 336.04 | V29: =Y28 -> 0 | W29: 0 | X29: 0 | Y29: =V29+W29-X29 -> 0 | Z29: =AC28 -> 0 | AA29: 0 | AB29: 0 | AC29: =Z29+AA29-AB29 -> 0 | AD29: =AG28 -> 0 | AE29: 0 | AF29: 0 | AG29: =AD29+AE29-AF29 -> 0 | AH29: =D29+I29+M29+R29+W29+AA29+Cement!P29+Cement!T29+AE29 -> 3825.82 | AI29: =E29+J29+N29+S29+X29+AB29+Clinker!E29+AF29 -> 2954 | AJ29: =Production2!N29 -> 2468 | AK29: =AJ29-AI29 -> -486 | AM29: =E29/AJ29 -> 1.1632901 | AN29: =J29/AJ29 -> 0 | AO29: =N29/AJ29 -> 0.0048622366 | AP29: =S29/AJ29 -> 0.0048622366 | AR29: =AI29+Cement!Q29-Clinker!E29 -> 3197.55 | AT29: =AI29-Production2!N29 -> 486 | AU29: =AI29 -> 2954 | AV29: 27 | AY29: 0 | AZ29: =(AI29-Production2!N29)/'Mines (2)'!AI29 -> 0.16452268 | BA29: =AZ29*100 -> 16.452268
B30: 28 | C30: =G29 -> 15403.783 | D30: 0 | E30: =F30+'RAW MILL 2'!C30 -> 2779 | F30: 2620 | G30: =C30+D30-E30 -> 12624.783 | H30: =K29 -> 5975.1685 | I30: 0 | J30: 0 | K30: =H30+I30-J30-Cement!Q30 -> 5810.4685 | L30: =P29 -> 1200.5 | M30: 0 | N30: =O30+'RAW MILL 2'!D30 -> 66 | O30: 62 | P30: =L30+M30-N30 -> 1134.5 | Q30: =U29 -> 336.04 | R30: 0 | S30: =T30+'RAW MILL 2'!E30 -> 23 | T30: 22 | U30: =Q30+R30-S30 -> 313.04 | V30: =Y29 -> 0 | W30: 0 | X30: 0 | Y30: =V30+W30-X30 -> 0 | Z30: =AC29 -> 0 | AA30: 0 | AB30: 0 | AC30: =Z30+AA30-AB30 -> 0 | AD30: =AG29 -> 0 | AE30: 0 | AF30: 0 | AG30: =AD30+AE30-AF30 -> 0 | AH30: =D30+I30+M30+R30+W30+AA30+Cement!P30+Cement!T30+AE30 -> 0 | AI30: =E30+J30+N30+S30+X30+AB30+Clinker!E30+AF30 -> 2923 | AJ30: =Production2!N30 -> 2480 | AK30: =AJ30-AI30 -> -443 | AM30: =E30/AJ30 -> 1.1205645 | AN30: =J30/AJ30 -> 0 | AO30: =N30/AJ30 -> 0.026612903 | AP30: =S30/AJ30 -> 0.0092741935 | AR30: =AI30+Cement!Q30-Clinker!E30 -> 3032.7 | AT30: =AI30-Production2!N30 -> 443 | AU30: =AI30 -> 2923 | AV30: 28 | AY30: 0 | AZ30: =(AI30-Production2!N30)/'Mines (2)'!AI30 -> 0.15155662 | BA30: =AZ30*100 -> 15.155662
B31: 29 | C31: =G30 -> 12624.783 | D31: 0 | E31: =F31+'RAW MILL 2'!C31 -> 2702 | F31: 2499 | G31: =C31+D31-E31 -> 9922.7832 | H31: =K30 -> 5810.4685 | I31: 0 | J31: 0 | K31: =H31+I31-J31-Cement!Q31 -> 5536.5685 | L31: =P30 -> 1134.5 | M31: 0 | N31: =O31+'RAW MILL 2'!D31 -> 71 | O31: 65 | P31: =L31+M31-N31 -> 1063.5 | Q31: =U30 -> 313.04 | R31: 0 | S31: =T31+'RAW MILL 2'!E31 -> 67 | T31: 62 | U31: =Q31+R31-S31 -> 246.04 | V31: =Y30 -> 0 | W31: 0 | X31: 0 | Y31: =V31+W31-X31 -> 0 | Z31: =AC30 -> 0 | AA31: 0 | AB31: 0 | AC31: =Z31+AA31-AB31 -> 0 | AD31: =AG30 -> 0 | AE31: 0 | AF31: 0 | AG31: =AD31+AE31-AF31 -> 0 | AH31: =D31+I31+M31+R31+W31+AA31+Cement!P31+Cement!T31+AE31 -> 0 | AI31: =E31+J31+N31+S31+X31+AB31+Clinker!E31+AF31 -> 2907 | AJ31: =Production2!N31 -> 2420 | AK31: =AJ31-AI31 -> -487 | AM31: =E31/AJ31 -> 1.1165289 | AN31: =J31/AJ31 -> 0 | AO31: =N31/AJ31 -> 0.029338843 | AP31: =S31/AJ31 -> 0.02768595 | AR31: =AI31+Cement!Q31-Clinker!E31 -> 3113.9 | AT31: =AI31-Production2!N31 -> 487 | AU31: =AI31 -> 2907 | AV31: 29 | AY31: 0 | AZ31: =(AI31-Production2!N31)/'Mines (2)'!AI31 -> 0.16752666 | BA31: =AZ31*100 -> 16.752666
B32: 30 | C32: =G31 -> 9922.7832 | D32: 0 | E32: =F32+'RAW MILL 2'!C32 -> 2650 | F32: 2468 | G32: =C32+D32-E32 -> 7272.7832 | H32: =K31 -> 5536.5685 | I32: 0 | J32: 0 | K32: =H32+I32-J32-Cement!Q32 -> 5298.9685 | L32: =P31 -> 1063.5 | M32: 0 | N32: =O32+'RAW MILL 2'!D32 -> 117 | O32: 107 | P32: =L32+M32-N32 -> 946.5 | Q32: =U31 -> 246.04 | R32: 0 | S32: =T32+'RAW MILL 2'!E32 -> 55 | T32: 54 | U32: =Q32+R32-S32 -> 191.04 | V32: =Y31 -> 0 | W32: 0 | X32: 0 | Y32: =V32+W32-X32 -> 0 | Z32: =AC31 -> 0 | AA32: 0 | AB32: 0 | AC32: =Z32+AA32-AB32 -> 0 | AD32: =AG31 -> 0 | AE32: 0 | AF32: 0 | AG32: =AD32+AE32-AF32 -> 0 | AH32: =D32+I32+M32+R32+W32+AA32+Cement!P32+Cement!T32+AE32 -> 0 | AI32: =E32+J32+N32+S32+X32+AB32+Clinker!E32+AF32 -> 2880 | AJ32: =Production2!N32 -> 2416 | AK32: =AJ32-AI32 -> -464 | AM32: =E32/AJ32 -> 1.0968543 | AN32: =J32/AJ32 -> 0 | AO32: =N32/AJ32 -> 0.048427152 | AP32: =S32/AJ32 -> 0.022764901 | AR32: =AI32+Cement!Q32-Clinker!E32 -> 3059.6 | AT32: =AI32-Production2!N32 -> 464 | AU32: =AI32 -> 2880 | AV32: 30 | AY32: 0 | AZ32: =(AI32-Production2!N32)/'Mines (2)'!AI32 -> 0.16111111
B33: 31 | C33: =G32 -> 7272.7832 | D33: 0 | E33: =F33+'RAW MILL 2'!C33 -> 0 | F33: 0 | G33: =C33+D33-E33 -> 7272.7832 | H33: =K32 -> 5298.9685 | I33: 0 | J33: 0 | K33: =H33+I33-J33-Cement!Q33 -> 5298.9685 | L33: =P32 -> 946.5 | M33: 0 | N33: =O33+'RAW MILL 2'!D33 -> 0 | O33: 0 | P33: =L33+M33-N33 -> 946.5 | Q33: =U32 -> 191.04 | R33: 0 | S33: =T33+'RAW MILL 2'!E33 -> 0 | T33: 0 | U33: =Q33+R33-S33 -> 191.04 | V33: =Y32 -> 0 | W33: 0 | X33: 0 | Y33: =V33+W33-X33 -> 0 | Z33: =AC32 -> 0 | AA33: 0 | AB33: 0 | AC33: =Z33+AA33-AB33 -> 0 | AD33: =AG32 -> 0 | AE33: 0 | AF33: 0 | AG33: =AD33+AE33-AF33 -> 0 | AH33: =D33+I33+M33+R33+W33+AA33+Cement!P33+Cement!T33+AE33 -> 0 | AI33: =E33+J33+N33+S33+X33+AB33+Clinker!E33+AF33 -> 0 | AT33: =AI33-Production2!N33 -> 0
B34: MTD | D34: =SUM(D3:D33) -> 32065.72 | E34: =SUM(E3:E33) -> 34299 | I34: =SUM(I3:I33) -> 32919.98 | J34: =SUM(J3:J33) -> 32588 | M34: =SUM(M3:M33) -> 1351.46 | N34: =SUM(N3:N33) -> 529 | O34: =SUM(O3:O33) -> 492 | R34: =SUM(R3:R33) -> 137.76 | S34: =SUM(S3:S33) -> 547 | T34: =SUM(T3:T33) -> 517 | U34: =SUM(U3:U33) -> 15093.12 | V34: =SUM(V3:V33) -> 0 | W34: =SUM(W3:W33) -> 0 | X34: =SUM(X3:X33) -> 0 | Y34: =SUM(Y3:Y33) -> 0 | ... AG34: =SUM(AG3:AG33) -> 0 | AI34: =SUM(AI3:AI33) -> 69400
B35: YTD | D35: =D36+SUM(D3:D33) -> 32065.72 | E35: =E36+SUM(E3:E33) -> 34299 | I35: =I36+SUM(I3:I33) -> 32919.98 | J35: =J36+SUM(J3:J33) -> 32588 | M35: =M36+SUM(M3:M33) -> 1351.46 | N35: =N36+SUM(N3:N33) -> 529 | O35: =O36+SUM(O3:O33) -> 492 | R35: =R36+SUM(R3:R33) -> 137.76 | S35: =S36+SUM(S3:S33) -> 547 | T35: =T36+SUM(T3:T33) -> 517 | W35: =W36+SUM(W3:W33) -> 0 | X35: =X36+SUM(X3:X33) -> 0 | AA35: =AA36+SUM(AA3:AA33) -> 0 | AB35: =AB36+SUM(AB3:AB33) -> 0 | AE35: =AE36+SUM(AE3:AE33) -> 0 | AF35: =AF36+SUM(AF3:AF33) -> 0
B36: YTD | D36: 0 | E36: 0 | I36: 0 | J36: 0 | M36: 0 | N36: 0 | O36: 0 | R36: 0 | S36: 0 | T36: 0 | W36: 0 | X36: 0 | AA36: 0 | AB36: 0 | AE36: 0 | AF36: 0 | AN36: =G33+G33 -> 14545.566
I39: =D36+I36+W36+AA36+Cement!P36+Cement!T36 -> 0 | J39: =E36+J36+X36+AB36+Cement!Q36+Cement!U36 -> 0 | Q39: 3103 | R39: 3286 | S39: 2899 | T39: 2899 | U39: 3290 | V39: 3245 | W39: 3139 | X39: 1732 | Y39: 1959 | Z39: 3119 | AA39: 3017 | AB39: 3256 | AC39: 3209 | AD39: 3075 | AE39: 2456 | AF39: 2956 | AG39: 3022 | AH39: 2379 | AI39: 3157 | AJ39: 2838 | AK39: 3051 | AL39: 2232

Sheet Clinker
B1: DEC | C1: Iron Ore | H1: Raw Meal | L1: Tan Coal | R1: EDENVILLEY coal | X1: RUVUMA coal | AC1: GODMWANGA coal | AG1: STAMICO coal | AK1: Ash Coal | AO1: Ariim Coal | AT1: Lik & Lambert coal | AY1: JITEGEMEE | BD1: MAX COAL | BI1: SINO COAL | BN1: Ibrico | BS1: MEGA CJ | BX1: MABENGA COAL | CC1: TENCO | CH1: Scolastica | CM1: Connect | CR1: Yongda | CW1: Kindaini | DB1: MONTREAL | DG1: ludewa | DL1: MCHEKANE | DQ1: MARKET | DV1: SIAAS | EA1: KILN COAL | EE1: cpp coal | EI1: Clinker | EO1: Spg TRACKING
B2: Date | C2: Opening Stock | D2: Production | E2: Consumption/RM1 | G2: Closing Stock | H2: Opening Stock | I2: Production | J2: total Consumption | K2: Closing Stock | L2: Opening Stock | M2: Production | N2: CPP | O2: KILN | P2: Consumption | Q2: Closing Stock | R2: Opening Stock | S2: Production | T2: Consumption CPP | U2: Consump Kiln | V2: Total Consumption | W2: Closing Stock | X2: Opening Stock | Y2: Production | Z2: CPP | AA2: Consumption | AB2: Closing Stock | AC2: Opening Stock | AD2: Production | AE2: Consumption | AF2: Closing Stock | AG2: Opening Stock | AH2: Production | AI2: Consumption | AJ2: Closing Stock | AK2: Opening Stock | AL2: Production | AM2: Consumption | AN2: Closing Stock | AO2: Opening Stock | AP2: Production | AQ2: Consumption | AR2: CONS CPP | AS2: Closing Stock | AT2: Opening Stock | AU2: Production | AV2: Consumption | AW2: CONS CPP | AX2: Closing Stock | AY2: Opening Stock | AZ2: Production | BA2: Consumption | BB2: CONS CPP | BC2: Closing Stock | BD2: Opening Stock | BE2: Production | BF2: Consumption | BG2: CONS CPP | BH2: Closing Stock | BI2: Opening Stock | BJ2: Production | BK2: Consumption | BL2: CONS CPP | BM2: Closing Stock | BN2: Opening Stock | BO2: Production | BP2: Consumption | BQ2: CONS CPP | BR2: Closing Stock | BS2: Opening Stock | BT2: Production | BU2: Consumption | BV2: CONS CPP | BW2: Closing Stock | BX2: Opening Stock | BY2: Production | BZ2: Consumption | CA2: CONS CPP | CB2: Closing Stock | CC2: Opening Stock | CD2: Production | CE2: Consumption | CF2: CONS CPP | CG2: Closing Stock | CH2: Opening Stock | CI2: Production | CJ2: Consumption | CK2: CONS CPP | CL2: Closing Stock | CM2: Opening Stock | CN2: Production | CO2: Consumption | CP2: CONS CPP | CQ2: Closing Stock | CR2: Opening Stock | CS2: Production | CT2: Consumption | CU2: CONS CPP | CV2: Closing Stock | CW2: Opening Stock | CX2: Production | CY2: Consumption | CZ2: CONS CPP | DA2: Closing Stock | DB2: Opening Stock | DC2: Production | DD2: Consumption | DE2: CONS CPP | DF2: Closing Stock | DG2: Opening Stock | DH2: Production | DI2: Consumption | DJ2: CONS CPP | DK2: Closing Stock | DL2: Opening Stock | DM2: Production | DN2: Consumption | DO2: CONS CPP | DP2: Closing Stock | DQ2: Opening Stock | DR2: Production | DS2: Consumption | DT2: CONS CPP | DU2: Closing Stock | DV2: Opening Stock | DW2: Production | DX2: Consumption | DY2: CONS CPP | DZ2: Closing Stock | EA2: Closing Stock | EB2: Production | EC2: Consumption | ED2: Closing Stock | EE2: Opening Stock | EF2: Production | EG2: Consumption | EH2: Closing Stock | EI2: Opening Stock | EJ2: Production | EK2: Consumption | EL2: Closing Stock | EM2: clinker despatch | EN2: OP | EO2: CLINKER PURCHASED | EP2: CLINKER CONS | EQ2: CLOSING
B3: 1 | C3: =5364.45+1.19 -> 5365.64 | D3: 0 | E3: =F3+'RAW MILL 2'!F3 -> 0 | F3: 0 | G3: =C3+D3-E3 -> 5365.64 | H3: 1996 | I3: =Production2!N3 -> 0 | J3: =Production2!K3 -> 0 | K3: =H3+I3-J3 -> 1996 | L3: 0 | M3: 0 | N3: =CPP!D3 -> 0 | O3: 0 | P3: =N3+O3 -> 0 | Q3: =L3+M3-O3-N3 -> 0 | R3: 0 | S3: 0 | T3: =CPP!E3 -> 0 | U3: 0 | V3: =T3+U3 -> 0 | W3: =R3+S3-V3 -> 0 | X3: 10013.88 | Y3: 0 | Z3: =CPP!H3 -> 0 | AA3: 0 | AB3: =X3+Y3-AA3-Z3 -> 10013.88 | AC3: 0 | AD3: 0 | AE3: 0 | AF3: =AC3+AD3-AE3 -> 0 | AG3: 12785.6 | AH3: 33.35 | AI3: =CPP!G3 -> 22 | AJ3: =AG3+AH3-AI3 -> 12796.95 | AK3: 0 | AL3: 0 | AM3: 0 | AN3: =AK3+AL3-AM3 -> 0 | AO3: 0 | AP3: 0 | AQ3: 0 | AR3: =CPP!I3 -> 0 | AS3: =AO3+AP3-AQ3-AR3 -> 0 | AT3: 0 | AU3: 0 | AV3: 0 | AW3: =CPP!J3 -> 0 | AX3: =AT3+AU3-AV3-AW3 -> 0 | AY3: =0.296999999990248-0.01 -> 0.287 | AZ3: 0 | BA3: 0 | BB3: =CPP!K3 -> 0 | BC3: =AY3+AZ3-BA3-BB3 -> 0.287 | BD3: 0 | BE3: 0 | BF3: 0 | BG3: =CPP!L3 -> 0 | BH3: =BD3+BE3-BF3-BG3 -> 0 | BI3: 0 | BJ3: 0 | BK3: 0 | BL3: =CPP!M3 -> 0 | BM3: =BI3+BJ3-BK3-BL3 -> 0 | BN3: 0 | BO3: 0 | BP3: 0 | BQ3: =CPP!N3 -> 0 | BR3: =BN3+BO3-BP3-BQ3 -> 0 | BS3: 0 | BT3: 0 | BU3: 0 | BV3: =CPP!O3 -> 0 | BW3: =BS3+BT3-BU3-BV3 -> 0 | BX3: 0.01 | BY3: 0 | BZ3: 0 | CB3: 0 | CC3: 0 | CD3: 0 | CE3: 0 | CF3: =CPP!P3 -> 0 | CG3: =CC3+CD3-CE3-CF3 -> 0 | CH3: 0 | CI3: 0 | CJ3: 0 | CK3: =CPP!Q3 -> 0 | CL3: =CH3+CI3-CJ3-CK3 -> 0 | CM3: 0.05 | CN3: 0 | CO3: 0 | CP3: =CPP!R3 -> 0 | CQ3: =CM3+CN3-CO3-CP3 -> 0.05 | CR3: 0 | CS3: 0 | CT3: 0 | CU3: =CPP!S3 -> 0 | CV3: =CR3+CS3-CT3-CU3 -> 0 | CW3: 0 | CX3: 0 | CY3: 0 | CZ3: =CPP!T3 -> 0 | DA3: =CW3+CX3-CY3-CZ3 -> 0 | DB3: 306 | DC3: 0 | DD3: 0 | DE3: =CPP!U3 -> 0 | DF3: =DB3+DC3-DD3-DE3 -> 306 | DG3: 0 | DH3: 0 | DI3: 0 | DJ3: =CPP!V3 -> 0 | DK3: =DG3+DH3-DI3-DJ3 -> 0 | DL3: 0 | DM3: 0 | DN3: 0 | DO3: =CPP!W3 -> 0 | DP3: =DL3+DM3-DN3-DO3 -> 0 | DQ3: 5514.1 | DR3: 60 | DS3: 0 | DT3: =CPP!X3 -> 0 | DU3: =DQ3+DR3-DS3-DT3 -> 5574.1 | DV3: 0 | DW3: 0 | DX3: 0 | DY3: =CPP!Y3 -> 0 | DZ3: =DV3+DW3-DX3-DY3 -> 0 | EA3: =L3+AO3+AT3+AY3+BD3+BI3+BS3+BX3+CC3+CH3+CR3+CW3+DB3+DG3+DL3+DV3+X3+DQ3 -> 15834.277 | EB3: =M3+Y3+AL3+AP3+AU3+AZ3+BE3+BJ3+BO3+BT3+BY3+CS3+CX3+DC3+DH3+DM3+DW3+DR3 -> 60 | EC3: =O3+AA3+AM3+AQ3+AV3+BA3+BF3+BK3+BP3+BU3+BZ3+CT3+CY3+DD3+DI3+DN3+DX3+DS3 -> 0 | ED3: =EA3+EB3-EC3-N3-Z3-AR3-AW3-BB3-BG3-BL3-BQ3-BV3-CU3-CZ3-DE3-DJ3-DO3-DY3-DT3 -> 15894.277 | EE3: =R3+AC3+AG3+AK3+CM3 -> 12785.65 | EF3: =S3+AD3+AH3+CD3+CI3+CN3 -> 33.35 | EG3: =CPP!D3+CPP!E3+CPP!F3+CPP!G3+CPP!H3+CPP!I3+CPP!J3+CPP!K3+CPP!L3+CPP!M3+CPP!N3+CPP!O3+CPP!P3+CPP!Q3+CPP!R3+CPP!S3+CZ3+DE3+DJ3+CPP!W3+DT3 -> 22 | EH3: =EE3+EF3-CPP!G3-CPP!E3-CPP!F3-CPP!P3-CPP!Q3-CK3-CP3-DT3 -> 12797 | EI3: =3283.86009962673-2.32 -> 3281.5401 | EJ3: 0 | EK3: ='Daily CEM-1'!AG4+'Daily CEM - 2'!AF4-EP3 -> 0.049999832 | EL3: =EI3+EJ3-EK3-EM3 -> 3281.4901 | EM3: 0 | EN3: 8849.549 | EO3: 657.16 | EP3: 1857.1 | EQ3: =EN3+EO3-EP3 -> 7649.609 | ER3: =ES3-EO3 -> 1065.41 | ES3: 1722.57 | ET3: =EK3+EP3 -> 1857.15 | EU3: =EK3+EP3 -> 1857.15 | EV3: =EU3/Production2!CG3 -> 0.76363076 | EW3: #DIV/0! | EX3: =EW3*100 -> #DIV/0!
B4: 2 | C4: =G3 -> 5365.64 | D4: 0 | E4: =F4+'RAW MILL 2'!F4 -> 0 | F4: 0 | G4: =C4+D4-E4 -> 5365.64 | H4: =K3 -> 1996 | I4: =Production2!N4 -> 0 | J4: =Production2!K4 -> 0 | K4: =H4+I4-J4 -> 1996 | L4: =Q3 -> 0 | M4: 0 | N4: =CPP!D4 -> 0 | O4: 0 | P4: =N4+O4 -> 0 | Q4: =L4+M4-O4-N4 -> 0 | R4: =W3 -> 0 | S4: 0 | T4: =CPP!E4 -> 0 | U4: 0 | V4: =T4+U4 -> 0 | W4: =R4+S4-V4 -> 0 | X4: =AB3 -> 10013.88 | Y4: 0 | Z4: =CPP!H4 -> 0 | AA4: 0 | AB4: =X4+Y4-AA4-Z4 -> 10013.88 | AC4: =AF3 -> 0 | AD4: 0 | AE4: 0 | AF4: =AC4+AD4-AE4 -> 0 | AG4: =AJ3 -> 12796.95 | AH4: 61.7 | AI4: =CPP!G4 -> 138 | AJ4: =AG4+AH4-AI4 -> 12720.65 | AK4: =AN3 -> 0 | AL4: 0 | AM4: 0 | AN4: =AK4+AL4-AM4 -> 0 | AO4: =AS3 -> 0 | AP4: 0 | AQ4: 0 | AR4: =CPP!I4 -> 0 | AS4: =AO4+AP4-AQ4-AR4 -> 0 | AT4: =AX3 -> 0 | AU4: 0 | AV4: 0 | AW4: =CPP!J4 -> 0 | AX4: =AT4+AU4-AV4-AW4 -> 0 | AY4: =BC3 -> 0.287 | AZ4: 0 | BA4: 0 | BB4: =CPP!K4 -> 0 | BC4: =AY4+AZ4-BA4-BB4 -> 0.287 | BD4: =BH3 -> 0 | BE4: 0 | BF4: 0 | BG4: =CPP!L4 -> 0 | BH4: =BD4+BE4-BF4-BG4 -> 0 | BI4: =BM3 -> 0 | BJ4: 0 | BK4: 0 | BL4: =CPP!M4 -> 0 | BM4: =BI4+BJ4-BK4-BL4 -> 0 | BN4: =BR3 -> 0 | BO4: 0 | BP4: 0 | BQ4: =CPP!N4 -> 0 | BR4: =BN4+BO4-BP4-BQ4 -> 0 | BS4: =BW3 -> 0 | BT4: 0 | BU4: 0 | BV4: =CPP!O4 -> 0 | BW4: =BS4+BT4-BU4-BV4 -> 0 | BX4: =CB3 -> 0 | BY4: 0 | BZ4: 0 | CB4: =BX4+BY4-BZ4-CA4 -> 0 | CC4: =CG3 -> 0 | CD4: 0 | CE4: 0 | CF4: =CPP!P4 -> 0 | CG4: =CC4+CD4-CE4-CF4 -> 0 | CH4: =CL3 -> 0 | CI4: 0 | CJ4: 0 | CK4: =CPP!Q4 -> 0 | CL4: =CH4+CI4-CJ4-CK4 -> 0 | CM4: =CQ3 -> 0.05 | CN4: 0 | CO4: 0 | CP4: =CPP!R4 -> 0 | CQ4: =CM4+CN4-CO4-CP4 -> 0.05 | CR4: =CV3 -> 0 | CS4: 0 | CT4: 0 | CU4: =CPP!S4 -> 0 | CV4: =CR4+CS4-CT4-CU4 -> 0 | CW4: =DA3 -> 0 | CX4: 0 | CY4: 0 | CZ4: =CPP!T4 -> 0 | DA4: =CW4+CX4-CY4-CZ4 -> 0 | DB4: =DF3 -> 306 | DC4: 0 | DD4: 0 | DE4: =CPP!U4 -> 0 | DF4: =DB4+DC4-DD4-DE4 -> 306 | DG4: =DK3 -> 0 | DH4: 0 | DI4: 0 | DJ4: =CPP!V4 -> 0 | DK4: =DG4+DH4-DI4-DJ4 -> 0 | DL4: =DP3 -> 0 | DM4: 0 | DN4: 0 | DO4: =CPP!W4 -> 0 | DP4: =DL4+DM4-DN4-DO4 -> 0 | DQ4: =DU3 -> 5574.1 | DR4: 60.5 | DS4: 11.11 | DT4: =CPP!X4 -> 0 | DU4: =DQ4+DR4-DS4-DT4 -> 5623.49 | DV4: =DZ3 -> 0 | DW4: 0 | DX4: 0 | DY4: =CPP!Y4 -> 0 | DZ4: =DV4+DW4-DX4-DY4 -> 0 | EA4: =L4+AO4+AT4+AY4+BD4+BI4+BS4+BX4+CC4+CH4+CR4+CW4+DB4+DG4+DL4+DV4+X4+DQ4 -> 15894.267 | EB4: =M4+Y4+AL4+AP4+AU4+AZ4+BE4+BJ4+BO4+BT4+BY4+CS4+CX4+DC4+DH4+DM4+DW4+DR4 -> 60.5 | EC4: =O4+AA4+AM4+AQ4+AV4+BA4+BF4+BK4+BP4+BU4+BZ4+CT4+CY4+DD4+DI4+DN4+DX4+DS4 -> 11.11 | ED4: =EA4+EB4-EC4-N4-Z4-AR4-AW4-BB4-BG4-BL4-BQ4-BV4-CU4-CZ4-DE4-DJ4-DO4-DY4-DT4 -> 15943.657 | EE4: =R4+AC4+AG4+AK4+CM4 -> 12797 | EF4: =S4+AD4+AH4+CD4+CI4+CN4 -> 61.7 | EG4: =CPP!D4+CPP!E4+CPP!F4+CPP!G4+CPP!H4+CPP!I4+CPP!J4+CPP!K4+CPP!L4+CPP!M4+CPP!N4+CPP!O4+CPP!P4+CPP!Q4+CPP!R4+CPP!S4+CZ4+DE4+DJ4+CPP!W4+DT4 -> 138 | EH4: =EE4+EF4-CPP!G4-CPP!E4-CPP!F4-CPP!P4-CPP!Q4-CK4-CP4-DT4 -> 12720.7 | EI4: =EL3 -> 3281.4901 | EJ4: 0 | EK4: ='Daily CEM-1'!AG5+'Daily CEM - 2'!AF5-EP4 -> 2.6725002e-06 | EL4: =EI4+EJ4-EK4-EM4 -> 3281.4901 | EM4: 0 | EN4: =EQ3 -> 7649.609 | EO4: 1503.82 | EP4: 2110.2 | EQ4: =EN4+EO4-EP4 -> 7043.229 | ER4: =ES4-EO4 -> -332.72 | ES4: 1171.1 | ET4: =EK4+EP4 -> 2110.2 | EU4: =EK4+EP4 -> 2110.2 | EV4: =EU4/Production2!CG4 -> 0.77580882 | EW4: #DIV/0! | EX4: =EW4*100 -> #DIV/0!
B5: 3 | C5: =G4 -> 5365.64 | D5: 0 | E5: =F5+'RAW MILL 2'!F5 -> 10 | F5: 10 | G5: =C5+D5-E5 -> 5355.64 | H5: =K4 -> 1996 | I5: =Production2!N5 -> 448.5 | J5: =Production2!K5 -> 852.5 | K5: =H5+I5-J5 -> 1592 | L5: =Q4 -> 0 | M5: 0 | N5: =CPP!D5 -> 0 | O5: 0 | P5: =N5+O5 -> 0 | Q5: =L5+M5-O5-N5 -> 0 | R5: =W4 -> 0 | S5: 0 | T5: =CPP!E5 -> 0 | U5: 0 | V5: =T5+U5 -> 0 | W5: =R5+S5-V5 -> 0 | X5: =AB4 -> 10013.88 | Y5: 0 | Z5: =CPP!H5 -> 34 | AA5: 0 | AB5: =X5+Y5-AA5-Z5 -> 9979.88 | AC5: =AF4 -> 0 | AD5: 0 | AE5: 0 | AF5: =AC5+AD5-AE5 -> 0 | AG5: =AJ4 -> 12720.65 | AH5: 0 | AI5: =CPP!G5 -> 92 | AJ5: =AG5+AH5-AI5 -> 12628.65 | AK5: =AN4 -> 0 | AL5: 0 | AM5: 0 | AN5: =AK5+AL5-AM5 -> 0 | AO5: =AS4 -> 0 | AP5: 0 | AQ5: 0 | AR5: =CPP!I5 -> 0 | AS5: =AO5+AP5-AQ5-AR5 -> 0 | AT5: =AX4 -> 0 | AU5: 0 | AV5: 0 | AW5: =CPP!J5 -> 0 | AX5: =AT5+AU5-AV5-AW5 -> 0 | AY5: =BC4 -> 0.287 | AZ5: 0 | BA5: 0 | BB5: =CPP!K5 -> 0 | BC5: =AY5+AZ5-BA5-BB5 -> 0.287 | BD5: =BH4 -> 0 | BE5: 0 | BF5: 0 | BG5: =CPP!L5 -> 0 | BH5: =BD5+BE5-BF5-BG5 -> 0 | BI5: =BM4 -> 0 | BJ5: 0 | BK5: 0 | BL5: =CPP!M5 -> 0 | BM5: =BI5+BJ5-BK5-BL5 -> 0 | BN5: =BR4 -> 0 | BO5: 0 | BP5: 0 | BQ5: =CPP!N5 -> 0 | BR5: =BN5+BO5-BP5-BQ5 -> 0 | BS5: =BW4 -> 0 | BT5: 0 | BU5: 0 | BV5: =CPP!O5 -> 0 | BW5: =BS5+BT5-BU5-BV5 -> 0 | BX5: =CB4 -> 0 | BY5: 0 | BZ5: 0 | CB5: =BX5+BY5-BZ5-CA5 -> 0 | CC5: =CG4 -> 0 | CD5: 0 | CE5: 0 | CF5: =CPP!P5 -> 0 | CG5: =CC5+CD5-CE5-CF5 -> 0 | CH5: =CL4 -> 0 | CI5: 0 | CJ5: 0 | CK5: =CPP!Q5 -> 0 | CL5: =CH5+CI5-CJ5-CK5 -> 0 | CM5: =CQ4 -> 0.05 | CN5: 0 | CO5: 0 | CP5: =CPP!R5 -> 0 | CQ5: =CM5+CN5-CO5-CP5 -> 0.05 | CR5: =CV4 -> 0 | CS5: 0 | CT5: 0 | CU5: =CPP!S5 -> 0 | CV5: =CR5+CS5-CT5-CU5 -> 0 | CW5: =DA4 -> 0 | CX5: 0 | CY5: 0 | CZ5: =CPP!T5 -> 0 | DA5: =CW5+CX5-CY5-CZ5 -> 0 | DB5: =DF4 -> 306 | DC5: 0 | DD5: 0 | DE5: =CPP!U5 -> 0 | DF5: =DB5+DC5-DD5-DE5 -> 306 | DG5: =DK4 -> 0 | DH5: 0 | DI5: 0 | DJ5: =CPP!V5 -> 0 | DK5: =DG5+DH5-DI5-DJ5 -> 0 | DL5: =DP4 -> 0 | DM5: 0 | DN5: 0 | DO5: =CPP!W5 -> 0 | DP5: =DL5+DM5-DN5-DO5 -> 0 | DQ5: =DU4 -> 5623.49 | DR5: 0 | DS5: 133.33 | DT5: =CPP!X5 -> 0 | DU5: =DQ5+DR5-DS5-DT5 -> 5490.16 | DV5: =DZ4 -> 0 | DW5: 0 | DX5: 0 | DY5: =CPP!Y5 -> 0 | DZ5: =DV5+DW5-DX5-DY5 -> 0 | EA5: =L5+AO5+AT5+AY5+BD5+BI5+BS5+BX5+CC5+CH5+CR5+CW5+DB5+DG5+DL5+DV5+X5+DQ5 -> 15943.657 | EB5: =M5+Y5+AL5+AP5+AU5+AZ5+BE5+BJ5+BO5+BT5+BY5+CS5+CX5+DC5+DH5+DM5+DW5+DR5 -> 0 | EC5: =O5+AA5+AM5+AQ5+AV5+BA5+BF5+BK5+BP5+BU5+BZ5+CT5+CY5+DD5+DI5+DN5+DX5+DS5 -> 133.33 | ED5: =EA5+EB5-EC5-N5-Z5-AR5-AW5-BB5-BG5-BL5-BQ5-BV5-CU5-CZ5-DE5-DJ5-DO5-DY5-DT5 -> 15776.327 | EE5: =R5+AC5+AG5+AK5+CM5 -> 12720.7 | EF5: =S5+AD5+AH5+CD5+CI5+CN5 -> 0 | EG5: =CPP!D5+CPP!E5+CPP!F5+CPP!G5+CPP!H5+CPP!I5+CPP!J5+CPP!K5+CPP!L5+CPP!M5+CPP!N5+CPP!O5+CPP!P5+CPP!Q5+CPP!R5+CPP!S5+CZ5+DE5+DJ5+CPP!W5+DT5 -> 126 | EH5: =EE5+EF5-CPP!G5-CPP!E5-CPP!F5-CPP!P5-CPP!Q5-CK5-CP5-DT5 -> 12628.7 | EI5: =EL4 -> 3281.4901 | EJ5: 550 | EK5: ='Daily CEM-1'!AG6+'Daily CEM - 2'!AF6-EP5 -> 1.6124e-06 | EL5: =EI5+EJ5-EK5-EM5 -> 3831.4901 | EM5: 0 | EN5: =EQ4 -> 7043.229 | EO5: 0 | EP5: 1934.3 | EQ5: =EN5+EO5-EP5 -> 5108.929 | ER5: =ES5-EO5 -> 1446.55 | ES5: 1446.55 | ET5: =EK5+EP5 -> 1934.3 | EU5: =EK5+EP5 -> 1934.3 | EV5: =EU5/Production2!CG5 -> 0.77063745 | EW5: #DIV/0! | EX5: =EW5*100 -> #DIV/0!
B6: 4 | C6: =G5 -> 5355.64 | D6: 0 | E6: =F6+'RAW MILL 2'!F6 -> 23 | F6: 23 | G6: =C6+D6-E6 -> 5332.64 | H6: =K5 -> 1592 | I6: =Production2!N6 -> 1044.69 | J6: =Production2!K6 -> 1162.5 | K6: =H6+I6-J6 -> 1474.19 | L6: =Q5 -> 0 | M6: 0 | N6: =CPP!D6 -> 0 | O6: 0 | P6: =N6+O6 -> 0 | Q6: =L6+M6-O6-N6 -> 0 | R6: =W5 -> 0 | S6: 0 | T6: =CPP!E6 -> 0 | U6: 0 | V6: =T6+U6 -> 0 | W6: =R6+S6-V6 -> 0 | X6: =AB5 -> 9979.88 | Y6: 0 | Z6: =CPP!H6 -> 0 | AA6: 0 | AB6: =X6+Y6-AA6-Z6 -> 9979.88 | AC6: =AF5 -> 0 | AD6: 0 | AE6: 0 | AF6: =AC6+AD6-AE6 -> 0 | AG6: =AJ5 -> 12628.65 | AH6: 0 | AI6: =CPP!G6 -> 97 | AJ6: =AG6+AH6-AI6 -> 12531.65 | AK6: =AN5 -> 0 | AL6: 0 | AM6: 0 | AN6: =AK6+AL6-AM6 -> 0 | AO6: =AS5 -> 0 | AP6: 0 | AQ6: 0 | AR6: =CPP!I6 -> 0 | AS6: =AO6+AP6-AQ6-AR6 -> 0 | AT6: =AX5 -> 0 | AU6: 0 | AV6: 0 | AW6: =CPP!J6 -> 0 | AX6: =AT6+AU6-AV6-AW6 -> 0 | AY6: =BC5 -> 0.287 | AZ6: 0 | BA6: 0 | BB6: =CPP!K6 -> 0 | BC6: =AY6+AZ6-BA6-BB6 -> 0.287 | BD6: =BH5 -> 0 | BE6: 0 | BF6: 0 | BG6: =CPP!L6 -> 0 | BH6: =BD6+BE6-BF6-BG6 -> 0 | BI6: =BM5 -> 0 | BJ6: 0 | BK6: 0 | BL6: =CPP!M6 -> 0 | BM6: =BI6+BJ6-BK6-BL6 -> 0 | BN6: =BR5 -> 0 | BO6: 0 | BP6: 0 | BQ6: =CPP!N6 -> 0 | BR6: =BN6+BO6-BP6-BQ6 -> 0 | BS6: =BW5 -> 0 | BT6: 0 | BU6: 0 | BV6: =CPP!O6 -> 0 | BW6: =BS6+BT6-BU6-BV6 -> 0 | BX6: =CB5 -> 0 | BY6: 0 | BZ6: 0 | CB6: =BX6+BY6-BZ6-CA6 -> 0 | CC6: =CG5 -> 0 | CD6: 0 | CE6: 0 | CF6: =CPP!P6 -> 0 | CG6: =CC6+CD6-CE6-CF6 -> 0 | CH6: =CL5 -> 0 | CI6: 0 | CJ6: 0 | CK6: =CPP!Q6 -> 0 | CL6: =CH6+CI6-CJ6-CK6 -> 0 | CM6: =CQ5 -> 0.05 | CN6: 0 | CO6: 0 | CP6: =CPP!R6 -> 0 | CQ6: =CM6+CN6-CO6-CP6 -> 0.05 | CR6: =CV5 -> 0 | CS6: 0 | CT6: 0 | CU6: =CPP!S6 -> 0 | CV6: =CR6+CS6-CT6-CU6 -> 0 | CW6: =DA5 -> 0 | CX6: 0 | CY6: 0 | CZ6: =CPP!T6 -> 0 | DA6: =CW6+CX6-CY6-CZ6 -> 0 | DB6: =DF5 -> 306 | DC6: 0 | DD6: 0 | DE6: =CPP!U6 -> 0 | DF6: =DB6+DC6-DD6-DE6 -> 306 | DG6: =DK5 -> 0 | DH6: 0 | DI6: 0 | DJ6: =CPP!V6 -> 0 | DK6: =DG6+DH6-DI6-DJ6 -> 0 | DL6: =DP5 -> 0 | DM6: 0 | DN6: 0 | DO6: =CPP!W6 -> 0 | DP6: =DL6+DM6-DN6-DO6 -> 0 | DQ6: =DU5 -> 5490.16 | DR6: 31 | DS6: 137.78 | DT6: =CPP!X6 -> 0 | DU6: =DQ6+DR6-DS6-DT6 -> 5383.38 | DV6: =DZ5 -> 0 | DW6: 0 | DX6: 0 | DY6: =CPP!Y6 -> 0 | DZ6: =DV6+DW6-DX6-DY6 -> 0 | EA6: =L6+AO6+AT6+AY6+BD6+BI6+BS6+BX6+CC6+CH6+CR6+CW6+DB6+DG6+DL6+DV6+X6+DQ6 -> 15776.327 | EB6: =M6+Y6+AL6+AP6+AU6+AZ6+BE6+BJ6+BO6+BT6+BY6+CS6+CX6+DC6+DH6+DM6+DW6+DR6 -> 31 | EC6: =O6+AA6+AM6+AQ6+AV6+BA6+BF6+BK6+BP6+BU6+BZ6+CT6+CY6+DD6+DI6+DN6+DX6+DS6 -> 137.78 | ED6: =EA6+EB6-EC6-N6-Z6-AR6-AW6-BB6-BG6-BL6-BQ6-BV6-CU6-CZ6-DE6-DJ6-DO6-DY6-DT6 -> 15669.547 | EE6: =R6+AC6+AG6+AK6+CM6 -> 12628.7 | EF6: =S6+AD6+AH6+CD6+CI6+CN6 -> 0 | EG6: =CPP!D6+CPP!E6+CPP!F6+CPP!G6+CPP!H6+CPP!I6+CPP!J6+CPP!K6+CPP!L6+CPP!M6+CPP!N6+CPP!O6+CPP!P6+CPP!Q6+CPP!R6+CPP!S6+CZ6+DE6+DJ6+CPP!W6+DT6 -> 97 | EH6: =EE6+EF6-CPP!G6-CPP!E6-CPP!F6-CPP!P6-CPP!Q6-CK6-CP6-DT6 -> 12531.7 | EI6: =EL5 -> 3831.4901 | EJ6: 750 | EK6: ='Daily CEM-1'!AG7+'Daily CEM - 2'!AF7-EP6 -> 1.7293999e-06 | EL6: =EI6+EJ6-EK6-EM6 -> 4581.4901 | EM6: 0 | EN6: =EQ5 -> 5108.929 | EO6: 1617.32 | EP6: 1714.2 | EQ6: =EN6+EO6-EP6 -> 5012.049 | ER6: =ES6-EO6 -> -117.03 | ES6: 1500.29 | ET6: =EK6+EP6 -> 1714.2 | EU6: =EK6+EP6 -> 1714.2 | EV6: =EU6/Production2!CG6 -> 0.77008086 | EW6: 0.77 | EX6: =EW6*100 -> 77
B7: 5 | C7: =G6 -> 5332.64 | D7: 0 | E7: =F7+'RAW MILL 2'!F7 -> 0 | F7: 0 | G7: =C7+D7-E7 -> 5332.64 | H7: =K6 -> 1474.19 | I7: =Production2!N7 -> 0 | J7: =Production2!K7 -> 0 | K7: =H7+I7-J7 -> 1474.19 | L7: =Q6 -> 0 | M7: 0 | N7: =CPP!D7 -> 0 | O7: 0 | P7: =N7+O7 -> 0 | Q7: =L7+M7-O7-N7 -> 0 | R7: =W6 -> 0 | S7: 0 | T7: =CPP!E7 -> 0 | U7: 0 | V7: =T7+U7 -> 0 | W7: =R7+S7-V7 -> 0 | X7: =AB6 -> 9979.88 | Y7: 0 | Z7: =CPP!H7 -> 0 | AA7: 0 | AB7: =X7+Y7-AA7-Z7 -> 9979.88 | AC7: =AF6 -> 0 | AD7: 0 | AE7: 0 | AF7: =AC7+AD7-AE7 -> 0 | AG7: =AJ6 -> 12531.65 | AH7: 0 | AI7: =CPP!G7 -> 91 | AJ7: =AG7+AH7-AI7 -> 12440.65 | AK7: =AN6 -> 0 | AL7: 0 | AM7: 0 | AN7: =AK7+AL7-AM7 -> 0 | AO7: =AS6 -> 0 | AP7: 0 | AQ7: 0 | AR7: =CPP!I7 -> 0 | AS7: =AO7+AP7-AQ7-AR7 -> 0 | AT7: =AX6 -> 0 | AU7: 0 | AV7: 0 | AW7: =CPP!J7 -> 0 | AX7: =AT7+AU7-AV7-AW7 -> 0 | AY7: =BC6 -> 0.287 | AZ7: 0 | BA7: 0 | BB7: =CPP!K7 -> 0 | BC7: =AY7+AZ7-BA7-BB7 -> 0.287 | BD7: =BH6 -> 0 | BE7: 0 | BF7: 0 | BG7: =CPP!L7 -> 0 | BH7: =BD7+BE7-BF7-BG7 -> 0 | BI7: =BM6 -> 0 | BJ7: 0 | BK7: 0 | BL7: =CPP!M7 -> 0 | BM7: =BI7+BJ7-BK7-BL7 -> 0 | BN7: =BR6 -> 0 | BO7: 0 | BP7: 0 | BQ7: =CPP!N7 -> 0 | BR7: =BN7+BO7-BP7-BQ7 -> 0 | BS7: =BW6 -> 0 | BT7: 0 | BU7: 0 | BV7: =CPP!O7 -> 0 | BW7: =BS7+BT7-BU7-BV7 -> 0 | BX7: =CB6 -> 0 | BY7: 0 | BZ7: 0 | CB7: =BX7+BY7-BZ7-CA7 -> 0 | CC7: =CG6 -> 0 | CD7: 0 | CE7: 0 | CF7: =CPP!P7 -> 0 | CG7: =CC7+CD7-CE7-CF7 -> 0 | CH7: =CL6 -> 0 | CI7: 0 | CJ7: 0 | CK7: =CPP!Q7 -> 0 | CL7: =CH7+CI7-CJ7-CK7 -> 0 | CM7: =CQ6 -> 0.05 | CN7: 0 | CO7: 0 | CP7: =CPP!R7 -> 0 | CQ7: =CM7+CN7-CO7-CP7 -> 0.05 | CR7: =CV6 -> 0 | CS7: 0 | CT7: 0 | CU7: =CPP!S7 -> 0 | CV7: =CR7+CS7-CT7-CU7 -> 0 | CW7: =DA6 -> 0 | CX7: 0 | CY7: 0 | CZ7: =CPP!T7 -> 0 | DA7: =CW7+CX7-CY7-CZ7 -> 0 | DB7: =DF6 -> 306 | DC7: 0 | DD7: 0 | DE7: =CPP!U7 -> 0 | DF7: =DB7+DC7-DD7-DE7 -> 306 | DG7: =DK6 -> 0 | DH7: 0 | DI7: 0 | DJ7: =CPP!V7 -> 0 | DK7: =DG7+DH7-DI7-DJ7 -> 0 | DL7: =DP6 -> 0 | DM7: 0 | DN7: 0 | DO7: =CPP!W7 -> 0 | DP7: =DL7+DM7-DN7-DO7 -> 0 | DQ7: =DU6 -> 5383.38 | DR7: 0 | DS7: 0 | DT7: =CPP!X7 -> 0 | DU7: =DQ7+DR7-DS7-DT7 -> 5383.38 | DV7: =DZ6 -> 0 | DW7: 0 | DX7: 0 | DY7: =CPP!Y7 -> 0 | DZ7: =DV7+DW7-DX7-DY7 -> 0 | EA7: =L7+AO7+AT7+AY7+BD7+BI7+BS7+BX7+CC7+CH7+CR7+CW7+DB7+DG7+DL7+DV7+X7+DQ7 -> 15669.547 | EB7: =M7+Y7+AL7+AP7+AU7+AZ7+BE7+BJ7+BO7+BT7+BY7+CS7+CX7+DC7+DH7+DM7+DW7+DR7 -> 0 | EC7: =O7+AA7+AM7+AQ7+AV7+BA7+BF7+BK7+BP7+BU7+BZ7+CT7+CY7+DD7+DI7+DN7+DX7+DS7 -> 0 | ED7: =EA7+EB7-EC7-N7-Z7-AR7-AW7-BB7-BG7-BL7-BQ7-BV7-CU7-CZ7-DE7-DJ7-DO7-DY7-DT7 -> 15669.547 | EE7: =R7+AC7+AG7+AK7+CM7 -> 12531.7 | EF7: =S7+AD7+AH7+CD7+CI7+CN7 -> 0 | EG7: =CPP!D7+CPP!E7+CPP!F7+CPP!G7+CPP!H7+CPP!I7+CPP!J7+CPP!K7+CPP!L7+CPP!M7+CPP!N7+CPP!O7+CPP!P7+CPP!Q7+CPP!R7+CPP!S7+CZ7+DE7+DJ7+CPP!W7+DT7 -> 91 | EH7: =EE7+EF7-CPP!G7-CPP!E7-CPP!F7-CPP!P7-CPP!Q7-CK7-CP7-DT7 -> 12440.7 | EI7: =EL6 -> 4581.4901 | EJ7: 0 | EK7: ='Daily CEM-1'!AG8+'Daily CEM - 2'!AF8-EP7 -> 217.5 | EL7: =EI7+EJ7-EK7-EM7 -> 4363.9901 | EM7: 0 | EN7: =EQ6 -> 5012.049 | EO7: 0 | EP7: 1958.8 | EQ7: =EN7+EO7-EP7 -> 3053.249 | ER7: =ES7-EO7 -> 0 | ET7: =EK7+EP7 -> 2176.3 | EU7: =EK7+EP7 -> 2176.3 | EV7: =EU7/Production2!CG7 -> 0.74786942 | EW7: 0.78583916 | EX7: =EW7*100 -> 78.583916
