Workbook

Sheet Mines (2)
B1: MARCH | C1: HG LS | H1: LG LS | L1: Clay | Q1: Sand | V1: TG | Z1: HGHMGO | AD1: PURCHASED LIMESTONE | AH1: Total
B2: Date | C2: Opening Stock | D2: Production | E2: Total Consumption | F2: CONS R/M1 | G2: Closing Stock | H2: Opening Stock | I2: Production | J2: Consumption | K2: Closing Stock | L2: Opening Stock | M2: Production | N2: TOTAL Consumption | O2: Cons R/M1 | P2: Closing Stock | Q2: Opening Stock | R2: Production | S2: TOTALConsumption | T2: Cons R/M1 | U2: Closing Stock | V2: Opening Stock | W2: Production | X2: Consumption | Y2: Closing Stock | Z2: Opening Stock | AA2: Production | AB2: Consumption | AC2: Closing Stock | AD2: Opening Stock | AE2: Production | AF2: Consumption | AG2: Closing Stock | AH2: P | AI2: C | AJ2: Raw meal | AK2: diff | AL2: LG | AR2: MINES CONS | AS2: MINES RECEIPT
B3: 1 | C3: 7272.7832 | D3: 6632.02 | E3: =F3+'RAW MILL 2'!C3 -> 36 | F3: 36 | G3: =C3+D3-E3 -> 13868.803 | H3: 5298.9685 | I3: 2996.2 | J3: 200 | K3: =H3+I3-J3-Cement!S3 -> 7877.1685 | L3: 946.5 | M3: 832.26 | N3: =O3+'RAW MILL 2'!D3 -> 1 | O3: 1 | P3: =L3+M3-N3 -> 1777.76 | Q3: 191.04 | R3: 0 | S3: =T3+'RAW MILL 2'!E3 -> 13 | T3: 13 | U3: =Q3+R3-S3 -> 178.04 | V3: 0 | W3: 0 | X3: 0 | Y3: =V3+W3-X3 -> 0 | Z3: 0 | AA3: 0 | AB3: 0 | AC3: =Z3+AA3-AB3 -> 0 | AD3: 0 | AE3: 0 | AF3: 0 | AG3: =AD3+AE3-AF3 -> 0 | AH3: =D3+I3+M3+R3+W3+AA3+Cement!Q3+Cement!V3+AE3 -> 10460.48 | AI3: =E3+J3+N3+S3+X3+AB3+Clinker!E3+AF3 -> 255 | AJ3: =Production2!N3 -> 229.65 | AL3: 3103 | AQ3: =D3+I3+M3+R3+Cement!Q3 -> 10460.48 | AR3: =AI3+Cement!R3-Clinker!E3 -> 468 | AS3: 940.1 | AT3: =AI3-Production2!N3 -> 25.35 | AU3: =AI3 -> 255 | AV3: =E3+J3 -> 236 | AW3: =AS3-D3 -> -5691.92 | AX3: =I3-AY3 -> 1376.7 | AY3: 1619.5 | AZ3: =(AI3-Production2!N3)/'Mines (2)'!AI3 -> 0.099411765 | BA3: =AZ3*100 -> 9.9411765 | BB3: =E3+J3+AB3 -> 236
B4: 2 | C4: =G3 -> 13868.803 | D4: 368.46 | E4: =F4+'RAW MILL 2'!C4 -> 734 | F4: 604 | G4: =C4+D4-E4 -> 13503.263 | H4: =K3 -> 7877.1685 | I4: 161.42 | J4: 2000 | K4: =H4+I4-J4-Cement!S4 -> 5791.5885 | L4: =P3 -> 1777.76 | M4: 291.42 | N4: =O4+'RAW MILL 2'!D4 -> 148 | O4: 141 | P4: =L4+M4-N4 -> 1921.18 | Q4: =U3 -> 178.04 | R4: 0 | S4: =T4+'RAW MILL 2'!E4 -> 15 | T4: 14 | U4: =Q4+R4-S4 -> 163.04 | V4: =Y3 -> 0 | W4: 0 | X4: 0 | Y4: =V4+W4-X4 -> 0 | Z4: =AC3 -> 0 | AA4: 0 | AB4: 0 | AC4: =Z4+AA4-AB4 -> 0 | AD4: =AG3 -> 0 | AE4: 0 | AF4: 0 | AG4: =AD4+AE4-AF4 -> 0 | AH4: =D4+I4+M4+R4+W4+AA4+Cement!Q4+Cement!V4+AE4 -> 821.3 | AI4: =E4+J4+N4+S4+X4+AB4+Clinker!E4+AF4 -> 2957 | AJ4: =Production2!N4 -> 2535 | AK4: =AJ4-AI4 -> -422 | AL4: 3286 | AQ4: =D4+I4+M4+R4+Cement!Q4 -> 821.3 | AR4: =AI4+Cement!R4-Clinker!E4 -> 3144 | AS4: 987.54 | AT4: =AI4-Production2!N4 -> 422 | AU4: =AI4 -> 2957 | AV4: =E4+J4 -> 2734 | AW4: =AS4-D4 -> 619.08 | AX4: =I4-AY4 -> -461.86 | AY4: 623.28 | AZ4: =(AI4-Production2!N4)/'Mines (2)'!AI4 -> 0.14271221 | BA4: =AZ4*100 -> 14.271221 | BB4: =E4+J4+AB4 -> 2734
B5: 3 | C5: =G4 -> 13503.263 | D5: 1465.02 | E5: =F5+'RAW MILL 2'!C5 -> 2540 | F5: 2352 | G5: =C5+D5-E5 -> 12428.283 | H5: =K4 -> 5791.5885 | I5: 1261.98 | J5: 0 | K5: =H5+I5-J5-Cement!S5 -> 7011.0685 | L5: =P4 -> 1921.18 | M5: 348.68 | N5: =O5+'RAW MILL 2'!D5 -> 75 | O5: 69 | P5: =L5+M5-N5 -> 2194.86 | Q5: =U4 -> 163.04 | R5: 0 | S5: =T5+'RAW MILL 2'!E5 -> 13 | T5: 12 | U5: =Q5+R5-S5 -> 150.04 | V5: =Y4 -> 0 | W5: 0 | X5: 0 | Y5: =V5+W5-X5 -> 0 | Z5: =AC4 -> 0 | AA5: 0 | AB5: 0 | AC5: =Z5+AA5-AB5 -> 0 | AD5: =AG4 -> 0 | AE5: 0 | AF5: 0 | AG5: =AD5+AE5-AF5 -> 0 | AH5: =D5+I5+M5+R5+W5+AA5+Cement!Q5+Cement!V5+AE5 -> 3075.68 | AI5: =E5+J5+N5+S5+X5+AB5+Clinker!E5+AF5 -> 2682 | AJ5: =Production2!N5 -> 2235 | AK5: =AJ5-AI5 -> -447 | AL5: 2899 | AQ5: =D5+I5+M5+R5+Cement!Q5 -> 3075.68 | AR5: =AI5+Cement!R5-Clinker!E5 -> 2670.5 | AS5: 249.34 | AT5: =AI5-Production2!N5 -> 447 | AU5: =AI5 -> 2682 | AV5: =E5+J5 -> 2540 | AW5: =AS5-D5 -> -1215.68 | AX5: =I5-AY5 -> 819.48 | AY5: 442.5 | AZ5: =(AI5-Production2!N5)/'Mines (2)'!AI5 -> 0.16666667 | BA5: =AZ5*100 -> 16.666667 | BB5: =E5+J5+AB5 -> 2540
B6: 4 | C6: =G5 -> 12428.283 | D6: 711.34 | E6: =F6+'RAW MILL 2'!C6 -> 1874 | F6: 1773 | G6: =C6+D6-E6 -> 11265.623 | H6: =K5 -> 7011.0685 | I6: 1588.22 | J6: 0 | K6: =H6+I6-J6-Cement!S6 -> 8463.2885 | L6: =P5 -> 2194.86 | M6: 70.7 | N6: =O6+'RAW MILL 2'!D6 -> 40 | O6: 38 | P6: =L6+M6-N6 -> 2225.56 | Q6: =U5 -> 150.04 | R6: 0 | S6: =T6+'RAW MILL 2'!E6 -> 20 | T6: 19 | U6: =Q6+R6-S6 -> 130.04 | V6: =Y5 -> 0 | W6: 0 | X6: 0 | Y6: =V6+W6-X6 -> 0 | Z6: =AC5 -> 0 | AA6: 0 | AB6: 0 | AC6: =Z6+AA6-AB6 -> 0 | AD6: =AG5 -> 0 | AE6: 0 | AF6: 0 | AG6: =AD6+AE6-AF6 -> 0 | AH6: =D6+I6+M6+R6+W6+AA6+Cement!Q6+Cement!V6+AE6 -> 2370.26 | AI6: =E6+J6+N6+S6+X6+AB6+Clinker!E6+AF6 -> 1973 | AJ6: =Production2!N6 -> 1680 | AK6: =AJ6-AI6 -> -293 | AL6: 3290 | AQ6: =D6+I6+M6+R6+Cement!Q6 -> 2370.26 | AR6: =AI6+Cement!R6-Clinker!E6 -> 2070 | AS6: 1108.96 | AT6: =AI6-Production2!N6 -> 293 | AU6: =AI6 -> 1973 | AV6: =E6+J6 -> 1874 | AW6: =AS6-D6 -> 397.62 | AX6: =I6-AY6 -> -648.54 | AY6: 2236.76 | AZ6: =(AI6-Production2!N6)/'Mines (2)'!AI6 -> 0.14850482 | BA6: =AZ6*100 -> 14.850482 | BB6: =E6+J6+AB6 -> 1874
B7: 5 | C7: =G6 -> 11265.623 | D7: 2441.96 | E7: =F7+'RAW MILL 2'!C7 -> 1862 | F7: 1778 | G7: =C7+D7-E7 -> 11845.583 | H7: =K6 -> 8463.2885 | I7: 584.44 | J7: 0 | K7: =H7+I7-J7-Cement!S7 -> 8903.3285 | L7: =P6 -> 2225.56 | M7: 84.9 | N7: =O7+'RAW MILL 2'!D7 -> 47 | O7: 45 | P7: =L7+M7-N7 -> 2263.46 | Q7: =U6 -> 130.04 | R7: 0 | S7: =T7+'RAW MILL 2'!E7 -> 4 | T7: 4 | U7: =Q7+R7-S7 -> 126.04 | V7: =Y6 -> 0 | W7: 0 | X7: 0 | Y7: =V7+W7-X7 -> 0 | Z7: =AC6 -> 0 | AA7: 0 | AB7: 0 | AC7: =Z7+AA7-AB7 -> 0 | AD7: =AG6 -> 0 | AE7: 0 | AF7: 0 | AG7: =AD7+AE7-AF7 -> 0 | AH7: =D7+I7+M7+R7+W7+AA7+Cement!Q7+Cement!V7+AE7 -> 3111.3 | AI7: =E7+J7+N7+S7+X7+AB7+Clinker!E7+AF7 -> 1952 | AJ7: =Production2!N7 -> 1678 | AK7: =AJ7-AI7 -> -274 | AL7: 3245 | AQ7: =D7+I7+R7+Cement!Q7 -> 3026.4 | AR7: =AI7+Cement!R7-Clinker!E7 -> 2057.4 | AS7: 0 | AT7: =AI7-Production2!N7 -> 274 | AU7: =AI7 -> 1952 | AV7: =E7+J7 -> 1862 | AW7: =AS7-D7 -> -2441.96 | AX7: =I7-AY7 -> 584.44 | AY7: 0 | AZ7: =(AI7-Production2!N7)/'Mines (2)'!AI7 -> 0.14036885 | BA7: =AZ7*100 -> 14.036885 | BB7: =E7+J7+AB7 -> 1862
B8: 6 | C8: =G7 -> 11845.583 | D8: 1954.74 | E8: =F8+'RAW MILL 2'!C8 -> 2241 | F8: 2241 | G8: =C8+D8-E8 -> 11559.323 | H8: =K7 -> 8903.3285 | I8: 82.44 | J8: 0 | K8: =H8+I8-J8-Cement!S8 -> 8736.4385 | L8: =P7 -> 2263.46 | M8: 0 | N8: =O8+'RAW MILL 2'!D8 -> 60 | O8: 60 | P8: =L8+M8-N8 -> 2203.46 | Q8: =U7 -> 126.04 | R8: 0 | S8: =T8+'RAW MILL 2'!E8 -> 0 | T8: 0 | U8: =Q8+R8-S8 -> 126.04 | V8: =Y7 -> 0 | W8: 0 | X8: 0 | Y8: =V8+W8-X8 -> 0 | Z8: =AC7 -> 0 | AA8: 0 | AB8: 0 | AC8: =Z8+AA8-AB8 -> 0 | AD8: =AG7 -> 0 | AE8: 0 | AF8: 0 | AG8: =AD8+AE8-AF8 -> 0 | AH8: =D8+I8+M8+R8+W8+AA8+Cement!Q8+Cement!V8+AE8 -> 2037.18 | AI8: =E8+J8+N8+S8+X8+AB8+Clinker!E8+AF8 -> 2360 | AJ8: =Production2!N8 -> 2125.77 | AK8: =AJ8-AI8 -> -234.23 | AL8: 3139 | AQ8: =D8+I8+M8+R8+Cement!Q8 -> 2037.18 | AR8: =AI8+Cement!R8-Clinker!E8 -> 2550.33 | AS8: 1300 | AT8: =AI8-Production2!N8 -> 234.23 | AU8: =AI8 -> 2360 | AV8: =E8+J8 -> 2241 | AW8: =AS8-D8 -> -654.74 | AX8: =I8-AY8 -> -757.56 | AY8: 840 | AZ8: =(AI8-Production2!N8)/'Mines (2)'!AI8 -> 0.09925 | BA8: =AZ8*100 -> 9.925 | BB8: =E8+J8+AB8 -> 2241
B9: 7 | C9: =G8 -> 11559.323 | D9: 2109.64 | E9: =F9+'RAW MILL 2'!C9 -> 717 | F9: 717 | G9: =C9+D9-E9 -> 12951.963 | H9: =K8 -> 8736.4385 | I9: 406.4 | J9: 300 | K9: =H9+I9-J9-Cement!S9 -> 8644.0507 | L9: =P8 -> 2203.46 | M9: 0 | N9: =O9+'RAW MILL 2'!D9 -> 24 | O9: 24 | P9: =L9+M9-N9 -> 2179.46 | Q9: =U8 -> 126.04 | R9: 0 | S9: =T9+'RAW MILL 2'!E9 -> 25 | T9: 25 | U9: =Q9+R9-S9 -> 101.04 | V9: =Y8 -> 0 | W9: 0 | X9: 0 | Y9: =V9+W9-X9 -> 0 | Z9: =AC8 -> 0 | AA9: 0 | AB9: 0 | AC9: =Z9+AA9-AB9 -> 0 | AD9: =AG8 -> 0 | AE9: 0 | AF9: 0 | AG9: =AD9+AE9-AF9 -> 0 | AH9: =D9+I9+M9+R9+W9+AA9+Cement!Q9+Cement!V9+AE9 -> 2516.04 | AI9: =E9+J9+N9+S9+X9+AB9+Clinker!E9+AF9 -> 1088 | AJ9: =Production2!N9 -> 980.3 | AK9: =AJ9-AI9 -> -107.7 | AL9: 1732 | AQ9: =D9+I9+M9+R9+Cement!Q9 -> 2516.04 | AR9: =AI9+Cement!R9-Clinker!E9 -> 1244.9 | AS9: 480 | AT9: =AI9-Production2!N9 -> 107.7 | AU9: =AI9 -> 1088 | AV9: =E9+J9 -> 1017 | AW9: =AS9-D9 -> -1629.64 | AX9: =I9-AY9 -> -1773.6 | AY9: 2180 | AZ9: =(AI9-Production2!N9)/'Mines (2)'!AI9 -> 0.098988971 | BA9: =AZ9*100 -> 9.8988971 | BB9: =E9+J9+AB9 -> 1017
B10: 8 | C10: =G9 -> 12951.963 | D10: 1836.44 | E10: =F10+'RAW MILL 2'!C10 -> 1014 | F10: 1014 | G10: =C10+D10-E10 -> 13774.403 | H10: =K9 -> 8644.0507 | I10: 1422.66 | J10: 1000 | K10: =H10+I10-J10-Cement!S10 -> 8763.7207 | L10: =P9 -> 2179.46 | M10: 177.22 | N10: =O10+'RAW MILL 2'!D10 -> 47 | O10: 47 | P10: =L10+M10-N10 -> 2309.68 | Q10: =U9 -> 101.04 | R10: 0 | S10: =T10+'RAW MILL 2'!E10 -> 43 | T10: 43 | U10: =Q10+R10-S10 -> 58.04 | V10: =Y9 -> 0 | W10: 0 | X10: 0 | Y10: =V10+W10-X10 -> 0 | Z10: =AC9 -> 0 | AA10: 0 | AB10: 0 | AC10: =Z10+AA10-AB10 -> 0 | AD10: =AG9 -> 0 | AE10: 0 | AF10: 0 | AG10: =AD10+AE10-AF10 -> 0 | AH10: =D10+I10+M10+R10+W10+AA10+Cement!Q10+Cement!V10+AE10 -> 3436.32 | AI10: =E10+J10+N10+S10+X10+AB10+Clinker!E10+AF10 -> 2154 | AJ10: =Production2!N10 -> 1940.1 | AK10: =AJ10-AI10 -> -213.9 | AL10: 1959 | AQ10: =D10+I10+M10+R10+Cement!Q10 -> 3436.32 | AR10: =AI10+Cement!R10-Clinker!E10 -> 2376.691 | AS10: 1612.08 | AT10: =AI10-Production2!N10 -> 213.9 | AU10: =AI10 -> 2154 | AV10: =E10+J10 -> 2014 | AW10: =AS10-D10 -> -224.36 | AX10: =I10-AY10 -> 782.66 | AY10: 640 | AZ10: =(AI10-Production2!N10)/'Mines (2)'!AI10 -> 0.099303621 | BA10: =AZ10*100 -> 9.9303621 | BB10: =E10+J10+AB10 -> 2014
B11: 9 | C11: =G10 -> 13774.403 | D11: 922.72 | E11: =F11+'RAW MILL 2'!C11 -> 1697 | F11: 1697 | G11: =C11+D11-E11 -> 13000.123 | H11: =K10 -> 8763.7207 | I11: 1864.88 | J11: 0 | K11: =H11+I11-J11-Cement!S11 -> 10101.761 | L11: =P10 -> 2309.68 | M11: 73.24 | N11: =O11+'RAW MILL 2'!D11 -> 40 | O11: 40 | P11: =L11+M11-N11 -> 2342.92 | Q11: =U10 -> 58.04 | R11: 0 | S11: =T11+'RAW MILL 2'!E11 -> 36 | T11: 36 | U11: =Q11+R11-S11 -> 22.04 | V11: =Y10 -> 0 | W11: 0 | X11: 0 | Y11: =V11+W11-X11 -> 0 | Z11: =AC10 -> 0 | AA11: 0 | AB11: 0 | AC11: =Z11+AA11-AB11 -> 0 | AD11: =AG10 -> 0 | AE11: 0 | AF11: 0 | AG11: =AD11+AE11-AF11 -> 0 | AH11: =D11+I11+M11+R11+W11+AA11+Cement!Q11+Cement!V11+AE11 -> 2860.84 | AI11: =E11+J11+N11+S11+X11+AB11+Clinker!E11+AF11 -> 1815 | AJ11: =Production2!N11 -> 1634.76 | AK11: =AJ11-AI11 -> -180.24 | AL11: 3119 | AQ11: =D11+I11+M11+R11+Cement!Q11 -> 2860.84 | AR11: =AI11+Cement!R11-Clinker!E11 -> 2247.156 | AS11: 2277.26 | AT11: =AI11-Production2!N11 -> 180.24 | AU11: =AI11 -> 1815 | AV11: =E11+J11 -> 1697 | AW11: =AS11-D11 -> 1354.54 | AX11: =I11-AY11 -> 1247.1 | AY11: 617.78 | AZ11: =(AI11-Production2!N11)/'Mines (2)'!AI11 -> 0.099305785 | BA11: =AZ11*100 -> 9.9305785 | BB11: =E11+J11+AB11 -> 1697
B12: 10 | C12: =G11 -> 13000.123 | D12: 1666.44 | E12: =F12+'RAW MILL 2'!C12 -> 1861 | F12: 1861 | G12: =C12+D12-E12 -> 12805.563 | H12: =K11 -> 10101.761 | I12: 1090.48 | J12: 0 | K12: =H12+I12-J12-Cement!S12 -> 10855.041 | L12: =P11 -> 2342.92 | M12: 241.34 | N12: =O12+'RAW MILL 2'!D12 -> 73 | O12: 73 | P12: =L12+M12-N12 -> 2511.26 | Q12: =U11 -> 22.04 | R12: 0 | S12: =T12+'RAW MILL 2'!E12 -> 3 | T12: 3 | U12: =Q12+R12-S12 -> 19.04 | V12: =Y11 -> 0 | W12: 0 | X12: 0 | Y12: =V12+W12-X12 -> 0 | Z12: =AC11 -> 0 | AA12: 0 | AB12: 0 | AC12: =Z12+AA12-AB12 -> 0 | AD12: =AG11 -> 0 | AE12: 0 | AF12: 0 | AG12: =AD12+AE12-AF12 -> 0 | AH12: =D12+I12+M12+R12+W12+AA12+Cement!Q12+Cement!V12+AE12 -> 2998.26 | AI12: =E12+J12+N12+S12+X12+AB12+Clinker!E12+AF12 -> 1987 | AJ12: =Production2!N12 -> 1789.8 | AK12: =AJ12-AI12 -> -197.2 | AL12: 3017 | AQ12: =D12+I12+M12+R12+Cement!Q12 -> 2998.26 | AR12: =AI12+Cement!R12-Clinker!E12 -> 2240.48 | AS12: 400.64 | AT12: =AI12-Production2!N12 -> 197.2 | AU12: =AI12 -> 1987 | AV12: =E12+J12 -> 1861 | AW12: =AS12-D12 -> -1265.8 | AX12: =I12-AY12 -> -52.1 | AY12: 1142.58 | AZ12: =(AI12-Production2!N12)/'Mines (2)'!AI12 -> 0.099245093 | BA12: =AZ12*100 -> 9.9245093 | BB12: =E12+J12+AB12 -> 1861
B13: 11 | C13: =G12 -> 12805.563 | D13: 1171.64 | E13: =F13+'RAW MILL 2'!C13 -> 1875 | F13: 1875 | G13: =C13+D13-E13 -> 12102.203 | H13: =K12 -> 10855.041 | I13: 545.84 | J13: 0 | K13: =H13+I13-J13-Cement!S13 -> 11064.192 | L13: =P12 -> 2511.26 | M13: 60.3 | N13: =O13+'RAW MILL 2'!D13 -> 83 | O13: 83 | P13: =L13+M13-N13 -> 2488.56 | Q13: =U12 -> 19.04 | R13: 0 | S13: =T13+'RAW MILL 2'!E13 -> 4 | T13: 4 | U13: =Q13+R13-S13 -> 15.04 | V13: =Y12 -> 0 | W13: 0 | X13: 0 | Y13: =V13+W13-X13 -> 0 | Z13: =AC12 -> 0 | AA13: 0 | AB13: 0 | AC13: =Z13+AA13-AB13 -> 0 | AD13: =AG12 -> 0 | AE13: 0 | AF13: 0 | AG13: =AD13+AE13-AF13 -> 0 | AH13: =D13+I13+M13+R13+W13+AA13+Cement!Q13+Cement!V13+AE13 -> 1777.78 | AI13: =E13+J13+N13+S13+X13+AB13+Clinker!E13+AF13 -> 2010 | AJ13: =Production2!N13 -> 1810.44 | AK13: =AJ13-AI13 -> -199.56 | AL13: 3256 | AQ13: =D13+I13+M13+R13+Cement!Q13 -> 1777.78 | AR13: =AI13+Cement!R13-Clinker!E13 -> 2265.02 | AS13: 1843.24 | AT13: =AI13-Production2!N13 -> 199.56 | AU13: =AI13 -> 2010 | AV13: =E13+J13 -> 1875 | AW13: =AS13-D13 -> 671.6 | AX13: =I13-AY13 -> -547.64 | AY13: 1093.48 | AZ13: =(AI13-Production2!N13)/'Mines (2)'!AI13 -> 0.099283582 | BA13: =AZ13*100 -> 9.9283582 | BB13: =E13+J13+AB13 -> 1875
B14: 12 | C14: =G13 -> 12102.203 | D14: 2037.24 | E14: =F14+'RAW MILL 2'!C14 -> 1841 | F14: 1841 | G14: =C14+D14-E14 -> 12298.443 | H14: =K13 -> 11064.192 | I14: 780.1 | J14: 0 | K14: =H14+I14-J14-Cement!S14 -> 11518.514 | L14: =P13 -> 2488.56 | M14: 83 | N14: =O14+'RAW MILL 2'!D14 -> 68 | O14: 68 | P14: =L14+M14-N14 -> 2503.56 | Q14: =U13 -> 15.04 | R14: 0 | S14: =T14+'RAW MILL 2'!E14 -> 14 | T14: 14 | U14: =Q14+R14-S14 -> 1.04 | V14: =Y13 -> 0 | W14: 0 | X14: 0 | Y14: =V14+W14-X14 -> 0 | Z14: =AC13 -> 0 | AA14: 0 | AB14: 0 | AC14: =Z14+AA14-AB14 -> 0 | AD14: =AG13 -> 0 | AE14: 0 | AF14: 0 | AG14: =AD14+AE14-AF14 -> 0 | AH14: =D14+I14+M14+R14+W14+AA14+Cement!Q14+Cement!V14+AE14 -> 2900.34 | AI14: =E14+J14+N14+S14+X14+AB14+Clinker!E14+AF14 -> 1976 | AJ14: =Production2!N14 -> 1779.99 | AK14: =AJ14-AI14 -> -196.01 | AL14: 3209 | AQ14: =D14+I14+M14+R14+Cement!Q14 -> 2900.34 | AR14: =AI14+Cement!R14-Clinker!E14 -> 2216.2 | AS14: 665.76 | AT14: =AI14-Production2!N14 -> 196.01 | AU14: =AI14 -> 1976 | AV14: =E14+J14 -> 1841 | AW14: =AS14-D14 -> -1371.48 | AX14: =I14-AY14 -> -405.32 | AY14: 1185.42 | AZ14: =(AI14-Production2!N14)/'Mines (2)'!AI14 -> 0.099195344 | BA14: =AZ14*100 -> 9.9195344 | BB14: =E14+J14+AB14 -> 1841
B15: 13 | C15: =G14 -> 12298.443 | D15: 1923.4 | E15: =F15+'RAW MILL 2'!C15 -> 2200 | F15: 2200 | G15: =C15+D15-E15 -> 12021.843 | H15: =K14 -> 11518.514 | I15: 1008.88 | J15: 0 | K15: =H15+I15-J15-Cement!S15 -> 12122.294 | L15: =P14 -> 2503.56 | M15: 179.16 | N15: =O15+'RAW MILL 2'!D15 -> 83 | O15: 83 | P15: =L15+M15-N15 -> 2599.72 | Q15: =U14 -> 1.04 | R15: 0 | S15: =T15+'RAW MILL 2'!E15 -> 1 | T15: 1 | U15: =Q15+R15-S15 -> 0.04 | V15: =Y14 -> 0 | W15: 0 | X15: 0 | Y15: =V15+W15-X15 -> 0 | Z15: =AC14 -> 0 | AA15: 0 | AB15: 0 | AC15: =Z15+AA15-AB15 -> 0 | AD15: =AG14 -> 0 | AE15: 0 | AF15: 0 | AG15: =AD15+AE15-AF15 -> 0 | AH15: =D15+I15+M15+R15+W15+AA15+Cement!Q15+Cement!V15+AE15 -> 3111.44 | AI15: =E15+J15+N15+S15+X15+AB15+Clinker!E15+AF15 -> 2343 | AJ15: =Production2!N15 -> 2110.47 | AK15: =AJ15-AI15 -> -232.53 | AL15: 3075 | AQ15: =D15+I15+M15+R15+Cement!Q15 -> 3111.44 | AR15: =AI15+Cement!R15-Clinker!E15 -> 2648.59 | AS15: 776.72 | AT15: =AI15-Production2!N15 -> 232.53 | AU15: =AI15 -> 2343 | AV15: =E15+J15 -> 2200 | AW15: =AS15-D15 -> -1146.68 | AX15: =I15-AY15 -> -211.64 | AY15: 1220.52 | AZ15: =(AI15-Production2!N15)/'Mines (2)'!AI15 -> 0.099244558 | BA15: =AZ15*100 -> 9.9244558 | BB15: =E15+J15+AB15 -> 2200
B16: 14 | C16: =G15 -> 12021.843 | D16: 1668.48 | E16: =F16+'RAW MILL 2'!C16 -> 2117 | F16: 2117 | G16: =C16+D16-E16 -> 11573.323 | H16: =K15 -> 12122.294 | I16: 879.14 | J16: 0 | K16: =H16+I16-J16-Cement!S16 -> 12580.634 | L16: =P15 -> 2599.72 | M16: 0 | N16: =O16+'RAW MILL 2'!D16 -> 92 | O16: 92 | P16: =L16+M16-N16 -> 2507.72 | Q16: =U15 -> 0.04 | R16: 0 | S16: =T16+'RAW MILL 2'!E16 -> 0 | T16: 0 | U16: =Q16+R16-S16 -> 0.04 | V16: =Y15 -> 0 | W16: 0 | X16: 0 | Y16: =V16+W16-X16 -> 0 | Z16: =AC15 -> 0 | AA16: 0 | AB16: 0 | AC16: =Z16+AA16-AB16 -> 0 | AD16: =AG15 -> 0 | AE16: 0 | AF16: 0 | AG16: =AD16+AE16-AF16 -> 0 | AH16: =D16+I16+M16+R16+W16+AA16+Cement!Q16+Cement!V16+AE16 -> 2547.62 | AI16: =E16+J16+N16+S16+X16+AB16+Clinker!E16+AF16 -> 2266 | AJ16: =Production2!N16 -> 2041.11 | AK16: =AJ16-AI16 -> -224.89 | AL16: 2456 | AQ16: =D16+I16+M16+R16+Cement!Q16 -> 2547.62 | AR16: =AI16+Cement!R16-Clinker!E16 -> 2587.72 | AS16: 1682.06 | AT16: =AI16-Production2!N16 -> 224.89 | AU16: =AI16 -> 2266 | AV16: =E16+J16 -> 2117 | AW16: =AS16-D16 -> 13.58 | AX16: =I16-AY16 -> -179.02 | AY16: 1058.16 | AZ16: =(AI16-Production2!N16)/'Mines (2)'!AI16 -> 0.099245366 | BA16: =AZ16*100 -> 9.9245366 | BB16: =E16+J16+AB16 -> 2117
B17: 15 | C17: =G16 -> 11573.323 | D17: 1255.92 | E17: =F17+'RAW MILL 2'!C17 -> 1836 | F17: 1836 | G17: =C17+D17-E17 -> 10993.243 | H17: =K16 -> 12580.634 | I17: 1212.28 | J17: 0 | K17: =H17+I17-J17-Cement!S17 -> 13406.914 | L17: =P16 -> 2507.72 | M17: 106.6 | N17: =O17+'RAW MILL 2'!D17 -> 80 | O17: 80 | P17: =L17+M17-N17 -> 2534.32 | Q17: =U16 -> 0.04 | R17: 0 | S17: =T17+'RAW MILL 2'!E17 -> 0 | T17: 0 | U17: =Q17+R17-S17 -> 0.04 | V17: =Y16 -> 0 | W17: 0 | X17: 0 | Y17: =V17+W17-X17 -> 0 | Z17: =AC16 -> 0 | AA17: 0 | AB17: 0 | AC17: =Z17+AA17-AB17 -> 0 | AD17: =AG16 -> 0 | AE17: 0 | AF17: 0 | AG17: =AD17+AE17-AF17 -> 0 | AH17: =D17+I17+M17+R17+W17+AA17+Cement!Q17+Cement!V17+AE17 -> 2574.8 | AI17: =E17+J17+N17+S17+X17+AB17+Clinker!E17+AF17 -> 1965 | AJ17: =Production2!N17 -> 1769.97 | AK17: =AJ17-AI17 -> -195.03 | AL17: 2956 | AM17: =E17/AJ17 -> 1.0373057 | AN17: =J17/AJ17 -> 0 | AO17: =N17/AJ17 -> 0.045198506 | AP17: =S17/AJ17 -> 0 | AQ17: =D17+I17+M17+R17+Cement!Q17 -> 2574.8 | AR17: =AI17+Cement!R17-Clinker!E17 -> 2263.4 | AS17: 593.68 | AT17: =AI17-Production2!N17 -> 195.03 | AU17: =AI17 -> 1965 | AV17: =E17+J17 -> 1836 | AW17: =AS17-D17 -> -662.24 | AX17: =I17-AY17 -> 641.36 | AY17: 570.92 | AZ17: =(AI17-Production2!N17)/'Mines (2)'!AI17 -> 0.099251908 | BA17: =AZ17*100 -> 9.9251908 | BB17: =E17+J17+AB17 -> 1836
B18: 16 | C18: =G17 -> 10993.243 | D18: 2943.14 | E18: =F18+'RAW MILL 2'!C18 -> 2588 | F18: 2588 | G18: =C18+D18-E18 -> 11348.383 | H18: =K17 -> 13406.914 | I18: 729.6 | J18: 0 | K18: =H18+I18-J18-Cement!S18 -> 13677.351 | L18: =P17 -> 2534.32 | M18: 390.8 | N18: =O18+'RAW MILL 2'!D18 -> 112 | O18: 112 | P18: =L18+M18-N18 -> 2813.12 | Q18: =U17 -> 0.04 | R18: 0 | S18: =T18+'RAW MILL 2'!E18 -> 0 | T18: 0 | U18: =Q18+R18-S18 -> 0.04 | V18: =Y17 -> 0 | W18: 0 | X18: 0 | Y18: =V18+W18-X18 -> 0 | Z18: =AC17 -> 0 | AA18: 0 | AB18: 0 | AC18: =Z18+AA18-AB18 -> 0 | AD18: =AG17 -> 0 | AE18: 0 | AF18: 0 | AG18: =AD18+AE18-AF18 -> 0 | AH18: =D18+I18+M18+R18+W18+AA18+Cement!Q18+Cement!V18+AE18 -> 4063.54 | AI18: =E18+J18+N18+S18+X18+AB18+Clinker!E18+AF18 -> 2769 | AJ18: =Production2!N18 -> 2494.17 | AK18: =AJ18-AI18 -> -274.83 | AL18: 3022 | AM18: =E18/AJ18 -> 1.0376197 | AN18: =J18/AJ18 -> 0 | AO18: =N18/AJ18 -> 0.044904718 | AP18: =S18/AJ18 -> 0 | AQ18: =D18+I18+M18+R18+Cement!Q18 -> 4063.54 | AR18: =AI18+Cement!R18-Clinker!E18 -> 3113.247 | AS18: 1924.02 | AT18: =AI18-Production2!N18 -> 274.83 | AU18: =AI18 -> 2769 | AV18: =E18+J18 -> 2588 | AW18: =AS18-D18 -> -1019.12 | AX18: =I18-AY18 -> -1198.98 | AY18: 1928.58 | AZ18: =(AI18-Production2!N18)/'Mines (2)'!AI18 -> 0.099252438 | BA18: =AZ18*100 -> 9.9252438 | BB18: =E18+J18+AB18 -> 2588
B19: 17 | C19: =G18 -> 11348.383 | D19: 1944.6 | E19: =F19+'RAW MILL 2'!C19 -> 2545 | F19: 2446 | G19: =C19+D19-E19 -> 10747.983 | H19: =K18 -> 13677.351 | I19: 843.54 | J19: 0 | K19: =H19+I19-J19-Cement!S19 -> 14121.669 | L19: =P18 -> 2813.12 | M19: 37.84 | N19: =O19+'RAW MILL 2'!D19 -> 75 | O19: 72 | P19: =L19+M19-N19 -> 2775.96 | Q19: =U18 -> 0.04 | R19: 0 | S19: =T19+'RAW MILL 2'!E19 -> 0 | T19: 0 | U19: =Q19+R19-S19 -> 0.04 | V19: =Y18 -> 0 | W19: 0 | X19: 0 | Y19: =V19+W19-X19 -> 0 | Z19: =AC18 -> 0 | AA19: 0 | AB19: 0 | AC19: =Z19+AA19-AB19 -> 0 | AD19: =AG18 -> 0 | AE19: 0 | AF19: 0 | AG19: =AD19+AE19-AF19 -> 0 | AH19: =D19+I19+M19+R19+W19+AA19+Cement!Q19+Cement!V19+AE19 -> 2825.98 | AI19: =E19+J19+N19+S19+X19+AB19+Clinker!E19+AF19 -> 2666 | AJ19: =Production2!N19 -> 2306 | AK19: =AJ19-AI19 -> -360 | AL19: 2379 | AM19: =E19/AJ19 -> 1.1036427 | AN19: =J19/AJ19 -> 0 | AO19: =N19/AJ19 -> 0.032523851 | AP19: =S19/AJ19 -> 0 | AQ19: =D19+I19+M19+R19+Cement!Q19 -> 2825.98 | AR19: =AI19+Cement!R19-Clinker!E19 -> 2979.3 | AS19: 2200 | AT19: =AI19-Production2!N19 -> 360 | AU19: =AI19 -> 2666 | AV19: =E19+J19 -> 2545 | AW19: =AS19-D19 -> 255.4 | AX19: =I19-AY19 -> -56.46 | AY19: 900 | AZ19: =(AI19-Production2!N19)/'Mines (2)'!AI19 -> 0.13503376 | BA19: =AZ19*100 -> 13.503376 | BB19: =E19+J19+AB19 -> 2545
B20: 18 | C20: =G19 -> 10747.983 | D20: 1705.08 | E20: =F20+'RAW MILL 2'!C20 -> 2664 | F20: 2454 | G20: =C20+D20-E20 -> 9789.0632 | H20: =K19 -> 14121.669 | I20: 873.28 | J20: 0 | K20: =H20+I20-J20-Cement!S20 -> 14699.926 | L20: =P19 -> 2775.96 | M20: 0 | N20: =O20+'RAW MILL 2'!D20 -> 84 | O20: 77 | P20: =L20+M20-N20 -> 2691.96 | Q20: =U19 -> 0.04 | R20: 0 | S20: =T20+'RAW MILL 2'!E20 -> 0 | T20: 0 | U20: =Q20+R20-S20 -> 0.04 | V20: =Y19 -> 0 | W20: 0 | X20: 0 | Y20: =V20+W20-X20 -> 0 | Z20: =AC19 -> 0 | AA20: 0 | AB20: 0 | AC20: =Z20+AA20-AB20 -> 0 | AD20: =AG19 -> 0 | AE20: 0 | AF20: 0 | AG20: =AD20+AE20-AF20 -> 0 | AH20: =D20+I20+M20+R20+W20+AA20+Cement!Q20+Cement!V20+AE20 -> 2578.36 | AI20: =E20+J20+N20+S20+X20+AB20+Clinker!E20+AF20 -> 2798 | AJ20: =Production2!N20 -> 2320 | AK20: =AJ20-AI20 -> -478 | AL20: 3157 | AM20: =E20/AJ20 -> 1.1482759 | AN20: =J20/AJ20 -> 0 | AO20: =N20/AJ20 -> 0.036206897 | AP20: =S20/AJ20 -> 0 | AQ20: =D20+I20+M20+R20+Cement!Q20 -> 2578.36 | AR20: =AI20+Cement!R20-Clinker!E20 -> 3013.52 | AS20: 1275.56 | AT20: =AI20-Production2!N20 -> 478 | AU20: =AI20 -> 2798 | AV20: =E20+J20 -> 2664 | AW20: =AS20-D20 -> -429.52 | AX20: =I20-AY20 -> 291.96 | AY20: 581.32 | AZ20: =(AI20-Production2!N20)/'Mines (2)'!AI20 -> 0.17083631 | BA20: =AZ20*100 -> 17.083631 | BB20: =E20+J20+AB20 -> 2664
B21: 19 | C21: =G20 -> 9789.0632 | D21: 1936.24 | E21: =F21+'RAW MILL 2'!C21 -> 3110 | F21: 2955 | G21: =C21+D21-E21 -> 8615.3032 | H21: =K20 -> 14699.926 | I21: 1173.04 | J21: 0 | K21: =H21+I21-J21-Cement!S21 -> 15584.633 | L21: =P20 -> 2691.96 | M21: 105.44 | N21: =O21+'RAW MILL 2'!D21 -> 58 | O21: 55 | P21: =L21+M21-N21 -> 2739.4 | Q21: =U20 -> 0.04 | R21: 0 | S21: =T21+'RAW MILL 2'!E21 -> 0 | T21: 0 | U21: =Q21+R21-S21 -> 0.04 | V21: =Y20 -> 0 | W21: 0 | X21: 0 | Y21: =V21+W21-X21 -> 0 | Z21: =AC20 -> 0 | AA21: 0 | AB21: 0 | AC21: =Z21+AA21-AB21 -> 0 | AD21: =AG20 -> 0 | AE21: 0 | AF21: 0 | AG21: =AD21+AE21-AF21 -> 0 | AH21: =D21+I21+M21+R21+W21+AA21+Cement!Q21+Cement!V21+AE21 -> 3214.72 | AI21: =E21+J21+N21+S21+X21+AB21+Clinker!E21+AF21 -> 3220 | AJ21: =Production2!N21 -> 2754 | AK21: =AJ21-AI21 -> -466 | AL21: 2838 | AM21: =E21/AJ21 -> 1.1292665 | AN21: =J21/AJ21 -> 0 | AO21: =N21/AJ21 -> 0.021060276 | AP21: =S21/AJ21 -> 0 | AQ21: =D21+I21+M21+R21+Cement!Q21 -> 3214.72 | AR21: =AI21+Cement!R21-Clinker!E21 -> 3427.5 | AS21: 244.68 | AT21: =AI21-Production2!N21 -> 466 | AU21: =AI21 -> 3220 | AV21: =E21+J21 -> 3110 | AW21: =AS21-D21 -> -1691.56 | AX21: =I21-AY21 -> -207.08 | AY21: 1380.12 | AZ21: =(AI21-Production2!N21)/'Mines (2)'!AI21 -> 0.1447205 | BA21: =AZ21*100 -> 14.47205 | BB21: =E21+J21+AB21 -> 3110
B22: 20 | C22: =G21 -> 8615.3032 | D22: 2358.56 | E22: =F22+'RAW MILL 2'!C22 -> 3059 | F22: 2850 | G22: =C22+D22-E22 -> 7914.8632 | H22: =K21 -> 15584.633 | I22: 1207.22 | J22: 0 | K22: =H22+I22-J22-Cement!S22 -> 16287.009 | L22: =P21 -> 2739.4 | M22: 0 | N22: =O22+'RAW MILL 2'!D22 -> 38 | O22: 35 | P22: =L22+M22-N22 -> 2701.4 | Q22: =U21 -> 0.04 | R22: 0 | S22: =T22+'RAW MILL 2'!E22 -> 0 | T22: 0 | U22: =Q22+R22-S22 -> 0.04 | V22: =Y21 -> 0 | W22: 0 | X22: 0 | Y22: =V22+W22-X22 -> 0 | Z22: =AC21 -> 0 | AA22: 0 | AB22: 0 | AC22: =Z22+AA22-AB22 -> 0 | AD22: =AG21 -> 0 | AE22: 0 | AF22: 0 | AG22: =AD22+AE22-AF22 -> 0 | AH22: =D22+I22+M22+R22+W22+AA22+Cement!Q22+Cement!V22+AE22 -> 3565.78 | AI22: =E22+J22+N22+S22+X22+AB22+Clinker!E22+AF22 -> 3160 | AJ22: =Production2!N22 -> 2651 | AK22: =AJ22-AI22 -> -509 | AL22: 3051 | AM22: =E22/AJ22 -> 1.1539042 | AN22: =J22/AJ22 -> 0 | AO22: =N22/AJ22 -> 0.014334214 | AP22: =S22/AJ22 -> 0 | AQ22: =D22+I22+M22+R22+Cement!Q22 -> 3565.78 | AR22: =AI22+Cement!R22-Clinker!E22 -> 3551.36 | AS22: 841.18 | AT22: =AI22-Production2!N22 -> 509 | AU22: =AI22 -> 3160 | AV22: =E22+J22 -> 3059 | AW22: =AS22-D22 -> -1517.38 | AX22: =I22-AY22 -> -393.58 | AY22: 1600.8 | AZ22: =(AI22-Production2!N22)/'Mines (2)'!AI22 -> 0.16107595 | BA22: =AZ22*100 -> 16.107595
B23: 21 | C23: =G22 -> 7914.8632 | D23: 1526.78 | E23: =F23+'RAW MILL 2'!C23 -> 1148 | F23: 915 | G23: =C23+D23-E23 -> 8293.6432 | H23: =K22 -> 16287.009 | I23: 233.48 | J23: 2000 | K23: =H23+I23-J23-Cement!S23 -> 13953.389 | L23: =P22 -> 2701.4 | M23: 188.54 | N23: =O23+'RAW MILL 2'!D23 -> 66 | O23: 61 | P23: =L23+M23-N23 -> 2823.94 | Q23: =U22 -> 0.04 | R23: 0 | S23: =T23+'RAW MILL 2'!E23 -> 0 | T23: 0 | U23: =Q23+R23-S23 -> 0.04 | V23: =Y22 -> 0 | W23: 0 | X23: 0 | Y23: =V23+W23-X23 -> 0 | Z23: =AC22 -> 0 | AA23: 0 | AB23: 0 | AC23: =Z23+AA23-AB23 -> 0 | AD23: =AG22 -> 0 | AE23: 0 | AF23: 0 | AG23: =AD23+AE23-AF23 -> 0 | AH23: =D23+I23+M23+R23+W23+AA23+Cement!Q23+Cement!V23+AE23 -> 1948.8 | AI23: =E23+J23+N23+S23+X23+AB23+Clinker!E23+AF23 -> 3290 | AJ23: =Production2!N23 -> 2743 | AK23: =AJ23-AI23 -> -547 | AL23: 2232 | AM23: =E23/AJ23 -> 0.41851987 | AN23: =J23/AJ23 -> 0.72912869 | AO23: =N23/AJ23 -> 0.024061247 | AP23: =S23/AJ23 -> 0 | AQ23: =D23+I23+R23+#REF!+Cement!Q23 -> #REF! | AR23: =AI23+Cement!R23-Clinker!E23 -> 3724.39 | AS23: 0 | AT23: =AI23-Production2!N23 -> 547 | AU23: =AI23 -> 3290 | AV23: =E23+J23 -> 3148 | AW23: =AS23-D23 -> -1526.78 | AX23: =I23-AY23 -> -794.1 | AY23: 1027.58 | AZ23: =(AI23-Production2!N23)/'Mines (2)'!AI23 -> 0.1662614 | BA23: =AZ23*100 -> 16.62614
B24: 22 | C24: =G23 -> 8293.6432 | D24: 2228.22 | E24: =F24+'RAW MILL 2'!C24 -> 2103 | F24: 2000 | G24: =C24+D24-E24 -> 8418.8632 | H24: =K23 -> 13953.389 | I24: 754.04 | J24: 302 | K24: =H24+I24-J24-Cement!S24 -> 13953.777 | L24: =P23 -> 2823.94 | M24: 0 | N24: =O24+'RAW MILL 2'!D24 -> 50 | O24: 48 | P24: =L24+M24-N24 -> 2773.94 | Q24: =U23 -> 0.04 | R24: 0 | S24: =T24+'RAW MILL 2'!E24 -> 0 | T24: 0 | U24: =Q24+R24-S24 -> 0.04 | V24: =Y23 -> 0 | W24: 0 | X24: 0 | Y24: =V24+W24-X24 -> 0 | Z24: =AC23 -> 0 | AA24: 0 | AB24: 0 | AC24: =Z24+AA24-AB24 -> 0 | AD24: =AG23 -> 0 | AE24: 0 | AF24: 0 | AG24: =AD24+AE24-AF24 -> 0 | AH24: =D24+I24+M24+R24+W24+AA24+Cement!Q24+Cement!V24+AE24 -> 2982.26 | AI24: =E24+J24+N24+S24+X24+AB24+Clinker!E24+AF24 -> 2514 | AJ24: =Production2!N24 -> 2166 | AK24: =AJ24-AI24 -> -348 | AM24: =E24/AJ24 -> 0.97091413 | AN24: =J24/AJ24 -> 0.13942752 | AO24: =N24/AJ24 -> 0.023084026 | AP24: =S24/AJ24 -> 0 | AQ24: =D24+I24+M24+R24+Cement!Q24 -> 2982.26 | AR24: =AI24+Cement!R24-Clinker!E24 -> 2861.486 | AT24: =AI24-Production2!N24 -> 348 | AU24: =AI24 -> 2514 | AV24: =E24+J24 -> 2405 | AW24: =AS24-D24 -> -2228.22 | AX24: =I24-AY24 -> 754.04 | AY24: 0 | AZ24: =(AI24-Production2!N24)/'Mines (2)'!AI24 -> 0.13842482 | BA24: =AZ24*100 -> 13.842482
B25: 23 | C25: =G24 -> 8418.8632 | D25: 2834.02 | E25: =F25+'RAW MILL 2'!C25 -> 2397 | F25: 2234 | G25: =C25+D25-E25 -> 8855.8832 | H25: =K24 -> 13953.777 | I25: 1154.54 | J25: 0 | K25: =H25+I25-J25-Cement!S25 -> 14676.351 | L25: =P24 -> 2773.94 | M25: 0 | N25: =O25+'RAW MILL 2'!D25 -> 51 | O25: 47 | P25: =L25+M25-N25 -> 2722.94 | Q25: =U24 -> 0.04 | R25: 0 | S25: =T25+'RAW MILL 2'!E25 -> 0 | T25: 0 | U25: =Q25+R25-S25 -> 0.04 | V25: =Y24 -> 0 | W25: 0 | X25: 0 | Y25: =V25+W25-X25 -> 0 | Z25: =AC24 -> 0 | AA25: 0 | AB25: 0 | AC25: =Z25+AA25-AB25 -> 0 | AD25: =AG24 -> 0 | AE25: 0 | AF25: 0 | AG25: =AD25+AE25-AF25 -> 0 | AH25: =D25+I25+M25+R25+W25+AA25+Cement!Q25+Cement!V25+AE25 -> 3988.56 | AI25: =E25+J25+N25+S25+X25+AB25+Clinker!E25+AF25 -> 2506 | AJ25: =Production2!N25 -> 2102 | AK25: =AJ25-AI25 -> -404 | AM25: =E25/AJ25 -> 1.1403425 | AN25: =J25/AJ25 -> 0 | AO25: =N25/AJ25 -> 0.024262607 | AP25: =S25/AJ25 -> 0 | AQ25: =D25+I25+M25+R25+Cement!Q25 -> 3988.56 | AR25: =AI25+Cement!R25-Clinker!E25 -> 2836.77 | AT25: =AI25-Production2!N25 -> 404 | AU25: =AI25 -> 2506 | AV25: =E25+J25 -> 2397 | AW25: =AS25-D25 -> -2834.02 | AX25: =I25-AY25 -> 1154.54 | AY25: 0 | AZ25: =(AI25-Production2!N25)/'Mines (2)'!AI25 -> 0.16121309 | BA25: =AZ25*100 -> 16.121309
B26: 24 | C26: =G25 -> 8855.8832 | D26: 1992.58 | E26: =F26+'RAW MILL 2'!C26 -> 2137 | F26: 2017 | G26: =C26+D26-E26 -> 8711.4632 | H26: =K25 -> 14676.351 | I26: 748 | J26: 1000 | K26: =H26+I26-J26-Cement!S26 -> 13918.351 | L26: =P25 -> 2722.94 | M26: 265.28 | N26: =O26+'RAW MILL 2'!D26 -> 107 | O26: 103 | P26: =L26+M26-N26 -> 2881.22 | Q26: =U25 -> 0.04 | R26: 0 | S26: =T26+'RAW MILL 2'!E26 -> 0 | T26: 0 | U26: =Q26+R26-S26 -> 0.04 | V26: =Y25 -> 0 | W26: 0 | X26: 0 | Y26: =V26+W26-X26 -> 0 | Z26: =AC25 -> 0 | AA26: 0 | AB26: 0 | AC26: =Z26+AA26-AB26 -> 0 | AD26: =AG25 -> 0 | AE26: 0 | AF26: 0 | AG26: =AD26+AE26-AF26 -> 0 | AH26: =D26+I26+M26+R26+W26+AA26+Cement!Q26+Cement!V26+AE26 -> 3005.86 | AI26: =E26+J26+N26+S26+X26+AB26+Clinker!E26+AF26 -> 3338 | AJ26: =Production2!N26 -> 2890 | AK26: =AJ26-AI26 -> -448 | AM26: =E26/AJ26 -> 0.73944637 | AN26: =J26/AJ26 -> 0.34602076 | AO26: =N26/AJ26 -> 0.037024221 | AP26: =S26/AJ26 -> 0 | AQ26: =D26+I26+M26+R26+Cement!Q26 -> 3005.86 | AR26: =AI26+Cement!R26-Clinker!E26 -> 3699.4 | AT26: =AI26-Production2!N26 -> 448 | AU26: =AI26 -> 3338 | AV26: =E26+J26 -> 3137 | AW26: =AS26-D26 -> -1992.58 | AX26: =D26-AY26 -> 1992.58 | AY26: 0 | AZ26: =(AI26-Production2!N26)/'Mines (2)'!AI26 -> 0.1342121 | BA26: =AZ26*100 -> 13.42121
B27: 25 | C27: =G26 -> 8711.4632 | D27: 1106.52 | E27: =F27+'RAW MILL 2'!C27 -> 2546 | F27: 2546 | G27: =C27+D27-E27 -> 7271.9832 | H27: =K26 -> 13918.351 | I27: 1498.02 | J27: 0 | K27: =H27+I27-J27-Cement!S27 -> 14988.393 | L27: =P26 -> 2881.22 | M27: 44.38 | N27: =O27+'RAW MILL 2'!D27 -> 71 | O27: 71 | P27: =L27+M27-N27 -> 2854.6 | Q27: =U26 -> 0.04 | R27: 0 | S27: =T27+'RAW MILL 2'!E27 -> 0 | T27: 0 | U27: =Q27+R27-S27 -> 0.04 | V27: =Y26 -> 0 | W27: 0 | X27: 0 | Y27: =V27+W27-X27 -> 0 | Z27: =AC26 -> 0 | AA27: 0 | AB27: 0 | AC27: =Z27+AA27-AB27 -> 0 | AD27: =AG26 -> 0 | AE27: 0 | AF27: 0 | AG27: =AD27+AE27-AF27 -> 0 | AH27: =D27+I27+M27+R27+W27+AA27+Cement!Q27+Cement!V27+AE27 -> 2648.92 | AI27: =E27+J27+N27+S27+X27+AB27+Clinker!E27+AF27 -> 2692 | AJ27: =Production2!N27 -> 2425.05 | AK27: =AJ27-AI27 -> -266.95 | AM27: =E27/AJ27 -> 1.0498753 | AN27: =J27/AJ27 -> 0 | AO27: =N27/AJ27 -> 0.029277747 | AP27: =S27/AJ27 -> 0 | AQ27: =D27+I27+M27+R27+Cement!Q27 -> 2648.92 | AR27: =AI27+Cement!R27-Clinker!E27 -> 3002.18 | AT27: =AI27-Production2!N27 -> 266.95 | AU27: =AI27 -> 2692 | AV27: 25 | AY27: 0 | AZ27: =(AI27-Production2!N27)/'Mines (2)'!AI27 -> 0.09916419 | BA27: =AZ27*100 -> 9.916419
B28: 26 | C28: =G27 -> 7271.9832 | D28: 105.4 | E28: =F28+'RAW MILL 2'!C28 -> 1765 | F28: 1765 | G28: =C28+D28-E28 -> 5612.3832 | H28: =K27 -> 14988.393 | I28: 2922.04 | J28: 0 | K28: =H28+I28-J28-Cement!S28 -> 17353.875 | L28: =P27 -> 2854.6 | M28: 136.66 | N28: =O28+'RAW MILL 2'!D28 -> 49 | O28: 49 | P28: =L28+M28-N28 -> 2942.26 | Q28: =U27 -> 0.04 | R28: 0 | S28: =T28+'RAW MILL 2'!E28 -> 0 | T28: 0 | U28: =Q28+R28-S28 -> 0.04 | V28: =Y27 -> 0 | W28: 0 | X28: 0 | Y28: =V28+W28-X28 -> 0 | Z28: =AC27 -> 0 | AA28: 0 | AB28: 0 | AC28: =Z28+AA28-AB28 -> 0 | AD28: =AG27 -> 0 | AE28: 0 | AF28: 0 | AG28: =AD28+AE28-AF28 -> 0 | AH28: =D28+I28+M28+R28+W28+AA28+Cement!Q28+Cement!V28+AE28 -> 3164.1 | AI28: =E28+J28+N28+S28+X28+AB28+Clinker!E28+AF28 -> 1867 | AJ28: =Production2!N28 -> 1681.89 | AK28: =AJ28-AI28 -> -185.11 | AM28: =E28/AJ28 -> 1.0494146 | AN28: =J28/AJ28 -> 0 | AO28: =N28/AJ28 -> 0.029133891 | AP28: =S28/AJ28 -> 0 | AQ28: =D28+I28+M28+R28+Cement!Q28 -> 3164.1 | AR28: =AI28+Cement!R28-Clinker!E28 -> 2314.902 | AT28: =AI28-Production2!N28 -> 185.11 | AU28: =AI28 -> 1867 | AV28: 26 | AY28: 0 | AZ28: =(AI28-Production2!N28)/'Mines (2)'!AI28 -> 0.099148366 | BA28: =AZ28*100 -> 9.9148366
B29: 27 | C29: =G28 -> 5612.3832 | D29: 2026.58 | E29: =F29+'RAW MILL 2'!C29 -> 1083 | F29: 1083 | G29: =C29+D29-E29 -> 6555.9632 | H29: =K28 -> 17353.875 | I29: 1040.54 | J29: 2000 | K29: =H29+I29-J29-Cement!S29 -> 15808.415 | L29: =P28 -> 2942.26 | M29: 0 | N29: =O29+'RAW MILL 2'!D29 -> 32 | O29: 32 | P29: =L29+M29-N29 -> 2910.26 | Q29: =U28 -> 0.04 | R29: 0 | S29: =T29+'RAW MILL 2'!E29 -> 0 | T29: 0 | U29: =Q29+R29-S29 -> 0.04 | V29: =Y28 -> 0 | W29: 0 | X29: 0 | Y29: =V29+W29-X29 -> 0 | Z29: =AC28 -> 0 | AA29: 0 | AB29: 0 | AC29: =Z29+AA29-AB29 -> 0 | AD29: =AG28 -> 0 | AE29: 0 | AF29: 0 | AG29: =AD29+AE29-AF29 -> 0 | AH29: =D29+I29+M29+R29+W29+AA29+Cement!Q29+Cement!V29+AE29 -> 3067.12 | AI29: =E29+J29+N29+S29+X29+AB29+Clinker!E29+AF29 -> 3179 | AJ29: =Production2!N29 -> 2863.02 | AK29: =AJ29-AI29 -> -315.98 | AM29: =E29/AJ29 -> 0.37827189 | AN29: =J29/AJ29 -> 0.69856306 | AO29: =N29/AJ29 -> 0.011177009 | AP29: =S29/AJ29 -> 0 | AR29: =AI29+Cement!R29-Clinker!E29 -> 3642.4 | AT29: =AI29-Production2!N29 -> 315.98 | AU29: =AI29 -> 3179 | AV29: 27 | AY29: 0 | AZ29: =(AI29-Production2!N29)/'Mines (2)'!AI29 -> 0.099396036 | BA29: =AZ29*100 -> 9.9396036
B30: 28 | C30: =G29 -> 6555.9632 | D30: 1283.02 | E30: =F30+'RAW MILL 2'!C30 -> 1204 | F30: 1204 | G30: =C30+D30-E30 -> 6634.9832 | H30: =K29 -> 15808.415 | I30: 2006.46 | J30: 2000 | K30: =H30+I30-J30-Cement!S30 -> 15460.909 | L30: =P29 -> 2910.26 | M30: 88 | N30: =O30+'RAW MILL 2'!D30 -> 33 | O30: 33 | P30: =L30+M30-N30 -> 2965.26 | Q30: =U29 -> 0.04 | R30: 0 | S30: =T30+'RAW MILL 2'!E30 -> 0 | T30: 0 | U30: =Q30+R30-S30 -> 0.04 | V30: =Y29 -> 0 | W30: 0 | X30: 0 | Y30: =V30+W30-X30 -> 0 | Z30: =AC29 -> 0 | AA30: 0 | AB30: 0 | AC30: =Z30+AA30-AB30 -> 0 | AD30: =AG29 -> 0 | AE30: 0 | AF30: 0 | AG30: =AD30+AE30-AF30 -> 0 | AH30: =D30+I30+M30+R30+W30+AA30+Cement!Q30+Cement!V30+AE30 -> 3377.48 | AI30: =E30+J30+N30+S30+X30+AB30+Clinker!E30+AF30 -> 3303 | AJ30: =Production2!N30 -> 2974.68 | AK30: =AJ30-AI30 -> -328.32 | AM30: =E30/AJ30 -> 0.40474942 | AN30: =J30/AJ30 -> 0.67234123 | AO30: =N30/AJ30 -> 0.01109363 | AP30: =S30/AJ30 -> 0 | AR30: =AI30+Cement!R30-Clinker!E30 -> 3555.57 | AT30: =AI30-Production2!N30 -> 328.32 | AU30: =AI30 -> 3303 | AV30: 28 | AY30: 0 | AZ30: =(AI30-Production2!N30)/'Mines (2)'!AI30 -> 0.099400545 | BA30: =AZ30*100 -> 9.9400545
B31: 29 | C31: =G30 -> 6634.9832 | D31: 2814.02 | E31: =F31+'RAW MILL 2'!C31 -> 856 | F31: 856 | G31: =C31+D31-E31 -> 8593.0032 | H31: =K30 -> 15460.909 | I31: 1258.2 | J31: 2000 | K31: =H31+I31-J31-Cement!S31 -> 14299.007 | L31: =P30 -> 2965.26 | M31: 112.18 | N31: =O31+'RAW MILL 2'!D31 -> 30 | O31: 30 | P31: =L31+M31-N31 -> 3047.44 | Q31: =U30 -> 0.04 | R31: 0 | S31: =T31+'RAW MILL 2'!E31 -> 0 | T31: 0 | U31: =Q31+R31-S31 -> 0.04 | V31: =Y30 -> 0 | W31: 0 | X31: 0 | Y31: =V31+W31-X31 -> 0 | Z31: =AC30 -> 0 | AA31: 0 | AB31: 0 | AC31: =Z31+AA31-AB31 -> 0 | AD31: =AG30 -> 0 | AE31: 0 | AF31: 0 | AG31: =AD31+AE31-AF31 -> 0 | AH31: =D31+I31+M31+R31+W31+AA31+Cement!Q31+Cement!V31+AE31 -> 4184.4 | AI31: =E31+J31+N31+S31+X31+AB31+Clinker!E31+AF31 -> 2945 | AJ31: =Production2!N31 -> 2652.27 | AK31: =AJ31-AI31 -> -292.73 | AM31: =E31/AJ31 -> 0.32274241 | AN31: =J31/AJ31 -> 0.75407104 | AO31: =N31/AJ31 -> 0.011311066 | AP31: =S31/AJ31 -> 0 | AR31: =AI31+Cement!R31-Clinker!E31 -> 3264.091 | AT31: =AI31-Production2!N31 -> 292.73 | AU31: =AI31 -> 2945 | AV31: 29 | AY31: 0 | AZ31: =(AI31-Production2!N31)/'Mines (2)'!AI31 -> 0.099398981 | BA31: =AZ31*100 -> 9.9398981
B32: 30 | C32: =G31 -> 8593.0032 | D32: 967.26 | E32: =F32+'RAW MILL 2'!C32 -> 1338 | F32: 1329 | G32: =C32+D32-E32 -> 8222.2632 | H32: =K31 -> 14299.007 | I32: 1893.42 | J32: 2000 | K32: =H32+I32-J32-Cement!S32 -> 13566.939 | L32: =P31 -> 3047.44 | M32: 0 | N32: =O32+'RAW MILL 2'!D32 -> 35 | O32: 34 | P32: =L32+M32-N32 -> 3012.44 | Q32: =U31 -> 0.04 | R32: 0 | S32: =T32+'RAW MILL 2'!E32 -> 0 | T32: 0 | U32: =Q32+R32-S32 -> 0.04 | V32: =Y31 -> 0 | W32: 0 | X32: 0 | Y32: =V32+W32-X32 -> 0 | Z32: =AC31 -> 0 | AA32: 0 | AB32: 0 | AC32: =Z32+AA32-AB32 -> 0 | AD32: =AG31 -> 0 | AE32: 0 | AF32: 0 | AG32: =AD32+AE32-AF32 -> 0 | AH32: =D32+I32+M32+R32+W32+AA32+Cement!Q32+Cement!V32+AE32 -> 2860.68 | AI32: =E32+J32+N32+S32+X32+AB32+Clinker!E32+AF32 -> 3451 | AJ32: =Production2!N32 -> 3098 | AK32: =AJ32-AI32 -> -353 | AM32: =E32/AJ32 -> 0.43189154 | AN32: =J32/AJ32 -> 0.64557779 | AO32: =N32/AJ32 -> 0.011297611 | AP32: =S32/AJ32 -> 0 | AR32: =AI32+Cement!R32-Clinker!E32 -> 3935.96 | AT32: =AI32-Production2!N32 -> 353 | AU32: =AI32 -> 3451 | AV32: 30 | AY32: 0 | AZ32: =(AI32-Production2!N32)/'Mines (2)'!AI32 -> 0.10228919
B33: 31 | C33: =G32 -> 8222.2632 | D33: 654.52 | E33: =F33+'RAW MILL 2'!C33 -> 1354 | F33: 1155 | G33: =C33+D33-E33 -> 7522.7832 | H33: =K32 -> 13566.939 | I33: 1068.8 | J33: 2000 | K33: =H33+I33-J33-Cement!S33 -> 11945.017 | L33: =P32 -> 3012.44 | M33: 0 | N33: =O33+'RAW MILL 2'!D33 -> 101 | O33: 95 | P33: =L33+M33-N33 -> 2911.44 | Q33: =U32 -> 0.04 | R33: 0 | S33: =T33+'RAW MILL 2'!E33 -> 0 | T33: 0 | U33: =Q33+R33-S33 -> 0.04 | V33: =Y32 -> 0 | W33: 0 | X33: 0 | Y33: =V33+W33-X33 -> 0 | Z33: =AC32 -> 0 | AA33: 0 | AB33: 0 | AC33: =Z33+AA33-AB33 -> 0 | AD33: =AG32 -> 0 | AE33: 0 | AF33: 0 | AG33: =AD33+AE33-AF33 -> 0 | AH33: =D33+I33+M33+R33+W33+AA33+Cement!Q33+Cement!V33+AE33 -> 1723.32 | AI33: =E33+J33+N33+S33+X33+AB33+Clinker!E33+AF33 -> 3505 | AT33: =AI33-Production2!N33 -> 538
B34: MTD | D34: =SUM(D3:D33) -> 56592 | E34: =SUM(E3:E33) -> 56342 | I34: =SUM(I3:I33) -> 35289.58 | J34: =SUM(J3:J33) -> 16802 | M34: =SUM(M3:M33) -> 3917.94 | N34: =SUM(N3:N33) -> 1953 | O34: =SUM(O3:O33) -> 1898 | R34: =SUM(R3:R33) -> 0 | S34: =SUM(S3:S33) -> 191 | T34: =SUM(T3:T33) -> 188 | U34: =SUM(U3:U33) -> 1090.24 | V34: =SUM(V3:V33) -> 0 | W34: =SUM(W3:W33) -> 0 | X34: =SUM(X3:X33) -> 0 | Y34: =SUM(Y3:Y33) -> 0 | ... AG34: =SUM(AG3:AG33) -> 0 | AI34: =SUM(AI3:AI33) -> 76986
B35: YTD | D35: =D36+SUM(D3:D33) -> 88657.72 | E35: =E36+SUM(E3:E33) -> 90641 | I35: =I36+SUM(I3:I33) -> 68209.56 | J35: =J36+SUM(J3:J33) -> 49390 | M35: =M36+SUM(M3:M33) -> 5269.4 | N35: =N36+SUM(N3:N33) -> 2482 | O35: =O36+SUM(O3:O33) -> 2390 | R35: =R36+SUM(R3:R33) -> 137.76 | S35: =S36+SUM(S3:S33) -> 738 | T35: =T36+SUM(T3:T33) -> 705 | W35: =W36+SUM(W3:W33) -> 0 | X35: =X36+SUM(X3:X33) -> 0 | AA35: =AA36+SUM(AA3:AA33) -> 0 | AB35: =AB36+SUM(AB3:AB33) -> 0 | AE35: =AE36+SUM(AE3:AE33) -> 0 | AF35: =AF36+SUM(AF3:AF33) -> 0
D36: 32065.72 | E36: 34299 | I36: 32919.98 | J36: 32588 | M36: 1351.46 | N36: 529 | O36: 492 | R36: 137.76 | S36: 547 | T36: 517 | W36: 0 | X36: 0 | AA36: 0 | AB36: 0 | AE36: 0 | AF36: 0
I39: =D36+I36+W36+AA36+Cement!Q36+Cement!V36 -> 64985.7 | J39: =E36+J36+X36+AB36+Cement!R36+Cement!W36 -> 75518.82 | Q39: 3103 | R39: 3286 | S39: 2899 | T39: 2899 | U39: 3290 | V39: 3245 | W39: 3139 | X39: 1732 | Y39: 1959 | Z39: 3119 | AA39: 3017 | AB39: 3256 | AC39: 3209 | AD39: 3075 | AE39: 2456 | AF39: 2956 | AG39: 3022 | AH39: 2379 | AI39: 3157 | AJ39: 2838 | AK39: 3051 | AL39: 2232

Sheet Clinker
B1: DEC | C1: Iron Ore | H1: Raw Meal | L1: Tan Coal | R1: EDENVILLEY coal | X1: RUVUMA coal | AC1: GODMWANGA coal | AG1: STAMICO coal | AL1: Ash Coal | AP1: Ariim Coal | AU1: Lik & Lambert coal | AZ1: JITEGEMEE | BE1: MAX COAL | BJ1: SINO COAL | BO1: Ibrico | BT1: MEGA CJ | BY1: MABENGA COAL | CD1: TENCO | CI1: Scolastica | CN1: Connect | CS1: Yongda | CX1: Kindaini | DC1: MONTREAL | DH1: ludewa | DM1: MCHEKANE | DR1: MARKET | DW1: SIAAS | EB1: KILN COAL | EF1: cpp coal | EJ1: Clinker | EP1: Spg TRACKING
B2: Date | C2: Opening Stock | D2: Production | E2: Consumption/RM1 | G2: Closing Stock | H2: Opening Stock | I2: Production | J2: total Consumption | K2: Closing Stock | L2: Opening Stock | M2: Production | N2: CPP | O2: KILN | P2: Consumption | Q2: Closing Stock | R2: Opening Stock | S2: Production | T2: Consumption CPP | U2: Consump Kiln | V2: Total Consumption | W2: Closing Stock | X2: Opening Stock | Y2: Production | Z2: CPP | AA2: Consumption | AB2: Closing Stock | AC2: Opening Stock | AD2: Production | AE2: Consumption | AF2: Closing Stock | AG2: Opening Stock | AH2: Production | AI2: Kiln cons | AJ2: Consumption | AK2: Closing Stock | AL2: Opening Stock | AM2: Production | AN2: Consumption | AO2: Closing Stock | AP2: Opening Stock | AQ2: Production | AR2: Consumption | AS2: CONS CPP | AT2: Closing Stock | AU2: Opening Stock | AV2: Production | AW2: Consumption | AX2: CONS CPP | AY2: Closing Stock | AZ2: Opening Stock | BA2: Production | BB2: Consumption | BC2: CONS CPP | BD2: Closing Stock | BE2: Opening Stock | BF2: Production | BG2: Consumption | BH2: CONS CPP | BI2: Closing Stock | BJ2: Opening Stock | BK2: Production | BL2: Consumption | BM2: CONS CPP | BN2: Closing Stock | BO2: Opening Stock | BP2: Production | BQ2: Consumption | BR2: CONS CPP | BS2: Closing Stock | BT2: Opening Stock | BU2: Production | BV2: Consumption | BW2: CONS CPP | BX2: Closing Stock | BY2: Opening Stock | BZ2: Production | CA2: Consumption | CB2: CONS CPP | CC2: Closing Stock | CD2: Opening Stock | CE2: Production | CF2: Consumption | CG2: CONS CPP | CH2: Closing Stock | CI2: Opening Stock | CJ2: Production | CK2: Consumption | CL2: CONS CPP | CM2: Closing Stock | CN2: Opening Stock | CO2: Production | CP2: Consumption | CQ2: CONS CPP | CR2: Closing Stock | CS2: Opening Stock | CT2: Production | CU2: Consumption | CV2: CONS CPP | CW2: Closing Stock | CX2: Opening Stock | CY2: Production | CZ2: Consumption | DA2: CONS CPP | DB2: Closing Stock | DC2: Opening Stock | DD2: Production | DE2: Consumption | DF2: CONS CPP | DG2: Closing Stock | DH2: Opening Stock | DI2: Production | DJ2: Consumption | DK2: CONS CPP | DL2: Closing Stock | DM2: Opening Stock | DN2: Production | DO2: Consumption | DP2: CONS CPP | DQ2: Closing Stock | DR2: Opening Stock | DS2: Production | DT2: Consumption | DU2: CONS CPP | DV2: Closing Stock | DW2: Opening Stock | DX2: Production | DY2: Consumption | DZ2: CONS CPP | EA2: Closing Stock | EB2: Closing Stock | EC2: Production | ED2: Consumption | EE2: Closing Stock | EF2: Opening Stock | EG2: Production | EH2: Consumption | EI2: Closing Stock | EJ2: Opening Stock | EK2: Production | EL2: Consumption | EM2: Closing Stock | EN2: clinker despatch | EO2: OP | EP2: CLINKER PURCHASED | EQ2: CLINKER CONS | ER2: CLOSING
B3: 1 | C3: 3998.34 | D3: 0 | E3: =F3+'RAW MILL 2'!F3 -> 5 | F3: 5 | G3: =C3+D3-E3 -> 3993.34 | H3: 1996 | I3: =Production2!N3 -> 229.65 | J3: =Production2!K3 -> 348.75 | K3: =H3+I3-J3 -> 1876.9 | L3: 0 | M3: 0 | N3: =CPP!D3 -> 0 | O3: 0 | P3: =N3+O3 -> 0 | Q3: =L3+M3-O3-N3 -> 0 | R3: 0 | S3: 0 | T3: =CPP!E3 -> 0 | U3: 0 | V3: =T3+U3 -> 0 | W3: =R3+S3-V3 -> 0 | X3: 3663.83 | Y3: 0 | Z3: =CPP!H3 -> 48 | AA3: 55.56 | AB3: =X3+Y3-AA3-Z3 -> 3560.27 | AC3: 0 | AD3: 0 | AE3: 0 | AF3: =AC3+AD3-AE3 -> 0 | AG3: 10010.65 | AH3: 0 | AJ3: =CPP!G3 -> 48 | AK3: =AG3+AH3-AJ3 -> 9962.65 | AL3: 0 | AM3: 0 | AN3: 0 | AO3: =AL3+AM3-AN3 -> 0 | AP3: 0 | AQ3: 0 | AR3: 0 | AS3: =CPP!I3 -> 0 | AT3: =AP3+AQ3-AR3-AS3 -> 0 | AU3: 0 | AV3: 0 | AW3: 0 | AX3: =CPP!J3 -> 0 | AY3: =AU3+AV3-AW3-AX3 -> 0 | AZ3: =0.296999999990248-0.01 -> 0.287 | BA3: 0 | BB3: 0 | BC3: =CPP!K3 -> 0 | BD3: =AZ3+BA3-BB3-BC3 -> 0.287 | BE3: 0 | BF3: 0 | BG3: 0 | BH3: =CPP!L3 -> 0 | BI3: =BE3+BF3-BG3-BH3 -> 0 | BJ3: 0 | BK3: 0 | BL3: 0 | BM3: =CPP!M3 -> 0 | BN3: =BJ3+BK3-BL3-BM3 -> 0 | BO3: 0 | BP3: 0 | BQ3: 0 | BR3: =CPP!N3 -> 0 | BS3: =BO3+BP3-BQ3-BR3 -> 0 | BT3: 0 | BU3: 0 | BV3: 0 | BW3: =CPP!O3 -> 0 | BX3: =BT3+BU3-BV3-BW3 -> 0 | BY3: 0.01 | BZ3: 0 | CA3: 0 | CC3: 0 | CD3: 0 | CE3: 0 | CF3: 0 | CG3: =CPP!P3 -> 0 | CH3: =CD3+CE3-CF3-CG3 -> 0 | CI3: 0 | CJ3: 0 | CK3: 0 | CL3: =CPP!Q3 -> 0 | CM3: =CI3+CJ3-CK3-CL3 -> 0 | CN3: 0.05 | CO3: 0 | CP3: 0 | CQ3: =CPP!R3 -> 0 | CR3: =CN3+CO3-CP3-CQ3 -> 0.05 | CS3: 0 | CT3: 0 | CU3: 0 | CV3: =CPP!S3 -> 0 | CW3: =CS3+CT3-CU3-CV3 -> 0 | CX3: 0 | CY3: 0 | CZ3: 0 | DA3: =CPP!T3 -> 0 | DB3: =CX3+CY3-CZ3-DA3 -> 0 | DC3: 306 | DD3: 0 | DE3: 0 | DF3: =CPP!U3 -> 0 | DG3: =DC3+DD3-DE3-DF3 -> 306 | DH3: 0 | DI3: 0 | DJ3: 0 | DK3: =CPP!V3 -> 0 | DL3: =DH3+DI3-DJ3-DK3 -> 0 | DM3: 0 | DN3: 0 | DO3: 0 | DP3: =CPP!W3 -> 0 | DQ3: =DM3+DN3-DO3-DP3 -> 0 | DR3: 4270.35 | DS3: 0 | DT3: 0 | DU3: =CPP!X3 -> 0 | DV3: =DR3+DS3-DT3-DU3 -> 4270.35 | DW3: 0 | DX3: 0 | DY3: 0 | DZ3: =CPP!Y3 -> 0 | EA3: =DW3+DX3-DY3-DZ3 -> 0 | EB3: =L3+AP3+AU3+AZ3+BE3+BJ3+BT3+BY3+CD3+CI3+CS3+CX3+DC3+DH3+DM3+DW3+X3+DR3 -> 8240.477 | EC3: =M3+Y3+AM3+AQ3+AV3+BA3+BF3+BK3+BP3+BU3+BZ3+CT3+CY3+DD3+DI3+DN3+DX3+DS3 -> 0 | ED3: =O3+AA3+AN3+AR3+AW3+BB3+BG3+BL3+BQ3+BV3+CA3+CU3+CZ3+DE3+DJ3+DO3+DY3+DT3 -> 55.56 | EE3: =EB3+EC3-ED3-N3-Z3-AS3-AX3-BC3-BH3-BM3-BR3-BW3-CV3-DA3-DF3-DK3-DP3-DZ3-DU3 -> 8136.917 | EF3: =R3+AC3+AG3+AL3+CN3 -> 10010.7 | EG3: =S3+AD3+AH3+CE3+CJ3+CO3 -> 0 | EH3: =CPP!D3+CPP!E3+CPP!F3+CPP!G3+CPP!H3+CPP!I3+CPP!J3+CPP!K3+CPP!L3+CPP!M3+CPP!N3+CPP!O3+CPP!P3+CPP!Q3+CPP!R3+CPP!S3+DA3+DF3+DK3+CPP!W3+DU3 -> 96 | EI3: =EF3+EG3-CPP!G3-CPP!E3-CPP!F3-CPP!P3-CPP!Q3-CL3-CQ3-DU3 -> 9962.7 | EJ3: 24919.66 | EK3: 225 | EL3: ='Daily CEM-1'!AG4+'Daily CEM - 2'!AF4-EQ3 -> 808 | EM3: =EJ3+EK3-EL3-EN3 -> 24336.66 | EN3: 0 | EO3: 5155.329 | EP3: 0 | EQ3: 0 | ER3: =EO3+EP3-EQ3 -> 5155.329 | ES3: =ET3-EP3 -> 1722.57 | ET3: 1722.57 | EU3: =EL3+EQ3 -> 808 | EV3: =EL3+EQ3 -> 808 | EW3: =(EU3/Production2!CG3)*100 -> 74.814815 | EX3: 74.814815 | EY3: =EX3*100 -> 7481.4815
B4: 2 | C4: =G3 -> 3993.34 | D4: 37.52 | E4: =F4+'RAW MILL 2'!F4 -> 60 | F4: 57 | G4: =C4+D4-E4 -> 3970.86 | H4: =K3 -> 1876.9 | I4: =Production2!N4 -> 2535 | J4: =Production2!K4 -> 2239.75 | K4: =H4+I4-J4 -> 2172.15 | L4: =Q3 -> 0 | M4: 0 | N4: =CPP!D4 -> 0 | O4: 0 | P4: =N4+O4 -> 0 | Q4: =L4+M4-O4-N4 -> 0 | R4: =W3 -> 0 | S4: 0 | T4: =CPP!E4 -> 0 | U4: 0 | V4: =T4+U4 -> 0 | W4: =R4+S4-V4 -> 0 | X4: =AB3 -> 3560.27 | Y4: 0 | Z4: =CPP!H4 -> 67 | AA4: 266.67 | AB4: =X4+Y4-AA4-Z4 -> 3226.6 | AC4: =AF3 -> 0 | AD4: 0 | AE4: 0 | AF4: =AC4+AD4-AE4 -> 0 | AG4: =AK3 -> 9962.65 | AH4: 64.3 | AJ4: =CPP!G4 -> 68 | AK4: =AG4+AH4-AJ4 -> 9958.95 | AL4: =AO3 -> 0 | AM4: 0 | AN4: 0 | AO4: =AL4+AM4-AN4 -> 0 | AP4: =AT3 -> 0 | AQ4: 0 | AR4: 0 | AS4: =CPP!I4 -> 0 | AT4: =AP4+AQ4-AR4-AS4 -> 0 | AU4: =AY3 -> 0 | AV4: 0 | AW4: 0 | AX4: =CPP!J4 -> 0 | AY4: =AU4+AV4-AW4-AX4 -> 0 | AZ4: =BD3 -> 0.287 | BA4: 0 | BB4: 0 | BC4: =CPP!K4 -> 0 | BD4: =AZ4+BA4-BB4-BC4 -> 0.287 | BE4: =BI3 -> 0 | BF4: 0 | BG4: 0 | BH4: =CPP!L4 -> 0 | BI4: =BE4+BF4-BG4-BH4 -> 0 | BJ4: =BN3 -> 0 | BK4: 0 | BL4: 0 | BM4: =CPP!M4 -> 0 | BN4: =BJ4+BK4-BL4-BM4 -> 0 | BO4: =BS3 -> 0 | BP4: 0 | BQ4: 0 | BR4: =CPP!N4 -> 0 | BS4: =BO4+BP4-BQ4-BR4 -> 0 | BT4: =BX3 -> 0 | BU4: 0 | BV4: 0 | BW4: =CPP!O4 -> 0 | BX4: =BT4+BU4-BV4-BW4 -> 0 | BY4: =CC3 -> 0 | BZ4: 0 | CA4: 0 | CC4: =BY4+BZ4-CA4-CB4 -> 0 | CD4: =CH3 -> 0 | CE4: 0 | CF4: 0 | CG4: =CPP!P4 -> 0 | CH4: =CD4+CE4-CF4-CG4 -> 0 | CI4: =CM3 -> 0 | CJ4: 0 | CK4: 0 | CL4: =CPP!Q4 -> 0 | CM4: =CI4+CJ4-CK4-CL4 -> 0 | CN4: =CR3 -> 0.05 | CO4: 0 | CP4: 0 | CQ4: =CPP!R4 -> 0 | CR4: =CN4+CO4-CP4-CQ4 -> 0.05 | CS4: =CW3 -> 0 | CT4: 0 | CU4: 0 | CV4: =CPP!S4 -> 0 | CW4: =CS4+CT4-CU4-CV4 -> 0 | CX4: =DB3 -> 0 | CY4: 0 | CZ4: 0 | DA4: =CPP!T4 -> 0 | DB4: =CX4+CY4-CZ4-DA4 -> 0 | DC4: =DG3 -> 306 | DD4: 0 | DE4: 0 | DF4: =CPP!U4 -> 0 | DG4: =DC4+DD4-DE4-DF4 -> 306 | DH4: =DL3 -> 0 | DI4: 0 | DJ4: 0 | DK4: =CPP!V4 -> 0 | DL4: =DH4+DI4-DJ4-DK4 -> 0 | DM4: =DQ3 -> 0 | DN4: 0 | DO4: 0 | DP4: =CPP!W4 -> 0 | DQ4: =DM4+DN4-DO4-DP4 -> 0 | DR4: =DV3 -> 4270.35 | DS4: 0 | DT4: 0 | DU4: =CPP!X4 -> 0 | DV4: =DR4+DS4-DT4-DU4 -> 4270.35 | DW4: =EA3 -> 0 | DX4: 0 | DY4: 0 | DZ4: =CPP!Y4 -> 0 | EA4: =DW4+DX4-DY4-DZ4 -> 0 | EB4: =L4+AP4+AU4+AZ4+BE4+BJ4+BT4+BY4+CD4+CI4+CS4+CX4+DC4+DH4+DM4+DW4+X4+DR4 -> 8136.907 | EC4: =M4+Y4+AM4+AQ4+AV4+BA4+BF4+BK4+BP4+BU4+BZ4+CT4+CY4+DD4+DI4+DN4+DX4+DS4 -> 0 | ED4: =O4+AA4+AN4+AR4+AW4+BB4+BG4+BL4+BQ4+BV4+CA4+CU4+CZ4+DE4+DJ4+DO4+DY4+DT4 -> 266.67 | EE4: =EB4+EC4-ED4-N4-Z4-AS4-AX4-BC4-BH4-BM4-BR4-BW4-CV4-DA4-DF4-DK4-DP4-DZ4-DU4 -> 7803.237 | EF4: =R4+AC4+AG4+AL4+CN4 -> 9962.7 | EG4: =S4+AD4+AH4+CE4+CJ4+CO4 -> 64.3 | EH4: =CPP!D4+CPP!E4+CPP!F4+CPP!G4+CPP!H4+CPP!I4+CPP!J4+CPP!K4+CPP!L4+CPP!M4+CPP!N4+CPP!O4+CPP!P4+CPP!Q4+CPP!R4+CPP!S4+DA4+DF4+DK4+CPP!W4+DU4 -> 135 | EI4: =EF4+EG4-CPP!G4-CPP!E4-CPP!F4-CPP!P4-CPP!Q4-CL4-CQ4-DU4 -> 9959 | EJ4: =EM3 -> 24336.66 | EK4: 1445 | EL4: ='Daily CEM-1'!AG5+'Daily CEM - 2'!AF5-EQ4 -> 862.5 | EM4: =EJ4+EK4-EL4-EN4 -> 24919.16 | EN4: 0 | EO4: =ER3 -> 5155.329 | EP4: 91.19 | EQ4: 0 | ER4: =EO4+EP4-EQ4 -> 5246.519 | ES4: =ET4-EP4 -> 1079.91 | ET4: 1171.1 | EU4: =EL4+EQ4 -> 862.5 | EV4: =EL4+EQ4 -> 862.5 | EW4: =(EU4/Production2!CG4)*100 -> 73.844178 | EX4: 73.844178 | EY4: =EX4*100 -> 7384.4178
B5: 3 | C5: =G4 -> 3970.86 | D5: 0 | E5: =F5+'RAW MILL 2'!F5 -> 54 | F5: 50 | G5: =C5+D5-E5 -> 3916.86 | H5: =K4 -> 2172.15 | I5: =Production2!N5 -> 2235 | J5: =Production2!K5 -> 2518.75 | K5: =H5+I5-J5 -> 1888.4 | L5: =Q4 -> 0 | M5: 0 | N5: =CPP!D5 -> 0 | O5: 0 | P5: =N5+O5 -> 0 | Q5: =L5+M5-O5-N5 -> 0 | R5: =W4 -> 0 | S5: 0 | T5: =CPP!E5 -> 0 | U5: 0 | V5: =T5+U5 -> 0 | W5: =R5+S5-V5 -> 0 | X5: =AB4 -> 3226.6 | Y5: 0 | Z5: =CPP!H5 -> 72 | AA5: 212 | AB5: =X5+Y5-AA5-Z5 -> 2942.6 | AC5: =AF4 -> 0 | AD5: 0 | AE5: 0 | AF5: =AC5+AD5-AE5 -> 0 | AG5: =AK4 -> 9958.95 | AH5: 0 | AJ5: =CPP!G5 -> 72 | AK5: =AG5+AH5-AJ5 -> 9886.95 | AL5: =AO4 -> 0 | AM5: 0 | AN5: 0 | AO5: =AL5+AM5-AN5 -> 0 | AP5: =AT4 -> 0 | AQ5: 0 | AR5: 0 | AS5: =CPP!I5 -> 0 | AT5: =AP5+AQ5-AR5-AS5 -> 0 | AU5: =AY4 -> 0 | AV5: 0 | AW5: 0 | AX5: =CPP!J5 -> 0 | AY5: =AU5+AV5-AW5-AX5 -> 0 | AZ5: =BD4 -> 0.287 | BA5: 0 | BB5: 0 | BC5: =CPP!K5 -> 0 | BD5: =AZ5+BA5-BB5-BC5 -> 0.287 | BE5: =BI4 -> 0 | BF5: 0 | BG5: 0 | BH5: =CPP!L5 -> 0 | BI5: =BE5+BF5-BG5-BH5 -> 0 | BJ5: =BN4 -> 0 | BK5: 0 | BL5: 0 | BM5: =CPP!M5 -> 0 | BN5: =BJ5+BK5-BL5-BM5 -> 0 | BO5: =BS4 -> 0 | BP5: 0 | BQ5: 0 | BR5: =CPP!N5 -> 0 | BS5: =BO5+BP5-BQ5-BR5 -> 0 | BT5: =BX4 -> 0 | BU5: 0 | BV5: 0 | BW5: =CPP!O5 -> 0 | BX5: =BT5+BU5-BV5-BW5 -> 0 | BY5: =CC4 -> 0 | BZ5: 0 | CA5: 0 | CC5: =BY5+BZ5-CA5-CB5 -> 0 | CD5: =CH4 -> 0 | CE5: 0 | CF5: 0 | CG5: =CPP!P5 -> 0 | CH5: =CD5+CE5-CF5-CG5 -> 0 | CI5: =CM4 -> 0 | CJ5: 0 | CK5: 0 | CL5: =CPP!Q5 -> 0 | CM5: =CI5+CJ5-CK5-CL5 -> 0 | CN5: =CR4 -> 0.05 | CO5: 0 | CP5: 0 | CQ5: =CPP!R5 -> 0 | CR5: =CN5+CO5-CP5-CQ5 -> 0.05 | CS5: =CW4 -> 0 | CT5: 0 | CU5: 0 | CV5: =CPP!S5 -> 0 | CW5: =CS5+CT5-CU5-CV5 -> 0 | CX5: =DB4 -> 0 | CY5: 0 | CZ5: 0 | DA5: =CPP!T5 -> 0 | DB5: =CX5+CY5-CZ5-DA5 -> 0 | DC5: =DG4 -> 306 | DD5: 0 | DE5: 0 | DF5: =CPP!U5 -> 0 | DG5: =DC5+DD5-DE5-DF5 -> 306 | DH5: =DL4 -> 0 | DI5: 0 | DJ5: 0 | DK5: =CPP!V5 -> 0 | DL5: =DH5+DI5-DJ5-DK5 -> 0 | DM5: =DQ4 -> 0 | DN5: 0 | DO5: 0 | DP5: =CPP!W5 -> 0 | DQ5: =DM5+DN5-DO5-DP5 -> 0 | DR5: =DV4 -> 4270.35 | DS5: 0 | DT5: 53 | DU5: =CPP!X5 -> 0 | DV5: =DR5+DS5-DT5-DU5 -> 4217.35 | DW5: =EA4 -> 0 | DX5: 0 | DY5: 0 | DZ5: =CPP!Y5 -> 0 | EA5: =DW5+DX5-DY5-DZ5 -> 0 | EB5: =L5+AP5+AU5+AZ5+BE5+BJ5+BT5+BY5+CD5+CI5+CS5+CX5+DC5+DH5+DM5+DW5+X5+DR5 -> 7803.237 | EC5: =M5+Y5+AM5+AQ5+AV5+BA5+BF5+BK5+BP5+BU5+BZ5+CT5+CY5+DD5+DI5+DN5+DX5+DS5 -> 0 | ED5: =O5+AA5+AN5+AR5+AW5+BB5+BG5+BL5+BQ5+BV5+CA5+CU5+CZ5+DE5+DJ5+DO5+DY5+DT5 -> 265 | EE5: =EB5+EC5-ED5-N5-Z5-AS5-AX5-BC5-BH5-BM5-BR5-BW5-CV5-DA5-DF5-DK5-DP5-DZ5-DU5 -> 7466.237 | EF5: =R5+AC5+AG5+AL5+CN5 -> 9959 | EG5: =S5+AD5+AH5+CE5+CJ5+CO5 -> 0 | EH5: =CPP!D5+CPP!E5+CPP!F5+CPP!G5+CPP!H5+CPP!I5+CPP!J5+CPP!K5+CPP!L5+CPP!M5+CPP!N5+CPP!O5+CPP!P5+CPP!Q5+CPP!R5+CPP!S5+DA5+DF5+DK5+CPP!W5+DU5 -> 144 | EI5: =EF5+EG5-CPP!G5-CPP!E5-CPP!F5-CPP!P5-CPP!Q5-CL5-CQ5-DU5 -> 9887 | EJ5: =EM4 -> 24919.16 | EK5: 1625 | EL5: ='Daily CEM-1'!AG6+'Daily CEM - 2'!AF6-EQ5 -> 195 | EM5: =EJ5+EK5-EL5-EN5 -> 26349.16 | EN5: 0 | EO5: =ER4 -> 5246.519 | EP5: 0 | EQ5: 0 | ER5: =EO5+EP5-EQ5 -> 5246.519 | ES5: =ET5-EP5 -> 1446.55 | ET5: 1446.55 | EU5: =EL5+EQ5 -> 195 | EV5: =EL5+EQ5 -> 195 | EW5: =(EU5/Production2!CG5)*100 -> 78 | EX5: 78 | EY5: =EX5*100 -> 7800
B6: 4 | C6: =G5 -> 3916.86 | D6: 32 | E6: =F6+'RAW MILL 2'!F6 -> 39 | F6: 37 | G6: =C6+D6-E6 -> 3909.86 | H6: =K5 -> 1888.4 | I6: =Production2!N6 -> 1680 | J6: =Production2!K6 -> 2286.25 | K6: =H6+I6-J6 -> 1282.15 | L6: =Q5 -> 0 | M6: 0 | N6: =CPP!D6 -> 0 | O6: 0 | P6: =N6+O6 -> 0 | Q6: =L6+M6-O6-N6 -> 0 | R6: =W5 -> 0 | S6: 0 | T6: =CPP!E6 -> 0 | U6: 0 | V6: =T6+U6 -> 0 | W6: =R6+S6-V6 -> 0 | X6: =AB5 -> 2942.6 | Y6: 0 | Z6: =CPP!H6 -> 74 | AA6: 200 | AB6: =X6+Y6-AA6-Z6 -> 2668.6 | AC6: =AF5 -> 0 | AD6: 0 | AE6: 0 | AF6: =AC6+AD6-AE6 -> 0 | AG6: =AK5 -> 9886.95 | AH6: 90.9 | AJ6: =CPP!G6 -> 49 | AK6: =AG6+AH6-AJ6 -> 9928.85 | AL6: =AO5 -> 0 | AM6: 0 | AN6: 0 | AO6: =AL6+AM6-AN6 -> 0 | AP6: =AT5 -> 0 | AQ6: 0 | AR6: 0 | AS6: =CPP!I6 -> 0 | AT6: =AP6+AQ6-AR6-AS6 -> 0 | AU6: =AY5 -> 0 | AV6: 0 | AW6: 0 | AX6: =CPP!J6 -> 0 | AY6: =AU6+AV6-AW6-AX6 -> 0 | AZ6: =BD5 -> 0.287 | BA6: 0 | BB6: 0 | BC6: =CPP!K6 -> 0 | BD6: =AZ6+BA6-BB6-BC6 -> 0.287 | BE6: =BI5 -> 0 | BF6: 0 | BG6: 0 | BH6: =CPP!L6 -> 0 | BI6: =BE6+BF6-BG6-BH6 -> 0 | BJ6: =BN5 -> 0 | BK6: 0 | BL6: 0 | BM6: =CPP!M6 -> 0 | BN6: =BJ6+BK6-BL6-BM6 -> 0 | BO6: =BS5 -> 0 | BP6: 0 | BQ6: 0 | BR6: =CPP!N6 -> 0 | BS6: =BO6+BP6-BQ6-BR6 -> 0 | BT6: =BX5 -> 0 | BU6: 0 | BV6: 0 | BW6: =CPP!O6 -> 0 | BX6: =BT6+BU6-BV6-BW6 -> 0 | BY6: =CC5 -> 0 | BZ6: 0 | CA6: 0 | CC6: =BY6+BZ6-CA6-CB6 -> 0 | CD6: =CH5 -> 0 | CE6: 0 | CF6: 0 | CG6: =CPP!P6 -> 0 | CH6: =CD6+CE6-CF6-CG6 -> 0 | CI6: =CM5 -> 0 | CJ6: 0 | CK6: 0 | CL6: =CPP!Q6 -> 0 | CM6: =CI6+CJ6-CK6-CL6 -> 0 | CN6: =CR5 -> 0.05 | CO6: 0 | CP6: 0 | CQ6: =CPP!R6 -> 0 | CR6: =CN6+CO6-CP6-CQ6 -> 0.05 | CS6: =CW5 -> 0 | CT6: 0 | CU6: 0 | CV6: =CPP!S6 -> 0 | CW6: =CS6+CT6-CU6-CV6 -> 0 | CX6: =DB5 -> 0 | CY6: 0 | CZ6: 0 | DA6: =CPP!T6 -> 0 | DB6: =CX6+CY6-CZ6-DA6 -> 0 | DC6: =DG5 -> 306 | DD6: 0 | DE6: 0 | DF6: =CPP!U6 -> 0 | DG6: =DC6+DD6-DE6-DF6 -> 306 | DH6: =DL5 -> 0 | DI6: 0 | DJ6: 0 | DK6: =CPP!V6 -> 0 | DL6: =DH6+DI6-DJ6-DK6 -> 0 | DM6: =DQ5 -> 0 | DN6: 0 | DO6: 0 | DP6: =CPP!W6 -> 0 | DQ6: =DM6+DN6-DO6-DP6 -> 0 | DR6: =DV5 -> 4217.35 | DS6: 0 | DT6: 50 | DU6: =CPP!X6 -> 0 | DV6: =DR6+DS6-DT6-DU6 -> 4167.35 | DW6: =EA5 -> 0 | DX6: 0 | DY6: 0 | DZ6: =CPP!Y6 -> 0 | EA6: =DW6+DX6-DY6-DZ6 -> 0 | EB6: =L6+AP6+AU6+AZ6+BE6+BJ6+BT6+BY6+CD6+CI6+CS6+CX6+DC6+DH6+DM6+DW6+X6+DR6 -> 7466.237 | EC6: =M6+Y6+AM6+AQ6+AV6+BA6+BF6+BK6+BP6+BU6+BZ6+CT6+CY6+DD6+DI6+DN6+DX6+DS6 -> 0 | ED6: =O6+AA6+AN6+AR6+AW6+BB6+BG6+BL6+BQ6+BV6+CA6+CU6+CZ6+DE6+DJ6+DO6+DY6+DT6 -> 250 | EE6: =EB6+EC6-ED6-N6-Z6-AS6-AX6-BC6-BH6-BM6-BR6-BW6-CV6-DA6-DF6-DK6-DP6-DZ6-DU6 -> 7142.237 | EF6: =R6+AC6+AG6+AL6+CN6 -> 9887 | EG6: =S6+AD6+AH6+CE6+CJ6+CO6 -> 90.9 | EH6: =CPP!D6+CPP!E6+CPP!F6+CPP!G6+CPP!H6+CPP!I6+CPP!J6+CPP!K6+CPP!L6+CPP!M6+CPP!N6+CPP!O6+CPP!P6+CPP!Q6+CPP!R6+CPP!S6+DA6+DF6+DK6+CPP!W6+DU6 -> 123 | EI6: =EF6+EG6-CPP!G6-CPP!E6-CPP!F6-CPP!P6-CPP!Q6-CL6-CQ6-DU6 -> 9928.9 | EJ6: =EM5 -> 26349.16 | EK6: 1475 | EL6: ='Daily CEM-1'!AG7+'Daily CEM - 2'!AF7-EQ6 -> 671.5 | EM6: =EJ6+EK6-EL6-EN6 -> 27152.66 | EN6: 0 | EO6: =ER5 -> 5246.519 | EP6: 59.59 | EQ6: 0 | ER6: =EO6+EP6-EQ6 -> 5306.109 | ES6: =ET6-EP6 -> 1440.7 | ET6: 1500.29 | EU6: =EL6+EQ6 -> 671.5 | EV6: =EL6+EQ6 -> 671.5 | EW6: =(EU6/Production2!CG6)*100 -> 79 | EX6: 79 | EY6: =EX6*100 -> 7900
B7: 5 | C7: =G6 -> 3909.86 | D7: 0 | E7: =F7+'RAW MILL 2'!F7 -> 39 | F7: 37 | G7: =C7+D7-E7 -> 3870.86 | H7: =K6 -> 1282.15 | I7: =Production2!N7 -> 1678 | J7: =Production2!K7 -> 2030.5 | K7: =H7+I7-J7 -> 929.65002 | L7: =Q6 -> 0 | M7: 0 | N7: =CPP!D7 -> 0 | O7: 0 | P7: =N7+O7 -> 0 | Q7: =L7+M7-O7-N7 -> 0 | R7: =W6 -> 0 | S7: 0 | T7: =CPP!E7 -> 0 | U7: 0 | V7: =T7+U7 -> 0 | W7: =R7+S7-V7 -> 0 | X7: =AB6 -> 2668.6 | Y7: 0 | Z7: =CPP!H7 -> 60 | AA7: 184 | AB7: =X7+Y7-AA7-Z7 -> 2424.6 | AC7: =AF6 -> 0 | AD7: 0 | AE7: 0 | AF7: =AC7+AD7-AE7 -> 0 | AG7: =AK6 -> 9928.85 | AH7: 154.3 | AJ7: =CPP!G7 -> 60 | AK7: =AG7+AH7-AJ7 -> 10023.15 | AL7: =AO6 -> 0 | AM7: 0 | AN7: 0 | AO7: =AL7+AM7-AN7 -> 0 | AP7: =AT6 -> 0 | AQ7: 0 | AR7: 0 | AS7: =CPP!I7 -> 0 | AT7: =AP7+AQ7-AR7-AS7 -> 0 | AU7: =AY6 -> 0 | AV7: 0 | AW7: 0 | AX7: =CPP!J7 -> 0 | AY7: =AU7+AV7-AW7-AX7 -> 0 | AZ7: =BD6 -> 0.287 | BA7: 0 | BB7: 0 | BC7: =CPP!K7 -> 0 | BD7: =AZ7+BA7-BB7-BC7 -> 0.287 | BE7: =BI6 -> 0 | BF7: 0 | BG7: 0 | BH7: =CPP!L7 -> 0 | BI7: =BE7+BF7-BG7-BH7 -> 0 | BJ7: =BN6 -> 0 | BK7: 0 | BL7: 0 | BM7: =CPP!M7 -> 0 | BN7: =BJ7+BK7-BL7-BM7 -> 0 | BO7: =BS6 -> 0 | BP7: 0 | BQ7: 0 | BR7: =CPP!N7 -> 0 | BS7: =BO7+BP7-BQ7-BR7 -> 0 | BT7: =BX6 -> 0 | BU7: 0 | BV7: 0 | BW7: =CPP!O7 -> 0 | BX7: =BT7+BU7-BV7-BW7 -> 0 | BY7: =CC6 -> 0 | BZ7: 0 | CA7: 0 | CC7: =BY7+BZ7-CA7-CB7 -> 0 | CD7: =CH6 -> 0 | CE7: 0 | CF7: 0 | CG7: =CPP!P7 -> 0 | CH7: =CD7+CE7-CF7-CG7 -> 0 | CI7: =CM6 -> 0 | CJ7: 0 | CK7: 0 | CL7: =CPP!Q7 -> 0 | CM7: =CI7+CJ7-CK7-CL7 -> 0 | CN7: =CR6 -> 0.05 | CO7: 0 | CP7: 0 | CQ7: =CPP!R7 -> 0 | CR7: =CN7+CO7-CP7-CQ7 -> 0.05 | CS7: =CW6 -> 0 | CT7: 0 | CU7: 0 | CV7: =CPP!S7 -> 0 | CW7: =CS7+CT7-CU7-CV7 -> 0 | CX7: =DB6 -> 0 | CY7: 0 | CZ7: 0 | DA7: =CPP!T7 -> 0 | DB7: =CX7+CY7-CZ7-DA7 -> 0 | DC7: =DG6 -> 306 | DD7: 0 | DE7: 0 | DF7: =CPP!U7 -> 0 | DG7: =DC7+DD7-DE7-DF7 -> 306 | DH7: =DL6 -> 0 | DI7: 0 | DJ7: 0 | DK7: =CPP!V7 -> 0 | DL7: =DH7+DI7-DJ7-DK7 -> 0 | DM7: =DQ6 -> 0 | DN7: 0 | DO7: 0 | DP7: =CPP!W7 -> 0 | DQ7: =DM7+DN7-DO7-DP7 -> 0 | DR7: =DV6 -> 4167.35 | DS7: 0 | DT7: 46 | DU7: =CPP!X7 -> 0 | DV7: =DR7+DS7-DT7-DU7 -> 4121.35 | DW7: =EA6 -> 0 | DX7: 0 | DY7: 0 | DZ7: =CPP!Y7 -> 0 | EA7: =DW7+DX7-DY7-DZ7 -> 0 | EB7: =L7+AP7+AU7+AZ7+BE7+BJ7+BT7+BY7+CD7+CI7+CS7+CX7+DC7+DH7+DM7+DW7+X7+DR7 -> 7142.237 | EC7: =M7+Y7+AM7+AQ7+AV7+BA7+BF7+BK7+BP7+BU7+BZ7+CT7+CY7+DD7+DI7+DN7+DX7+DS7 -> 0 | ED7: =O7+AA7+AN7+AR7+AW7+BB7+BG7+BL7+BQ7+BV7+CA7+CU7+CZ7+DE7+DJ7+DO7+DY7+DT7 -> 230 | EE7: =EB7+EC7-ED7-N7-Z7-AS7-AX7-BC7-BH7-BM7-BR7-BW7-CV7-DA7-DF7-DK7-DP7-DZ7-DU7 -> 6852.237 | EF7: =R7+AC7+AG7+AL7+CN7 -> 9928.9 | EG7: =S7+AD7+AH7+CE7+CJ7+CO7 -> 154.3 | EH7: =CPP!D7+CPP!E7+CPP!F7+CPP!G7+CPP!H7+CPP!I7+CPP!J7+CPP!K7+CPP!L7+CPP!M7+CPP!N7+CPP!O7+CPP!P7+CPP!Q7+CPP!R7+CPP!S7+DA7+DF7+DK7+CPP!W7+DU7 -> 120 | EI7: =EF7+EG7-CPP!G7-CPP!E7-CPP!F7-CPP!P7-CPP!Q7-CL7-CQ7-DU7 -> 10023.2 | EJ7: =EM6 -> 27152.66 | EK7: 1310 | EL7: ='Daily CEM-1'!AG8+'Daily CEM - 2'!AF8-EQ7 -> 463.6 | EM7: =EJ7+EK7-EL7-EN7 -> 27999.06 | EN7: 0 | EO7: =ER6 -> 5306.109 | EP7: 0 | EQ7: 0 | ER7: =EO7+EP7-EQ7 -> 5306.109 | ES7: =ET7-EP7 -> 0 | EU7: =EL7+EQ7 -> 463.6 | EV7: =EL7+EQ7 -> 463.6 | EW7: =(EU7/Production2!CG7)*100 -> 72.4375 | EX7: 72.4375 | EY7: =EX7*100 -> 7243.75
